Workbook

Sheet Hoja1
A1: N° de serie | B1: Year | C1: Quarter | D1: Month | E1: Day | F1: Categoría | G1: T. respuesta | H1: Business Team | I1: Pago Base CDMX y área metropolitana | J1: Pago Base Interior | K1: menos de 3 días | L1: entre 3 y 6 días | M1: entre 7 y 15 días | N1: entre 16 y 30 días | O1: entre 31 y 59 días | P1: 60 días o más | Q1: REGION | R1: TR Ciudades principales | S1: TR Otras ciudades | T1: Loc TR | U1: familia matriz global | V1: Cliente | W1: Ruta | X1: Year.1 | Y1: Quarter.1 | Z1: Month.1 | AA1: Day.1 | AB1: time | AC1: pagofinal
A2: 2411031 | B2: 2019 | C2: Qtr 2 | D2: April | E2: 12 | F2: CONFIGURACION | G2: 0.6666667 | H2: WF Mono Systems and Legacy Color | I2: 803 | J2: 1573 | K2: 0.2 | L2: 0.6 | M2: 0.8 | N2: 1.05 | O2: 1.1 | P2: 1.15 | Q2: INTERIOR | R2: 4 | S2: 6 | T2: Ciudad principal | U2: WF Mono Systems and Legacy Color | V2: XEROX MEXICANA SA DE CV / XEROX MEXICANA | W2: QUERETARO | X2: 2019 | Y2: Qtr 2 | Z2: April | AA2: 12 | AB2: 0 | AC2: 235.95
A3: 02TX061945 | B3: 2019 | C3: Qtr 2 | D3: April | E3: 9 | F3: CORRECTIVO | G3: 0 | H3: A3 Office Color Laser MFPs | I3: 655 | J3: 1365 | K3: 0 | L3: 0 | M3: 0.6 | N3: 0.8 | O3: 1.05 | P3: 1.1 | Q3: INTERIOR | R3: 5 | S3: 9 | T3: Ciudad principal | U3: A3 Office Color Laser MFPs | V3: XEROX MEXICANA SA DE CV / XEROX MEXICANA | W3: CHIHUAHUA | X3: 2019 | Y3: Qtr 2 | Z3: April | AA3: 10 | AB3: 0 | AC3: 1501.5
A4: 03AG873545 | B4: 2019 | C4: Qtr 2 | D4: April | E4: 9 | F4: CORRECTIVO | G4: 0.5333334 | H4: Departmental Digital | I4: 655 | J4: 1365 | K4: 0 | L4: 0 | M4: 0.6 | N4: 0.8 | O4: 1.05 | P4: 1.1 | Q4: INTERIOR | R4: 5 | S4: 9 | T4: Ciudad principal | U4: Light Production Digital Business | V4: XEROX MEXICANA SA DE CV / XEROX MEXICANA | W4: QUERETARO | X4: 2019 | Y4: Qtr 2 | Z4: April | AA4: 11 | AB4: 82 | AC4: 136.5
A5: 03AG873545 | B5: 2019 | C5: Qtr 2 | D5: April | E5: 23 | F5: CORRECTIVO | G5: 0.7166666 | H5: Departmental Digital | I5: 655 | J5: 1365 | K5: 0 | L5: 0 | M5: 0.6 | N5: 0.8 | O5: 1.05 | P5: 1.1 | Q5: INTERIOR | R5: 5 | S5: 9 | T5: Ciudad principal | U5: Light Production Digital Business | V5: XEROX MEXICANA SA DE CV / XEROX MEXICANA | W5: QUERETARO | X5: 2019 | Y5: Qtr 2 | Z5: April | AA5: 23 | AB5: 14 | AC5: -546
A6: 03AG873545 | B6: 2019 | C6: Qtr 2 | D6: April | E6: 29 | F6: CORRECTIVO | G6: 0.75 | H6: Departmental Digital | I6: 655 | J6: 1365 | K6: 0 | L6: 0 | M6: 0.6 | N6: 0.8 | O6: 1.05 | P6: 1.1 | Q6: INTERIOR | R6: 5 | S6: 9 | T6: Ciudad principal | U6: Light Production Digital Business | V6: XEROX MEXICANA SA DE CV / XEROX MEXICANA | W6: QUERETARO | X6: 2019 | Y6: Qtr 2 | Z6: April | AA6: 29 | AB6: 6 | AC6: -1365
A7: 03AG876220 | B7: 2019 | C7: Qtr 2 | D7: April | E7: 24 | F7: CORRECTIVO | G7: 1.683333 | H7: Departmental Digital | I7: 655 | J7: 1365 | K7: 0 | L7: 0 | M7: 0.6 | N7: 0.8 | O7: 1.05 | P7: 1.1 | Q7: METRO | R7: 5 | S7: 9 | T7: Ciudad principal | U7: Light Production Digital Business | V7: XEROX MEXICANA SA DE CV / XEROX MEXICANA | W7: CHIHUAHUA | X7: 2019 | Y7: Qtr 2 | Z7: April | AA7: 24 | AB7: 47 | AC7: 365.11377
A8: 03AG877768 | B8: 2019 | C8: Qtr 2 | D8: April | E8: 10 | F8: CORRECTIVO | G8: 0.5833333 | H8: Departmental Digital | I8: 655 | J8: 1365 | K8: 0 | L8: 0 | M8: 0.6 | N8: 0.8 | O8: 1.05 | P8: 1.1 | Q8: INTERIOR | R8: 5 | S8: 9 | T8: Ciudad principal | U8: Light Production Digital Business | V8: XEROX MEXICANA SA DE CV / XEROX MEXICANA | W8: QUERETARO | X8: 2019 | Y8: Qtr 2 | Z8: April | AA8: 10 | AB8: 0 | AC8: 136.5
A9: 03AG877879 | B9: 2019 | C9: Qtr 2 | D9: April | E9: 8 | F9: CORRECTIVO | G9: 1.5 | H9: Departmental Digital | I9: 655 | J9: 1365 | K9: 0 | L9: 0 | M9: 0.6 | N9: 0.8 | O9: 1.05 | P9: 1.1 | Q9: INTERIOR | R9: 5 | S9: 9 | T9: Ciudad principal | U9: Light Production Digital Business | V9: XEROX MEXICANA SA DE CV / XEROX MEXICANA | W9: NUEVO LEON | X9: 2019 | Y9: Qtr 2 | Z9: April | AA9: 8 | AB9: 0 | AC9: 136.5
A10: 03AG877899 | B10: 2019 | C10: Qtr 2 | D10: April | E10: 22 | F10: CORRECTIVO | G10: 1.75 | H10: Departmental Digital | I10: 655 | J10: 1365 | K10: 0 | L10: 0 | M10: 0.6 | N10: 0.8 | O10: 1.05 | P10: 1.1 | Q10: INTERIOR | R10: 5 | S10: 9 | T10: Ciudad principal | U10: Light Production Digital Business | V10: XEROX MEXICANA SA DE CV / XEROX MEXICANA | W10: TAMAULIPAS | X10: 2019 | Y10: Qtr 2 | Z10: April | AA10: 22 | AB10: 0 | AC10: 867.75
A11: 03AG879434 | B11: 2019 | C11: Qtr 2 | D11: April | E11: 25 | F11: CORRECTIVO | G11: 1.416667 | H11: Departmental Digital | I11: 655 | J11: 1365 | K11: 0 | L11: 0 | M11: 0.6 | N11: 0.8 | O11: 1.05 | P11: 1.1 | Q11: INTERIOR | R11: 5 | S11: 9 | T11: Ciudad principal | U11: Light Production Digital Business | V11: XEROX MEXICANA SA DE CV / XEROX MEXICANA | W11: QUERETARO | X11: 2019 | Y11: Qtr 2 | Z11: April | AA11: 25 | AB11: 0 | AC11: 136.5
A12: 03AG879544 | B12: 2019 | C12: Qtr 2 | D12: April | E12: 12 | F12: CORRECTIVO | G12: 2.1 | H12: Departmental Digital | I12: 655 | J12: 1365 | K12: 0 | L12: 0 | M12: 0.6 | N12: 0.8 | O12: 1.05 | P12: 1.1 | Q12: INTERIOR | R12: 5 | S12: 9 | T12: Ciudad principal | U12: Light Production Digital Business | V12: XEROX MEXICANA SA DE CV / XEROX MEXICANA | W12: JALISCO | X12: 2019 | Y12: Qtr 2 | Z12: April | AA12: 16 | AB12: 0 | AC12: 1030.25
A13: 03AG879544 | B13: 2019 | C13: Qtr 2 | D13: April | E13: 16 | F13: MANTENIMIENTO PREVENTIVO | G13: 0 | H13: Departmental Digital | I13: 655 | J13: 1365 | K13: 0 | L13: 0 | M13: 0.6 | N13: 0.8 | O13: 1.05 | P13: 1.1 | Q13: INTERIOR | R13: 5 | S13: 9 | T13: Ciudad principal | U13: Light Production Digital Business | V13: XEROX MEXICANA SA DE CV / XEROX MEXICANA | W13: JALISCO | X13: 2019 | Y13: Qtr 2 | Z13: April | AA13: 16 | AB13: 0 | AC13: 1365
A14: 03AG879576 | B14: 2019 | C14: Qtr 2 | D14: April | E14: 26 | F14: CORRECTIVO | G14: 0.8666667 | H14: Departmental Digital | I14: 655 | J14: 1365 | K14: 0 | L14: 0 | M14: 0.6 | N14: 0.8 | O14: 1.05 | P14: 1.1 | Q14: INTERIOR | R14: 5 | S14: 9 | T14: Ciudad principal | U14: Light Production Digital Business | V14: XEROX MEXICANA SA DE CV / XEROX MEXICANA | W14: GUANAJUATO | X14: 2019 | Y14: Qtr 2 | Z14: April | AA14: 26 | AB14: 0 | AC14: 136.5
... A52: 08TB572633 | B52: 2019 | C52: Qtr 2 | D52: April | E52: 10 | F52: CORRECTIVO | G52: 1.183333 | H52: A3 Office Color Laser MFPs | I52: 655 | J52: 1365 | K52: 0 | L52: 0 | M52: 0.6 | N52: 0.8 | O52: 1.05 | P52: 1.1 | Q52: INTERIOR | R52: 5 | S52: 9 | T52: Ciudad principal | U52: A3 Office Color Laser MFPs | V52: XEROX MEXICANA SA DE CV / XEROX MEXICANA | W52: CHIHUAHUA | X52: 2019 | Y52: Qtr 2 | Z52: April | AA52: 15 | AB52: 345 | AC52: 136.5
A53: 08TB608554 | B53: 2019 | C53: Qtr 2 | D53: April | E53: 3 | F53: CORRECTIVO | G53: 0.95 | I53: NA | J53: NA | K53: NA | L53: NA | M53: NA | N53: NA | O53: NA | P53: NA | R53: NA | S53: NA | U53: A3 Office Color Laser MFPs | V53: XEROX MEXICANA SA DE CV / XEROX MEXICANA | W53: NUEVO LEON | X53: 2019 | Y53: Qtr 2 | Z53: April | AA53: 5 | AB53: 0 | AC53: 1501.5
A54: 09HB317209 | B54: 2019 | C54: Qtr 2 | D54: April | E54: 23 | F54: CORRECTIVO | G54: 0.8833333 | H54: A4 Mono MFPs | I54: 468 | J54: 715 | K54: 0 | L54: 0 | M54: 0 | N54: 0.6 | O54: 0.8 | P54: 1.05 | Q54: INTERIOR | R54: 5 | S54: 9 | T54: Ciudad principal | U54: A4 Mono MFPs | V54: XEROX MEXICANA SA DE CV / XEROX MEXICANA | W54: NUEVO LEON | X54: 2019 | Y54: Qtr 2 | Z54: April | AA54: 23 | AB54: 189 | AC54: 35.75
A55: 09HB317209 | B55: 2019 | C55: Qtr 2 | D55: April | E55: 26 | F55: CORRECTIVO | G55: 1.066667 | H55: A4 Mono MFPs | I55: 468 | J55: 715 | K55: 0 | L55: 0 | M55: 0 | N55: 0.6 | O55: 0.8 | P55: 1.05 | Q55: INTERIOR | R55: 5 | S55: 9 | T55: Ciudad principal | U55: A4 Mono MFPs | V55: XEROX MEXICANA SA DE CV / XEROX MEXICANA | W55: NUEVO LEON | X55: 2019 | Y55: Qtr 2 | Z55: April | AA55: 26 | AB55: 3 | AC55: -715
A56: 09HB318209 | B56: 2019 | C56: Qtr 2 | D56: April | E56: 11 | F56: CORRECTIVO | G56: 0.7666667 | H56: A4 Mono MFPs | I56: 468 | J56: 715 | K56: 0 | L56: 0 | M56: 0 | N56: 0.6 | O56: 0.8 | P56: 1.05 | Q56: INTERIOR | R56: 5 | S56: 9 | T56: Otras | U56: A4 Mono MFPs | V56: XEROX MEXICANA SA DE CV / XEROX MEXICANA | W56: COAHUILA | X56: 2019 | Y56: Qtr 2 | Z56: April | AA56: 11 | AB56: 0 | AC56: 35.75
A57: 09HB320584 | B57: 2019 | C57: Qtr 2 | D57: April | E57: 9 | F57: CORRECTIVO | G57: 3.25 | I57: NA | J57: NA | K57: NA | L57: NA | M57: NA | N57: NA | O57: NA | P57: NA | R57: NA | S57: NA | U57: A4 Mono MFPs | V57: XEROX MEXICANA SA DE CV / XEROX MEXICANA | W57: CHIHUAHUA | X57: 2019 | Y57: Qtr 2 | Z57: April | AA57: 10 | AB57: 0 | AC57: 750.75
A58: 09HB320824 | B58: 2019 | C58: Qtr 2 | D58: April | E58: 12 | F58: CORRECTIVO | G58: 1.183333 | H58: A4 Mono MFPs | I58: 468 | J58: 715 | K58: 0 | L58: 0 | M58: 0 | N58: 0.6 | O58: 0.8 | P58: 1.05 | Q58: INTERIOR | R58: 5 | S58: 9 | T58: Ciudad principal | U58: A4 Mono MFPs | V58: XEROX MEXICANA SA DE CV / XEROX MEXICANA | W58: NUEVO LEON | X58: 2019 | Y58: Qtr 2 | Z58: April | AA58: 12 | AB58: 0 | AC58: 35.75
A59: 09HB320873 | B59: 2019 | C59: Qtr 2 | D59: April | E59: 8 | F59: CORRECTIVO | G59: 1.9 | H59: A4 Mono MFPs | I59: 468 | J59: 715 | K59: 0 | L59: 0 | M59: 0 | N59: 0.6 | O59: 0.8 | P59: 1.05 | Q59: INTERIOR | R59: 5 | S59: 9 | T59: Ciudad principal | U59: A4 Mono MFPs | V59: XEROX MEXICANA SA DE CV / XEROX MEXICANA | W59: ESTADO DE MEXICO | X59: 2019 | Y59: Qtr 2 | Z59: April | AA59: 8 | AB59: 257 | AC59: 459.10526
A60: 09HB321202 | B60: 2019 | C60: Qtr 2 | D60: April | E60: 8 | F60: CORRECTIVO | G60: 0.3833333 | H60: A4 Mono MFPs | I60: 468 | J60: 715 | K60: 0 | L60: 0 | M60: 0 | N60: 0.6 | O60: 0.8 | P60: 1.05 | Q60: INTERIOR | R60: 5 | S60: 9 | T60: Otras | U60: A4 Mono MFPs | V60: XEROX MEXICANA SA DE CV / XEROX MEXICANA | W60: COAHUILA | X60: 2019 | Y60: Qtr 2 | Z60: April | AA60: 8 | AB60: 0 | AC60: 35.75
A61: 09HB321394 | B61: 2019 | C61: Qtr 2 | D61: April | E61: 3 | F61: CORRECTIVO | G61: 8.133333 | H61: A4 Mono MFPs | I61: 468 | J61: 715 | K61: 0 | L61: 0 | M61: 0 | N61: 0.6 | O61: 0.8 | P61: 1.05 | Q61: INTERIOR | R61: 5 | S61: 9 | T61: Otras | U61: A4 Mono MFPs | V61: XEROX MEXICANA SA DE CV / XEROX MEXICANA | W61: CHIHUAHUA | X61: 2019 | Y61: Qtr 2 | Z61: April | AA61: 4 | AB61: 317 | AC61: 731.70286
A62: 09HB321575 | B62: 2019 | C62: Qtr 1 | D62: March | E62: 31 | F62: MANTENIMIENTO PREVENTIVO | G62: 0.1666667 | H62: A4 Mono MFPs | I62: 468 | J62: 715 | K62: 0 | L62: 0 | M62: 0 | N62: 0.6 | O62: 0.8 | P62: 1.05 | Q62: INTERIOR | R62: 5 | S62: 9 | T62: Ciudad principal | U62: A4 Mono MFPs | V62: XEROX MEXICANA SA DE CV / XEROX MEXICANA | W62: CHIHUAHUA | X62: 2019 | Y62: Qtr 2 | Z62: April | AA62: 1 | AB62: 24 | AC62: 715
A63: 09HB321576 | B63: 2019 | C63: Qtr 2 | D63: April | E63: 25 | F63: CORRECTIVO | G63: 0.5666667 | H63: A4 Mono MFPs | I63: 468 | J63: 715 | K63: 0 | L63: 0 | M63: 0 | N63: 0.6 | O63: 0.8 | P63: 1.05 | Q63: INTERIOR | R63: 5 | S63: 9 | T63: Ciudad principal | U63: A4 Mono MFPs | V63: XEROX MEXICANA SA DE CV / XEROX MEXICANA | W63: NUEVO LEON | X63: 2019 | Y63: Qtr 2 | Z63: April | AA63: 26 | AB63: 94 | AC63: 35.75
A64: 09HB321623 | B64: 2019 | C64: Qtr 2 | D64: April | E64: 26 | F64: CORRECTIVO | G64: 0.7666667 | H64: A4 Mono MFPs | I64: 468 | J64: 715 | K64: 0 | L64: 0 | M64: 0 | N64: 0.6 | O64: 0.8 | P64: 1.05 | Q64: INTERIOR | R64: 5 | S64: 9 | T64: Ciudad principal | U64: A4 Mono MFPs | V64: XEROX MEXICANA SA DE CV / XEROX MEXICANA | W64: NUEVO LEON | X64: 2019 | Y64: Qtr 2 | Z64: April | AA64: 26 | AB64: 7257600 | AC64: 35.75
A65: 09HB321648 | B65: 2019 | C65: Qtr 2 | D65: April | E65: 17 | F65: CORRECTIVO | G65: 1.266667 | H65: A4 Mono MFPs | I65: 468 | J65: 715 | K65: 0 | L65: 0 | M65: 0 | N65: 0.6 | O65: 0.8 | P65: 1.05 | Q65: INTERIOR | R65: 5 | S65: 9 | T65: Ciudad principal | U65: A4 Mono MFPs | V65: XEROX MEXICANA SA DE CV / XEROX MEXICANA | W65: NUEVO LEON | X65: 2019 | Y65: Qtr 2 | Z65: April | AA65: 17 | AB65: 0 | AC65: 35.75
A66: 09HB325731 | B66: 2019 | C66: Qtr 2 | D66: April | E66: 8 | F66: CORRECTIVO | G66: 1.133333 | H66: A4 Mono MFPs | I66: 468 | J66: 715 | K66: 0 | L66: 0 | M66: 0 | N66: 0.6 | O66: 0.8 | P66: 1.05 | Q66: INTERIOR | R66: 5 | S66: 9 | T66: Ciudad principal | U66: A4 Mono MFPs | V66: XEROX MEXICANA SA DE CV / XEROX MEXICANA | W66: NUEVO LEON | X66: 2019 | Y66: Qtr 2 | Z66: April | AA66: 8 | AB66: 341 | AC66: 35.75
A67: 09HB325846 | B67: 2019 | C67: Qtr 2 | D67: April | E67: 24 | F67: CORRECTIVO | G67: 3.333333 | H67: A4 Mono MFPs | I67: 468 | J67: 715 | K67: 0 | L67: 0 | M67: 0 | N67: 0.6 | O67: 0.8 | P67: 1.05 | Q67: INTERIOR | R67: 5 | S67: 9 | T67: Otras | U67: A4 Mono MFPs | V67: XEROX MEXICANA SA DE CV / XEROX MEXICANA | W67: TAMAULIPAS | X67: 2019 | Y67: Qtr 2 | Z67: April | AA67: 25 | AB67: 357 | AC67: 446.87495
A68: 09HB325909 | B68: 2019 | C68: Qtr 2 | D68: April | E68: 17 | F68: CORRECTIVO | G68: 2.2 | H68: A4 Mono MFPs | I68: 468 | J68: 715 | K68: 0 | L68: 0 | M68: 0 | N68: 0.6 | O68: 0.8 | P68: 1.05 | Q68: INTERIOR | R68: 5 | S68: 9 | T68: Otras | U68: A4 Mono MFPs | V68: XEROX MEXICANA SA DE CV / XEROX MEXICANA | W68: NUEVO LEON | X68: 2019 | Y68: Qtr 2 | Z68: April | AA68: 17 | AB68: 0 | AC68: 35.75
A69: 09HB328020 | B69: 2019 | C69: Qtr 2 | D69: April | E69: 5 | F69: CORRECTIVO | G69: 1.566667 | H69: A4 Mono MFPs | I69: 468 | J69: 715 | K69: 0 | L69: 0 | M69: 0 | N69: 0.6 | O69: 0.8 | P69: 1.05 | Q69: INTERIOR | R69: 5 | S69: 9 | T69: Ciudad principal | U69: A4 Mono MFPs | V69: XEROX MEXICANA SA DE CV / XEROX MEXICANA | W69: QUERETARO | X69: 2019 | Y69: Qtr 2 | Z69: April | AA69: 5 | AB69: 0 | AC69: 35.75
... A107: 0A1H022379 | B107: 2019 | C107: Qtr 2 | D107: April | E107: 25 | F107: CORRECTIVO | G107: 1.416667 | H107: WF Mono Systems and Legacy Color | I107: 803 | J107: 1573 | K107: 0.2 | L107: 0.6 | M107: 0.8 | N107: 1.05 | O107: 1.1 | P107: 1.15 | Q107: INTERIOR | R107: 4 | S107: 6 | T107: Ciudad principal | U107: WF Mono Systems and Legacy Color | V107: XEROX MEXICANA SA DE CV / XEROX MEXICANA | W107: CHIHUAHUA | X107: 2019 | Y107: Qtr 2 | Z107: April | AA107: 25 | AB107: 185 | AC107: 1091.8473
A108: 0A1H022391 | B108: 2019 | C108: Qtr 2 | D108: April | E108: 4 | F108: CORRECTIVO | G108: 1.766667 | I108: NA | J108: NA | K108: NA | L108: NA | M108: NA | N108: NA | O108: NA | P108: NA | R108: NA | S108: NA | U108: WF Mono Systems and Legacy Color | V108: XEROX MEXICANA SA DE CV / XEROX MEXICANA | W108: SAN LUIS POTOSI | X108: 2019 | Y108: Qtr 2 | Z108: April | AA108: 5 | AB108: 0 | AC108: 235.95
A109: 0A1H022401 | B109: 2019 | C109: Qtr 2 | D109: April | E109: 11 | F109: CORRECTIVO | G109: 0.4833333 | H109: WF Mono Systems and Legacy Color | I109: 803 | J109: 1573 | K109: 0.2 | L109: 0.6 | M109: 0.8 | N109: 1.05 | O109: 1.1 | P109: 1.15 | Q109: INTERIOR | R109: 4 | S109: 6 | T109: Ciudad principal | U109: WF Mono Systems and Legacy Color | V109: XEROX MEXICANA SA DE CV / XEROX MEXICANA | W109: QUERETARO | X109: 2019 | Y109: Qtr 2 | Z109: April | AA109: 12 | AB109: 0 | AC109: 235.95
A110: 0A1H022530 | B110: 2019 | C110: Qtr 2 | D110: April | E110: 15 | F110: CORRECTIVO | G110: 1.116667 | H110: WF Mono Systems and Legacy Color | I110: 803 | J110: 1573 | K110: 0.2 | L110: 0.6 | M110: 0.8 | N110: 1.05 | O110: 1.1 | P110: 1.15 | Q110: INTERIOR | R110: 4 | S110: 6 | T110: Ciudad principal | U110: WF Mono Systems and Legacy Color | V110: XEROX MEXICANA SA DE CV / XEROX MEXICANA | W110: JALISCO | X110: 2019 | Y110: Qtr 2 | Z110: April | AA110: 15 | AB110: 0 | AC110: 235.95
A111: 0A1H022532 | B111: 2019 | C111: Qtr 2 | D111: April | E111: 25 | F111: MANTENIMIENTO PREVENTIVO | G111: 0 | H111: WF Mono Systems and Legacy Color | I111: 803 | J111: 1573 | K111: 0.2 | L111: 0.6 | M111: 0.8 | N111: 1.05 | O111: 1.1 | P111: 1.15 | Q111: INTERIOR | R111: 4 | S111: 6 | T111: Ciudad principal | U111: WF Mono Systems and Legacy Color | V111: XEROX MEXICANA SA DE CV / XEROX MEXICANA | W111: JALISCO | X111: 2019 | Y111: Qtr 2 | Z111: April | AA111: 25 | AB111: 0 | AC111: 1573
A112: 0A2T199725 | B112: 2019 | C112: Qtr 2 | D112: April | E112: 25 | F112: CORRECTIVO | G112: 1.983333 | H112: A4 Mono MFPs | I112: 468 | J112: 715 | K112: 0 | L112: 0 | M112: 0 | N112: 0.6 | O112: 0.8 | P112: 1.05 | Q112: INTERIOR | R112: 5 | S112: 9 | T112: Ciudad principal | U112: A4 Mono MFPs | V112: XEROX MEXICANA SA DE CV / XEROX MEXICANA | W112: JALISCO | X112: 2019 | Y112: Qtr 2 | Z112: April | AA112: 26 | AB112: 0 | AC112: 478.86967
A113: 0A2T199940 | B113: 2019 | C113: Qtr 2 | D113: April | E113: 4 | F113: CORRECTIVO | G113: 1.5 | H113: A4 Mono MFPs | I113: 468 | J113: 715 | K113: 0 | L113: 0 | M113: 0 | N113: 0.6 | O113: 0.8 | P113: 1.05 | Q113: INTERIOR | R113: 5 | S113: 9 | T113: Ciudad principal | U113: A4 Mono MFPs | V113: XEROX MEXICANA SA DE CV / XEROX MEXICANA | W113: ESTADO DE MEXICO | X113: 2019 | Y113: Qtr 2 | Z113: April | AA113: 11 | AB113: 35 | AC113: -143
A114: 0A2T200060 | B114: 2019 | C114: Qtr 2 | D114: April | E114: 17 | F114: CORRECTIVO | G114: 3.133333 | H114: A4 Mono MFPs | I114: 468 | J114: 715 | K114: 0 | L114: 0 | M114: 0 | N114: 0.6 | O114: 0.8 | P114: 1.05 | Q114: INTERIOR | R114: 5 | S114: 9 | T114: Ciudad principal | U114: A4 Mono MFPs | V114: XEROX MEXICANA SA DE CV / XEROX MEXICANA | W114: JALISCO | X114: 2019 | Y114: Qtr 2 | Z114: April | AA114: 17 | AB114: 0 | AC114: 644.26061
...

Sheet Hoja2
A1: N° de serie | B1: Year | C1: Quarter | D1: Month | E1: Day | F1: Categoría | G1: T. respuesta | H1: Business Team | I1: Pago Base CDMX y área metropolitana | J1: Pago Base Interior | K1: menos de 3 días | L1: entre 3 y 6 días | M1: entre 7 y 15 días | N1: entre 16 y 30 días | O1: entre 31 y 59 días | P1: 60 días o más | Q1: REGION | R1: TR Ciudades principales | S1: TR Otras ciudades | T1: Loc TR | U1: familia matriz global | V1: Cliente | W1: Ruta | X1: Year.1 | Y1: Quarter.1 | Z1: Month.1 | AA1: Day.1 | AB1: time | AC1: viabilidad | AD1: veces_obj | AE1: pagofinal | AF1: pago MIF | AG1: dias MIF | AH1: Fiabilidad MIF | AI1: vece obj MIF | AJ1: familia MIF | AK1: pagos iguales | AL1: dias iguales | AM1: fiabilidad igual | AN1: veces obj iguales | AO1: familias iguales
A2: 9HB334888 | B2: 2019 | C2: Qtr 1 | D2: March | E2: 4 | F2: INSTALACION NUEVA | G2: 0 | I2: NA | J2: NA | K2: NA | L2: NA | M2: NA | N2: NA | O2: NA | P2: NA | R2: NA | S2: NA | U2: A4 Mono MFPs | V2: XEROX MEXICANA SA DE CV / XEROX MEXICANA | W2: ESTADO DE MEXICO | X2: 2019 | Y2: Qtr 2 | Z2: April | AA2: 4 | AB2: 0 | AC2: 1.1 | AD2: 0 | AE2: 715 | AF2: =VLOOKUP(A2,[1]DETALLE!$A$1:$AK$841,37,FALSE) -> 1501.5 | AG2: =VLOOKUP(A2,[1]DETALLE!$A$1:$AK$841,16,FALSE) -> 88 | AH2: =VLOOKUP(A2,[1]DETALLE!$A$1:$AK$841,22,FALSE) -> 1.1 | AI2: =VLOOKUP(A2,[1]DETALLE!$A$1:$AK$841,27,FALSE) -> 0.22 | AJ2: =VLOOKUP(A2,[1]DETALLE!$A$1:$AK$841,18,FALSE) -> Departmental Digital | AK2: =IF(AE2=AF2,1,0) -> 0 | AL2: =IF(AB2=AG2,1,0) -> 0 | AM2: =IF(AC2=AH2,1,0) -> 1 | AN2: =IF(AD2=AI2,1,0) -> 0 | AO2: =IF(H2=AJ2,1,0) -> 0
A3: 0AGD461524 | B3: 2019 | C3: Qtr 1 | D3: March | E3: 5 | F3: CORRECTIVO | G3: 2.866667 | I3: NA | J3: NA | K3: NA | L3: NA | M3: NA | N3: NA | O3: NA | P3: NA | R3: NA | S3: NA | U3: A4 Color Laser MFPs | V3: XEROX MEXICANA SA DE CV / XEROX MEXICANA | W3: NUEVO LEON | X3: 2019 | Y3: Qtr 2 | Z3: April | AA3: 22 | AB3: 12 | AC3: 1.1 | AD3: 0 | AE3: 0 | AF3: =VLOOKUP(A3,[1]DETALLE!$A$1:$AK$841,37,FALSE) -> 1092 | AG3: =VLOOKUP(A3,[1]DETALLE!$A$1:$AK$841,16,FALSE) -> 17 | AH3: =VLOOKUP(A3,[1]DETALLE!$A$1:$AK$841,22,FALSE) -> 0.8 | AI3: =VLOOKUP(A3,[1]DETALLE!$A$1:$AK$841,27,FALSE) -> 0.196 | AJ3: =VLOOKUP(A3,[1]DETALLE!$A$1:$AK$841,18,FALSE) -> A3 Office Color Laser MFPs | AK3: =IF(AE3=AF3,1,0) -> 0 | AL3: =IF(AB3=AG3,1,0) -> 0 | AM3: =IF(AC3=AH3,1,0) -> 0 | AN3: =IF(AD3=AI3,1,0) -> 0 | AO3: =IF(H3=AJ3,1,0) -> 0
A4: 0BG2951668 | B4: 2019 | C4: Qtr 1 | D4: March | E4: 11 | F4: MANTENIMIENTO PREVENTIVO | G4: 0 | H4: Light Production Digital Business | I4: 803 | J4: 1573 | K4: 0.2 | L4: 0.6 | M4: 0.8 | N4: 1.05 | O4: 1.1 | P4: 1.15 | Q4: INTERIOR | R4: 4 | S4: 6 | T4: Ciudad principal | U4: High End Cut Sheet | V4: XEROX MEXICANA SA DE CV / XEROX MEXICANA | W4: NUEVO LEON | X4: 2019 | Y4: Qtr 2 | Z4: April | AA4: 11 | AB4: 14 | AC4: 0 | AD4: 0 | AE4: 1573 | AF4: =VLOOKUP(A4,[1]DETALLE!$A$1:$AK$841,37,FALSE) -> 1651.65 | AG4: =VLOOKUP(A4,[1]DETALLE!$A$1:$AK$841,16,FALSE) -> 18 | AH4: =VLOOKUP(A4,[1]DETALLE!$A$1:$AK$841,22,FALSE) -> 1.05 | AI4: =VLOOKUP(A4,[1]DETALLE!$A$1:$AK$841,27,FALSE) -> 0.555 | AJ4: =VLOOKUP(A4,[1]DETALLE!$A$1:$AK$841,18,FALSE) -> WF Mono Systems and Legacy Color | AK4: =IF(AE4=AF4,1,0) -> 0 | AL4: =IF(AB4=AG4,1,0) -> 0 | AM4: =IF(AC4=AH4,1,0) -> 0 | AN4: =IF(AD4=AI4,1,0) -> 0 | AO4: =IF(H4=AJ4,1,0) -> 0
A5: 0BPB110617 | B5: 2019 | C5: Qtr 1 | D5: March | E5: 13 | F5: CORRECTIVO | G5: 2.216667 | I5: NA | J5: NA | K5: NA | L5: NA | M5: NA | N5: NA | O5: NA | P5: NA | R5: NA | S5: NA | U5: High End Cut Sheet | V5: XEROX MEXICANA SA DE CV / XEROX MEXICANA | W5: JALISCO | X5: 2019 | Y5: Qtr 2 | Z5: April | AA5: 1 | AB5: 13 | AC5: 1.1 | AD5: 0 | AE5: 107.25 | AF5: =VLOOKUP(A5,[1]DETALLE!$A$1:$AK$841,37,FALSE) -> 750.75 | AG5: =VLOOKUP(A5,[1]DETALLE!$A$1:$AK$841,16,FALSE) -> 294 | AH5: =VLOOKUP(A5,[1]DETALLE!$A$1:$AK$841,22,FALSE) -> 1.05 | AI5: =VLOOKUP(A5,[1]DETALLE!$A$1:$AK$841,27,FALSE) -> 0 | AJ5: =VLOOKUP(A5,[1]DETALLE!$A$1:$AK$841,18,FALSE) -> Entry Mono Printers | AK5: =IF(AE5=AF5,1,0) -> 0 | AL5: =IF(AB5=AG5,1,0) -> 0 | AM5: =IF(AC5=AH5,1,0) -> 0 | AN5: =IF(AD5=AI5,1,0) -> 1 | AO5: =IF(H5=AJ5,1,0) -> 0
A6: 0BPB110653 | B6: 2019 | C6: Qtr 1 | D6: March | E6: 13 | F6: CORRECTIVO | G6: 4.233333 | I6: NA | J6: NA | K6: NA | L6: NA | M6: NA | N6: NA | O6: NA | P6: NA | R6: NA | S6: NA | U6: High End Cut Sheet | V6: XEROX MEXICANA SA DE CV / XEROX MEXICANA | W6: JALISCO | X6: 2019 | Y6: Qtr 2 | Z6: April | AA6: 3 | AB6: 35 | AC6: 1.1 | AD6: 0 | AE6: 321.75 | AF6: =VLOOKUP(A6,[1]DETALLE!$A$1:$AK$841,37,FALSE) -> 1730.3 | AG6: =VLOOKUP(A6,[1]DETALLE!$A$1:$AK$841,16,FALSE) -> 50 | AH6: =VLOOKUP(A6,[1]DETALLE!$A$1:$AK$841,22,FALSE) -> 1.1 | AI6: =VLOOKUP(A6,[1]DETALLE!$A$1:$AK$841,27,FALSE) -> 0.505 | AJ6: =VLOOKUP(A6,[1]DETALLE!$A$1:$AK$841,18,FALSE) -> Entry Production Color Low/Mid | AK6: =IF(AE6=AF6,1,0) -> 0 | AL6: =IF(AB6=AG6,1,0) -> 0 | AM6: =IF(AC6=AH6,1,0) -> 1 | AN6: =IF(AD6=AI6,1,0) -> 0 | AO6: =IF(H6=AJ6,1,0) -> 0
A7: 0VGW686533 | B7: 2019 | C7: Qtr 1 | D7: March | E7: 15 | F7: CORRECTIVO | G7: 0.25 | H7: A3 Professional Color Laser MFPs | I7: 655 | J7: 1365 | K7: 0 | L7: 0 | M7: 0.6 | N7: 0.8 | O7: 1.05 | P7: 1.1 | Q7: INTERIOR | R7: 5 | S7: 9 | T7: Ciudad principal | U7: Entry Production Color Low/Mid | V7: XEROX MEXICANA SA DE CV / XEROX MEXICANA | W7: CHIHUAHUA | X7: 2019 | Y7: Qtr 2 | Z7: April | AA7: 9 | AB7: 29 | AC7: 0.8 | AD7: 0.05 | AE7: 1092 | AF7: =VLOOKUP(A7,[1]DETALLE!$A$1:$AK$841,37,FALSE) -> 452.2375 | AG7: =VLOOKUP(A7,[1]DETALLE!$A$1:$AK$841,16,FALSE) -> 5 | AH7: =VLOOKUP(A7,[1]DETALLE!$A$1:$AK$841,22,FALSE) -> 0.6 | AI7: =VLOOKUP(A7,[1]DETALLE!$A$1:$AK$841,27,FALSE) -> 2.25 | AJ7: =VLOOKUP(A7,[1]DETALLE!$A$1:$AK$841,18,FALSE) -> Light Production Digital Business | AK7: =IF(AE7=AF7,1,0) -> 0 | AL7: =IF(AB7=AG7,1,0) -> 0 | AM7: =IF(AC7=AH7,1,0) -> 0 | AN7: =IF(AD7=AI7,1,0) -> 0 | AO7: =IF(H7=AJ7,1,0) -> 0
A8: 0BG0971716 | B8: 2019 | C8: Qtr 1 | D8: March | E8: 20 | F8: CORRECTIVO | G8: 1.183333 | H8: Light Production Digital Business | I8: 803 | J8: 1573 | K8: 0.2 | L8: 0.6 | M8: 0.8 | N8: 1.05 | O8: 1.1 | P8: 1.15 | Q8: INTERIOR | R8: 4 | S8: 6 | T8: Ciudad principal | U8: High End Cut Sheet | V8: XEROX MEXICANA SA DE CV / XEROX MEXICANA | W8: NUEVO LEON | X8: 2019 | Y8: Qtr 2 | Z8: April | AA8: 3 | AB8: 49 | AC8: 1.1 | AD8: 0.29583325 | AE8: 1730.3 | AF8: =VLOOKUP(A8,[1]DETALLE!$A$1:$AK$841,37,FALSE) -> 1730.3 | AG8: =VLOOKUP(A8,[1]DETALLE!$A$1:$AK$841,16,FALSE) -> 37 | AH8: =VLOOKUP(A8,[1]DETALLE!$A$1:$AK$841,22,FALSE) -> 1.1 | AI8: =VLOOKUP(A8,[1]DETALLE!$A$1:$AK$841,27,FALSE) -> 0.5925 | AJ8: =VLOOKUP(A8,[1]DETALLE!$A$1:$AK$841,18,FALSE) -> Light Production Digital Business | AK8: =IF(AE8=AF8,1,0) -> 1 | AL8: =IF(AB8=AG8,1,0) -> 0 | AM8: =IF(AC8=AH8,1,0) -> 1 | AN8: =IF(AD8=AI8,1,0) -> 0 | AO8: =IF(H8=AJ8,1,0) -> 1
A9: 0EX9310036 | B9: 2019 | C9: Qtr 1 | D9: March | E9: 21 | F9: CORRECTIVO | G9: 1.666667 | H9: Departmental Digital | I9: 655 | J9: 1365 | K9: 0 | L9: 0 | M9: 0.6 | N9: 0.8 | O9: 1.05 | P9: 1.1 | Q9: INTERIOR | R9: 5 | S9: 9 | T9: Ciudad principal | U9: Departmental Digital | V9: XEROX MEXICANA SA DE CV / XEROX MEXICANA | W9: TAMAULIPAS | X9: 2019 | Y9: Qtr 2 | Z9: April | AA9: 5 | AB9: 48 | AC9: 1.05 | AD9: 0.3333334 | AE9: 1433.25 | AF9: =VLOOKUP(A9,[1]DETALLE!$A$1:$AK$841,37,FALSE) -> 1258.4 | AG9: =VLOOKUP(A9,[1]DETALLE!$A$1:$AK$841,16,FALSE) -> 14 | AH9: =VLOOKUP(A9,[1]DETALLE!$A$1:$AK$841,22,FALSE) -> 0.8 | AI9: =VLOOKUP(A9,[1]DETALLE!$A$1:$AK$841,27,FALSE) -> 0 | AJ9: =VLOOKUP(A9,[1]DETALLE!$A$1:$AK$841,18,FALSE) -> Entry Production Color Low/Mid | AK9: =IF(AE9=AF9,1,0) -> 0 | AL9: =IF(AB9=AG9,1,0) -> 0 | AM9: =IF(AC9=AH9,1,0) -> 0 | AN9: =IF(AD9=AI9,1,0) -> 0 | AO9: =IF(H9=AJ9,1,0) -> 0
A10: 0RXD138712 | B10: 2019 | C10: Qtr 1 | D10: March | E10: 21 | F10: CORRECTIVO | G10: 0.3166667 | I10: NA | J10: NA | K10: NA | L10: NA | M10: NA | N10: NA | O10: NA | P10: NA | R10: NA | S10: NA | U10: Departmental Digital | V10: XEROX MEXICANA SA DE CV / XEROX MEXICANA | W10: COAHUILA | X10: 2019 | Y10: Qtr 2 | Z10: April | AA10: 5 | AB10: 58 | AC10: 1.1 | AD10: 0 | AE10: 962 | AF10: =VLOOKUP(A10,[1]DETALLE!$A$1:$AK$841,37,FALSE) -> #N/A | AG10: =VLOOKUP(A10,[1]DETALLE!$A$1:$AK$841,16,FALSE) -> #N/A | AH10: =VLOOKUP(A10,[1]DETALLE!$A$1:$AK$841,22,FALSE) -> #N/A | AI10: =VLOOKUP(A10,[1]DETALLE!$A$1:$AK$841,27,FALSE) -> #N/A | AJ10: =VLOOKUP(A10,[1]DETALLE!$A$1:$AK$841,18,FALSE) -> #N/A | AK10: =IF(AE10=AF10,1,0) -> #N/A | AL10: =IF(AB10=AG10,1,0) -> #N/A | AM10: =IF(AC10=AH10,1,0) -> #N/A | AN10: =IF(AD10=AI10,1,0) -> #N/A | AO10: =IF(H10=AJ10,1,0) -> #N/A
A11: 0BG2948893 | B11: 2019 | C11: Qtr 1 | D11: March | E11: 22 | F11: CORRECTIVO | G11: 2.65 | H11: Light Production Digital Business | I11: 803 | J11: 1573 | K11: 0.2 | L11: 0.6 | M11: 0.8 | N11: 1.05 | O11: 1.1 | P11: 1.15 | Q11: INTERIOR | R11: 4 | S11: 6 | T11: Ciudad principal | U11: High End Cut Sheet | V11: XEROX MEXICANA SA DE CV / XEROX MEXICANA | W11: NUEVO LEON | X11: 2019 | Y11: Qtr 2 | Z11: April | AA11: 4 | AB11: 15 | AC11: 0.8 | AD11: 0.6625 | AE11: 1258.4 | AF11: =VLOOKUP(A11,[1]DETALLE!$A$1:$AK$841,37,FALSE) -> 0 | AG11: =VLOOKUP(A11,[1]DETALLE!$A$1:$AK$841,16,FALSE) -> 10 | AH11: =VLOOKUP(A11,[1]DETALLE!$A$1:$AK$841,22,FALSE) -> 0 | AI11: =VLOOKUP(A11,[1]DETALLE!$A$1:$AK$841,27,FALSE) -> 0.216 | AJ11: =VLOOKUP(A11,[1]DETALLE!$A$1:$AK$841,18,FALSE) -> A4 Color Laser MFPs | AK11: =IF(AE11=AF11,1,0) -> 0 | AL11: =IF(AB11=AG11,1,0) -> 0 | AM11: =IF(AC11=AH11,1,0) -> 0 | AN11: =IF(AD11=AI11,1,0) -> 0 | AO11: =IF(H11=AJ11,1,0) -> 0
A12: 0LX5697800 | B12: 2019 | C12: Qtr 1 | D12: March | E12: 22 | F12: CORRECTIVO | G12: 1.066667 | H12: A3 Office Color Laser MFPs | I12: 655 | J12: 1365 | K12: 0 | L12: 0 | M12: 0.6 | N12: 0.8 | O12: 1.05 | P12: 1.1 | Q12: INTERIOR | R12: 5 | S12: 9 | T12: Ciudad principal | U12: A3 Office Color Laser MFPs | V12: XEROX MEXICANA SA DE CV / XEROX MEXICANA | W12: CHIHUAHUA | X12: 2019 | Y12: Qtr 2 | Z12: April | AA12: 4 | AB12: 17 | AC12: 0.8 | AD12: 0.2133334 | AE12: 1092 | AF12: =VLOOKUP(A12,[1]DETALLE!$A$1:$AK$841,37,FALSE) -> 1258.4 | AG12: =VLOOKUP(A12,[1]DETALLE!$A$1:$AK$841,16,FALSE) -> 7 | AH12: =VLOOKUP(A12,[1]DETALLE!$A$1:$AK$841,22,FALSE) -> 0.8 | AI12: =VLOOKUP(A12,[1]DETALLE!$A$1:$AK$841,27,FALSE) -> 0.3125 | AJ12: =VLOOKUP(A12,[1]DETALLE!$A$1:$AK$841,18,FALSE) -> Light Production Digital Business | AK12: =IF(AE12=AF12,1,0) -> 0 | AL12: =IF(AB12=AG12,1,0) -> 0 | AM12: =IF(AC12=AH12,1,0) -> 1 | AN12: =IF(AD12=AI12,1,0) -> 0 | AO12: =IF(H12=AJ12,1,0) -> 0
A13: 0AB9779149 | B13: 2019 | C13: Qtr 1 | D13: March | E13: 25 | F13: CORRECTIVO | G13: 0 | H13: Color Laser Printers | I13: 468 | J13: 715 | K13: 0 | L13: 0 | M13: 0 | N13: 0.6 | O13: 0.8 | P13: 1.05 | Q13: INTERIOR | R13: 5 | S13: 9 | T13: Ciudad principal | U13: Departmental Digital | V13: XEROX MEXICANA SA DE CV / XEROX MEXICANA | W13: QUERETARO | X13: 2019 | Y13: Qtr 2 | Z13: April | AA13: 8 | AB13: 194 | AC13: 1.05 | AD13: 0 | AE13: 750.75 | AF13: =VLOOKUP(A13,[1]DETALLE!$A$1:$AK$841,37,FALSE) -> 750.75 | AG13: =VLOOKUP(A13,[1]DETALLE!$A$1:$AK$841,16,FALSE) -> 117 | AH13: =VLOOKUP(A13,[1]DETALLE!$A$1:$AK$841,22,FALSE) -> 1.05 | AI13: =VLOOKUP(A13,[1]DETALLE!$A$1:$AK$841,27,FALSE) -> 0.3 | AJ13: =VLOOKUP(A13,[1]DETALLE!$A$1:$AK$841,18,FALSE) -> A4 Color Laser MFPs | AK13: =IF(AE13=AF13,1,0) -> 1 | AL13: =IF(AB13=AG13,1,0) -> 0 | AM13: =IF(AC13=AH13,1,0) -> 1 | AN13: =IF(AD13=AI13,1,0) -> 0 | AO13: =IF(H13=AJ13,1,0) -> 0
A14: 0BG2949298 | B14: 2019 | C14: Qtr 1 | D14: March | E14: 25 | F14: CORRECTIVO | G14: 2.733333 | H14: Light Production Digital Business | I14: 803 | J14: 1573 | K14: 0.2 | L14: 0.6 | M14: 0.8 | N14: 1.05 | O14: 1.1 | P14: 1.15 | Q14: INTERIOR | R14: 4 | S14: 6 | T14: Ciudad principal | U14: High End Cut Sheet | V14: XEROX MEXICANA SA DE CV / XEROX MEXICANA | W14: ESTADO DE MEXICO | X14: 2019 | Y14: Qtr 2 | Z14: April | AA14: 2 | AB14: 14 | AC14: 0.8 | AD14: 0.68333325 | AE14: 1258.4 | AF14: =VLOOKUP(A14,[1]DETALLE!$A$1:$AK$841,37,FALSE) -> 1258.4 | AG14: =VLOOKUP(A14,[1]DETALLE!$A$1:$AK$841,16,FALSE) -> 14 | AH14: =VLOOKUP(A14,[1]DETALLE!$A$1:$AK$841,22,FALSE) -> 0.8 | AI14: =VLOOKUP(A14,[1]DETALLE!$A$1:$AK$841,27,FALSE) -> 0.1875 | AJ14: =VLOOKUP(A14,[1]DETALLE!$A$1:$AK$841,18,FALSE) -> Light Production Digital Business | AK14: =IF(AE14=AF14,1,0) -> 1 | AL14: =IF(AB14=AG14,1,0) -> 1 | AM14: =IF(AC14=AH14,1,0) -> 1 | AN14: =IF(AD14=AI14,1,0) -> 0 | AO14: =IF(H14=AJ14,1,0) -> 1
A15: 0EX9299901 | B15: 2019 | C15: Qtr 1 | D15: March | E15: 25 | F15: CORRECTIVO | G15: 2.783333 | H15: Departmental Digital | I15: 655 | J15: 1365 | K15: 0 | L15: 0 | M15: 0.6 | N15: 0.8 | O15: 1.05 | P15: 1.1 | Q15: INTERIOR | R15: 5 | S15: 9 | T15: Ciudad principal | U15: Departmental Digital | V15: XEROX MEXICANA SA DE CV / XEROX MEXICANA | W15: TAMAULIPAS | X15: 2019 | Y15: Qtr 2 | Z15: April | AA15: 2 | AB15: 348 | AC15: 1.1 | AD15: 0.5566666 | AE15: 1501.5 | AF15: =VLOOKUP(A15,[1]DETALLE!$A$1:$AK$841,37,FALSE) -> 1808.95 | AG15: =VLOOKUP(A15,[1]DETALLE!$A$1:$AK$841,16,FALSE) -> 118 | AH15: =VLOOKUP(A15,[1]DETALLE!$A$1:$AK$841,22,FALSE) -> 1.15 | AI15: =VLOOKUP(A15,[1]DETALLE!$A$1:$AK$841,27,FALSE) -> 0.0825 | AJ15: =VLOOKUP(A15,[1]DETALLE!$A$1:$AK$841,18,FALSE) -> WF Mono Systems and Legacy Color | AK15: =IF(AE15=AF15,1,0) -> 0 | AL15: =IF(AB15=AG15,1,0) -> 0 | AM15: =IF(AC15=AH15,1,0) -> 0 | AN15: =IF(AD15=AI15,1,0) -> 0 | AO15: =IF(H15=AJ15,1,0) -> 0
A16: 0KPA018838 | B16: 2019 | C16: Qtr 1 | D16: March | E16: 25 | F16: MANTENIMIENTO PREVENTIVO | G16: 0 | H16: Entry Mono Printers | I16: 468 | J16: 715 | K16: 0 | L16: 0 | M16: 0 | N16: 0.6 | O16: 0.8 | P16: 1.05 | Q16: INTERIOR | R16: 5 | S16: 9 | T16: Ciudad principal | U16: Departmental Digital | V16: XEROX MEXICANA SA DE CV / XEROX MEXICANA | W16: CHIHUAHUA | X16: 2019 | Y16: Qtr 2 | Z16: April | AA16: 1 | AB16: 12 | AC16: 0 | AD16: 0 | AE16: 715 | AF16: =VLOOKUP(A16,[1]DETALLE!$A$1:$AK$841,37,FALSE) -> 0 | AG16: =VLOOKUP(A16,[1]DETALLE!$A$1:$AK$841,16,FALSE) -> 28 | AH16: =VLOOKUP(A16,[1]DETALLE!$A$1:$AK$841,22,FALSE) -> 0.8 | AI16: =VLOOKUP(A16,[1]DETALLE!$A$1:$AK$841,27,FALSE) -> 0.558 | AJ16: =VLOOKUP(A16,[1]DETALLE!$A$1:$AK$841,18,FALSE) -> Office Digital | AK16: =IF(AE16=AF16,1,0) -> 0 | AL16: =IF(AB16=AG16,1,0) -> 0 | AM16: =IF(AC16=AH16,1,0) -> 0 | AN16: =IF(AD16=AI16,1,0) -> 0 | AO16: =IF(H16=AJ16,1,0) -> 0
A17: 0BG2946876 | B17: 2019 | C17: Qtr 1 | D17: March | E17: 26 | F17: CORRECTIVO | G17: 3.95 | H17: Light Production Digital Business | I17: 803 | J17: 1573 | K17: 0.2 | L17: 0.6 | M17: 0.8 | N17: 1.05 | O17: 1.1 | P17: 1.15 | Q17: INTERIOR | R17: 4 | S17: 6 | T17: Ciudad principal | U17: High End Cut Sheet | V17: XEROX MEXICANA SA DE CV / XEROX MEXICANA | W17: GUANAJUATO | X17: 2019 | Y17: Qtr 2 | Z17: April | AA17: 2 | AB17: 7 | AC17: 0.8 | AD17: 0.9875 | AE17: 1258.4 | AF17: =VLOOKUP(A17,[1]DETALLE!$A$1:$AK$841,37,FALSE) -> 750.75 | AG17: =VLOOKUP(A17,[1]DETALLE!$A$1:$AK$841,16,FALSE) -> 194 | AH17: =VLOOKUP(A17,[1]DETALLE!$A$1:$AK$841,22,FALSE) -> 1.05 | AI17: =VLOOKUP(A17,[1]DETALLE!$A$1:$AK$841,27,FALSE) -> 0 | AJ17: =VLOOKUP(A17,[1]DETALLE!$A$1:$AK$841,18,FALSE) -> Color Laser Printers | AK17: =IF(AE17=AF17,1,0) -> 0 | AL17: =IF(AB17=AG17,1,0) -> 0 | AM17: =IF(AC17=AH17,1,0) -> 0 | AN17: =IF(AD17=AI17,1,0) -> 0 | AO17: =IF(H17=AJ17,1,0) -> 0
A18: 0DRB131260 | B18: 2019 | C18: Qtr 1 | D18: March | E18: 26 | F18: CORRECTIVO | G18: 1.816667 | H18: Entry Production Color Low/Mid | I18: 803 | J18: 1573 | K18: 0.2 | L18: 0.6 | M18: 0.8 | N18: 1.05 | O18: 1.1 | P18: 1.15 | Q18: INTERIOR | R18: 4 | S18: 6 | T18: Ciudad principal | U18: Entry Production Color Low/Mid | V18: XEROX MEXICANA SA DE CV / XEROX MEXICANA | W18: JALISCO | X18: 2019 | Y18: Qtr 2 | Z18: April | AA18: 5 | AB18: 64 | AC18: 1.15 | AD18: 0.45416675 | AE18: 1808.95 | AF18: =VLOOKUP(A18,[1]DETALLE!$A$1:$AK$841,37,FALSE) -> 750.75 | AG18: =VLOOKUP(A18,[1]DETALLE!$A$1:$AK$841,16,FALSE) -> 177 | AH18: =VLOOKUP(A18,[1]DETALLE!$A$1:$AK$841,22,FALSE) -> 1.05 | AI18: =VLOOKUP(A18,[1]DETALLE!$A$1:$AK$841,27,FALSE) -> 0.466 | AJ18: =VLOOKUP(A18,[1]DETALLE!$A$1:$AK$841,18,FALSE) -> Entry Mono Printers | AK18: =IF(AE18=AF18,1,0) -> 0 | AL18: =IF(AB18=AG18,1,0) -> 0 | AM18: =IF(AC18=AH18,1,0) -> 0 | AN18: =IF(AD18=AI18,1,0) -> 0 | AO18: =IF(H18=AJ18,1,0) -> 0
A19: 0XKK418248 | B19: 2019 | C19: Qtr 1 | D19: March | E19: 26 | F19: CORRECTIVO | G19: 0.35 | I19: NA | J19: NA | K19: NA | L19: NA | M19: NA | N19: NA | O19: NA | P19: NA | R19: NA | S19: NA | U19: A3 Office Color Laser MFPs | V19: XEROX MEXICANA SA DE CV / XEROX MEXICANA | W19: COAHUILA | X19: 2019 | Y19: Qtr 2 | Z19: April | AA19: 1 | AB19: 41 | AC19: 1.1 | AD19: 0 | AE19: 1433.25 | AF19: =VLOOKUP(A19,[1]DETALLE!$A$1:$AK$841,37,FALSE) -> #N/A | AG19: =VLOOKUP(A19,[1]DETALLE!$A$1:$AK$841,16,FALSE) -> #N/A | AH19: =VLOOKUP(A19,[1]DETALLE!$A$1:$AK$841,22,FALSE) -> #N/A | AI19: =VLOOKUP(A19,[1]DETALLE!$A$1:$AK$841,27,FALSE) -> #N/A | AJ19: =VLOOKUP(A19,[1]DETALLE!$A$1:$AK$841,18,FALSE) -> #N/A | AK19: =IF(AE19=AF19,1,0) -> #N/A | AL19: =IF(AB19=AG19,1,0) -> #N/A | AM19: =IF(AC19=AH19,1,0) -> #N/A | AN19: =IF(AD19=AI19,1,0) -> #N/A | AO19: =IF(H19=AJ19,1,0) -> #N/A
A20: 0BG2947932 | B20: 2019 | C20: Qtr 1 | D20: March | E20: 27 | F20: CORRECTIVO | G20: 1.433333 | H20: Light Production Digital Business | I20: 803 | J20: 1573 | K20: 0.2 | L20: 0.6 | M20: 0.8 | N20: 1.05 | O20: 1.1 | P20: 1.15 | Q20: INTERIOR | R20: 4 | S20: 6 | T20: Ciudad principal | U20: High End Cut Sheet | V20: XEROX MEXICANA SA DE CV / XEROX MEXICANA | W20: QUERETARO | X20: 2019 | Y20: Qtr 2 | Z20: April | AA20: 15 | AB20: 41 | AC20: 1.1 | AD20: 0.35833325 | AE20: 1730.3 | AF20: =VLOOKUP(A20,[1]DETALLE!$A$1:$AK$841,37,FALSE) -> 1730.3 | AG20: =VLOOKUP(A20,[1]DETALLE!$A$1:$AK$841,16,FALSE) -> 56 | AH20: =VLOOKUP(A20,[1]DETALLE!$A$1:$AK$841,22,FALSE) -> 1.1 | AI20: =VLOOKUP(A20,[1]DETALLE!$A$1:$AK$841,27,FALSE) -> 0.155 | AJ20: =VLOOKUP(A20,[1]DETALLE!$A$1:$AK$841,18,FALSE) -> Entry Production Color Low/Mid | AK20: =IF(AE20=AF20,1,0) -> 1 | AL20: =IF(AB20=AG20,1,0) -> 0 | AM20: =IF(AC20=AH20,1,0) -> 1 | AN20: =IF(AD20=AI20,1,0) -> 0 | AO20: =IF(H20=AJ20,1,0) -> 0
A21: 0EX9293999 | B21: 2019 | C21: Qtr 1 | D21: March | E21: 27 | F21: CORRECTIVO | G21: 1.066667 | H21: Departmental Digital | I21: 655 | J21: 1365 | K21: 0 | L21: 0 | M21: 0.6 | N21: 0.8 | O21: 1.05 | P21: 1.1 | Q21: INTERIOR | R21: 5 | S21: 9 | T21: Ciudad principal | U21: Departmental Digital | V21: XEROX MEXICANA SA DE CV / XEROX MEXICANA | W21: GUANAJUATO | X21: 2019 | Y21: Qtr 2 | Z21: April | AA21: 2 | AB21: 15 | AC21: 0.6 | AD21: 0.2133334 | AE21: 819 | AF21: =VLOOKUP(A21,[1]DETALLE!$A$1:$AK$841,37,FALSE) -> 1501.5 | AG21: =VLOOKUP(A21,[1]DETALLE!$A$1:$AK$841,16,FALSE) -> 150 | AH21: =VLOOKUP(A21,[1]DETALLE!$A$1:$AK$841,22,FALSE) -> 1.1 | AI21: =VLOOKUP(A21,[1]DETALLE!$A$1:$AK$841,27,FALSE) -> 0.554 | AJ21: =VLOOKUP(A21,[1]DETALLE!$A$1:$AK$841,18,FALSE) -> Departmental Digital | AK21: =IF(AE21=AF21,1,0) -> 0 | AL21: =IF(AB21=AG21,1,0) -> 0 | AM21: =IF(AC21=AH21,1,0) -> 0 | AN21: =IF(AD21=AI21,1,0) -> 0 | AO21: =IF(H21=AJ21,1,0) -> 1
A22: 0LBP345977 | B22: 2019 | C22: Qtr 1 | D22: March | E22: 27 | F22: CORRECTIVO | G22: 4 | I22: NA | J22: NA | K22: NA | L22: NA | M22: NA | N22: NA | O22: NA | P22: NA | R22: NA | S22: NA | U22: A4 Mono MFPs | V22: XEROX MEXICANA SA DE CV / XEROX MEXICANA | W22: JALISCO | X22: 2019 | Y22: Qtr 2 | Z22: April | AA22: 3 | AB22: 0 | AC22: 1.1 | AD22: 0 | AE22: 750.75 | AF22: =VLOOKUP(A22,[1]DETALLE!$A$1:$AK$841,37,FALSE) -> 429 | AG22: =VLOOKUP(A22,[1]DETALLE!$A$1:$AK$841,16,FALSE) -> 22 | AH22: =VLOOKUP(A22,[1]DETALLE!$A$1:$AK$841,22,FALSE) -> 0.6 | AI22: =VLOOKUP(A22,[1]DETALLE!$A$1:$AK$841,27,FALSE) -> 0.246 | AJ22: =VLOOKUP(A22,[1]DETALLE!$A$1:$AK$841,18,FALSE) -> Color Laser Printers | AK22: =IF(AE22=AF22,1,0) -> 0 | AL22: =IF(AB22=AG22,1,0) -> 0 | AM22: =IF(AC22=AH22,1,0) -> 0 | AN22: =IF(AD22=AI22,1,0) -> 0 | AO22: =IF(H22=AJ22,1,0) -> 0
A23: 7TX135776 | B23: 2019 | C23: Qtr 1 | D23: March | E23: 27 | F23: MANTENIMIENTO PREVENTIVO | G23: 0 | H23: A3 Office Color Laser MFPs | I23: 655 | J23: 1365 | K23: 0 | L23: 0 | M23: 0.6 | N23: 0.8 | O23: 1.05 | P23: 1.1 | Q23: INTERIOR | R23: 5 | S23: 9 | T23: Ciudad principal | U23: A3 Office Color Laser MFPs | V23: XEROX MEXICANA SA DE CV / XEROX MEXICANA | W23: MICHOACAN | X23: 2019 | Y23: Qtr 2 | Z23: April | AA23: 16 | AB23: 76 | AC23: 0 | AD23: 0 | AE23: 1365 | AF23: =VLOOKUP(A23,[1]DETALLE!$A$1:$AK$841,37,FALSE) -> 1433.25 | AG23: =VLOOKUP(A23,[1]DETALLE!$A$1:$AK$841,16,FALSE) -> 42 | AH23: =VLOOKUP(A23,[1]DETALLE!$A$1:$AK$841,22,FALSE) -> 1.05 | AI23: =VLOOKUP(A23,[1]DETALLE!$A$1:$AK$841,27,FALSE) -> 0 | AJ23: =VLOOKUP(A23,[1]DETALLE!$A$1:$AK$841,18,FALSE) -> Departmental Digital | AK23: =IF(AE23=AF23,1,0) -> 0 | AL23: =IF(AB23=AG23,1,0) -> 0 | AM23: =IF(AC23=AH23,1,0) -> 0 | AN23: =IF(AD23=AI23,1,0) -> 1 | AO23: =IF(H23=AJ23,1,0) -> 0
A24: 03AG880144 | B24: 2019 | C24: Qtr 1 | D24: March | E24: 28 | F24: CORRECTIVO | G24: 0.25 | H24: Departmental Digital | I24: 655 | J24: 1365 | K24: 0 | L24: 0 | M24: 0.6 | N24: 0.8 | O24: 1.05 | P24: 1.1 | Q24: INTERIOR | R24: 5 | S24: 9 | T24: Ciudad principal | U24: Light Production Digital Business | V24: XEROX MEXICANA SA DE CV / XEROX MEXICANA | W24: NUEVO LEON | X24: 2019 | Y24: Qtr 2 | Z24: April | AA24: 2 | AB24: 7 | AC24: 0.6 | AD24: 0.05 | AE24: 819 | AF24: =VLOOKUP(A24,[1]DETALLE!$A$1:$AK$841,37,FALSE) -> 2234.375 | AG24: =VLOOKUP(A24,[1]DETALLE!$A$1:$AK$841,16,FALSE) -> 7 | AH24: =VLOOKUP(A24,[1]DETALLE!$A$1:$AK$841,22,FALSE) -> 1.05 | AI24: =VLOOKUP(A24,[1]DETALLE!$A$1:$AK$841,27,FALSE) -> 1.0333333 | AJ24: =VLOOKUP(A24,[1]DETALLE!$A$1:$AK$841,18,FALSE) -> Xerox Color Press | AK24: =IF(AE24=AF24,1,0) -> 0 | AL24: =IF(AB24=AG24,1,0) -> 1 | AM24: =IF(AC24=AH24,1,0) -> 0 | AN24: =IF(AD24=AI24,1,0) -> 0 | AO24: =IF(H24=AJ24,1,0) -> 0
A25: 03BT801962 | B25: 2019 | C25: Qtr 1 | D25: March | E25: 28 | F25: INSTALACION NUEVA | G25: 0 | H25: A4 Mono MFPs | I25: 468 | J25: 715 | K25: 0 | L25: 0 | M25: 0 | N25: 0.6 | O25: 0.8 | P25: 1.05 | Q25: INTERIOR | R25: 5 | S25: 9 | T25: Ciudad principal | U25: A4 Mono MFPs | V25: XEROX MEXICANA SA DE CV / XEROX MEXICANA | W25: SAN LUIS POTOSI | X25: 2019 | Y25: Qtr 2 | Z25: April | AA25: 1 | AB25: 34 | AC25: 0 | AD25: 0 | AE25: 715 | AF25: =VLOOKUP(A25,[1]DETALLE!$A$1:$AK$841,37,FALSE) -> #N/A | AG25: =VLOOKUP(A25,[1]DETALLE!$A$1:$AK$841,16,FALSE) -> #N/A | AH25: =VLOOKUP(A25,[1]DETALLE!$A$1:$AK$841,22,FALSE) -> #N/A | AI25: =VLOOKUP(A25,[1]DETALLE!$A$1:$AK$841,27,FALSE) -> #N/A | AJ25: =VLOOKUP(A25,[1]DETALLE!$A$1:$AK$841,18,FALSE) -> #N/A | AK25: =IF(AE25=AF25,1,0) -> #N/A | AL25: =IF(AB25=AG25,1,0) -> #N/A | AM25: =IF(AC25=AH25,1,0) -> #N/A | AN25: =IF(AD25=AI25,1,0) -> #N/A | AO25: =IF(H25=AJ25,1,0) -> #N/A
A26: 0A2T369923 | B26: 2019 | C26: Qtr 1 | D26: March | E26: 28 | F26: CORRECTIVO | G26: 0 | H26: A4 Mono MFPs | I26: 468 | J26: 715 | K26: 0 | L26: 0 | M26: 0 | N26: 0.6 | O26: 0.8 | P26: 1.05 | Q26: INTERIOR | R26: 5 | S26: 9 | T26: Otras | U26: A4 Mono MFPs | V26: XEROX MEXICANA SA DE CV / XEROX MEXICANA | W26: TAMAULIPAS | X26: 2019 | Y26: Qtr 2 | Z26: April | AA26: 4 | AB26: 66 | AC26: 1.05 | AD26: 0 | AE26: 750.75 | AF26: =VLOOKUP(A26,[1]DETALLE!$A$1:$AK$841,37,FALSE) -> 1808.95 | AG26: =VLOOKUP(A26,[1]DETALLE!$A$1:$AK$841,16,FALSE) -> 230 | AH26: =VLOOKUP(A26,[1]DETALLE!$A$1:$AK$841,22,FALSE) -> 1.15 | AI26: =VLOOKUP(A26,[1]DETALLE!$A$1:$AK$841,27,FALSE) -> 0.665 | AJ26: =VLOOKUP(A26,[1]DETALLE!$A$1:$AK$841,18,FALSE) -> Entry Production Color Low/Mid | AK26: =IF(AE26=AF26,1,0) -> 0 | AL26: =IF(AB26=AG26,1,0) -> 0 | AM26: =IF(AC26=AH26,1,0) -> 0 | AN26: =IF(AD26=AI26,1,0) -> 0 | AO26: =IF(H26=AJ26,1,0) -> 0
A27: 0BG2946750 | B27: 2019 | C27: Qtr 1 | D27: March | E27: 28 | F27: CORRECTIVO | G27: 1.816667 | H27: Light Production Digital Business | I27: 803 | J27: 1573 | K27: 0.2 | L27: 0.6 | M27: 0.8 | N27: 1.05 | O27: 1.1 | P27: 1.15 | Q27: INTERIOR | R27: 4 | S27: 6 | T27: Ciudad principal | U27: High End Cut Sheet | V27: XEROX MEXICANA SA DE CV / XEROX MEXICANA | W27: CHIHUAHUA | X27: 2019 | Y27: Qtr 2 | Z27: April | AA27: 1 | AB27: 3 | AC27: 0.6 | AD27: 0.45416675 | AE27: 943.8 | AF27: =VLOOKUP(A27,[1]DETALLE!$A$1:$AK$841,37,FALSE) -> -97.5975 | AG27: =VLOOKUP(A27,[1]DETALLE!$A$1:$AK$841,16,FALSE) -> 1 | AH27: =VLOOKUP(A27,[1]DETALLE!$A$1:$AK$841,22,FALSE) -> 0 | AI27: =VLOOKUP(A27,[1]DETALLE!$A$1:$AK$841,27,FALSE) -> 1.546 | AJ27: =VLOOKUP(A27,[1]DETALLE!$A$1:$AK$841,18,FALSE) -> A4 Mono MFPs | AK27: =IF(AE27=AF27,1,0) -> 0 | AL27: =IF(AB27=AG27,1,0) -> 0 | AM27: =IF(AC27=AH27,1,0) -> 0 | AN27: =IF(AD27=AI27,1,0) -> 0 | AO27: =IF(H27=AJ27,1,0) -> 0
A28: 0BG2951627 | B28: 2019 | C28: Qtr 1 | D28: March | E28: 28 | F28: CORRECTIVO | G28: 0.06666667 | H28: Light Production Digital Business | I28: 803 | J28: 1573 | K28: 0.2 | L28: 0.6 | M28: 0.8 | N28: 1.05 | O28: 1.1 | P28: 1.15 | Q28: INTERIOR | R28: 4 | S28: 6 | T28: Ciudad principal | U28: High End Cut Sheet | V28: XEROX MEXICANA SA DE CV / XEROX MEXICANA | W28: TAMAULIPAS | X28: 2019 | Y28: Qtr 2 | Z28: April | AA28: 15 | AB28: 10 | AC28: 0.8 | AD28: 0.016666667 | AE28: 1258.4 | AF28: =VLOOKUP(A28,[1]DETALLE!$A$1:$AK$841,37,FALSE) -> 1501.5 | AG28: =VLOOKUP(A28,[1]DETALLE!$A$1:$AK$841,16,FALSE) -> 89 | AH28: =VLOOKUP(A28,[1]DETALLE!$A$1:$AK$841,22,FALSE) -> 1.1 | AI28: =VLOOKUP(A28,[1]DETALLE!$A$1:$AK$841,27,FALSE) -> 0.054 | AJ28: =VLOOKUP(A28,[1]DETALLE!$A$1:$AK$841,18,FALSE) -> Office Digital | AK28: =IF(AE28=AF28,1,0) -> 0 | AL28: =IF(AB28=AG28,1,0) -> 0 | AM28: =IF(AC28=AH28,1,0) -> 0 | AN28: =IF(AD28=AI28,1,0) -> 0 | AO28: =IF(H28=AJ28,1,0) -> 0
A29: 0EX9293515 | B29: 2019 | C29: Qtr 1 | D29: March | E29: 28 | F29: CORRECTIVO | G29: 0.03333334 | H29: Departmental Digital | I29: 655 | J29: 1365 | K29: 0 | L29: 0 | M29: 0.6 | N29: 0.8 | O29: 1.05 | P29: 1.1 | Q29: INTERIOR | R29: 5 | S29: 9 | T29: Ciudad principal | U29: Departmental Digital | V29: XEROX MEXICANA SA DE CV / XEROX MEXICANA | W29: JALISCO | X29: 2019 | Y29: Qtr 2 | Z29: April | AA29: 1 | AB29: 8 | AC29: 0.6 | AD29: 0.006666668 | AE29: 819 | AF29: =VLOOKUP(A29,[1]DETALLE!$A$1:$AK$841,37,FALSE) -> 819 | AG29: =VLOOKUP(A29,[1]DETALLE!$A$1:$AK$841,16,FALSE) -> 14 | AH29: =VLOOKUP(A29,[1]DETALLE!$A$1:$AK$841,22,FALSE) -> 0.6 | AI29: =VLOOKUP(A29,[1]DETALLE!$A$1:$AK$841,27,FALSE) -> 0.324 | AJ29: =VLOOKUP(A29,[1]DETALLE!$A$1:$AK$841,18,FALSE) -> Departmental Digital | AK29: =IF(AE29=AF29,1,0) -> 1 | AL29: =IF(AB29=AG29,1,0) -> 0 | AM29: =IF(AC29=AH29,1,0) -> 1 | AN29: =IF(AD29=AI29,1,0) -> 0 | AO29: =IF(H29=AJ29,1,0) -> 1
A30: 0FBG479583 | B30: 2019 | C30: Qtr 1 | D30: March | E30: 28 | F30: CORRECTIVO | G30: 1.383333 | H30: Light Production Digital Business | I30: 803 | J30: 1573 | K30: 0.2 | L30: 0.6 | M30: 0.8 | N30: 1.05 | O30: 1.1 | P30: 1.15 | Q30: INTERIOR | R30: 4 | S30: 6 | T30: Otras | U30: High End Cut Sheet | V30: XEROX MEXICANA SA DE CV / XEROX MEXICANA | W30: NUEVO LEON | X30: 2019 | Y30: Qtr 2 | Z30: April | AA30: 4 | AB30: 7 | AC30: 0.8 | AD30: 0.2305555 | AE30: 1258.4 | AF30: =VLOOKUP(A30,[1]DETALLE!$A$1:$AK$841,37,FALSE) -> 0 | AG30: =VLOOKUP(A30,[1]DETALLE!$A$1:$AK$841,16,FALSE) -> 42 | AH30: =VLOOKUP(A30,[1]DETALLE!$A$1:$AK$841,22,FALSE) -> 1.05 | AI30: =VLOOKUP(A30,[1]DETALLE!$A$1:$AK$841,27,FALSE) -> 0.052 | AJ30: =VLOOKUP(A30,[1]DETALLE!$A$1:$AK$841,18,FALSE) -> Office Digital | AK30: =IF(AE30=AF30,1,0) -> 0 | AL30: =IF(AB30=AG30,1,0) -> 0 | AM30: =IF(AC30=AH30,1,0) -> 0 | AN30: =IF(AD30=AI30,1,0) -> 0 | AO30: =IF(H30=AJ30,1,0) -> 0
A31: 0PW4111396 | B31: 2019 | C31: Qtr 1 | D31: March | E31: 28 | F31: MANTENIMIENTO PREVENTIVO | G31: 0 | H31: WF Mono Systems and Legacy Color | I31: 803 | J31: 1573 | K31: 0.2 | L31: 0.6 | M31: 0.8 | N31: 1.05 | O31: 1.1 | P31: 1.15 | Q31: INTERIOR | R31: 4 | S31: 6 | T31: Ciudad principal | U31: WF Mono Systems and Legacy Color | V31: XEROX MEXICANA SA DE CV / XEROX MEXICANA | W31: COAHUILA | X31: 2019 | Y31: Qtr 2 | Z31: April | AA31: 3 | AB31: 156 | AC31: 0 | AD31: 0 | AE31: 1573 | AF31: =VLOOKUP(A31,[1]DETALLE!$A$1:$AK$841,37,FALSE) -> 0 | AG31: =VLOOKUP(A31,[1]DETALLE!$A$1:$AK$841,16,FALSE) -> 34 | AH31: =VLOOKUP(A31,[1]DETALLE!$A$1:$AK$841,22,FALSE) -> 1.05 | AI31: =VLOOKUP(A31,[1]DETALLE!$A$1:$AK$841,27,FALSE) -> 0.282 | AJ31: =VLOOKUP(A31,[1]DETALLE!$A$1:$AK$841,18,FALSE) -> Office Digital | AK31: =IF(AE31=AF31,1,0) -> 0 | AL31: =IF(AB31=AG31,1,0) -> 0 | AM31: =IF(AC31=AH31,1,0) -> 0 | AN31: =IF(AD31=AI31,1,0) -> 0 | AO31: =IF(H31=AJ31,1,0) -> 0
A32: 0BG2940184 | B32: 2019 | C32: Qtr 1 | D32: March | E32: 29 | F32: CORRECTIVO | G32: 0.5 | H32: Light Production Digital Business | I32: 803 | J32: 1573 | K32: 0.2 | L32: 0.6 | M32: 0.8 | N32: 1.05 | O32: 1.1 | P32: 1.15 | Q32: INTERIOR | R32: 4 | S32: 6 | T32: Ciudad principal | U32: High End Cut Sheet | V32: XEROX MEXICANA SA DE CV / XEROX MEXICANA | W32: JALISCO | X32: 2019 | Y32: Qtr 2 | Z32: April | AA32: 4 | AB32: 1 | AC32: 0.2 | AD32: 0.125 | AE32: 314.6 | AF32: =VLOOKUP(A32,[1]DETALLE!$A$1:$AK$841,37,FALSE) -> 750.75 | AG32: =VLOOKUP(A32,[1]DETALLE!$A$1:$AK$841,16,FALSE) -> 854 | AH32: =VLOOKUP(A32,[1]DETALLE!$A$1:$AK$841,22,FALSE) -> 1.05 | AI32: =VLOOKUP(A32,[1]DETALLE!$A$1:$AK$841,27,FALSE) -> 0.312 | AJ32: =VLOOKUP(A32,[1]DETALLE!$A$1:$AK$841,18,FALSE) -> Entry Mono Printers | AK32: =IF(AE32=AF32,1,0) -> 0 | AL32: =IF(AB32=AG32,1,0) -> 0 | AM32: =IF(AC32=AH32,1,0) -> 0 | AN32: =IF(AD32=AI32,1,0) -> 0 | AO32: =IF(H32=AJ32,1,0) -> 0
A33: 0BG2949312 | B33: 2019 | C33: Qtr 1 | D33: March | E33: 29 | F33: CORRECTIVO | G33: 1.316667 | H33: Light Production Digital Business | I33: 803 | J33: 1573 | K33: 0.2 | L33: 0.6 | M33: 0.8 | N33: 1.05 | O33: 1.1 | P33: 1.15 | Q33: INTERIOR | R33: 4 | S33: 6 | T33: Ciudad principal | U33: High End Cut Sheet | V33: XEROX MEXICANA SA DE CV / XEROX MEXICANA | W33: ESTADO DE MEXICO | X33: 2019 | Y33: Qtr 2 | Z33: April | AA33: 1 | AB33: 36 | AC33: 1.1 | AD33: 0.32916675 | AE33: 1730.3 | AF33: =VLOOKUP(A33,[1]DETALLE!$A$1:$AK$841,37,FALSE) -> 1651.65 | AG33: =VLOOKUP(A33,[1]DETALLE!$A$1:$AK$841,16,FALSE) -> 27 | AH33: =VLOOKUP(A33,[1]DETALLE!$A$1:$AK$841,22,FALSE) -> 1.05 | AI33: =VLOOKUP(A33,[1]DETALLE!$A$1:$AK$841,27,FALSE) -> 0.8925 | AJ33: =VLOOKUP(A33,[1]DETALLE!$A$1:$AK$841,18,FALSE) -> Light Production Digital Business | AK33: =IF(AE33=AF33,1,0) -> 0 | AL33: =IF(AB33=AG33,1,0) -> 0 | AM33: =IF(AC33=AH33,1,0) -> 0 | AN33: =IF(AD33=AI33,1,0) -> 0 | AO33: =IF(H33=AJ33,1,0) -> 1
A34: 0CX0060974 | B34: 2019 | C34: Qtr 1 | D34: March | E34: 29 | F34: CORRECTIVO | G34: 0.2333333 | H34: Entry Production Color Mid | I34: 803 | J34: 1573 | K34: 0.2 | L34: 0.6 | M34: 0.8 | N34: 1.05 | O34: 1.1 | P34: 1.15 | Q34: INTERIOR | R34: 4 | S34: 6 | T34: Ciudad principal | U34: Entry Production Color High | V34: XEROX MEXICANA SA DE CV / XEROX MEXICANA | W34: CHIHUAHUA | X34: 2019 | Y34: Qtr 2 | Z34: April | AA34: 1 | AB34: 28 | AC34: 1.05 | AD34: 0.058333325 | AE34: 1651.65 | AF34: =VLOOKUP(A34,[1]DETALLE!$A$1:$AK$841,37,FALSE) -> 679.965 | AG34: =VLOOKUP(A34,[1]DETALLE!$A$1:$AK$841,16,FALSE) -> 575 | AH34: =VLOOKUP(A34,[1]DETALLE!$A$1:$AK$841,22,FALSE) -> 1.05 | AI34: =VLOOKUP(A34,[1]DETALLE!$A$1:$AK$841,27,FALSE) -> 1.396 | AJ34: =VLOOKUP(A34,[1]DETALLE!$A$1:$AK$841,18,FALSE) -> A4 Mono MFPs | AK34: =IF(AE34=AF34,1,0) -> 0 | AL34: =IF(AB34=AG34,1,0) -> 0 | AM34: =IF(AC34=AH34,1,0) -> 1 | AN34: =IF(AD34=AI34,1,0) -> 0 | AO34: =IF(H34=AJ34,1,0) -> 0
... A50: 0A1H020735 | B50: 2019 | C50: Qtr 2 | D50: April | E50: 1 | F50: CORRECTIVO | G50: 0 | H50: WF Mono Systems and Legacy Color | I50: 803 | J50: 1573 | K50: 0.2 | L50: 0.6 | M50: 0.8 | N50: 1.05 | O50: 1.1 | P50: 1.15 | Q50: INTERIOR | R50: 4 | S50: 6 | T50: Ciudad principal | U50: WF Mono Systems and Legacy Color | V50: XEROX MEXICANA SA DE CV / XEROX MEXICANA | W50: CHIHUAHUA | X50: 2019 | Y50: Qtr 2 | Z50: April | AA50: 4 | AB50: 47 | AC50: 1.1 | AD50: 0 | AE50: 1730.3 | AF50: =VLOOKUP(A50,[1]DETALLE!$A$1:$AK$841,37,FALSE) -> 750.75 | AG50: =VLOOKUP(A50,[1]DETALLE!$A$1:$AK$841,16,FALSE) -> 236 | AH50: =VLOOKUP(A50,[1]DETALLE!$A$1:$AK$841,22,FALSE) -> 1.05 | AI50: =VLOOKUP(A50,[1]DETALLE!$A$1:$AK$841,27,FALSE) -> 0.56 | AJ50: =VLOOKUP(A50,[1]DETALLE!$A$1:$AK$841,18,FALSE) -> A4 Mono MFPs | AK50: =IF(AE50=AF50,1,0) -> 0 | AL50: =IF(AB50=AG50,1,0) -> 0 | AM50: =IF(AC50=AH50,1,0) -> 0 | AN50: =IF(AD50=AI50,1,0) -> 0 | AO50: =IF(H50=AJ50,1,0) -> 0
A51: 0A4T021913 | B51: 2019 | C51: Qtr 2 | D51: April | E51: 1 | F51: CORRECTIVO | G51: 1.283333 | I51: NA | J51: NA | K51: NA | L51: NA | M51: NA | N51: NA | O51: NA | P51: NA | R51: NA | S51: NA | U51: A4 Mono MFPs | V51: XEROX MEXICANA SA DE CV / XEROX MEXICANA | W51: CHIHUAHUA | X51: 2019 | Y51: Qtr 2 | Z51: April | AA51: 3 | AB51: 0 | AC51: 1.1 | AD51: 0 | AE51: 750.75 | AF51: =VLOOKUP(A51,[1]DETALLE!$A$1:$AK$841,37,FALSE) -> 0 | AG51: =VLOOKUP(A51,[1]DETALLE!$A$1:$AK$841,16,FALSE) -> 3 | AH51: =VLOOKUP(A51,[1]DETALLE!$A$1:$AK$841,22,FALSE) -> 0 | AI51: =VLOOKUP(A51,[1]DETALLE!$A$1:$AK$841,27,FALSE) -> 0.256 | AJ51: =VLOOKUP(A51,[1]DETALLE!$A$1:$AK$841,18,FALSE) -> Departmental Digital | AK51: =IF(AE51=AF51,1,0) -> 0 | AL51: =IF(AB51=AG51,1,0) -> 0 | AM51: =IF(AC51=AH51,1,0) -> 0 | AN51: =IF(AD51=AI51,1,0) -> 0 | AO51: =IF(H51=AJ51,1,0) -> 0
A52: 0A4T558109 | B52: 2019 | C52: Qtr 2 | D52: April | E52: 1 | F52: CORRECTIVO | G52: 1.666667 | H52: Entry Mono Printers | I52: 468 | J52: 715 | K52: 0 | L52: 0 | M52: 0 | N52: 0.6 | O52: 0.8 | P52: 1.05 | Q52: INTERIOR | R52: 5 | S52: 9 | T52: Ciudad principal | U52: A4 Mono MFPs | V52: XEROX MEXICANA SA DE CV / XEROX MEXICANA | W52: GUANAJUATO | X52: 2019 | Y52: Qtr 2 | Z52: April | AA52: 3 | AB52: 383 | AC52: 1.05 | AD52: 0.3333334 | AE52: 750.75 | AF52: =VLOOKUP(A52,[1]DETALLE!$A$1:$AK$841,37,FALSE) -> 750.75 | AG52: =VLOOKUP(A52,[1]DETALLE!$A$1:$AK$841,16,FALSE) -> 146 | AH52: =VLOOKUP(A52,[1]DETALLE!$A$1:$AK$841,22,FALSE) -> 1.05 | AI52: =VLOOKUP(A52,[1]DETALLE!$A$1:$AK$841,27,FALSE) -> 0.258 | AJ52: =VLOOKUP(A52,[1]DETALLE!$A$1:$AK$841,18,FALSE) -> Entry Mono Printers | AK52: =IF(AE52=AF52,1,0) -> 1 | AL52: =IF(AB52=AG52,1,0) -> 0 | AM52: =IF(AC52=AH52,1,0) -> 1 | AN52: =IF(AD52=AI52,1,0) -> 0 | AO52: =IF(H52=AJ52,1,0) -> 1
A53: 0AE7146573 | B53: 2019 | C53: Qtr 2 | D53: April | E53: 1 | F53: CORRECTIVO | G53: 3.95 | H53: Office Digital | I53: 655 | J53: 1365 | K53: 0 | L53: 0 | M53: 0.6 | N53: 0.8 | O53: 1.05 | P53: 1.1 | Q53: INTERIOR | R53: 5 | S53: 9 | T53: Ciudad principal | U53: Departmental Digital | V53: XEROX MEXICANA SA DE CV / XEROX MEXICANA | W53: TAMAULIPAS | X53: 2019 | Y53: Qtr 2 | Z53: April | AA53: 5 | AB53: 313 | AC53: 1.1 | AD53: 0.79 | AE53: 1501.5 | AF53: =VLOOKUP(A53,[1]DETALLE!$A$1:$AK$841,37,FALSE) -> 1258.4 | AG53: =VLOOKUP(A53,[1]DETALLE!$A$1:$AK$841,16,FALSE) -> 7 | AH53: =VLOOKUP(A53,[1]DETALLE!$A$1:$AK$841,22,FALSE) -> 0.8 | AI53: =VLOOKUP(A53,[1]DETALLE!$A$1:$AK$841,27,FALSE) -> 0.625 | AJ53: =VLOOKUP(A53,[1]DETALLE!$A$1:$AK$841,18,FALSE) -> Entry Production Color Low/Mid | AK53: =IF(AE53=AF53,1,0) -> 0 | AL53: =IF(AB53=AG53,1,0) -> 0 | AM53: =IF(AC53=AH53,1,0) -> 0 | AN53: =IF(AD53=AI53,1,0) -> 0 | AO53: =IF(H53=AJ53,1,0) -> 0
A54: 0BB1252119 | B54: 2019 | C54: Qtr 2 | D54: April | E54: 1 | F54: CORRECTIVO | G54: 0.2833333 | H54: A4 Mono MFPs | I54: 468 | J54: 715 | K54: 0 | L54: 0 | M54: 0 | N54: 0.6 | O54: 0.8 | P54: 1.05 | Q54: INTERIOR | R54: 5 | S54: 9 | T54: Ciudad principal | U54: A4 Mono MFPs | V54: XEROX MEXICANA SA DE CV / XEROX MEXICANA | W54: CHIHUAHUA | X54: 2019 | Y54: Qtr 2 | Z54: April | AA54: 1 | AB54: 32 | AC54: 0.8 | AD54: 0.05666666 | AE54: 572 | AF54: =VLOOKUP(A54,[1]DETALLE!$A$1:$AK$841,37,FALSE) -> 0 | AG54: =VLOOKUP(A54,[1]DETALLE!$A$1:$AK$841,16,FALSE) -> 210 | AH54: =VLOOKUP(A54,[1]DETALLE!$A$1:$AK$841,22,FALSE) -> 1.1 | AI54: =VLOOKUP(A54,[1]DETALLE!$A$1:$AK$841,27,FALSE) -> 0.106 | AJ54: =VLOOKUP(A54,[1]DETALLE!$A$1:$AK$841,18,FALSE) -> Office Digital | AK54: =IF(AE54=AF54,1,0) -> 0 | AL54: =IF(AB54=AG54,1,0) -> 0 | AM54: =IF(AC54=AH54,1,0) -> 0 | AN54: =IF(AD54=AI54,1,0) -> 0 | AO54: =IF(H54=AJ54,1,0) -> 0
A55: 0BG0966721 | B55: 2019 | C55: Qtr 2 | D55: April | E55: 1 | F55: CORRECTIVO | G55: 0.9333333 | H55: Light Production Digital Business | I55: 803 | J55: 1573 | K55: 0.2 | L55: 0.6 | M55: 0.8 | N55: 1.05 | O55: 1.1 | P55: 1.15 | Q55: INTERIOR | R55: 4 | S55: 6 | T55: Ciudad principal | U55: High End Cut Sheet | V55: XEROX MEXICANA SA DE CV / XEROX MEXICANA | W55: GUANAJUATO | X55: 2019 | Y55: Qtr 2 | Z55: April | AA55: 9 | AB55: 4 | AC55: 0.6 | AD55: 0.23333333 | AE55: 943.8 | AF55: =VLOOKUP(A55,[1]DETALLE!$A$1:$AK$841,37,FALSE) -> 1808.95 | AG55: =VLOOKUP(A55,[1]DETALLE!$A$1:$AK$841,16,FALSE) -> 121 | AH55: =VLOOKUP(A55,[1]DETALLE!$A$1:$AK$841,22,FALSE) -> 1.15 | AI55: =VLOOKUP(A55,[1]DETALLE!$A$1:$AK$841,27,FALSE) -> 0.795 | AJ55: =VLOOKUP(A55,[1]DETALLE!$A$1:$AK$841,18,FALSE) -> WF Mono Systems and Legacy Color | AK55: =IF(AE55=AF55,1,0) -> 0 | AL55: =IF(AB55=AG55,1,0) -> 0 | AM55: =IF(AC55=AH55,1,0) -> 0 | AN55: =IF(AD55=AI55,1,0) -> 0 | AO55: =IF(H55=AJ55,1,0) -> 0
...

Sheet prueba con 16mil datos
A1: N° de serie | B1: Year | C1: Quarter | D1: Month | E1: Day | F1: Categoría | G1: T. respuesta | H1: Business Team | I1: Pago Base CDMX y área metropolitana | J1: Pago Base Interior | K1: menos de 3 días | L1: entre 3 y 6 días | M1: entre 7 y 15 días | N1: entre 16 y 30 días | O1: entre 31 y 59 días | P1: 60 días o más | Q1: REGION | R1: TR Ciudades principales | S1: TR Otras ciudades | T1: Loc TR | U1: familia matriz global | V1: Cliente | W1: Ruta | X1: Year.1 | Y1: Quarter.1 | Z1: Month.1 | AA1: Day.1 | AB1: time | AC1: viabilidad | AD1: veces_obj | AE1: pagofinal | AF1: pago MIF | AG1: dias MIF | AH1: Fiabilidad MIF | AI1: vece obj MIF | AJ1: familia MIF | AK1: pagos iguales | AL1: dias iguales | AM1: fiabilidad igual | AN1: veces obj iguales | AO1: familias iguales
A2: 9HB334888 | B2: 2019 | C2: Qtr 1 | D2: March | E2: 4 | F2: INSTALACION NUEVA | G2: 0 | I2: NA | J2: NA | K2: NA | L2: NA | M2: NA | N2: NA | O2: NA | P2: NA | R2: NA | S2: NA | U2: A4 Mono MFPs | V2: XEROX MEXICANA SA DE CV / XEROX MEXICANA | W2: ESTADO DE MEXICO | X2: 2019 | Y2: Qtr 2 | Z2: April | AA2: 4 | AB2: 0 | AC2: 1.1 | AD2: 0 | AE2: 715 | AF2: =VLOOKUP(A2,[1]DETALLE!$A$1:$AK$841,37,FALSE) -> 1501.5 | AG2: =VLOOKUP(A2,[1]DETALLE!$A$1:$AK$841,16,FALSE) -> 88 | AH2: =VLOOKUP(A2,[1]DETALLE!$A$1:$AK$841,22,FALSE) -> 1.1 | AI2: =VLOOKUP(A2,[1]DETALLE!$A$1:$AK$841,27,FALSE) -> 0.22 | AJ2: =VLOOKUP(A2,[1]DETALLE!$A$1:$AK$841,18,FALSE) -> Departmental Digital | AK2: =IF(AE2=AF2,1,0) -> 0 | AL2: =IF(AB2=AG2,1,0) -> 0 | AM2: =IF(AC2=AH2,1,0) -> 1 | AN2: =IF(AD2=AI2,1,0) -> 0 | AO2: =IF(H2=AJ2,1,0) -> 0
A3: 0AGD461524 | B3: 2019 | C3: Qtr 1 | D3: March | E3: 5 | F3: CORRECTIVO | G3: 2.866667 | I3: NA | J3: NA | K3: NA | L3: NA | M3: NA | N3: NA | O3: NA | P3: NA | R3: NA | S3: NA | U3: A4 Color Laser MFPs | V3: XEROX MEXICANA SA DE CV / XEROX MEXICANA | W3: NUEVO LEON | X3: 2019 | Y3: Qtr 2 | Z3: April | AA3: 22 | AB3: 12 | AC3: 1.1 | AD3: 0 | AE3: 0 | AF3: =VLOOKUP(A3,[1]DETALLE!$A$1:$AK$841,37,FALSE) -> 1092 | AG3: =VLOOKUP(A3,[1]DETALLE!$A$1:$AK$841,16,FALSE) -> 17 | AH3: =VLOOKUP(A3,[1]DETALLE!$A$1:$AK$841,22,FALSE) -> 0.8 | AI3: =VLOOKUP(A3,[1]DETALLE!$A$1:$AK$841,27,FALSE) -> 0.196 | AJ3: =VLOOKUP(A3,[1]DETALLE!$A$1:$AK$841,18,FALSE) -> A3 Office Color Laser MFPs | AK3: =IF(AE3=AF3,1,0) -> 0 | AL3: =IF(AB3=AG3,1,0) -> 0 | AM3: =IF(AC3=AH3,1,0) -> 0 | AN3: =IF(AD3=AI3,1,0) -> 0 | AO3: =IF(H3=AJ3,1,0) -> 0
A4: 0BG2951668 | B4: 2019 | C4: Qtr 1 | D4: March | E4: 11 | F4: MANTENIMIENTO PREVENTIVO | G4: 0 | H4: Light Production Digital Business | I4: 803 | J4: 1573 | K4: 0.2 | L4: 0.6 | M4: 0.8 | N4: 1.05 | O4: 1.1 | P4: 1.15 | Q4: INTERIOR | R4: 4 | S4: 6 | T4: Ciudad principal | U4: High End Cut Sheet | V4: XEROX MEXICANA SA DE CV / XEROX MEXICANA | W4: NUEVO LEON | X4: 2019 | Y4: Qtr 2 | Z4: April | AA4: 11 | AB4: 14 | AC4: 0 | AD4: 0 | AE4: 1573 | AF4: =VLOOKUP(A4,[1]DETALLE!$A$1:$AK$841,37,FALSE) -> 1651.65 | AG4: =VLOOKUP(A4,[1]DETALLE!$A$1:$AK$841,16,FALSE) -> 18 | AH4: =VLOOKUP(A4,[1]DETALLE!$A$1:$AK$841,22,FALSE) -> 1.05 | AI4: =VLOOKUP(A4,[1]DETALLE!$A$1:$AK$841,27,FALSE) -> 0.555 | AJ4: =VLOOKUP(A4,[1]DETALLE!$A$1:$AK$841,18,FALSE) -> WF Mono Systems and Legacy Color | AK4: =IF(AE4=AF4,1,0) -> 0 | AL4: =IF(AB4=AG4,1,0) -> 0 | AM4: =IF(AC4=AH4,1,0) -> 0 | AN4: =IF(AD4=AI4,1,0) -> 0 | AO4: =IF(H4=AJ4,1,0) -> 0
A5: 0BPB110617 | B5: 2019 | C5: Qtr 1 | D5: March | E5: 13 | F5: CORRECTIVO | G5: 2.216667 | I5: NA | J5: NA | K5: NA | L5: NA | M5: NA | N5: NA | O5: NA | P5: NA | R5: NA | S5: NA | U5: High End Cut Sheet | V5: XEROX MEXICANA SA DE CV / XEROX MEXICANA | W5: JALISCO | X5: 2019 | Y5: Qtr 2 | Z5: April | AA5: 1 | AB5: 13 | AC5: 1.1 | AD5: 0 | AE5: 107.25 | AF5: =VLOOKUP(A5,[1]DETALLE!$A$1:$AK$841,37,FALSE) -> 750.75 | AG5: =VLOOKUP(A5,[1]DETALLE!$A$1:$AK$841,16,FALSE) -> 294 | AH5: =VLOOKUP(A5,[1]DETALLE!$A$1:$AK$841,22,FALSE) -> 1.05 | AI5: =VLOOKUP(A5,[1]DETALLE!$A$1:$AK$841,27,FALSE) -> 0 | AJ5: =VLOOKUP(A5,[1]DETALLE!$A$1:$AK$841,18,FALSE) -> Entry Mono Printers | AK5: =IF(AE5=AF5,1,0) -> 0 | AL5: =IF(AB5=AG5,1,0) -> 0 | AM5: =IF(AC5=AH5,1,0) -> 0 | AN5: =IF(AD5=AI5,1,0) -> 1 | AO5: =IF(H5=AJ5,1,0) -> 0
A6: 0BPB110653 | B6: 2019 | C6: Qtr 1 | D6: March | E6: 13 | F6: CORRECTIVO | G6: 4.233333 | I6: NA | J6: NA | K6: NA | L6: NA | M6: NA | N6: NA | O6: NA | P6: NA | R6: NA | S6: NA | U6: High End Cut Sheet | V6: XEROX MEXICANA SA DE CV / XEROX MEXICANA | W6: JALISCO | X6: 2019 | Y6: Qtr 2 | Z6: April | AA6: 3 | AB6: 35 | AC6: 1.1 | AD6: 0 | AE6: 321.75 | AF6: =VLOOKUP(A6,[1]DETALLE!$A$1:$AK$841,37,FALSE) -> 1730.3 | AG6: =VLOOKUP(A6,[1]DETALLE!$A$1:$AK$841,16,FALSE) -> 50 | AH6: =VLOOKUP(A6,[1]DETALLE!$A$1:$AK$841,22,FALSE) -> 1.1 | AI6: =VLOOKUP(A6,[1]DETALLE!$A$1:$AK$841,27,FALSE) -> 0.505 | AJ6: =VLOOKUP(A6,[1]DETALLE!$A$1:$AK$841,18,FALSE) -> Entry Production Color Low/Mid | AK6: =IF(AE6=AF6,1,0) -> 0 | AL6: =IF(AB6=AG6,1,0) -> 0 | AM6: =IF(AC6=AH6,1,0) -> 1 | AN6: =IF(AD6=AI6,1,0) -> 0 | AO6: =IF(H6=AJ6,1,0) -> 0
