Workbook

Sheet data
A1: DIA DE CIERRE | B1: MONTO | C1: costo_referenciado_real | D1: FECHA1 | E1: COSTO REFERENCIADO | F1: clave pitss total | G1: CLAVE | H1: INCIDENT_N | I1: TASK_NUMBE | J1: SERIE | K1: SUCURSAL | L1: GRUPO | M1: EMPLEADO | N1: PARTE | O1: CANTIDAD | P1: NOMBRE | Q1: RAZON | R1: MODELO | S1: STATUS | T1: ASP | U1: diferencias en septiembre
A2: 43345 | B2: 43.373616 | C2: 72.289359 | D2: 43341 | E2: 180.7451 | F2: 43345 | G2: PITSS CHIHUAHUA43345 | H2: 1915245 | I2: 3421734 | J2: 0X76704337 | K2: 450 | L2: 20 | M2: 500155 | N2: 059K85121-N | O2: 1 | P2: MONTOYA PORTILLO, (500155) CARLOS ALBERTO (SEI | Q2: HONEYWELL AUTOMOTIVE DE MEXICO S DE RL D | R2: 5945 | S2: XGS RENTAL | T2: PITSS CHIHUAHUA | U2: =IF(C2=E2,0,1) -> 1
A3: 43345 | B3: 57.925196 | C3: 96.541993 | D3: 43341 | E3: 58.503213 | F3: 43345 | G3: PITSS CHIHUAHUA43345 | H3: 1915245 | I3: 3421734 | J3: 0X76704337 | K3: 450 | L3: 20 | M3: 500155 | N3: 859K04215-N | O3: 1 | P3: MONTOYA PORTILLO, (500155) CARLOS ALBERTO (SEI | Q3: HONEYWELL AUTOMOTIVE DE MEXICO S DE RL D | R3: 5945 | S3: XGS RENTAL | T3: PITSS CHIHUAHUA | U3: =IF(C3=E3,0,1) -> 1
A4: 43345 | B4: 14.2205 | C4: 23.700834 | D4: 43341 | E4: 38.425837 | F4: 43345 | G4: PITSS CHIHUAHUA43345 | H4: 1915245 | I4: 3421734 | J4: 0X76704337 | K4: 450 | L4: 20 | M4: 500155 | N4: 059K69802-N | O4: 2 | P4: MONTOYA PORTILLO, (500155) CARLOS ALBERTO (SEI | Q4: HONEYWELL AUTOMOTIVE DE MEXICO S DE RL D | R4: 5945 | S4: XGS RENTAL | T4: PITSS CHIHUAHUA | U4: =IF(C4=E4,0,1) -> 1
A5: 43345 | B5: 1.4587718 | C5: 2.4312863 | D5: 43341 | E5: 38.620695 | F5: 43345 | G5: PITSS CHIHUAHUA43345 | H5: 1915245 | I5: 3421734 | J5: 0X76704337 | K5: 450 | L5: 20 | M5: 500155 | N5: 059K59221-N | O5: 1 | P5: MONTOYA PORTILLO, (500155) CARLOS ALBERTO (SEI | Q5: HONEYWELL AUTOMOTIVE DE MEXICO S DE RL D | R5: 5945 | S5: XGS RENTAL | T5: PITSS CHIHUAHUA | U5: =IF(C5=E5,0,1) -> 1
A6: 43345 | B6: 605.37274 | C6: 1008.9546 | D6: 43336 | E6: 43.047496 | F6: 43345 | G6: PITSS TAMAULIPAS43345 | H6: 1912931 | I6: 3420692 | J6: 03AG877899 | K6: 450 | L6: 14 | M6: 500056 | N6: 084K43040-N | O6: 1 | P6: CRUZ HERRERA, (500056) ROBERTO | Q6: OPERADORA OMX SA DE CV | R6: 8075 | S6: SALES ORDE | T6: PITSS TAMAULIPAS | U6: =IF(C6=E6,0,1) -> 1
A7: 43345 | B7: 85.546734 | C7: 142.57789 | D7: 43339 | E7: 38.626009 | F7: 43345 | G7: PITSS JALISCO43345 | H7: 1913693 | I7: 3420961 | J7: 0DRB131260 | K7: 480 | L7: 23 | M7: 800027 | N7: 013R00603-N | O7: 3 | P7: GARCIA VILLACAÐA, (800027) RICARDO PASCUAL | Q7: COMPUTER FORMS SA DE CV | R7: 1263 | S7: FSMA | T7: PITSS JALISCO | U7: =IF(C7=E7,0,1) -> 1
A8: 43345 | B8: 115.23872 | C8: 192.06453 | D8: 43339 | E8: 39.060895 | F8: 43345 | G8: PITSS JALISCO43345 | H8: 1913693 | I8: 3420961 | J8: 0DRB131260 | K8: 480 | L8: 23 | M8: 800027 | N8: 013R00602-N | O8: 1 | P8: GARCIA VILLACAÐA, (800027) RICARDO PASCUAL | Q8: COMPUTER FORMS SA DE CV | R8: 1263 | S8: FSMA | T8: PITSS JALISCO | U8: =IF(C8=E8,0,1) -> 1
A9: 43345 | B9: 0.76472589 | C9: 1.2745431 | D9: 43339 | E9: 9.2220593 | F9: 43345 | G9: PITSS TOLUCA43345 | H9: 1914051 | I9: 3421503 | J9: 07CX042178 | K9: 420 | L9: 18 | M9: 100037 | N9: 120E34245-N | O9: 1 | P9: CASTILLO SANCHEZ, (100037) MIGUEL ANGEL (SEITON | Q9: UNIVERSIDAD AUTONOMA DEL ESTADO DE MEXIC | R9: 7025 | S9: XGS RENTAL | T9: PITSS TOLUCA | U9: =IF(C9=E9,0,1) -> 1
A10: 43345 | B10: 0 | C10: 0 | D10: 43339 | E10: 1.1319431 | F10: 43345 | G10: PITSS TOLUCA43345 | H10: 1914051 | I10: 3421503 | J10: 07CX042178 | K10: 420 | L10: 18 | M10: 100037 | N10: 011K04261-N | O10: 1 | P10: CASTILLO SANCHEZ, (100037) MIGUEL ANGEL (SEITON | Q10: UNIVERSIDAD AUTONOMA DEL ESTADO DE MEXIC | R10: 7025 | S10: XGS RENTAL | T10: PITSS TOLUCA | U10: =IF(C10=E10,0,1) -> 1
A11: 43345 | B11: 3.1689093 | C11: 5.2815155 | D11: 43341 | E11: 132.02549 | F11: 43345 | G11: PITSS NUEVO LEON43345 | H11: 1915259 | I11: 3421836 | J11: 0BG2948814 | K11: 450 | L11: 18 | M11: 500164 | N11: 059K29520-N | O11: 2 | P11: GONZALEZ GUERRERO, (500164) FEDERICO (PITSS) | Q11: OFFICE DEPOT DE MEXICO SA DE CV | R11: 4395 | S11: XGS FSMA | T11: PITSS NUEVO LEON | U11: =IF(C11=E11,0,1) -> 1
A12: 43345 | B12: 3.5462237 | C12: 5.9103728 | D12: 43341 | E12: 55.83367 | F12: 43345 | G12: PITSS NUEVO LEON43345 | H12: 1915259 | I12: 3421836 | J12: 0BG2948814 | K12: 450 | L12: 18 | M12: 500164 | N12: 059K29510-N | O12: 2 | P12: GONZALEZ GUERRERO, (500164) FEDERICO (PITSS) | Q12: OFFICE DEPOT DE MEXICO SA DE CV | R12: 4395 | S12: XGS FSMA | T12: PITSS NUEVO LEON | U12: =IF(C12=E12,0,1) -> 1
A13: 43345 | B13: 9.0714878 | C13: 15.119146 | D13: 43341 | E13: 152.25166 | F13: 43345 | G13: PITSS NUEVO LEON43345 | H13: 1915259 | I13: 3421836 | J13: 0BG2948814 | K13: 450 | L13: 18 | M13: 500164 | N13: 059K30951-N | O13: 2 | P13: GONZALEZ GUERRERO, (500164) FEDERICO (PITSS) | Q13: OFFICE DEPOT DE MEXICO SA DE CV | R13: 4395 | S13: XGS FSMA | T13: PITSS NUEVO LEON | U13: =IF(C13=E13,0,1) -> 1
... A70: 43346 | B70: 23.979125 | C70: 39.965209 | D70: 43336 | E70: 11.800374 | F70: 43346 | G70: PITSS CHIHUAHUA43346 | H70: 1912917 | I70: 3421024 | J70: 0MX4355681 | K70: 450 | L70: 20 | M70: 500157 | N70: 094K92393-N | O70: 1 | P70: MAR MARQUEZ, (500157) CESAR (SEITON) | Q70: HONEYWELL AUTOMOTIVE DE MEXICO S DE RL D | R70: 7845 | S70: XGS RENTAL | T70: PITSS CHIHUAHUA | U70: =IF(C70=E70,0,1) -> 1
A71: 43346 | B71: 102.56627 | C71: 170.94378 | D71: 43339 | E71: 24.800006 | F71: 43346 | G71: PITSS TOLUCA43346 | H71: 1913803 | I71: 3421220 | J71: 0EX9293026 | K71: 420 | L71: 18 | M71: 100038 | N71: 960K73366-N | O71: 1 | P71: GUTIERREZ GUTIERREZ, (100038) LUIS (SEITON) | Q71: 0 | R71: 5866 | S71: 0 | T71: PITSS TOLUCA | U71: =IF(C71=E71,0,1) -> 1
A72: 43346 | B72: 20.86389 | C72: 34.773151 | D72: 43339 | E72: 2.7705149 | F72: 43346 | G72: PITSS TOLUCA43346 | H72: 1913803 | I72: 3421220 | J72: 0EX9293026 | K72: 420 | L72: 18 | M72: 100038 | N72: 604K67240-N | O72: 1 | P72: GUTIERREZ GUTIERREZ, (100038) LUIS (SEITON) | Q72: 0 | R72: 5866 | S72: 0 | T72: PITSS TOLUCA | U72: =IF(C72=E72,0,1) -> 1
A73: 43346 | B73: 14.356546 | C73: 23.927577 | D73: 43338 | E73: 7.569316 | F73: 43346 | G73: PITSS QUERETARO43346 | H73: 1913379 | I73: 3421008 | J73: 0E2B658511 | K73: 480 | L73: 01 | M73: 800187 | N73: 127K66880-N | O73: 1 | P73: MEJIA DUARTE, (800187) JOSE LUIS (PITSS) | Q73: OPERADORA OMX SA DE CV | R73: 0070 | S73: XGS FSMA | T73: PITSS QUERETARO | U73: =IF(C73=E73,0,1) -> 1
A74: 43346 | B74: 10.568522 | C74: 17.614204 | D74: 43338 | E74: 211.55999 | F74: 43346 | G74: PITSS QUERETARO43346 | H74: 1913379 | I74: 3421008 | J74: 0E2B658511 | K74: 480 | L74: 01 | M74: 800187 | N74: 604K56080-N | O74: 3 | P74: MEJIA DUARTE, (800187) JOSE LUIS (PITSS) | Q74: OPERADORA OMX SA DE CV | R74: 0070 | S74: XGS FSMA | T74: PITSS QUERETARO | U74: =IF(C74=E74,0,1) -> 1
A75: 43346 | B75: 3.9974066 | C75: 6.6623444 | D75: 43338 | E75: 4.8528297 | F75: 43346 | G75: PITSS QUERETARO43346 | H75: 1913379 | I75: 3421008 | J75: 0E2B658511 | K75: 480 | L75: 01 | M75: 800187 | N75: 121K33941-N | O75: 1 | P75: MEJIA DUARTE, (800187) JOSE LUIS (PITSS) | Q75: OPERADORA OMX SA DE CV | R75: 0070 | S75: XGS FSMA | T75: PITSS QUERETARO | U75: =IF(C75=E75,0,1) -> 1
A76: 43346 | B76: 3.5138065 | C76: 5.8563442 | D76: 43341 | E76: 2.500372 | F76: 43346 | G76: PITSS NUEVO LEON43346 | H76: 1914899 | I76: 3421621 | J76: 0VMA569564 | K76: 450 | L76: 18 | M76: 500028 | N76: 029N00412-N | O76: 1 | P76: PEREZ BALBOA, (500028) CESAR | Q76: BOTANAS Y DERIVADOS SA DE CV | R76: 3350 | S76: XGS RENTAL | T76: PITSS NUEVO LEON | U76: =IF(C76=E76,0,1) -> 1
A77: 43346 | B77: 0.70361159 | C77: 1.172686 | D77: 43341 | E77: 1.5110289 | F77: 43346 | G77: PITSS NUEVO LEON43346 | H77: 1914899 | I77: 3421621 | J77: 0VMA569564 | K77: 450 | L77: 18 | M77: 500028 | N77: 029N00410-N | O77: 1 | P77: PEREZ BALBOA, (500028) CESAR | Q77: BOTANAS Y DERIVADOS SA DE CV | R77: 3350 | S77: XGS RENTAL | T77: PITSS NUEVO LEON | U77: =IF(C77=E77,0,1) -> 1
A78: 43346 | B78: 47.280679 | C78: 78.801132 | D78: 43341 | E78: 5.3196012 | F78: 43346 | G78: PITSS CHIHUAHUA43346 | H78: 1914985 | I78: 3421632 | J78: 0VMA561125 | K78: 450 | L78: 20 | M78: 500155 | N78: 126N00342-N | O78: 1 | P78: MONTOYA PORTILLO, (500155) CARLOS ALBERTO (SEI | Q78: HONEYWELL AUTOMOTIVE DE MEXICO S DE RL D | R78: 3350 | S78: XGS RENTAL | T78: PITSS CHIHUAHUA | U78: =IF(C78=E78,0,1) -> 1
A79: 43346 | B79: 4.3284867 | C79: 7.2141445 | D79: 43341 | E79: 97.457822 | F79: 43346 | G79: PITSS CHIHUAHUA43346 | H79: 1914985 | I79: 3421632 | J79: 0VMA561125 | K79: 450 | L79: 20 | M79: 500155 | N79: 022N02413-N | O79: 2 | P79: MONTOYA PORTILLO, (500155) CARLOS ALBERTO (SEI | Q79: HONEYWELL AUTOMOTIVE DE MEXICO S DE RL D | R79: 3350 | S79: XGS RENTAL | T79: PITSS CHIHUAHUA | U79: =IF(C79=E79,0,1) -> 1
A80: 43346 | B80: 1.5198861 | C80: 2.5331434 | D80: 43341 | E80: 14.345032 | F80: 43346 | G80: PITSS CHIHUAHUA43346 | H80: 1914985 | I80: 3421632 | J80: 0VMA561125 | K80: 450 | L80: 20 | M80: 500155 | N80: 003N01042-N | O80: 1 | P80: MONTOYA PORTILLO, (500155) CARLOS ALBERTO (SEI | Q80: HONEYWELL AUTOMOTIVE DE MEXICO S DE RL D | R80: 3350 | S80: XGS RENTAL | T80: PITSS CHIHUAHUA | U80: =IF(C80=E80,0,1) -> 1
A81: 43346 | B81: 3.0004464 | C81: 5.000744 | D81: 43341 | E81: 13.833089 | F81: 43346 | G81: PITSS CHIHUAHUA43346 | H81: 1914985 | I81: 3421632 | J81: 0VMA561125 | K81: 450 | L81: 20 | M81: 500155 | N81: 019N00947-N | O81: 2 | P81: MONTOYA PORTILLO, (500155) CARLOS ALBERTO (SEI | Q81: HONEYWELL AUTOMOTIVE DE MEXICO S DE RL D | R81: 3350 | S81: XGS RENTAL | T81: PITSS CHIHUAHUA | U81: =IF(C81=E81,0,1) -> 1
A82: 43346 | B82: 7.7338818 | C82: 12.889803 | D82: 43341 | E82: 44.376067 | F82: 43346 | G82: PITSS CHIHUAHUA43346 | H82: 1914985 | I82: 3421632 | J82: 0VMA561125 | K82: 450 | L82: 20 | M82: 500155 | N82: 130N01533-N | O82: 1 | P82: MONTOYA PORTILLO, (500155) CARLOS ALBERTO (SEI | Q82: HONEYWELL AUTOMOTIVE DE MEXICO S DE RL D | R82: 3350 | S82: XGS RENTAL | T82: PITSS CHIHUAHUA | U82: =IF(C82=E82,0,1) -> 1
A83: 43346 | B83: 4.5357439 | C83: 7.5595732 | D83: 43339 | E83: 29.251607 | F83: 43346 | G83: PITSS CHIHUAHUA43346 | H83: 1913629 | I83: 3421086 | J83: 0BG2940370 | K83: 450 | L83: 20 | M83: 500157 | N83: 059K30951-N | O83: 1 | P83: MAR MARQUEZ, (500157) CESAR (SEITON) | Q83: OFFICE DEPOT DE MEXICO SA DE CV | R83: 4395 | S83: XGS FSMA | T83: PITSS CHIHUAHUA | U83: =IF(C83=E83,0,1) -> 1
A84: 43346 | B84: 129.00591 | C84: 215.00985 | D84: 43339 | E84: 23.700834 | F84: 43346 | G84: PITSS CHIHUAHUA43346 | H84: 1913629 | I84: 3421086 | J84: 0BG2940370 | K84: 450 | L84: 20 | M84: 500157 | N84: 604K67480-N | O84: 1 | P84: MAR MARQUEZ, (500157) CESAR (SEITON) | Q84: OFFICE DEPOT DE MEXICO SA DE CV | R84: 4395 | S84: XGS FSMA | T84: PITSS CHIHUAHUA | U84: =IF(C84=E84,0,1) -> 1
... A126: 43347 | B126: 32.45063 | C126: 54.084384 | D126: 43340 | E126: 33.534922 | F126: 43347 | G126: PITSS CHIHUAHUA43347 | H126: 1914461 | I126: 3421871 | J126: 0MX4742892 | K126: 450 | L126: 20 | M126: 500157 | N126: 960K60405-N | O126: 1 | P126: MAR MARQUEZ, (500157) CESAR (SEITON) | Q126: HONEYWELL AUTOMOTIVE DE MEXICO S DE RL D | R126: 7845 | S126: XGS RENTAL | T126: PITSS CHIHUAHUA | U126: =IF(C126=E126,0,1) -> 1
A127: 43347 | B127: 93.908764 | C127: 156.51461 | D127: 43343 | E127: 47.201497 | F127: 43347 | G127: PITSS TOLUCA43347 | H127: 1916007 | I127: 3425994 | J127: 0XLT281041 | K127: 420 | L127: 18 | M127: 100039 | N127: 126N00339-N | O127: 1 | P127: PATRICIO AGUILAR, (100039) JHONATTAN (SEITON) | Q127: 0 | R127: 4601 | S127: XGS RENTAL | T127: PITSS TOLUCA | U127: =IF(C127=E127,0,1) -> 1
A128: 43347 | B128: 240.81691 | C128: 401.36152 | D128: 43343 | E128: 46.346782 | F128: 43347 | G128: PITSS TOLUCA43347 | H128: 1915999 | I128: 3425989 | J128: 0XKK398692 | K128: 420 | L128: 18 | M128: 100039 | N128: 604K94280-N | O128: 1 | P128: PATRICIO AGUILAR, (100039) JHONATTAN (SEITON) | Q128: FCA MEXICO SA DE CV | R128: 7530 | S128: XGS FSMA | T128: PITSS TOLUCA | U128: =IF(C128=E128,0,1) -> 1
A129: 43347 | B129: 1.5810004 | C129: 2.6350006 | D129: 43343 | E129: 58.503213 | F129: 43347 | G129: PITSS CHIHUAHUA43347 | H129: 1915911 | I129: 3422502 | J129: 0VMA569561 | K129: 450 | L129: 20 | M129: 500155 | N129: 121N01162-N | O129: 1 | P129: MONTOYA PORTILLO, (500155) CARLOS ALBERTO (SEI | Q129: HONEYWELL AUTOMOTIVE DE MEXICO S DE RL D | R129: 3350 | S129: XGS RENTAL | T129: PITSS CHIHUAHUA | U129: =IF(C129=E129,0,1) -> 1
A130: 43347 | B130: 0.18440576 | C130: 0.30734293 | D130: 43343 | E130: 19.458262 | F130: 43347 | G130: PITSS CHIHUAHUA43347 | H130: 1915911 | I130: 3422502 | J130: 0VMA569561 | K130: 450 | L130: 20 | M130: 500155 | N130: 003N01081-N | O130: 1 | P130: MONTOYA PORTILLO, (500155) CARLOS ALBERTO (SEI | Q130: HONEYWELL AUTOMOTIVE DE MEXICO S DE RL D | R130: 3350 | S130: XGS RENTAL | T130: PITSS CHIHUAHUA | U130: =IF(C130=E130,0,1) -> 1
A131: 43347 | B131: 85.048254 | C131: 141.74709 | D131: 43343 | E131: 8.828802 | F131: 43347 | G131: PITSS CHIHUAHUA43347 | H131: 1915911 | I131: 3422502 | J131: 0VMA569561 | K131: 450 | L131: 20 | M131: 500155 | N131: 622S01139-N | O131: 1 | P131: MONTOYA PORTILLO, (500155) CARLOS ALBERTO (SEI | Q131: HONEYWELL AUTOMOTIVE DE MEXICO S DE RL D | R131: 3350 | S131: XGS RENTAL | T131: PITSS CHIHUAHUA | U131: =IF(C131=E131,0,1) -> 1
A132: 43347 | B132: 0.33692579 | C132: 0.56154299 | D132: 43343 | E132: 4.8625725 | F132: 43347 | G132: PITSS CHIHUAHUA43347 | H132: 1915911 | I132: 3422502 | J132: 0VMA569561 | K132: 450 | L132: 20 | M132: 500155 | N132: 003N01080-N | O132: 1 | P132: MONTOYA PORTILLO, (500155) CARLOS ALBERTO (SEI | Q132: HONEYWELL AUTOMOTIVE DE MEXICO S DE RL D | R132: 3350 | S132: XGS RENTAL | T132: PITSS CHIHUAHUA | U132: =IF(C132=E132,0,1) -> 1
A133: 43347 | B133: 1.6123547 | C133: 2.6872578 | D133: 43343 | E133: 17.982661 | F133: 43347 | G133: PITSS CHIHUAHUA43347 | H133: 1915911 | I133: 3422502 | J133: 0VMA569561 | K133: 450 | L133: 20 | M133: 500155 | N133: 121N01208-N | O133: 1 | P133: MONTOYA PORTILLO, (500155) CARLOS ALBERTO (SEI | Q133: HONEYWELL AUTOMOTIVE DE MEXICO S DE RL D | R133: 3350 | S133: XGS RENTAL | T133: PITSS CHIHUAHUA | U133: =IF(C133=E133,0,1) -> 1
A134: 43347 | B134: 4.7254639 | C134: 7.8757732 | D134: 43343 | E134: 18.469804 | F134: 43347 | G134: PITSS CHIHUAHUA43347 | H134: 1915911 | I134: 3422502 | J134: 0VMA569561 | K134: 450 | L134: 20 | M134: 500155 | N134: 005N01031-N | O134: 1 | P134: MONTOYA PORTILLO, (500155) CARLOS ALBERTO (SEI | Q134: HONEYWELL AUTOMOTIVE DE MEXICO S DE RL D | R134: 3350 | S134: XGS RENTAL | T134: PITSS CHIHUAHUA | U134: =IF(C134=E134,0,1) -> 1
A135: 43347 | B135: 3.0004464 | C135: 5.000744 | D135: 43343 | E135: 45.996925 | F135: 43347 | G135: PITSS CHIHUAHUA43347 | H135: 1915911 | I135: 3422502 | J135: 0VMA569561 | K135: 450 | L135: 20 | M135: 500155 | N135: 019N00947-N | O135: 2 | P135: MONTOYA PORTILLO, (500155) CARLOS ALBERTO (SEI | Q135: HONEYWELL AUTOMOTIVE DE MEXICO S DE RL D | R135: 3350 | S135: XGS RENTAL | T135: PITSS CHIHUAHUA | U135: =IF(C135=E135,0,1) -> 1
A136: 43347 | B136: 14.2205 | C136: 23.700834 | D136: 43347 | E136: 20.42369 | F136: 43347 | G136: PITSS CHIHUAHUA43347 | H136: 1917721 | I136: 3426273 | J136: 0EX9300822 | K136: 450 | L136: 20 | M136: 500158 | N136: 059K69802-N | O136: 2 | P136: TORRES RICARDEZ, (500158) ALFREDO (SEITON) | Q136: DELPHI DIESEL SYSTEMS S DE RL DE CV | R136: 5866 | S136: XGS RENTAL | T136: PITSS CHIHUAHUA | U136: =IF(C136=E136,0,1) -> 1
A137: 43347 | B137: 17.550964 | C137: 29.251607 | D137: 43347 | E137: 97.457822 | F137: 43347 | G137: PITSS CHIHUAHUA43347 | H137: 1917721 | I137: 3426273 | J137: 0EX9300822 | K137: 450 | L137: 20 | M137: 500158 | N137: 604K83641-N | O137: 1 | P137: TORRES RICARDEZ, (500158) ALFREDO (SEITON) | Q137: DELPHI DIESEL SYSTEMS S DE RL DE CV | R137: 5866 | S137: XGS RENTAL | T137: PITSS CHIHUAHUA | U137: =IF(C137=E137,0,1) -> 1
...

Sheet temp
A1: SERIE | B1: DIA DE CIERRE | C1: MONTO | D1: costo_referenciado_real | E1: FECHA1 | F1: COSTO REFERENCIADO | G1: clave pitss total | H1: CLAVE | I1: INCIDENT_N | J1: TASK_NUMBE | K1: SUCURSAL | L1: GRUPO | M1: EMPLEADO | N1: PARTE | O1: CANTIDAD | P1: NOMBRE | Q1: RAZON | R1: MODELO | S1: STATUS | T1: ASP | U1: diferencias en septiembre
A2: 0X76704337 | B2: 43345 | C2: 43.373616 | D2: 72.289359 | E2: 43341 | F2: 180.7451 | G2: 43345 | H2: PITSS CHIHUAHUA43345 | I2: 1915245 | J2: 3421734 | K2: 450 | L2: 20 | M2: 500155 | N2: 059K85121-N | O2: 1 | P2: MONTOYA PORTILLO, (500155) CARLOS ALBERTO (SEI | Q2: HONEYWELL AUTOMOTIVE DE MEXICO S DE RL D | R2: 5945 | S2: XGS RENTAL | T2: PITSS CHIHUAHUA | U2: =IF(D2=F2,0,1) -> 1
A3: 0X76704337 | B3: 43345 | C3: 57.925196 | D3: 96.541993 | E3: 43341 | F3: 58.503213 | G3: 43345 | H3: PITSS CHIHUAHUA43345 | I3: 1915245 | J3: 3421734 | K3: 450 | L3: 20 | M3: 500155 | N3: 859K04215-N | O3: 1 | P3: MONTOYA PORTILLO, (500155) CARLOS ALBERTO (SEI | Q3: HONEYWELL AUTOMOTIVE DE MEXICO S DE RL D | R3: 5945 | S3: XGS RENTAL | T3: PITSS CHIHUAHUA | U3: =IF(D3=F3,0,1) -> 1
A4: 0X76704337 | B4: 43345 | C4: 14.2205 | D4: 23.700834 | E4: 43341 | F4: 38.425837 | G4: 43345 | H4: PITSS CHIHUAHUA43345 | I4: 1915245 | J4: 3421734 | K4: 450 | L4: 20 | M4: 500155 | N4: 059K69802-N | O4: 2 | P4: MONTOYA PORTILLO, (500155) CARLOS ALBERTO (SEI | Q4: HONEYWELL AUTOMOTIVE DE MEXICO S DE RL D | R4: 5945 | S4: XGS RENTAL | T4: PITSS CHIHUAHUA | U4: =IF(D4=F4,0,1) -> 1
A5: 0X76704337 | B5: 43345 | C5: 1.4587718 | D5: 2.4312863 | E5: 43341 | F5: 38.620695 | G5: 43345 | H5: PITSS CHIHUAHUA43345 | I5: 1915245 | J5: 3421734 | K5: 450 | L5: 20 | M5: 500155 | N5: 059K59221-N | O5: 1 | P5: MONTOYA PORTILLO, (500155) CARLOS ALBERTO (SEI | Q5: HONEYWELL AUTOMOTIVE DE MEXICO S DE RL D | R5: 5945 | S5: XGS RENTAL | T5: PITSS CHIHUAHUA | U5: =IF(D5=F5,0,1) -> 1
A6: 03AG877899 | B6: 43345 | C6: 605.37274 | D6: 1008.9546 | E6: 43336 | F6: 43.047496 | G6: 43345 | H6: PITSS TAMAULIPAS43345 | I6: 1912931 | J6: 3420692 | K6: 450 | L6: 14 | M6: 500056 | N6: 084K43040-N | O6: 1 | P6: CRUZ HERRERA, (500056) ROBERTO | Q6: OPERADORA OMX SA DE CV | R6: 8075 | S6: SALES ORDE | T6: PITSS TAMAULIPAS | U6: =IF(D6=F6,0,1) -> 1
A7: 0DRB131260 | B7: 43345 | C7: 85.546734 | D7: 142.57789 | E7: 43339 | F7: 38.626009 | G7: 43345 | H7: PITSS JALISCO43345 | I7: 1913693 | J7: 3420961 | K7: 480 | L7: 23 | M7: 800027 | N7: 013R00603-N | O7: 3 | P7: GARCIA VILLACAÐA, (800027) RICARDO PASCUAL | Q7: COMPUTER FORMS SA DE CV | R7: 1263 | S7: FSMA | T7: PITSS JALISCO | U7: =IF(D7=F7,0,1) -> 1
A8: 0DRB131260 | B8: 43345 | C8: 115.23872 | D8: 192.06453 | E8: 43339 | F8: 39.060895 | G8: 43345 | H8: PITSS JALISCO43345 | I8: 1913693 | J8: 3420961 | K8: 480 | L8: 23 | M8: 800027 | N8: 013R00602-N | O8: 1 | P8: GARCIA VILLACAÐA, (800027) RICARDO PASCUAL | Q8: COMPUTER FORMS SA DE CV | R8: 1263 | S8: FSMA | T8: PITSS JALISCO | U8: =IF(D8=F8,0,1) -> 1
A9: 07CX042178 | B9: 43345 | C9: 0.76472589 | D9: 1.2745431 | E9: 43339 | F9: 9.2220593 | G9: 43345 | H9: PITSS TOLUCA43345 | I9: 1914051 | J9: 3421503 | K9: 420 | L9: 18 | M9: 100037 | N9: 120E34245-N | O9: 1 | P9: CASTILLO SANCHEZ, (100037) MIGUEL ANGEL (SEITON | Q9: UNIVERSIDAD AUTONOMA DEL ESTADO DE MEXIC | R9: 7025 | S9: XGS RENTAL | T9: PITSS TOLUCA | U9: =IF(D9=F9,0,1) -> 1
A10: 07CX042178 | B10: 43345 | C10: 0 | D10: 0 | E10: 43339 | F10: 1.1319431 | G10: 43345 | H10: PITSS TOLUCA43345 | I10: 1914051 | J10: 3421503 | K10: 420 | L10: 18 | M10: 100037 | N10: 011K04261-N | O10: 1 | P10: CASTILLO SANCHEZ, (100037) MIGUEL ANGEL (SEITON | Q10: UNIVERSIDAD AUTONOMA DEL ESTADO DE MEXIC | R10: 7025 | S10: XGS RENTAL | T10: PITSS TOLUCA | U10: =IF(D10=F10,0,1) -> 1
A11: 0BG2948814 | B11: 43345 | C11: 3.1689093 | D11: 5.2815155 | E11: 43341 | F11: 132.02549 | G11: 43345 | H11: PITSS NUEVO LEON43345 | I11: 1915259 | J11: 3421836 | K11: 450 | L11: 18 | M11: 500164 | N11: 059K29520-N | O11: 2 | P11: GONZALEZ GUERRERO, (500164) FEDERICO (PITSS) | Q11: OFFICE DEPOT DE MEXICO SA DE CV | R11: 4395 | S11: XGS FSMA | T11: PITSS NUEVO LEON | U11: =IF(D11=F11,0,1) -> 1
A12: 0BG2948814 | B12: 43345 | C12: 3.5462237 | D12: 5.9103728 | E12: 43341 | F12: 55.83367 | G12: 43345 | H12: PITSS NUEVO LEON43345 | I12: 1915259 | J12: 3421836 | K12: 450 | L12: 18 | M12: 500164 | N12: 059K29510-N | O12: 2 | P12: GONZALEZ GUERRERO, (500164) FEDERICO (PITSS) | Q12: OFFICE DEPOT DE MEXICO SA DE CV | R12: 4395 | S12: XGS FSMA | T12: PITSS NUEVO LEON | U12: =IF(D12=F12,0,1) -> 1
A13: 0BG2948814 | B13: 43345 | C13: 9.0714878 | D13: 15.119146 | E13: 43341 | F13: 152.25166 | G13: 43345 | H13: PITSS NUEVO LEON43345 | I13: 1915259 | J13: 3421836 | K13: 450 | L13: 18 | M13: 500164 | N13: 059K30951-N | O13: 2 | P13: GONZALEZ GUERRERO, (500164) FEDERICO (PITSS) | Q13: OFFICE DEPOT DE MEXICO SA DE CV | R13: 4395 | S13: XGS FSMA | T13: PITSS NUEVO LEON | U13: =IF(D13=F13,0,1) -> 1
... A70: 0MX4355681 | B70: 43346 | C70: 23.979125 | D70: 39.965209 | E70: 43336 | F70: 11.800374 | G70: 43346 | H70: PITSS CHIHUAHUA43346 | I70: 1912917 | J70: 3421024 | K70: 450 | L70: 20 | M70: 500157 | N70: 094K92393-N | O70: 1 | P70: MAR MARQUEZ, (500157) CESAR (SEITON) | Q70: HONEYWELL AUTOMOTIVE DE MEXICO S DE RL D | R70: 7845 | S70: XGS RENTAL | T70: PITSS CHIHUAHUA | U70: =IF(D70=F70,0,1) -> 1
A71: 0EX9293026 | B71: 43346 | C71: 102.56627 | D71: 170.94378 | E71: 43339 | F71: 24.800006 | G71: 43346 | H71: PITSS TOLUCA43346 | I71: 1913803 | J71: 3421220 | K71: 420 | L71: 18 | M71: 100038 | N71: 960K73366-N | O71: 1 | P71: GUTIERREZ GUTIERREZ, (100038) LUIS (SEITON) | Q71: 0 | R71: 5866 | S71: 0 | T71: PITSS TOLUCA | U71: =IF(D71=F71,0,1) -> 1
A72: 0EX9293026 | B72: 43346 | C72: 20.86389 | D72: 34.773151 | E72: 43339 | F72: 2.7705149 | G72: 43346 | H72: PITSS TOLUCA43346 | I72: 1913803 | J72: 3421220 | K72: 420 | L72: 18 | M72: 100038 | N72: 604K67240-N | O72: 1 | P72: GUTIERREZ GUTIERREZ, (100038) LUIS (SEITON) | Q72: 0 | R72: 5866 | S72: 0 | T72: PITSS TOLUCA | U72: =IF(D72=F72,0,1) -> 1
A73: 0E2B658511 | B73: 43346 | C73: 14.356546 | D73: 23.927577 | E73: 43338 | F73: 7.569316 | G73: 43346 | H73: PITSS QUERETARO43346 | I73: 1913379 | J73: 3421008 | K73: 480 | L73: 01 | M73: 800187 | N73: 127K66880-N | O73: 1 | P73: MEJIA DUARTE, (800187) JOSE LUIS (PITSS) | Q73: OPERADORA OMX SA DE CV | R73: 0070 | S73: XGS FSMA | T73: PITSS QUERETARO | U73: =IF(D73=F73,0,1) -> 1
A74: 0E2B658511 | B74: 43346 | C74: 10.568522 | D74: 17.614204 | E74: 43338 | F74: 211.55999 | G74: 43346 | H74: PITSS QUERETARO43346 | I74: 1913379 | J74: 3421008 | K74: 480 | L74: 01 | M74: 800187 | N74: 604K56080-N | O74: 3 | P74: MEJIA DUARTE, (800187) JOSE LUIS (PITSS) | Q74: OPERADORA OMX SA DE CV | R74: 0070 | S74: XGS FSMA | T74: PITSS QUERETARO | U74: =IF(D74=F74,0,1) -> 1
A75: 0E2B658511 | B75: 43346 | C75: 3.9974066 | D75: 6.6623444 | E75: 43338 | F75: 4.8528297 | G75: 43346 | H75: PITSS QUERETARO43346 | I75: 1913379 | J75: 3421008 | K75: 480 | L75: 01 | M75: 800187 | N75: 121K33941-N | O75: 1 | P75: MEJIA DUARTE, (800187) JOSE LUIS (PITSS) | Q75: OPERADORA OMX SA DE CV | R75: 0070 | S75: XGS FSMA | T75: PITSS QUERETARO | U75: =IF(D75=F75,0,1) -> 1
A76: 0VMA569564 | B76: 43346 | C76: 3.5138065 | D76: 5.8563442 | E76: 43341 | F76: 2.500372 | G76: 43346 | H76: PITSS NUEVO LEON43346 | I76: 1914899 | J76: 3421621 | K76: 450 | L76: 18 | M76: 500028 | N76: 029N00412-N | O76: 1 | P76: PEREZ BALBOA, (500028) CESAR | Q76: BOTANAS Y DERIVADOS SA DE CV | R76: 3350 | S76: XGS RENTAL | T76: PITSS NUEVO LEON | U76: =IF(D76=F76,0,1) -> 1
A77: 0VMA569564 | B77: 43346 | C77: 0.70361159 | D77: 1.172686 | E77: 43341 | F77: 1.5110289 | G77: 43346 | H77: PITSS NUEVO LEON43346 | I77: 1914899 | J77: 3421621 | K77: 450 | L77: 18 | M77: 500028 | N77: 029N00410-N | O77: 1 | P77: PEREZ BALBOA, (500028) CESAR | Q77: BOTANAS Y DERIVADOS SA DE CV | R77: 3350 | S77: XGS RENTAL | T77: PITSS NUEVO LEON | U77: =IF(D77=F77,0,1) -> 1
A78: 0VMA561125 | B78: 43346 | C78: 47.280679 | D78: 78.801132 | E78: 43341 | F78: 5.3196012 | G78: 43346 | H78: PITSS CHIHUAHUA43346 | I78: 1914985 | J78: 3421632 | K78: 450 | L78: 20 | M78: 500155 | N78: 126N00342-N | O78: 1 | P78: MONTOYA PORTILLO, (500155) CARLOS ALBERTO (SEI | Q78: HONEYWELL AUTOMOTIVE DE MEXICO S DE RL D | R78: 3350 | S78: XGS RENTAL | T78: PITSS CHIHUAHUA | U78: =IF(D78=F78,0,1) -> 1
A79: 0VMA561125 | B79: 43346 | C79: 4.3284867 | D79: 7.2141445 | E79: 43341 | F79: 97.457822 | G79: 43346 | H79: PITSS CHIHUAHUA43346 | I79: 1914985 | J79: 3421632 | K79: 450 | L79: 20 | M79: 500155 | N79: 022N02413-N | O79: 2 | P79: MONTOYA PORTILLO, (500155) CARLOS ALBERTO (SEI | Q79: HONEYWELL AUTOMOTIVE DE MEXICO S DE RL D | R79: 3350 | S79: XGS RENTAL | T79: PITSS CHIHUAHUA | U79: =IF(D79=F79,0,1) -> 1
A80: 0VMA561125 | B80: 43346 | C80: 1.5198861 | D80: 2.5331434 | E80: 43341 | F80: 14.345032 | G80: 43346 | H80: PITSS CHIHUAHUA43346 | I80: 1914985 | J80: 3421632 | K80: 450 | L80: 20 | M80: 500155 | N80: 003N01042-N | O80: 1 | P80: MONTOYA PORTILLO, (500155) CARLOS ALBERTO (SEI | Q80: HONEYWELL AUTOMOTIVE DE MEXICO S DE RL D | R80: 3350 | S80: XGS RENTAL | T80: PITSS CHIHUAHUA | U80: =IF(D80=F80,0,1) -> 1
A81: 0VMA561125 | B81: 43346 | C81: 3.0004464 | D81: 5.000744 | E81: 43341 | F81: 13.833089 | G81: 43346 | H81: PITSS CHIHUAHUA43346 | I81: 1914985 | J81: 3421632 | K81: 450 | L81: 20 | M81: 500155 | N81: 019N00947-N | O81: 2 | P81: MONTOYA PORTILLO, (500155) CARLOS ALBERTO (SEI | Q81: HONEYWELL AUTOMOTIVE DE MEXICO S DE RL D | R81: 3350 | S81: XGS RENTAL | T81: PITSS CHIHUAHUA | U81: =IF(D81=F81,0,1) -> 1
A82: 0VMA561125 | B82: 43346 | C82: 7.7338818 | D82: 12.889803 | E82: 43341 | F82: 44.376067 | G82: 43346 | H82: PITSS CHIHUAHUA43346 | I82: 1914985 | J82: 3421632 | K82: 450 | L82: 20 | M82: 500155 | N82: 130N01533-N | O82: 1 | P82: MONTOYA PORTILLO, (500155) CARLOS ALBERTO (SEI | Q82: HONEYWELL AUTOMOTIVE DE MEXICO S DE RL D | R82: 3350 | S82: XGS RENTAL | T82: PITSS CHIHUAHUA | U82: =IF(D82=F82,0,1) -> 1
A83: 0BG2940370 | B83: 43346 | C83: 4.5357439 | D83: 7.5595732 | E83: 43339 | F83: 29.251607 | G83: 43346 | H83: PITSS CHIHUAHUA43346 | I83: 1913629 | J83: 3421086 | K83: 450 | L83: 20 | M83: 500157 | N83: 059K30951-N | O83: 1 | P83: MAR MARQUEZ, (500157) CESAR (SEITON) | Q83: OFFICE DEPOT DE MEXICO SA DE CV | R83: 4395 | S83: XGS FSMA | T83: PITSS CHIHUAHUA | U83: =IF(D83=F83,0,1) -> 1
A84: 0BG2940370 | B84: 43346 | C84: 129.00591 | D84: 215.00985 | E84: 43339 | F84: 23.700834 | G84: 43346 | H84: PITSS CHIHUAHUA43346 | I84: 1913629 | J84: 3421086 | K84: 450 | L84: 20 | M84: 500157 | N84: 604K67480-N | O84: 1 | P84: MAR MARQUEZ, (500157) CESAR (SEITON) | Q84: OFFICE DEPOT DE MEXICO SA DE CV | R84: 4395 | S84: XGS FSMA | T84: PITSS CHIHUAHUA | U84: =IF(D84=F84,0,1) -> 1
... A126: 0MX4742892 | B126: 43347 | C126: 32.45063 | D126: 54.084384 | E126: 43340 | F126: 33.534922 | G126: 43347 | H126: PITSS CHIHUAHUA43347 | I126: 1914461 | J126: 3421871 | K126: 450 | L126: 20 | M126: 500157 | N126: 960K60405-N | O126: 1 | P126: MAR MARQUEZ, (500157) CESAR (SEITON) | Q126: HONEYWELL AUTOMOTIVE DE MEXICO S DE RL D | R126: 7845 | S126: XGS RENTAL | T126: PITSS CHIHUAHUA | U126: =IF(D126=F126,0,1) -> 1
A127: 0XLT281041 | B127: 43347 | C127: 93.908764 | D127: 156.51461 | E127: 43343 | F127: 47.201497 | G127: 43347 | H127: PITSS TOLUCA43347 | I127: 1916007 | J127: 3425994 | K127: 420 | L127: 18 | M127: 100039 | N127: 126N00339-N | O127: 1 | P127: PATRICIO AGUILAR, (100039) JHONATTAN (SEITON) | Q127: 0 | R127: 4601 | S127: XGS RENTAL | T127: PITSS TOLUCA | U127: =IF(D127=F127,0,1) -> 1
A128: 0XKK398692 | B128: 43347 | C128: 240.81691 | D128: 401.36152 | E128: 43343 | F128: 46.346782 | G128: 43347 | H128: PITSS TOLUCA43347 | I128: 1915999 | J128: 3425989 | K128: 420 | L128: 18 | M128: 100039 | N128: 604K94280-N | O128: 1 | P128: PATRICIO AGUILAR, (100039) JHONATTAN (SEITON) | Q128: FCA MEXICO SA DE CV | R128: 7530 | S128: XGS FSMA | T128: PITSS TOLUCA | U128: =IF(D128=F128,0,1) -> 1
A129: 0VMA569561 | B129: 43347 | C129: 1.5810004 | D129: 2.6350006 | E129: 43343 | F129: 58.503213 | G129: 43347 | H129: PITSS CHIHUAHUA43347 | I129: 1915911 | J129: 3422502 | K129: 450 | L129: 20 | M129: 500155 | N129: 121N01162-N | O129: 1 | P129: MONTOYA PORTILLO, (500155) CARLOS ALBERTO (SEI | Q129: HONEYWELL AUTOMOTIVE DE MEXICO S DE RL D | R129: 3350 | S129: XGS RENTAL | T129: PITSS CHIHUAHUA | U129: =IF(D129=F129,0,1) -> 1
A130: 0VMA569561 | B130: 43347 | C130: 0.18440576 | D130: 0.30734293 | E130: 43343 | F130: 19.458262 | G130: 43347 | H130: PITSS CHIHUAHUA43347 | I130: 1915911 | J130: 3422502 | K130: 450 | L130: 20 | M130: 500155 | N130: 003N01081-N | O130: 1 | P130: MONTOYA PORTILLO, (500155) CARLOS ALBERTO (SEI | Q130: HONEYWELL AUTOMOTIVE DE MEXICO S DE RL D | R130: 3350 | S130: XGS RENTAL | T130: PITSS CHIHUAHUA | U130: =IF(D130=F130,0,1) -> 1
A131: 0VMA569561 | B131: 43347 | C131: 85.048254 | D131: 141.74709 | E131: 43343 | F131: 8.828802 | G131: 43347 | H131: PITSS CHIHUAHUA43347 | I131: 1915911 | J131: 3422502 | K131: 450 | L131: 20 | M131: 500155 | N131: 622S01139-N | O131: 1 | P131: MONTOYA PORTILLO, (500155) CARLOS ALBERTO (SEI | Q131: HONEYWELL AUTOMOTIVE DE MEXICO S DE RL D | R131: 3350 | S131: XGS RENTAL | T131: PITSS CHIHUAHUA | U131: =IF(D131=F131,0,1) -> 1
A132: 0VMA569561 | B132: 43347 | C132: 0.33692579 | D132: 0.56154299 | E132: 43343 | F132: 4.8625725 | G132: 43347 | H132: PITSS CHIHUAHUA43347 | I132: 1915911 | J132: 3422502 | K132: 450 | L132: 20 | M132: 500155 | N132: 003N01080-N | O132: 1 | P132: MONTOYA PORTILLO, (500155) CARLOS ALBERTO (SEI | Q132: HONEYWELL AUTOMOTIVE DE MEXICO S DE RL D | R132: 3350 | S132: XGS RENTAL | T132: PITSS CHIHUAHUA | U132: =IF(D132=F132,0,1) -> 1
A133: 0VMA569561 | B133: 43347 | C133: 1.6123547 | D133: 2.6872578 | E133: 43343 | F133: 17.982661 | G133: 43347 | H133: PITSS CHIHUAHUA43347 | I133: 1915911 | J133: 3422502 | K133: 450 | L133: 20 | M133: 500155 | N133: 121N01208-N | O133: 1 | P133: MONTOYA PORTILLO, (500155) CARLOS ALBERTO (SEI | Q133: HONEYWELL AUTOMOTIVE DE MEXICO S DE RL D | R133: 3350 | S133: XGS RENTAL | T133: PITSS CHIHUAHUA | U133: =IF(D133=F133,0,1) -> 1
A134: 0VMA569561 | B134: 43347 | C134: 4.7254639 | D134: 7.8757732 | E134: 43343 | F134: 18.469804 | G134: 43347 | H134: PITSS CHIHUAHUA43347 | I134: 1915911 | J134: 3422502 | K134: 450 | L134: 20 | M134: 500155 | N134: 005N01031-N | O134: 1 | P134: MONTOYA PORTILLO, (500155) CARLOS ALBERTO (SEI | Q134: HONEYWELL AUTOMOTIVE DE MEXICO S DE RL D | R134: 3350 | S134: XGS RENTAL | T134: PITSS CHIHUAHUA | U134: =IF(D134=F134,0,1) -> 1
A135: 0VMA569561 | B135: 43347 | C135: 3.0004464 | D135: 5.000744 | E135: 43343 | F135: 45.996925 | G135: 43347 | H135: PITSS CHIHUAHUA43347 | I135: 1915911 | J135: 3422502 | K135: 450 | L135: 20 | M135: 500155 | N135: 019N00947-N | O135: 2 | P135: MONTOYA PORTILLO, (500155) CARLOS ALBERTO (SEI | Q135: HONEYWELL AUTOMOTIVE DE MEXICO S DE RL D | R135: 3350 | S135: XGS RENTAL | T135: PITSS CHIHUAHUA | U135: =IF(D135=F135,0,1) -> 1
A136: 0EX9300822 | B136: 43347 | C136: 14.2205 | D136: 23.700834 | E136: 43347 | F136: 20.42369 | G136: 43347 | H136: PITSS CHIHUAHUA43347 | I136: 1917721 | J136: 3426273 | K136: 450 | L136: 20 | M136: 500158 | N136: 059K69802-N | O136: 2 | P136: TORRES RICARDEZ, (500158) ALFREDO (SEITON) | Q136: DELPHI DIESEL SYSTEMS S DE RL DE CV | R136: 5866 | S136: XGS RENTAL | T136: PITSS CHIHUAHUA | U136: =IF(D136=F136,0,1) -> 1
A137: 0EX9300822 | B137: 43347 | C137: 17.550964 | D137: 29.251607 | E137: 43347 | F137: 97.457822 | G137: 43347 | H137: PITSS CHIHUAHUA43347 | I137: 1917721 | J137: 3426273 | K137: 450 | L137: 20 | M137: 500158 | N137: 604K83641-N | O137: 1 | P137: TORRES RICARDEZ, (500158) ALFREDO (SEITON) | Q137: DELPHI DIESEL SYSTEMS S DE RL DE CV | R137: 5866 | S137: XGS RENTAL | T137: PITSS CHIHUAHUA | U137: =IF(D137=F137,0,1) -> 1
...

Sheet lecturas_Data
A1: Serie | B1: Fecha | C1: Categoría | D1: Clave | E1: Descripción | F1: Cantidad | G1: Costo | H1: Asesor/Técnico | I1: Lectura | J1: Origen | K1: Folio | L1: Categoría
A2: 002411031 | B2: 43546.505 | C2: CORRECTIVO / EMERGENCIA | D2: SERVICIO Y MTTO | E2: OS 67126 Tarea... 3577274 Fecha... 22 Marzo 2019 Inicio... 1000 Llegada... 1015 Concluída... 1115 Contador... 4514 Equipo funciona... Si Falla intermitente... - Folio de almacén... - Comentarios del RT... Reforzamiento de operación y comprobación de calidad de impresión. Descarga... - Firma... Maricruz Leyva | F2: 1 | G2: 0 | H2: JOSE LUIS MEJIA/800187 | I2: 4514 | J2: Orden de Servicio | K2: 67126 | L2: CORRECTIVO / EMERGENCIA
A3: 002411031 | B3: 43531.442 | C3: MANTENIMIENTO PREVENTIVO | D3: SERVICIO Y MTTO | E3: Se realizó mantenimiento preventivo: limpieza de gomas dadf, escáner dúplex, área xerográfica, msi, transporte de papel, inspección fusor, aspirado filtro de succión, revisión calidad de impresión, rev. de niveles de consumibles. ok | F3: 1 | G3: 0 | H3: JOSE LUIS MEJIA/800187 | I3: 4095 | J3: Orden de Servicio | K3: 64159 | L3: MANTENIMIENTO PREVENTIVO
A4: 002411031 | B4: 43530.744 | C4: CONFIGURACION | D4: SERVICIO Y MTTO | E4: Se realizó mantenimiento preventivo: limpieza de gomas dadf, escáner dúplex, área xerográfica, msi, transporte de papel, inspección fusor, aspirado filtro de succión, revisión calidad de impresión. ok | F4: 1 | G4: 0 | H4: JOSE LUIS MEJIA/800187 | I4: 4071 | J4: Orden de Servicio | K4: 64450 | L4: CONFIGURACION
A5: 002411031 | B5: 43467.773 | C5: MANTENIMIENTO PREVENTIVO | D5: SERVICIO Y MTTO | E5: OS 53465 Tarea... - Fecha... 02 Enero 2019 Inicio... 0940 Llegada... 1005 Concluída... 1110 Contador... 2232 Equipo... Funcionando Falla intermitente...- Folio de almacén... - Comentario Rt... Se ajustó calidad de impresión, se reinstaló s o., Se reforzó operación general del equipo. Descarga ... - Firma... Laura Ochoa | F5: 1 | G5: 0 | H5: JOSE LUIS MEJIA/800187 | I5: 2245 | J5: Orden de Servicio | K5: 53463 | L5: CORRECTIVO/EMERGENCIA PROACTIVO
A6: 002411031 | B6: 43453.495 | C6: CORRECTIVO / EMERGENCIA | D6: SERVICIO Y MTTO | E6: OS 52543 Tarea... 3507168 Fecha... 19 Diciembre 2018 Inicio... 0745 Llegada... 0800 Concluída...0900 Contador... 1372516 Equipo... Funcionando Falla intermitente...- Folio de almacén... 2060 Comentario Rt... Se reforzó configuración de márgenes de impresión tanto desde el driver de impresión como PDFs impresos desde USB Descarga ... - Firma... Laura Ochoa | F6: 1 | G6: 0 | H6: JOSE LUIS MEJIA/800187 | I6: 2071 | J6: Orden de Servicio | K6: 52543 | L6: INSTALACION
A7: 002411031 | B7: 43444.741 | C7: CORRECTIVO / EMERGENCIA | D7: SERVICIO Y MTTO | E7: OS 50936 Tarea... 3501486 Fecha... 10 Diciembre 2018 Inicio... 1050 Llegada... 1115 Concluída...1215 Contador... 1856 Equipo... Funcionando Folio de almacén... - Comentario Rt... Al retirar papel atorado safaron uñas de despegue del rodillo de calor del fusor. Siguen sin configurar los márgenes de impresión. Es necesario reforzar estas acciones para evitar los atoramientos y las constantes llamada | F7: 1 | G7: 0 | H7: JOSE LUIS MEJIA/800187 | I7: 1856 | J7: Orden de Servicio | K7: 50936 | L7: AJUSTE LECTURA
A8: 002411031 | B8: 43439.623 | C8: CORRECTIVO / EMERGENCIA | D8: SERVICIO Y MTTO | E8: OS 50259 Tarea... 3496639 Fecha... 05 Diciembre 2018 Inicio... 1015 Llegada... 1025 Concluida...1125 Contador... 1749 Equipo... Funcionando Folio de almacén... - Comentario Rt... Nuevamente hay atoramientos en el fusor debido a qué no configuran los márgenes de impresión. al parecer los operadores actules no comparten la información con los diferentes turnos, es necesario reforzar estas acciones p | F8: 1 | G8: 0 | H8: JOSE LUIS MEJIA/800187 | I8: 1749 | J8: Orden de Servicio | K8: 50259 | L8: APOYO VIA TELEFONICA
A9: 002411031 | B9: 43438.668 | C9: CORRECTIVO / EMERGENCIA | D9: SERVICIO Y MTTO | E9: OS 50015 Tarea... 3496219 Fecha... 04 Diciembre 2018 Inicio... 0945 Llegada... 1005 Concluida...1105 Contador... Equipo... Funcionando Folio de almacén...- Comentario Rt... Atoramiento por error de operación. Al imprimir no configuran margen blanco en impresiones. Se indicó a usuario como configurarlo. Persona capacitada durante la instalación ya no labora en Omx. Descarga ... - Firma... Karla Mo | F9: 1 | G9: 0 | H9: JOSE LUIS MEJIA/800187 | I9: 1699 | J9: Orden de Servicio | K9: 50015 | L9: GARANTIA DE SERVICIO
A10: 002411031 | B10: 43434.747 | C10: CORRECTIVO / EMERGENCIA | D10: SERVICIO Y MTTO | E10: OS 49594 Tarea... 3492313 Fecha... 30 Noviembre 2018 Inicio... 1205 Llegada... 1225 Concluida...1330 Contador.. 1681 Equipo... Funcionando Folio de almacén... - Comentarios del RT... Revisión/ lmpieza del recorrido de papel Descarga ... - Firma... Laura Ochoa | F10: 1 | G10: 0 | H10: JOSE LUIS MEJIA/800187 | I10: 1681 | J10: Orden de Servicio | K10: 49594 | L10: AUDITORIA DE SERVICIO
A11: 002411031 | B11: 43431.762 | C11: CORRECTIVO / EMERGENCIA | D11: SERVICIO Y MTTO | E11: OS 48862 Tarea... 3491172 Fecha... 27 Noviembre 2018 Inicio... 1200 Llegada... 1220 Concluida...1325 Contador... 1651 Equipo... funcionando Folio de almacén... Conclusión Comentarios del RT... Retiro papel del recorrido y se retiró pedazo de papel del alimentador del rollo 1 Descarga ... - Firma... Karla Moreno | F11: 1 | G11: 0 | H11: JOSE LUIS MEJIA/800187 | I11: 1653 | J11: Orden de Servicio | K11: 48862 | L11: SERVICIO CON CARGO MANO DE OBRA
A12: 002411031 | B12: 43416.769 | C12: CORRECTIVO / EMERGENCIA | D12: SERVICIO Y MTTO | E12: tarea 3480129 concluida y funcionando inicio 17:55 llegada 18:00 salida. 18:30 medidor 1355 retiré hoja atorada subsistema 03/41 firma Felipe Rodríguez | F12: 1 | G12: 0 | H12: MIGUEL ANGEL CASTILLO/100037 | I12: 1356 | J12: Orden de Servicio | K12: 46322 | L12: CAMBIO DE UBICACION
A13: 002411031 | B13: 43402.815 | C13: CORRECTIVO / EMERGENCIA | D13: SERVICIO Y MTTO | E13: OS 44349 Tarea... 3469436 Fecha... 29 octubre 2018 Inicio... 1500 Llegada... 1520 Concluida...1615 Contador.. 994 Equipo... Funciona Folio de almacén... - Comentarios del RT... Se encontró papel dentro del equipo, se indicó al cliente. Descarga ... - Firma... Laura del Valle | F13: 1 | G13: 0 | H13: JOSE LUIS MEJIA/800187 | I13: 997 | J13: Orden de Servicio | K13: 44349 | L13: RETIRO
... A19: 02TX060372 | B19: 43504.473 | C19: CORRECTIVO / EMERGENCIA | D19: SERVICIO Y MTTO | E19: requiere cambio de cilindro negro | F19: 1 | G19: 0 | H19: CARLOS GUITIERREZ/800196 | I19: 53468 | J19: Orden de Servicio | K19: 59776 | L19: SERVICIOS
A20: 02TX060372 | B20: 43494.442 | C20: MANTENIMIENTO PREVENTIVO | D20: SERVICIO Y MTTO | E20: mtto preventivo | F20: 1 | G20: 0 | H20: LUCIO DEL PILAR MENDEZ | I20: 49680 | J20: Orden de Servicio | K20: 57122
A21: 02TX060400 | B21: 43544.699 | C21: MANTENIMIENTO PREVENTIVO | D21: SERVICIO Y MTTO | E21: Limpieza general | F21: 1 | G21: 0 | H21: HECTOR MARIN AVILA | I21: 61571 | J21: Orden de Servicio | K21: 66830
A22: 02TX060400 | B22: 43494.477 | C22: MANTENIMIENTO PREVENTIVO | D22: SERVICIO Y MTTO | E22: mantenimiento | F22: 1 | G22: 0 | H22: CARLOS GUITIERREZ/800196 | I22: 46522 | J22: Orden de Servicio | K22: 57137
A23: 02TX060400 | B23: 43474.578 | C23: CORRECTIVO / EMERGENCIA | D23: SERVICIO Y MTTO | E23: se reemplazaron partes solicitadas con el folio 921517 | F23: 1 | G23: 0 | H23: CARLOS GUITIERREZ/800196 | I23: 39510 | J23: Orden de Servicio | K23: 54717
A24: 02TX060400 | B24: 43473.407 | C24: MANTENIMIENTO PREVENTIVO | D24: SERVICIO Y MTTO | E24: se retira grapa atorada en Adf, se configuran 2 PCs como impresoras | F24: 1 | G24: 0 | H24: CARLOS GUITIERREZ/800196 | I24: 39078 | J24: Orden de Servicio | K24: 54292
A25: 02TX060400 | B25: 43460.515 | C25: CORRECTIVO/EMERGENCIA PROACTIVO | D25: SERVICIO Y MTTO | E25: se reemplazaron partes solicitadas | F25: 1 | G25: 0 | H25: CARLOS GUITIERREZ/800196 | I25: 38065 | J25: Orden de Servicio | K25: 52020
A26: 02TX060400 | B26: 43453.542 | C26: CORRECTIVO/EMERGENCIA PROACTIVO | D26: SERVICIO Y MTTO | E26: se instaló cables planos pedidos pero el equipo no quedó | F26: 1 | G26: 0 | H26: CARLOS GUITIERREZ/800196 | I26: 37641 | J26: Orden de Servicio | K26: 52020
A27: 02TX060400 | B27: 43451.41 | C27: CORRECTIVO/EMERGENCIA PROACTIVO | D27: SERVICIO Y MTTO | E27: se actualiza firmware y se resetea sistema... no quedó, se encuentro boletín de cambio de cables planos | F27: 1 | G27: 0 | H27: CARLOS GUITIERREZ/800196 | I27: 36770 | J27: Orden de Servicio | K27: 52020
A28: 02TX060400 | B28: 43445.598 | C28: MANTENIMIENTO PREVENTIVO | D28: SERVICIO Y MTTO | E28: se actualiza firmware y se configura scaner a smb | F28: 1 | G28: 0 | H28: CARLOS GUITIERREZ/800196 | I28: 36044 | J28: Orden de Servicio | K28: 51235
A29: 02TX061769 | B29: 43515.449 | C29: CORRECTIVO / EMERGENCIA | D29: SERVICIO Y MTTO | E29: OS 61555 tarea:3549848 inicio viaje: 8:49 llegada: 9:20 salida: 10:00 contador: 118011 firma Víctor Molina equipo funcionando correctamente se descarga pieza: 604K56080 cantidad 1 | F29: 1 | G29: 0 | H29: RAFAEL CASAS/500027 | I29: 118200 | J29: Orden de Servicio | K29: 61555
A30: 02TX061769 | B30: 43511.71 | C30: CORRECTIVO / EMERGENCIA | D30: SERVICIO Y MTTO | E30: OS 61555 tarea:3549848 inicio viaje: 2:30 llegada:2:34 finalizó: 3:50 contador: B&N: 85,888 Color: 32,123 Total: 118,011 firma Víctor Molina equipo requiere gomas de alimentación : número de parte:607K12020 cantidad 4 folio: 273933 equipo funcionando. | F30: 1 | G30: 0 | H30: RAFAEL CASAS/500027 | I30: 118011 | J30: Orden de Servicio | K30: 61555
A31: 02TX061769 | B31: 43388.628 | C31: CORRECTIVO / EMERGENCIA | D31: SERVICIO Y MTTO | E31: buen día envío datos de tarea 3458335 serie 2TX061769 viaje 1100 a 1130 salida 1230 medidor b27417 c 10115 atendí Victor Molina código 03 38 equipo ok limpieza y trabaja ok | F31: 1 | G31: 0 | H31: CESAR E. MAR/500157 | I31: 2385 | J31: Orden de Servicio | K31: 42039
... A13336: Y4X838933 | B13336: 43342.704 | C13336: CORRECTIVO / EMERGENCIA | D13336: SERVICIO Y MTTO | E13336: 34967 3421852 30--08--2018 15:00-16:30-16:45 revisión general pendiente por asistencia | F13336: 1 | G13336: 0 | H13336: JUAN GUADALUPE ESCOBEDO/500083 | I13336: 0 | J13336: Orden de Servicio | K13336: 34967

Sheet unique
A1: lecturas | B1: data | C1: SERIE | D1: TECNICO | E1: unique data
A2: 002411031 | B2: 002411031 | C2: =VLOOKUP(A2,temp!$A$2:$U$4706,18,FALSE) -> 4310 | D2: =VLOOKUP(A2,temp!$A$2:$U$4706,16,FALSE) -> MEJIA DUARTE, (800187) JOSE LUIS (PITSS) | E2: =SUMPRODUCT(1/COUNTIF(data!J2:J4706,data!J2:J4706)) -> 1235
A3: 02TX060372 | B3: 02TX060372 | C3: =VLOOKUP(A3,temp!$A$2:$U$4706,18,FALSE) -> 8035 | D3: =VLOOKUP(A3,temp!$A$2:$U$4706,16,FALSE) -> GUTIERREZ MUNOZ, (800196) CARLOS
A4: 02TX060400 | B4: 02TX060400 | C4: =VLOOKUP(A4,temp!$A$2:$U$4706,18,FALSE) -> 8035 | D4: =VLOOKUP(A4,temp!$A$2:$U$4706,16,FALSE) -> GUTIERREZ MUNOZ, (800196) CARLOS
A5: 02TX061769 | B5: 02TX061769 | C5: =VLOOKUP(A5,temp!$A$2:$U$4706,18,FALSE) -> 8030 | D5: =VLOOKUP(A5,temp!$A$2:$U$4706,16,FALSE) -> CASAS CHAVARRIA, (500027) RAFAEL
A6: 03AG873331 | B6: 03AG873331 | C6: =VLOOKUP(A6,temp!$A$2:$U$4706,18,FALSE) -> 8075 | D6: =VLOOKUP(A6,temp!$A$2:$U$4706,16,FALSE) -> TORRES PEREZ, (800142) CARLOS ALBERTO
A7: 03AG873369 | B7: 03AG873369 | C7: =VLOOKUP(A7,temp!$A$2:$U$4706,18,FALSE) -> 8075 | D7: =VLOOKUP(A7,temp!$A$2:$U$4706,16,FALSE) -> HERNADEZ RODRIGUEZ, (000207) JORGE (PITSS)
A8: 03AG873408 | B8: 03AG873408 | C8: =VLOOKUP(A8,temp!$A$2:$U$4706,18,FALSE) -> 8075 | D8: =VLOOKUP(A8,temp!$A$2:$U$4706,16,FALSE) -> LOPEZ TERRON, (000196) ROBERTO PORFIRIO (SEITON
A9: 03AG873545 | B9: 03AG873545 | C9: =VLOOKUP(A9,temp!$A$2:$U$4706,18,FALSE) -> 8075 | D9: =VLOOKUP(A9,temp!$A$2:$U$4706,16,FALSE) -> MEJIA DUARTE, (800187) JOSE LUIS (PITSS)
A10: 03AG873634 | B10: 03AG873634 | C10: =VLOOKUP(A10,temp!$A$2:$U$4706,18,FALSE) -> 8075 | D10: =VLOOKUP(A10,temp!$A$2:$U$4706,16,FALSE) -> LOPEZ TERRON, (000196) ROBERTO PORFIRIO (SEITON
A11: 03AG873673 | B11: 03AG873673 | C11: =VLOOKUP(A11,temp!$A$2:$U$4706,18,FALSE) -> 8075 | D11: =VLOOKUP(A11,temp!$A$2:$U$4706,16,FALSE) -> MEJIA DUARTE, (800187) JOSE LUIS (PITSS)
A12: 03AG873706 | B12: 03AG873706 | C12: =VLOOKUP(A12,temp!$A$2:$U$4706,18,FALSE) -> 8075 | D12: =VLOOKUP(A12,temp!$A$2:$U$4706,16,FALSE) -> HUERAMO HUERAMO, (800110) DANIEL
A13: 03AG873748 | B13: 03AG873748 | C13: =VLOOKUP(A13,temp!$A$2:$U$4706,18,FALSE) -> 8075 | D13: =VLOOKUP(A13,temp!$A$2:$U$4706,16,FALSE) -> LOPEZ TERRON, (000196) ROBERTO PORFIRIO (SEITON
A14: 03AG873888 | B14: 03AG873888 | C14: =VLOOKUP(A14,temp!$A$2:$U$4706,18,FALSE) -> 8075 | D14: =VLOOKUP(A14,temp!$A$2:$U$4706,16,FALSE) -> MARTINEZ MORALES, (500036) TOMAS
... A1178: 0Y4X846822 | B1178: 0Y4X846822 | C1178: =VLOOKUP(A1178,temp!$A$2:$U$4706,18,FALSE) -> 8055 | D1178: =VLOOKUP(A1178,temp!$A$2:$U$4706,16,FALSE) -> MONTOYA PORTILLO, (500155) CARLOS ALBERTO (SEI
A1179: 0Y4X846836 | B1179: 0Y4X846836 | C1179: 8055 | D1179: =VLOOKUP(A1179,temp!$A$2:$U$4706,16,FALSE) -> MAR MARQUEZ, (500157) CESAR (SEITON)
A1180: 0Y4X847279 | B1180: 0Y4X847279 | C1180: =VLOOKUP(A1180,temp!$A$2:$U$4706,18,FALSE) -> 8045 | D1180: =VLOOKUP(A1180,temp!$A$2:$U$4706,16,FALSE) -> GUTIERREZ MUNOZ, (800196) CARLOS
A1181: 0Y4X848684 | B1181: 0Y4X848684 | C1181: =VLOOKUP(A1181,temp!$A$2:$U$4706,18,FALSE) -> 8045 | D1181: =VLOOKUP(A1181,temp!$A$2:$U$4706,16,FALSE) -> CHAVEZ PEDRAZA, (000195) SAMUEL (SEITON)
A1182: 0Y4X848752 | B1182: 0Y4X848752 | C1182: =VLOOKUP(A1182,temp!$A$2:$U$4706,18,FALSE) -> 8045 | D1182: =VLOOKUP(A1182,temp!$A$2:$U$4706,16,FALSE) -> GUTIERREZ MUNOZ, (800196) CARLOS
A1183: 0Y4X848801 | B1183: 0Y4X848801 | C1183: =VLOOKUP(A1183,temp!$A$2:$U$4706,18,FALSE) -> 8045 | D1183: =VLOOKUP(A1183,temp!$A$2:$U$4706,16,FALSE) -> GUTIERREZ MUNOZ, (800196) CARLOS
A1184: 0Y4X848978 | B1184: 0Y4X848978 | C1184: =VLOOKUP(A1184,temp!$A$2:$U$4706,18,FALSE) -> 8045 | D1184: =VLOOKUP(A1184,temp!$A$2:$U$4706,16,FALSE) -> GUTIERREZ MUNOZ, (800196) CARLOS
A1185: 0Y4X849031 | B1185: 0Y4X849031 | C1185: =VLOOKUP(A1185,temp!$A$2:$U$4706,18,FALSE) -> 8045 | D1185: =VLOOKUP(A1185,temp!$A$2:$U$4706,16,FALSE) -> ARROYO RAMIREZ, (800072) HECTOR HUGO
A1186: 0YRB116522 | B1186: 0YRB116522 | C1186: =VLOOKUP(A1186,temp!$A$2:$U$4706,18,FALSE) -> 6505 | D1186: =VLOOKUP(A1186,temp!$A$2:$U$4706,16,FALSE) -> TORRES RICARDEZ, (500158) ALFREDO (SEITON)
A1187: 0YTB116653 | B1187: 0YTB116653 | C1187: =VLOOKUP(A1187,temp!$A$2:$U$4706,18,FALSE) -> 6506 | D1187: =VLOOKUP(A1187,temp!$A$2:$U$4706,16,FALSE) -> MOLINA RAMIREZ, (500089) GERARDO DANIEL
A1188: 0YTB116654 | B1188: 0YTB116654 | C1188: =VLOOKUP(A1188,temp!$A$2:$U$4706,18,FALSE) -> 6506 | D1188: =VLOOKUP(A1188,temp!$A$2:$U$4706,16,FALSE) -> TORRES RICARDEZ, (500158) ALFREDO (SEITON)
A1189: 0YTB116722 | B1189: 0YTB116722 | C1189: =VLOOKUP(A1189,temp!$A$2:$U$4706,18,FALSE) -> 6506 | D1189: =VLOOKUP(A1189,temp!$A$2:$U$4706,16,FALSE) -> PEREZ BALBOA, (500028) CESAR
A1190: 0YTB126164 | B1190: 0YTB126164 | C1190: =VLOOKUP(A1190,temp!$A$2:$U$4706,18,FALSE) -> 6506 | D1190: =VLOOKUP(A1190,temp!$A$2:$U$4706,16,FALSE) -> MOLINA RAMIREZ, (500089) GERARDO DANIEL
A1191: 0YTB130367 | B1191: 0YTB130367 | C1191: =VLOOKUP(A1191,temp!$A$2:$U$4706,18,FALSE) -> 6506 | D1191: =VLOOKUP(A1191,temp!$A$2:$U$4706,16,FALSE) -> MARTINEZ ZAMORA, (500019) GERARDO MARIO (SEITON
... A1236: Y4X838933 | B1236: Y4X838933 | C1236: =VLOOKUP(A1236,temp!$A$2:$U$4706,18,FALSE) -> 8045 | D1236: =VLOOKUP(A1236,temp!$A$2:$U$4706,16,FALSE) -> MARTINEZ MORALES, (800192) MARTIN (PITSS)

Sheet objetivos
B1: objetivo | C1: extra | D1: total
A2: febrero | B2: 33.43 | C2: 6.92 | D2: =+B2+C2 -> 40.35
A3: enero | B3: 33.12 | C3: 4.46 | D3: =+B3+C3 -> 37.58
A4: diciembre | B4: 33.12 | C4: 5.89 | D4: =+B4+C4 -> 39.01
A5: noviembre | B5: 36.8 | C5: 0.78 | D5: =+B5+C5 -> 37.58
A6: octubre | B6: 42.32 | C6: 6.1 | D6: =+B6+C6 -> 48.42
A7: septiembre | B7: 42.32 | C7: -9.03 | D7: =+B7+C7 -> 33.29

Sheet pendiente
A1: 23-JAN-2019 | B1: 124.33369 | C1: 207.22282 | D1: 18-JAN-2019 | E1: 1981557 | F1: 3532041 | G1: 0E1B971869 | H1: 480 | I1: 23 | J1: 800071 | K1: 604K77533-N | L1: 1 | M1: 207.22282 | N1: IBARRA RAMOS, (800071) RAMIRO | O1: INSTITUTO TECNOLOGICO Y DE ESTUDIOS SUPE | P1: 6656 | Q1: XGS RENTAL | R1: PITSS JALISCO | S1: 43488 | T1: PITSS JALISCO43488 | U1: 18-JAN-2019 | V1: 1981557 | W1: 3532041 | X1: 0E1B971869 | Y1: 480 | Z1: 23 | AA1: 800071 | AB1: 604K77533-N | AC1: 1 | AD1: IBARRA RAMOS, (800071) RAMIRO | AE1: INSTITUTO TECNOLOGICO Y DE ESTUDIOS SUPE | AF1: 6656 | AG1: XGS RENTAL | AH1: PITSS JALISCO
A2: 23-JAN-2019 | B2: 20.186236 | C2: 33.643726 | D2: 18-JAN-2019 | E2: 1981557 | F2: 3532041 | G2: 0E1B971869 | H2: 480 | I2: 23 | J2: 800071 | K2: 604K85850-N | L2: 1 | M2: 33.643726 | N2: IBARRA RAMOS, (800071) RAMIRO | O2: INSTITUTO TECNOLOGICO Y DE ESTUDIOS SUPE | P2: 6656 | Q2: XGS RENTAL | R2: PITSS JALISCO | S2: 43488 | T2: PITSS JALISCO43488 | U2: 18-JAN-2019 | V2: 1981557 | W2: 3532041 | X2: 0E1B971869 | Y2: 480 | Z2: 23 | AA2: 800071 | AB2: 604K85850-N | AC2: 1 | AD2: IBARRA RAMOS, (800071) RAMIRO | AE2: INSTITUTO TECNOLOGICO Y DE ESTUDIOS SUPE | AF2: 6656 | AG2: XGS RENTAL | AH2: PITSS JALISCO
A3: 23-JAN-2019 | B3: 4.4723933 | C3: 7.4539888 | D3: 18-JAN-2019 | E3: 1981557 | F3: 3532041 | G3: 0E1B971869 | H3: 480 | I3: 23 | J3: 800071 | K3: 604K11192-N | L3: 2 | M3: 7.4539888 | N3: IBARRA RAMOS, (800071) RAMIRO | O3: INSTITUTO TECNOLOGICO Y DE ESTUDIOS SUPE | P3: 6656 | Q3: XGS RENTAL | R3: PITSS JALISCO | S3: 43488 | T3: PITSS JALISCO43488 | U3: 18-JAN-2019 | V3: 1981557 | W3: 3532041 | X3: 0E1B971869 | Y3: 480 | Z3: 23 | AA3: 800071 | AB3: 604K11192-N | AC3: 2 | AD3: IBARRA RAMOS, (800071) RAMIRO | AE3: INSTITUTO TECNOLOGICO Y DE ESTUDIOS SUPE | AF3: 6656 | AG3: XGS RENTAL | AH3: PITSS JALISCO
A4: 23-JAN-2019 | B4: 57.472304 | C4: 95.787173 | D4: 17-JAN-2019 | E4: 1980959 | F4: 3527809 | G4: 0X76703275 | H4: 480 | I4: 23 | J4: 800183 | K4: 050K77271-N | L4: 1 | M4: 95.787173 | N4: CASTILLO RAMIREZ, (800183) HECTOR IVAN (SEITON | O4: BBVA BANCOMER SA | P4: 5955 | Q4: XGS RENTAL | R4: PITSS JALISCO | S4: 43488 | T4: PITSS JALISCO43488 | U4: 17-JAN-2019 | V4: 1980959 | W4: 3527809 | X4: 0X76703275 | Y4: 480 | Z4: 23 | AA4: 800183 | AB4: 050K77271-N | AC4: 1 | AD4: CASTILLO RAMIREZ, (800183) HECTOR IVAN (SEITON | AE4: BBVA BANCOMER SA | AF4: 5955 | AG4: XGS RENTAL | AH4: PITSS JALISCO
A5: 23-JAN-2019 | B5: 2.9665228 | C5: 4.9442046 | D5: 21-JAN-2019 | E5: 1982243 | F5: 3532021 | G5: 0BA9588072 | H5: 450 | I5: 18 | J5: 500066 | K5: 019N00947-N | L5: 2 | M5: 4.9442046 | N5: TREVIÐO ALVAREZ, (500066) JORGE ALBERTO | O5: INGERSOLL-RAND MANUFACTURA S DE RL DE CV | P5: 3637 | Q5: XGS FSMA | R5: PITSS NUEVO LEON | S5: 43488 | T5: PITSS NUEVO LEON43488 | U5: 21-JAN-2019 | V5: 1982243 | W5: 3532021 | X5: 0BA9588072 | Y5: 450 | Z5: 18 | AA5: 500066 | AB5: 019N00947-N | AC5: 2 | AD5: TREVIÐO ALVAREZ, (500066) JORGE ALBERTO | AE5: INGERSOLL-RAND MANUFACTURA S DE RL DE CV | AF5: 3637 | AG5: XGS FSMA | AH5: PITSS NUEVO LEON
A6: 23-JAN-2019 | B6: 4.1169573 | C6: 6.8615956 | D6: 21-JAN-2019 | E6: 1982243 | F6: 3532021 | G6: 0BA9588072 | H6: 450 | I6: 18 | J6: 500066 | K6: 022N02413-N | L6: 2 | M6: 6.8615956 | N6: TREVIÐO ALVAREZ, (500066) JORGE ALBERTO | O6: INGERSOLL-RAND MANUFACTURA S DE RL DE CV | P6: 3637 | Q6: XGS FSMA | R6: PITSS NUEVO LEON | S6: 43488 | T6: PITSS NUEVO LEON43488 | U6: 21-JAN-2019 | V6: 1982243 | W6: 3532021 | X6: 0BA9588072 | Y6: 450 | Z6: 18 | AA6: 500066 | AB6: 022N02413-N | AC6: 2 | AD6: TREVIÐO ALVAREZ, (500066) JORGE ALBERTO | AE6: INGERSOLL-RAND MANUFACTURA S DE RL DE CV | AF6: 3637 | AG6: XGS FSMA | AH6: PITSS NUEVO LEON
A7: 23-JAN-2019 | B7: 3.1279412 | C7: 5.2132353 | D7: 21-JAN-2019 | E7: 1982243 | F7: 3532021 | G7: 0BA9588072 | H7: 450 | I7: 18 | J7: 500066 | K7: 121N01162-N | L7: 2 | M7: 5.2132353 | N7: TREVIÐO ALVAREZ, (500066) JORGE ALBERTO | O7: INGERSOLL-RAND MANUFACTURA S DE RL DE CV | P7: 3637 | Q7: XGS FSMA | R7: PITSS NUEVO LEON | S7: 43488 | T7: PITSS NUEVO LEON43488 | U7: 21-JAN-2019 | V7: 1982243 | W7: 3532021 | X7: 0BA9588072 | Y7: 450 | Z7: 18 | AA7: 500066 | AB7: 121N01162-N | AC7: 2 | AD7: TREVIÐO ALVAREZ, (500066) JORGE ALBERTO | AE7: INGERSOLL-RAND MANUFACTURA S DE RL DE CV | AF7: 3637 | AG7: XGS FSMA | AH7: PITSS NUEVO LEON
A8: 23-JAN-2019 | B8: 0.99900625 | C8: 1.6650104 | D8: 21-JAN-2019 | E8: 1982595 | F8: 3532132 | G8: 0A4T557718 | H8: 480 | I8: 23 | J8: 800071 | K8: 604K77520-N | L8: 1 | M8: 1.6650104 | N8: IBARRA RAMOS, (800071) RAMIRO | O8: FLEXTRONICS MANUFACTURING MEX SA DE CV | P8: 3611 | Q8: XGS RENTAL | R8: PITSS JALISCO | S8: 43488 | T8: PITSS JALISCO43488 | U8: 21-JAN-2019 | V8: 1982595 | W8: 3532132 | X8: 0A4T557718 | Y8: 480 | Z8: 23 | AA8: 800071 | AB8: 604K77520-N | AC8: 1 | AD8: IBARRA RAMOS, (800071) RAMIRO | AE8: FLEXTRONICS MANUFACTURING MEX SA DE CV | AF8: 3611 | AG8: XGS RENTAL | AH8: PITSS JALISCO
A9: 23-JAN-2019 | B9: 18.122499 | C9: 30.204165 | D9: 21-JAN-2019 | E9: 1982595 | F9: 3532132 | G9: 0A4T557718 | H9: 480 | I9: 23 | J9: 800071 | K9: 059K79334-N | L9: 1 | M9: 30.204165 | N9: IBARRA RAMOS, (800071) RAMIRO | O9: FLEXTRONICS MANUFACTURING MEX SA DE CV | P9: 3611 | Q9: XGS RENTAL | R9: PITSS JALISCO | S9: 43488 | T9: PITSS JALISCO43488 | U9: 21-JAN-2019 | V9: 1982595 | W9: 3532132 | X9: 0A4T557718 | Y9: 480 | Z9: 23 | AA9: 800071 | AB9: 059K79334-N | AC9: 1 | AD9: IBARRA RAMOS, (800071) RAMIRO | AE9: FLEXTRONICS MANUFACTURING MEX SA DE CV | AF9: 3611 | AG9: XGS RENTAL | AH9: PITSS JALISCO
A10: 23-JAN-2019 | B10: 3.4744386 | C10: 5.790731 | D10: 21-JAN-2019 | E10: 1982595 | F10: 3532132 | G10: 0A4T557718 | H10: 480 | I10: 23 | J10: 800071 | K10: 604K77290-N | L10: 1 | M10: 5.790731 | N10: IBARRA RAMOS, (800071) RAMIRO | O10: FLEXTRONICS MANUFACTURING MEX SA DE CV | P10: 3611 | Q10: XGS RENTAL | R10: PITSS JALISCO | S10: 43488 | T10: PITSS JALISCO43488 | U10: 21-JAN-2019 | V10: 1982595 | W10: 3532132 | X10: 0A4T557718 | Y10: 480 | Z10: 23 | AA10: 800071 | AB10: 604K77290-N | AC10: 1 | AD10: IBARRA RAMOS, (800071) RAMIRO | AE10: FLEXTRONICS MANUFACTURING MEX SA DE CV | AF10: 3611 | AG10: XGS RENTAL | AH10: PITSS JALISCO
A11: 23-JAN-2019 | B11: 148.74625 | C11: 247.91041 | D11: 21-JAN-2019 | E11: 1982359 | F11: 3532126 | G11: 0A1H021115 | H11: 450 | I11: 07 | J11: 800084 | K11: 121K52558-N | L11: 1 | M11: 247.91041 | N11: DOMINGUEZ ESCAMILLA, (800084) VICTOR HUGO | O11: OFFICE DEPOT DE MEXICO SA DE CV | P11: 6705 | Q11: XGS FSMA | R11: PITSS COAHUILA | S11: 43488 | T11: PITSS COAHUILA43488 | U11: 21-JAN-2019 | V11: 1982359 | W11: 3532126 | X11: 0A1H021115 | Y11: 450 | Z11: 07 | AA11: 800084 | AB11: 121K52558-N | AC11: 1 | AD11: DOMINGUEZ ESCAMILLA, (800084) VICTOR HUGO | AE11: OFFICE DEPOT DE MEXICO SA DE CV | AF11: 6705 | AG11: XGS FSMA | AH11: PITSS COAHUILA
A12: 23-JAN-2019 | B12: 53.632965 | C12: 89.388275 | D12: 21-JAN-2019 | E12: 1982359 | F12: 3532126 | G12: 0A1H021115 | H12: 450 | I12: 07 | J12: 800084 | K12: 133K25932-N | L12: 1 | M12: 89.388275 | N12: DOMINGUEZ ESCAMILLA, (800084) VICTOR HUGO | O12: OFFICE DEPOT DE MEXICO SA DE CV | P12: 6705 | Q12: XGS FSMA | R12: PITSS COAHUILA | S12: 43488 | T12: PITSS COAHUILA43488 | U12: 21-JAN-2019 | V12: 1982359 | W12: 3532126 | X12: 0A1H021115 | Y12: 450 | Z12: 07 | AA12: 800084 | AB12: 133K25932-N | AC12: 1 | AD12: DOMINGUEZ ESCAMILLA, (800084) VICTOR HUGO | AE12: OFFICE DEPOT DE MEXICO SA DE CV | AF12: 6705 | AG12: XGS FSMA | AH12: PITSS COAHUILA
... A114: 29-JAN-2019 | B114: 10.436986 | C114: 17.394977 | D114: 18-JAN-2019 | E114: 1981571 | F114: 3531829 | G114: 0X76373083 | H114: 450 | I114: 18 | J114: 500035 | K114: 237E27478-N | L114: 1 | M114: 17.394977 | N114: MEDELLIN COLUNGA, (500035) RUBEN DARIO | O114: APTIV CONTRACT SERVICES NUEVO LAREDO S D | P114: 5945 | Q114: XGS RENTAL | R114: PITSS NUEVO LEON | S114: 43494 | T114: PITSS NUEVO LEON43494 | U114: 18-JAN-2019 | V114: 1981571 | W114: 3531829 | X114: 0X76373083 | Y114: 450 | Z114: 18 | AA114: 500035 | AB114: 237E27478-N | AC114: 1 | AD114: MEDELLIN COLUNGA, (500035) RUBEN DARIO | AE114: APTIV CONTRACT SERVICES NUEVO LAREDO S D | AF114: 5945 | AG114: XGS RENTAL | AH114: PITSS NUEVO LEON
