Workbook

Sheet CPD PITSS
B2: CONSULTORIA EN PROYECTOS DINAMICOS S DE RL DE CV
B3: Lista de Raya (forma tabular)
B4: Reg Pat IMSS: Z2940859106
B5: RFC: CPD -150911-FA3
B7: 1 | C7: =+B7+1 -> 2 | D7: =+C7+1 -> 3 | E7: =+D7+1 -> 4 | F7: =+E7+1 -> 5 | G7: =+F7+1 -> 6 | H7: =+G7+1 -> 7 | I7: =+H7+1 -> 8 | J7: =+I7+1 -> 9 | ... V7: =+U7+1 -> 21
A8: Código | B8: Empleado | C8: Dias Laborados | D8: Dias Vacaciones | E8: Salario Diario | F8: Salario Diario Integrado | G8: Sueldo | H8: Vacaciones a tiempo | I8: Prima de vacaciones a tiempo | J8: Ayuda de Transporte | K8: Ayuda Alimentaria | L8: Ayuda de Renta | M8: *TOTAL* *PERCEPCIONES* | N8: Seguro de vivienda Infonavit | O8: Préstamo Infonavit (vsm) | P8: Subsidio al Empleo (sp) | Q8: I.S.R. (sp) | R8: I.M.S.S. | S8: Deduccion General | T8: Ajuste al neto | U8: *TOTAL* *DEDUCCIONES* | V8: *NETO* | W8: Invalidez y Vida | X8: Cesantia y Vejez | Y8: Enf. y Mat. Patron | Z8: 2% Fondo retiro SAR (8) | AA8: 2% Impuesto estatal | AB8: Riesgo de trabajo (9) | AC8: I.M.S.S. empresa | AD8: Infonavit empresa | AE8: Guarderia I.M.S.S. (7) | AF8: Banco | AG8: Aguinaldo
A9: SEI0009 | B9: Gutierrez Gutierrez Luis Arturo | C9: 15 | D9: 0 | E9: 141.67 | F9: 150.25 | G9: 2125.05 | H9: 0 | I9: 0 | J9: 212.51 | K9: 212.51 | L9: 212.51 | M9: 2762.58 | N9: 0 | O9: 0 | P9: -65.5 | Q9: 0 | R9: 53.52 | S9: 0 | T9: -0.04 | U9: -12.02 | V9: 2774.6 | W9: 39.44 | X9: 70.99 | Y9: 297.98 | Z9: 183.93 | AA9: 55.25 | AB9: 11.27 | AC9: 408.41 | AD9: 112.69 | AE9: 161.39 | AF9: 110 | AG9: =((20/365.24)*15)*($E9*1.3) -> 151.27396
A10: SEI0026 | B10: Patricio Aguilar Jhonattan Cristian | C10: 15 | D10: 0 | E10: 150 | F10: 159.07 | G10: 2250 | H10: 0 | I10: 0 | J10: 225 | K10: 225 | L10: 225 | M10: 2925 | N10: 0 | O10: 0 | P10: -43.57 | Q10: 0 | R10: 56.67 | S10: 0 | T10: -0.1 | U10: 13 | V10: 2912 | W10: 41.76 | X10: 75.16 | Y10: 300.29 | Z10: 186.57 | AA10: 58.5 | AB10: 11.93 | AC10: 417.21 | AD10: 119.31 | AE10: 162.71 | AF10: 110 | AG10: =((20/365.24)*15)*($E10*1.3) -> 160.16866
A11: SEI0040 | B11: Mora Ramirez Acal Aldo Isidro | C11: 15 | D11: 0 | E11: 216.67 | F11: 229.79 | G11: 3250.05 | H11: 0 | I11: 0 | J11: 325.01 | K11: 325.01 | L11: 325.01 | M11: 4225.08 | N11: 0 | O11: 0 | P11: 0 | Q11: 107.17 | R11: 81.87 | S11: 0 | T11: 0.04 | U11: 189.08 | V11: 4036 | W11: 60.32 | X11: 108.58 | Y11: 318.86 | Z11: 207.79 | AA11: 84.5 | AB11: 17.23 | AC11: 487.76 | AD11: 172.34 | AE11: 173.32 | AF11: 110 | AG11: =((20/365.24)*15)*($E11*1.3) -> 231.35828
A12: SEI0041 | B12: Vazquez Perez Miguel Angel | C12: 15 | D12: 0 | E12: 283.33 | F12: 300.49 | G12: 4249.95 | H12: 0 | I12: 0 | J12: 425 | K12: 425 | L12: 425 | M12: 5524.95 | N12: 0 | O12: 0 | P12: 0 | Q12: 341.06 | R12: 109.87 | S12: 0 | T12: 0.02 | U12: 450.95 | V12: 5074 | W12: 78.88 | X12: 141.98 | Y12: 345.18 | Z12: 229 | AA12: 110.5 | AB12: 22.54 | AC12: 566.04 | AD12: 225.37 | AE12: 183.92 | AF12: 110 | AG12: =((20/365.24)*15)*($E12*1.3) -> 302.53724
A13: SEI0088 | B13: Morgado Fernandez Martin | C13: 15 | D13: 0 | E13: 273.33 | F13: 289.87 | G13: 4099.95 | H13: 0 | I13: 0 | J13: 410 | K13: 410 | L13: 410 | M13: 5329.95 | N13: 0 | O13: 0 | P13: 0 | Q13: 324.74 | R13: 105.46 | S13: 275.95 | T13: 0 | U13: 706.15 | V13: 4623.8 | W13: 76.09 | X13: 136.96 | Y13: 340.64 | Z13: 225.81 | AA13: 106.6 | AB13: 21.74 | AC13: 553.69 | AD13: 217.4 | AE13: 182.33 | AF13: 110 | AG13: =((20/365.24)*15)*($E13*1.3) -> 291.85933
A14: SEI0097 | B14: Arreola Jimenez Jose Nieves | C14: 15 | D14: 0 | E14: 185.83 | F14: 197.07 | G14: 2787.45 | H14: 0 | I14: 0 | J14: 278.75 | K14: 278.75 | L14: 278.75 | M14: 3623.7 | N14: 0 | O14: 1541.78 | P14: 0 | Q14: 36.57 | R14: 70.22 | S14: 308.55 | T14: -0.02 | U14: 1957.1 | V14: 1666.6 | W14: 51.73 | X14: 93.12 | Y14: 310.27 | Z14: 197.97 | AA14: 72.47 | AB14: 14.78 | AC14: 455.12 | AD14: 147.8 | AE14: 168.41 | AF14: 110 | AG14: =((20/365.24)*15)*($E14*1.3) -> 198.42761
A15: SEI0099 | B15: Garcia Villicaña Ricardo Pascual | C15: 15 | D15: 0 | E15: 273.33 | F15: 289.87 | G15: 4099.95 | H15: 0 | I15: 0 | J15: 410 | K15: 410 | L15: 410 | M15: 5329.95 | N15: 0 | O15: 0 | P15: 0 | Q15: 324.74 | R15: 105.46 | S15: 213.55 | T15: 0 | U15: 643.75 | V15: 4686.2 | W15: 76.09 | X15: 136.96 | Y15: 340.64 | Z15: 225.81 | AA15: 106.6 | AB15: 21.74 | AC15: 553.69 | AD15: 217.4 | AE15: 182.33 | AF15: 110 | AG15: =((20/365.24)*15)*($E15*1.3) -> 291.85933
A16: SEI0108 | B16: Caballero Diaz Francisco Javier | C16: 15 | D16: 0 | E16: 185.83 | F16: 197.07 | G16: 2787.45 | H16: 0 | I16: 0 | J16: 278.75 | K16: 278.75 | L16: 278.75 | M16: 3623.7 | N16: 0 | O16: 1789.38 | P16: 0 | Q16: 36.57 | R16: 70.22 | S16: 238.8 | T16: -0.07 | U16: 2134.9 | V16: 1488.8 | W16: 51.73 | X16: 93.12 | Y16: 310.27 | Z16: 197.97 | AA16: 72.47 | AB16: 14.78 | AC16: 455.12 | AD16: 147.8 | AE16: 168.41 | AF16: 110 | AG16: =((20/365.24)*15)*($E16*1.3) -> 198.42761
A17: SEI0116 | B17: Casillas Cardona Cesar Alejandro | C17: 10 | D17: 5 | E17: 220.83 | F17: 234.19 | G17: 2208.3 | H17: 1104.15 | I17: 331.25 | J17: 331.25 | K17: 331.25 | L17: 331.25 | M17: 4637.45 | N17: 0 | O17: 894.93 | P17: 0 | Q17: 113.96 | R17: 83.43 | S17: 0 | T17: -0.07 | U17: 1092.25 | V17: 3545.2 | W17: 61.47 | X17: 110.65 | Y17: 320.01 | Z17: 209.11 | AA17: 92.75 | AB17: 17.56 | AC17: 492.13 | AD17: 175.64 | AE17: 173.98 | AF17: 110 | AG17: =((20/365.24)*15)*($E17*1.3) -> 235.8003
A18: SEI0117 | B18: Mariscal Romero Luis Adrian | C18: 12 | D18: 3 | E18: 264.58 | F18: 276.54 | G18: 3174.96 | H18: 793.74 | I18: 238.12 | J18: 396.87 | K18: 396.87 | L18: 396.87 | M18: 5397.43 | N18: 0 | O18: 0 | P18: 0 | Q18: 310.46 | R18: 99.91 | S18: 0 | T18: -0.14 | U18: 410.23 | V18: 4987.2 | W18: 72.59 | X18: 130.66 | Y18: 334.94 | Z18: 221.81 | AA18: 107.95 | AB18: 20.74 | AC18: 538.19 | AD18: 207.4 | AE18: 180.33 | AF18: 110 | AG18: =((20/365.24)*15)*($E18*1.3) -> 282.51615
A19: SEI0118 | B19: Arroyo Ramirez Hector Hugo | C19: 14 | D19: 1 | E19: 238.33 | F19: 252.75 | G19: 3336.62 | H19: 238.33 | I19: 71.5 | J19: 357.5 | K19: 357.5 | L19: 357.5 | M19: 4718.95 | N19: 0 | O19: 1402.48 | P19: 0 | Q19: 160.25 | R19: 90.05 | S19: 0 | T19: -0.01 | U19: 1660.55 | V19: 3058.4 | W19: 66.35 | X19: 119.42 | Y19: 324.89 | Z19: 214.67 | AA19: 94.38 | AB19: 18.96 | AC19: 510.66 | AD19: 189.56 | AE19: 176.76 | AF19: 110 | AG19: =((20/365.24)*15)*($E19*1.3) -> 254.48664
A20: SEI0127 | B20: Hernandez Ochoa Eduardo | C20: 15 | D20: 0 | E20: 273.33 | F20: 289.87 | G20: 4099.95 | H20: 0 | I20: 0 | J20: 410 | K20: 410 | L20: 410 | M20: 5329.95 | N20: 0 | O20: 0 | P20: 0 | Q20: 324.74 | R20: 105.46 | S20: 0 | T20: -0.05 | U20: 430.15 | V20: 4899.8 | W20: 76.09 | X20: 136.96 | Y20: 340.64 | Z20: 225.81 | AA20: 106.6 | AB20: 21.74 | AC20: 553.69 | AD20: 217.4 | AE20: 182.33 | AF20: 110 | AG20: =((20/365.24)*15)*($E20*1.3) -> 291.85933
... A26: SEI0442 | B26: Sierra Escamilla Daniela | C26: 15 | D26: 0 | E26: 216.67 | F26: 229.79 | G26: 3250.05 | H26: 0 | I26: 0 | J26: 325.01 | K26: 325.01 | L26: 325.01 | M26: 4225.08 | N26: 0 | O26: 0 | P26: 0 | Q26: 107.17 | R26: 81.87 | S26: 0 | T26: 0.04 | U26: 189.08 | V26: 4036 | W26: 60.32 | X26: 108.58 | Y26: 318.86 | Z26: 207.79 | AA26: 84.5 | AB26: 17.23 | AC26: 487.76 | AD26: 172.34 | AE26: 173.32 | AF26: 110 | AG26: =((20/365.24)*15)*($E26*1.3) -> 231.35828
C27: ============= | D27: ============= | E27: ============= | F27: ============= | G27: ============= | H27: ============= | I27: ============= | J27: ============= | K27: ============= | L27: ============= | M27: ============= | N27: ============= | O27: ============= | P27: ============= | Q27: ============= | R27: ============= | S27: ============= | T27: ============= | U27: ============= | V27: ============= | W27: ============= | X27: ============= | Y27: ============= | Z27: ============= | AA27: ============= | AB27: ============= | AC27: ============= | AD27: ============= | AE27: ============= | AF27: ============= | AG27: =============
A28: Total Gral. | C28: =SUM(C9:C26) -> 252 | D28: =SUM(D9:D26) -> 18 | E28: =SUM(E9:E26) -> 4708.72 | F28: =SUM(F9:F26) -> 4989.65 | G28: =SUM(G9:G26) -> 66822.11 | H28: =SUM(H9:H26) -> 3808.69 | I28: =SUM(I9:I26) -> 1142.61 | J28: =SUM(J9:J26) -> 7063.16 | ... AG28: =SUM(AG9:AG26) -> 5027.929
A30: 18 | B30: Nomina
B31: Altas | L31: FACTURACION PITS | N31: VENTAS | O31: ADMON | P31: SERVICIO
B32: Bajas | L32: Devengado Salario | M32: =+V28 -> 75245.8 | O32: 28375.2 | P32: =M32-O32 -> 46870.6
A33: =+A30+A31-A32 -> 18 | B33: Total Nomina | L33: RETORNOS | M33: =+S28 -> 1614.38 | O33: =S22 -> 280.53 | P33: =M33-O33 -> 1333.85
L34: Infonavit | M34: =+N28+O28 -> 9230.05 | P34: =M34 -> 9230.05
L35: Prestamo Prospera | M35: 0
L36: Subtotal 1 | M36: =SUM(M32:M35) -> 86090.23 | N36: =SUM(N32:N35) -> 0 | O36: =SUM(O32:O35) -> 28655.73 | P36: =SUM(P32:P35) -> 57434.5
L37: Comision | M37: =+M36*2% -> 1721.8046 | O37: =O36*2% -> 573.1146 | P37: =P36*2% -> 1148.69
L38: Subtotal 2 | M38: =+M36+M37 -> 87812.035 | O38: =SUM(O36:O37) -> 29228.845 | P38: =SUM(P36:P37) -> 58583.19
L39: Costo Patronal Imss | M39: =+R28+W28+X28+Y28+AB28+Z28+AD28+AE28 -> 23005.39 | O39: 6971.36 | P39: =M39-O39 -> 16034.03
L40: 2% Sobre Nomina | M40: =+M28*2% -> 1859.2578 | O40: =32386.44*2% -> 647.7288 | P40: =M40-O40 -> 1211.529
L41: Importe de Factura | M41: =+M38+M39+M40 -> 112676.68 | O41: =SUM(O38:O40) -> 36847.933 | P41: =SUM(P38:P40) -> 75828.749
L42: IVA | M42: =+M41*16% -> 18028.269 | O42: =O41*16% -> 5895.6693 | P42: =P41*16% -> 12132.6
L43: TOTAL | M43: =+M41+M42 -> 130704.95 | O43: =O42+O41 -> 42743.603 | P43: =P42+P41 -> 87961.349
O44: =O41-O37 -> 36274.819 | P44: =P41-P37 -> 74680.059
L45: PROVISION AGUINALDO | O45: 0.73 | P45: 0.11 | Q45: 0.12 | R45: 0.04
L46: FACTURACION PITS | O46: ITA | P46: IP | Q46: CPD | R46: EM
L47: Subtotal 1 | M47: =+AG28 -> 5027.929 | N47: ADMON | O47: =O44*$O$45 -> 26480.618 | P47: =O44*$P$45 -> 3990.2301 | Q47: =O44*$Q$45 -> 4352.9783 | R47: =O44*$R$45 -> 1450.9928
L48: Comision | M48: =+M47*2% -> 100.55858 | N48: SERVICIO | O48: =P44*$O$45 -> 54516.443 | P48: =P44*$P$45 -> 8214.8065 | Q48: =P44*Q45 -> 8961.6071 | R48: =P44*$R$45 -> 2987.2024
...

Sheet IP PITSS
B2: IP INNOVACION EN PROYECTOS S DE RL DE CV
B3: Lista de Raya (forma tabular)
B4: Reg Pat IMSS: R1363592103
B5: RFC: IIP -150923-DT7
A8: Código | B8: Empleado | C8: Dias Laborados | D8: Dias Vacaciones | E8: Salario Diario | F8: Salario Diario Integrado | G8: Sueldo | H8: Vacaciones a tiempo | I8: Prima de vacaciones a tiempo | J8: *TOTAL* *PERCEPCIONES* | K8: Seguro de vivienda Infonavit | L8: Préstamo Infonavit (vsm) | M8: Préstamo Infonavit (cf) | N8: Subsidio al Empleo (sp) | O8: I.S.R. (sp) | P8: I.M.S.S. | Q8: Préstamo FONACOT | R8: Deduccion general | S8: Ajuste al neto | T8: *TOTAL* *DEDUCCIONES* | U8: *NETO* | V8: Invalidez y Vida | W8: Cesantia y Vejez | X8: Enf. y Mat. Patron | Y8: 2% Fondo retiro SAR (8) | Z8: 2% Impuesto estatal | AA8: Riesgo de trabajo (9) | AB8: I.M.S.S. empresa | AC8: Infonavit empresa | AD8: Guarderia I.M.S.S. (7) | AE8: Banco | AF8: Aguinaldo
A9: SEI0010 | B9: Torres Ricardez Alfredo | C9: 15 | D9: 0 | E9: 266.67 | F9: 278.72 | G9: 4000.05 | H9: 0 | I9: 0 | J9: 4000.05 | K9: 0 | L9: 0 | M9: 0 | N9: 0 | O9: 313.87 | P9: 100.81 | Q9: 0 | R9: 250 | S9: -0.03 | T9: 664.65 | U9: 3335.4 | V9: 73.16 | W9: 131.7 | X9: 335.88 | Y9: 273.62 | Z9: 80 | AA9: 33.3 | AB9: 540.74 | AC9: 209.04 | AD9: 231.81 | AE9: 110 | AF9: =((20/365.24)*15)*E9 -> 219.0368
A10: SEI0014 | B10: Montoya Portillo Carlos Alberto | C10: 15 | D10: 0 | E10: 266.67 | F10: 278.72 | G10: 4000.05 | H10: 0 | I10: 0 | J10: 4000.05 | K10: 0 | L10: 0 | M10: 0 | N10: 0 | O10: 313.87 | P10: 100.81 | Q10: 0 | R10: 0 | S10: -0.03 | T10: 414.65 | U10: 3585.4 | V10: 73.16 | W10: 131.7 | X10: 335.88 | Y10: 273.62 | Z10: 80 | AA10: 33.3 | AB10: 540.74 | AC10: 209.04 | AD10: 231.81 | AE10: 110 | AF10: =((20/365.24)*15)*E10 -> 219.0368
A11: SEI0015 | B11: Cota Jaramillo Miguel Angel | C11: 15 | D11: 0 | E11: 200 | F11: 209.04 | G11: 3000 | H11: 0 | I11: 0 | J11: 3000 | K11: 0 | L11: 0 | M11: 0 | N11: 0 | O11: 59.69 | P11: 74.48 | Q11: 0 | R11: 1125 | S11: 0.03 | T11: 1259.2 | U11: 1740.8 | V11: 54.87 | W11: 98.77 | X11: 313.41 | Y11: 252.71 | Z11: 60 | AA11: 24.98 | AB11: 467.05 | AC11: 156.78 | AD11: 221.36 | AE11: 110 | AF11: =((20/365.24)*15)*E11 -> 164.27554
A12: SEI0016 | B12: Negrete Bejar Aide Sarai | C12: 15 | D12: 0 | E12: 154 | F12: 160.96 | G12: 2310 | H12: 0 | I12: 0 | J12: 2310 | K12: 0 | L12: 977.57 | M12: 0 | N12: -39.73 | O12: 0 | P12: 57.34 | Q12: 0 | R12: 0 | S12: 0.02 | T12: 995.2 | U12: 1314.8 | V12: 42.25 | W12: 76.05 | X12: 300.79 | Y12: 238.29 | Z12: 46.2 | AA12: 19.23 | AB12: 419.09 | AC12: 120.72 | AD12: 214.14 | AE12: 110 | AF12: =((20/365.24)*15)*E12 -> 126.49217
A13: SEI0017 | B13: Muñoz Reyes Luis Eduardo | C13: 15 | D13: 0 | E13: 266.67 | F13: 278.72 | G13: 4000.05 | H13: 0 | I13: 0 | J13: 4000.05 | K13: 0 | L13: 868.44 | M13: 0 | N13: 0 | O13: 313.87 | P13: 100.81 | Q13: 0 | R13: 0 | S13: -0.07 | T13: 1283.05 | U13: 2717 | V13: 73.16 | W13: 131.7 | X13: 335.88 | Y13: 273.62 | Z13: 80 | AA13: 33.3 | AB13: 540.74 | AC13: 209.04 | AD13: 231.81 | AE13: 110 | AF13: =((20/365.24)*15)*E13 -> 219.0368
A14: SEI0019 | B14: Gonzalez Rasgado Miguel Isaias | C14: 15 | D14: 0 | E14: 521.68 | F14: 553.24 | G14: 7825.2 | H14: 0 | I14: 0 | J14: 7825.2 | K14: 0 | L14: 0 | M14: 0 | N14: 0 | O14: 1033.24 | P14: 215.09 | Q14: 0 | R14: 0 | S14: -0.13 | T14: 1248.2 | U14: 6577 | V14: 145.23 | W14: 261.41 | X14: 453.23 | Y14: 355.97 | Z14: 156.5 | AA14: 66.11 | AB14: 859.87 | AC14: 414.93 | AD14: 272.99 | AE14: 110 | AF14: =((20/365.24)*15)*E14 -> 428.49633
A15: SEI0020 | B15: Mar Marquez Cesar Eduardo | C15: 15 | D15: 0 | E15: 266.67 | F15: 278.72 | G15: 4000.05 | H15: 0 | I15: 0 | J15: 4000.05 | K15: 0 | L15: 0 | M15: 0 | N15: 0 | O15: 313.87 | P15: 100.81 | Q15: 0 | R15: 0 | S15: -0.03 | T15: 414.65 | U15: 3585.4 | V15: 73.16 | W15: 131.7 | X15: 335.88 | Y15: 273.62 | Z15: 80 | AA15: 33.3 | AB15: 540.74 | AC15: 209.04 | AD15: 231.81 | AE15: 110 | AF15: =((20/365.24)*15)*E15 -> 219.0368
A16: SEI0021 | B16: Velez Rodriguez Jaime | C16: 15 | D16: 0 | E16: 200 | F16: 212.1 | G16: 3000 | H16: 0 | I16: 0 | J16: 3000 | K16: 0 | L16: 1347.1 | M16: 0 | N16: 0 | O16: 59.69 | P16: 75.55 | Q16: 0 | R16: 0 | S16: -0.14 | T16: 1482.2 | U16: 1517.8 | V16: 55.68 | W16: 100.22 | X16: 314.22 | Y16: 253.63 | Z16: 60 | AA16: 25.34 | AB16: 470.12 | AC16: 159.08 | AD16: 221.82 | AE16: 110 | AF16: =((20/365.24)*15)*E16 -> 164.27554
A17: SEI0022 | B17: Najera Lopez Raul | C17: 14 | D17: 0 | E17: 333.33 | F17: 353.5 | G17: 4666.62 | H17: 0 | I17: 0 | J17: 4666.62 | K17: 0 | L17: 0 | M17: 0 | N17: 0 | O17: 407.33 | P17: 125.75 | Q17: 0 | R17: 0 | S17: -0.06 | T17: 533.02 | U17: 4133.6 | V17: 92.79 | W17: 167.03 | X17: 367.84 | Y17: 296.05 | Z17: 93.33 | AA17: 42.24 | AB17: 627.66 | AC17: 265.12 | AD17: 243.02 | AE17: 110 | AF17: =((20/365.24)*15)*E17 -> 273.78984
A18: SEI0023 | B18: Puente Murguia Luis Felipe | C18: 15 | D18: 0 | E18: 233.33 | F18: 247.45 | G18: 3499.95 | H18: 0 | I18: 0 | J18: 3499.95 | K18: 0 | L18: 0 | M18: 0 | N18: 0 | O18: 134.36 | P18: 88.16 | Q18: 0 | R18: 0 | S18: -0.17 | T18: 222.35 | U18: 3277.6 | V18: 64.95 | W18: 116.92 | X18: 323.49 | Y18: 264.23 | Z18: 70 | AA18: 29.57 | AB18: 505.36 | AC18: 185.58 | AD18: 227.12 | AE18: 110 | AF18: =((20/365.24)*15)*E18 -> 191.65206
A19: SEI0029 | B19: Arceo Garcia Manuel Federico | C19: 15 | D19: 0 | E19: 200 | F19: 212.1 | G19: 3000 | H19: 0 | I19: 0 | J19: 3000 | K19: 0 | L19: 0 | M19: 0 | N19: 0 | O19: 59.69 | P19: 75.55 | Q19: 600 | R19: 0 | S19: -0.04 | T19: 735.2 | U19: 2264.8 | V19: 55.68 | W19: 100.22 | X19: 314.22 | Y19: 253.63 | Z19: 60 | AA19: 25.34 | AB19: 470.12 | AC19: 159.08 | AD19: 221.82 | AE19: 110 | AF19: =((20/365.24)*15)*E19 -> 164.27554
A20: SEI0364 | B20: Dominguez Lopez Mayeli Del Pilar | C20: 15 | D20: 0 | E20: 266.67 | F20: 282.81 | G20: 4000.05 | H20: 0 | I20: 0 | J20: 4000.05 | K20: 0 | L20: 0 | M20: 0 | N20: 0 | O20: 313.87 | P20: 102.51 | Q20: 0 | R20: 0 | S20: 0.07 | T20: 416.45 | U20: 3583.6 | V20: 74.24 | W20: 133.63 | X20: 337.62 | Y20: 274.84 | Z20: 80 | AA20: 33.79 | AB20: 545.49 | AC20: 212.11 | AD20: 232.42 | AE20: 110 | AF20: =((20/365.24)*15)*E20 -> 219.0368
... A93: SEI0554 | B93: Moreno Castillo Paulina Yamileth | C93: 6 | D93: 0 | E93: 200 | F93: 209.04 | G93: 1200 | H93: 0 | I93: 0 | J93: 1200 | K93: 0 | L93: 0 | M93: 0 | N93: -136.73 | O93: 0 | P93: 29.79 | Q93: 0 | R93: 0 | S93: -0.06 | T93: -107 | U93: 1307 | V93: 21.95 | W93: 39.51 | X93: 125.37 | Y93: 215.08 | Z93: 24 | AA93: 9.99 | AB93: 186.83 | AC93: 62.71 | AD93: 202.54 | AE93: 0 | AF93: =((20/365.24)*15)*E93 -> 164.27554
C94: ============= | D94: ============= | E94: ============= | F94: ============= | G94: ============= | H94: ============= | I94: ============= | J94: ============= | K94: ============= | L94: ============= | M94: ============= | N94: ============= | O94: ============= | P94: ============= | Q94: ============= | R94: ============= | S94: ============= | T94: ============= | U94: ============= | V94: ============= | W94: ============= | X94: ============= | Y94: ============= | Z94: ============= | AA94: ============= | AB94: ============= | AC94: ============= | AD94: ============= | AE94: ============= | AF94: =============
A95: Total Gral. | C95: =SUM(C9:C94) -> 1249 | D95: =SUM(D9:D94) -> 13 | E95: =SUM(E9:E94) -> 20330.61 | F95: =SUM(F9:F94) -> 21428.9 | G95: =SUM(G9:G94) -> 299308.23 | H95: =SUM(H9:H94) -> 2897.69 | I95: =SUM(I9:I94) -> 869.31 | J95: =SUM(J9:J94) -> 303075.23 | ... AF95: =SUM(AF9:AF94) -> 16699.11
A97: 83 | B97: Nomina
A98: 3 | B98: Altas | I98: FACTURACION PITS | K98: VENTAS | L98: ADMON | M98: SERVICIO
A99: 1 | B99: Bajas | I99: Devengado Salario | J99: =+U95 -> 238785.2 | K99: 1314.8 | M99: =J99-K99 -> 237470.4
A100: =+A97+A98-A99 -> 85 | B100: Total Nomina | I100: RETORNOS | J100: =+R95-R77 -> 5673.24 | K100: 0 | M100: =J100-K100-L100 -> 5673.24
I101: Infonavit | J101: =+K95+L95+M95 -> 32692.97 | K101: 977.57 | M101: =J101-K101 -> 31715.4
I102: Prestamo Prospera | J102: =+Q95 -> 1236.6 | M102: =J102 -> 1236.6
I103: Subtotal 1 | J103: =SUM(J99:J102) -> 278388.01 | K103: =SUM(K99:K102) -> 2292.37 | M103: =SUM(M99:M102) -> 276095.64
I104: Comision | J104: =+J103*2% -> 5567.7602 | K104: =K103*2% -> 45.8474 | L104: =L103*2% -> 0 | M104: =M103*2% -> 5521.9128
I105: Subtotal 2 | J105: =+J103+J104 -> 283955.77 | K105: =K103+K104 -> 2338.2174 | L105: =L103+L104 -> 0 | M105: =M103+M104 -> 281617.55
I106: Costo Patronal Imss | J106: =+P95+V95+W95+X95+Y95+AA95+AC95+AD95 -> 111385.54 | K106: 1068.81 | M106: =J106-K106 -> 110316.73
I107: 2% Sobre Nomina | J107: =+J95*2% -> 6061.5046 | K107: =2310*2% -> 46.2 | M107: =J107-K107 -> 6015.3046
I108: Importe de Factura | J108: =+J105+J106+J107 -> 401402.81 | K108: =SUM(K105:K107) -> 3453.2274 | M108: =SUM(M105:M107) -> 397949.59
I109: IVA | J109: =+J108*16% -> 64224.45 | K109: =K108*16% -> 552.51638 | L109: =L108*16% -> 0 | M109: =M108*16% -> 63671.934
I110: TOTAL | J110: =+J108+J109 -> 465627.27 | K110: =K109+K108 -> 4005.7438 | L110: =L109+L108 -> 0 | M110: =M109+M108 -> 461621.52
K111: =K108-K104 -> 3407.38 | M111: =M108-M104 -> 392427.67
I112: PROVISION AGUINALDO
I113: FACTURACION PITS | L113: 0.73 | M113: 0.11 | N113: 0.12 | O113: 0.04
I114: Subtotal 1 | J114: =+AF95 -> 16699.11 | L114: ITA | M114: IP | N114: CPD | O114: EM
I115: Comision | J115: =+J114*2% -> 333.9822 | K115: ADMON | L115: =L112*$O$45 -> 0 | M115: =L112*$P$45 -> 0 | N115: =L112*$Q$45 -> 0 | O115: =L112*$R$45 -> 0
I116: Subtotal 2 | J116: =+J114+J115 -> 17033.092 | K116: SERVICIO | L116: =M111*$L$113 -> 286472.2 | M116: =M111*$M$113 -> 43167.044 | N116: =M111*$N$113 -> 47091.321 | O116: =M111*$O$113 -> 15697.107
...

Sheet SIND PITS
C2: SINDICATO
C3: Lista de Raya (forma tabular)
D7: SINDICATO
A8: CLAVE | B8: EMPRESA | C8: NOMBRE | D8: SUELDO SINDICATO | E8: BONO | F8: COMISION | G8: prima vacaciones | H8: TOTAL | I8: CLAVE SINDICATO | J8: CUADRE
A9: SEI0097 | B9: IP INNOVACION | C9: Aguilar Aguirre Alfonso | D9: 135.2 | E9: 0 | F9: 0 | G9: =+VLOOKUP(C9,'EXTRAS Y FESTIVOS'!$B$9:T129,19,0) -> 0 | H9: =SUM(D9:G9) -> 135.2 | I9: SEI0652 | J9: =+VLOOKUP(C9,'RESUMEN PITS'!$C$9:W129,21,0) -> -54.055924
A10: SEI0118 | B10: IP INNOVACION | C10: Aguilar Garcia Rosa Paola | D10: 53.2 | E10: 0 | F10: 0 | G10: =+VLOOKUP(C10,'EXTRAS Y FESTIVOS'!$B$9:T206,19,0) -> 0 | H10: =SUM(D10:G10) -> 53.2 | I10: SEI0654 | J10: =+VLOOKUP(C10,'RESUMEN PITS'!$C$9:W206,21,0) -> -54.055924
A11: SEI0377 | B11: IP INNOVACION | C11: Alejandro Peña Deivi | D11: 175.8 | E11: 900 | F11: 0 | G11: =+VLOOKUP(C11,'EXTRAS Y FESTIVOS'!$B$9:T130,19,0) -> 0 | H11: =SUM(D11:G11) -> 1075.8 | I11: SEI0628 | J11: =+VLOOKUP(C11,'RESUMEN PITS'!$C$9:W130,21,0) -> -54.055924
A12: SEI0108 | B12: IP INNOVACION | C12: Alejandro Vazquez Erasmo Miguel | D12: 3135.25 | E12: 750 | F12: 0 | G12: =+VLOOKUP(C12,'EXTRAS Y FESTIVOS'!$B$9:T131,19,0) -> 0 | H12: =SUM(D12:G12) -> 3885.25 | I12: SEI0638 | J12: =+VLOOKUP(C12,'RESUMEN PITS'!$C$9:W131,21,0) -> -54.055924
A13: SEI0425 | B13: IP INNOVACION | C13: Arceo Garcia Manuel Federico | D13: 285.2 | E13: 1000 | F13: 0 | G13: =+VLOOKUP(C13,'EXTRAS Y FESTIVOS'!$B$9:T132,19,0) -> 0 | H13: =SUM(D13:G13) -> 1285.2 | I13: SEI0029 | J13: =+VLOOKUP(C13,'RESUMEN PITS'!$C$9:W132,21,0) -> -54.055924
A14: SEI0116 | B14: CONSULTORIA | C14: Arreola Jimenez Jose Nieves | D14: 1558.07 | E14: 420 | F14: 0 | G14: =+VLOOKUP(C14,'EXTRAS Y FESTIVOS'!$B$9:T108,19,0) -> 0 | H14: =SUM(D14:G14) -> 1978.07 | I14: SEI0097 | J14: =+VLOOKUP(C14,'RESUMEN PITS'!$C$9:W111,21,0) -> -54.055924
A15: SEI0401 | B15: CONSULTORIA | C15: Arroyo Ramirez Hector Hugo | D15: 2110.62 | E15: 0 | F15: 0 | G15: =+VLOOKUP(C15,'EXTRAS Y FESTIVOS'!$B$9:T112,19,0) -> 58.5 | H15: =SUM(D15:G15) -> 2169.12 | I15: SEI0118 | J15: =+VLOOKUP(C15,'RESUMEN PITS'!$C$9:W112,21,0) -> -54.055924
A16: SEI0099 | B16: IP INNOVACION | C16: Arzate Gil Juan Sebastian | D16: 416.4 | E16: 510 | F16: 0 | G16: =+VLOOKUP(C16,'EXTRAS Y FESTIVOS'!$B$9:T133,19,0) -> 0 | H16: =SUM(D16:G16) -> 926.4 | I16: SEI0550 | J16: =+VLOOKUP(C16,'RESUMEN PITS'!$C$9:W133,21,0) -> -54.055924
A17: SEI0009 | B17: CONSULTORIA | C17: Benavides Herrera Alejandra | D17: 16803.2 | E17: 0 | F17: 0 | G17: =+VLOOKUP(C17,'EXTRAS Y FESTIVOS'!$B$9:T113,19,0) -> 0 | H17: =SUM(D17:G17) -> 16803.2 | I17: SEI0377 | J17: =+VLOOKUP(C17,'RESUMEN PITS'!$C$9:W113,21,0) -> -54.055924
A18: SEI0127 | B18: CONSULTORIA | C18: Caballero Diaz Francisco Javier | D18: 1558.02 | E18: 210 | F18: 0 | G18: =+VLOOKUP(C18,'EXTRAS Y FESTIVOS'!$B$9:T114,19,0) -> 0 | H18: =SUM(D18:G18) -> 1768.02 | I18: SEI0108 | J18: =+VLOOKUP(C18,'RESUMEN PITS'!$C$9:W114,21,0) -> -54.055924
A19: SEI0117 | B19: CONSULTORIA | C19: Carbajal Cabuto Jose Luis | D19: 1607.97 | E19: 210 | F19: 0 | G19: =+VLOOKUP(C19,'EXTRAS Y FESTIVOS'!$B$9:T115,19,0) -> 0 | H19: =SUM(D19:G19) -> 1817.97 | I19: SEI0453 | J19: =+VLOOKUP(C19,'RESUMEN PITS'!$C$9:W115,21,0) -> -54.055924
A20: SEI0040 | B20: IP INNOVACION | C20: Casas Chavarria Rafael | D20: 175.52 | E20: 1350 | F20: 0 | G20: =+VLOOKUP(C20,'EXTRAS Y FESTIVOS'!$B$9:T134,19,0) -> 0 | H20: =SUM(D20:G20) -> 1525.52 | I20: SEI0629 | J20: =+VLOOKUP(C20,'RESUMEN PITS'!$C$9:W134,21,0) -> -54.055924
A21: SEI0088 | B21: CONSULTORIA | C21: Casillas Cardona Cesar Alejandro | D21: 1891.12 | E21: 0 | F21: 0 | G21: =+VLOOKUP(C21,'EXTRAS Y FESTIVOS'!$B$9:T116,19,0) -> 268.75 | H21: =SUM(D21:G21) -> 2159.87 | I21: SEI0116 | J21: =+VLOOKUP(C21,'RESUMEN PITS'!$C$9:W116,21,0) -> -54.055924
A22: SEI0173 | B22: IP INNOVACION | C22: Castellon Ramos Rene | D22: 384.785 | E22: 70 | F22: 0 | G22: =+VLOOKUP(C22,'EXTRAS Y FESTIVOS'!$B$9:T135,19,0) -> 0.0599 | H22: =SUM(D22:G22) -> 454.8449 | I22: SEI0499 | J22: =+VLOOKUP(C22,'RESUMEN PITS'!$C$9:W135,21,0) -> -54.055924
A23: SEI0026 | B23: IP INNOVACION | C23: Castillo Nungaray Nestor Roman | D23: 285.2 | E23: 800 | F23: 0 | G23: =+VLOOKUP(C23,'EXTRAS Y FESTIVOS'!$B$9:T136,19,0) -> 0 | H23: =SUM(D23:G23) -> 1085.2 | I23: SEI0468 | J23: =+VLOOKUP(C23,'RESUMEN PITS'!$C$9:W136,21,0) -> -54.055924
A24: SEI0221 | B24: IP INNOVACION | C24: Castillo Ramirez Hector Ivan | D24: 3721.4 | E24: 281.25 | F24: 0 | G24: =+VLOOKUP(C24,'EXTRAS Y FESTIVOS'!$B$9:T137,19,0) -> 0 | H24: =SUM(D24:G24) -> 4002.65 | I24: SEI0448 | J24: =+VLOOKUP(C24,'RESUMEN PITS'!$C$9:W137,21,0) -> -1414.5349
A25: SEI0442 | B25: IP INNOVACION | C25: Cerro Garcia Elvis | D25: 2553.4 | E25: 400 | F25: 0 | G25: =+VLOOKUP(C25,'EXTRAS Y FESTIVOS'!$B$9:T138,19,0) -> 0 | H25: =SUM(D25:G25) -> 2953.4 | I25: SEI0513 | J25: =+VLOOKUP(C25,'RESUMEN PITS'!$C$9:W138,21,0) -> -1414.5349
A26: SEI0041 | B26: IP INNOVACION | C26: Chavez Dominguez Salvador | D26: 2667.4 | E26: 500 | F26: 0 | G26: =+VLOOKUP(C26,'EXTRAS Y FESTIVOS'!$B$9:T139,19,0) -> 0 | H26: =SUM(D26:G26) -> 3167.4 | I26: SEI0483 | J26: =+VLOOKUP(C26,'RESUMEN PITS'!$C$9:W139,21,0) -> -1414.5349
A27: SEI0544 | B27: IP INNOVACION | C27: Chavez Govea Edgar Aram | D27: 222.6 | E27: 187.5 | F27: 0 | G27: =+VLOOKUP(C27,'EXTRAS Y FESTIVOS'!$B$9:T140,19,0) -> 0 | H27: =SUM(D27:G27) -> 410.1 | I27: SEI0644 | J27: =+VLOOKUP(C27,'RESUMEN PITS'!$C$9:W140,21,0) -> -1414.5349
A28: SEI0527 | B28: IP INNOVACION | C28: Chavez Pedraza Samuel | D28: 1047.8 | E28: 312.5 | F28: 0 | G28: =+VLOOKUP(C28,'EXTRAS Y FESTIVOS'!$B$9:T141,19,0) -> 0 | H28: =SUM(D28:G28) -> 1360.3 | I28: SEI0467 | J28: =+VLOOKUP(C28,'RESUMEN PITS'!$C$9:W141,21,0) -> -1414.5349
A29: SEI0535 | B29: IP INNOVACION | C29: Chavez Saucedo Jorge Arturo | D29: 414.6 | E29: 600 | F29: 0 | G29: =+VLOOKUP(C29,'EXTRAS Y FESTIVOS'!$B$9:T142,19,0) -> 0 | H29: =SUM(D29:G29) -> 1014.6 | I29: SEI0516 | J29: =+VLOOKUP(C29,'RESUMEN PITS'!$C$9:W142,21,0) -> -1414.5349
A30: SEI0029 | B30: IP INNOVACION | C30: Chavira Garcia David Fernando | D30: 593.6 | E30: 60 | F30: 0 | G30: =+VLOOKUP(C30,'EXTRAS Y FESTIVOS'!$B$9:T143,19,0) -> 0 | H30: =SUM(D30:G30) -> 653.6 | I30: SEI0495 | J30: =+VLOOKUP(C30,'RESUMEN PITS'!$C$9:W143,21,0) -> -1414.5349
A31: SEI0472 | B31: IP INNOVACION | C31: Cota Jaramillo Miguel Angel | D31: 134.2 | E31: 337.5 | F31: 0 | G31: =+VLOOKUP(C31,'EXTRAS Y FESTIVOS'!$B$9:T144,19,0) -> 0 | H31: =SUM(D31:G31) -> 471.7 | I31: SEI0015 | J31: =+VLOOKUP(C31,'RESUMEN PITS'!$C$9:W144,21,0) -> -1414.5349
A32: SEI0528 | B32: IP INNOVACION | C32: Courtenay Gutierrez Barry Vladimir | D32: 52.25 | E32: 250 | F32: 0 | G32: =+VLOOKUP(C32,'EXTRAS Y FESTIVOS'!$B$9:T145,19,0) -> 0 | H32: =SUM(D32:G32) -> 302.25 | I32: SEI0436 | J32: =+VLOOKUP(C32,'RESUMEN PITS'!$C$9:W145,21,0) -> -1414.5349
A33: SEI0460 | B33: IP INNOVACION | C33: Cruz Herrera Roberto | D33: 1667.49 | E33: 90 | F33: 0 | G33: =+VLOOKUP(C33,'EXTRAS Y FESTIVOS'!$B$9:T146,19,0) -> 0 | H33: =SUM(D33:G33) -> 1757.49 | I33: SEI0485 | J33: =+VLOOKUP(C33,'RESUMEN PITS'!$C$9:W146,21,0) -> -1414.5349
A34: SEI0443 | B34: IP INNOVACION | C34: Cruz Perez Alejandro Nezahualcoyotl | D34: 416.4 | E34: 570 | F34: 0 | G34: =+VLOOKUP(C34,'EXTRAS Y FESTIVOS'!$B$9:T147,19,0) -> 0 | H34: =SUM(D34:G34) -> 986.4 | I34: SEI0606 | J34: =+VLOOKUP(C34,'RESUMEN PITS'!$C$9:W147,21,0) -> -1414.5349
A35: SEI0490 | B35: CONSULTORIA | C35: De La Torre Zambara Francisco Ernesto | D35: 1558.2 | E35: 60 | F35: 0 | G35: =+VLOOKUP(C35,'EXTRAS Y FESTIVOS'!$B$9:T117,19,0) -> 0 | H35: =SUM(D35:G35) -> 1618.2 | I35: SEI0401 | J35: =+VLOOKUP(C35,'RESUMEN PITS'!$C$9:W117,21,0) -> -1414.5349
A36: SEI0508 | B36: IP INNOVACION | C36: Del Pilar Mendez Lucio | D36: 134.2 | E36: 363.75 | F36: 0 | G36: =+VLOOKUP(C36,'EXTRAS Y FESTIVOS'!$B$9:T148,19,0) -> 0 | H36: =SUM(D36:G36) -> 497.95 | I36: SEI0630 | J36: =+VLOOKUP(C36,'RESUMEN PITS'!$C$9:W148,21,0) -> -1414.5349
A37: SEI0499 | B37: IP INNOVACION | C37: Diaz Ortiz Hiram Guillermo | D37: 174.54 | E37: 56.25 | F37: 0 | G37: =+VLOOKUP(C37,'EXTRAS Y FESTIVOS'!$B$9:T149,19,0) -> 0 | H37: =SUM(D37:G37) -> 230.79 | I37: SEI0646 | J37: =+VLOOKUP(C37,'RESUMEN PITS'!$C$9:W149,21,0) -> -1414.5349
A38: SEI0541 | B38: IP INNOVACION | C38: Dominguez Lopez Mayeli Del Pilar | D38: 1416.4 | E38: 1087.5 | F38: 0 | G38: =+VLOOKUP(C38,'EXTRAS Y FESTIVOS'!$B$9:T150,19,0) -> 0 | H38: =SUM(D38:G38) -> 2503.9 | I38: SEI0364 | J38: =+VLOOKUP(C38,'RESUMEN PITS'!$C$9:W150,21,0) -> -1414.5349
A39: SEI0442 | B39: IP INNOVACION | C39: Escobedo Olivares Juan Guadalupe | D39: 3721.2 | E39: 125 | F39: 0 | G39: =+VLOOKUP(C39,'EXTRAS Y FESTIVOS'!$B$9:T151,19,0) -> 0 | H39: =SUM(D39:G39) -> 3846.2 | I39: SEI0447 | J39: =+VLOOKUP(C39,'RESUMEN PITS'!$C$9:W151,21,0) -> -1414.5349
A40: SEI0462 | B40: IP INNOVACION | C40: Flores Cerrillos Jorge Humberto | D40: 416.2 | E40: 130 | F40: 0 | G40: =+VLOOKUP(C40,'EXTRAS Y FESTIVOS'!$B$9:T152,19,0) -> 0 | H40: =SUM(D40:G40) -> 546.2 | I40: SEI0474 | J40: =+VLOOKUP(C40,'RESUMEN PITS'!$C$9:W152,21,0) -> -1414.5349
A41: SEI0456 | B41: IP INNOVACION | C41: Flores Franco Marco | D41: 451.005 | E41: 162.5 | F41: 0 | G41: =+VLOOKUP(C41,'EXTRAS Y FESTIVOS'!$B$9:T153,19,0) -> 0 | H41: =SUM(D41:G41) -> 613.505 | I41: SEI0500 | J41: =+VLOOKUP(C41,'RESUMEN PITS'!$C$9:W153,21,0) -> -1414.5349
A42: SEI0015 | B42: IP INNOVACION | C42: Garcia Gutierrez Jose Juan | D42: 3135.2 | E42: 0 | F42: 0 | G42: =+VLOOKUP(C42,'EXTRAS Y FESTIVOS'!$B$9:T154,19,0) -> 0 | H42: =SUM(D42:G42) -> 3135.2 | I42: SEI0484 | J42: =+VLOOKUP(C42,'RESUMEN PITS'!$C$9:W154,21,0) -> -1414.5349
A43: SEI0413 | B43: CONSULTORIA | C43: Garcia Villicaña Ricardo Pascual | D43: 2600.25 | E43: 0 | F43: 0 | G43: =+VLOOKUP(C43,'EXTRAS Y FESTIVOS'!$B$9:T118,19,0) -> 0 | H43: =SUM(D43:G43) -> 2600.25 | I43: SEI0099 | J43: =+VLOOKUP(C43,'RESUMEN PITS'!$C$9:W118,21,0) -> -1414.5349
A44: SEI0501 | B44: IP INNOVACION | C44: Gonzalez Ramirez Paul | D44: 134.1 | E44: 292.5 | F44: 0 | G44: =+VLOOKUP(C44,'EXTRAS Y FESTIVOS'!$B$9:T155,19,0) -> 0 | H44: =SUM(D44:G44) -> 426.6 | I44: 0SEI0635 | J44: =+VLOOKUP(C44,'RESUMEN PITS'!$C$9:W155,21,0) -> -1414.5349
...

Sheet EXTRAS Y FESTIVOS
B2: HORAS EXTRAS Y DIAS FESTIVOS
A8: Clave | B8: Nombre | C8: DIAS LABORADOS | D8: SDI | E8: Sueldo Mensual | F8: Sueldo quincenal | G8: Sueldo diario con bonos | I8: Faltas | J8: Monto | L8: DIAS VACACIONES | M8: Total de Vacaciones | N8: VACACIONES IMSS | O8: VACACIONES SINDICATO | Q8: PRIMA VACACIONAL | R8: Total de Prima vacacional | S8: PRIMA IMSS | T8: PRIMA SINDICATO | W8: VACACIONES PAGADAS | X8: Total | Y8: IMSS | Z8: SINDICATO | AA8: Total de Prima vacacional | AB8: PRIMA IMSS | AC8: PRIMA SINDICATO | AD8: INCAPACIDAD | AE8: TOTAL | AF8: IMSS | AG8: SINDICATO
A9: CONSULTORIA | B9: Arreola Jimenez Jose Nieves | C9: =+VLOOKUP(B9,'CPD PITSS'!$B$9:C26,2,0) -> 15 | D9: =+VLOOKUP(B9,'CPD PITSS'!$B$9:F26,5,0) -> 197.07 | E9: 10150 | F9: =+E9/2 -> 5075 | G9: =+F9/15 -> 338.33333 | I9: =15-C9 -> 0 | J9: =+I9*G9 -> 0 | L9: =+VLOOKUP(B9,'CPD PITSS'!$B$9:AG27,3,0) -> 0 | M9: =+G9*L9 -> 0 | N9: =+VLOOKUP(B9,'CPD PITSS'!$B$9:AH27,7,0) -> 0 | O9: =+M9-N9 -> 0 | Q9: =+VLOOKUP(B9,'CPD PITSS'!$B$9:AK27,3,0) -> 0 | R9: =+G9*Q9*30% -> 0 | S9: =+VLOOKUP(B9,'CPD PITSS'!$B$9:AM27,8,0) -> 0 | T9: =+R9-S9 -> 0 | W9: 0 | X9: =+G9*W9 -> 0 | Y9: 0 | Z9: =+X9-Y9 -> 0 | AA9: =+X9*0.25 -> 0 | AB9: 0 | AC9: =+AA9-AB9 -> 0 | AD9: 0 | AE9: =+G9*AD9 -> 0 | AF9: =+AD9*D9 -> 0 | AG9: =+AE9-AF9 -> 0
A10: CONSULTORIA | B10: Arroyo Ramirez Hector Hugo | C10: =+VLOOKUP(B10,'CPD PITSS'!$B$9:C27,2,0) -> 14 | D10: =+VLOOKUP(B10,'CPD PITSS'!$B$9:F27,5,0) -> 252.75 | E10: 13000 | F10: =+E10/2 -> 6500 | G10: =+F10/15 -> 433.33333 | I10: 0 | J10: =+I10*G10 -> 0 | L10: =+VLOOKUP(B10,'CPD PITSS'!$B$9:AG28,3,0) -> 1 | M10: =+G10*L10 -> 433.33333 | N10: =+VLOOKUP(B10,'CPD PITSS'!$B$9:AH28,7,0) -> 238.33 | O10: =+M10-N10 -> 195.00333 | Q10: =+VLOOKUP(B10,'CPD PITSS'!$B$9:AK28,3,0) -> 1 | R10: =+G10*Q10*30% -> 130 | S10: =+VLOOKUP(B10,'CPD PITSS'!$B$9:AM28,8,0) -> 71.5 | T10: =+R10-S10 -> 58.5 | AD10: 0 | AE10: =+G10*AD10 -> 0 | AF10: =+AD10*D10 -> 0 | AG10: =+AE10-AF10 -> 0
A11: CONSULTORIA | B11: Benavides Herrera Alejandra | C11: =+VLOOKUP(B11,'CPD PITSS'!$B$9:C28,2,0) -> 15 | D11: =+VLOOKUP(B11,'CPD PITSS'!$B$9:F28,5,0) -> 176.76 | E11: 40000 | F11: =+E11/2 -> 20000 | G11: =+F11/15 -> 1333.3333 | I11: =15-C11 -> 0 | J11: =+I11*G11 -> 0 | L11: =+VLOOKUP(B11,'CPD PITSS'!$B$9:AG29,3,0) -> 0 | M11: =+G11*L11 -> 0 | N11: =+VLOOKUP(B11,'CPD PITSS'!$B$9:AH29,7,0) -> 0 | O11: =+M11-N11 -> 0 | Q11: =+VLOOKUP(B11,'CPD PITSS'!$B$9:AK29,3,0) -> 0 | R11: =+G11*Q11*30% -> 0 | S11: =+VLOOKUP(B11,'CPD PITSS'!$B$9:AM29,8,0) -> 0 | T11: =+R11-S11 -> 0 | AD11: 0 | AE11: =+G11*AD11 -> 0 | AF11: =+AD11*D11 -> 0 | AG11: =+AE11-AF11 -> 0
A12: CONSULTORIA | B12: Caballero Diaz Francisco Javier | C12: =+VLOOKUP(B12,'CPD PITSS'!$B$9:C29,2,0) -> 15 | D12: =+VLOOKUP(B12,'CPD PITSS'!$B$9:F29,5,0) -> 197.07 | E12: 10150 | F12: =+E12/2 -> 5075 | G12: =+F12/15 -> 338.33333 | I12: =15-C12 -> 0 | J12: =+I12*G12 -> 0 | L12: =+VLOOKUP(B12,'CPD PITSS'!$B$9:AG30,3,0) -> 0 | M12: =+G12*L12 -> 0 | N12: =+VLOOKUP(B12,'CPD PITSS'!$B$9:AH30,7,0) -> 0 | O12: =+M12-N12 -> 0 | Q12: =+VLOOKUP(B12,'CPD PITSS'!$B$9:AK30,3,0) -> 0 | R12: =+G12*Q12*30% -> 0 | S12: =+VLOOKUP(B12,'CPD PITSS'!$B$9:AM30,8,0) -> 0 | T12: =+R12-S12 -> 0 | AD12: 0 | AE12: =+G12*AD12 -> 0 | AF12: =+AD12*D12 -> 0 | AG12: =+AE12-AF12 -> 0
A13: CONSULTORIA | B13: Carbajal Cabuto Jose Luis | C13: =+VLOOKUP(B13,'CPD PITSS'!$B$9:C30,2,0) -> 15 | D13: =+VLOOKUP(B13,'CPD PITSS'!$B$9:F30,5,0) -> 197.07 | E13: 10250 | F13: =+E13/2 -> 5125 | G13: =+F13/15 -> 341.66667 | I13: =15-C13 -> 0 | J13: =+I13*G13 -> 0 | L13: =+VLOOKUP(B13,'CPD PITSS'!$B$9:AG31,3,0) -> 0 | M13: =+G13*L13 -> 0 | N13: =+VLOOKUP(B13,'CPD PITSS'!$B$9:AH31,7,0) -> 0 | O13: =+M13-N13 -> 0 | Q13: =+VLOOKUP(B13,'CPD PITSS'!$B$9:AK31,3,0) -> 0 | R13: =+G13*Q13*30% -> 0 | S13: =+VLOOKUP(B13,'CPD PITSS'!$B$9:AM31,8,0) -> 0 | T13: =+R13-S13 -> 0 | AD13: 0 | AE13: =+G13*AD13 -> 0 | AF13: =+AD13*D13 -> 0 | AG13: =+AE13-AF13 -> 0
A14: CONSULTORIA | B14: Casillas Cardona Cesar Alejandro | C14: =+VLOOKUP(B14,'CPD PITSS'!$B$9:C31,2,0) -> 10 | D14: =+VLOOKUP(B14,'CPD PITSS'!$B$9:F31,5,0) -> 234.19 | E14: 12000 | F14: =+E14/2 -> 6000 | G14: =+F14/15 -> 400 | I14: 0 | J14: =+I14*G14 -> 0 | L14: =+VLOOKUP(B14,'CPD PITSS'!$B$9:AG32,3,0) -> 5 | M14: =+G14*L14 -> 2000 | N14: =+VLOOKUP(B14,'CPD PITSS'!$B$9:AH32,7,0) -> 1104.15 | O14: =+M14-N14 -> 895.85 | Q14: =+VLOOKUP(B14,'CPD PITSS'!$B$9:AK32,3,0) -> 5 | R14: =+G14*Q14*30% -> 600 | S14: =+VLOOKUP(B14,'CPD PITSS'!$B$9:AM32,8,0) -> 331.25 | T14: =+R14-S14 -> 268.75 | AD14: 0 | AE14: =+G14*AD14 -> 0 | AF14: =+AD14*D14 -> 0 | AG14: =+AE14-AF14 -> 0
A15: CONSULTORIA | B15: De La Torre Zambara Francisco Ernesto | C15: =+VLOOKUP(B15,'CPD PITSS'!$B$9:C32,2,0) -> 15 | D15: =+VLOOKUP(B15,'CPD PITSS'!$B$9:F32,5,0) -> 197.07 | E15: 10150 | F15: =+E15/2 -> 5075 | G15: =+F15/15 -> 338.33333 | I15: =15-C15 -> 0 | J15: =+I15*G15 -> 0 | L15: =+VLOOKUP(B15,'CPD PITSS'!$B$9:AG33,3,0) -> 0 | M15: =+G15*L15 -> 0 | N15: =+VLOOKUP(B15,'CPD PITSS'!$B$9:AH33,7,0) -> 0 | O15: =+M15-N15 -> 0 | Q15: =+VLOOKUP(B15,'CPD PITSS'!$B$9:AK33,3,0) -> 0 | R15: =+G15*Q15*30% -> 0 | S15: =+VLOOKUP(B15,'CPD PITSS'!$B$9:AM33,8,0) -> 0 | T15: =+R15-S15 -> 0 | AD15: 0 | AE15: =+G15*AD15 -> 0 | AF15: =+AD15*D15 -> 0 | AG15: =+AE15-AF15 -> 0
A16: CONSULTORIA | B16: Garcia Villicaña Ricardo Pascual | C16: =+VLOOKUP(B16,'CPD PITSS'!$B$9:C33,2,0) -> 15 | D16: =+VLOOKUP(B16,'CPD PITSS'!$B$9:F33,5,0) -> 289.87 | E16: 15000 | F16: =+E16/2 -> 7500 | G16: =+F16/15 -> 500 | I16: =15-C16 -> 0 | J16: =+I16*G16 -> 0 | L16: =+VLOOKUP(B16,'CPD PITSS'!$B$9:AG34,3,0) -> 0 | M16: =+G16*L16 -> 0 | N16: =+VLOOKUP(B16,'CPD PITSS'!$B$9:AH34,7,0) -> 0 | O16: =+M16-N16 -> 0 | Q16: =+VLOOKUP(B16,'CPD PITSS'!$B$9:AK34,3,0) -> 0 | R16: =+G16*Q16*30% -> 0 | S16: =+VLOOKUP(B16,'CPD PITSS'!$B$9:AM34,8,0) -> 0 | T16: =+R16-S16 -> 0 | AD16: 0 | AE16: =+G16*AD16 -> 0 | AF16: =+AD16*D16 -> 0 | AG16: =+AE16-AF16 -> 0
A17: CONSULTORIA | B17: Gutierrez Gutierrez Luis Arturo | C17: =+VLOOKUP(B17,'CPD PITSS'!$B$9:C34,2,0) -> 15 | D17: =+VLOOKUP(B17,'CPD PITSS'!$B$9:F34,5,0) -> 150.25 | E17: 8500 | F17: =+E17/2 -> 4250 | G17: =+F17/15 -> 283.33333 | I17: =15-C17 -> 0 | J17: =+I17*G17 -> 0 | L17: =+VLOOKUP(B17,'CPD PITSS'!$B$9:AG35,3,0) -> 0 | M17: =+G17*L17 -> 0 | N17: =+VLOOKUP(B17,'CPD PITSS'!$B$9:AH35,7,0) -> 0 | O17: =+M17-N17 -> 0 | Q17: =+VLOOKUP(B17,'CPD PITSS'!$B$9:AK35,3,0) -> 0 | R17: =+G17*Q17*30% -> 0 | S17: =+VLOOKUP(B17,'CPD PITSS'!$B$9:AM35,8,0) -> 0 | T17: =+R17-S17 -> 0 | AD17: 0 | AE17: =+G17*AD17 -> 0 | AF17: =+AD17*D17 -> 0 | AG17: =+AE17-AF17 -> 0
A18: CONSULTORIA | B18: Hernandez Ochoa Eduardo | C18: =+VLOOKUP(B18,'CPD PITSS'!$B$9:C35,2,0) -> 15 | D18: =+VLOOKUP(B18,'CPD PITSS'!$B$9:F35,5,0) -> 289.87 | E18: 15000 | F18: =+E18/2 -> 7500 | G18: =+F18/15 -> 500 | I18: =15-C18 -> 0 | J18: =+I18*G18 -> 0 | L18: =+VLOOKUP(B18,'CPD PITSS'!$B$9:AG36,3,0) -> 0 | M18: =+G18*L18 -> 0 | N18: =+VLOOKUP(B18,'CPD PITSS'!$B$9:AH36,7,0) -> 0 | O18: =+M18-N18 -> 0 | Q18: =+VLOOKUP(B18,'CPD PITSS'!$B$9:AK36,3,0) -> 0 | R18: =+G18*Q18*30% -> 0 | S18: =+VLOOKUP(B18,'CPD PITSS'!$B$9:AM36,8,0) -> 0 | T18: =+R18-S18 -> 0 | AD18: 0 | AE18: =+G18*AD18 -> 0 | AF18: =+AD18*D18 -> 0 | AG18: =+AE18-AF18 -> 0
A19: CONSULTORIA | B19: Mariscal Romero Luis Adrian | C19: =+VLOOKUP(B19,'CPD PITSS'!$B$9:C36,2,0) -> 12 | D19: =+VLOOKUP(B19,'CPD PITSS'!$B$9:F36,5,0) -> 276.54 | E19: 15000 | F19: =+E19/2 -> 7500 | G19: =+F19/15 -> 500 | I19: 0 | J19: =+I19*G19 -> 0 | L19: =+VLOOKUP(B19,'CPD PITSS'!$B$9:AG37,3,0) -> 3 | M19: =+G19*L19 -> 1500 | N19: =+VLOOKUP(B19,'CPD PITSS'!$B$9:AH37,7,0) -> 793.74 | O19: =+M19-N19 -> 706.26 | Q19: =+VLOOKUP(B19,'CPD PITSS'!$B$9:AK37,3,0) -> 3 | R19: =+G19*Q19*30% -> 450 | S19: =+VLOOKUP(B19,'CPD PITSS'!$B$9:AM37,8,0) -> 238.12 | T19: =+R19-S19 -> 211.88 | AD19: 0 | AE19: =+G19*AD19 -> 0 | AF19: =+AD19*D19 -> 0 | AG19: =+AE19-AF19 -> 0
A20: CONSULTORIA | B20: Mora Ramirez Acal Aldo Isidro | C20: =+VLOOKUP(B20,'CPD PITSS'!$B$9:C37,2,0) -> 15 | D20: =+VLOOKUP(B20,'CPD PITSS'!$B$9:F37,5,0) -> 229.79 | E20: 13000 | F20: =+E20/2 -> 6500 | G20: =+F20/15 -> 433.33333 | I20: =15-C20 -> 0 | J20: =+I20*G20 -> 0 | L20: =+VLOOKUP(B20,'CPD PITSS'!$B$9:AG38,3,0) -> 0 | M20: =+G20*L20 -> 0 | N20: =+VLOOKUP(B20,'CPD PITSS'!$B$9:AH38,7,0) -> 0 | O20: =+M20-N20 -> 0 | Q20: =+VLOOKUP(B20,'CPD PITSS'!$B$9:AK38,3,0) -> 0 | R20: =+G20*Q20*30% -> 0 | S20: =+VLOOKUP(B20,'CPD PITSS'!$B$9:AM38,8,0) -> 0 | T20: =+R20-S20 -> 0 | AD20: 0 | AE20: =+G20*AD20 -> 0 | AF20: =+AD20*D20 -> 0 | AG20: =+AE20-AF20 -> 0
A21: CONSULTORIA | B21: Morgado Fernandez Martin | C21: =+VLOOKUP(B21,'CPD PITSS'!$B$9:C38,2,0) -> 15 | D21: =+VLOOKUP(B21,'CPD PITSS'!$B$9:F38,5,0) -> 289.87 | E21: 15000 | F21: =+E21/2 -> 7500 | G21: =+F21/15 -> 500 | I21: =15-C21 -> 0 | J21: =+I21*G21 -> 0 | L21: =+VLOOKUP(B21,'CPD PITSS'!$B$9:AG39,3,0) -> 0 | M21: =+G21*L21 -> 0 | N21: =+VLOOKUP(B21,'CPD PITSS'!$B$9:AH39,7,0) -> 0 | O21: =+M21-N21 -> 0 | Q21: =+VLOOKUP(B21,'CPD PITSS'!$B$9:AK39,3,0) -> 0 | R21: =+G21*Q21*30% -> 0 | S21: =+VLOOKUP(B21,'CPD PITSS'!$B$9:AM39,8,0) -> 0 | T21: =+R21-S21 -> 0 | AD21: 0 | AE21: =+G21*AD21 -> 0 | AF21: =+AD21*D21 -> 0 | AG21: =+AE21-AF21 -> 0
A22: CONSULTORIA | B22: Nieto Ortiz Jose Luis | C22: =+VLOOKUP(B22,'CPD PITSS'!$B$9:C39,2,0) -> 6 | D22: =+VLOOKUP(B22,'CPD PITSS'!$B$9:F39,5,0) -> 197.07 | E22: 10000 | F22: =+E22/2 -> 5000 | G22: =+F22/15 -> 333.33333 | I22: 0 | J22: =+I22*G22 -> 0 | L22: =+VLOOKUP(B22,'CPD PITSS'!$B$9:AG40,3,0) -> 9 | M22: =+G22*L22 -> 3000 | N22: =+VLOOKUP(B22,'CPD PITSS'!$B$9:AH40,7,0) -> 1672.47 | O22: =+M22-N22 -> 1327.53 | Q22: =+VLOOKUP(B22,'CPD PITSS'!$B$9:AK40,3,0) -> 9 | R22: =+G22*Q22*30% -> 900 | S22: =+VLOOKUP(B22,'CPD PITSS'!$B$9:AM40,8,0) -> 501.74 | T22: =+R22-S22 -> 398.26 | AD22: 0 | AE22: =+G22*AD22 -> 0 | AF22: =+AD22*D22 -> 0 | AG22: =+AE22-AF22 -> 0
A23: CONSULTORIA | B23: Patricio Aguilar Jhonattan Cristian | C23: =+VLOOKUP(B23,'CPD PITSS'!$B$9:C40,2,0) -> 15 | D23: =+VLOOKUP(B23,'CPD PITSS'!$B$9:F40,5,0) -> 159.07 | E23: 9000 | F23: =+E23/2 -> 4500 | G23: =+F23/15 -> 300 | I23: =15-C23 -> 0 | J23: =+I23*G23 -> 0 | L23: =+VLOOKUP(B23,'CPD PITSS'!$B$9:AG41,3,0) -> 0 | M23: =+G23*L23 -> 0 | N23: =+VLOOKUP(B23,'CPD PITSS'!$B$9:AH41,7,0) -> 0 | O23: =+M23-N23 -> 0 | Q23: =+VLOOKUP(B23,'CPD PITSS'!$B$9:AK41,3,0) -> 0 | R23: =+G23*Q23*30% -> 0 | S23: =+VLOOKUP(B23,'CPD PITSS'!$B$9:AM41,8,0) -> 0 | T23: =+R23-S23 -> 0 | AD23: 0 | AE23: =+G23*AD23 -> 0 | AF23: =+AD23*D23 -> 0 | AG23: =+AE23-AF23 -> 0
A24: CONSULTORIA | B24: Rogel Teran Marco Antonio | C24: =+VLOOKUP(B24,'CPD PITSS'!$B$9:C41,2,0) -> 15 | D24: =+VLOOKUP(B24,'CPD PITSS'!$B$9:F41,5,0) -> 1125.06 | E24: 60000 | F24: =+E24/2 -> 30000 | G24: =+F24/15 -> 2000 | I24: =15-C24 -> 0 | J24: =+I24*G24 -> 0 | L24: =+VLOOKUP(B24,'CPD PITSS'!$B$9:AG42,3,0) -> 0 | M24: =+G24*L24 -> 0 | N24: =+VLOOKUP(B24,'CPD PITSS'!$B$9:AH42,7,0) -> 0 | O24: =+M24-N24 -> 0 | Q24: =+VLOOKUP(B24,'CPD PITSS'!$B$9:AK42,3,0) -> 0 | R24: =+G24*Q24*30% -> 0 | S24: =+VLOOKUP(B24,'CPD PITSS'!$B$9:AM42,8,0) -> 0 | T24: =+R24-S24 -> 0 | AD24: 0 | AE24: =+G24*AD24 -> 0 | AF24: =+AD24*D24 -> 0 | AG24: =+AE24-AF24 -> 0
A25: CONSULTORIA | B25: Sierra Escamilla Daniela | C25: =+VLOOKUP(B25,'CPD PITSS'!$B$9:C42,2,0) -> 15 | D25: =+VLOOKUP(B25,'CPD PITSS'!$B$9:F42,5,0) -> 229.79 | E25: 13000 | F25: =+E25/2 -> 6500 | G25: =+F25/15 -> 433.33333 | I25: =15-C25 -> 0 | J25: =+I25*G25 -> 0 | L25: =+VLOOKUP(B25,'CPD PITSS'!$B$9:AG43,3,0) -> 0 | M25: =+G25*L25 -> 0 | N25: =+VLOOKUP(B25,'CPD PITSS'!$B$9:AH43,7,0) -> 0 | O25: =+M25-N25 -> 0 | Q25: =+VLOOKUP(B25,'CPD PITSS'!$B$9:AK43,3,0) -> 0 | R25: =+G25*Q25*30% -> 0 | S25: =+VLOOKUP(B25,'CPD PITSS'!$B$9:AM43,8,0) -> 0 | T25: =+R25-S25 -> 0 | AD25: 0 | AE25: =+G25*AD25 -> 0 | AF25: =+AD25*D25 -> 0 | AG25: =+AE25-AF25 -> 0
A26: CONSULTORIA | B26: Vazquez Perez Miguel Angel | C26: =+VLOOKUP(B26,'CPD PITSS'!$B$9:C43,2,0) -> 15 | D26: =+VLOOKUP(B26,'CPD PITSS'!$B$9:F43,5,0) -> 300.49 | E26: 18500 | F26: =+E26/2 -> 9250 | G26: =+F26/15 -> 616.66667 | I26: =15-C26 -> 0 | J26: =+I26*G26 -> 0 | L26: =+VLOOKUP(B26,'CPD PITSS'!$B$9:AG44,3,0) -> 0 | M26: =+G26*L26 -> 0 | N26: =+VLOOKUP(B26,'CPD PITSS'!$B$9:AH44,7,0) -> 0 | O26: =+M26-N26 -> 0 | Q26: =+VLOOKUP(B26,'CPD PITSS'!$B$9:AK44,3,0) -> 0 | R26: =+G26*Q26*30% -> 0 | S26: =+VLOOKUP(B26,'CPD PITSS'!$B$9:AM44,8,0) -> 0 | T26: =+R26-S26 -> 0 | AD26: 0 | AE26: =+G26*AD26 -> 0 | AF26: =+AD26*D26 -> 0 | AG26: =+AE26-AF26 -> 0
A27: IP INNOVACION | B27: Aguilar Aguirre Alfonso | C27: =+VLOOKUP(B27,'IP PITSS'!$B$9:C93,2,0) -> 15 | D27: =+VLOOKUP(B27,'IP PITSS'!$B$9:F93,5,0) -> 212.11 | E27: 6000 | F27: =+E27/2 -> 3000 | G27: =+F27/15 -> 200 | I27: =15-C27 -> 0 | J27: =+I27*G27 -> 0 | L27: =+VLOOKUP(B27,'IP PITSS'!$B$9:AF94,3,0) -> 0 | M27: =+G27*L27 -> 0 | N27: =+VLOOKUP(B27,'IP PITSS'!$B$9:AG94,7,0) -> 0 | O27: =+M27-N27 -> 0 | Q27: =+VLOOKUP(B27,'IP PITSS'!$B$9:AJ94,3,0) -> 0 | R27: =+G27*Q27*30% -> 0 | S27: =+VLOOKUP(B27,'IP PITSS'!$B$9:AL94,8,0) -> 0 | T27: =+R27-S27 -> 0 | AD27: 0 | AE27: =+G27*AD27 -> 0 | AF27: =+AD27*D27 -> 0 | AG27: =+AE27-AF27 -> 0
A28: IP INNOVACION | B28: Alejandro Peña Deivi | C28: =+VLOOKUP(B28,'IP PITSS'!$B$9:C94,2,0) -> 15 | D28: =+VLOOKUP(B28,'IP PITSS'!$B$9:F94,5,0) -> 222.72 | E28: 6300 | F28: =+E28/2 -> 3150 | G28: =+F28/15 -> 210 | I28: =15-C28 -> 0 | J28: =+I28*G28 -> 0 | L28: =+VLOOKUP(B28,'IP PITSS'!$B$9:AF95,3,0) -> 0 | M28: =+G28*L28 -> 0 | N28: =+VLOOKUP(B28,'IP PITSS'!$B$9:AG95,7,0) -> 0 | O28: =+M28-N28 -> 0 | Q28: =+VLOOKUP(B28,'IP PITSS'!$B$9:AJ95,3,0) -> 0 | R28: =+G28*Q28*30% -> 0 | S28: =+VLOOKUP(B28,'IP PITSS'!$B$9:AL95,8,0) -> 0 | T28: =+R28-S28 -> 0 | AD28: 0 | AE28: =+G28*AD28 -> 0 | AF28: =+AD28*D28 -> 0 | AG28: =+AE28-AF28 -> 0
A29: IP INNOVACION | B29: Alejandro Vazquez Erasmo Miguel | C29: =+VLOOKUP(B29,'IP PITSS'!$B$9:C95,2,0) -> 15 | D29: =+VLOOKUP(B29,'IP PITSS'!$B$9:F95,5,0) -> 212.11 | E29: 12000 | F29: =+E29/2 -> 6000 | G29: =+F29/15 -> 400 | I29: =15-C29 -> 0 | J29: =+I29*G29 -> 0 | L29: =+VLOOKUP(B29,'IP PITSS'!$B$9:AF96,3,0) -> 0 | M29: =+G29*L29 -> 0 | N29: =+VLOOKUP(B29,'IP PITSS'!$B$9:AG96,7,0) -> 0 | O29: =+M29-N29 -> 0 | Q29: =+VLOOKUP(B29,'IP PITSS'!$B$9:AJ96,3,0) -> 0 | R29: =+G29*Q29*30% -> 0 | S29: =+VLOOKUP(B29,'IP PITSS'!$B$9:AL96,8,0) -> 0 | T29: =+R29-S29 -> 0 | AD29: 0 | AE29: =+G29*AD29 -> 0 | AF29: =+AD29*D29 -> 0 | AG29: =+AE29-AF29 -> 0
A30: IP INNOVACION | B30: Arceo Garcia Manuel Federico | C30: =+VLOOKUP(B30,'IP PITSS'!$B$9:C96,2,0) -> 15 | D30: =+VLOOKUP(B30,'IP PITSS'!$B$9:F96,5,0) -> 212.1 | E30: 6300 | F30: =+E30/2 -> 3150 | G30: =+F30/15 -> 210 | I30: =15-C30 -> 0 | J30: =+I30*G30 -> 0 | L30: =+VLOOKUP(B30,'IP PITSS'!$B$9:AF97,3,0) -> 0 | M30: =+G30*L30 -> 0 | N30: =+VLOOKUP(B30,'IP PITSS'!$B$9:AG97,7,0) -> 0 | O30: =+M30-N30 -> 0 | Q30: =+VLOOKUP(B30,'IP PITSS'!$B$9:AJ97,3,0) -> 0 | R30: =+G30*Q30*30% -> 0 | S30: =+VLOOKUP(B30,'IP PITSS'!$B$9:AL97,8,0) -> 0 | T30: =+R30-S30 -> 0 | AD30: 0 | AE30: =+G30*AD30 -> 0 | AF30: =+AD30*D30 -> 0 | AG30: =+AE30-AF30 -> 0
A31: IP INNOVACION | B31: Arzate Gil Juan Sebastian | C31: =+VLOOKUP(B31,'IP PITSS'!$B$9:C97,2,0) -> 15 | D31: =+VLOOKUP(B31,'IP PITSS'!$B$9:F97,5,0) -> 282.81 | E31: 8000 | F31: =+E31/2 -> 4000 | G31: =+F31/15 -> 266.66667 | I31: =15-C31 -> 0 | J31: =+I31*G31 -> 0 | L31: =+VLOOKUP(B31,'IP PITSS'!$B$9:AF98,3,0) -> 0 | M31: =+G31*L31 -> 0 | N31: =+VLOOKUP(B31,'IP PITSS'!$B$9:AG98,7,0) -> 0 | O31: =+M31-N31 -> 0 | Q31: =+VLOOKUP(B31,'IP PITSS'!$B$9:AJ98,3,0) -> 0 | R31: =+G31*Q31*30% -> 0 | S31: =+VLOOKUP(B31,'IP PITSS'!$B$9:AL98,8,0) -> 0 | T31: =+R31-S31 -> 0 | AD31: 0 | AE31: =+G31*AD31 -> 0 | AF31: =+AD31*D31 -> 0 | AG31: =+AE31-AF31 -> 0
A32: IP INNOVACION | B32: Casas Chavarria Rafael | C32: =+VLOOKUP(B32,'IP PITSS'!$B$9:C98,2,0) -> 15 | D32: =+VLOOKUP(B32,'IP PITSS'!$B$9:F98,5,0) -> 222.72 | E32: 6300 | F32: =+E32/2 -> 3150 | G32: =+F32/15 -> 210 | I32: =15-C32 -> 0 | J32: =+I32*G32 -> 0 | L32: =+VLOOKUP(B32,'IP PITSS'!$B$9:AF99,3,0) -> 0 | M32: =+G32*L32 -> 0 | N32: =+VLOOKUP(B32,'IP PITSS'!$B$9:AG99,7,0) -> 0 | O32: =+M32-N32 -> 0 | Q32: =+VLOOKUP(B32,'IP PITSS'!$B$9:AJ99,3,0) -> 0 | R32: =+G32*Q32*30% -> 0 | S32: =+VLOOKUP(B32,'IP PITSS'!$B$9:AL99,8,0) -> 0 | T32: =+R32-S32 -> 0 | AD32: 0 | AE32: =+G32*AD32 -> 0 | AF32: =+AD32*D32 -> 0 | AG32: =+AE32-AF32 -> 0
A33: IP INNOVACION | B33: Castellon Ramos Rene | C33: =+VLOOKUP(B33,'IP PITSS'!$B$9:C99,2,0) -> 14 | D33: =+VLOOKUP(B33,'IP PITSS'!$B$9:F99,5,0) -> 265.14 | E33: 7505.99 | F33: =+E33/2 -> 3752.995 | G33: =+F33/15 -> 250.19967 | I33: 0 | J33: =+I33*G33 -> 0 | L33: =+VLOOKUP(B33,'IP PITSS'!$B$9:AF100,3,0) -> 1 | M33: =+G33*L33 -> 250.19967 | N33: =+VLOOKUP(B33,'IP PITSS'!$B$9:AG100,7,0) -> 250 | O33: =+M33-N33 -> 0.19966667 | Q33: =+VLOOKUP(B33,'IP PITSS'!$B$9:AJ100,3,0) -> 1 | R33: =+G33*Q33*30% -> 75.0599 | S33: =+VLOOKUP(B33,'IP PITSS'!$B$9:AL100,8,0) -> 75 | T33: =+R33-S33 -> 0.0599 | AD33: 0 | AE33: =+G33*AD33 -> 0 | AF33: =+AD33*D33 -> 0 | AG33: =+AE33-AF33 -> 0
A34: IP INNOVACION | B34: Castillo Nungaray Nestor Roman | C34: =+VLOOKUP(B34,'IP PITSS'!$B$9:C100,2,0) -> 15 | D34: =+VLOOKUP(B34,'IP PITSS'!$B$9:F100,5,0) -> 212.11 | E34: 6300 | F34: =+E34/2 -> 3150 | G34: =+F34/15 -> 210 | I34: =15-C34 -> 0 | J34: =+I34*G34 -> 0 | L34: =+VLOOKUP(B34,'IP PITSS'!$B$9:AF101,3,0) -> 0 | M34: =+G34*L34 -> 0 | N34: =+VLOOKUP(B34,'IP PITSS'!$B$9:AG101,7,0) -> 0 | O34: =+M34-N34 -> 0 | Q34: =+VLOOKUP(B34,'IP PITSS'!$B$9:AJ101,3,0) -> 0 | R34: =+G34*Q34*30% -> 0 | S34: =+VLOOKUP(B34,'IP PITSS'!$B$9:AL101,8,0) -> 0 | T34: =+R34-S34 -> 0 | AD34: 0 | AE34: =+G34*AD34 -> 0 | AF34: =+AD34*D34 -> 0 | AG34: =+AE34-AF34 -> 0
A35: IP INNOVACION | B35: Castillo Ramirez Hector Ivan | C35: =+VLOOKUP(B35,'IP PITSS'!$B$9:C101,2,0) -> 15 | D35: =+VLOOKUP(B35,'IP PITSS'!$B$9:F101,5,0) -> 243.88 | E35: 14000 | F35: =+E35/2 -> 7000 | G35: =+F35/15 -> 466.66667 | I35: =15-C35 -> 0 | J35: =+I35*G35 -> 0 | L35: =+VLOOKUP(B35,'IP PITSS'!$B$9:AF102,3,0) -> 0 | M35: =+G35*L35 -> 0 | N35: =+VLOOKUP(B35,'IP PITSS'!$B$9:AG102,7,0) -> 0 | O35: =+M35-N35 -> 0 | Q35: =+VLOOKUP(B35,'IP PITSS'!$B$9:AJ102,3,0) -> 0 | R35: =+G35*Q35*30% -> 0 | S35: =+VLOOKUP(B35,'IP PITSS'!$B$9:AL102,8,0) -> 0 | T35: =+R35-S35 -> 0 | AD35: 0 | AE35: =+G35*AD35 -> 0 | AF35: =+AD35*D35 -> 0 | AG35: =+AE35-AF35 -> 0
A36: IP INNOVACION | B36: Cerro Garcia Elvis | C36: =+VLOOKUP(B36,'IP PITSS'!$B$9:C102,2,0) -> 15 | D36: =+VLOOKUP(B36,'IP PITSS'!$B$9:F102,5,0) -> 177.03 | E36: 10000 | F36: =+E36/2 -> 5000 | G36: =+F36/15 -> 333.33333 | I36: =15-C36 -> 0 | J36: =+I36*G36 -> 0 | L36: =+VLOOKUP(B36,'IP PITSS'!$B$9:AF103,3,0) -> 0 | M36: =+G36*L36 -> 0 | N36: =+VLOOKUP(B36,'IP PITSS'!$B$9:AG103,7,0) -> 0 | O36: =+M36-N36 -> 0 | Q36: =+VLOOKUP(B36,'IP PITSS'!$B$9:AJ103,3,0) -> 0 | R36: =+G36*Q36*30% -> 0 | S36: =+VLOOKUP(B36,'IP PITSS'!$B$9:AL103,8,0) -> 0 | T36: =+R36-S36 -> 0 | AD36: 0 | AE36: =+G36*AD36 -> 0 | AF36: =+AD36*D36 -> 0 | AG36: =+AE36-AF36 -> 0
A37: IP INNOVACION | B37: Chavez Dominguez Salvador | C37: =+VLOOKUP(B37,'IP PITSS'!$B$9:C103,2,0) -> 15 | D37: =+VLOOKUP(B37,'IP PITSS'!$B$9:F103,5,0) -> 249.64 | E37: 12000 | F37: =+E37/2 -> 6000 | G37: =+F37/15 -> 400 | I37: =15-C37 -> 0 | J37: =+I37*G37 -> 0 | L37: =+VLOOKUP(B37,'IP PITSS'!$B$9:AF104,3,0) -> 0 | M37: =+G37*L37 -> 0 | N37: =+VLOOKUP(B37,'IP PITSS'!$B$9:AG104,7,0) -> 0 | O37: =+M37-N37 -> 0 | Q37: =+VLOOKUP(B37,'IP PITSS'!$B$9:AJ104,3,0) -> 0 | R37: =+G37*Q37*30% -> 0 | S37: =+VLOOKUP(B37,'IP PITSS'!$B$9:AL104,8,0) -> 0 | T37: =+R37-S37 -> 0 | AD37: 0 | AE37: =+G37*AD37 -> 0 | AF37: =+AD37*D37 -> 0 | AG37: =+AE37-AF37 -> 0
A38: IP INNOVACION | B38: Chavez Govea Edgar Aram | C38: =+VLOOKUP(B38,'IP PITSS'!$B$9:C104,2,0) -> 15 | D38: =+VLOOKUP(B38,'IP PITSS'!$B$9:F104,5,0) -> 247.46 | E38: 7000 | F38: =+E38/2 -> 3500 | G38: =+F38/15 -> 233.33333 | I38: =15-C38 -> 0 | J38: =+I38*G38 -> 0 | L38: =+VLOOKUP(B38,'IP PITSS'!$B$9:AF105,3,0) -> 0 | M38: =+G38*L38 -> 0 | N38: =+VLOOKUP(B38,'IP PITSS'!$B$9:AG105,7,0) -> 0 | O38: =+M38-N38 -> 0 | Q38: =+VLOOKUP(B38,'IP PITSS'!$B$9:AJ105,3,0) -> 0 | R38: =+G38*Q38*30% -> 0 | S38: =+VLOOKUP(B38,'IP PITSS'!$B$9:AL105,8,0) -> 0 | T38: =+R38-S38 -> 0 | AD38: 0 | AE38: =+G38*AD38 -> 0 | AF38: =+AD38*D38 -> 0 | AG38: =+AE38-AF38 -> 0
A39: IP INNOVACION | B39: Chavez Pedraza Samuel | C39: =+VLOOKUP(B39,'IP PITSS'!$B$9:C105,2,0) -> 15 | D39: =+VLOOKUP(B39,'IP PITSS'!$B$9:F105,5,0) -> 494.92 | E39: 14000 | F39: =+E39/2 -> 7000 | G39: =+F39/15 -> 466.66667 | I39: =15-C39 -> 0 | J39: =+I39*G39 -> 0 | L39: =+VLOOKUP(B39,'IP PITSS'!$B$9:AF106,3,0) -> 0 | M39: =+G39*L39 -> 0 | N39: =+VLOOKUP(B39,'IP PITSS'!$B$9:AG106,7,0) -> 0 | O39: =+M39-N39 -> 0 | Q39: =+VLOOKUP(B39,'IP PITSS'!$B$9:AJ106,3,0) -> 0 | R39: =+G39*Q39*30% -> 0 | S39: =+VLOOKUP(B39,'IP PITSS'!$B$9:AL106,8,0) -> 0 | T39: =+R39-S39 -> 0 | AD39: 0 | AE39: =+G39*AD39 -> 0 | AF39: =+AD39*D39 -> 0 | AG39: =+AE39-AF39 -> 0
A40: IP INNOVACION | B40: Chavez Saucedo Jorge Arturo | C40: =+VLOOKUP(B40,'IP PITSS'!$B$9:C106,2,0) -> 15 | D40: =+VLOOKUP(B40,'IP PITSS'!$B$9:F106,5,0) -> 278.72 | E40: 8000 | F40: =+E40/2 -> 4000 | G40: =+F40/15 -> 266.66667 | I40: =15-C40 -> 0 | J40: =+I40*G40 -> 0 | L40: =+VLOOKUP(B40,'IP PITSS'!$B$9:AF107,3,0) -> 0 | M40: =+G40*L40 -> 0 | N40: =+VLOOKUP(B40,'IP PITSS'!$B$9:AG107,7,0) -> 0 | O40: =+M40-N40 -> 0 | Q40: =+VLOOKUP(B40,'IP PITSS'!$B$9:AJ107,3,0) -> 0 | R40: =+G40*Q40*30% -> 0 | S40: =+VLOOKUP(B40,'IP PITSS'!$B$9:AL107,8,0) -> 0 | T40: =+R40-S40 -> 0 | AD40: 0 | AE40: =+G40*AD40 -> 0 | AF40: =+AD40*D40 -> 0 | AG40: =+AE40-AF40 -> 0
A41: IP INNOVACION | B41: Chavira Garcia David Fernando | C41: =+VLOOKUP(B41,'IP PITSS'!$B$9:C107,2,0) -> 15 | D41: =+VLOOKUP(B41,'IP PITSS'!$B$9:F107,5,0) -> 353.52 | E41: 10000 | F41: =+E41/2 -> 5000 | G41: =+F41/15 -> 333.33333 | I41: =15-C41 -> 0 | J41: =+I41*G41 -> 0 | L41: =+VLOOKUP(B41,'IP PITSS'!$B$9:AF108,3,0) -> 0 | M41: =+G41*L41 -> 0 | N41: =+VLOOKUP(B41,'IP PITSS'!$B$9:AG108,7,0) -> 0 | O41: =+M41-N41 -> 0 | Q41: =+VLOOKUP(B41,'IP PITSS'!$B$9:AJ108,3,0) -> 0 | R41: =+G41*Q41*30% -> 0 | S41: =+VLOOKUP(B41,'IP PITSS'!$B$9:AL108,8,0) -> 0 | T41: =+R41-S41 -> 0 | AD41: 0 | AE41: =+G41*AD41 -> 0 | AF41: =+AD41*D41 -> 0 | AG41: =+AE41-AF41 -> 0
A42: IP INNOVACION | B42: Cota Jaramillo Miguel Angel | C42: =+VLOOKUP(B42,'IP PITSS'!$B$9:C108,2,0) -> 15 | D42: =+VLOOKUP(B42,'IP PITSS'!$B$9:F108,5,0) -> 209.04 | E42: 6000 | F42: =+E42/2 -> 3000 | G42: =+F42/15 -> 200 | I42: =15-C42 -> 0 | J42: =+I42*G42 -> 0 | L42: =+VLOOKUP(B42,'IP PITSS'!$B$9:AF109,3,0) -> 0 | M42: =+G42*L42 -> 0 | N42: =+VLOOKUP(B42,'IP PITSS'!$B$9:AG109,7,0) -> 0 | O42: =+M42-N42 -> 0 | Q42: =+VLOOKUP(B42,'IP PITSS'!$B$9:AJ109,3,0) -> 0 | R42: =+G42*Q42*30% -> 0 | S42: =+VLOOKUP(B42,'IP PITSS'!$B$9:AL109,8,0) -> 0 | T42: =+R42-S42 -> 0 | AD42: 0 | AE42: =+G42*AD42 -> 0 | AF42: =+AD42*D42 -> 0 | AG42: =+AE42-AF42 -> 0
A43: IP INNOVACION | B43: Courtenay Gutierrez Barry Vladimir | C43: =+VLOOKUP(B43,'IP PITSS'!$B$9:C109,2,0) -> 15 | D43: =+VLOOKUP(B43,'IP PITSS'!$B$9:F109,5,0) -> 174.2 | E43: 5000 | F43: =+E43/2 -> 2500 | G43: =+F43/15 -> 166.66667 | I43: =15-C43 -> 0 | J43: =+I43*G43 -> 0 | L43: =+VLOOKUP(B43,'IP PITSS'!$B$9:AF110,3,0) -> 0 | M43: =+G43*L43 -> 0 | N43: =+VLOOKUP(B43,'IP PITSS'!$B$9:AG110,7,0) -> 0 | O43: =+M43-N43 -> 0 | Q43: =+VLOOKUP(B43,'IP PITSS'!$B$9:AJ110,3,0) -> 0 | R43: =+G43*Q43*30% -> 0 | S43: =+VLOOKUP(B43,'IP PITSS'!$B$9:AL110,8,0) -> 0 | T43: =+R43-S43 -> 0 | AD43: 0 | AE43: =+G43*AD43 -> 0 | AF43: =+AD43*D43 -> 0 | AG43: =+AE43-AF43 -> 0
A44: IP INNOVACION | B44: Cruz Herrera Roberto | C44: =+VLOOKUP(B44,'IP PITSS'!$B$9:C110,2,0) -> 15 | D44: =+VLOOKUP(B44,'IP PITSS'!$B$9:F110,5,0) -> 249.64 | E44: 10000 | F44: =+E44/2 -> 5000 | G44: =+F44/15 -> 333.33333 | I44: =15-C44 -> 0 | J44: =+I44*G44 -> 0 | L44: =+VLOOKUP(B44,'IP PITSS'!$B$9:AF111,3,0) -> 0 | M44: =+G44*L44 -> 0 | N44: =+VLOOKUP(B44,'IP PITSS'!$B$9:AG111,7,0) -> 0 | O44: =+M44-N44 -> 0 | Q44: =+VLOOKUP(B44,'IP PITSS'!$B$9:AJ111,3,0) -> 0 | R44: =+G44*Q44*30% -> 0 | S44: =+VLOOKUP(B44,'IP PITSS'!$B$9:AL111,8,0) -> 0 | T44: =+R44-S44 -> 0 | AD44: 0 | AE44: =+G44*AD44 -> 0 | AF44: =+AD44*D44 -> 0 | AG44: =+AE44-AF44 -> 0
A45: IP INNOVACION | B45: Cruz Perez Alejandro Nezahualcoyotl | C45: =+VLOOKUP(B45,'IP PITSS'!$B$9:C111,2,0) -> 15 | D45: =+VLOOKUP(B45,'IP PITSS'!$B$9:F111,5,0) -> 282.81 | E45: 8000 | F45: =+E45/2 -> 4000 | G45: =+F45/15 -> 266.66667 | I45: =15-C45 -> 0 | J45: =+I45*G45 -> 0 | L45: =+VLOOKUP(B45,'IP PITSS'!$B$9:AF112,3,0) -> 0 | M45: =+G45*L45 -> 0 | N45: =+VLOOKUP(B45,'IP PITSS'!$B$9:AG112,7,0) -> 0 | O45: =+M45-N45 -> 0 | Q45: =+VLOOKUP(B45,'IP PITSS'!$B$9:AJ112,3,0) -> 0 | R45: =+G45*Q45*30% -> 0 | S45: =+VLOOKUP(B45,'IP PITSS'!$B$9:AL112,8,0) -> 0 | T45: =+R45-S45 -> 0 | AD45: 0 | AE45: =+G45*AD45 -> 0 | AF45: =+AD45*D45 -> 0 | AG45: =+AE45-AF45 -> 0
... A70: IP INNOVACION | B70: Martinez Morales Jose Martin | C70: =+VLOOKUP(B70,'IP PITSS'!$B$9:C136,2,0) -> 15 | D70: =+VLOOKUP(B70,'IP PITSS'!$B$9:F136,5,0) -> 494.92 | E70: 14000 | F70: =+E70/2 -> 7000 | G70: =+F70/15 -> 466.66667 | I70: =15-C70 -> 0 | J70: =+I70*G70 -> 0 | L70: =+VLOOKUP(B70,'IP PITSS'!$B$9:AF137,3,0) -> 0 | M70: =+G70*L70 -> 0 | N70: =+VLOOKUP(B70,'IP PITSS'!$B$9:AG137,7,0) -> 0 | O70: =+M70-N70 -> 0 | Q70: =+VLOOKUP(B70,'IP PITSS'!$B$9:AJ137,3,0) -> 0 | R70: =+G70*Q70*30% -> 0 | S70: =+VLOOKUP(B70,'IP PITSS'!$B$9:AL137,8,0) -> 0 | T70: =+R70-S70 -> 0 | AD70: 0 | AE70: =+G70*AD70 -> 0 | AF70: =+AD70*D70 -> 0 | AG70: =+AE70-AF70 -> 0
...

Sheet RESUMEN PITS
B2: RESUMEN
B3: Lista de Raya (forma tabular)
F7: SINDICATO
A8: CLAVE | B8: EMPRESA | C8: NOMBRE | D8: NETO IMSS | F8: SUELDO SINDICATO | G8: BONO | H8: COMISION | I8: PRIMA VACACIONAL SINDICATO | J8: B | K8: NETO A PAGAR | L8: NETO MENSUAL | M8: NETO QUINCENAL SEITON | N8: C | O8: prima vacacional | P8: COMISION Y PRIMA VACACIONAL | Q8: INFONAVIT | R8: FONACOT | S8: FALTAS | T8: DESCUENTOS | U8: D | V8: TOTAL GENERAL | W8: DIFERENCIAS | X8: OBSERVACIONES
A9: SEI0009 | B9: CONSULTORIA | C9: Gutierrez Gutierrez Luis Arturo | D9: =+VLOOKUP(C9,'CPD PITSS'!$B$9:V27,21,0) -> 2774.6 | F9: =VLOOKUP(C9,'SIND PITS'!$C$9:$H$113,2,0) -> 1475.4 | G9: =VLOOKUP(C9,'SIND PITS'!$C$9:$E$113,3,0) -> 0 | H9: =VLOOKUP(C9,'SIND PITS'!$C$9:$F$113,4,0) -> 0 | I9: =VLOOKUP(C9,'SIND PITS'!$C$9:$G$113,5,0) -> 0 | K9: =SUM(D9:I9) -> 4250 | L9: 8500 | M9: =+L9/2 -> 4250 | O9: =+VLOOKUP(C9,'CPD PITSS'!$B$9:I27,8,0) -> 0 | P9: =+G9+H9+I9 -> 0 | Q9: =(VLOOKUP($C9,'CPD PITSS'!$B$9:V26,13,0))+(VLOOKUP($C9,'CPD PITSS'!$B$9:V26,14,0)) -> 0 | R9: 0 | S9: =+VLOOKUP(C9,'EXTRAS Y FESTIVOS'!$B$9:J111,9,0) -> 0 | T9: =VLOOKUP(C9,'CPD PITSS'!$B$9:S26,18,0) -> 0 | V9: =+K9-O9-P9+Q9+R9+T9+S9+IFERROR(VLOOKUP('RESUMEN PITS'!C9,'IP PITSS'!$B$9:$M$93,10),0)+IFERROR(VLOOKUP('RESUMEN PITS'!C9,'IP PITSS'!$B$9:$M$93,11),0)+IFERROR(VLOOKUP('RESUMEN PITS'!C9,'IP PITSS'!$B$9:$M$93,12),0)+VLOOKUP("Comision",'IP PITSS'!$I$99:$J$110,2)/COUNT($F$9:$F$111)+IFERROR(VLOOKUP('RESUMEN PITS'!C9,'IP PITSS'!$B$9:$AD$93,15),0)+IFERROR(VLOOKUP('RESUMEN PITS'!C9,'IP PITSS'!$B$9:$AD$93,21),0)+IFERROR(VLOOKUP('RESUMEN PITS'!C9,'IP PITSS'!$B$9:$AD$93,22),0)+IFERROR(VLOOKUP('RESUMEN PITS'!C9,'IP PITSS'!$B$9:$AD$93,23),0)+IFERROR(VLOOKUP('RESUMEN PITS'!C9,'IP PITSS'!$B$9:$AD$93,24),0)+IFERROR(VLOOKUP('RESUMEN PITS'!C9,'IP PITSS'!$B$9:$AD$93,26),0)+IFERROR(VLOOKUP('RESUMEN PITS'!C9,'IP PITSS'!$B$9:$AD$93,28),0)+IFERROR(VLOOKUP('RESUMEN PITS'!C9,'IP PITSS'!$B$9:$AD$93,29),0)+IFERROR(VLOOKUP('RESUMEN PITS'!C9,'IP PITSS'!$B$9:$AD$93,9),0)*2% -> 5664.5349 | W9: =+M9-V9-S9 -> -1414.5349 | Y9: SEI0009 | Z9: =SUM(V9:V111) -> 631029.97
A10: SEI0026 | B10: CONSULTORIA | C10: Patricio Aguilar Jhonattan Cristian | D10: =+VLOOKUP(C10,'CPD PITSS'!$B$9:V28,21,0) -> 2912 | F10: =VLOOKUP(C10,'SIND PITS'!$C$9:$H$113,2,0) -> 1588 | G10: =VLOOKUP(C10,'SIND PITS'!$C$9:$E$113,3,0) -> 400 | H10: =VLOOKUP(C10,'SIND PITS'!$C$9:$F$113,4,0) -> 0 | I10: =VLOOKUP(C10,'SIND PITS'!$C$9:$G$113,5,0) -> 0 | K10: =SUM(D10:I10) -> 4900 | L10: 9000 | M10: =+L10/2 -> 4500 | O10: =+VLOOKUP(C10,'CPD PITSS'!$B$9:I28,8,0) -> 0 | P10: =+G10+H10+I10 -> 400 | Q10: =(VLOOKUP($C10,'CPD PITSS'!$B$9:V27,13,0))+(VLOOKUP($C10,'CPD PITSS'!$B$9:V27,14,0)) -> 0 | R10: 0 | S10: =+VLOOKUP(C10,'EXTRAS Y FESTIVOS'!$B$9:J112,9,0) -> 0 | T10: =VLOOKUP(C10,'CPD PITSS'!$B$9:S27,18,0) -> 0 | V10: =+K10-O10-P10+Q10+R10+T10+S10+IFERROR(VLOOKUP('RESUMEN PITS'!C10,'IP PITSS'!$B$9:$M$93,10),0)+IFERROR(VLOOKUP('RESUMEN PITS'!C10,'IP PITSS'!$B$9:$M$93,11),0)+IFERROR(VLOOKUP('RESUMEN PITS'!C10,'IP PITSS'!$B$9:$M$93,12),0)+VLOOKUP("Comision",'IP PITSS'!$I$99:$J$110,2)/COUNT($F$9:$F$111)+IFERROR(VLOOKUP('RESUMEN PITS'!C10,'IP PITSS'!$B$9:$AD$93,15),0)+IFERROR(VLOOKUP('RESUMEN PITS'!C10,'IP PITSS'!$B$9:$AD$93,21),0)+IFERROR(VLOOKUP('RESUMEN PITS'!C10,'IP PITSS'!$B$9:$AD$93,22),0)+IFERROR(VLOOKUP('RESUMEN PITS'!C10,'IP PITSS'!$B$9:$AD$93,23),0)+IFERROR(VLOOKUP('RESUMEN PITS'!C10,'IP PITSS'!$B$9:$AD$93,24),0)+IFERROR(VLOOKUP('RESUMEN PITS'!C10,'IP PITSS'!$B$9:$AD$93,26),0)+IFERROR(VLOOKUP('RESUMEN PITS'!C10,'IP PITSS'!$B$9:$AD$93,28),0)+IFERROR(VLOOKUP('RESUMEN PITS'!C10,'IP PITSS'!$B$9:$AD$93,29),0)+IFERROR(VLOOKUP('RESUMEN PITS'!C10,'IP PITSS'!$B$9:$AD$93,9),0)*2% -> 5842.3659 | W10: =+M10-V10-S10 -> -1342.3659 | Y10: SEI0026
