Workbook

Sheet FACTURACION SINDICATO
B2: codigo | C2: empres | D2: nombre | E2: PAGO POR SINDICATO | F2: comision y bono | G2: prima vacaciones | H2: TOTAL | I2: CC
B3: SEI0097 | C3: SEITON - (CONSULTORIA II) | D3: Arreola Jimenez Jose Nieves | E3: 1558.05 | F3: 2975 | G3: 0 | H3: 4533.05 | I3: AA
B4: SEI0118 | C4: SEITON - (CONSULTORIA II) | D4: Arroyo Ramirez Hector Hugo | E4: 2103.54 | G4: 234 | H4: 2337.54 | I4: AA
B5: SEI0108 | C5: SEITON - (CONSULTORIA II) | D5: Caballero Diaz Francisco Javier | E5: 1558.01 | G5: 0 | H5: 1558.01 | I5: AA
B6: SEI0425 | C6: SEITON - (CONSULTORIA II) | D6: Carbajal Cabuto Jose Luis | E6: 1608.07 | G6: 0 | H6: 1608.07 | I6: AA
B7: SEI0116 | C7: SEITON - (CONSULTORIA II) | D7: Casillas Cardona Cesar Alejandro | E7: 1891.22 | G7: 0 | H7: 1891.22 | I7: AA
B8: SEI0401 | C8: SEITON - (CONSULTORIA II) | D8: De La Torre Zambara Francisco Ernesto | E8: 78.08 | G8: 0 | H8: 78.08 | I8: AA
B9: SEI0119 | C9: SEITON - (CONSULTORIA II) | D9: Dominguez Lopez Maria De Jesus | E9: 0 | G9: 0 | H9: 0 | I9: AA
B10: SEI0099 | C10: SEITON - (CONSULTORIA II) | D10: Garcia Villicaña Ricardo Pascual | E10: 2600.8 | F10: 600 | G10: 0 | H10: 3200.8 | I10: AA
B11: SEI0009 | C11: SEITON - (CONSULTORIA II) | D11: Gutierrez Gutierrez Luis Arturo | E11: 1474.6 | G11: 0 | H11: 1474.6 | I11: AA
B12: SEI0127 | C12: SEITON - (CONSULTORIA II) | D12: Hernandez Ochoa Eduardo | E12: 2601 | G12: 0 | H12: 2601 | I12: AA
B13: SEI0088 | C13: SEITON - (CONSULTORIA II) | D13: Morgado Fernandez Martin | E13: 2601 | F13: 1125 | G13: 0 | H13: 3726 | I13: AA
B14: SEI0173 | C14: SEITON - (CONSULTORIA II) | D14: Nieto Ortiz Jose Luis | E14: 1483.15 | F14: 1232 | G14: 0 | H14: 2715.15 | I14: AA
B15: SEI0026 | C15: SEITON - (CONSULTORIA II) | D15: Patricio Aguilar Jhonattan Cristian | E15: 1588 | G15: 0 | H15: 1588 | I15: AA
B16: SEI0027 | C16: SEITON - (CONSULTORIA II) | D16: Tavares Guzman Jose Enrique | E16: 2378.2 | G16: 0 | H16: 2378.2 | I16: AA
B17: SEI032 | C17: SEITON - (CONSULTORIA II) | D17: Camarena Quiroz Erick Frank | E17: 1588 | F17: 225 | G17: 0 | H17: 1813 | I17: AA
B18: SEI0438 | C18: SEITON - (CONSULTORIA II) | D18: Valdes Arrioja Karla Naborina | E18: 1803.2 | H18: 1803.2 | I18: AA
B19: SEI0482 | C19: SEITON (IP INNOVA II) | D19: Camarillo Canela Reynaldo | E19: 2236.64 | F19: 2150 | G19: 0 | H19: 4386.64 | I19: AA
B20: SEI0485 | C20: SEITON (IP INNOVA II) | D20: Molina Ramirez Gerardo Daniel | E20: 2271.77 | G20: 0 | H20: 2271.77 | I20: AA
B21: SEI0488 | C21: SEITON (IP INNOVA II) | D21: Mireles Casillas Brenda Cristina | E21: 2257 | G21: 0 | H21: 2257 | I21: AA
B22: SEI0489 | C22: SEITON (IP INNOVA II) | D22: Escobedo Olivares Juan Guadalupe | E22: 3723.8 | G22: 0 | H22: 3723.8 | I22: AA
B23: SEI0490 | C23: SEITON (IP INNOVA II) | D23: Castillo Ramirez Hector Ivan | E23: 3753.78 | F23: 1280 | G23: 0 | H23: 5033.78 | I23: AA
B24: SEI0492 | C24: SEITON (IP INNOVA II) | D24: Cadena Ramirez Hugo | E24: 2513.4 | G24: 0 | H24: 2513.4 | I24: AA
B25: SEI0493 | C25: SEITON (IP INNOVA II) | D25: Martinez Morales Tomas | E25: 3397.14 | F25: 1320 | G25: 0 | H25: 4717.14 | I25: AA
B26: SEI0494 | C26: SEITON (IP INNOVA II) | D26: Medellin Colunga Ruben Dario | E26: 4412.14 | F26: 2320 | G26: 0 | H26: 6732.14 | I26: AA
B27: SEI0495 | C27: SEITON (IP INNOVA II) | D27: Torres Perez Carlos Alberto | E27: 1685.3 | F27: 4495 | G27: 0 | H27: 6180.3 | I27: AA
B28: SEI0496 | C28: SEITON (IP INNOVA II) | D28: Velazquez Herrera Nayeli | E28: 3382.26 | F28: 950 | G28: 56.14 | H28: 4388.4 | I28: AA
B29: SEI0497 | C29: SEITON (IP INNOVA II) | D29: Treviño Alvarez Jorge Alberto | E29: 2700.29 | F29: 680 | G29: 0 | H29: 3380.29 | I29: AA
B30: SEI0498 | C30: SEITON (IP INNOVA II) | D30: Tenorio Alvarez Alberto Antonio | E30: 1685.2 | G30: 0 | H30: 1685.2 | I30: AA
B31: SEI0499 | C31: SEITON (IP INNOVA II) | D31: Chavez Dominguez Salvador | E31: 2685.2 | G31: 0 | H31: 2685.2 | I31: AA
B32: SEI0500 | C32: SEITON (IP INNOVA II) | D32: Garcia Gutierrez Jose Juan | E32: 1685.2 | G32: 0 | H32: 1685.2 | I32: AA
B33: SEI0501 | C33: SEITON (IP INNOVA II) | D33: Cruz Herrera Roberto | E33: 1670.2 | G33: 0 | H33: 1670.2 | I33: AA
B34: SEI0502 | C34: SEITON (IP INNOVA II) | D34: Dominguez Escamilla Victor Hugo | E34: 2700.14 | G34: 0 | H34: 2700.14 | I34: AA
B35: SEI0503 | C35: SEITON (IP INNOVA II) | D35: Martinez Rodriguez Paulo Cesar | E35: 2554.8 | G35: 0 | H35: 2554.8 | I35: AA
B36: SEI0504 | C36: SEITON (IP INNOVA II) | D36: Martinez Malo Cesar | E36: 1711.46 | G36: 0 | H36: 1711.46 | I36: AA
B37: SEI0505 | C37: SEITON (IP INNOVA II) | D37: Perez Balboa Cesar | E37: 2211.65 | G37: 0 | H37: 2211.65 | I37: AA
B38: SEI0506 | C38: SEITON (IP INNOVA II) | D38: Mejia Duarte Jose Luis | E38: 2570.57 | G38: 0 | H38: 2570.57 | I38: AA
B39: SEI0507 | C39: SEITON (IP INNOVA II) | D39: Diaz Saldierna Leonel Gonzalo | E39: 2585.53 | G39: 0 | H39: 2585.53 | I39: AA
B40: SEI0508 | C40: SEITON (IP INNOVA II) | D40: Cerro Garcia Elvis | E40: 2570.6 | F40: 2125 | G40: 0 | H40: 4695.6 | I40: AA
B41: SEI0078 | C41: SEITON (IP INNOVA II) | D41: Aguilar Leal Karina Livier | E41: 952.25 | F41: 16065.1 | G41: 10 | H41: 17027.35 | I41: AA
...

Sheet CPD
B2: CONSULTORIA EN PROYECTOS DINAMICOS S DE RL DE CV
B3: Lista de Raya (forma tabular)
B4: Reg Pat IMSS: Z2940859106
B5: RFC: CPD -150911-FA3
A8: Código | B8: Empleado | C8: Dias Laborados | D8: Dias Vacaciones | E8: Salario Diario | F8: Salario Diario Integrado | G8: Sueldo | H8: Vacaciones a tiempo | I8: Prima de vacaciones a tiempo | J8: Ayuda de Transporte | K8: Ayuda Alimentaria | L8: Ayuda de Renta | M8: *TOTAL* *PERCEPCIONES* | N8: I.S.R. (sp) | O8: Subsidio al Empleo (sp) | P8: I.M.S.S. | Q8: Préstamo Infonavit | R8: Préstamo Infonavit (vsm) | S8: Préstamo Infonavit (cf) | T8: Seguro de vivienda Infonavit | U8: Prestamo Empresa | V8: Deduccion general | W8: Ajuste al neto | X8: *TOTAL* *DEDUCCIONES* | Y8: *NETO* | Z8: Ret. Inv. Y Vida | AA8: Ret. Cesantia | AB8: Ret. Enf. y Mat. obrero | AC8: Subs al Empleo acreditado | AD8: I.S.R. antes de Subs al Empleo | AE8: isr 2 | AF8: Invalidez y Vida | AG8: Cesantia y Vejez | AH8: Enf. y Mat. Patron | AI8: Total Percepciones | AJ8: 2% Fondo retiro SAR (8) | AK8: 2% Impuesto estatal | AL8: Riesgo de trabajo (9) | AM8: I.M.S.S. empresa | AN8: Infonavit empresa | AO8: Guarderia I.M.S.S. (7) | AP8: Proporcion Aguinaldo | AQ8: FACTURACION
A9: SEI0009 | B9: Gutierrez Gutierrez Luis Arturo | C9: 15 | D9: 0 | E9: 141.67 | F9: 150.25 | G9: 2125.05 | H9: 0 | I9: 0 | J9: 212.51 | K9: 212.51 | L9: 212.51 | M9: 2762.58 | N9: 0 | O9: -65.5 | P9: 53.52 | Q9: 0 | R9: 0 | V9: 0 | W9: 0.16 | X9: -11.82 | Y9: 2774.4 | Z9: 14.09 | AA9: 25.35 | AB9: 14.08 | AC9: -188.71 | AD9: 123.22 | AF9: 39.44 | AG9: 70.99 | AH9: 297.98 | AI9: 2762.58 | AJ9: 240.44 | AK9: 55.25 | AL9: 12.91 | AM9: 408.41 | AN9: 112.69 | AO9: 217.9 | AP9: 151.27396 | AQ9: PITSS
A10: SEI0010 | B10: Compean Tobias Braulio Gerardo | C10: 15 | D10: 0 | E10: 300 | F10: 313.56 | G10: 4500 | H10: 0 | I10: 0 | J10: 450 | K10: 450 | L10: 450 | M10: 5850 | N10: 380.67 | O10: 0 | P10: 115.32 | Q10: 0 | R10: 1320.68 | V10: 0 | W10: -0.07 | X10: 1816.6 | Y10: 4033.4 | Z10: 29.4 | AA10: 52.91 | AB10: 33.01 | AC10: 0 | AD10: 380.67 | AF10: 82.31 | AG10: 148.16 | AH10: 350.77 | AI10: 5850 | AJ10: 289.43 | AK10: 117 | AL10: 26.95 | AM10: 581.24 | AN10: 235.17 | AO10: 242.39 | AP10: 320.33731 | AQ10: SEITON
A11: SEI0026 | B11: Patricio Aguilar Jhonattan Cristian | C11: 15 | D11: 0 | E11: 150 | F11: 159.07 | G11: 2250 | H11: 0 | I11: 0 | J11: 225 | K11: 225 | L11: 225 | M11: 2925 | N11: 0 | O11: -43.57 | P11: 56.67 | Q11: 0 | R11: 0 | V11: 0 | W11: 0.1 | X11: 13.2 | Y11: 2911.8 | Z11: 14.91 | AA11: 26.84 | AB11: 14.92 | AC11: -174.78 | AD11: 131.21 | AF11: 41.76 | AG11: 75.16 | AH11: 300.29 | AI11: 2925 | AJ11: 243.08 | AK11: 58.5 | AL11: 13.67 | AM11: 417.21 | AN11: 119.31 | AO11: 219.22 | AP11: 160.16866 | AQ11: PITSS
A12: SEI0039 | B12: Benavides Herrera Pablo | C12: 15 | D12: 0 | E12: 666.67 | F12: 696.81 | G12: 10000.05 | H12: 0 | I12: 0 | J12: 1000 | K12: 1000 | L12: 1000 | M12: 13000.05 | N12: 1497.79 | O12: 0 | P12: 274.85 | Q12: 0 | R12: 0 | V12: 0 | W12: 0.01 | X12: 1772.65 | Y12: 11227.4 | Z12: 65.33 | AA12: 117.59 | AB12: 91.93 | AC12: 0 | AD12: 1497.79 | AF12: 182.91 | AG12: 329.24 | AH12: 514.6 | AI12: 13000.05 | AJ12: 404.4 | AK12: 260 | AL12: 59.88 | AM12: 1026.75 | AN12: 522.61 | AO12: 299.88 | AP12: 711.86425 | AQ12: PITSS
A13: SEI0040 | B13: Mora Ramirez Acal Aldo Isidro | C13: 15 | D13: 0 | E13: 216.67 | F13: 229.79 | G13: 3250.05 | H13: 0 | I13: 0 | J13: 325.01 | K13: 325.01 | L13: 325.01 | M13: 4225.08 | N13: 107.17 | O13: 0 | P13: 81.87 | Q13: 0 | R13: 0 | V13: 0 | W13: 0.04 | X13: 189.08 | Y13: 4036 | Z13: 21.54 | AA13: 38.78 | AB13: 21.55 | AC13: -125.1 | AD13: 232.27 | AF13: 60.32 | AG13: 108.58 | AH13: 318.86 | AI13: 4225.08 | AJ13: 264.3 | AK13: 84.5 | AL13: 19.75 | AM13: 487.76 | AN13: 172.34 | AO13: 229.83 | AP13: 231.35828 | AQ13: PITSS
A14: SEI0041 | B14: Vazquez Perez Miguel Angel | C14: 15 | D14: 0 | E14: 283.33 | F14: 300.49 | G14: 4249.95 | H14: 0 | I14: 0 | J14: 425 | K14: 425 | L14: 425 | M14: 5524.95 | N14: 341.06 | O14: 0 | P14: 109.87 | Q14: 0 | R14: 0 | V14: 0 | W14: 0.02 | X14: 450.95 | Y14: 5074 | Z14: 28.17 | AA14: 50.71 | AB14: 30.99 | AC14: 0 | AD14: 341.06 | AF14: 78.88 | AG14: 141.98 | AH14: 345.18 | AI14: 5524.95 | AJ14: 285.51 | AK14: 110.5 | AL14: 25.82 | AM14: 566.04 | AN14: 225.37 | AO14: 240.43 | AP14: 302.53724 | AQ14: PITSS
A15: SEI0088 | B15: Morgado Fernandez Martin | C15: 15 | D15: 0 | E15: 273.33 | F15: 289.87 | G15: 4099.95 | H15: 0 | I15: 0 | J15: 410 | K15: 410 | L15: 410 | M15: 5329.95 | N15: 324.74 | O15: 0 | P15: 105.46 | Q15: 0 | R15: 0 | V15: 0 | W15: 0.15 | X15: 430.35 | Y15: 4899.6 | Z15: 27.18 | AA15: 48.92 | AB15: 29.36 | AC15: 0 | AD15: 324.74 | AF15: 76.09 | AG15: 136.96 | AH15: 340.64 | AI15: 5329.95 | AJ15: 282.32 | AK15: 106.6 | AL15: 24.91 | AM15: 553.69 | AN15: 217.4 | AO15: 238.84 | AP15: 291.85933 | AQ15: PITSS
A16: SEI0097 | B16: Arreola Jimenez Jose Nieves | C16: 15 | D16: 0 | E16: 185.83 | F16: 197.07 | G16: 2787.45 | H16: 0 | I16: 0 | J16: 278.75 | K16: 278.75 | L16: 278.75 | M16: 3623.7 | N16: 36.57 | O16: 0 | P16: 70.22 | Q16: 0 | R16: 1559.39 | V16: 224.7 | W16: -0.18 | X16: 1890.7 | Y16: 1733 | Z16: 18.48 | AA16: 33.26 | AB16: 18.48 | AC16: -145.38 | AD16: 181.94 | AF16: 51.73 | AG16: 93.12 | AH16: 310.27 | AI16: 3623.7 | AJ16: 254.48 | AK16: 72.47 | AL16: 16.94 | AM16: 455.12 | AN16: 147.8 | AO16: 224.92 | AP16: 198.42761 | AQ16: PITSS
A17: SEI0099 | B17: Garcia Villicaña Ricardo Pascual | C17: 14 | D17: 1 | E17: 273.33 | F17: 289.87 | G17: 3826.62 | H17: 273.33 | I17: 82 | J17: 410 | K17: 410 | L17: 410 | M17: 5411.95 | N17: 324.74 | O17: 0 | P17: 105.46 | Q17: 0 | R17: 0 | V17: 0 | W17: 0.15 | X17: 430.35 | Y17: 4981.6 | Z17: 27.18 | AA17: 48.92 | AB17: 29.36 | AC17: 0 | AD17: 324.74 | AF17: 76.09 | AG17: 136.96 | AH17: 340.64 | AI17: 5411.95 | AJ17: 282.32 | AK17: 108.24 | AL17: 24.91 | AM17: 553.69 | AN17: 217.4 | AO17: 238.84 | AP17: 291.85933 | AQ17: PITSS
A18: SEI0108 | B18: Caballero Diaz Francisco Javier | C18: 15 | D18: 0 | E18: 185.83 | F18: 197.07 | G18: 2787.45 | H18: 0 | I18: 0 | J18: 278.75 | K18: 278.75 | L18: 278.75 | M18: 3623.7 | N18: 36.57 | O18: 0 | P18: 70.22 | Q18: 0 | R18: 1809.82 | V18: 0 | W18: 0.09 | X18: 1916.7 | Y18: 1707 | Z18: 18.48 | AA18: 33.26 | AB18: 18.48 | AC18: -145.38 | AD18: 181.94 | AF18: 51.73 | AG18: 93.12 | AH18: 310.27 | AI18: 3623.7 | AJ18: 254.48 | AK18: 72.47 | AL18: 16.94 | AM18: 455.12 | AN18: 147.8 | AO18: 224.92 | AP18: 198.42761 | AQ18: PITSS
A19: SEI0116 | B19: Casillas Cardona Cesar Alejandro | C19: 15 | D19: 0 | E19: 220.83 | F19: 234.19 | G19: 3312.45 | H19: 0 | I19: 0 | J19: 331.25 | K19: 331.25 | L19: 331.25 | M19: 4306.2 | N19: 113.96 | O19: 0 | P19: 83.43 | Q19: 0 | R19: 1045.17 | V19: 0 | W19: -0.16 | X19: 1242.4 | Y19: 3063.8 | Z19: 21.96 | AA19: 39.52 | AB19: 21.95 | AC19: -125.1 | AD19: 239.06 | AF19: 61.47 | AG19: 110.65 | AH19: 320.01 | AI19: 4306.2 | AJ19: 265.62 | AK19: 86.12 | AL19: 20.13 | AM19: 492.13 | AN19: 175.64 | AO19: 230.49 | AP19: 235.8003 | AQ19: PITSS
A20: SEI0117 | B20: Mariscal Romero Luis Adrian | C20: 15 | D20: 0 | E20: 264.58 | F20: 276.54 | G20: 3968.7 | H20: 0 | I20: 0 | J20: 396.87 | K20: 396.87 | L20: 396.87 | M20: 5159.31 | N20: 310.46 | O20: 0 | P20: 99.91 | Q20: 0 | R20: 1658.56 | V20: 396 | W20: -0.02 | X20: 2464.91 | Y20: 2694.4 | Z20: 25.93 | AA20: 46.67 | AB20: 27.31 | AC20: 0 | AD20: 310.46 | AF20: 72.59 | AG20: 130.66 | AH20: 334.94 | AI20: 5159.31 | AJ20: 278.32 | AK20: 103.19 | AL20: 23.76 | AM20: 538.19 | AN20: 207.4 | AO20: 236.84 | AP20: 282.51615 | AQ20: PITSS
... A37: SEI0448 | B37: Rodriguez Chavez Oswaldo Emmanuel | C37: 15 | D37: 0 | E37: 233.33 | F37: 247.46 | G37: 3499.95 | H37: 0 | I37: 0 | J37: 350 | K37: 350 | L37: 350 | M37: 4549.95 | N37: 134.36 | O37: 0 | P37: 88.16 | Q37: 0 | R37: 0 | V37: 0 | W37: 0.03 | X37: 222.55 | Y37: 4327.4 | Z37: 23.2 | AA37: 41.76 | AB37: 23.2 | AC37: -125.1 | AD37: 259.46 | AF37: 64.96 | AG37: 116.92 | AH37: 323.5 | AI37: 4549.95 | AJ37: 269.6 | AK37: 91 | AL37: 21.27 | AM37: 505.38 | AN37: 185.6 | AO37: 232.48 | AP37: 249.14768 | AQ37: SEITON
A38: Total Depto | C38: ----------------------- | D38: ----------------------- | E38: ----------------------- | F38: ----------------------- | G38: ----------------------- | H38: ----------------------- | I38: ----------------------- | J38: ----------------------- | K38: ----------------------- | L38: ----------------------- | M38: ----------------------- | N38: ----------------------- | O38: ----------------------- | P38: ----------------------- | Q38: ----------------------- | R38: ----------------------- | S38: ----------------------- | T38: ----------------------- | U38: ----------------------- | V38: ----------------------- | W38: ----------------------- | X38: ----------------------- | Y38: ----------------------- | Z38: ----------------------- | AA38: ----------------------- | AB38: ----------------------- | AC38: ----------------------- | AD38: ----------------------- | AF38: ----------------------- | AG38: ----------------------- | AH38: ----------------------- | AI38: ----------------------- | AJ38: ----------------------- | AK38: ----------------------- | AL38: ----------------------- | AM38: ----------------------- | AN38: ----------------------- | AO38: -----------------------
A39: =SUM(A9:A38) -> 0 | B39: =SUM(B9:B38) -> 0 | C39: =SUM(C9:C38) -> 432 | D39: =SUM(D9:D38) -> 3 | E39: =SUM(E9:E38) -> 7674.55 | F39: =SUM(F9:F38) -> 8118.17 | G39: =SUM(G9:G38) -> 114511.58 | H39: =SUM(H9:H38) -> 606.67 | ... AP39: =SUM(AP9:AP38) -> 8194.8157
A41: 30 | B41: Nomina
A42: 0 | B42: Altas
A43: 1 | B43: Bajas
A44: =+A41+A42-A43 -> 29 | B44: Total Nomina | L44: Devengado Salario | M44: =+Y39 -> 121000.4
L45: RETORNOS | M45: =+V39 -> 2029.52
L46: Infonavit | M46: =+S39+R39+Q39+T39 -> 15253.11
L47: Prestamo Prospera | M47: =+U39 -> 0
L48: Subtotal 1 | M48: =SUM(M44:M47) -> 138283.03
L49: Comision | M49: =+M48*2% -> 2765.6606
L50: Subtotal 2 | M50: =+M48+M49 -> 141048.69
L51: Costo Patronal Imss | M51: =+P39+AF39+AG39+AH39+AJ39+AL39+AN39+AO39 -> 40641.15
L52: 2% Sobre Nomina | M52: =+M39*2% -> 2990.4412
L53: Importe de Factura | M53: =+M50+M51+M52 -> 184680.28
L54: IVA | M54: =+M53*16% -> 29548.845
L55: TOTAL | M55: =+M53+M54 -> 214229.13

Sheet FAC-CPD
C2: CONSULTORIA EN PROYECTOS DINAMICOS S DE RL DE CV
C3: Lista de Raya (forma tabular)
C4: Reg Pat IMSS: Z2940859106
C5: RFC: CPD -150911-FA3
B8: Código | C8: Empleado | D8: Dias Laborados | E8: Dias Vacaciones | F8: Salario Diario | G8: Salario Diario Integrado | H8: Sueldo | I8: Vacaciones a tiempo | J8: Prima de vacaciones a tiempo | K8: Ayuda de Transporte | L8: Ayuda Alimentaria | M8: Ayuda de Renta | N8: *TOTAL* *PERCEPCIONES* | O8: I.S.R. (sp) | P8: Subsidio al Empleo (sp) | Q8: I.M.S.S. | R8: Préstamo Infonavit | S8: Préstamo Infonavit (vsm) | T8: Préstamo Infonavit (cf) | U8: Seguro de vivienda Infonavit | V8: Prestamo Empresa | W8: Deduccion general | X8: Ajuste al neto | Y8: *TOTAL* *DEDUCCIONES* | Z8: *NETO* | AA8: Ret. Inv. Y Vida | AB8: Ret. Cesantia | AC8: Ret. Enf. y Mat. obrero | AD8: Subs al Empleo acreditado | AE8: I.S.R. antes de Subs al Empleo | AF8: isr 2 | AG8: Invalidez y Vida | AH8: Cesantia y Vejez | AI8: Enf. y Mat. Patron | AJ8: Total Percepciones | AK8: 2% Fondo retiro SAR (8) | AL8: 2% Impuesto estatal | AM8: Riesgo de trabajo (9) | AN8: I.M.S.S. empresa | AO8: Infonavit empresa | AP8: Guarderia I.M.S.S. (7) | AQ8: Proporcion Aguinaldo | AR8: FACTURACION
B9: SEI0009 | C9: Gutierrez Gutierrez Luis Arturo | D9: 15 | E9: 0 | F9: 141.67 | G9: 150.25 | H9: 2125.05 | I9: 0 | J9: 0 | K9: 212.51 | L9: 212.51 | M9: 212.51 | N9: 2762.58 | O9: 0 | P9: -65.5 | Q9: 53.52 | R9: 0 | S9: 0 | W9: 0 | X9: 0.16 | Y9: -11.82 | Z9: 2774.4 | AA9: 14.09 | AB9: 25.35 | AC9: 14.08 | AD9: -188.71 | AE9: 123.22 | AG9: 39.44 | AH9: 70.99 | AI9: 297.98 | AJ9: 2762.58 | AK9: 240.44 | AL9: 55.25 | AM9: 12.91 | AN9: 408.41 | AO9: 112.69 | AP9: 217.9 | AQ9: 151.27396 | AR9: PITSS
B10: SEI0026 | C10: Patricio Aguilar Jhonattan Cristian | D10: 15 | E10: 0 | F10: 150 | G10: 159.07 | H10: 2250 | I10: 0 | J10: 0 | K10: 225 | L10: 225 | M10: 225 | N10: 2925 | O10: 0 | P10: -43.57 | Q10: 56.67 | R10: 0 | S10: 0 | W10: 0 | X10: 0.1 | Y10: 13.2 | Z10: 2911.8 | AA10: 14.91 | AB10: 26.84 | AC10: 14.92 | AD10: -174.78 | AE10: 131.21 | AG10: 41.76 | AH10: 75.16 | AI10: 300.29 | AJ10: 2925 | AK10: 243.08 | AL10: 58.5 | AM10: 13.67 | AN10: 417.21 | AO10: 119.31 | AP10: 219.22 | AQ10: 160.16866 | AR10: PITSS
B11: SEI0039 | C11: Benavides Herrera Pablo | D11: 15 | E11: 0 | F11: 666.67 | G11: 696.81 | H11: 10000.05 | I11: 0 | J11: 0 | K11: 1000 | L11: 1000 | M11: 1000 | N11: 13000.05 | O11: 1497.79 | P11: 0 | Q11: 274.85 | R11: 0 | S11: 0 | W11: 0 | X11: 0.01 | Y11: 1772.65 | Z11: 11227.4 | AA11: 65.33 | AB11: 117.59 | AC11: 91.93 | AD11: 0 | AE11: 1497.79 | AG11: 182.91 | AH11: 329.24 | AI11: 514.6 | AJ11: 13000.05 | AK11: 404.4 | AL11: 260 | AM11: 59.88 | AN11: 1026.75 | AO11: 522.61 | AP11: 299.88 | AQ11: 711.86425 | AR11: PITSS
B12: SEI0040 | C12: Mora Ramirez Acal Aldo Isidro | D12: 15 | E12: 0 | F12: 216.67 | G12: 229.79 | H12: 3250.05 | I12: 0 | J12: 0 | K12: 325.01 | L12: 325.01 | M12: 325.01 | N12: 4225.08 | O12: 107.17 | P12: 0 | Q12: 81.87 | R12: 0 | S12: 0 | W12: 0 | X12: 0.04 | Y12: 189.08 | Z12: 4036 | AA12: 21.54 | AB12: 38.78 | AC12: 21.55 | AD12: -125.1 | AE12: 232.27 | AG12: 60.32 | AH12: 108.58 | AI12: 318.86 | AJ12: 4225.08 | AK12: 264.3 | AL12: 84.5 | AM12: 19.75 | AN12: 487.76 | AO12: 172.34 | AP12: 229.83 | AQ12: 231.35828 | AR12: PITSS
B13: SEI0041 | C13: Vazquez Perez Miguel Angel | D13: 15 | E13: 0 | F13: 283.33 | G13: 300.49 | H13: 4249.95 | I13: 0 | J13: 0 | K13: 425 | L13: 425 | M13: 425 | N13: 5524.95 | O13: 341.06 | P13: 0 | Q13: 109.87 | R13: 0 | S13: 0 | W13: 0 | X13: 0.02 | Y13: 450.95 | Z13: 5074 | AA13: 28.17 | AB13: 50.71 | AC13: 30.99 | AD13: 0 | AE13: 341.06 | AG13: 78.88 | AH13: 141.98 | AI13: 345.18 | AJ13: 5524.95 | AK13: 285.51 | AL13: 110.5 | AM13: 25.82 | AN13: 566.04 | AO13: 225.37 | AP13: 240.43 | AQ13: 302.53724 | AR13: PITSS
B14: SEI0088 | C14: Morgado Fernandez Martin | D14: 15 | E14: 0 | F14: 273.33 | G14: 289.87 | H14: 4099.95 | I14: 0 | J14: 0 | K14: 410 | L14: 410 | M14: 410 | N14: 5329.95 | O14: 324.74 | P14: 0 | Q14: 105.46 | R14: 0 | S14: 0 | W14: 0 | X14: 0.15 | Y14: 430.35 | Z14: 4899.6 | AA14: 27.18 | AB14: 48.92 | AC14: 29.36 | AD14: 0 | AE14: 324.74 | AG14: 76.09 | AH14: 136.96 | AI14: 340.64 | AJ14: 5329.95 | AK14: 282.32 | AL14: 106.6 | AM14: 24.91 | AN14: 553.69 | AO14: 217.4 | AP14: 238.84 | AQ14: 291.85933 | AR14: PITSS
B15: SEI0097 | C15: Arreola Jimenez Jose Nieves | D15: 15 | E15: 0 | F15: 185.83 | G15: 197.07 | H15: 2787.45 | I15: 0 | J15: 0 | K15: 278.75 | L15: 278.75 | M15: 278.75 | N15: 3623.7 | O15: 36.57 | P15: 0 | Q15: 70.22 | R15: 0 | S15: 1559.39 | W15: 224.7 | X15: -0.18 | Y15: 1890.7 | Z15: 1733 | AA15: 18.48 | AB15: 33.26 | AC15: 18.48 | AD15: -145.38 | AE15: 181.94 | AG15: 51.73 | AH15: 93.12 | AI15: 310.27 | AJ15: 3623.7 | AK15: 254.48 | AL15: 72.47 | AM15: 16.94 | AN15: 455.12 | AO15: 147.8 | AP15: 224.92 | AQ15: 198.42761 | AR15: PITSS
B16: SEI0099 | C16: Garcia Villicaña Ricardo Pascual | D16: 14 | E16: 1 | F16: 273.33 | G16: 289.87 | H16: 3826.62 | I16: 273.33 | J16: 82 | K16: 410 | L16: 410 | M16: 410 | N16: 5411.95 | O16: 324.74 | P16: 0 | Q16: 105.46 | R16: 0 | S16: 0 | W16: 0 | X16: 0.15 | Y16: 430.35 | Z16: 4981.6 | AA16: 27.18 | AB16: 48.92 | AC16: 29.36 | AD16: 0 | AE16: 324.74 | AG16: 76.09 | AH16: 136.96 | AI16: 340.64 | AJ16: 5411.95 | AK16: 282.32 | AL16: 108.24 | AM16: 24.91 | AN16: 553.69 | AO16: 217.4 | AP16: 238.84 | AQ16: 291.85933 | AR16: PITSS
B17: SEI0108 | C17: Caballero Diaz Francisco Javier | D17: 15 | E17: 0 | F17: 185.83 | G17: 197.07 | H17: 2787.45 | I17: 0 | J17: 0 | K17: 278.75 | L17: 278.75 | M17: 278.75 | N17: 3623.7 | O17: 36.57 | P17: 0 | Q17: 70.22 | R17: 0 | S17: 1809.82 | W17: 0 | X17: 0.09 | Y17: 1916.7 | Z17: 1707 | AA17: 18.48 | AB17: 33.26 | AC17: 18.48 | AD17: -145.38 | AE17: 181.94 | AG17: 51.73 | AH17: 93.12 | AI17: 310.27 | AJ17: 3623.7 | AK17: 254.48 | AL17: 72.47 | AM17: 16.94 | AN17: 455.12 | AO17: 147.8 | AP17: 224.92 | AQ17: 198.42761 | AR17: PITSS
B18: SEI0116 | C18: Casillas Cardona Cesar Alejandro | D18: 15 | E18: 0 | F18: 220.83 | G18: 234.19 | H18: 3312.45 | I18: 0 | J18: 0 | K18: 331.25 | L18: 331.25 | M18: 331.25 | N18: 4306.2 | O18: 113.96 | P18: 0 | Q18: 83.43 | R18: 0 | S18: 1045.17 | W18: 0 | X18: -0.16 | Y18: 1242.4 | Z18: 3063.8 | AA18: 21.96 | AB18: 39.52 | AC18: 21.95 | AD18: -125.1 | AE18: 239.06 | AG18: 61.47 | AH18: 110.65 | AI18: 320.01 | AJ18: 4306.2 | AK18: 265.62 | AL18: 86.12 | AM18: 20.13 | AN18: 492.13 | AO18: 175.64 | AP18: 230.49 | AQ18: 235.8003 | AR18: PITSS
B19: SEI0117 | C19: Mariscal Romero Luis Adrian | D19: 15 | E19: 0 | F19: 264.58 | G19: 276.54 | H19: 3968.7 | I19: 0 | J19: 0 | K19: 396.87 | L19: 396.87 | M19: 396.87 | N19: 5159.31 | O19: 310.46 | P19: 0 | Q19: 99.91 | R19: 0 | S19: 1658.56 | W19: 396 | X19: -0.02 | Y19: 2464.91 | Z19: 2694.4 | AA19: 25.93 | AB19: 46.67 | AC19: 27.31 | AD19: 0 | AE19: 310.46 | AG19: 72.59 | AH19: 130.66 | AI19: 334.94 | AJ19: 5159.31 | AK19: 278.32 | AL19: 103.19 | AM19: 23.76 | AN19: 538.19 | AO19: 207.4 | AP19: 236.84 | AQ19: 282.51615 | AR19: PITSS
B20: SEI0118 | C20: Arroyo Ramirez Hector Hugo | D20: 15 | E20: 0 | F20: 238.33 | G20: 252.75 | H20: 3574.95 | I20: 0 | J20: 285.99 | K20: 357.5 | L20: 357.5 | M20: 357.5 | N20: 4933.44 | O20: 160.25 | P20: 0 | Q20: 90.05 | R20: 0 | S20: 1418.5 | W20: 678.02 | X20: 0.02 | Y20: 2346.84 | Z20: 2586.6 | AA20: 23.7 | AB20: 42.65 | AC20: 23.7 | AD20: -107.37 | AE20: 267.62 | AG20: 66.35 | AH20: 119.42 | AI20: 324.89 | AJ20: 4933.44 | AK20: 271.18 | AL20: 98.67 | AM20: 21.72 | AN20: 510.66 | AO20: 189.56 | AP20: 233.27 | AQ20: 254.48664 | AR20: PITSS
... B29: SEI0445 | C29: Muñoz Melgoza Gabriel | D29: 15 | E29: 0 | F29: 256.67 | G29: 272.21 | H29: 3850.05 | I29: 0 | J29: 0 | K29: 385.01 | L29: 385.01 | M29: 385.01 | N29: 5005.08 | O29: 297.55 | P29: 0 | Q29: 98.1 | R29: 0 | S29: 0 | W29: 0 | X29: 0.03 | Y29: 395.68 | Z29: 4609.4 | AA29: 25.52 | AB29: 45.94 | AC29: 26.64 | AD29: 0 | AE29: 297.55 | AG29: 71.46 | AH29: 128.62 | AI29: 333.08 | AJ29: 5005.08 | AK29: 277.02 | AL29: 100.1 | AM29: 23.39 | AN29: 533.16 | AO29: 204.16 | AP29: 236.19 | AQ29: 274.06993 | AR29: PITSS
A30: Total PITSS | B30: =SUBTOTAL(9,B9:B29) -> 0 | C30: =SUBTOTAL(9,C9:C29) -> 0 | D30: =SUBTOTAL(9,D9:D29) -> 314 | E30: =SUBTOTAL(9,E9:E29) -> 1 | F30: =SUBTOTAL(9,F9:F29) -> 5852.89 | G30: =SUBTOTAL(9,G9:G29) -> 6192.87 | H30: =SUBTOTAL(9,H9:H29) -> 87520.02 | I30: =SUBTOTAL(9,I9:I29) -> 273.33 | ... AR30: =SUBTOTAL(9,AR9:AR29) -> 0
B31: SEI0010 | C31: Compean Tobias Braulio Gerardo | D31: 15 | E31: 0 | F31: 300 | G31: 313.56 | H31: 4500 | I31: 0 | J31: 0 | K31: 450 | L31: 450 | M31: 450 | N31: 5850 | O31: 380.67 | P31: 0 | Q31: 115.32 | R31: 0 | S31: 1320.68 | W31: 0 | X31: -0.07 | Y31: 1816.6 | Z31: 4033.4 | AA31: 29.4 | AB31: 52.91 | AC31: 33.01 | AD31: 0 | AE31: 380.67 | AG31: 82.31 | AH31: 148.16 | AI31: 350.77 | AJ31: 5850 | AK31: 289.43 | AL31: 117 | AM31: 26.95 | AN31: 581.24 | AO31: 235.17 | AP31: 242.39 | AQ31: 320.33731 | AR31: SEITON
B32: SEI0119 | C32: Dominguez Lopez Maria De Jesus | D32: 15 | E32: 0 | F32: 238.33 | G32: 252.76 | H32: 3574.95 | I32: 0 | J32: 0 | K32: 357.5 | L32: 357.5 | M32: 357.5 | N32: 4647.45 | O32: 160.25 | P32: 0 | Q32: 90.05 | R32: 947.85 | S32: 0 | W32: 0 | X32: 0.1 | Y32: 1198.25 | Z32: 3449.2 | AA32: 23.7 | AB32: 42.65 | AC32: 23.7 | AD32: -107.37 | AE32: 267.62 | AG32: 66.35 | AH32: 119.43 | AI32: 324.89 | AJ32: 4647.45 | AK32: 271.19 | AL32: 92.95 | AM32: 21.72 | AN32: 510.67 | AO32: 189.57 | AP32: 233.27 | AQ32: 254.48664 | AR32: SEITON
B33: SEI0147 | C33: Diaz Munguia Martha Liliana | D33: 15 | E33: 0 | F33: 308.33 | G33: 327 | H33: 4624.95 | I33: 0 | J33: 0 | K33: 462.5 | L33: 462.5 | M33: 462.5 | N33: 6012.45 | O33: 400.66 | P33: 0 | Q33: 120.9 | R33: 0 | S33: 413.05 | W33: 0 | X33: 0.04 | Y33: 934.65 | Z33: 5077.8 | AA33: 30.66 | AB33: 55.18 | AC33: 35.06 | AD33: 0 | AE33: 400.66 | AG33: 85.84 | AH33: 154.51 | AI33: 356.51 | AJ33: 6012.45 | AK33: 293.46 | AL33: 120.25 | AM33: 28.1 | AN33: 596.86 | AO33: 245.25 | AP33: 244.41 | AQ33: 329.23201 | AR33: SEITON
B34: SEI032 | C34: Camarena Quiroz Erick Frank | D34: 15 | E34: 0 | F34: 150 | G34: 159.07 | H34: 2250 | I34: 0 | J34: 0 | K34: 225 | L34: 225 | M34: 225 | N34: 2925 | O34: 0 | P34: -43.57 | Q34: 56.67 | R34: 0 | S34: 0 | W34: 0 | X34: -0.1 | Y34: 13 | Z34: 2912 | AA34: 14.91 | AB34: 26.84 | AC34: 14.92 | AD34: -174.78 | AE34: 131.21 | AG34: 41.76 | AH34: 75.16 | AI34: 300.29 | AJ34: 2925 | AK34: 243.08 | AL34: 58.5 | AM34: 13.67 | AN34: 417.21 | AO34: 119.3 | AP34: 219.22 | AQ34: 160.16866 | AR34: SEITON
B35: SEI0437 | C35: Leal Montaño Diego | D35: 13 | E35: 2 | F35: 166.67 | G35: 176.76 | H35: 2166.71 | I35: 333.34 | J35: 100 | K35: 250.01 | L35: 250.01 | M35: 250.01 | N35: 3350.08 | O35: 0 | P35: -9.62 | Q35: 62.97 | R35: 0 | S35: 392.72 | W35: 0 | X35: 0.01 | Y35: 446.08 | Z35: 2904 | AA35: 16.57 | AB35: 29.83 | AC35: 16.57 | AD35: -160.3 | AE35: 150.67 | AG35: 46.4 | AH35: 83.52 | AI35: 304.94 | AJ35: 3250.08 | AK35: 248.39 | AL35: 65 | AM35: 15.19 | AN35: 434.86 | AO35: 132.57 | AP35: 221.87 | AQ35: 177.96873 | AR35: SEITON
B36: SEI0440 | C36: Leija Arevalo Guadalupe | D36: 15 | E36: 0 | F36: 133.33 | G36: 139.36 | H36: 1999.95 | I36: 0 | J36: 0 | K36: 0 | L36: 0 | M36: 0 | N36: 1999.95 | O36: 0 | P36: -73.5 | Q36: 49.65 | R36: 0 | S36: 1044.75 | W36: 0 | X36: 0.05 | Y36: 1020.95 | Z36: 979 | AA36: 13.06 | AB36: 23.52 | AC36: 13.07 | AD36: -188.71 | AE36: 115.21 | AG36: 36.58 | AH36: 65.85 | AI36: 295.12 | AJ36: 1999.95 | AK36: 237.17 | AL36: 40 | AM36: 11.98 | AN36: 397.55 | AO36: 104.52 | AP36: 216.26 | AQ36: 142.36858 | AR36: SEITON
B37: SEI0447 | C37: Oliver Olague Vicente | D37: 15 | E37: 0 | F37: 291.67 | G37: 309.33 | H37: 4375.05 | I37: 0 | J37: 0 | K37: 437.51 | L37: 437.51 | M37: 437.51 | N37: 5687.58 | O37: 360.68 | P37: 0 | Q37: 113.55 | R37: 0 | S37: 0 | W37: 0 | X37: 0.15 | Y37: 474.38 | Z37: 5213.2 | AA37: 29 | AB37: 52.2 | AC37: 32.35 | AD37: 0 | AE37: 360.68 | AG37: 81.2 | AH37: 146.16 | AI37: 348.96 | AJ37: 5687.58 | AK37: 288.16 | AL37: 113.75 | AM37: 26.58 | AN37: 576.32 | AO37: 232 | AP37: 241.76 | AQ37: 311.44261 | AR37: SEITON
B38: SEI0448 | C38: Rodriguez Chavez Oswaldo Emmanuel | D38: 15 | E38: 0 | F38: 233.33 | G38: 247.46 | H38: 3499.95 | I38: 0 | J38: 0 | K38: 350 | L38: 350 | M38: 350 | N38: 4549.95 | O38: 134.36 | P38: 0 | Q38: 88.16 | R38: 0 | S38: 0 | W38: 0 | X38: 0.03 | Y38: 222.55 | Z38: 4327.4 | AA38: 23.2 | AB38: 41.76 | AC38: 23.2 | AD38: -125.1 | AE38: 259.46 | AG38: 64.96 | AH38: 116.92 | AI38: 323.5 | AJ38: 4549.95 | AK38: 269.6 | AL38: 91 | AM38: 21.27 | AN38: 505.38 | AO38: 185.6 | AP38: 232.48 | AQ38: 249.14768 | AR38: SEITON
A39: Total SEITON | B39: =SUBTOTAL(9,B31:B38) -> 0 | C39: =SUBTOTAL(9,C31:C38) -> 0 | D39: =SUBTOTAL(9,D31:D38) -> 118 | E39: =SUBTOTAL(9,E31:E38) -> 2 | F39: =SUBTOTAL(9,F31:F38) -> 1821.66 | G39: =SUBTOTAL(9,G31:G38) -> 1925.3 | H39: =SUBTOTAL(9,H31:H38) -> 26991.56 | I39: =SUBTOTAL(9,I31:I38) -> 333.34 | ... AR39: =SUBTOTAL(9,AR31:AR38) -> 0
B40: Total Depto | D40: ----------------------- | E40: ----------------------- | F40: ----------------------- | G40: ----------------------- | H40: ----------------------- | I40: ----------------------- | J40: ----------------------- | K40: ----------------------- | L40: ----------------------- | M40: ----------------------- | N40: ----------------------- | O40: ----------------------- | P40: ----------------------- | Q40: ----------------------- | R40: ----------------------- | S40: ----------------------- | T40: ----------------------- | U40: ----------------------- | V40: ----------------------- | W40: ----------------------- | X40: ----------------------- | Y40: ----------------------- | Z40: ----------------------- | AA40: ----------------------- | AB40: ----------------------- | AC40: ----------------------- | AD40: ----------------------- | AE40: ----------------------- | AF40: ----------------------- | AG40: ----------------------- | AH40: ----------------------- | AI40: ----------------------- | AJ40: ----------------------- | AK40: ----------------------- | AL40: ----------------------- | AM40: ----------------------- | AN40: ----------------------- | AO40: ----------------------- | AP40: -----------------------
B41: =SUM(B9:B40) -> 0 | C41: =SUM(C9:C40) -> 0 | D41: =+D30+D39 -> 432 | E41: =+E30+E39 -> 3 | F41: =+F30+F39 -> 7674.55 | G41: =+G30+G39 -> 8118.17 | H41: =+H30+H39 -> 114511.58 | I41: =+I30+I39 -> 606.67 | J41: =+J30+J39 -> 467.99 | K41: =+K30+K39 -> 11311.94 | ... AR41: =+AR30+AR39 -> 0
M42: FACTURACION PITS | O42: FACTURACION SEITON
B43: 30 | C43: Nomina | M43: Devengado Salario | N43: =+Z30 -> 92104.4 | O43: Devengado Salario | P43: =+Z39 -> 28896
B44: 0 | C44: Altas | M44: RETORNOS | N44: =+W30 -> 2029.52 | O44: RETORNOS | P44: =+W39 -> 0
B45: 1 | C45: Bajas | M45: Infonavit | N45: =+T30+S30+R30+U30 -> 11134.06 | O45: Infonavit | P45: =+T39+S39+R39+U39 -> 4119.05
B46: =+B43+B44-B45 -> 29 | C46: Total Nomina | M46: Prestamo Prospera | N46: =+V30 -> 0 | O46: Prestamo Prospera | P46: =+W39 -> 0
M47: Subtotal 1 | N47: =SUM(N43:N46) -> 105267.98 | O47: Subtotal 1 | P47: =SUM(P43:P46) -> 33015.05
M48: Comision | N48: =+N47*2% -> 2105.3596 | O48: Comision | P48: =+P47*2% -> 660.301
M49: Subtotal 2 | N49: =+N47+N48 -> 107373.34 | O49: Subtotal 2 | P49: =+P47+P48 -> 33675.351
M50: Costo Patronal Imss | N50: =+Q30+AG30+AH30+AI30+AK30+AM30+AO30+AP30 -> 30322.21 | O50: Costo Patronal Imss | P50: =+Q39+AG39+AH39+AI39+AK39+AM39+AO39+AP39 -> 10318.94
M51: 2% Sobre Nomina | N51: =+N30*2% -> 2289.992 | O51: 2% Sobre Nomina | P51: =+N39*2% -> 700.4492
...

Sheet IP
B2: IP INNOVACION EN PROYECTOS S DE RL DE CV
B3: Lista de Raya (forma tabular)
B4: Reg Pat IMSS: Z2942442109
B5: RFC: IIP -150923-DT7
A8: Código | B8: Empleado | C8: Dias Laborados | D8: Dias Vacaciones | E8: Salario Diario | F8: Salario Diario Integrado | G8: Sueldo | H8: Vacaciones a tiempo | I8: Prima de vacaciones a tiempo | J8: *TOTAL* *PERCEPCIONES* | K8: I.S.R. (sp) | L8: Subsidio al Empleo (sp) | M8: I.M.S.S. | N8: Préstamo Infonavit (vsm) | O8: Préstamo Infonavit (cf) | P8: Seguro de vivienda Infonavit | Q8: Prestamo FONACOT | R8: Deduccion general | S8: Aportación voluntaria SAR | T8: Ajuste al neto | U8: *TOTAL* *DEDUCCIONES* | V8: *NETO* | W8: Ret. Inv. Y Vida | X8: Ret. Cesantia | Y8: Ret. Enf. y Mat. obrero | Z8: Subs al Empleo acreditado | AA8: I.S.R. antes de Subs al Empleo | AB8: isr 2 | AC8: Invalidez y Vida | AD8: Cesantia y Vejez | AE8: Enf. y Mat. Patron | AF8: Total Percepciones | AG8: 2% Fondo retiro SAR (8) | AH8: 2% Impuesto estatal | AI8: Riesgo de trabajo (9) | AJ8: I.M.S.S. empresa | AK8: Infonavit empresa | AL8: Guarderia I.M.S.S. (7) | AM8: Proporcion Aguinaldo | AN8: CC
A9: SEI0010 | B9: Torres Ricardez Alfredo | C9: 15 | D9: 0 | E9: 266.67 | F9: 278.72 | G9: 4000.05 | H9: 0 | I9: 0 | J9: 4000.05 | K9: 313.87 | L9: 0 | M9: 100.81 | N9: 0 | O9: 0 | Q9: 0 | R9: 0 | S9: 0 | T9: 0.17 | U9: 414.85 | V9: 3585.2 | W9: 26.13 | X9: 47.03 | Y9: 27.65 | Z9: 0 | AA9: 313.87 | AC9: 73.16 | AD9: 131.7 | AE9: 335.88 | AF9: 4000.05 | AG9: 266.64 | AH9: 80 | AI9: 47.27 | AJ9: 540.74 | AK9: 209.04 | AL9: 224.83 | AM9: 219.0368 | AN9: PITSS
A10: SEI0014 | B10: Montoya Portillo Carlos Alberto | C10: 15 | D10: 0 | E10: 266.67 | F10: 278.72 | G10: 4000.05 | H10: 0 | I10: 0 | J10: 4000.05 | K10: 313.87 | L10: 0 | M10: 100.81 | N10: 0 | O10: 0 | Q10: 0 | R10: 0 | S10: 0 | T10: -0.03 | U10: 414.65 | V10: 3585.4 | W10: 26.13 | X10: 47.03 | Y10: 27.65 | Z10: 0 | AA10: 313.87 | AC10: 73.16 | AD10: 131.7 | AE10: 335.88 | AF10: 4000.05 | AG10: 266.64 | AH10: 80 | AI10: 47.27 | AJ10: 540.74 | AK10: 209.04 | AL10: 224.83 | AM10: 219.0368 | AN10: PITSS
A11: SEI0015 | B11: Cota Jaramillo Miguel Angel | C11: 15 | D11: 0 | E11: 200 | F11: 209.04 | G11: 3000 | H11: 0 | I11: 0 | J11: 3000 | K11: 59.69 | L11: 0 | M11: 74.48 | N11: 0 | O11: 0 | Q11: 0 | R11: 0 | S11: 0 | T11: 0.03 | U11: 134.2 | V11: 2865.8 | W11: 19.6 | X11: 35.28 | Y11: 19.6 | Z11: -145.38 | AA11: 205.07 | AC11: 54.87 | AD11: 98.77 | AE11: 313.41 | AF11: 3000 | AG11: 245.73 | AH11: 60 | AI11: 35.45 | AJ11: 467.05 | AK11: 156.78 | AL11: 214.38 | AM11: 164.27554 | AN11: PITSS
A12: SEI0016 | B12: Negrete Bejar Aide Sarai | C12: 15 | D12: 0 | E12: 154 | F12: 160.96 | G12: 2310 | H12: 0 | I12: 0 | J12: 2310 | K12: 0 | L12: -39.73 | M12: 57.34 | N12: 1188.73 | O12: 0 | Q12: 0 | R12: 0 | S12: 0 | T12: 0.06 | U12: 1206.4 | V12: 1103.6 | W12: 15.09 | X12: 27.16 | Y12: 15.09 | Z12: -174.78 | AA12: 135.05 | AC12: 42.25 | AD12: 76.05 | AE12: 300.79 | AF12: 2310 | AG12: 231.31 | AH12: 46.2 | AI12: 27.3 | AJ12: 419.09 | AK12: 120.72 | AL12: 207.16 | AM12: 126.49217 | AN12: SEITON
A13: SEI0017 | B13: Muñoz Reyes Luis Eduardo | C13: 15 | D13: 0 | E13: 266.67 | F13: 278.72 | G13: 4000.05 | H13: 0 | I13: 0 | J13: 4000.05 | K13: 313.87 | L13: 0 | M13: 100.81 | N13: 878.36 | O13: 0 | Q13: 0 | R13: 0 | S13: 0 | T13: 0.01 | U13: 1293.05 | V13: 2707 | W13: 26.13 | X13: 47.03 | Y13: 27.65 | Z13: 0 | AA13: 313.87 | AC13: 73.16 | AD13: 131.7 | AE13: 335.88 | AF13: 4000.05 | AG13: 266.64 | AH13: 80 | AI13: 47.27 | AJ13: 540.74 | AK13: 209.04 | AL13: 224.83 | AM13: 219.0368 | AN13: PITSS
A14: SEI0018 | B14: Dominguez Mendez Victor Manuel | C14: 15 | D14: 0 | E14: 300 | F14: 313.56 | G14: 4500 | H14: 0 | I14: 0 | J14: 4500 | K14: 380.67 | L14: 0 | M14: 115.32 | N14: 0 | O14: 0 | Q14: 0 | R14: 0 | S14: 0 | T14: 0.01 | U14: 496 | V14: 4004 | W14: 29.4 | X14: 52.91 | Y14: 33.01 | Z14: 0 | AA14: 380.67 | AC14: 82.31 | AD14: 148.16 | AE14: 350.76 | AF14: 4500 | AG14: 277.09 | AH14: 90 | AI14: 53.18 | AJ14: 581.23 | AK14: 235.17 | AL14: 230.05 | AM14: 246.41332 | AN14: PITSS
A15: SEI0019 | B15: Gonzalez Rasgado Miguel Isaias | C15: 13 | D15: 2 | E15: 400 | F15: 424.2 | G15: 5200 | H15: 800 | I15: 240 | J15: 6240 | K15: 643.38 | L15: 0 | M15: 161.36 | N15: 0 | O15: 0 | Q15: 0 | R15: 0 | S15: 0 | T15: 0.06 | U15: 804.8 | V15: 5435.2 | W15: 39.77 | X15: 71.58 | Y15: 50.01 | Z15: 0 | AA15: 643.38 | AC15: 111.35 | AD15: 200.43 | AE15: 398.06 | AF15: 6240 | AG15: 310.28 | AH15: 124.8 | AI15: 71.94 | AJ15: 709.84 | AK15: 318.15 | AL15: 246.65 | AM15: 328.55109 | AN15: PITSS
A16: SEI0020 | B16: Mar Marquez Cesar Eduardo | C16: 15 | D16: 0 | E16: 266.67 | F16: 278.72 | G16: 4000.05 | H16: 0 | I16: 0 | J16: 4000.05 | K16: 313.87 | L16: 0 | M16: 100.81 | N16: 0 | O16: 0 | Q16: 0 | R16: 0 | S16: 0 | T16: -0.03 | U16: 414.65 | V16: 3585.4 | W16: 26.13 | X16: 47.03 | Y16: 27.65 | Z16: 0 | AA16: 313.87 | AC16: 73.16 | AD16: 131.7 | AE16: 335.88 | AF16: 4000.05 | AG16: 266.64 | AH16: 80 | AI16: 47.27 | AJ16: 540.74 | AK16: 209.04 | AL16: 224.83 | AM16: 219.0368 | AN16: PITSS
A17: SEI0021 | B17: Velez Rodriguez Jaime | C17: 15 | D17: 0 | E17: 200 | F17: 212.1 | G17: 3000 | H17: 0 | I17: 0 | J17: 3000 | K17: 59.69 | L17: 0 | M17: 75.55 | N17: 1362.48 | O17: 0 | Q17: 0 | R17: 0 | S17: 0 | T17: -0.12 | U17: 1497.6 | V17: 1502.4 | W17: 19.88 | X17: 35.79 | Y17: 19.88 | Z17: -145.38 | AA17: 205.07 | AC17: 55.68 | AD17: 100.22 | AE17: 314.22 | AF17: 3000 | AG17: 246.65 | AH17: 60 | AI17: 35.97 | AJ17: 470.12 | AK17: 159.08 | AL17: 214.84 | AM17: 164.27554 | AN17: PITSS
A18: SEI0022 | B18: Najera Lopez Raul | C18: 15 | D18: 0 | E18: 333.33 | F18: 353.5 | G18: 4999.95 | H18: 0 | I18: 0 | J18: 4999.95 | K18: 461.63 | L18: 0 | M18: 131.93 | N18: 0 | O18: 0 | Q18: 0 | R18: 0 | S18: 0 | T18: -0.01 | U18: 593.55 | V18: 4406.4 | W18: 33.14 | X18: 59.65 | Y18: 39.14 | Z18: 0 | AA18: 461.63 | AC18: 92.79 | AD18: 167.03 | AE18: 367.84 | AF18: 4999.95 | AG18: 289.07 | AH18: 100 | AI18: 59.95 | AJ18: 627.66 | AK18: 265.12 | AL18: 236.04 | AM18: 273.78984 | AN18: PITSS
A19: SEI0023 | B19: Puente Murguia Luis Felipe | C19: 15 | D19: 0 | E19: 233.33 | F19: 247.45 | G19: 3499.95 | H19: 0 | I19: 0 | J19: 3499.95 | K19: 134.36 | L19: 0 | M19: 88.16 | N19: 0 | O19: 0 | Q19: 0 | R19: 0 | S19: 0 | T19: 0.03 | U19: 222.55 | V19: 3277.4 | W19: 23.2 | X19: 41.76 | Y19: 23.2 | Z19: -125.1 | AA19: 259.46 | AC19: 64.95 | AD19: 116.92 | AE19: 323.49 | AF19: 3499.95 | AG19: 257.25 | AH19: 70 | AI19: 41.97 | AJ19: 505.36 | AK19: 185.58 | AL19: 220.14 | AM19: 191.65206 | AN19: PITSS
A20: SEI0028 | B20: Jimenez Alcaraz Elizabeth | C20: 15 | D20: 0 | E20: 200 | F20: 212.11 | G20: 3000 | H20: 0 | I20: 0 | J20: 3000 | K20: 59.69 | L20: 0 | M20: 75.56 | N20: 0 | O20: 0 | Q20: 0 | R20: 0 | S20: 0 | T20: -0.05 | U20: 135.2 | V20: 2864.8 | W20: 19.89 | X20: 35.79 | Y20: 19.88 | Z20: -145.38 | AA20: 205.07 | AC20: 55.68 | AD20: 100.22 | AE20: 314.22 | AF20: 3000 | AG20: 246.65 | AH20: 60 | AI20: 35.97 | AJ20: 470.12 | AK20: 159.08 | AL20: 214.84 | AM20: 164.27554 | AN20: PITSS
... A117: SEI479 | B117: Cruz Perez Alejandro Nezahualcoyotl | C117: 15 | D117: 0 | E117: 266.67 | F117: 282.81 | G117: 4000.05 | H117: 0 | I117: 0 | J117: 4000.05 | K117: 313.87 | L117: 0 | M117: 102.51 | N117: 0 | O117: 0 | Q117: 0 | R117: 0 | S117: 0 | T117: 0.07 | U117: 416.45 | V117: 3583.6 | W117: 26.51 | X117: 47.72 | Y117: 28.28 | Z117: 0 | AA117: 313.87 | AC117: 74.24 | AD117: 133.63 | AE117: 337.62 | AF117: 4000.05 | AG117: 267.86 | AH117: 80 | AI117: 47.96 | AJ117: 545.49 | AK117: 212.11 | AL117: 225.44 | AM117: 219.0368 | AN117: PITSS
A118: Total Depto | C118: ----------------------- | D118: ----------------------- | E118: ----------------------- | F118: ----------------------- | G118: ----------------------- | H118: ----------------------- | I118: ----------------------- | J118: ----------------------- | K118: ----------------------- | L118: ----------------------- | M118: ----------------------- | N118: ----------------------- | O118: ----------------------- | P118: ----------------------- | Q118: ----------------------- | R118: ----------------------- | S118: ----------------------- | T118: ----------------------- | U118: ----------------------- | V118: ----------------------- | W118: ----------------------- | X118: ----------------------- | Y118: ----------------------- | Z118: ----------------------- | AA118: ----------------------- | AC118: ----------------------- | AD118: ----------------------- | AE118: ----------------------- | AF118: ----------------------- | AG118: ----------------------- | AH118: ----------------------- | AI118: ----------------------- | AJ118: ----------------------- | AK118: ----------------------- | AL118: ----------------------- | AM118: -----------------------
A119: =SUM(A9:A118) -> 0 | B119: =SUM(B9:B118) -> 0 | C119: =SUM(C9:C118) -> 1601 | D119: =SUM(D9:D118) -> 20 | E119: =SUM(E9:E118) -> 26931.83 | F119: =SUM(F9:F118) -> 28414.15 | G119: =SUM(G9:G118) -> 397676.68 | H119: =SUM(H9:H118) -> 4500.82 | ... AA119: =SUM(AA9:AA118) -> 32286.74 | AC119: =SUM(AC9:AC118) -> 7439.29 | AD119: =SUM(AD9:AD118) -> 13390.65 | AE119: =SUM(AE9:AE118) -> 36006.34 | AF119: =SUM(AF9:AF118) -> 404965.69 | AG119: =SUM(AG9:AG118) -> 28451.06 | AH119: =SUM(AH9:AH118) -> 8099.28 | AI119: =SUM(AI9:AI118) -> 4806.25 | AJ119: =SUM(AJ9:AJ118) -> 56836.28 | ... AM119: =SUM(AM9:AM118) -> 22121.205
A121: 107 | B121: Nomina | I121: Devengado Salario | J121: =+V119 -> 319330.2
A122: 2 | B122: Altas | I122: Retornos | J122: =+R119 -> 7146.18
A123: 0 | B123: Bajas | I123: Infonavit | J123: =+N119+O119+P119 -> 39195.6
A124: =+A121+A122-A123 -> 109 | B124: Total Nomina | I124: Prestamo Prospera | J124: =+Q119 -> 4763.93
I125: aportacion voluntaria | J125: =+S119 -> 500
I126: Subtotal 1 | J126: =SUM(J121:J125) -> 370935.91
I127: Comision | J127: =+J126*2% -> 7418.7182
I128: Subtotal 2 | J128: =+J126+J127 -> 378354.63
I129: Costo Patronal Imss | J129: =+M119+AC119+AD119+AE119+AG119+AI119+AL119+AK119 -> 145834.12
I130: 2% Sobre Nomina | J130: =+J119*2% -> 8107.1186
I131: Importe de Factura | J131: =+J128+J129+J130 -> 532295.87
I132: certificacion de cheque | J132: 0
I133: IVA | J133: =(+J131+J132)*0.16 -> 85167.339
I134: TOTAL | J134: =+J131+J132+J133 -> 617463.21

Sheet FAC-IP
C2: IP INNOVACION EN PROYECTOS S DE RL DE CV
C3: Lista de Raya (forma tabular)
C4: Reg Pat IMSS: Z2942442109
C5: RFC: IIP -150923-DT7
B8: Código | C8: Empleado | D8: Dias Laborados | E8: Dias Vacaciones | F8: Salario Diario | G8: Salario Diario Integrado | H8: Sueldo | I8: Vacaciones a tiempo | J8: Prima de vacaciones a tiempo | K8: *TOTAL* *PERCEPCIONES* | L8: I.S.R. (sp) | M8: Subsidio al Empleo (sp) | N8: I.M.S.S. | O8: Préstamo Infonavit (vsm) | P8: Préstamo Infonavit (cf) | Q8: Seguro de vivienda Infonavit | R8: Prestamo FONACOT | S8: Deduccion general | T8: Aportación voluntaria SAR | U8: Ajuste al neto | V8: *TOTAL* *DEDUCCIONES* | W8: *NETO* | X8: Ret. Inv. Y Vida | Y8: Ret. Cesantia | Z8: Ret. Enf. y Mat. obrero | AA8: Subs al Empleo acreditado | AB8: I.S.R. antes de Subs al Empleo | AC8: isr 2 | AD8: Invalidez y Vida | AE8: Cesantia y Vejez | AF8: Enf. y Mat. Patron | AG8: Total Percepciones | AH8: 2% Fondo retiro SAR (8) | AI8: 2% Impuesto estatal | AJ8: Riesgo de trabajo (9) | AK8: I.M.S.S. empresa | AL8: Infonavit empresa | AM8: Guarderia I.M.S.S. (7) | AN8: Proporcion Aguinaldo | AO8: FACTURACION
B9: SEI0010 | C9: Torres Ricardez Alfredo | D9: 15 | E9: 0 | F9: 266.67 | G9: 278.72 | H9: 4000.05 | I9: 0 | J9: 0 | K9: 4000.05 | L9: 313.87 | M9: 0 | N9: 100.81 | O9: 0 | P9: 0 | R9: 0 | S9: 0 | T9: 0 | U9: 0.17 | V9: 414.85 | W9: 3585.2 | X9: 26.13 | Y9: 47.03 | Z9: 27.65 | AA9: 0 | AB9: 313.87 | AD9: 73.16 | AE9: 131.7 | AF9: 335.88 | AG9: 4000.05 | AH9: 266.64 | AI9: 80 | AJ9: 47.27 | AK9: 540.74 | AL9: 209.04 | AM9: 224.83 | AN9: 219.0368 | AO9: PITSS
B10: SEI0014 | C10: Montoya Portillo Carlos Alberto | D10: 15 | E10: 0 | F10: 266.67 | G10: 278.72 | H10: 4000.05 | I10: 0 | J10: 0 | K10: 4000.05 | L10: 313.87 | M10: 0 | N10: 100.81 | O10: 0 | P10: 0 | R10: 0 | S10: 0 | T10: 0 | U10: -0.03 | V10: 414.65 | W10: 3585.4 | X10: 26.13 | Y10: 47.03 | Z10: 27.65 | AA10: 0 | AB10: 313.87 | AD10: 73.16 | AE10: 131.7 | AF10: 335.88 | AG10: 4000.05 | AH10: 266.64 | AI10: 80 | AJ10: 47.27 | AK10: 540.74 | AL10: 209.04 | AM10: 224.83 | AN10: 219.0368 | AO10: PITSS
B11: SEI0015 | C11: Cota Jaramillo Miguel Angel | D11: 15 | E11: 0 | F11: 200 | G11: 209.04 | H11: 3000 | I11: 0 | J11: 0 | K11: 3000 | L11: 59.69 | M11: 0 | N11: 74.48 | O11: 0 | P11: 0 | R11: 0 | S11: 0 | T11: 0 | U11: 0.03 | V11: 134.2 | W11: 2865.8 | X11: 19.6 | Y11: 35.28 | Z11: 19.6 | AA11: -145.38 | AB11: 205.07 | AD11: 54.87 | AE11: 98.77 | AF11: 313.41 | AG11: 3000 | AH11: 245.73 | AI11: 60 | AJ11: 35.45 | AK11: 467.05 | AL11: 156.78 | AM11: 214.38 | AN11: 164.27554 | AO11: PITSS
B12: SEI0017 | C12: Muñoz Reyes Luis Eduardo | D12: 15 | E12: 0 | F12: 266.67 | G12: 278.72 | H12: 4000.05 | I12: 0 | J12: 0 | K12: 4000.05 | L12: 313.87 | M12: 0 | N12: 100.81 | O12: 878.36 | P12: 0 | R12: 0 | S12: 0 | T12: 0 | U12: 0.01 | V12: 1293.05 | W12: 2707 | X12: 26.13 | Y12: 47.03 | Z12: 27.65 | AA12: 0 | AB12: 313.87 | AD12: 73.16 | AE12: 131.7 | AF12: 335.88 | AG12: 4000.05 | AH12: 266.64 | AI12: 80 | AJ12: 47.27 | AK12: 540.74 | AL12: 209.04 | AM12: 224.83 | AN12: 219.0368 | AO12: PITSS
B13: SEI0018 | C13: Dominguez Mendez Victor Manuel | D13: 15 | E13: 0 | F13: 300 | G13: 313.56 | H13: 4500 | I13: 0 | J13: 0 | K13: 4500 | L13: 380.67 | M13: 0 | N13: 115.32 | O13: 0 | P13: 0 | R13: 0 | S13: 0 | T13: 0 | U13: 0.01 | V13: 496 | W13: 4004 | X13: 29.4 | Y13: 52.91 | Z13: 33.01 | AA13: 0 | AB13: 380.67 | AD13: 82.31 | AE13: 148.16 | AF13: 350.76 | AG13: 4500 | AH13: 277.09 | AI13: 90 | AJ13: 53.18 | AK13: 581.23 | AL13: 235.17 | AM13: 230.05 | AN13: 246.41332 | AO13: PITSS
B14: SEI0019 | C14: Gonzalez Rasgado Miguel Isaias | D14: 13 | E14: 2 | F14: 400 | G14: 424.2 | H14: 5200 | I14: 800 | J14: 240 | K14: 6240 | L14: 643.38 | M14: 0 | N14: 161.36 | O14: 0 | P14: 0 | R14: 0 | S14: 0 | T14: 0 | U14: 0.06 | V14: 804.8 | W14: 5435.2 | X14: 39.77 | Y14: 71.58 | Z14: 50.01 | AA14: 0 | AB14: 643.38 | AD14: 111.35 | AE14: 200.43 | AF14: 398.06 | AG14: 6240 | AH14: 310.28 | AI14: 124.8 | AJ14: 71.94 | AK14: 709.84 | AL14: 318.15 | AM14: 246.65 | AN14: 328.55109 | AO14: PITSS
B15: SEI0020 | C15: Mar Marquez Cesar Eduardo | D15: 15 | E15: 0 | F15: 266.67 | G15: 278.72 | H15: 4000.05 | I15: 0 | J15: 0 | K15: 4000.05 | L15: 313.87 | M15: 0 | N15: 100.81 | O15: 0 | P15: 0 | R15: 0 | S15: 0 | T15: 0 | U15: -0.03 | V15: 414.65 | W15: 3585.4 | X15: 26.13 | Y15: 47.03 | Z15: 27.65 | AA15: 0 | AB15: 313.87 | AD15: 73.16 | AE15: 131.7 | AF15: 335.88 | AG15: 4000.05 | AH15: 266.64 | AI15: 80 | AJ15: 47.27 | AK15: 540.74 | AL15: 209.04 | AM15: 224.83 | AN15: 219.0368 | AO15: PITSS
B16: SEI0021 | C16: Velez Rodriguez Jaime | D16: 15 | E16: 0 | F16: 200 | G16: 212.1 | H16: 3000 | I16: 0 | J16: 0 | K16: 3000 | L16: 59.69 | M16: 0 | N16: 75.55 | O16: 1362.48 | P16: 0 | R16: 0 | S16: 0 | T16: 0 | U16: -0.12 | V16: 1497.6 | W16: 1502.4 | X16: 19.88 | Y16: 35.79 | Z16: 19.88 | AA16: -145.38 | AB16: 205.07 | AD16: 55.68 | AE16: 100.22 | AF16: 314.22 | AG16: 3000 | AH16: 246.65 | AI16: 60 | AJ16: 35.97 | AK16: 470.12 | AL16: 159.08 | AM16: 214.84 | AN16: 164.27554 | AO16: PITSS
B17: SEI0022 | C17: Najera Lopez Raul | D17: 15 | E17: 0 | F17: 333.33 | G17: 353.5 | H17: 4999.95 | I17: 0 | J17: 0 | K17: 4999.95 | L17: 461.63 | M17: 0 | N17: 131.93 | O17: 0 | P17: 0 | R17: 0 | S17: 0 | T17: 0 | U17: -0.01 | V17: 593.55 | W17: 4406.4 | X17: 33.14 | Y17: 59.65 | Z17: 39.14 | AA17: 0 | AB17: 461.63 | AD17: 92.79 | AE17: 167.03 | AF17: 367.84 | AG17: 4999.95 | AH17: 289.07 | AI17: 100 | AJ17: 59.95 | AK17: 627.66 | AL17: 265.12 | AM17: 236.04 | AN17: 273.78984 | AO17: PITSS
B18: SEI0023 | C18: Puente Murguia Luis Felipe | D18: 15 | E18: 0 | F18: 233.33 | G18: 247.45 | H18: 3499.95 | I18: 0 | J18: 0 | K18: 3499.95 | L18: 134.36 | M18: 0 | N18: 88.16 | O18: 0 | P18: 0 | R18: 0 | S18: 0 | T18: 0 | U18: 0.03 | V18: 222.55 | W18: 3277.4 | X18: 23.2 | Y18: 41.76 | Z18: 23.2 | AA18: -125.1 | AB18: 259.46 | AD18: 64.95 | AE18: 116.92 | AF18: 323.49 | AG18: 3499.95 | AH18: 257.25 | AI18: 70 | AJ18: 41.97 | AK18: 505.36 | AL18: 185.58 | AM18: 220.14 | AN18: 191.65206 | AO18: PITSS
B19: SEI0029 | C19: Arceo Garcia Manuel Federico | D19: 15 | E19: 0 | F19: 200 | G19: 212.1 | H19: 3000 | I19: 0 | J19: 0 | K19: 3000 | L19: 59.69 | M19: 0 | N19: 75.55 | O19: 0 | P19: 0 | R19: 1800 | S19: 0 | T19: 0 | U19: -0.04 | V19: 1935.2 | W19: 1064.8 | X19: 19.88 | Y19: 35.79 | Z19: 19.88 | AA19: -145.38 | AB19: 205.07 | AD19: 55.68 | AE19: 100.22 | AF19: 314.22 | AG19: 3000 | AH19: 246.65 | AI19: 60 | AJ19: 35.97 | AK19: 470.12 | AL19: 159.08 | AM19: 214.84 | AN19: 164.27554 | AO19: PITSS
B20: SEI0364 | C20: Dominguez Lopez Mayeli Del Pilar | D20: 15 | E20: 0 | F20: 266.67 | G20: 282.81 | H20: 4000.05 | I20: 0 | J20: 0 | K20: 4000.05 | L20: 313.87 | M20: 0 | N20: 102.51 | O20: 0 | P20: 0 | R20: 0 | S20: 1666.67 | T20: 0 | U20: 0 | V20: 2083.05 | W20: 1917 | X20: 26.51 | Y20: 47.72 | Z20: 28.28 | AA20: 0 | AB20: 313.87 | AD20: 74.24 | AE20: 133.63 | AF20: 337.62 | AG20: 4000.05 | AH20: 267.86 | AI20: 80 | AJ20: 47.96 | AK20: 545.49 | AL20: 212.11 | AM20: 225.44 | AN20: 219.0368 | AO20: PITSS
... B88: SEI479 | C88: Cruz Perez Alejandro Nezahualcoyotl | D88: 15 | E88: 0 | F88: 266.67 | G88: 282.81 | H88: 4000.05 | I88: 0 | J88: 0 | K88: 4000.05 | L88: 313.87 | M88: 0 | N88: 102.51 | O88: 0 | P88: 0 | R88: 0 | S88: 0 | T88: 0 | U88: 0.07 | V88: 416.45 | W88: 3583.6 | X88: 26.51 | Y88: 47.72 | Z88: 28.28 | AA88: 0 | AB88: 313.87 | AD88: 74.24 | AE88: 133.63 | AF88: 337.62 | AG88: 4000.05 | AH88: 267.86 | AI88: 80 | AJ88: 47.96 | AK88: 545.49 | AL88: 212.11 | AM88: 225.44 | AN88: 219.0368 | AO88: PITSS
A89: Total PITSS | B89: =SUBTOTAL(9,B9:B88) -> 0 | C89: =SUBTOTAL(9,C9:C88) -> 0 | D89: =SUBTOTAL(9,D9:D88) -> 1181 | E89: =SUBTOTAL(9,E9:E88) -> 6 | F89: =SUBTOTAL(9,F9:F88) -> 19133.77 | G89: =SUBTOTAL(9,G9:G88) -> 20176.62 | H89: =SUBTOTAL(9,H9:H88) -> 283739.98 | I89: =SUBTOTAL(9,I9:I88) -> 1666.67 | ... AO89: =SUBTOTAL(9,AO9:AO88) -> 0
B90: SEI0522 | C90: Peña Lopez Abigail | D90: 15 | E90: 0 | F90: 230 | G90: 243.93 | H90: 3450 | I90: 0 | J90: 0 | K90: 3450 | L90: 128.93 | M90: 0 | N90: 86.9 | O90: 0 | P90: 0 | R90: 0 | S90: 0 | T90: 0 | U90: 0.17 | V90: 216 | W90: 3234 | X90: 22.87 | Y90: 41.16 | Z90: 22.87 | AA90: -125.1 | AB90: 254.03 | AD90: 64.03 | AE90: 115.26 | AF90: 322.57 | AG90: 3450 | AH90: 256.2 | AI90: 69 | AJ90: 41.37 | AK90: 501.86 | AL90: 182.95 | AM90: 219.61 | AN90: 188.91688 | AO90: SEITON
B91: SEI0028 | C91: Jimenez Alcaraz Elizabeth | D91: 15 | E91: 0 | F91: 200 | G91: 212.11 | H91: 3000 | I91: 0 | J91: 0 | K91: 3000 | L91: 59.69 | M91: 0 | N91: 75.56 | O91: 0 | P91: 0 | R91: 0 | S91: 0 | T91: 0 | U91: -0.05 | V91: 135.2 | W91: 2864.8 | X91: 19.89 | Y91: 35.79 | Z91: 19.88 | AA91: -145.38 | AB91: 205.07 | AD91: 55.68 | AE91: 100.22 | AF91: 314.22 | AG91: 3000 | AH91: 246.65 | AI91: 60 | AJ91: 35.97 | AK91: 470.12 | AL91: 159.08 | AM91: 214.84 | AN91: 164.27554 | AO91: SEITON
B92: SEI0016 | C92: Negrete Bejar Aide Sarai | D92: 15 | E92: 0 | F92: 154 | G92: 160.96 | H92: 2310 | I92: 0 | J92: 0 | K92: 2310 | L92: 0 | M92: -39.73 | N92: 57.34 | O92: 1188.73 | P92: 0 | R92: 0 | S92: 0 | T92: 0 | U92: 0.06 | V92: 1206.4 | W92: 1103.6 | X92: 15.09 | Y92: 27.16 | Z92: 15.09 | AA92: -174.78 | AB92: 135.05 | AD92: 42.25 | AE92: 76.05 | AF92: 300.79 | AG92: 2310 | AH92: 231.31 | AI92: 46.2 | AJ92: 27.3 | AK92: 419.09 | AL92: 120.72 | AM92: 207.16 | AN92: 126.49217 | AO92: SEITON
B93: SEI0031 | C93: Contreras Zetina Victor Hugo | D93: 15 | E93: 0 | F93: 230 | G93: 243.91 | H93: 3450 | I93: 0 | J93: 0 | K93: 3450 | L93: 128.93 | M93: 0 | N93: 86.9 | O93: 0 | P93: 0 | R93: 0 | S93: 0 | T93: 0 | U93: -0.03 | V93: 215.8 | W93: 3234.2 | X93: 22.87 | Y93: 41.16 | Z93: 22.87 | AA93: -125.1 | AB93: 254.03 | AD93: 64.03 | AE93: 115.25 | AF93: 322.57 | AG93: 3450 | AH93: 256.19 | AI93: 69 | AJ93: 41.37 | AK93: 501.85 | AL93: 182.93 | AM93: 219.61 | AN93: 188.91688 | AO93: SEITON
B94: SEI0037 | C94: Gomez Oliveros Alin | D94: 15 | E94: 0 | F94: 200 | G94: 212.11 | H94: 3000 | I94: 0 | J94: 0 | K94: 3000 | L94: 59.69 | M94: 0 | N94: 75.56 | O94: 0 | P94: 0 | R94: 0 | S94: 0 | T94: 0 | U94: -0.05 | V94: 135.2 | W94: 2864.8 | X94: 19.89 | Y94: 35.79 | Z94: 19.88 | AA94: -145.38 | AB94: 205.07 | AD94: 55.68 | AE94: 100.22 | AF94: 314.22 | AG94: 3000 | AH94: 246.65 | AI94: 60 | AJ94: 35.97 | AK94: 470.12 | AL94: 159.08 | AM94: 214.84 | AN94: 164.27554 | AO94: SEITON
B95: SEI0078 | C95: Aguilar Leal Karina Livier | D95: 15 | E95: 0 | F95: 266.67 | G95: 282.81 | H95: 4000.05 | I95: 0 | J95: 0 | K95: 4000.05 | L95: 313.87 | M95: 0 | N95: 102.51 | O95: 0 | P95: 0 | R95: 0 | S95: 0 | T95: 0 | U95: 0.07 | V95: 416.45 | W95: 3583.6 | X95: 26.51 | Y95: 47.72 | Z95: 28.28 | AA95: 0 | AB95: 313.87 | AD95: 74.24 | AE95: 133.63 | AF95: 337.62 | AG95: 4000.05 | AH95: 267.86 | AI95: 80 | AJ95: 47.96 | AK95: 545.49 | AL95: 212.11 | AM95: 225.44 | AN95: 219.0368 | AO95: SEITON
B96: SEI0079 | C96: Amezcua Contreras Martha Frine | D96: 15 | E96: 0 | F96: 566.67 | G96: 600.98 | H96: 8500.05 | I96: 0 | J96: 0 | K96: 8500.05 | L96: 1177.39 | M96: 0 | N96: 234.96 | O96: 0 | P96: 0 | R96: 0 | S96: 0 | T96: 0 | U96: 0.1 | V96: 1412.45 | W96: 7087.6 | X96: 56.34 | Y96: 101.42 | Z96: 77.2 | AA96: 0 | AB96: 1177.39 | AD96: 157.76 | AE96: 283.96 | AF96: 473.63 | AG96: 8500.05 | AH96: 363.31 | AI96: 170 | AJ96: 101.92 | AK96: 915.35 | AL96: 450.74 | AM96: 273.17 | AN96: 465.45011 | AO96: SEITON
B97: SEI0081 | C97: Guizar Perez Sergio | D97: 15 | E97: 0 | F97: 250 | G97: 265.14 | H97: 3750 | I97: 0 | J97: 0 | K97: 3750 | L97: 286.67 | M97: 0 | N97: 95.15 | O97: 0 | P97: 0 | R97: 0 | S97: 0 | T97: 0 | U97: -0.02 | V97: 381.8 | W97: 3368.2 | X97: 24.86 | Y97: 44.74 | Z97: 25.55 | AA97: 0 | AB97: 286.67 | AD97: 69.6 | AE97: 125.28 | AF97: 330.07 | AG97: 3750 | AH97: 262.56 | AI97: 75 | AJ97: 44.97 | AK97: 524.95 | AL97: 198.86 | AM97: 222.79 | AN97: 205.34443 | AO97: SEITON
B98: SEI0100 | C98: Quinto Valle Martin | D98: 15 | E98: 0 | F98: 333.33 | G98: 353.52 | H98: 4999.95 | I98: 0 | J98: 0 | K98: 4999.95 | L98: 461.63 | M98: 0 | N98: 131.95 | O98: 0 | P98: 0 | R98: 0 | S98: 0 | T98: 500 | U98: -0.03 | V98: 1093.55 | W98: 3906.4 | X98: 33.14 | Y98: 59.66 | Z98: 39.15 | AA98: 0 | AB98: 461.63 | AD98: 92.8 | AE98: 167.04 | AF98: 367.85 | AG98: 4999.95 | AH98: 289.08 | AI98: 100 | AJ98: 59.96 | AK98: 627.69 | AL98: 265.14 | AM98: 236.05 | AN98: 273.78984 | AO98: SEITON
B99: SEI0109 | C99: Negrete Renteria Jose Luis | D99: 15 | E99: 0 | F99: 281.67 | G99: 298.72 | H99: 4225.05 | I99: 0 | J99: 0 | K99: 4225.05 | L99: 338.35 | M99: 0 | N99: 109.14 | O99: 1642.17 | P99: 0 | R99: 0 | S99: 0 | T99: 0 | U99: -0.01 | V99: 2089.65 | W99: 2135.4 | X99: 28.01 | Y99: 50.41 | Z99: 30.72 | AA99: 0 | AB99: 338.35 | AD99: 78.41 | AE99: 141.15 | AF99: 344.43 | AG99: 4225.05 | AH99: 272.64 | AI99: 84.5 | AJ99: 50.66 | AK99: 563.99 | AL99: 224.04 | AM99: 227.83 | AN99: 231.35746 | AO99: SEITON
B100: SEI0126 | C100: Alonso Flores Beda | D100: 15 | E100: 0 | F100: 341.35 | G100: 357.25 | H100: 5120.25 | I100: 0 | J100: 0 | K100: 5120.25 | L100: 483.19 | M100: 0 | N100: 133.51 | O100: 0 | P100: 0 | R100: 0 | S100: 0 | T100: 0 | U100: 0.15 | V100: 616.85 | W100: 4503.4 | X100: 33.49 | Y100: 60.29 | Z100: 39.73 | AA100: 0 | AB100: 483.19 | AD100: 93.78 | AE100: 168.8 | AF100: 369.44 | AG100: 5120.25 | AH100: 290.19 | AI100: 102.41 | AJ100: 60.59 | AK100: 632.02 | AL100: 267.94 | AM100: 236.61 | AN100: 280.37729 | AO100: SEITON
B101: SEI0133 | C101: Romero Mayoral Lorenzo | D101: 13 | E101: 2 | F101: 266.67 | G101: 282.81 | H101: 3466.71 | I101: 533.34 | J101: 160 | K101: 4160.05 | L101: 313.87 | M101: 0 | N101: 102.51 | O101: 1090.32 | P101: 0 | R101: 0 | S101: 0 | T101: 0 | U101: -0.05 | V101: 1506.65 | W101: 2653.4 | X101: 26.51 | Y101: 47.72 | Z101: 28.28 | AA101: 0 | AB101: 313.87 | AD101: 74.24 | AE101: 133.63 | AF101: 337.62 | AG101: 4160.05 | AH101: 267.86 | AI101: 83.2 | AJ101: 47.96 | AK101: 545.49 | AL101: 212.11 | AM101: 225.44 | AN101: 219.0368 | AO101: SEITON
... B118: SEI0518 | C118: Amezcua Magaña Tania Estefania | D118: 15 | E118: 0 | F118: 233.33 | G118: 243.88 | H118: 3499.95 | I118: 0 | J118: 0 | K118: 3499.95 | L118: 134.36 | M118: 0 | N118: 86.88 | O118: 0 | P118: 0 | R118: 0 | S118: 0 | T118: 0 | U118: 0.11 | V118: 221.35 | W118: 3278.6 | X118: 22.86 | Y118: 41.15 | Z118: 22.87 | AA118: -125.1 | AB118: 259.46 | AD118: 64.02 | AE118: 115.23 | AF118: 322.56 | AG118: 3499.95 | AH118: 256.18 | AI118: 70 | AJ118: 41.36 | AK118: 501.81 | AL118: 182.91 | AM118: 219.6 | AN118: 191.65206 | AO118: SEITON
A119: Total SEITON | B119: =SUBTOTAL(9,B92:B118) -> 0 | C119: =SUBTOTAL(9,C92:C118) -> 0 | D119: =SUBTOTAL(9,D90:D118) -> 420 | E119: =SUBTOTAL(9,E90:E118) -> 14 | F119: =SUBTOTAL(9,F90:F118) -> 7798.06 | G119: =SUBTOTAL(9,G90:G118) -> 8237.53 | H119: =SUBTOTAL(9,H90:H118) -> 113936.7 | I119: =SUBTOTAL(9,I90:I118) -> 2834.15 | J119: =SUBTOTAL(9,J90:J118) -> 850.24 | K119: =SUBTOTAL(9,K90:K118) -> 117621.09 | ... AN119: =SUBTOTAL(9,AN90:AN118) -> 6405.1528 | AO119: =SUBTOTAL(9,AO92:AO118) -> 0
B120: Total Depto | D120: ----------------------- | E120: ----------------------- | F120: ----------------------- | G120: ----------------------- | H120: ----------------------- | I120: ----------------------- | J120: ----------------------- | K120: ----------------------- | L120: ----------------------- | M120: ----------------------- | N120: ----------------------- | O120: ----------------------- | P120: ----------------------- | Q120: ----------------------- | R120: ----------------------- | S120: ----------------------- | T120: ----------------------- | U120: ----------------------- | V120: ----------------------- | W120: ----------------------- | X120: ----------------------- | Y120: ----------------------- | Z120: ----------------------- | AA120: ----------------------- | AB120: ----------------------- | AD120: ----------------------- | AE120: ----------------------- | AF120: ----------------------- | AG120: ----------------------- | AH120: ----------------------- | AI120: ----------------------- | AJ120: ----------------------- | AK120: ----------------------- | AL120: ----------------------- | AM120: ----------------------- | AN120: -----------------------
B121: =SUM(B9:B120) -> 0 | C121: =SUM(C9:C120) -> 0 | D121: =+D89+D119 -> 1601 | E121: =+E89+E119 -> 20 | F121: =+F89+F119 -> 26931.83 | G121: =+G89+G119 -> 28414.15 | H121: =+H89+H119 -> 397676.68 | I121: =+I89+I119 -> 4500.82 | J121: =+J89+J119 -> 3178.43 | K121: =+K89+K119 -> 405355.93 | ... AO121: =+AO89+AO119 -> 0
J122: FACTURACION PITS | L122: FACTURACION SEITON
B123: 107 | C123: Nomina | J123: Devengado Salario | K123: =+W89 -> 224113 | L123: Devengado Salario | M123: =+W119 -> 95217.2
B124: 2 | C124: Altas | J124: Retornos | K124: =+S89 -> 7146.18 | L124: Retornos | M124: =+S119 -> 0
B125: 0 | C125: Bajas | J125: Infonavit | K125: =+O89+P89+Q89 -> 28576.72 | L125: Infonavit | M125: =+O119+P119+Q119 -> 10618.88
B126: =+B123+B124-B125 -> 109 | C126: Total Nomina | J126: Prestamo Fonacot | K126: =+R89 -> 4763.93 | L126: Prestamo Fonacot | M126: =+R119 -> 0
...

Sheet SINDICATO
A5: 1 | B5: 2 | C5: 3 | F5: 4 | G5: 5 | H5: 6
A6: CLAVE | B6: EMPRESA | C6: NOMBRE | F6: PAGO POR SINDICATO | G6: comision y bono | H6: prima vacaciones | I6: TOTAL | J6: DIAS DE VACACIONES | K6: SUELDO NETO MENSUAL | L6: MONTO PRIMA TOTAL | M6: MENOS PRIMA IMSS | N6: PRIMA A PAGAR SINDICATO | Q6: FACTURACION
A7: SEI0097 | B7: SEITON - (CONSULTORIA II) | C7: Arreola Jimenez Jose Nieves | F7: 1557.91 | G7: 432.22 | H7: =+N7 -> 0 | I7: =+F7+G7+H7 -> 1990.13 | J7: =VLOOKUP(C7,CPD!$B$9:$D$37,3,0) -> 0 | K7: =VLOOKUP(C7,RESUMEN!$C$4:$L$121,10,) -> 10150 | L7: =(((+K7/30)*J7)*30%) -> 0 | M7: =VLOOKUP(C7,CPD!$B$9:$I$37,8,0) -> 0 | N7: =+L7-M7 -> 0 | O7: =VLOOKUP(C7,RESUMEN!$C$4:$Z$133,24,0) -> 0 | Q7: PITSS
A8: SEI0118 | B8: SEITON - (CONSULTORIA II) | C8: Arroyo Ramirez Hector Hugo | F8: 2102.87 | G8: 200 | H8: =+N8 -> 234.01 | I8: =+F8+G8+H8 -> 2536.88 | J8: 4 | K8: =VLOOKUP(C8,RESUMEN!$C$4:$L$121,10,) -> 13000 | L8: =(((+K8/30)*J8)*30%) -> 520 | M8: =VLOOKUP(C8,CPD!$B$9:$I$37,8,0) -> 285.99 | N8: =+L8-M8 -> 234.01 | O8: =VLOOKUP(C8,RESUMEN!$C$4:$Z$133,24,0) -> 0 | Q8: PITSS
