Workbook

Sheet FACTURACION SINDICATO
B2: codigo | C2: empres | D2: nombre | E2: PAGO POR SINDICATO | F2: comision y bono | G2: prima vacaciones | H2: TOTAL | I2: CC
B3: SEI0097 | C3: SEITON - (CONSULTORIA II) | D3: Arreola Jimenez Jose Nieves | E3: 1558.05 | F3: 2975 | G3: 0 | H3: 4533.05 | I3: AA
B4: SEI0118 | C4: SEITON - (CONSULTORIA II) | D4: Arroyo Ramirez Hector Hugo | E4: 2103.54 | G4: 234 | H4: 2337.54 | I4: AA
B5: SEI0108 | C5: SEITON - (CONSULTORIA II) | D5: Caballero Diaz Francisco Javier | E5: 1558.01 | G5: 0 | H5: 1558.01 | I5: AA
B6: SEI0425 | C6: SEITON - (CONSULTORIA II) | D6: Carbajal Cabuto Jose Luis | E6: 1608.07 | G6: 0 | H6: 1608.07 | I6: AA
B7: SEI0116 | C7: SEITON - (CONSULTORIA II) | D7: Casillas Cardona Cesar Alejandro | E7: 1891.22 | G7: 0 | H7: 1891.22 | I7: AA
B8: SEI0401 | C8: SEITON - (CONSULTORIA II) | D8: De La Torre Zambara Francisco Ernesto | E8: 78.08 | G8: 0 | H8: 78.08 | I8: AA
B9: SEI0119 | C9: SEITON - (CONSULTORIA II) | D9: Dominguez Lopez Maria De Jesus | E9: 0 | G9: 0 | H9: 0 | I9: AA
B10: SEI0099 | C10: SEITON - (CONSULTORIA II) | D10: Garcia Villicaña Ricardo Pascual | E10: 2600.8 | F10: 600 | G10: 0 | H10: 3200.8 | I10: AA
B11: SEI0009 | C11: SEITON - (CONSULTORIA II) | D11: Gutierrez Gutierrez Luis Arturo | E11: 1474.6 | G11: 0 | H11: 1474.6 | I11: AA
B12: SEI0127 | C12: SEITON - (CONSULTORIA II) | D12: Hernandez Ochoa Eduardo | E12: 2601 | G12: 0 | H12: 2601 | I12: AA
B13: SEI0088 | C13: SEITON - (CONSULTORIA II) | D13: Morgado Fernandez Martin | E13: 2601 | F13: 1125 | G13: 0 | H13: 3726 | I13: AA
B14: SEI0173 | C14: SEITON - (CONSULTORIA II) | D14: Nieto Ortiz Jose Luis | E14: 1483.15 | F14: 1232 | G14: 0 | H14: 2715.15 | I14: AA
B15: SEI0026 | C15: SEITON - (CONSULTORIA II) | D15: Patricio Aguilar Jhonattan Cristian | E15: 1588 | G15: 0 | H15: 1588 | I15: AA
B16: SEI0027 | C16: SEITON - (CONSULTORIA II) | D16: Tavares Guzman Jose Enrique | E16: 2378.2 | G16: 0 | H16: 2378.2 | I16: AA
B17: SEI032 | C17: SEITON - (CONSULTORIA II) | D17: Camarena Quiroz Erick Frank | E17: 1588 | F17: 225 | G17: 0 | H17: 1813 | I17: AA
B18: SEI0438 | C18: SEITON - (CONSULTORIA II) | D18: Valdes Arrioja Karla Naborina | E18: 1803.2 | H18: 1803.2 | I18: AA
B19: SEI0482 | C19: SEITON (IP INNOVA II) | D19: Camarillo Canela Reynaldo | E19: 2236.64 | F19: 2150 | G19: 0 | H19: 4386.64 | I19: AA
B20: SEI0485 | C20: SEITON (IP INNOVA II) | D20: Molina Ramirez Gerardo Daniel | E20: 2271.77 | G20: 0 | H20: 2271.77 | I20: AA
B21: SEI0488 | C21: SEITON (IP INNOVA II) | D21: Mireles Casillas Brenda Cristina | E21: 2257 | G21: 0 | H21: 2257 | I21: AA
B22: SEI0489 | C22: SEITON (IP INNOVA II) | D22: Escobedo Olivares Juan Guadalupe | E22: 3723.8 | G22: 0 | H22: 3723.8 | I22: AA
B23: SEI0490 | C23: SEITON (IP INNOVA II) | D23: Castillo Ramirez Hector Ivan | E23: 3753.78 | F23: 1280 | G23: 0 | H23: 5033.78 | I23: AA
B24: SEI0492 | C24: SEITON (IP INNOVA II) | D24: Cadena Ramirez Hugo | E24: 2513.4 | G24: 0 | H24: 2513.4 | I24: AA
B25: SEI0493 | C25: SEITON (IP INNOVA II) | D25: Martinez Morales Tomas | E25: 3397.14 | F25: 1320 | G25: 0 | H25: 4717.14 | I25: AA
B26: SEI0494 | C26: SEITON (IP INNOVA II) | D26: Medellin Colunga Ruben Dario | E26: 4412.14 | F26: 2320 | G26: 0 | H26: 6732.14 | I26: AA
B27: SEI0495 | C27: SEITON (IP INNOVA II) | D27: Torres Perez Carlos Alberto | E27: 1685.3 | F27: 4495 | G27: 0 | H27: 6180.3 | I27: AA
B28: SEI0496 | C28: SEITON (IP INNOVA II) | D28: Velazquez Herrera Nayeli | E28: 3382.26 | F28: 950 | G28: 56.14 | H28: 4388.4 | I28: AA
B29: SEI0497 | C29: SEITON (IP INNOVA II) | D29: Treviño Alvarez Jorge Alberto | E29: 2700.29 | F29: 680 | G29: 0 | H29: 3380.29 | I29: AA
B30: SEI0498 | C30: SEITON (IP INNOVA II) | D30: Tenorio Alvarez Alberto Antonio | E30: 1685.2 | G30: 0 | H30: 1685.2 | I30: AA
B31: SEI0499 | C31: SEITON (IP INNOVA II) | D31: Chavez Dominguez Salvador | E31: 2685.2 | G31: 0 | H31: 2685.2 | I31: AA
B32: SEI0500 | C32: SEITON (IP INNOVA II) | D32: Garcia Gutierrez Jose Juan | E32: 1685.2 | G32: 0 | H32: 1685.2 | I32: AA
B33: SEI0501 | C33: SEITON (IP INNOVA II) | D33: Cruz Herrera Roberto | E33: 1670.2 | G33: 0 | H33: 1670.2 | I33: AA
B34: SEI0502 | C34: SEITON (IP INNOVA II) | D34: Dominguez Escamilla Victor Hugo | E34: 2700.14 | G34: 0 | H34: 2700.14 | I34: AA
B35: SEI0503 | C35: SEITON (IP INNOVA II) | D35: Martinez Rodriguez Paulo Cesar | E35: 2554.8 | G35: 0 | H35: 2554.8 | I35: AA
B36: SEI0504 | C36: SEITON (IP INNOVA II) | D36: Martinez Malo Cesar | E36: 1711.46 | G36: 0 | H36: 1711.46 | I36: AA
B37: SEI0505 | C37: SEITON (IP INNOVA II) | D37: Perez Balboa Cesar | E37: 2211.65 | G37: 0 | H37: 2211.65 | I37: AA
B38: SEI0506 | C38: SEITON (IP INNOVA II) | D38: Mejia Duarte Jose Luis | E38: 2570.57 | G38: 0 | H38: 2570.57 | I38: AA
B39: SEI0507 | C39: SEITON (IP INNOVA II) | D39: Diaz Saldierna Leonel Gonzalo | E39: 2585.53 | G39: 0 | H39: 2585.53 | I39: AA
B40: SEI0508 | C40: SEITON (IP INNOVA II) | D40: Cerro Garcia Elvis | E40: 2570.6 | F40: 2125 | G40: 0 | H40: 4695.6 | I40: AA
B41: SEI0078 | C41: SEITON (IP INNOVA II) | D41: Aguilar Leal Karina Livier | E41: 952.25 | F41: 16065.1 | G41: 10 | H41: 17027.35 | I41: AA
...

Sheet CPD PITS
B2: CONSULTORIA EN PROYECTOS DINAMICOS S DE RL DE CV
B3: Lista de Raya (forma tabular)
B4: Reg Pat IMSS: Z2940859106
B5: RFC: CPD -150911-FA3
A8: Código | B8: Empleado | C8: Dias Laborados | D8: Dias Vacaciones | E8: Salario Diario | F8: Salario Diario Integrado | G8: Sueldo | H8: Vacaciones a tiempo | I8: Prima de vacaciones a tiempo | J8: Ayuda de Transporte | K8: Ayuda Alimentaria | L8: Ayuda de Renta | M8: *TOTAL* *PERCEPCIONES* | N8: I.S.R. (sp) | O8: Subsidio al Empleo (sp) | P8: I.M.S.S. | Q8: Préstamo Infonavit | R8: Préstamo Infonavit (vsm) | S8: Préstamo Infonavit (cf) | T8: Seguro de vivienda Infonavit | U8: Prestamo Empresa | V8: Deduccion general | W8: Ajuste al neto | X8: *TOTAL* *DEDUCCIONES* | Y8: *NETO* | Z8: Ret. Inv. Y Vida | AA8: Ret. Cesantia | AB8: Ret. Enf. y Mat. obrero | AC8: Subs al Empleo acreditado | AD8: I.S.R. antes de Subs al Empleo | AE8: isr 2 | AF8: Invalidez y Vida | AG8: Cesantia y Vejez | AH8: Enf. y Mat. Patron | AI8: Total Percepciones | AJ8: 2% Fondo retiro SAR (8) | AK8: 2% Impuesto estatal | AL8: Riesgo de trabajo (9) | AM8: I.M.S.S. empresa | AN8: Infonavit empresa | AO8: Guarderia I.M.S.S. (7) | AP8: Proporcion Aguinaldo | AQ8: FACTURACION
A9: SEI0009 | B9: Gutierrez Gutierrez Luis Arturo | C9: 15 | D9: 0 | E9: 141.67 | F9: 150.25 | G9: 2125.05 | H9: 0 | I9: 0 | J9: 212.51 | K9: 212.51 | L9: 212.51 | M9: 2762.58 | N9: 0 | O9: -65.5 | P9: 53.52 | Q9: 0 | R9: 0 | T9: 0 | V9: 0 | W9: -0.04 | X9: -12.02 | Y9: 2774.6 | Z9: 14.09 | AA9: 25.35 | AB9: 14.08 | AC9: -188.71 | AD9: 123.22 | AF9: 39.44 | AG9: 70.99 | AH9: 297.98 | AI9: 2762.58 | AJ9: 254.91 | AK9: 55.25 | AL9: 11.27 | AM9: 408.41 | AN9: 112.69 | AO9: 232.37 | AP9: 151.27396 | AQ9: PITSS
A10: SEI0026 | B10: Patricio Aguilar Jhonattan Cristian | C10: 15 | D10: 0 | E10: 150 | F10: 159.07 | G10: 2250 | H10: 0 | I10: 0 | J10: 225 | K10: 225 | L10: 225 | M10: 2925 | N10: 0 | O10: -43.57 | P10: 56.67 | Q10: 0 | R10: 0 | T10: 0 | V10: 0 | W10: 0.1 | X10: 13.2 | Y10: 2911.8 | Z10: 14.91 | AA10: 26.84 | AB10: 14.92 | AC10: -174.78 | AD10: 131.21 | AF10: 41.76 | AG10: 75.16 | AH10: 300.29 | AI10: 2925 | AJ10: 257.55 | AK10: 58.5 | AL10: 11.93 | AM10: 417.21 | AN10: 119.31 | AO10: 233.69 | AP10: 160.16866 | AQ10: PITSS
A11: SEI0040 | B11: Mora Ramirez Acal Aldo Isidro | C11: 15 | D11: 0 | E11: 216.67 | F11: 229.79 | G11: 3250.05 | H11: 0 | I11: 0 | J11: 325.01 | K11: 325.01 | L11: 325.01 | M11: 4225.08 | N11: 107.17 | O11: 0 | P11: 81.87 | Q11: 0 | R11: 0 | T11: 0 | V11: 0 | W11: 0.04 | X11: 189.08 | Y11: 4036 | Z11: 21.54 | AA11: 38.78 | AB11: 21.55 | AC11: -125.1 | AD11: 232.27 | AF11: 60.32 | AG11: 108.58 | AH11: 318.86 | AI11: 4225.08 | AJ11: 278.77 | AK11: 84.5 | AL11: 17.23 | AM11: 487.76 | AN11: 172.34 | AO11: 244.3 | AP11: 231.35828 | AQ11: PITSS
A12: SEI0041 | B12: Vazquez Perez Miguel Angel | C12: 15 | D12: 0 | E12: 283.33 | F12: 300.49 | G12: 4249.95 | H12: 0 | I12: 0 | J12: 425 | K12: 425 | L12: 425 | M12: 5524.95 | N12: 341.06 | O12: 0 | P12: 109.87 | Q12: 0 | R12: 0 | T12: 0 | V12: 0 | W12: 0.02 | X12: 450.95 | Y12: 5074 | Z12: 28.17 | AA12: 50.71 | AB12: 30.99 | AC12: 0 | AD12: 341.06 | AF12: 78.88 | AG12: 141.98 | AH12: 345.18 | AI12: 5524.95 | AJ12: 299.98 | AK12: 110.5 | AL12: 22.54 | AM12: 566.04 | AN12: 225.37 | AO12: 254.9 | AP12: 302.53724 | AQ12: PITSS
A13: SEI0088 | B13: Morgado Fernandez Martin | C13: 15 | D13: 0 | E13: 273.33 | F13: 289.87 | G13: 4099.95 | H13: 0 | I13: 0 | J13: 410 | K13: 410 | L13: 410 | M13: 5329.95 | N13: 324.74 | O13: 0 | P13: 105.46 | Q13: 0 | R13: 0 | T13: 0 | V13: 0 | W13: 0.15 | X13: 430.35 | Y13: 4899.6 | Z13: 27.18 | AA13: 48.92 | AB13: 29.36 | AC13: 0 | AD13: 324.74 | AF13: 76.09 | AG13: 136.96 | AH13: 340.64 | AI13: 5329.95 | AJ13: 296.79 | AK13: 106.6 | AL13: 21.74 | AM13: 553.69 | AN13: 217.4 | AO13: 253.31 | AP13: 291.85933 | AQ13: PITSS
A14: SEI0097 | B14: Arreola Jimenez Jose Nieves | C14: 15 | D14: 0 | E14: 185.83 | F14: 197.07 | G14: 2787.45 | H14: 0 | I14: 0 | J14: 278.75 | K14: 278.75 | L14: 278.75 | M14: 3623.7 | N14: 36.57 | O14: 0 | P14: 70.22 | Q14: 0 | R14: 1574.29 | T14: 15 | V14: 0 | W14: 0.02 | X14: 1696.1 | Y14: 1927.6 | Z14: 18.48 | AA14: 33.26 | AB14: 18.48 | AC14: -145.38 | AD14: 181.94 | AF14: 51.73 | AG14: 93.12 | AH14: 310.27 | AI14: 3623.7 | AJ14: 268.95 | AK14: 72.47 | AL14: 14.78 | AM14: 455.12 | AN14: 147.8 | AO14: 239.39 | AP14: 198.42761 | AQ14: PITSS
A15: SEI0099 | B15: Garcia Villicaña Ricardo Pascual | C15: 15 | D15: 0 | E15: 273.33 | F15: 289.87 | G15: 4099.95 | H15: 0 | I15: 0 | J15: 410 | K15: 410 | L15: 410 | M15: 5329.95 | N15: 324.74 | O15: 0 | P15: 105.46 | Q15: 0 | R15: 0 | T15: 0 | V15: 0 | W15: -0.05 | X15: 430.15 | Y15: 4899.8 | Z15: 27.18 | AA15: 48.92 | AB15: 29.36 | AC15: 0 | AD15: 324.74 | AF15: 76.09 | AG15: 136.96 | AH15: 340.64 | AI15: 5329.95 | AJ15: 296.79 | AK15: 106.6 | AL15: 21.74 | AM15: 553.69 | AN15: 217.4 | AO15: 253.31 | AP15: 291.85933 | AQ15: PITSS
A16: SEI0108 | B16: Caballero Diaz Francisco Javier | C16: 15 | D16: 0 | E16: 185.83 | F16: 197.07 | G16: 2787.45 | H16: 0 | I16: 0 | J16: 278.75 | K16: 278.75 | L16: 278.75 | M16: 3623.7 | N16: 36.57 | O16: 0 | P16: 70.22 | Q16: 0 | R16: 1826.51 | T16: 15 | V16: 0 | W16: 0 | X16: 1948.3 | Y16: 1675.4 | Z16: 18.48 | AA16: 33.26 | AB16: 18.48 | AC16: -145.38 | AD16: 181.94 | AF16: 51.73 | AG16: 93.12 | AH16: 310.27 | AI16: 3623.7 | AJ16: 268.95 | AK16: 72.47 | AL16: 14.78 | AM16: 455.12 | AN16: 147.8 | AO16: 239.39 | AP16: 198.42761 | AQ16: PITSS
A17: SEI0116 | B17: Casillas Cardona Cesar Alejandro | C17: 15 | D17: 0 | E17: 220.83 | F17: 234.19 | G17: 3312.45 | H17: 0 | I17: 0 | J17: 331.25 | K17: 331.25 | L17: 331.25 | M17: 4306.2 | N17: 113.96 | O17: 0 | P17: 83.43 | Q17: 0 | R17: 757.32 | T17: 15 | V17: 0 | W17: -0.11 | X17: 969.6 | Y17: 3336.6 | Z17: 21.96 | AA17: 39.52 | AB17: 21.95 | AC17: -125.1 | AD17: 239.06 | AF17: 61.47 | AG17: 110.65 | AH17: 320.01 | AI17: 4306.2 | AJ17: 280.09 | AK17: 86.12 | AL17: 17.56 | AM17: 492.13 | AN17: 175.64 | AO17: 244.96 | AP17: 235.8003 | AQ17: PITSS
A18: SEI0117 | B18: Mariscal Romero Luis Adrian | C18: 15 | D18: 0 | E18: 264.58 | F18: 276.54 | G18: 3968.7 | H18: 0 | I18: 0 | J18: 396.87 | K18: 396.87 | L18: 396.87 | M18: 5159.31 | N18: 310.46 | O18: 0 | P18: 99.91 | Q18: 0 | R18: 1674 | T18: 15 | V18: 0 | W18: -0.06 | X18: 2099.31 | Y18: 3060 | Z18: 25.93 | AA18: 46.67 | AB18: 27.31 | AC18: 0 | AD18: 310.46 | AF18: 72.59 | AG18: 130.66 | AH18: 334.94 | AI18: 5159.31 | AJ18: 292.79 | AK18: 103.19 | AL18: 20.74 | AM18: 538.19 | AN18: 207.4 | AO18: 251.31 | AP18: 282.51615 | AQ18: PITSS
A19: SEI0118 | B19: Arroyo Ramirez Hector Hugo | C19: 15 | D19: 0 | E19: 238.33 | F19: 252.75 | G19: 3574.95 | H19: 0 | I19: 285.99 | J19: 357.5 | K19: 357.5 | L19: 357.5 | M19: 4933.44 | N19: 160.25 | O19: 0 | P19: 90.05 | Q19: 0 | R19: 1432.4 | T19: 15 | V19: 268.35 | W19: -0.01 | X19: 1966.04 | Y19: 2967.4 | Z19: 23.7 | AA19: 42.65 | AB19: 23.7 | AC19: -107.37 | AD19: 267.62 | AF19: 66.35 | AG19: 119.42 | AH19: 324.89 | AI19: 4933.44 | AJ19: 285.65 | AK19: 98.67 | AL19: 18.96 | AM19: 510.66 | AN19: 189.56 | AO19: 247.74 | AP19: 254.48664 | AQ19: PITSS
A20: SEI0127 | B20: Hernandez Ochoa Eduardo | C20: 15 | D20: 0 | E20: 273.33 | F20: 289.87 | G20: 4099.95 | H20: 0 | I20: 0 | J20: 410 | K20: 410 | L20: 410 | M20: 5329.95 | N20: 324.74 | O20: 0 | P20: 105.46 | Q20: 0 | R20: 0 | T20: 0 | V20: 0 | W20: -0.05 | X20: 430.15 | Y20: 4899.8 | Z20: 27.18 | AA20: 48.92 | AB20: 29.36 | AC20: 0 | AD20: 324.74 | AF20: 76.09 | AG20: 136.96 | AH20: 340.64 | AI20: 5329.95 | AJ20: 296.79 | AK20: 106.6 | AL20: 21.74 | AM20: 553.69 | AN20: 217.4 | AO20: 253.31 | AP20: 291.85933 | AQ20: PITSS
... A27: SEI0445 | B27: Muñoz Melgoza Gabriel | C27: 15 | D27: 0 | E27: 256.67 | F27: 272.21 | G27: 3850.05 | H27: 0 | I27: 0 | J27: 385.01 | K27: 385.01 | L27: 385.01 | M27: 5005.08 | N27: 297.55 | O27: 0 | P27: 98.1 | Q27: 0 | R27: 0 | T27: 0 | V27: 0 | W27: 0.03 | X27: 395.68 | Y27: 4609.4 | Z27: 25.52 | AA27: 45.94 | AB27: 26.64 | AC27: 0 | AD27: 297.55 | AF27: 71.46 | AG27: 128.62 | AH27: 333.08 | AI27: 5005.08 | AJ27: 291.49 | AK27: 100.1 | AL27: 20.42 | AM27: 533.16 | AN27: 204.16 | AO27: 250.66 | AP27: 274.06993 | AQ27: PITSS
A28: Total Depto | C28: ----------------------- | D28: ----------------------- | E28: ----------------------- | F28: ----------------------- | G28: ----------------------- | H28: ----------------------- | I28: ----------------------- | J28: ----------------------- | K28: ----------------------- | L28: ----------------------- | M28: ----------------------- | N28: ----------------------- | O28: ----------------------- | P28: ----------------------- | Q28: ----------------------- | R28: ----------------------- | S28: ----------------------- | T28: ----------------------- | U28: ----------------------- | V28: ----------------------- | W28: ----------------------- | X28: ----------------------- | Y28: ----------------------- | Z28: ----------------------- | AA28: ----------------------- | AB28: ----------------------- | AC28: ----------------------- | AD28: ----------------------- | AF28: ----------------------- | AG28: ----------------------- | AH28: ----------------------- | AI28: ----------------------- | AJ28: ----------------------- | AK28: ----------------------- | AL28: ----------------------- | AM28: ----------------------- | AN28: ----------------------- | AO28: ----------------------- | AP28: -----------------------
A29: =SUM(A9:A28) -> 0 | B29: =SUM(B9:B28) -> 0 | C29: =SUM(C9:C28) -> 285 | D29: =SUM(D9:D28) -> 0 | E29: =SUM(E9:E28) -> 4965.39 | F29: =SUM(F9:F28) -> 5261.86 | G29: =SUM(G9:G28) -> 74480.85 | H29: =SUM(H9:H28) -> 0 | ... AP29: =SUM(AP9:AP28) -> 5301.999
L31: FACTURACON PITS | O31: PROVISION AGUINALDO
L32: Devengado Salario | M32: =+Y29 -> 77805.4 | O32: FACTURACION PITS
L33: RETORNOS | M33: =+V29 -> 999.15 | O33: Subtotal 1 | P33: =+AP29 -> 5301.999
L34: Infonavit | M34: =+S29+R29+Q29+T29 -> 11045.69 | O34: Comision | P34: =+P33*2% -> 106.03998
L35: Prestamo Prospera | M35: =+U29 -> 0 | O35: Subtotal 2 | P35: =+P33+P34 -> 5408.0389
L36: Subtotal 1 | M36: =SUM(M32:M35) -> 89850.24 | O36: 2% Sobre Nomina | P36: =+P33*2% -> 106.03998
L37: Comision | M37: =+M36*2% -> 1797.0048 | O37: Importe de Factura | P37: =+P35+P36 -> 5514.0789
L38: Subtotal 2 | M38: =+M36+M37 -> 91647.245 | O38: IVA | P38: =+P37*16% -> 882.25263
L39: Costo Patronal Imss | M39: =+P29+AF29+AG29+AH29+AJ29+AL29+AN29+AO29 -> 26958.66 | O39: TOTAL | P39: =+P37+P38 -> 6396.3315
L40: 2% Sobre Nomina | M40: =+M29*2% -> 1942.227
L41: Importe de Factura | M41: =+M38+M39+M40 -> 120548.13
L42: IVA | M42: =+M41*16% -> 19287.701
L43: TOTAL | M43: =+M41+M42 -> 139835.83
H44: FACTURACION EM | K44: FACTURACION CPD | N44: FACTURACION IP | Q44: FACTURACION IT
H45: Importe de Factura | I45: =+M41*4% -> 4821.9253 | K45: Importe de Factura | L45: =+M41*12% -> 14465.776 | N45: Importe de Factura | O45: =+M41*11% -> 13260.294 | Q45: Importe de Factura | R45: =+M41*73% -> 88000.136
H46: IVA | I46: =+I45*16% -> 771.50804 | K46: IVA | L46: =+L45*16% -> 2314.5241 | N46: IVA | O46: =+O45*16% -> 2121.6471 | Q46: IVA | R46: =+R45*16% -> 14080.022
H47: TOTAL | I47: =+I45+I46 -> 5593.4333 | K47: TOTAL | L47: =+L45+L46 -> 16780.3 | N47: TOTAL | O47: =+O45+O46 -> 15381.942 | Q47: TOTAL | R47: =+R45+R46 -> 102080.16
H50: FACTURACION EM | K50: FACTURACION CPD | N50: FACTURACION IP | Q50: FACTURACION IT
H51: Importe de Factura | I51: =+P37*4% -> 220.56316 | K51: Importe de Factura | L51: =+P37*12% -> 661.68947 | N51: Importe de Factura | O51: =+P37*11% -> 606.54868 | Q51: Importe de Factura | R51: =+P37*73% -> 4025.2776
H52: IVA | I52: =+I51*16% -> 35.290105 | K52: IVA | L52: =+L51*16% -> 105.87032 | N52: IVA | O52: =+O51*16% -> 97.047789 | Q52: IVA | R52: =+R51*16% -> 644.04442
...

Sheet IP PITS
B2: IP INNOVACION EN PROYECTOS S DE RL DE CV
B3: Lista de Raya (forma tabular)
B4: Reg Pat IMSS: Z2942442109
B5: RFC: IIP -150923-DT7
A8: Código | B8: Empleado | C8: Dias Laborados | D8: Dias Vacaciones | E8: Salario Diario | F8: Salario Diario Integrado | G8: Sueldo | H8: Vacaciones a tiempo | I8: Prima de vacaciones a tiempo | J8: *TOTAL* *PERCEPCIONES* | K8: I.S.R. (sp) | L8: Subsidio al Empleo (sp) | M8: I.M.S.S. | N8: Préstamo Infonavit (vsm) | O8: Préstamo Infonavit (cf) | P8: Seguro de vivienda Infonavit | Q8: Prestamo FONACOT | R8: Deduccion general | S8: Aportación voluntaria SAR | T8: Ajuste al neto | U8: *TOTAL* *DEDUCCIONES* | V8: *NETO* | W8: Ret. Inv. Y Vida | X8: Ret. Cesantia | Y8: Ret. Enf. y Mat. obrero | Z8: Subs al Empleo acreditado | AA8: I.S.R. antes de Subs al Empleo | AB8: isr 2 | AC8: Invalidez y Vida | AD8: Cesantia y Vejez | AE8: Enf. y Mat. Patron | AF8: Total Percepciones | AG8: 2% Fondo retiro SAR (8) | AH8: 2% Impuesto estatal | AI8: Riesgo de trabajo (9) | AJ8: I.M.S.S. empresa | AK8: Infonavit empresa | AL8: Guarderia I.M.S.S. (7) | AM8: Proporcion Aguinaldo | AN8: CC
A9: SEI0010 | B9: Torres Ricardez Alfredo | C9: 15 | D9: 0 | E9: 266.67 | F9: 278.72 | G9: 4000.05 | H9: 0 | I9: 0 | J9: 4000.05 | K9: 313.87 | L9: 0 | M9: 100.81 | N9: 0 | O9: 0 | P9: 0 | Q9: 0 | R9: 0 | T9: -0.03 | U9: 414.65 | V9: 3585.4 | W9: 26.13 | X9: 47.03 | Y9: 27.65 | Z9: 0 | AA9: 313.87 | AC9: 73.16 | AD9: 131.7 | AE9: 335.88 | AF9: 4000.05 | AG9: 268.34 | AH9: 80 | AI9: 33.3 | AJ9: 540.74 | AK9: 209.04 | AL9: 226.53 | AM9: 219.0368 | AN9: PITSS
A10: SEI0014 | B10: Montoya Portillo Carlos Alberto | C10: 15 | D10: 0 | E10: 266.67 | F10: 278.72 | G10: 4000.05 | H10: 0 | I10: 0 | J10: 4000.05 | K10: 313.87 | L10: 0 | M10: 100.81 | N10: 0 | O10: 0 | P10: 0 | Q10: 0 | R10: 0 | T10: 0.17 | U10: 414.85 | V10: 3585.2 | W10: 26.13 | X10: 47.03 | Y10: 27.65 | Z10: 0 | AA10: 313.87 | AC10: 73.16 | AD10: 131.7 | AE10: 335.88 | AF10: 4000.05 | AG10: 268.34 | AH10: 80 | AI10: 33.3 | AJ10: 540.74 | AK10: 209.04 | AL10: 226.53 | AM10: 219.0368 | AN10: PITSS
A11: SEI0015 | B11: Cota Jaramillo Miguel Angel | C11: 15 | D11: 0 | E11: 200 | F11: 209.04 | G11: 3000 | H11: 0 | I11: 0 | J11: 3000 | K11: 59.69 | L11: 0 | M11: 74.48 | N11: 0 | O11: 0 | P11: 0 | Q11: 0 | R11: 0 | T11: 0.03 | U11: 134.2 | V11: 2865.8 | W11: 19.6 | X11: 35.28 | Y11: 19.6 | Z11: -145.38 | AA11: 205.07 | AC11: 54.87 | AD11: 98.77 | AE11: 313.41 | AF11: 3000 | AG11: 247.43 | AH11: 60 | AI11: 24.98 | AJ11: 467.05 | AK11: 156.78 | AL11: 216.08 | AM11: 164.27554 | AN11: PITSS
A12: SEI0017 | B12: Muñoz Reyes Luis Eduardo | C12: 15 | D12: 0 | E12: 266.67 | F12: 278.72 | G12: 4000.05 | H12: 0 | I12: 0 | J12: 4000.05 | K12: 313.87 | L12: 0 | M12: 100.81 | N12: 877.59 | O12: 0 | P12: 15 | Q12: 0 | R12: 0 | T12: -0.02 | U12: 1307.25 | V12: 2692.8 | W12: 26.13 | X12: 47.03 | Y12: 27.65 | Z12: 0 | AA12: 313.87 | AC12: 73.16 | AD12: 131.7 | AE12: 335.88 | AF12: 4000.05 | AG12: 268.34 | AH12: 80 | AI12: 33.3 | AJ12: 540.74 | AK12: 209.04 | AL12: 226.53 | AM12: 219.0368 | AN12: PITSS
A13: SEI0019 | B13: Gonzalez Rasgado Miguel Isaias | C13: 15 | D13: 0 | E13: 400 | F13: 424.2 | G13: 6000 | H13: 0 | I13: 0 | J13: 6000 | K13: 643.38 | L13: 0 | M13: 161.36 | N13: 0 | O13: 0 | P13: 0 | Q13: 0 | R13: 0 | T13: 0.06 | U13: 804.8 | V13: 5195.2 | W13: 39.77 | X13: 71.58 | Y13: 50.01 | Z13: 0 | AA13: 643.38 | AC13: 111.35 | AD13: 200.43 | AE13: 398.06 | AF13: 6000 | AG13: 311.98 | AH13: 120 | AI13: 50.69 | AJ13: 709.84 | AK13: 318.15 | AL13: 248.35 | AM13: 328.55109 | AN13: PITSS
A14: SEI0020 | B14: Mar Marquez Cesar Eduardo | C14: 15 | D14: 0 | E14: 266.67 | F14: 278.72 | G14: 4000.05 | H14: 0 | I14: 0 | J14: 4000.05 | K14: 313.87 | L14: 0 | M14: 100.81 | N14: 0 | O14: 0 | P14: 0 | Q14: 0 | R14: 0 | T14: -0.03 | U14: 414.65 | V14: 3585.4 | W14: 26.13 | X14: 47.03 | Y14: 27.65 | Z14: 0 | AA14: 313.87 | AC14: 73.16 | AD14: 131.7 | AE14: 335.88 | AF14: 4000.05 | AG14: 268.34 | AH14: 80 | AI14: 33.3 | AJ14: 540.74 | AK14: 209.04 | AL14: 226.53 | AM14: 219.0368 | AN14: PITSS
A15: SEI0021 | B15: Velez Rodriguez Jaime | C15: 15 | D15: 0 | E15: 200 | F15: 212.1 | G15: 3000 | H15: 0 | I15: 0 | J15: 3000 | K15: 59.69 | L15: 0 | M15: 75.55 | N15: 1359.23 | O15: 0 | P15: 15 | Q15: 0 | R15: 0 | T15: -0.07 | U15: 1509.4 | V15: 1490.6 | W15: 19.88 | X15: 35.79 | Y15: 19.88 | Z15: -145.38 | AA15: 205.07 | AC15: 55.68 | AD15: 100.22 | AE15: 314.22 | AF15: 3000 | AG15: 248.35 | AH15: 60 | AI15: 25.34 | AJ15: 470.12 | AK15: 159.08 | AL15: 216.54 | AM15: 164.27554 | AN15: PITSS
A16: SEI0022 | B16: Najera Lopez Raul | C16: 15 | D16: 0 | E16: 333.33 | F16: 353.5 | G16: 4999.95 | H16: 0 | I16: 0 | J16: 4999.95 | K16: 461.63 | L16: 0 | M16: 131.93 | N16: 0 | O16: 0 | P16: 0 | Q16: 0 | R16: 0 | T16: -0.01 | U16: 593.55 | V16: 4406.4 | W16: 33.14 | X16: 59.65 | Y16: 39.14 | Z16: 0 | AA16: 461.63 | AC16: 92.79 | AD16: 167.03 | AE16: 367.84 | AF16: 4999.95 | AG16: 290.77 | AH16: 100 | AI16: 42.24 | AJ16: 627.66 | AK16: 265.12 | AL16: 237.74 | AM16: 273.78984 | AN16: PITSS
A17: SEI0023 | B17: Puente Murguia Luis Felipe | C17: 15 | D17: 0 | E17: 233.33 | F17: 247.45 | G17: 3499.95 | H17: 0 | I17: 0 | J17: 3499.95 | K17: 134.36 | L17: 0 | M17: 88.16 | N17: 0 | O17: 0 | P17: 0 | Q17: 0 | R17: 0 | T17: 0.03 | U17: 222.55 | V17: 3277.4 | W17: 23.2 | X17: 41.76 | Y17: 23.2 | Z17: -125.1 | AA17: 259.46 | AC17: 64.95 | AD17: 116.92 | AE17: 323.49 | AF17: 3499.95 | AG17: 258.95 | AH17: 70 | AI17: 29.57 | AJ17: 505.36 | AK17: 185.58 | AL17: 221.84 | AM17: 191.65206 | AN17: PITSS
A18: SEI0028 | B18: Jimenez Alcaraz Elizabeth | C18: 15 | D18: 0 | E18: 200 | F18: 212.11 | G18: 3000 | H18: 0 | I18: 0 | J18: 3000 | K18: 59.69 | L18: 0 | M18: 75.56 | N18: 0 | O18: 0 | P18: 0 | Q18: 0 | R18: 0 | T18: -0.05 | U18: 135.2 | V18: 2864.8 | W18: 19.89 | X18: 35.79 | Y18: 19.88 | Z18: -145.38 | AA18: 205.07 | AC18: 55.68 | AD18: 100.22 | AE18: 314.22 | AF18: 3000 | AG18: 248.35 | AH18: 60 | AI18: 25.34 | AJ18: 470.12 | AK18: 159.08 | AL18: 216.54 | AM18: 164.27554 | AN18: PITSS
A19: SEI0029 | B19: Arceo Garcia Manuel Federico | C19: 14 | D19: 0 | E19: 200 | F19: 212.1 | G19: 2800 | H19: 0 | I19: 0 | J19: 2800 | K19: 37.93 | L19: 0 | M19: 71.85 | N19: 0 | O19: 0 | P19: 0 | Q19: 600 | R19: 0 | T19: 0.02 | U19: 709.8 | V19: 2090.2 | W19: 18.56 | X19: 33.41 | Y19: 19.88 | Z19: -145.38 | AA19: 183.31 | AC19: 55.68 | AD19: 100.22 | AE19: 314.22 | AF19: 2800 | AG19: 248.35 | AH19: 56 | AI19: 25.34 | AJ19: 470.12 | AK19: 159.08 | AL19: 216.54 | AM19: 164.27554 | AN19: PITSS
A20: SEI0364 | B20: Dominguez Lopez Mayeli Del Pilar | C20: 15 | D20: 0 | E20: 266.67 | F20: 282.81 | G20: 4000.05 | H20: 0 | I20: 0 | J20: 4000.05 | K20: 313.87 | L20: 0 | M20: 102.51 | N20: 0 | O20: 0 | P20: 0 | Q20: 0 | R20: 1666.67 | T20: 0 | U20: 2083.05 | V20: 1917 | W20: 26.51 | X20: 47.72 | Y20: 28.28 | Z20: 0 | AA20: 313.87 | AC20: 74.24 | AD20: 133.63 | AE20: 337.62 | AF20: 4000.05 | AG20: 269.56 | AH20: 80 | AI20: 33.79 | AJ20: 545.49 | AK20: 212.11 | AL20: 227.14 | AM20: 219.0368 | AN20: PITSS
... A78: SEI0530 | B78: Del Pilar Mendez Lucio | C78: 15 | D78: 0 | E78: 200 | F78: 209.04 | G78: 3000 | H78: 0 | I78: 0 | J78: 3000 | K78: 59.69 | L78: 0 | M78: 74.48 | N78: 0 | O78: 1605.6 | P78: 15 | Q78: 0 | R78: 0 | T78: 0.03 | U78: 1754.8 | V78: 1245.2 | W78: 19.6 | X78: 35.28 | Y78: 19.6 | Z78: -145.38 | AA78: 205.07 | AC78: 54.87 | AD78: 98.77 | AE78: 313.41 | AF78: 3000 | AG78: 247.43 | AH78: 60 | AI78: 24.98 | AJ78: 467.05 | AK78: 156.78 | AL78: 216.08 | AM78: 164.27554 | AN78: PITSS
A79: SEI0531 | B79: Garcia Valderrama Jose De Jesus | C79: 7 | D79: 0 | E79: 200 | F79: 209.04 | G79: 1400 | H79: 0 | I79: 0 | J79: 1400 | K79: 0 | L79: -123.82 | M79: 45.21 | N79: 0 | O79: 0 | P79: 0 | Q79: 0 | R79: 0 | S79: 0 | T79: 0.01 | U79: -78.6 | V79: 1478.6 | W79: 9.15 | X79: 16.46 | Y79: 19.6 | Z79: -200.63 | AA79: 76.81 | AC79: 54.87 | AD79: 98.77 | AE79: 313.41 | AF79: 1400 | AG79: 62.71 | AH79: 28 | AI79: 24.98 | AJ79: 467.05 | AK79: 156.78 | AL79: 31.36 | AM79: 164.28 | AN79: PITSS
A80: SEI0534 | B80: Gonzalez Ramirez Paul | C80: 15 | D80: 0 | E80: 200 | F80: 209.04 | G80: 3000 | H80: 0 | I80: 0 | J80: 3000 | K80: 59.69 | L80: 0 | M80: 74.48 | N80: 0 | O80: 0 | P80: 0 | Q80: 0 | R80: 0 | T80: 0.03 | U80: 134.2 | V80: 2865.8 | W80: 19.6 | X80: 35.28 | Y80: 19.6 | Z80: -145.38 | AA80: 205.07 | AC80: 54.87 | AD80: 98.77 | AE80: 313.41 | AF80: 3000 | AG80: 247.43 | AH80: 60 | AI80: 24.98 | AJ80: 467.05 | AK80: 156.78 | AL80: 216.08 | AM80: 164.27554 | AN80: PITSS
A81: SEI0535 | B81: Alejandro Vazquez Erasmo Miguel | C81: 15 | D81: 0 | E81: 200 | F81: 212.11 | G81: 3000 | H81: 0 | I81: 0 | J81: 3000 | K81: 59.69 | L81: 0 | M81: 75.56 | N81: 0 | O81: 477.81 | P81: 15 | Q81: 0 | R81: 0 | T81: -0.06 | U81: 628 | V81: 2372 | W81: 19.89 | X81: 35.79 | Y81: 19.88 | Z81: -145.38 | AA81: 205.07 | AC81: 55.68 | AD81: 100.22 | AE81: 314.22 | AF81: 3000 | AG81: 248.35 | AH81: 60 | AI81: 25.34 | AJ81: 470.12 | AK81: 159.08 | AL81: 216.54 | AM81: 164.27554 | AN81: PITSS
A82: SEI0536 | B82: Hernandez Ojeda Julio Cesar | C82: 15 | D82: 0 | E82: 116.67 | F82: 123.73 | G82: 1750.05 | H82: 0 | I82: 0 | J82: 1750.05 | K82: 0 | L82: -89.5 | M82: 44.08 | N82: 0 | O82: 854.85 | P82: 15 | Q82: 0 | R82: 0 | T82: 0.02 | U82: 824.45 | V82: 925.6 | W82: 11.6 | X82: 20.88 | Y82: 11.6 | Z82: -188.71 | AA82: 99.22 | AC82: 32.48 | AD82: 58.46 | AE82: 291.02 | AF82: 1750.05 | AG82: 221.84 | AH82: 35 | AI82: 14.78 | AJ82: 381.96 | AK82: 92.8 | AL82: 203.28 | AM82: 95.830139 | AN82: PITSS
A83: SEI0537 | B83: Serrano Esquivel Armando | C83: 15 | D83: 0 | E83: 116.67 | F83: 123.73 | G83: 1750.05 | H83: 0 | I83: 0 | J83: 1750.05 | K83: 0 | L83: -89.5 | M83: 44.08 | N83: 801.02 | O83: 0 | P83: 15 | Q83: 0 | R83: 0 | T83: 0.05 | U83: 770.65 | V83: 979.4 | W83: 11.6 | X83: 20.88 | Y83: 11.6 | Z83: -188.71 | AA83: 99.22 | AC83: 32.48 | AD83: 58.46 | AE83: 291.02 | AF83: 1750.05 | AG83: 221.84 | AH83: 35 | AI83: 14.78 | AJ83: 381.96 | AK83: 92.8 | AL83: 203.28 | AM83: 95.830139 | AN83: PITSS
A84: SEI0538 | B84: Coronado Vega Carlos Eduardo | C84: 15 | D84: 0 | E84: 210 | F84: 222.72 | G84: 3150 | H84: 0 | I84: 0 | J84: 3150 | K84: 96.29 | L84: 0 | M84: 79.34 | N84: 0 | O84: 0 | P84: 0 | Q84: 0 | R84: 0 | T84: -0.03 | U84: 175.6 | V84: 2974.4 | W84: 20.88 | X84: 37.58 | Y84: 20.88 | Z84: -125.1 | AA84: 221.39 | AC84: 58.46 | AD84: 105.24 | AE84: 317.01 | AF84: 3150 | AG84: 251.54 | AH84: 63 | AI84: 26.61 | AJ84: 480.71 | AK84: 167.04 | AL84: 218.13 | AM84: 86.244661 | AN84: PITSS
A85: SEI0539 | B85: Montes De Oca Trujillo Gloria | C85: 15 | D85: 0 | E85: 166.67 | F85: 176.76 | G85: 2500.05 | H85: 0 | I85: 0 | J85: 2500.05 | K85: 0 | L85: -9.62 | M85: 62.97 | N85: 0 | O85: 0 | P85: 0 | Q85: 0 | R85: 0 | T85: 0.1 | U85: 53.45 | V85: 2446.6 | W85: 16.57 | X85: 29.83 | Y85: 16.57 | Z85: -160.3 | AA85: 150.67 | AC85: 46.4 | AD85: 83.52 | AE85: 304.94 | AF85: 2500.05 | AG85: 237.75 | AH85: 50 | AI85: 21.12 | AJ85: 434.86 | AK85: 132.57 | AL85: 211.23 | AM85: 136.9 | AN85: PITSS
A86: SEI0540 | B86: Morales Martinez Eduardo | C86: 15 | D86: 0 | E86: 210 | F86: 222.72 | G86: 3150 | H86: 0 | I86: 0 | J86: 3150 | K86: 96.29 | L86: 0 | M86: 79.34 | N86: 0 | O86: 0 | P86: 0 | Q86: 0 | R86: 0 | T86: 0.17 | U86: 175.8 | V86: 2974.2 | W86: 20.88 | X86: 37.58 | Y86: 20.88 | Z86: -125.1 | AA86: 221.39 | AC86: 58.46 | AD86: 105.24 | AE86: 317.01 | AF86: 3150 | AG86: 251.54 | AH86: 63 | AI86: 26.61 | AJ86: 480.71 | AK86: 167.04 | AL86: 218.13 | AM86: 172.49 | AN86: PITSS
A87: SEI0541 | B87: Chavez Govea Edgar Aram | C87: 15 | D87: 0 | E87: 233.33 | F87: 247.46 | G87: 3499.95 | H87: 0 | I87: 0 | J87: 3499.95 | K87: 134.36 | L87: 0 | M87: 88.16 | N87: 0 | O87: 0 | P87: 0 | Q87: 0 | R87: 0 | T87: -0.17 | U87: 222.35 | V87: 3277.6 | W87: 23.2 | X87: 41.76 | Y87: 23.2 | Z87: -125.1 | AA87: 259.46 | AC87: 64.96 | AD87: 116.92 | AE87: 323.5 | AF87: 3499.95 | AG87: 258.96 | AH87: 70 | AI87: 29.57 | AJ87: 505.38 | AK87: 185.6 | AL87: 221.84 | AM87: 191.65 | AN87: PITSS
A88: SEI0542 | B88: Ramirez Elizalde Karen Viridiana | C88: 15 | D88: 0 | E88: 200 | F88: 209.04 | G88: 3000 | H88: 0 | I88: 0 | J88: 3000 | K88: 59.69 | L88: 0 | M88: 74.48 | N88: 0 | O88: 0 | P88: 0 | Q88: 0 | R88: 0 | T88: 0.03 | U88: 134.2 | V88: 2865.8 | W88: 19.6 | X88: 35.28 | Y88: 19.6 | Z88: -145.38 | AA88: 205.07 | AC88: 54.87 | AD88: 98.77 | AE88: 313.41 | AF88: 3000 | AG88: 247.43 | AH88: 60 | AI88: 24.98 | AJ88: 467.05 | AK88: 156.78 | AL88: 216.08 | AM88: 164.28 | AN88: PITSS
A89: SEI479 | B89: Cruz Perez Alejandro Nezahualcoyotl | C89: 15 | D89: 0 | E89: 266.67 | F89: 282.81 | G89: 4000.05 | H89: 0 | I89: 0 | J89: 4000.05 | K89: 313.87 | L89: 0 | M89: 102.51 | N89: 0 | O89: 0 | P89: 0 | Q89: 0 | R89: 0 | T89: 0.07 | U89: 416.45 | V89: 3583.6 | W89: 26.51 | X89: 47.72 | Y89: 28.28 | Z89: 0 | AA89: 313.87 | AC89: 74.24 | AD89: 133.63 | AE89: 337.62 | AF89: 4000.05 | AG89: 269.56 | AH89: 80 | AI89: 33.79 | AJ89: 545.49 | AK89: 212.11 | AL89: 227.14 | AM89: 219.0368 | AN89: PITSS
A90: SEI0543 | B90: Diaz Ortiz Hiram Guillermo | C90: 12 | D90: 0 | E90: 210 | F90: 219.49 | G90: 2520 | H90: 0 | I90: 0 | J90: 2520 | K90: 0 | L90: -7.45 | M90: 62.55 | N90: 600 | O90: 0 | P90: 0 | Q90: 0 | R90: 0 | T90: 0.1 | U90: 655.2 | V90: 1864.8 | W90: 16.46 | X90: 29.63 | Y90: 16.46 | Z90: -160.3 | AA90: 152.84 | AC90: 46.09 | AD90: 82.97 | AE90: 252.93 | AF90: 2520 | AG90: 237.4 | AH90: 50.4 | AI90: 20.98 | AJ90: 381.99 | AK90: 131.7 | AL90: 211.06 | AM90: 90.25 | AN90: PITSS
A91: Total Depto | C91: ----------------------- | D91: ----------------------- | E91: ----------------------- | F91: ----------------------- | G91: ----------------------- | H91: ----------------------- | I91: ----------------------- | J91: ----------------------- | K91: ----------------------- | L91: ----------------------- | M91: ----------------------- | N91: ----------------------- | O91: ----------------------- | P91: ----------------------- | Q91: ----------------------- | R91: ----------------------- | S91: ----------------------- | T91: ----------------------- | U91: ----------------------- | V91: ----------------------- | W91: ----------------------- | X91: ----------------------- | Y91: ----------------------- | Z91: ----------------------- | AA91: ----------------------- | AC91: ----------------------- | AD91: ----------------------- | AE91: ----------------------- | AF91: ----------------------- | AG91: ----------------------- | AH91: ----------------------- | AI91: ----------------------- | AJ91: ----------------------- | AK91: ----------------------- | AL91: ----------------------- | AM91: -----------------------
A92: =SUM(A9:A91) -> 0 | B92: =SUM(B9:B91) -> 0 | C92: =SUM(C9:C91) -> 1213 | D92: =SUM(D9:D91) -> 0 | E92: =SUM(E9:E91) -> 19589.93 | F92: =SUM(F9:F91) -> 20665.45 | G92: =SUM(G9:G91) -> 290189.19 | H92: =SUM(H9:H91) -> 0 | ... AM92: =SUM(AM9:AM91) -> 15922.257
I93: FACTURACION PITS | K93: PROVISION AGUINALDO
I94: Devengado Salario | J94: =+V92 -> 229673.73 | K94: FACTURACION PITS
I95: Retornos | J95: =+R92 -> 7609.9 | K95: Subtotal 1 | L95: =+AM92 -> 15922.257
I96: Infonavit | J96: =+N92+O92+P92 -> 28208.99 | K96: Comision | L96: =+L95*2% -> 318.44513
I97: Prestamo Prospera | J97: =+Q92 -> 1781.73 | K97: Subtotal 2 | L97: =+L95+L96 -> 16240.702
I98: aportacion voluntaria | J98: =+S92 -> 0 | K98: 2% Sobre Nomina | L98: =+L95*2% -> 318.44513
I99: Subtotal 1 | J99: =SUM(J94:J98) -> 267274.35 | K99: Importe de Factura | L99: =+L97+L98 -> 16559.147
I100: Comision | J100: =+J99*2% -> 5345.487 | K100: IVA | L100: =+L99*16% -> 2649.4635
...

Sheet SIND PITS
A5: 1 | B5: 2 | C5: 3 | D5: 4 | E5: 5 | F5: 6
A6: CLAVE | B6: EMPRESA | C6: NOMBRE | D6: PAGO POR SINDICATO | E6: comision y bono | F6: prima vacaciones | G6: TOTAL | H6: DIAS DE VACACIONES | I6: SUELDO NETO MENSUAL | J6: MONTO PRIMA TOTAL | K6: MENOS PRIMA IMSS | L6: PRIMA A PAGAR SINDICATO | M6: FACTURACION
A7: SEI0442 | B7: SEITON - (CONSULTORIA II) | C7: Sierra Escamilla Daniela | D7: 2464 | E7: 1000 | F7: =+L7 -> 0 | G7: =+D7+E7+F7 -> 3464 | H7: =VLOOKUP(C7,'CPD PITS'!$B$9:$D$27,3,0) -> 0 | I7: =VLOOKUP(C7,[1]RESUMEN!$C$4:$L$113,10,) -> 13000 | J7: =(((+I7/30)*H7)*30%) -> 0 | K7: =VLOOKUP(C7,[1]CPD!$B$9:$I$35,8,0) -> 0 | L7: =+J7-K7 -> 0 | M7: PITSS
A8: SEI0431 | B8: SEITON (IP INNOVA II) | C8: Alcaraz Conde Zabdi Guadalupe | D8: 135.2 | E8: 292.5 | F8: =+L8 -> 0 | G8: =+D8+E8+F8 -> 427.7 | H8: =VLOOKUP(C8,'IP PITS'!$B$9:$D$90,3,0) -> 0 | I8: =VLOOKUP(C8,[1]RESUMEN!$C$31:$L$127,10,0) -> 6000 | J8: =(((+I8/30)*H8)*30%) -> 0 | K8: =VLOOKUP(C8,[1]IP!$B$9:$I$116,8,0) -> 0 | L8: =+J8-K8 -> 0 | M8: PITSS
A9: SEI0527 | B9: SEITON (IP INNOVA II) | C9: Alejandro Peña Deivi | D9: 175.8 | E9: 618.75 | F9: =+L9 -> 0 | G9: =+D9+E9+F9 -> 794.55 | H9: =VLOOKUP(C9,'IP PITS'!$B$9:$D$90,3,0) -> 0 | I9: =VLOOKUP(C9,[1]RESUMEN!$C$31:$L$127,10,0) -> 6300 | J9: =(((+I9/30)*H9)*30%) -> 0 | K9: =VLOOKUP(C9,[1]IP!$B$9:$I$116,8,0) -> 0 | L9: =+J9-K9 -> 0 | M9: PITSS
A10: SEI0535 | B10: SEITON (IP INNOVA II) | C10: Alejandro Vazquez Erasmo Miguel | D10: 3135.19 | E10: 1750 | F10: =+L10 -> 0 | G10: =+D10+E10+F10 -> 4885.19 | H10: =VLOOKUP(C10,'IP PITS'!$B$9:$D$90,3,0) -> 0 | I10: 12000 | J10: =(((+I10/30)*H10)*30%) -> 0 | K10: =VLOOKUP(C10,[1]IP!$B$9:$I$116,8,0) -> 0 | L10: =+J10-K10 -> 0 | M10: PITSS
A11: SEI0029 | B11: SEITON (IP INNOVA II) | C11: Arceo Garcia Manuel Federico | D11: 109.8 | E11: 487.5 | F11: =+L11 -> 0 | G11: =+D11+E11+F11 -> 597.3 | H11: =VLOOKUP(C11,'IP PITS'!$B$9:$D$90,3,0) -> 0 | I11: =VLOOKUP(C11,[1]RESUMEN!$C$31:$L$127,10,0) -> 6000 | J11: =(((+I11/30)*H11)*30%) -> 0 | K11: =VLOOKUP(C11,[1]IP!$B$9:$I$116,8,0) -> 0 | L11: =+J11-K11 -> 0 | M11: PITSS
A12: SEI0097 | B12: SEITON - (CONSULTORIA II) | C12: Arreola Jimenez Jose Nieves | D12: 1558.11 | E12: 501 | F12: =+L12 -> 0 | G12: =+D12+E12+F12 -> 2059.11 | H12: =VLOOKUP(C12,'CPD PITS'!$B$9:$D$27,3,0) -> 0 | I12: =VLOOKUP(C12,[1]RESUMEN!$C$4:$L$113,10,) -> 10150 | J12: =(((+I12/30)*H12)*30%) -> 0 | K12: =VLOOKUP(C12,[1]CPD!$B$9:$I$35,8,0) -> 0 | L12: =+J12-K12 -> 0 | M12: PITSS
A13: SEI0118 | B13: SEITON - (CONSULTORIA II) | C13: Arroyo Ramirez Hector Hugo | D13: 2102.84 | F13: =+L13 -> 234.01 | G13: =+D13+E13+F13 -> 2336.85 | H13: 4 | I13: =VLOOKUP(C13,[1]RESUMEN!$C$4:$L$113,10,) -> 13000 | J13: =(((+I13/30)*H13)*30%) -> 520 | K13: =VLOOKUP(C13,[1]CPD!$B$9:$I$35,8,0) -> 285.99 | L13: =+J13-K13 -> 234.01 | M13: PITSS
A14: SEI0472 | B14: SEITON (IP INNOVA II) | C14: Arzate Gil Juan Sebastian | D14: 416.2 | E14: 463 | F14: =+L14 -> 0 | G14: =+D14+E14+F14 -> 879.2 | H14: =VLOOKUP(C14,'IP PITS'!$B$9:$D$90,3,0) -> 0 | I14: =VLOOKUP(C14,[1]RESUMEN!$C$31:$L$127,10,0) -> 8000 | J14: =(((+I14/30)*H14)*30%) -> 0 | K14: =VLOOKUP(C14,[1]IP!$B$9:$I$116,8,0) -> 0 | L14: =+J14-K14 -> 0 | M14: PITSS
A15: SEI0377 | B15: SEITON - (CONSULTORIA II) | C15: Benavides Herrera Alejandra | D15: 16803.2 | F15: =+L15 -> 0 | G15: =+D15+E15+F15 -> 16803.2 | H15: =VLOOKUP(C15,'CPD PITS'!$B$9:$D$27,3,0) -> 0 | I15: =VLOOKUP(C15,[1]RESUMEN!$C$4:$L$113,10,) -> 40000 | J15: =(((+I15/30)*H15)*30%) -> 0 | K15: =VLOOKUP(C15,[1]CPD!$B$9:$I$35,8,0) -> 0 | L15: =+J15-K15 -> 0 | M15: PITSS
A16: SEI0108 | B16: SEITON - (CONSULTORIA II) | C16: Caballero Diaz Francisco Javier | D16: 1558.09 | E16: =346+720 -> 1066 | F16: =+L16 -> 0 | G16: =+D16+E16+F16 -> 2624.09 | H16: =VLOOKUP(C16,'CPD PITS'!$B$9:$D$27,3,0) -> 0 | I16: =VLOOKUP(C16,[1]RESUMEN!$C$4:$L$113,10,) -> 10150 | J16: =(((+I16/30)*H16)*30%) -> 0 | K16: =VLOOKUP(C16,[1]CPD!$B$9:$I$35,8,0) -> 0 | L16: =+J16-K16 -> 0 | M16: PITSS
A17: SEI0425 | B17: SEITON - (CONSULTORIA II) | C17: Carbajal Cabuto Jose Luis | D17: 1608.1 | E17: =357+3080 -> 3437 | F17: =+L17 -> 0 | G17: =+D17+E17+F17 -> 5045.1 | H17: =VLOOKUP(C17,'CPD PITS'!$B$9:$D$27,3,0) -> 0 | I17: =VLOOKUP(C17,[1]RESUMEN!$C$4:$L$113,10,) -> 10250 | J17: =(((+I17/30)*H17)*30%) -> 0 | K17: =VLOOKUP(C17,[1]CPD!$B$9:$I$35,8,0) -> 0 | L17: =+J17-K17 -> 0 | M17: PITSS
A18: SEI0528 | B18: SEITON (IP INNOVA II) | C18: Casas Chavarria Rafael | D18: 175.61 | E18: 480 | F18: =+L18 -> 0 | G18: =+D18+E18+F18 -> 655.61 | H18: =VLOOKUP(C18,'IP PITS'!$B$9:$D$90,3,0) -> 0 | I18: =VLOOKUP(C18,[1]RESUMEN!$C$31:$L$127,10,0) -> 6300 | J18: =(((+I18/30)*H18)*30%) -> 0 | K18: =VLOOKUP(C18,[1]IP!$B$9:$I$116,8,0) -> 0 | L18: =+J18-K18 -> 0 | M18: PITSS
A19: SEI0116 | B19: SEITON - (CONSULTORIA II) | C19: Casillas Cardona Cesar Alejandro | D19: 1891.08 | F19: =+L19 -> 0 | G19: =+D19+E19+F19 -> 1891.08 | H19: =VLOOKUP(C19,'CPD PITS'!$B$9:$D$27,3,0) -> 0 | I19: =VLOOKUP(C19,[1]RESUMEN!$C$4:$L$113,10,) -> 12000 | J19: =(((+I19/30)*H19)*30%) -> 0 | K19: =VLOOKUP(C19,[1]CPD!$B$9:$I$35,8,0) -> 0 | L19: =+J19-K19 -> 0 | M19: PITSS
A20: SEI0460 | B20: SEITON (IP INNOVA II) | C20: Castellon Ramos Rene | D20: 384.775 | E20: 150 | F20: =+L20 -> 0 | G20: =+D20+E20+F20 -> 534.775 | H20: =VLOOKUP(C20,'IP PITS'!$B$9:$D$90,3,0) -> 0 | I20: =VLOOKUP(C20,[1]RESUMEN!$C$31:$L$127,10,0) -> 7505.99 | J20: =(((+I20/30)*H20)*30%) -> 0 | K20: =VLOOKUP(C20,[1]IP!$B$9:$I$116,8,0) -> 0 | L20: =+J20-K20 -> 0 | M20: PITSS
A21: SEI0443 | B21: SEITON (IP INNOVA II) | C21: Castillo Nungaray Nestor Roman | D21: 135.2 | E21: 1500 | F21: =+L21 -> 0 | G21: =+D21+E21+F21 -> 1635.2 | H21: =VLOOKUP(C21,'IP PITS'!$B$9:$D$90,3,0) -> 0 | I21: =VLOOKUP(C21,[1]RESUMEN!$C$31:$L$127,10,0) -> 6000 | J21: =(((+I21/30)*H21)*30%) -> 0 | K21: =VLOOKUP(C21,[1]IP!$B$9:$I$116,8,0) -> 0 | L21: =+J21-K21 -> 0 | M21: PITSS
A22: SEI0490 | B22: SEITON (IP INNOVA II) | C22: Castillo Ramirez Hector Ivan | D22: 3721.37 | E22: 208.5 | F22: =+L22 -> 0 | G22: =+D22+E22+F22 -> 3929.87 | H22: =VLOOKUP(C22,'IP PITS'!$B$9:$D$90,3,0) -> 0 | I22: =VLOOKUP(C22,[1]RESUMEN!$C$31:$L$127,10,0) -> 14000 | J22: =(((+I22/30)*H22)*30%) -> 0 | K22: =VLOOKUP(C22,[1]IP!$B$9:$I$116,8,0) -> 0 | L22: =+J22-K22 -> 0 | M22: PITSS
A23: SEI0508 | B23: SEITON (IP INNOVA II) | C23: Cerro Garcia Elvis | D23: 2553.4 | E23: 200 | F23: =+L23 -> 0 | G23: =+D23+E23+F23 -> 2753.4 | H23: =VLOOKUP(C23,'IP PITS'!$B$9:$D$90,3,0) -> 0 | I23: =VLOOKUP(C23,[1]RESUMEN!$C$31:$L$127,10,0) -> 10000 | J23: =(((+I23/30)*H23)*30%) -> 0 | K23: =VLOOKUP(C23,[1]IP!$B$9:$I$116,8,0) -> 0 | L23: =+J23-K23 -> 0 | M23: PITSS
A24: SEI0499 | B24: SEITON (IP INNOVA II) | C24: Chavez Dominguez Salvador | D24: 2667.4 | E24: 1054.5 | F24: =+L24 -> 0 | G24: =+D24+E24+F24 -> 3721.9 | H24: =VLOOKUP(C24,'IP PITS'!$B$9:$D$90,3,0) -> 0 | I24: =VLOOKUP(C24,[1]RESUMEN!$C$31:$L$127,10,0) -> 12000 | J24: =(((+I24/30)*H24)*30%) -> 0 | K24: =VLOOKUP(C24,[1]IP!$B$9:$I$116,8,0) -> 0 | L24: =+J24-K24 -> 0 | M24: PITSS
A25: SEI0541 | B25: SEITON (IP INNOVA II) | C25: Chavez Govea Edgar Aram | D25: 222.4 | F25: =+L25 -> 0 | G25: =+D25+E25+F25 -> 222.4 | H25: =VLOOKUP(C25,'IP PITS'!$B$9:$D$90,3,0) -> 0 | I25: 7000 | J25: =(((+I25/30)*H25)*30%) -> 0 | K25: =VLOOKUP(C25,[1]IP!$B$9:$I$116,8,0) -> 0 | L25: =+J25-K25 -> 0 | M25: PITSS
A26: SEI0442 | B26: SEITON (IP INNOVA II) | C26: Chavez Pedraza Samuel | D26: 1047.8 | E26: =420+675 -> 1095 | F26: =+L26 -> 0 | G26: =+D26+E26+F26 -> 2142.8 | H26: =VLOOKUP(C26,'IP PITS'!$B$9:$D$90,3,0) -> 0 | I26: =VLOOKUP(C26,[1]RESUMEN!$C$31:$L$127,10,0) -> 14000 | J26: =(((+I26/30)*H26)*30%) -> 0 | K26: =VLOOKUP(C26,[1]IP!$B$9:$I$116,8,0) -> 0 | L26: =+J26-K26 -> 0 | M26: PITSS
A27: SEI0462 | B27: SEITON (IP INNOVA II) | C27: Chavez Saucedo Jorge Arturo | D27: 414.6 | E27: 224.25 | F27: =+L27 -> 0 | G27: =+D27+E27+F27 -> 638.85 | H27: =VLOOKUP(C27,'IP PITS'!$B$9:$D$90,3,0) -> 0 | I27: =VLOOKUP(C27,[1]RESUMEN!$C$31:$L$127,10,0) -> 8000 | J27: =(((+I27/30)*H27)*30%) -> 0 | K27: =VLOOKUP(C27,[1]IP!$B$9:$I$116,8,0) -> 0 | L27: =+J27-K27 -> 0 | M27: PITSS
A28: SEI0456 | B28: SEITON (IP INNOVA II) | C28: Chavira Garcia David Fernando | D28: 593.6 | E28: 121.5 | F28: =+L28 -> 0 | G28: =+D28+E28+F28 -> 715.1 | H28: =VLOOKUP(C28,'IP PITS'!$B$9:$D$90,3,0) -> 0 | I28: =VLOOKUP(C28,[1]RESUMEN!$C$31:$L$127,10,0) -> 10000 | J28: =(((+I28/30)*H28)*30%) -> 0 | K28: =VLOOKUP(C28,[1]IP!$B$9:$I$116,8,0) -> 0 | L28: =+J28-K28 -> 0 | M28: PITSS
A29: SEI0538 | B29: SEITON (IP INNOVA II) | C29: Coronado Vega Carlos Eduardo | D29: 175.6 | F29: =+L29 -> 0 | G29: =+D29+E29+F29 -> 175.6 | H29: =VLOOKUP(C29,'IP PITS'!$B$9:$D$90,3,0) -> 0 | I29: 6300 | J29: =(((+I29/30)*H29)*30%) -> 0 | K29: =VLOOKUP(C29,[1]IP!$B$9:$I$116,8,0) -> 0 | L29: =+J29-K29 -> 0 | M29: PITSS
A30: SEI0015 | B30: SEITON (IP INNOVA II) | C30: Cota Jaramillo Miguel Angel | D30: 134.2 | E30: 378 | F30: =+L30 -> 0 | G30: =+D30+E30+F30 -> 512.2 | H30: =VLOOKUP(C30,'IP PITS'!$B$9:$D$90,3,0) -> 0 | I30: 6000 | J30: =(((+I30/30)*H30)*30%) -> 0 | K30: =VLOOKUP(C30,[1]IP!$B$9:$I$116,8,0) -> 0 | L30: =+J30-K30 -> 0 | M30: PITSS
A31: SEI0413 | B31: SEITON (IP INNOVA II) | C31: Courtenay Gutierrez Barry Vladimir | D31: 52.4 | E31: =3430+395.5 -> 3825.5 | F31: =+L31 -> 0 | G31: =+D31+E31+F31 -> 3877.9 | H31: =VLOOKUP(C31,'IP PITS'!$B$9:$D$90,3,0) -> 0 | I31: =VLOOKUP(C31,[1]RESUMEN!$C$31:$L$127,10,0) -> 5000 | J31: =(((+I31/30)*H31)*30%) -> 0 | K31: =VLOOKUP(C31,[1]IP!$B$9:$I$116,8,0) -> 0 | L31: =+J31-K31 -> 0 | M31: PITSS
A32: SEI0501 | B32: SEITON (IP INNOVA II) | C32: Cruz Herrera Roberto | D32: 1667.47 | E32: 226.5 | F32: =+L32 -> 0 | G32: =+D32+E32+F32 -> 1893.97 | H32: =VLOOKUP(C32,'IP PITS'!$B$9:$D$90,3,0) -> 0 | I32: =VLOOKUP(C32,[1]RESUMEN!$C$31:$L$127,10,0) -> 10000 | J32: =(((+I32/30)*H32)*30%) -> 0 | K32: =VLOOKUP(C32,[1]IP!$B$9:$I$116,8,0) -> 0 | L32: =+J32-K32 -> 0 | M32: PITSS
A33: SEI479 | B33: SEITON (IP INNOVA II) | C33: Cruz Perez Alejandro Nezahualcoyotl | D33: 416.4 | E33: 474 | F33: =+L33 -> 0 | G33: =+D33+E33+F33 -> 890.4 | H33: =VLOOKUP(C33,'IP PITS'!$B$9:$D$90,3,0) -> 0 | I33: =VLOOKUP(C33,[1]RESUMEN!$C$31:$L$127,10,0) -> 8000 | J33: =(((+I33/30)*H33)*30%) -> 0 | K33: =VLOOKUP(C33,[1]IP!$B$9:$I$116,8,0) -> 0 | L33: =+J33-K33 -> 0 | M33: PITSS
A34: SEI0401 | B34: SEITON - (CONSULTORIA II) | C34: De La Torre Zambara Francisco Ernesto | D34: 1558 | E34: =243.5+440 -> 683.5 | F34: =+L34 -> 0 | G34: =+D34+E34+F34 -> 2241.5 | H34: =VLOOKUP(C34,'CPD PITS'!$B$9:$D$27,3,0) -> 0 | I34: =VLOOKUP(C34,[1]RESUMEN!$C$4:$L$113,10,) -> 10150 | J34: =(((+I34/30)*H34)*30%) -> 0 | K34: =VLOOKUP(C34,[1]CPD!$B$9:$I$35,8,0) -> 0 | L34: =+J34-K34 -> 0 | M34: PITSS
A35: SEI0530 | B35: SEITON (IP INNOVA II) | C35: Del Pilar Mendez Lucio | D35: 134.2 | E35: 400 | F35: =+L35 -> 0 | G35: =+D35+E35+F35 -> 534.2 | H35: =VLOOKUP(C35,'IP PITS'!$B$9:$D$90,3,0) -> 0 | I35: =VLOOKUP(C35,[1]RESUMEN!$C$31:$L$127,10,0) -> 6000 | J35: =(((+I35/30)*H35)*30%) -> 0 | K35: =VLOOKUP(C35,[1]IP!$B$9:$I$116,8,0) -> 0 | L35: =+J35-K35 -> 0 | M35: PITSS
A36: SEI0543 | B36: SEITON (IP INNOVA II) | C36: Diaz Ortiz Hiram Guillermo | D36: 52.2 | F36: =+L36 -> 0 | G36: =+D36+E36+F36 -> 52.2 | H36: =VLOOKUP(C36,'IP PITS'!$B$9:$D$90,3,0) -> 0 | I36: 6300 | J36: =(((+I36/30)*H36)*30%) -> 0 | K36: =VLOOKUP(C36,[1]IP!$B$9:$I$116,8,0) -> 0 | L36: =+J36-K36 -> 0 | M36: PITSS
A37: SEI0364 | B37: SEITON (IP INNOVA II) | C37: Dominguez Lopez Mayeli Del Pilar | D37: 1416.33 | E37: 1250 | F37: =+L37 -> 0 | G37: =+D37+E37+F37 -> 2666.33 | H37: =VLOOKUP(C37,'IP PITS'!$B$9:$D$90,3,0) -> 0 | I37: =VLOOKUP(C37,[1]RESUMEN!$C$31:$L$127,10,0) -> 10000 | J37: =(((+I37/30)*H37)*30%) -> 0 | K37: =VLOOKUP(C37,[1]IP!$B$9:$I$116,8,0) -> 0 | L37: =+J37-K37 -> 0 | M37: PITSS
A38: SEI0474 | B38: SEITON (IP INNOVA II) | C38: Enriquez Zamora Jessica Del Rocio | D38: =109.8+25.42 -> 135.22 | E38: 292.5 | F38: =+L38 -> 0 | G38: =+D38+E38+F38 -> 427.72 | H38: =VLOOKUP(C38,'IP PITS'!$B$9:$D$90,3,0) -> 0 | I38: =VLOOKUP(C38,[1]RESUMEN!$C$31:$L$127,10,0) -> 6000 | J38: =(((+I38/30)*H38)*30%) -> 0 | K38: =VLOOKUP(C38,[1]IP!$B$9:$I$116,8,0) -> 0 | L38: =+J38-K38 -> 0 | M38: PITSS
A39: SEI0489 | B39: SEITON (IP INNOVA II) | C39: Escobedo Olivares Juan Guadalupe | D39: 3721.2 | E39: 166.67 | F39: =+L39 -> 0 | G39: =+D39+E39+F39 -> 3887.87 | H39: =VLOOKUP(C39,'IP PITS'!$B$9:$D$90,3,0) -> 0 | I39: =VLOOKUP(C39,[1]RESUMEN!$C$31:$L$127,10,0) -> 14000 | J39: =(((+I39/30)*H39)*30%) -> 0 | K39: =VLOOKUP(C39,[1]IP!$B$9:$I$116,8,0) -> 0 | L39: =+J39-K39 -> 0 | M39: PITSS
A40: SEI0449 | B40: SEITON (IP INNOVA II) | C40: Flores Cerrillos Jorge Humberto | D40: 416.4 | E40: 287 | F40: =+L40 -> 0 | G40: =+D40+E40+F40 -> 703.4 | H40: =VLOOKUP(C40,'IP PITS'!$B$9:$D$90,3,0) -> 0 | I40: =VLOOKUP(C40,[1]RESUMEN!$C$31:$L$127,10,0) -> 8000 | J40: =(((+I40/30)*H40)*30%) -> 0 | K40: =VLOOKUP(C40,[1]IP!$B$9:$I$116,8,0) -> 0 | L40: =+J40-K40 -> 0 | M40: PITSS
A41: SEI0461 | B41: SEITON (IP INNOVA II) | C41: Flores Franco Marco | D41: 451.005 | E41: 1200 | F41: =+L41 -> 0 | G41: =+D41+E41+F41 -> 1651.005 | H41: =VLOOKUP(C41,'IP PITS'!$B$9:$D$90,3,0) -> 0 | I41: =VLOOKUP(C41,[1]RESUMEN!$C$31:$L$127,10,0) -> 8500.01 | J41: =(((+I41/30)*H41)*30%) -> 0 | K41: =VLOOKUP(C41,[1]IP!$B$9:$I$116,8,0) -> 0 | L41: =+J41-K41 -> 0 | M41: PITSS
A42: SEI0500 | B42: SEITON (IP INNOVA II) | C42: Garcia Gutierrez Jose Juan | D42: 3135.2 | E42: 399.5 | F42: =+L42 -> 0 | G42: =+D42+E42+F42 -> 3534.7 | H42: =VLOOKUP(C42,'IP PITS'!$B$9:$D$90,3,0) -> 0 | I42: 12000 | J42: =(((+I42/30)*H42)*30%) -> 0 | K42: =VLOOKUP(C42,[1]IP!$B$9:$I$116,8,0) -> 0 | L42: =+J42-K42 -> 0 | M42: PITSS
A43: SEI0099 | B43: SEITON - (CONSULTORIA II) | C43: Garcia Villicaña Ricardo Pascual | D43: 2600.2 | E43: 216.5 | F43: =+L43 -> 0 | G43: =+D43+E43+F43 -> 2816.7 | H43: =VLOOKUP(C43,'CPD PITS'!$B$9:$D$27,3,0) -> 0 | I43: =VLOOKUP(C43,[1]RESUMEN!$C$4:$L$113,10,) -> 15000 | J43: =(((+I43/30)*H43)*30%) -> 0 | K43: =VLOOKUP(C43,[1]CPD!$B$9:$I$35,8,0) -> 0 | L43: =+J43-K43 -> 0 | M43: PITSS
A44: SEI0534 | B44: SEITON (IP INNOVA II) | C44: Gonzalez Ramirez Paul | D44: 134.2 | E44: 292.5 | F44: =+L44 -> 0 | G44: =+D44+E44+F44 -> 426.7 | H44: =VLOOKUP(C44,'IP PITS'!$B$9:$D$90,3,0) -> 0 | I44: =VLOOKUP(C44,[1]RESUMEN!$C$31:$L$127,10,0) -> 6000 | J44: =(((+I44/30)*H44)*30%) -> 0 | K44: =VLOOKUP(C44,[1]IP!$B$9:$I$116,8,0) -> 0 | L44: =+J44-K44 -> 0 | M44: PITSS
...

Sheet RESUMEN
A2: SUELDOS Y SALARIOS | G2: SINDICATO | K2: NETOS | O2: EXTRAS
A3: CLAVE | B3: EMPRESA | C3: NOMBRE | D3: NETO CPD | E3: NETO IP | F3: A | G3: PAGO SINDICATO | H3: COMISION | I3: PRIMA VACACIONAL SINDICATO | J3: B | K3: NETO A PAGAR | L3: NETO MENSUAL | M3: NETO QUINCENAL SEITON | N3: C | O3: prima vacacional | P3: COMISION Y PRIMA VACACIONAL | Q3: INFONAVIT | R3: INFONAVIT | S3: INFONAVIT | T3: INFONAVIT | U3: PRESTAMO | V3: APORTACION | W3: DESCUENTOS | X3: D | Y3: TOTAL GENERAL | Z3: DIFERENCIAS | AA3: OBSERVACIONES | AB3: CC
A4: SEI0009 | B4: SEITON - (CONSULTORIA II) | C4: Gutierrez Gutierrez Luis Arturo | D4: =VLOOKUP(C4,[2]CPD!$B$9:$Y$35,24,0) -> 2774.6 | G4: =VLOOKUP(C4,#REF!,4,0) -> #REF! | H4: =VLOOKUP(C4,#REF!,5,0) -> #REF! | I4: =VLOOKUP(C4,#REF!,6,0) -> #REF! | K4: =+D4+E4+G4+H4+I4 -> #REF! | L4: =VLOOKUP(C4,[1]ABC!$A$3:$B$88,2,0) -> 8500 | M4: =+L4/2 -> 4250 | O4: =VLOOKUP(C4,[2]CPD!$B$9:$I$35,8,0) -> 0 | P4: =+H4+I4 -> #REF! | Q4: =VLOOKUP(C4,[2]CPD!$B$9:$R$35,17,0) -> 0 | R4: =VLOOKUP(C4,[2]CPD!$B$9:$Q$35,16,0) -> 0 | S4: =VLOOKUP(C4,[1]CPD!$B$9:$S$35,18,0) -> 0 | T4: =VLOOKUP(C4,[2]CPD!$B$9:$T$35,19,0) -> 0 | W4: =VLOOKUP(C4,[2]CPD!$B$9:$V$35,21,0) -> 0 | Y4: =+K4-O4-P4+Q4+R4+S4+T4+U4+V4+W4 -> #REF! | Z4: =+M4-Y4 -> #REF! | AB4: =VLOOKUP(C4,[1]SINDICATO!$C$7:$Q$141,15,0) -> #N/A
A5: SEI0010 | B5: SEITON - (CONSULTORIA II) | C5: Compean Tobias Braulio Gerardo | D5: =VLOOKUP(C5,[2]CPD!$B$9:$Y$35,24,0) -> 4005.2 | G5: =VLOOKUP(C5,#REF!,4,0) -> #REF! | H5: =VLOOKUP(C5,#REF!,5,0) -> #REF! | I5: =VLOOKUP(C5,#REF!,6,0) -> #REF! | K5: =+D5+E5+G5+H5+I5 -> #REF! | L5: =VLOOKUP(C5,[1]ABC!$A$3:$B$88,2,0) -> 18000 | M5: =+L5/2 -> 9000 | O5: =VLOOKUP(C5,[2]CPD!$B$9:$I$35,8,0) -> 0 | P5: =+H5+I5 -> #REF! | Q5: =VLOOKUP(C5,[2]CPD!$B$9:$R$35,17,0) -> 1333.87 | R5: =VLOOKUP(C5,[2]CPD!$B$9:$Q$35,16,0) -> 0 | S5: =VLOOKUP(C5,[1]CPD!$B$9:$S$35,18,0) -> 0 | T5: =VLOOKUP(C5,[2]CPD!$B$9:$T$35,19,0) -> 15 | W5: =VLOOKUP(C5,[2]CPD!$B$9:$V$35,21,0) -> 0 | Y5: =+K5-O5-P5+Q5+R5+S5+T5+U5+V5+W5 -> #REF! | Z5: =+M5-Y5 -> #REF! | AB5: =VLOOKUP(C5,[1]SINDICATO!$C$7:$Q$141,15,0) -> 0
A6: SEI0026 | B6: SEITON - (CONSULTORIA II) | C6: Patricio Aguilar Jhonattan Cristian | D6: =VLOOKUP(C6,[2]CPD!$B$9:$Y$35,24,0) -> 2911.8 | G6: =VLOOKUP(C6,#REF!,4,0) -> #REF! | H6: =VLOOKUP(C6,#REF!,5,0) -> #REF! | I6: =VLOOKUP(C6,#REF!,6,0) -> #REF! | K6: =+D6+E6+G6+H6+I6 -> #REF! | L6: =VLOOKUP(C6,[1]ABC!$A$3:$B$88,2,0) -> 9000 | M6: =+L6/2 -> 4500 | O6: =VLOOKUP(C6,[2]CPD!$B$9:$I$35,8,0) -> 0 | P6: =+H6+I6 -> #REF! | Q6: =VLOOKUP(C6,[2]CPD!$B$9:$R$35,17,0) -> 0 | R6: =VLOOKUP(C6,[2]CPD!$B$9:$Q$35,16,0) -> 0 | S6: =VLOOKUP(C6,[1]CPD!$B$9:$S$35,18,0) -> 0 | T6: =VLOOKUP(C6,[2]CPD!$B$9:$T$35,19,0) -> 0 | W6: =VLOOKUP(C6,[2]CPD!$B$9:$V$35,21,0) -> 0 | Y6: =+K6-O6-P6+Q6+R6+S6+T6+U6+V6+W6 -> #REF! | Z6: =+M6-Y6 -> #REF! | AB6: =VLOOKUP(C6,[1]SINDICATO!$C$7:$Q$141,15,0) -> #N/A
A7: SEI0040 | B7: SEITON - (CONSULTORIA II) | C7: Mora Ramirez Acal Aldo Isidro | D7: =VLOOKUP(C7,[2]CPD!$B$9:$Y$35,24,0) -> 4036 | G7: =VLOOKUP(C7,#REF!,4,0) -> #REF! | H7: =VLOOKUP(C7,#REF!,5,0) -> #REF! | I7: =VLOOKUP(C7,#REF!,6,0) -> #REF! | K7: =+D7+E7+G7+H7+I7 -> #REF! | L7: 13000 | M7: =+L7/2 -> 6500 | O7: =VLOOKUP(C7,[2]CPD!$B$9:$I$35,8,0) -> 0 | P7: =+H7+I7 -> #REF! | Q7: =VLOOKUP(C7,[2]CPD!$B$9:$R$35,17,0) -> 0 | R7: =VLOOKUP(C7,[2]CPD!$B$9:$Q$35,16,0) -> 0 | S7: =VLOOKUP(C7,[1]CPD!$B$9:$S$35,18,0) -> 0 | T7: =VLOOKUP(C7,[2]CPD!$B$9:$T$35,19,0) -> 0 | W7: =VLOOKUP(C7,[2]CPD!$B$9:$V$35,21,0) -> 0 | Y7: =+K7-O7-P7+Q7+R7+S7+T7+U7+V7+W7 -> #REF! | Z7: =+M7-Y7 -> #REF! | AB7: =VLOOKUP(C7,[1]SINDICATO!$C$7:$Q$141,15,0) -> #N/A
A8: SEI0041 | B8: SEITON - (CONSULTORIA II) | C8: Vazquez Perez Miguel Angel | D8: =VLOOKUP(C8,[2]CPD!$B$9:$Y$35,24,0) -> 5074 | G8: =VLOOKUP(C8,#REF!,4,0) -> #REF! | H8: =VLOOKUP(C8,#REF!,5,0) -> #REF! | I8: =VLOOKUP(C8,#REF!,6,0) -> #REF! | K8: =+D8+E8+G8+H8+I8 -> #REF! | L8: =VLOOKUP(C8,[1]ABC!$A$3:$B$88,2,0) -> 18500 | M8: =+L8/2 -> 9250 | O8: =VLOOKUP(C8,[2]CPD!$B$9:$I$35,8,0) -> 0 | P8: =+H8+I8 -> #REF! | Q8: =VLOOKUP(C8,[2]CPD!$B$9:$R$35,17,0) -> 0 | R8: =VLOOKUP(C8,[2]CPD!$B$9:$Q$35,16,0) -> 0 | S8: =VLOOKUP(C8,[1]CPD!$B$9:$S$35,18,0) -> 0 | T8: =VLOOKUP(C8,[2]CPD!$B$9:$T$35,19,0) -> 0 | W8: =VLOOKUP(C8,[2]CPD!$B$9:$V$35,21,0) -> 0 | Y8: =+K8-O8-P8+Q8+R8+S8+T8+U8+V8+W8 -> #REF! | Z8: =+M8-Y8 -> #REF! | AB8: =VLOOKUP(C8,[1]SINDICATO!$C$7:$Q$141,15,0) -> #N/A
A9: SEI0088 | B9: SEITON - (CONSULTORIA II) | C9: Morgado Fernandez Martin | D9: =VLOOKUP(C9,[2]CPD!$B$9:$Y$35,24,0) -> 4899.6 | G9: =VLOOKUP(C9,#REF!,4,0) -> #REF! | H9: =VLOOKUP(C9,#REF!,5,0) -> #REF! | I9: =VLOOKUP(C9,#REF!,6,0) -> #REF! | K9: =+D9+E9+G9+H9+I9 -> #REF! | L9: =VLOOKUP(C9,[1]ABC!$A$3:$B$88,2,0) -> 15000 | M9: =+L9/2 -> 7500 | O9: =VLOOKUP(C9,[2]CPD!$B$9:$I$35,8,0) -> 0 | P9: =+H9+I9 -> #REF! | Q9: =VLOOKUP(C9,[2]CPD!$B$9:$R$35,17,0) -> 0 | R9: =VLOOKUP(C9,[2]CPD!$B$9:$Q$35,16,0) -> 0 | S9: =VLOOKUP(C9,[1]CPD!$B$9:$S$35,18,0) -> 0 | T9: =VLOOKUP(C9,[2]CPD!$B$9:$T$35,19,0) -> 0 | W9: =VLOOKUP(C9,[2]CPD!$B$9:$V$35,21,0) -> 0 | Y9: =+K9-O9-P9+Q9+R9+S9+T9+U9+V9+W9 -> #REF! | Z9: =+M9-Y9 -> #REF! | AB9: =VLOOKUP(C9,[1]SINDICATO!$C$7:$Q$141,15,0) -> #N/A
A10: SEI0097 | B10: SEITON - (CONSULTORIA II) | C10: Arreola Jimenez Jose Nieves | D10: =VLOOKUP(C10,[2]CPD!$B$9:$Y$35,24,0) -> 1927.6 | G10: =VLOOKUP(C10,#REF!,4,0) -> #REF! | H10: =VLOOKUP(C10,#REF!,5,0) -> #REF! | I10: =VLOOKUP(C10,#REF!,6,0) -> #REF! | K10: =+D10+E10+G10+H10+I10 -> #REF! | L10: =VLOOKUP(C10,[1]ABC!$A$3:$B$88,2,0) -> 10150 | M10: =+L10/2 -> 5075 | O10: =VLOOKUP(C10,[2]CPD!$B$9:$I$35,8,0) -> 0 | P10: =+H10+I10 -> #REF! | Q10: =VLOOKUP(C10,[2]CPD!$B$9:$R$35,17,0) -> 1574.29 | R10: =VLOOKUP(C10,[2]CPD!$B$9:$Q$35,16,0) -> 0 | S10: =VLOOKUP(C10,[1]CPD!$B$9:$S$35,18,0) -> 0 | T10: =VLOOKUP(C10,[2]CPD!$B$9:$T$35,19,0) -> 15 | W10: =VLOOKUP(C10,[2]CPD!$B$9:$V$35,21,0) -> 0 | Y10: =+K10-O10-P10+Q10+R10+S10+T10+U10+V10+W10 -> #REF! | Z10: =+M10-Y10 -> #REF! | AB10: =VLOOKUP(C10,[1]SINDICATO!$C$7:$Q$141,15,0) -> #N/A
A11: SEI0099 | B11: SEITON - (CONSULTORIA II) | C11: Garcia Villicaña Ricardo Pascual | D11: =VLOOKUP(C11,[2]CPD!$B$9:$Y$35,24,0) -> 4899.8 | G11: =VLOOKUP(C11,#REF!,4,0) -> #REF! | H11: =VLOOKUP(C11,#REF!,5,0) -> #REF! | I11: =VLOOKUP(C11,#REF!,6,0) -> #REF! | K11: =+D11+E11+G11+H11+I11 -> #REF! | L11: =VLOOKUP(C11,[1]ABC!$A$3:$B$88,2,0) -> 15000 | M11: =+L11/2 -> 7500 | O11: =VLOOKUP(C11,[2]CPD!$B$9:$I$35,8,0) -> 0 | P11: =+H11+I11 -> #REF! | Q11: =VLOOKUP(C11,[2]CPD!$B$9:$R$35,17,0) -> 0 | R11: =VLOOKUP(C11,[2]CPD!$B$9:$Q$35,16,0) -> 0 | S11: =VLOOKUP(C11,[1]CPD!$B$9:$S$35,18,0) -> 0 | T11: =VLOOKUP(C11,[2]CPD!$B$9:$T$35,19,0) -> 0 | W11: =VLOOKUP(C11,[2]CPD!$B$9:$V$35,21,0) -> 0 | Y11: =+K11-O11-P11+Q11+R11+S11+T11+U11+V11+W11 -> #REF! | Z11: =+M11-Y11 -> #REF! | AB11: =VLOOKUP(C11,[1]SINDICATO!$C$7:$Q$141,15,0) -> #N/A
A12: SEI0108 | B12: SEITON - (CONSULTORIA II) | C12: Caballero Diaz Francisco Javier | D12: =VLOOKUP(C12,[2]CPD!$B$9:$Y$35,24,0) -> 1675.4 | G12: =VLOOKUP(C12,#REF!,4,0) -> #REF! | H12: =VLOOKUP(C12,#REF!,5,0) -> #REF! | I12: =VLOOKUP(C12,#REF!,6,0) -> #REF! | K12: =+D12+E12+G12+H12+I12 -> #REF! | L12: =VLOOKUP(C12,[1]ABC!$A$3:$B$88,2,0) -> 10150 | M12: =+L12/2 -> 5075 | O12: =VLOOKUP(C12,[2]CPD!$B$9:$I$35,8,0) -> 0 | P12: =+H12+I12 -> #REF! | Q12: =VLOOKUP(C12,[2]CPD!$B$9:$R$35,17,0) -> 1826.51 | R12: =VLOOKUP(C12,[2]CPD!$B$9:$Q$35,16,0) -> 0 | S12: =VLOOKUP(C12,[1]CPD!$B$9:$S$35,18,0) -> 0 | T12: =VLOOKUP(C12,[2]CPD!$B$9:$T$35,19,0) -> 15 | W12: =VLOOKUP(C12,[2]CPD!$B$9:$V$35,21,0) -> 0 | Y12: =+K12-O12-P12+Q12+R12+S12+T12+U12+V12+W12 -> #REF! | Z12: =+M12-Y12 -> #REF! | AB12: =VLOOKUP(C12,[1]SINDICATO!$C$7:$Q$141,15,0) -> #N/A
A13: SEI0116 | B13: SEITON - (CONSULTORIA II) | C13: Casillas Cardona Cesar Alejandro | D13: =VLOOKUP(C13,[2]CPD!$B$9:$Y$35,24,0) -> 3336.6 | G13: =VLOOKUP(C13,#REF!,4,0) -> #REF! | H13: =VLOOKUP(C13,#REF!,5,0) -> #REF! | I13: =VLOOKUP(C13,#REF!,6,0) -> #REF! | K13: =+D13+E13+G13+H13+I13 -> #REF! | L13: =VLOOKUP(C13,[1]ABC!$A$3:$B$88,2,0) -> 12000 | M13: =+L13/2 -> 6000 | O13: =VLOOKUP(C13,[2]CPD!$B$9:$I$35,8,0) -> 0 | P13: =+H13+I13 -> #REF! | Q13: =VLOOKUP(C13,[2]CPD!$B$9:$R$35,17,0) -> 757.32 | R13: =VLOOKUP(C13,[2]CPD!$B$9:$Q$35,16,0) -> 0 | S13: =VLOOKUP(C13,[1]CPD!$B$9:$S$35,18,0) -> 0 | T13: =VLOOKUP(C13,[2]CPD!$B$9:$T$35,19,0) -> 15 | W13: =VLOOKUP(C13,[2]CPD!$B$9:$V$35,21,0) -> 0 | Y13: =+K13-O13-P13+Q13+R13+S13+T13+U13+V13+W13 -> #REF! | Z13: =+M13-Y13 -> #REF! | AB13: =VLOOKUP(C13,[1]SINDICATO!$C$7:$Q$141,15,0) -> #N/A
A14: SEI0117 | B14: SEITON - (CONSULTORIA II) | C14: Mariscal Romero Luis Adrian | D14: =VLOOKUP(C14,[2]CPD!$B$9:$Y$35,24,0) -> 3060 | G14: =VLOOKUP(C14,#REF!,4,0) -> #REF! | H14: =VLOOKUP(C14,#REF!,5,0) -> #REF! | I14: =VLOOKUP(C14,#REF!,6,0) -> #REF! | K14: =+D14+E14+G14+H14+I14 -> #REF! | L14: 15000 | M14: =+L14/2 -> 7500 | O14: =VLOOKUP(C14,[2]CPD!$B$9:$I$35,8,0) -> 0 | P14: =+H14+I14 -> #REF! | Q14: =VLOOKUP(C14,[2]CPD!$B$9:$R$35,17,0) -> 1674 | R14: =VLOOKUP(C14,[2]CPD!$B$9:$Q$35,16,0) -> 0 | S14: =VLOOKUP(C14,[1]CPD!$B$9:$S$35,18,0) -> 0 | T14: =VLOOKUP(C14,[2]CPD!$B$9:$T$35,19,0) -> 15 | W14: =VLOOKUP(C14,[2]CPD!$B$9:$V$35,21,0) -> 0 | Y14: =+K14-O14-P14+Q14+R14+S14+T14+U14+V14+W14 -> #REF! | Z14: =+M14-Y14 -> #REF! | AB14: =VLOOKUP(C14,[1]SINDICATO!$C$7:$Q$141,15,0) -> #N/A
A15: SEI0118 | B15: SEITON - (CONSULTORIA II) | C15: Arroyo Ramirez Hector Hugo | D15: =VLOOKUP(C15,[2]CPD!$B$9:$Y$35,24,0) -> 2967.4 | G15: =VLOOKUP(C15,#REF!,4,0) -> #REF! | H15: =VLOOKUP(C15,#REF!,5,0) -> #REF! | I15: =VLOOKUP(C15,#REF!,6,0) -> #REF! | K15: =+D15+E15+G15+H15+I15 -> #REF! | L15: =VLOOKUP(C15,[1]ABC!$A$3:$B$88,2,0) -> 13000 | M15: =+L15/2 -> 6500 | O15: =VLOOKUP(C15,[2]CPD!$B$9:$I$35,8,0) -> 285.99 | P15: =+H15+I15 -> #REF! | Q15: =VLOOKUP(C15,[2]CPD!$B$9:$R$35,17,0) -> 1432.4 | R15: =VLOOKUP(C15,[2]CPD!$B$9:$Q$35,16,0) -> 0 | S15: =VLOOKUP(C15,[1]CPD!$B$9:$S$35,18,0) -> 0 | T15: =VLOOKUP(C15,[2]CPD!$B$9:$T$35,19,0) -> 15 | W15: =VLOOKUP(C15,[2]CPD!$B$9:$V$35,21,0) -> 268.35 | Y15: =+K15-O15-P15+Q15+R15+S15+T15+U15+V15+W15 -> #REF! | Z15: =+M15-Y15 -> #REF! | AB15: =VLOOKUP(C15,[1]SINDICATO!$C$7:$Q$141,15,0) -> #N/A
A16: SEI0119 | B16: SEITON - (CONSULTORIA II) | C16: Dominguez Lopez Maria De Jesus | D16: =VLOOKUP(C16,[2]CPD!$B$9:$Y$35,24,0) -> 4635.4 | G16: =VLOOKUP(C16,#REF!,4,0) -> #REF! | H16: =VLOOKUP(C16,#REF!,5,0) -> #REF! | I16: =VLOOKUP(C16,#REF!,6,0) -> #REF! | J16: 0 | K16: =+D16+E16+G16+H16+I16 -> #REF! | L16: 13000 | M16: =+L16/2 -> 6500 | O16: =VLOOKUP(C16,[2]CPD!$B$9:$I$35,8,0) -> 786.49 | P16: =+H16+I16 -> #REF! | Q16: =VLOOKUP(C16,[2]CPD!$B$9:$R$35,17,0) -> 0 | R16: =VLOOKUP(C16,[2]CPD!$B$9:$Q$35,16,0) -> 533.16 | S16: =VLOOKUP(C16,[1]CPD!$B$9:$S$35,18,0) -> 0 | T16: =VLOOKUP(C16,[2]CPD!$B$9:$T$35,19,0) -> 15 | W16: =VLOOKUP(C16,[2]CPD!$B$9:$V$35,21,0) -> 0 | X16: 0 | Y16: =+K16-O16-P16+Q16+R16+S16+T16+U16+V16+W16 -> #REF! | Z16: =+M16-Y16 -> #REF! | AB16: =VLOOKUP(C16,[1]SINDICATO!$C$7:$Q$141,15,0) -> 0
A17: SEI0127 | B17: SEITON - (CONSULTORIA II) | C17: Hernandez Ochoa Eduardo | D17: =VLOOKUP(C17,[2]CPD!$B$9:$Y$35,24,0) -> 4899.8 | G17: =VLOOKUP(C17,#REF!,4,0) -> #REF! | H17: =VLOOKUP(C17,#REF!,5,0) -> #REF! | I17: =VLOOKUP(C17,#REF!,6,0) -> #REF! | K17: =+D17+E17+G17+H17+I17 -> #REF! | L17: =VLOOKUP(C17,[1]ABC!$A$3:$B$88,2,0) -> 15000 | M17: =+L17/2 -> 7500 | O17: =VLOOKUP(C17,[2]CPD!$B$9:$I$35,8,0) -> 0 | P17: =+H17+I17 -> #REF! | Q17: =VLOOKUP(C17,[2]CPD!$B$9:$R$35,17,0) -> 0 | R17: =VLOOKUP(C17,[2]CPD!$B$9:$Q$35,16,0) -> 0 | S17: =VLOOKUP(C17,[1]CPD!$B$9:$S$35,18,0) -> 0 | T17: =VLOOKUP(C17,[2]CPD!$B$9:$T$35,19,0) -> 0 | W17: =VLOOKUP(C17,[2]CPD!$B$9:$V$35,21,0) -> 0 | Y17: =+K17-O17-P17+Q17+R17+S17+T17+U17+V17+W17 -> #REF! | Z17: =+M17-Y17 -> #REF! | AB17: =VLOOKUP(C17,[1]SINDICATO!$C$7:$Q$141,15,0) -> #N/A
A18: SEI0147 | B18: SEITON - (CONSULTORIA II) | C18: Diaz Munguia Martha Liliana | D18: =VLOOKUP(C18,[2]CPD!$B$9:$Y$35,24,0) -> 5056.2 | G18: =VLOOKUP(C18,#REF!,4,0) -> #REF! | H18: =VLOOKUP(C18,#REF!,5,0) -> #REF! | I18: =VLOOKUP(C18,#REF!,6,0) -> #REF! | K18: =+D18+E18+G18+H18+I18 -> #REF! | L18: 25000 | M18: =+L18/2 -> 12500 | O18: =VLOOKUP(C18,[2]CPD!$B$9:$I$35,8,0) -> 0 | P18: =+H18+I18 -> #REF! | Q18: =VLOOKUP(C18,[2]CPD!$B$9:$R$35,17,0) -> 419.76 | R18: =VLOOKUP(C18,[2]CPD!$B$9:$Q$35,16,0) -> 0 | S18: =VLOOKUP(C18,[1]CPD!$B$9:$S$35,18,0) -> 0 | T18: =VLOOKUP(C18,[2]CPD!$B$9:$T$35,19,0) -> 15 | W18: =VLOOKUP(C18,[2]CPD!$B$9:$V$35,21,0) -> 0 | Y18: =+K18-O18-P18+Q18+R18+S18+T18+U18+V18+W18 -> #REF! | Z18: =+M18-Y18 -> #REF! | AB18: =VLOOKUP(C18,[1]SINDICATO!$C$7:$Q$141,15,0) -> 0
