Workbook

Sheet FACTURACION SINDICATO
B2: codigo | C2: empres | D2: nombre | E2: PAGO POR SINDICATO | F2: comision y bono | G2: prima vacaciones | H2: TOTAL | I2: CC
B3: SEI0097 | C3: SEITON - (CONSULTORIA II) | D3: Arreola Jimenez Jose Nieves | E3: 1558.05 | F3: 2975 | G3: 0 | H3: 4533.05 | I3: AA
B4: SEI0118 | C4: SEITON - (CONSULTORIA II) | D4: Arroyo Ramirez Hector Hugo | E4: 2103.54 | G4: 234 | H4: 2337.54 | I4: AA
B5: SEI0108 | C5: SEITON - (CONSULTORIA II) | D5: Caballero Diaz Francisco Javier | E5: 1558.01 | G5: 0 | H5: 1558.01 | I5: AA
B6: SEI0425 | C6: SEITON - (CONSULTORIA II) | D6: Carbajal Cabuto Jose Luis | E6: 1608.07 | G6: 0 | H6: 1608.07 | I6: AA
B7: SEI0116 | C7: SEITON - (CONSULTORIA II) | D7: Casillas Cardona Cesar Alejandro | E7: 1891.22 | G7: 0 | H7: 1891.22 | I7: AA
B8: SEI0401 | C8: SEITON - (CONSULTORIA II) | D8: De La Torre Zambara Francisco Ernesto | E8: 78.08 | G8: 0 | H8: 78.08 | I8: AA
B9: SEI0119 | C9: SEITON - (CONSULTORIA II) | D9: Dominguez Lopez Maria De Jesus | E9: 0 | G9: 0 | H9: 0 | I9: AA
B10: SEI0099 | C10: SEITON - (CONSULTORIA II) | D10: Garcia Villicaña Ricardo Pascual | E10: 2600.8 | F10: 600 | G10: 0 | H10: 3200.8 | I10: AA
B11: SEI0009 | C11: SEITON - (CONSULTORIA II) | D11: Gutierrez Gutierrez Luis Arturo | E11: 1474.6 | G11: 0 | H11: 1474.6 | I11: AA
B12: SEI0127 | C12: SEITON - (CONSULTORIA II) | D12: Hernandez Ochoa Eduardo | E12: 2601 | G12: 0 | H12: 2601 | I12: AA
B13: SEI0088 | C13: SEITON - (CONSULTORIA II) | D13: Morgado Fernandez Martin | E13: 2601 | F13: 1125 | G13: 0 | H13: 3726 | I13: AA
B14: SEI0173 | C14: SEITON - (CONSULTORIA II) | D14: Nieto Ortiz Jose Luis | E14: 1483.15 | F14: 1232 | G14: 0 | H14: 2715.15 | I14: AA
B15: SEI0026 | C15: SEITON - (CONSULTORIA II) | D15: Patricio Aguilar Jhonattan Cristian | E15: 1588 | G15: 0 | H15: 1588 | I15: AA
B16: SEI0027 | C16: SEITON - (CONSULTORIA II) | D16: Tavares Guzman Jose Enrique | E16: 2378.2 | G16: 0 | H16: 2378.2 | I16: AA
B17: SEI032 | C17: SEITON - (CONSULTORIA II) | D17: Camarena Quiroz Erick Frank | E17: 1588 | F17: 225 | G17: 0 | H17: 1813 | I17: AA
B18: SEI0438 | C18: SEITON - (CONSULTORIA II) | D18: Valdes Arrioja Karla Naborina | E18: 1803.2 | H18: 1803.2 | I18: AA
B19: SEI0482 | C19: SEITON (IP INNOVA II) | D19: Camarillo Canela Reynaldo | E19: 2236.64 | F19: 2150 | G19: 0 | H19: 4386.64 | I19: AA
B20: SEI0485 | C20: SEITON (IP INNOVA II) | D20: Molina Ramirez Gerardo Daniel | E20: 2271.77 | G20: 0 | H20: 2271.77 | I20: AA
B21: SEI0488 | C21: SEITON (IP INNOVA II) | D21: Mireles Casillas Brenda Cristina | E21: 2257 | G21: 0 | H21: 2257 | I21: AA
B22: SEI0489 | C22: SEITON (IP INNOVA II) | D22: Escobedo Olivares Juan Guadalupe | E22: 3723.8 | G22: 0 | H22: 3723.8 | I22: AA
B23: SEI0490 | C23: SEITON (IP INNOVA II) | D23: Castillo Ramirez Hector Ivan | E23: 3753.78 | F23: 1280 | G23: 0 | H23: 5033.78 | I23: AA
B24: SEI0492 | C24: SEITON (IP INNOVA II) | D24: Cadena Ramirez Hugo | E24: 2513.4 | G24: 0 | H24: 2513.4 | I24: AA
B25: SEI0493 | C25: SEITON (IP INNOVA II) | D25: Martinez Morales Tomas | E25: 3397.14 | F25: 1320 | G25: 0 | H25: 4717.14 | I25: AA
B26: SEI0494 | C26: SEITON (IP INNOVA II) | D26: Medellin Colunga Ruben Dario | E26: 4412.14 | F26: 2320 | G26: 0 | H26: 6732.14 | I26: AA
B27: SEI0495 | C27: SEITON (IP INNOVA II) | D27: Torres Perez Carlos Alberto | E27: 1685.3 | F27: 4495 | G27: 0 | H27: 6180.3 | I27: AA
B28: SEI0496 | C28: SEITON (IP INNOVA II) | D28: Velazquez Herrera Nayeli | E28: 3382.26 | F28: 950 | G28: 56.14 | H28: 4388.4 | I28: AA
B29: SEI0497 | C29: SEITON (IP INNOVA II) | D29: Treviño Alvarez Jorge Alberto | E29: 2700.29 | F29: 680 | G29: 0 | H29: 3380.29 | I29: AA
B30: SEI0498 | C30: SEITON (IP INNOVA II) | D30: Tenorio Alvarez Alberto Antonio | E30: 1685.2 | G30: 0 | H30: 1685.2 | I30: AA
B31: SEI0499 | C31: SEITON (IP INNOVA II) | D31: Chavez Dominguez Salvador | E31: 2685.2 | G31: 0 | H31: 2685.2 | I31: AA
B32: SEI0500 | C32: SEITON (IP INNOVA II) | D32: Garcia Gutierrez Jose Juan | E32: 1685.2 | G32: 0 | H32: 1685.2 | I32: AA
B33: SEI0501 | C33: SEITON (IP INNOVA II) | D33: Cruz Herrera Roberto | E33: 1670.2 | G33: 0 | H33: 1670.2 | I33: AA
B34: SEI0502 | C34: SEITON (IP INNOVA II) | D34: Dominguez Escamilla Victor Hugo | E34: 2700.14 | G34: 0 | H34: 2700.14 | I34: AA
B35: SEI0503 | C35: SEITON (IP INNOVA II) | D35: Martinez Rodriguez Paulo Cesar | E35: 2554.8 | G35: 0 | H35: 2554.8 | I35: AA
B36: SEI0504 | C36: SEITON (IP INNOVA II) | D36: Martinez Malo Cesar | E36: 1711.46 | G36: 0 | H36: 1711.46 | I36: AA
B37: SEI0505 | C37: SEITON (IP INNOVA II) | D37: Perez Balboa Cesar | E37: 2211.65 | G37: 0 | H37: 2211.65 | I37: AA
B38: SEI0506 | C38: SEITON (IP INNOVA II) | D38: Mejia Duarte Jose Luis | E38: 2570.57 | G38: 0 | H38: 2570.57 | I38: AA
B39: SEI0507 | C39: SEITON (IP INNOVA II) | D39: Diaz Saldierna Leonel Gonzalo | E39: 2585.53 | G39: 0 | H39: 2585.53 | I39: AA
B40: SEI0508 | C40: SEITON (IP INNOVA II) | D40: Cerro Garcia Elvis | E40: 2570.6 | F40: 2125 | G40: 0 | H40: 4695.6 | I40: AA
B41: SEI0078 | C41: SEITON (IP INNOVA II) | D41: Aguilar Leal Karina Livier | E41: 952.25 | F41: 16065.1 | G41: 10 | H41: 17027.35 | I41: AA
...

Sheet CPD PITS
B1: CONSULTORIA EN PROYECTOS DINAMICOS S DE RL DE CV
B2: Lista de Raya (forma tabular)
B3: Reg Pat IMSS: Z2940859106
B4: RFC: CPD -150911-FA3
A5: Código | B5: Empleado | C5: Dias Laborados | D5: Dias Vacaciones | E5: Salario Diario | F5: Salario Diario Integrado | G5: Sueldo | H5: Vacaciones a tiempo | I5: Prima de vacaciones a tiempo | J5: Ayuda de Transporte | K5: Ayuda Alimentaria | L5: Ayuda de Renta | M5: *TOTAL* *PERCEPCIONES* | N5: I.S.R. (sp) | O5: Subsidio al Empleo (sp) | P5: I.M.S.S. | Q5: Préstamo Infonavit | R5: Préstamo Infonavit (vsm) | S5: Deduccion general | T5: Ajuste al neto | U5: *TOTAL* *DEDUCCIONES* | V5: *NETO* | W5: Invalidez y Vida | X5: Cesantia y Vejez | Y5: Enf. y Mat. Patron | Z5: 2% Fondo retiro SAR (8) | AA5: 2% Impuesto estatal | AB5: Riesgo de trabajo (9) | AC5: I.M.S.S. empresa | AD5: Infonavit empresa | AE5: Guarderia I.M.S.S. (7) | AF5: Proporcion Aguinaldo | AG5: Banco
A6: SEI0009 | B6: Gutierrez Gutierrez Luis Arturo | C6: 15 | D6: 0 | E6: 141.67 | F6: 150.25 | G6: 2125.05 | H6: 0 | I6: 0 | J6: 212.51 | K6: 212.51 | L6: 212.51 | M6: 2762.58 | N6: 0 | O6: -65.5 | P6: 57.11 | Q6: 0 | R6: 0 | S6: 0 | T6: -0.03 | U6: -8.42 | V6: 2771 | W6: 42.07 | X6: 75.73 | Y6: 317.85 | Z6: 236.93 | AA6: 55.25 | AB6: 12.02 | AC6: 435.65 | AD6: 120.2 | AE6: 212.89 | AF6: 151.27396 | AG6: 12
A7: SEI0026 | B7: Patricio Aguilar Jhonattan Cristian | C7: 15 | D7: 0 | E7: 150 | F7: 159.07 | G7: 2250 | H7: 0 | I7: 0 | J7: 225 | K7: 225 | L7: 225 | M7: 2925 | N7: 0 | O7: -43.57 | P7: 60.44 | Q7: 0 | R7: 0 | S7: 0 | T7: -0.07 | U7: 16.8 | V7: 2908.2 | W7: 44.54 | X7: 80.17 | Y7: 320.32 | Z7: 239.75 | AA7: 58.5 | AB7: 12.73 | AC7: 445.03 | AD7: 127.26 | AE7: 214.3 | AF7: 160.16866 | AG7: 12
A8: SEI0040 | B8: Mora Ramirez Acal Aldo Isidro | C8: 15 | D8: 0 | E8: 216.67 | F8: 229.79 | G8: 3250.05 | H8: 0 | I8: 0 | J8: 325.01 | K8: 325.01 | L8: 325.01 | M8: 4225.08 | N8: 107.17 | O8: 0 | P8: 87.32 | Q8: 0 | R8: 0 | S8: 0 | T8: -0.01 | U8: 194.48 | V8: 4030.6 | W8: 64.34 | X8: 115.81 | Y8: 340.12 | Z8: 262.38 | AA8: 84.5 | AB8: 18.38 | AC8: 520.27 | AD8: 183.83 | AE8: 225.62 | AF8: 231.35828 | AG8: 12
A9: SEI0041 | B9: Vazquez Perez Miguel Angel | C9: 15 | D9: 0 | E9: 283.33 | F9: 300.49 | G9: 4249.95 | H9: 0 | I9: 0 | J9: 425 | K9: 425 | L9: 425 | M9: 5524.95 | N9: 341.06 | O9: 0 | P9: 117.2 | Q9: 0 | R9: 0 | S9: 0 | T9: -0.11 | U9: 458.15 | V9: 5066.8 | W9: 84.14 | X9: 151.45 | Y9: 368.19 | Z9: 285.01 | AA9: 110.5 | AB9: 24.04 | AC9: 603.78 | AD9: 240.39 | AE9: 236.93 | AF9: 302.53724 | AG9: 12
A10: SEI0088 | B10: Morgado Fernandez Martin | C10: 15 | D10: 0 | E10: 273.33 | F10: 289.87 | G10: 4099.95 | H10: 0 | I10: 0 | J10: 410 | K10: 410 | L10: 410 | M10: 5329.95 | N10: 324.74 | O10: 0 | P10: 112.48 | Q10: 0 | R10: 0 | S10: 0 | T10: -0.07 | U10: 437.15 | V10: 4892.8 | W10: 81.16 | X10: 146.09 | Y10: 363.36 | Z10: 281.61 | AA10: 106.6 | AB10: 23.19 | AC10: 590.61 | AD10: 231.89 | AE10: 235.23 | AF10: 291.85933 | AG10: 12
A11: SEI0097 | B11: Arreola Jimenez Jose Nieves | C11: 15 | D11: 0 | E11: 185.83 | F11: 197.07 | G11: 2787.45 | H11: 0 | I11: 0 | J11: 278.75 | K11: 278.75 | L11: 278.75 | M11: 3623.7 | N11: 36.57 | O11: 0 | P11: 74.88 | Q11: 0 | R11: 1574.29 | S11: 120 | T11: -0.04 | U11: 1805.7 | V11: 1818 | W11: 55.18 | X11: 99.32 | Y11: 330.96 | Z11: 251.91 | AA11: 72.47 | AB11: 15.77 | AC11: 485.46 | AD11: 157.66 | AE11: 220.38 | AF11: 198.42761 | AG11: 12
A12: SEI0099 | B12: Garcia Villicaña Ricardo Pascual | C12: 15 | D12: 0 | E12: 273.33 | F12: 289.87 | G12: 4099.95 | H12: 0 | I12: 0 | J12: 410 | K12: 410 | L12: 410 | M12: 5329.95 | N12: 324.74 | O12: 0 | P12: 112.48 | Q12: 0 | R12: 0 | S12: 0 | T12: -0.07 | U12: 437.15 | V12: 4892.8 | W12: 81.16 | X12: 146.09 | Y12: 363.36 | Z12: 281.61 | AA12: 106.6 | AB12: 23.19 | AC12: 590.61 | AD12: 231.89 | AE12: 235.23 | AF12: 291.85933 | AG12: 12
A13: SEI0108 | B13: Caballero Diaz Francisco Javier | C13: 15 | D13: 0 | E13: 185.83 | F13: 197.07 | G13: 2787.45 | H13: 0 | I13: 0 | J13: 278.75 | K13: 278.75 | L13: 278.75 | M13: 3623.7 | N13: 36.57 | O13: 0 | P13: 74.88 | Q13: 0 | R13: 1826.51 | S13: 0 | T13: -0.06 | U13: 1937.9 | V13: 1685.8 | W13: 55.18 | X13: 99.32 | Y13: 330.96 | Z13: 251.91 | AA13: 72.47 | AB13: 15.77 | AC13: 485.46 | AD13: 157.66 | AE13: 220.38 | AF13: 198.42761 | AG13: 12
A14: SEI0116 | B14: Casillas Cardona Cesar Alejandro | C14: 15 | D14: 0 | E14: 220.83 | F14: 234.19 | G14: 3312.45 | H14: 0 | I14: 0 | J14: 331.25 | K14: 331.25 | L14: 331.25 | M14: 4306.2 | N14: 113.96 | O14: 0 | P14: 88.99 | Q14: 0 | R14: 896.6 | S14: 0 | T14: 0.05 | U14: 1099.6 | V14: 3206.6 | W14: 65.57 | X14: 118.03 | Y14: 341.35 | Z14: 263.79 | AA14: 86.12 | AB14: 18.74 | AC14: 524.95 | AD14: 187.35 | AE14: 226.32 | AF14: 235.8003 | AG14: 12
A15: SEI0117 | B15: Mariscal Romero Luis Adrian | C15: 15 | D15: 0 | E15: 264.58 | F15: 276.54 | G15: 3968.7 | H15: 0 | I15: 0 | J15: 396.87 | K15: 396.87 | L15: 396.87 | M15: 5159.31 | N15: 310.46 | O15: 0 | P15: 106.56 | Q15: 0 | R15: 1674 | S15: 0 | T15: 0.09 | U15: 2091.11 | V15: 3068.2 | W15: 77.43 | X15: 139.38 | Y15: 357.27 | Z15: 277.34 | AA15: 103.19 | AB15: 22.12 | AC15: 574.08 | AD15: 221.23 | AE15: 233.1 | AF15: 282.51615 | AG15: 12
A16: SEI0118 | B16: Arroyo Ramirez Hector Hugo | C16: 15 | D16: 0 | E16: 238.33 | F16: 252.75 | G16: 3574.95 | H16: 0 | I16: 0 | J16: 357.5 | K16: 357.5 | L16: 357.5 | M16: 4647.45 | N16: 160.25 | O16: 0 | P16: 96.03 | Q16: 0 | R16: 1432.4 | S16: 268.35 | T16: 0.02 | U16: 1957.05 | V16: 2690.4 | W16: 70.77 | X16: 127.39 | Y16: 346.55 | Z16: 269.73 | AA16: 92.95 | AB16: 20.22 | AC16: 544.71 | AD16: 202.2 | AE16: 229.29 | AF16: 254.48664 | AG16: 12
A17: SEI0127 | B17: Hernandez Ochoa Eduardo | C17: 15 | D17: 0 | E17: 273.33 | F17: 289.87 | G17: 4099.95 | H17: 0 | I17: 0 | J17: 410 | K17: 410 | L17: 410 | M17: 5329.95 | N17: 324.74 | O17: 0 | P17: 112.48 | Q17: 0 | R17: 0 | S17: 0 | T17: 0.13 | U17: 437.35 | V17: 4892.6 | W17: 81.16 | X17: 146.09 | Y17: 363.36 | Z17: 281.61 | AA17: 106.6 | AB17: 23.19 | AC17: 590.61 | AD17: 231.89 | AE17: 235.23 | AF17: 291.85933 | AG17: 12
... A24: SEI0445 | B24: Muñoz Melgoza Gabriel | C24: 14 | D24: 0 | E24: 256.67 | F24: 272.21 | G24: 3593.38 | H24: 0 | I24: 0 | J24: 359.34 | K24: 359.34 | L24: 359.34 | M24: 4671.4 | N24: 162.25 | O24: 0 | P24: 99.88 | Q24: 0 | R24: 0 | S24: 0 | T24: 0.07 | U24: 262.2 | V24: 4409.2 | W24: 76.22 | X24: 137.19 | Y24: 355.3 | Z24: 275.96 | AA24: 93.43 | AB24: 21.78 | AC24: 568.71 | AD24: 217.77 | AE24: 232.4 | AF24: 274.06993 | AG24: 12
A25: Total Depto | C25: ----------------------- | D25: ----------------------- | E25: ----------------------- | F25: ----------------------- | G25: ----------------------- | H25: ----------------------- | I25: ----------------------- | J25: ----------------------- | K25: ----------------------- | L25: ----------------------- | M25: ----------------------- | N25: ----------------------- | O25: ----------------------- | P25: ----------------------- | Q25: ----------------------- | R25: ----------------------- | S25: ----------------------- | T25: ----------------------- | U25: ----------------------- | V25: ----------------------- | W25: ----------------------- | X25: ----------------------- | Y25: ----------------------- | Z25: ----------------------- | AA25: ----------------------- | AB25: ----------------------- | AC25: ----------------------- | AD25: ----------------------- | AF25: ----------------------- | AG25: -----------------------
A26: =SUM(A6:A25) -> 0 | B26: =SUM(B6:B25) -> 0 | C26: =SUM(C6:C25) -> 282 | D26: =SUM(D6:D25) -> 2 | E26: =SUM(E6:E25) -> 4965.39 | F26: =SUM(F6:F25) -> 5261.86 | G26: =SUM(G6:G25) -> 72977.52 | H26: =SUM(H6:H25) -> 1246.66 | ... AG26: =SUM(AG6:AG25) -> 228
A28: 19 | B28: Nomina | L28: FACTURACON PITS
A29: 0 | B29: Altas | L29: Devengado Salario | M29: =+Y26 -> 6901.43
A30: 0 | B30: Bajas | L30: RETORNOS | M30: =+V26 -> 77416.4
A31: =+A28+A29-A30 -> 19 | B31: Total Nomina | L31: Infonavit | M31: =+S26+R26+Q26+T26 -> 12199.17
L32: Prestamo Prospera | M32: =+U26 -> 19449.28
L33: Subtotal 1 | M33: =SUM(M29:M32) -> 115966.28
L34: Comision | M34: =+M33*2% -> 2319.3256
L35: Subtotal 2 | M35: =+M33+M34 -> 118285.61
L36: Costo Patronal Imss | M36: =+P26+W26+X26+Y26+AB26+Z26+AD26+AE26 -> 27422.3
L37: 2% Sobre Nomina | M37: =+M26*2% -> 1937.3136
L38: Importe de Factura | M38: =+M35+M36+M37 -> 147645.22
L39: IVA | M39: =+M38*16% -> 23623.235
L40: TOTAL | M40: =+M38+M39 -> 171268.45
L42: PROVISION AGUINALDO
L43: FACTURACION PITS
L44: Subtotal 1 | M44: =+AF26 -> 5301.999
L45: Comision | M45: =+M44*2% -> 106.03998
L46: Subtotal 2 | M46: =+M44+M45 -> 5408.0389
L47: 2% Sobre Nomina | M47: =+M44*2% -> 106.03998
L48: Importe de Factura | M48: =+M46+M47 -> 5514.0789
...

Sheet IP PITS
B1: IP INNOVACION EN PROYECTOS S DE RL DE CV
B2: Lista de Raya (forma tabular)
B3: Reg Pat IMSS: Z2942442109
B4: RFC: IIP -150923-DT7
A5: Código | B5: Empleado | C5: Dias Laborados | D5: Dias Vacaciones | E5: Salario Diario | F5: Salario Diario Integrado | G5: Sueldo | H5: Vacaciones a tiempo | I5: Prima de vacaciones a tiempo | J5: *TOTAL* *PERCEPCIONES* | K5: I.S.R. (sp) | L5: Subsidio al Empleo (sp) | M5: I.M.S.S. | N5: Préstamo Infonavit (vsm) | O5: Préstamo Infonavit (cf) | P5: Seguro de vivienda Infonavit | Q5: Préstamo FONACOT | R5: Deduccion general | S5: Aportación voluntaria Infonavit | T5: Ajuste al neto | U5: *TOTAL* *DEDUCCIONES* | V5: *NETO* | W5: Invalidez y Vida | X5: Cesantia y Vejez | Y5: Enf. y Mat. Patron | Z5: 2% Fondo retiro SAR (8) | AA5: 2% Impuesto estatal | AB5: Riesgo de trabajo (9) | AC5: I.M.S.S. empresa | AD5: Infonavit empresa | AE5: Guarderia I.M.S.S. (7) | AF5: PROVISION DE AGUINALDO | AG5: Banco
A6: SEI0010 | B6: Torres Ricardez Alfredo | C6: 15 | D6: 0 | E6: 266.67 | F6: 278.72 | G6: 4000.05 | H6: 0 | I6: 0 | J6: 4000.05 | K6: 313.87 | L6: 0 | M6: 107.53 | N6: 0 | O6: 0 | P6: 0 | Q6: 0 | R6: 0 | S6: 0 | T6: -0.15 | U6: 421.25 | V6: 3578.8 | W6: 78.04 | X6: 140.48 | Y6: 358.27 | Z6: 275.64 | AA6: 80 | AB6: 35.52 | AC6: 576.79 | AD6: 222.98 | AE6: 231.05 | AF6: 219.0368 | AG6: 12
A7: SEI0014 | B7: Montoya Portillo Carlos Alberto | C7: 15 | D7: 0 | E7: 266.67 | F7: 278.72 | G7: 4000.05 | H7: 0 | I7: 0 | J7: 4000.05 | K7: 313.87 | L7: 0 | M7: 107.53 | N7: 0 | O7: 0 | P7: 0 | Q7: 0 | R7: 0 | S7: 0 | T7: -0.15 | U7: 421.25 | V7: 3578.8 | W7: 78.04 | X7: 140.48 | Y7: 358.27 | Z7: 275.64 | AA7: 80 | AB7: 35.52 | AC7: 576.79 | AD7: 222.98 | AE7: 231.05 | AF7: 219.0368 | AG7: 12
A8: SEI0015 | B8: Cota Jaramillo Miguel Angel | C8: 15 | D8: 0 | E8: 200 | F8: 209.04 | G8: 3000 | H8: 0 | I8: 0 | J8: 3000 | K8: 59.69 | L8: 0 | M8: 79.43 | N8: 0 | O8: 0 | P8: 0 | Q8: 0 | R8: 0 | S8: 0 | T8: -0.12 | U8: 139 | V8: 2861 | W8: 58.53 | X8: 105.36 | Y8: 334.31 | Z8: 253.34 | AA8: 60 | AB8: 26.64 | AC8: 498.2 | AD8: 167.23 | AE8: 219.9 | AF8: 164.27554 | AG8: 12
A9: SEI0017 | B9: Muñoz Reyes Luis Eduardo | C9: 15 | D9: 0 | E9: 266.67 | F9: 278.72 | G9: 4000.05 | H9: 0 | I9: 0 | J9: 4000.05 | K9: 313.87 | L9: 0 | M9: 107.53 | N9: 877.59 | O9: 0 | P9: 0 | Q9: 0 | R9: 0 | S9: 0 | T9: 0.06 | U9: 1299.05 | V9: 2701 | W9: 78.04 | X9: 140.48 | Y9: 358.27 | Z9: 275.64 | AA9: 80 | AB9: 35.52 | AC9: 576.79 | AD9: 222.98 | AE9: 231.05 | AF9: 219.0368 | AG9: 12
A10: SEI0019 | B10: Gonzalez Rasgado Miguel Isaias | C10: 15 | D10: 0 | E10: 400 | F10: 424.2 | G10: 6000 | H10: 0 | I10: 0 | J10: 6000 | K10: 643.38 | L10: 0 | M10: 172.13 | N10: 0 | O10: 0 | P10: 0 | Q10: 0 | R10: 0 | S10: 0 | T10: 0.09 | U10: 815.6 | V10: 5184.4 | W10: 118.78 | X10: 213.8 | Y10: 424.61 | Z10: 322.19 | AA10: 120 | AB10: 54.07 | AC10: 757.19 | AD10: 339.36 | AE10: 254.32 | AF10: 328.55109 | AG10: 12
A11: SEI0020 | B11: Mar Marquez Cesar Eduardo | C11: 15 | D11: 0 | E11: 266.67 | F11: 278.72 | G11: 4000.05 | H11: 0 | I11: 0 | J11: 4000.05 | K11: 313.87 | L11: 0 | M11: 107.53 | N11: 0 | O11: 0 | P11: 0 | Q11: 0 | R11: 0 | S11: 0 | T11: 0.05 | U11: 421.45 | V11: 3578.6 | W11: 78.04 | X11: 140.48 | Y11: 358.27 | Z11: 275.64 | AA11: 80 | AB11: 35.52 | AC11: 576.79 | AD11: 222.98 | AE11: 231.05 | AF11: 219.0368 | AG11: 12
A12: SEI0021 | B12: Velez Rodriguez Jaime | C12: 14 | D12: 1 | E12: 200 | F12: 212.1 | G12: 2800 | H12: 200 | I12: 60 | J12: 3060 | K12: 59.69 | L12: 0 | M12: 80.6 | N12: 1359.23 | O12: 0 | P12: 0 | Q12: 0 | R12: 0 | S12: 0 | T12: 0.08 | U12: 1499.6 | V12: 1560.4 | W12: 59.39 | X12: 106.9 | Y12: 335.17 | Z12: 254.32 | AA12: 61.2 | AB12: 27.03 | AC12: 501.46 | AD12: 169.68 | AE12: 220.39 | AF12: 164.27554 | AG12: 12
A13: SEI0022 | B13: Najera Lopez Raul | C13: 15 | D13: 0 | E13: 333.33 | F13: 353.5 | G13: 4999.95 | H13: 0 | I13: 0 | J13: 4999.95 | K13: 461.63 | L13: 0 | M13: 140.73 | N13: 0 | O13: 0 | P13: 0 | Q13: 0 | R13: 0 | S13: 0 | T13: -0.01 | U13: 602.35 | V13: 4397.6 | W13: 98.98 | X13: 178.16 | Y13: 392.36 | Z13: 299.57 | AA13: 100 | AB13: 45.05 | AC13: 669.5 | AD13: 282.8 | AE13: 243.01 | AF13: 273.78984 | AG13: 12
A14: SEI0023 | B14: Puente Murguia Luis Felipe | C14: 15 | D14: 0 | E14: 233.33 | F14: 247.45 | G14: 3499.95 | H14: 0 | I14: 0 | J14: 3499.95 | K14: 134.36 | L14: 0 | M14: 94.03 | N14: 0 | O14: 0 | P14: 0 | Q14: 0 | R14: 0 | S14: 0 | T14: -0.04 | U14: 228.35 | V14: 3271.6 | W14: 69.28 | X14: 124.71 | Y14: 345.06 | Z14: 265.63 | AA14: 70 | AB14: 31.54 | AC14: 539.05 | AD14: 197.96 | AE14: 226.04 | AF14: 191.65206 | AG14: 12
A15: SEI0028 | B15: Jimenez Alcaraz Elizabeth | C15: 15 | D15: 0 | E15: 200 | F15: 212.11 | G15: 3000 | H15: 0 | I15: 0 | J15: 3000 | K15: 59.69 | L15: 0 | M15: 80.6 | N15: 0 | O15: 0 | P15: 0 | Q15: 0 | R15: 0 | S15: 0 | T15: 0.11 | U15: 140.4 | V15: 2859.6 | W15: 59.39 | X15: 106.9 | Y15: 335.17 | Z15: 254.33 | AA15: 60 | AB15: 27.03 | AC15: 501.46 | AD15: 169.69 | AE15: 220.39 | AF15: 164.27554 | AG15: 12
A16: SEI0029 | B16: Arceo Garcia Manuel Federico | C16: 15 | D16: 0 | E16: 200 | F16: 212.1 | G16: 3000 | H16: 0 | I16: 0 | J16: 3000 | K16: 59.69 | L16: 0 | M16: 80.6 | N16: 0 | O16: 0 | P16: 0 | Q16: 600 | R16: 0 | S16: 0 | T16: -0.09 | U16: 740.2 | V16: 2259.8 | W16: 59.39 | X16: 106.9 | Y16: 335.17 | Z16: 254.32 | AA16: 60 | AB16: 27.03 | AC16: 501.46 | AD16: 169.68 | AE16: 220.39 | AF16: 164.27554 | AG16: 12
A17: SEI0364 | B17: Dominguez Lopez Mayeli Del Pilar | C17: 15 | D17: 0 | E17: 266.67 | F17: 282.81 | G17: 4000.05 | H17: 0 | I17: 0 | J17: 4000.05 | K17: 313.87 | L17: 0 | M17: 109.35 | N17: 0 | O17: 0 | P17: 0 | Q17: 0 | R17: 1666.67 | S17: 0 | T17: 0.16 | U17: 2090.05 | V17: 1910 | W17: 79.19 | X17: 142.54 | Y17: 360.12 | Z17: 276.95 | AA17: 80 | AB17: 36.05 | AC17: 581.85 | AD17: 226.25 | AE17: 231.7 | AF17: 219.0368 | AG17: 12
... A86: SEI479 | B86: Cruz Perez Alejandro Nezahualcoyotl | C86: 15 | D86: 0 | E86: 266.67 | F86: 282.81 | G86: 4000.05 | H86: 0 | I86: 0 | J86: 4000.05 | K86: 313.87 | L86: 0 | M86: 109.35 | N86: 0 | O86: 0 | P86: 0 | Q86: 0 | R86: 0 | S86: 0 | T86: -0.17 | U86: 423.05 | V86: 3577 | W86: 79.19 | X86: 142.54 | Y86: 360.12 | Z86: 276.95 | AA86: 80 | AB86: 36.05 | AC86: 581.85 | AD86: 226.25 | AE86: 231.7 | AF86: 90.25 | AG86: 12
A87: Total Depto | C87: ----------------------- | D87: ----------------------- | E87: ----------------------- | F87: ----------------------- | G87: ----------------------- | H87: ----------------------- | I87: ----------------------- | J87: ----------------------- | K87: ----------------------- | L87: ----------------------- | M87: ----------------------- | N87: ----------------------- | O87: ----------------------- | P87: ----------------------- | Q87: ----------------------- | R87: ----------------------- | S87: ----------------------- | T87: ----------------------- | U87: ----------------------- | V87: ----------------------- | W87: ----------------------- | X87: ----------------------- | Y87: ----------------------- | Z87: ----------------------- | AA87: ----------------------- | AC87: ----------------------- | AD87: ----------------------- | AE87: ----------------------- | AF87: ----------------------- | AG87: -----------------------
A88: =SUM(A6:A87) -> 0 | B88: =SUM(B6:B87) -> 0 | C88: =SUM(C6:C87) -> 1205 | D88: =SUM(D6:D87) -> 3 | E88: =SUM(E6:E87) -> 19423.26 | F88: =SUM(F6:F87) -> 20494.83 | G88: =SUM(G6:G87) -> 289128.99 | H88: =SUM(H6:H87) -> 666.67 | ... AG88: =SUM(AG6:AG87) -> 972
A89: 82 | B89: Nomina | I89: FACTURACION PITS
A90: 2 | B90: Altas | I90: Devengado Salario | J90: =+V88 -> 226037
A91: 3 | B91: Bajas | I91: Retornos | J91: =+R88 -> 8698.25
A92: =+A89+A90-A91 -> 81 | B92: Total Nomina | I92: Infonavit | J92: =+N88+O88+P88 -> 29037.79
I93: Prestamo Prospera | J93: =+Q88 -> 2418.33
I94: aportacion voluntaria | J94: =+S88 -> 0
I95: Subtotal 1 | J95: =SUM(J90:J94) -> 266191.37
I96: Comision | J96: =+J95*2% -> 5323.8274
I97: Subtotal 2 | J97: =+J95+J96 -> 271515.2
I98: Costo Patronal Imss | J98: =+M88+W88+X88+Y88+AD88+AE88+AB88+Z88 -> 111282.82
I99: 2% Sobre Nomina | J99: =+J88*2% -> 5799.9132
I100: Importe de Factura | J100: =+J97+J98+J99 -> 388597.93
I101: certificacion de cheque | J101: 0
I102: IVA | J102: =(+J100+J101)*0.16 -> 62175.669
I103: TOTAL | J103: =+J100+J101+J102 -> 450773.6
I105: PROVISION AGUINALDO
I106: FACTURACION PITS
I107: Subtotal 1 | J107: =+AF88 -> 15836.012
I108: Comision | J108: =+J107*2% -> 316.72024
I109: Subtotal 2 | J109: =+J107+J108 -> 16152.732
...

Sheet SIND PITS
D1: SINDICATO | J1: PRIMA VACACIONAL
A2: CLAVE | B2: EMPRESA | C2: NOMBRE | D2: SUELDO SINDICATO | E2: BONO | F2: COMISION | G2: prima vacaciones | H2: TOTAL | J2: DIAS DE VACACIONES | K2: SUELDO NETO MENSUAL | L2: MONTO PRIMA TOTAL | M2: MENOS PRIMA IMSS | N2: PRIMA A PAGAR SINDICATO
A3: SEI0544 | B3: IP INNOVACION | C3: Aguilar Aguirre Alfonso | D3: =290.2+630 -> 920.2 | H3: =SUM(D3:G3) -> 920.2 | J3: =VLOOKUP(C3,'IP PITS'!$B$6:$D$86,3,0) -> 0 | K3: 6000 | L3: =(((+K3/30)*J3)*30%) -> 0 | M3: =VLOOKUP(C3,'IP PITS'!$B$6:$I$86,8,0) -> 0 | N3: =+L3-M3 -> 0
A4: SEI0431 | B4: IP INNOVACION | C4: Alcaraz Conde Zabdi Guadalupe | D4: 1260.6 | E4: 292.5 | G4: =+N4 -> 0 | H4: =SUM(D4:G4) -> 1553.1 | J4: =VLOOKUP(C4,'IP PITS'!$B$6:$D$86,3,0) -> 0 | K4: 6000 | L4: =(((+K4/30)*J4)*30%) -> 0 | M4: =VLOOKUP(C4,'IP PITS'!$B$6:$I$86,8,0) -> 0 | N4: =+L4-M4 -> 0
A5: SEI0527 | B5: IP INNOVACION | C5: Alejandro Peña Deivi | D5: 180.8 | E5: 618.75 | G5: =+N5 -> 0 | H5: =SUM(D5:G5) -> 799.55 | J5: =VLOOKUP(C5,'IP PITS'!$B$6:$D$86,3,0) -> 0 | K5: 6300 | L5: =(((+K5/30)*J5)*30%) -> 0 | M5: =VLOOKUP(C5,'IP PITS'!$B$6:$I$86,8,0) -> 0 | N5: =+L5-M5 -> 0
A6: SEI0535 | B6: IP INNOVACION | C6: Alejandro Vazquez Erasmo Miguel | D6: 3618.2 | E6: 1750 | G6: =+N6 -> 0 | H6: =SUM(D6:G6) -> 5368.2 | J6: =VLOOKUP(C6,'IP PITS'!$B$6:$D$86,3,0) -> 0 | K6: 12000 | L6: =(((+K6/30)*J6)*30%) -> 0 | M6: =VLOOKUP(C6,'IP PITS'!$B$6:$I$86,8,0) -> 0 | N6: =+L6-M6 -> 0
A7: SEI0029 | B7: IP INNOVACION | C7: Arceo Garcia Manuel Federico | D7: 140.2 | E7: 487.5 | G7: =+N7 -> 0 | H7: =SUM(D7:G7) -> 627.7 | J7: =VLOOKUP(C7,'IP PITS'!$B$6:$D$86,3,0) -> 0 | K7: 6000 | L7: =(((+K7/30)*J7)*30%) -> 0 | M7: =VLOOKUP(C7,'IP PITS'!$B$6:$I$86,8,0) -> 0 | N7: =+L7-M7 -> 0
A8: SEI0097 | B8: CONSULTORIA | C8: Arreola Jimenez Jose Nieves | D8: 1562.71 | E8: 501 | G8: =+N8 -> 0 | H8: =SUM(D8:G8) -> 2063.71 | J8: =VLOOKUP(C8,'CPD PITS'!$B$6:$D$24,3,0) -> 0 | K8: 10150 | L8: =(((+K8/30)*J8)*30%) -> 0 | M8: =VLOOKUP(C8,'CPD PITS'!$B$6:$I$24,8,0) -> 0 | N8: =+L8-M8 -> 0
A9: SEI0118 | B9: CONSULTORIA | C9: Arroyo Ramirez Hector Hugo | D9: 2108.85 | G9: =+N9 -> 0 | H9: =SUM(D9:G9) -> 2108.85 | J9: =VLOOKUP(C9,'CPD PITS'!$B$6:$D$24,3,0) -> 0 | K9: 13000 | L9: =(((+K9/30)*J9)*30%) -> 0 | M9: =VLOOKUP(C9,'CPD PITS'!$B$6:$I$24,8,0) -> 0 | N9: =+L9-M9 -> 0
A10: SEI0472 | B10: IP INNOVACION | C10: Arzate Gil Juan Sebastian | D10: 423.3 | E10: 463 | G10: =+N10 -> 0 | H10: =SUM(D10:G10) -> 886.3 | J10: =VLOOKUP(C10,'IP PITS'!$B$6:$D$86,3,0) -> 0 | K10: 8000 | L10: =(((+K10/30)*J10)*30%) -> 0 | M10: =VLOOKUP(C10,'IP PITS'!$B$6:$I$86,8,0) -> 0 | N10: =+L10-M10 -> 0
A11: SEI0377 | B11: CONSULTORIA | C11: Benavides Herrera Alejandra | D11: 16807.6 | G11: =+N11 -> 0 | H11: =SUM(D11:G11) -> 16807.6 | J11: =VLOOKUP(C11,'CPD PITS'!$B$6:$D$24,3,0) -> 0 | K11: 40000 | L11: =(((+K11/30)*J11)*30%) -> 0 | M11: =VLOOKUP(C11,'CPD PITS'!$B$6:$I$24,8,0) -> 0 | N11: =+L11-M11 -> 0
A12: SEI0108 | B12: CONSULTORIA | C12: Caballero Diaz Francisco Javier | D12: 1562.69 | E12: 346 | G12: =+N12 -> 0 | H12: =SUM(D12:G12) -> 1908.69 | J12: =VLOOKUP(C12,'CPD PITS'!$B$6:$D$24,3,0) -> 0 | K12: 10150 | L12: =(((+K12/30)*J12)*30%) -> 0 | M12: =VLOOKUP(C12,'CPD PITS'!$B$6:$I$24,8,0) -> 0 | N12: =+L12-M12 -> 0
A13: SEI0425 | B13: CONSULTORIA | C13: Carbajal Cabuto Jose Luis | D13: 1612.9 | E13: 357 | G13: =+N13 -> 0 | H13: =SUM(D13:G13) -> 1969.9 | J13: =VLOOKUP(C13,'CPD PITS'!$B$6:$D$24,3,0) -> 0 | K13: 10250 | L13: =(((+K13/30)*J13)*30%) -> 0 | M13: =VLOOKUP(C13,'CPD PITS'!$B$6:$I$24,8,0) -> 0 | N13: =+L13-M13 -> 0
A14: SEI0528 | B14: IP INNOVACION | C14: Casas Chavarria Rafael | D14: 1142.8 | E14: 480 | G14: =+N14 -> 0 | H14: =SUM(D14:G14) -> 1622.8 | J14: =VLOOKUP(C14,'IP PITS'!$B$6:$D$86,3,0) -> 0 | K14: 6300 | L14: =(((+K14/30)*J14)*30%) -> 0 | M14: =VLOOKUP(C14,'IP PITS'!$B$6:$I$86,8,0) -> 0 | N14: =+L14-M14 -> 0
A15: SEI0116 | B15: CONSULTORIA | C15: Casillas Cardona Cesar Alejandro | D15: 1896.8 | G15: =+N15 -> 0 | H15: =SUM(D15:G15) -> 1896.8 | J15: =VLOOKUP(C15,'CPD PITS'!$B$6:$D$24,3,0) -> 0 | K15: 12000 | L15: =(((+K15/30)*J15)*30%) -> 0 | M15: =VLOOKUP(C15,'CPD PITS'!$B$6:$I$24,8,0) -> 0 | N15: =+L15-M15 -> 0
A16: SEI0460 | B16: IP INNOVACION | C16: Castellon Ramos Rene | D16: 1827.515 | E16: 150 | G16: =+N16 -> 0 | H16: =SUM(D16:G16) -> 1977.515 | J16: =VLOOKUP(C16,'IP PITS'!$B$6:$D$86,3,0) -> 0 | K16: 7505.99 | L16: =(((+K16/30)*J16)*30%) -> 0 | M16: =VLOOKUP(C16,'IP PITS'!$B$6:$I$86,8,0) -> 0 | N16: =+L16-M16 -> 0
A17: SEI0443 | B17: IP INNOVACION | C17: Castillo Nungaray Nestor Roman | D17: 140.4 | E17: 1500 | G17: =+N17 -> 0 | H17: =SUM(D17:G17) -> 1640.4 | J17: =VLOOKUP(C17,'IP PITS'!$B$6:$D$86,3,0) -> 1 | K17: 6000 | L17: =(((+K17/30)*J17)*30%) -> 60 | M17: =VLOOKUP(C17,'IP PITS'!$B$6:$I$86,8,0) -> 60 | N17: =+L17-M17 -> 0
A18: SEI0490 | B18: IP INNOVACION | C18: Castillo Ramirez Hector Ivan | D18: 3727.1 | E18: 208.5 | G18: =+N18 -> 0 | H18: =SUM(D18:G18) -> 3935.6 | J18: =VLOOKUP(C18,'IP PITS'!$B$6:$D$86,3,0) -> 0 | K18: 14000 | L18: =(((+K18/30)*J18)*30%) -> 0 | M18: =VLOOKUP(C18,'IP PITS'!$B$6:$I$86,8,0) -> 0 | N18: =+L18-M18 -> 0
A19: SEI0508 | B19: IP INNOVACION | C19: Cerro Garcia Elvis | D19: 2557.6 | E19: 200 | G19: =+N19 -> 0 | H19: =SUM(D19:G19) -> 2757.6 | J19: =VLOOKUP(C19,'IP PITS'!$B$6:$D$86,3,0) -> 0 | K19: 10000 | L19: =(((+K19/30)*J19)*30%) -> 0 | M19: =VLOOKUP(C19,'IP PITS'!$B$6:$I$86,8,0) -> 0 | N19: =+L19-M19 -> 0
A20: SEI0499 | B20: IP INNOVACION | C20: Chavez Dominguez Salvador | D20: 2673.4 | E20: 1054.5 | G20: =+N20 -> 0 | H20: =SUM(D20:G20) -> 3727.9 | J20: =VLOOKUP(C20,'IP PITS'!$B$6:$D$86,3,0) -> 0 | K20: 12000 | L20: =(((+K20/30)*J20)*30%) -> 0 | M20: =VLOOKUP(C20,'IP PITS'!$B$6:$I$86,8,0) -> 0 | N20: =+L20-M20 -> 0
A21: SEI0541 | B21: IP INNOVACION | C21: Chavez Govea Edgar Aram | D21: 228.6 | G21: =+N21 -> 0 | H21: =SUM(D21:G21) -> 228.6 | J21: =VLOOKUP(C21,'IP PITS'!$B$6:$D$86,3,0) -> 0 | K21: 7000 | L21: =(((+K21/30)*J21)*30%) -> 0 | M21: =VLOOKUP(C21,'IP PITS'!$B$6:$I$86,8,0) -> 0 | N21: =+L21-M21 -> 0
A22: SEI0442 | B22: IP INNOVACION | C22: Chavez Pedraza Samuel | D22: 1060.4 | E22: 675 | G22: =+N22 -> 0 | H22: =SUM(D22:G22) -> 1735.4 | J22: =VLOOKUP(C22,'IP PITS'!$B$6:$D$86,3,0) -> 0 | K22: 14000 | L22: =(((+K22/30)*J22)*30%) -> 0 | M22: =VLOOKUP(C22,'IP PITS'!$B$6:$I$86,8,0) -> 0 | N22: =+L22-M22 -> 0
A23: SEI0462 | B23: IP INNOVACION | C23: Chavez Saucedo Jorge Arturo | D23: 387.54 | E23: 224.25 | G23: =+N23 -> 0 | H23: =SUM(D23:G23) -> 611.79 | J23: =VLOOKUP(C23,'IP PITS'!$B$6:$D$86,3,0) -> 1 | K23: 8000 | L23: =(((+K23/30)*J23)*30%) -> 80 | M23: =VLOOKUP(C23,'IP PITS'!$B$6:$I$86,8,0) -> 80 | N23: =+L23-M23 -> 0
A24: SEI0456 | B24: IP INNOVACION | C24: Chavira Garcia David Fernando | D24: 602.4 | E24: 121.5 | G24: =+N24 -> 0 | H24: =SUM(D24:G24) -> 723.9 | J24: =VLOOKUP(C24,'IP PITS'!$B$6:$D$86,3,0) -> 0 | K24: 10000 | L24: =(((+K24/30)*J24)*30%) -> 0 | M24: =VLOOKUP(C24,'IP PITS'!$B$6:$I$86,8,0) -> 0 | N24: =+L24-M24 -> 0
A25: SEI0538 | B25: IP INNOVACION | C25: Coronado Vega Carlos Eduardo | D25: 107.2 | G25: =+N25 -> 0 | H25: =SUM(D25:G25) -> 107.2 | J25: =VLOOKUP(C25,'IP PITS'!$B$6:$D$86,3,0) -> 0 | K25: 6300 | L25: =(((+K25/30)*J25)*30%) -> 0 | M25: =VLOOKUP(C25,'IP PITS'!$B$6:$I$86,8,0) -> 0 | N25: =+L25-M25 -> 0
A26: SEI0015 | B26: IP INNOVACION | C26: Cota Jaramillo Miguel Angel | D26: 139 | E26: 378 | G26: =+N26 -> 0 | H26: =SUM(D26:G26) -> 517 | J26: =VLOOKUP(C26,'IP PITS'!$B$6:$D$86,3,0) -> 0 | K26: 6000 | L26: =(((+K26/30)*J26)*30%) -> 0 | M26: =VLOOKUP(C26,'IP PITS'!$B$6:$I$86,8,0) -> 0 | N26: =+L26-M26 -> 0
A27: SEI0413 | B27: IP INNOVACION | C27: Courtenay Gutierrez Barry Vladimir | D27: 56.6 | E27: 395.5 | G27: =+N27 -> 0 | H27: =SUM(D27:G27) -> 452.1 | J27: =VLOOKUP(C27,'IP PITS'!$B$6:$D$86,3,0) -> 0 | K27: 5000 | L27: =(((+K27/30)*J27)*30%) -> 0 | M27: =VLOOKUP(C27,'IP PITS'!$B$6:$I$86,8,0) -> 0 | N27: =+L27-M27 -> 0
A28: SEI0501 | B28: IP INNOVACION | C28: Cruz Herrera Roberto | D28: 1673.44 | E28: 226.5 | G28: =+N28 -> 0 | H28: =SUM(D28:G28) -> 1899.94 | J28: =VLOOKUP(C28,'IP PITS'!$B$6:$D$86,3,0) -> 0 | K28: 10000 | L28: =(((+K28/30)*J28)*30%) -> 0 | M28: =VLOOKUP(C28,'IP PITS'!$B$6:$I$86,8,0) -> 0 | N28: =+L28-M28 -> 0
A29: SEI479 | B29: IP INNOVACION | C29: Cruz Perez Alejandro Nezahualcoyotl | D29: 423 | E29: 474 | G29: =+N29 -> 0 | H29: =SUM(D29:G29) -> 897 | J29: =VLOOKUP(C29,'IP PITS'!$B$6:$D$86,3,0) -> 0 | K29: 8000 | L29: =(((+K29/30)*J29)*30%) -> 0 | M29: =VLOOKUP(C29,'IP PITS'!$B$6:$I$86,8,0) -> 0 | N29: =+L29-M29 -> 0
A30: SEI0401 | B30: CONSULTORIA | C30: De La Torre Zambara Francisco Ernesto | D30: 1562.75 | E30: 243.5 | G30: =+N30 -> 45.75 | H30: =SUM(D30:G30) -> 1852 | J30: =VLOOKUP(C30,'CPD PITS'!$B$6:$D$24,3,0) -> 1 | K30: 10150 | L30: =(((+K30/30)*J30)*30%) -> 101.5 | M30: =VLOOKUP(C30,'CPD PITS'!$B$6:$I$24,8,0) -> 55.75 | N30: =+L30-M30 -> 45.75
A31: SEI0530 | B31: IP INNOVACION | C31: Del Pilar Mendez Lucio | D31: 1744.6 | E31: 400 | G31: =+N31 -> 0 | H31: =SUM(D31:G31) -> 2144.6 | J31: =VLOOKUP(C31,'IP PITS'!$B$6:$D$86,3,0) -> 0 | K31: 6000 | L31: =(((+K31/30)*J31)*30%) -> 0 | M31: =VLOOKUP(C31,'IP PITS'!$B$6:$I$86,8,0) -> 0 | N31: =+L31-M31 -> 0
A32: SEI0543 | B32: IP INNOVACION | C32: Diaz Ortiz Hiram Guillermo | D32: 194.52 | G32: =+N32 -> 0 | H32: =SUM(D32:G32) -> 194.52 | J32: =VLOOKUP(C32,'IP PITS'!$B$6:$D$86,3,0) -> 0 | K32: 6300 | L32: =(((+K32/30)*J32)*30%) -> 0 | M32: =VLOOKUP(C32,'IP PITS'!$B$6:$I$86,8,0) -> 0 | N32: =+L32-M32 -> 0
A33: SEI0364 | B33: IP INNOVACION | C33: Dominguez Lopez Mayeli Del Pilar | D33: 1423.33 | E33: 1250 | G33: =+N33 -> 0 | H33: =SUM(D33:G33) -> 2673.33 | J33: =VLOOKUP(C33,'IP PITS'!$B$6:$D$86,3,0) -> 0 | K33: 10000 | L33: =(((+K33/30)*J33)*30%) -> 0 | M33: =VLOOKUP(C33,'IP PITS'!$B$6:$I$86,8,0) -> 0 | N33: =+L33-M33 -> 0
A34: SEI0474 | B34: IP INNOVACION | C34: Enriquez Zamora Jessica Del Rocio | D34: 140.4 | E34: 292.5 | G34: =+N34 -> 0 | H34: =SUM(D34:G34) -> 432.9 | J34: =VLOOKUP(C34,'IP PITS'!$B$6:$D$86,3,0) -> 0 | K34: 6000 | L34: =(((+K34/30)*J34)*30%) -> 0 | M34: =VLOOKUP(C34,'IP PITS'!$B$6:$I$86,8,0) -> 0 | N34: =+L34-M34 -> 0
A35: SEI0489 | B35: IP INNOVACION | C35: Escobedo Olivares Juan Guadalupe | D35: 3727 | E35: 166.67 | G35: =+N35 -> 0 | H35: =SUM(D35:G35) -> 3893.67 | J35: =VLOOKUP(C35,'IP PITS'!$B$6:$D$86,3,0) -> 0 | K35: 14000 | L35: =(((+K35/30)*J35)*30%) -> 0 | M35: =VLOOKUP(C35,'IP PITS'!$B$6:$I$86,8,0) -> 0 | N35: =+L35-M35 -> 0
A36: SEI0449 | B36: IP INNOVACION | C36: Flores Cerrillos Jorge Humberto | D36: 423 | E36: 287 | G36: =+N36 -> 0 | H36: =SUM(D36:G36) -> 710 | J36: =VLOOKUP(C36,'IP PITS'!$B$6:$D$86,3,0) -> 0 | K36: 8000 | L36: =(((+K36/30)*J36)*30%) -> 0 | M36: =VLOOKUP(C36,'IP PITS'!$B$6:$I$86,8,0) -> 0 | N36: =+L36-M36 -> 0
A37: SEI0461 | B37: IP INNOVACION | C37: Flores Franco Marco | D37: 458.205 | E37: 1200 | G37: =+N37 -> 0 | H37: =SUM(D37:G37) -> 1658.205 | J37: =VLOOKUP(C37,'IP PITS'!$B$6:$D$86,3,0) -> 0 | K37: 8500.01 | L37: =(((+K37/30)*J37)*30%) -> 0 | M37: =VLOOKUP(C37,'IP PITS'!$B$6:$I$86,8,0) -> 0 | N37: =+L37-M37 -> 0
A38: SEI0500 | B38: IP INNOVACION | C38: Garcia Gutierrez Jose Juan | D38: 3140.2 | E38: 399.5 | G38: =+N38 -> 0 | H38: =SUM(D38:G38) -> 3539.7 | J38: =VLOOKUP(C38,'IP PITS'!$B$6:$D$86,3,0) -> 0 | K38: 12000 | L38: =(((+K38/30)*J38)*30%) -> 0 | M38: =VLOOKUP(C38,'IP PITS'!$B$6:$I$86,8,0) -> 0 | N38: =+L38-M38 -> 0
A39: SEI0099 | B39: CONSULTORIA | C39: Garcia Villicaña Ricardo Pascual | D39: 2607.2 | E39: 216.5 | G39: =+N39 -> 0 | H39: =SUM(D39:G39) -> 2823.7 | J39: =VLOOKUP(C39,'CPD PITS'!$B$6:$D$24,3,0) -> 0 | K39: 15000 | L39: =(((+K39/30)*J39)*30%) -> 0 | M39: =VLOOKUP(C39,'CPD PITS'!$B$6:$I$24,8,0) -> 0 | N39: =+L39-M39 -> 0
A40: SEI0534 | B40: IP INNOVACION | C40: Gonzalez Ramirez Paul | D40: 139.2 | E40: 292.5 | G40: =+N40 -> 0 | H40: =SUM(D40:G40) -> 431.7 | J40: =VLOOKUP(C40,'IP PITS'!$B$6:$D$86,3,0) -> 0 | K40: 6000 | L40: =(((+K40/30)*J40)*30%) -> 0 | M40: =VLOOKUP(C40,'IP PITS'!$B$6:$I$86,8,0) -> 0 | N40: =+L40-M40 -> 0
...

Sheet RESUMEN
A2: SUELDOS Y SALARIOS | G2: SINDICATO | K2: NETOS | O2: EXTRAS
A3: CLAVE | B3: EMPRESA | C3: NOMBRE | D3: NETO CPD | E3: NETO IP | F3: A | G3: PAGO SINDICATO | H3: COMISION | I3: PRIMA VACACIONAL SINDICATO | J3: B | K3: NETO A PAGAR | L3: NETO MENSUAL | M3: NETO QUINCENAL SEITON | N3: C | O3: prima vacacional | P3: COMISION Y PRIMA VACACIONAL | Q3: INFONAVIT | R3: INFONAVIT | S3: INFONAVIT | T3: INFONAVIT | U3: PRESTAMO | V3: APORTACION | W3: DESCUENTOS | X3: D | Y3: TOTAL GENERAL | Z3: DIFERENCIAS | AA3: OBSERVACIONES | AB3: CC
A4: SEI0009 | B4: SEITON - (CONSULTORIA II) | C4: Gutierrez Gutierrez Luis Arturo | D4: =VLOOKUP(C4,[1]CPD!$B$9:$Y$35,24,0) -> 2774.6 | G4: =VLOOKUP(C4,#REF!,4,0) -> #REF! | H4: =VLOOKUP(C4,#REF!,5,0) -> #REF! | I4: =VLOOKUP(C4,#REF!,6,0) -> #REF! | K4: =+D4+E4+G4+H4+I4 -> #REF! | L4: =VLOOKUP(C4,[2]ABC!$A$3:$B$88,2,0) -> 8500 | M4: =+L4/2 -> 4250 | O4: =VLOOKUP(C4,[1]CPD!$B$9:$I$35,8,0) -> 0 | P4: =+H4+I4 -> #REF! | Q4: =VLOOKUP(C4,[1]CPD!$B$9:$R$35,17,0) -> 0 | R4: =VLOOKUP(C4,[1]CPD!$B$9:$Q$35,16,0) -> 0 | S4: =VLOOKUP(C4,[2]CPD!$B$9:$S$35,18,0) -> 0 | T4: =VLOOKUP(C4,[1]CPD!$B$9:$T$35,19,0) -> 0 | W4: =VLOOKUP(C4,[1]CPD!$B$9:$V$35,21,0) -> 0 | Y4: =+K4-O4-P4+Q4+R4+S4+T4+U4+V4+W4 -> #REF! | Z4: =+M4-Y4 -> #REF! | AB4: =VLOOKUP(C4,[2]SINDICATO!$C$7:$Q$141,15,0) -> #N/A
A5: SEI0010 | B5: SEITON - (CONSULTORIA II) | C5: Compean Tobias Braulio Gerardo | D5: =VLOOKUP(C5,[1]CPD!$B$9:$Y$35,24,0) -> 4005.2 | G5: =VLOOKUP(C5,#REF!,4,0) -> #REF! | H5: =VLOOKUP(C5,#REF!,5,0) -> #REF! | I5: =VLOOKUP(C5,#REF!,6,0) -> #REF! | K5: =+D5+E5+G5+H5+I5 -> #REF! | L5: =VLOOKUP(C5,[2]ABC!$A$3:$B$88,2,0) -> 18000 | M5: =+L5/2 -> 9000 | O5: =VLOOKUP(C5,[1]CPD!$B$9:$I$35,8,0) -> 0 | P5: =+H5+I5 -> #REF! | Q5: =VLOOKUP(C5,[1]CPD!$B$9:$R$35,17,0) -> 1333.87 | R5: =VLOOKUP(C5,[1]CPD!$B$9:$Q$35,16,0) -> 0 | S5: =VLOOKUP(C5,[2]CPD!$B$9:$S$35,18,0) -> 0 | T5: =VLOOKUP(C5,[1]CPD!$B$9:$T$35,19,0) -> 15 | W5: =VLOOKUP(C5,[1]CPD!$B$9:$V$35,21,0) -> 0 | Y5: =+K5-O5-P5+Q5+R5+S5+T5+U5+V5+W5 -> #REF! | Z5: =+M5-Y5 -> #REF! | AB5: =VLOOKUP(C5,[2]SINDICATO!$C$7:$Q$141,15,0) -> 0
A6: SEI0026 | B6: SEITON - (CONSULTORIA II) | C6: Patricio Aguilar Jhonattan Cristian | D6: =VLOOKUP(C6,[1]CPD!$B$9:$Y$35,24,0) -> 2911.8 | G6: =VLOOKUP(C6,#REF!,4,0) -> #REF! | H6: =VLOOKUP(C6,#REF!,5,0) -> #REF! | I6: =VLOOKUP(C6,#REF!,6,0) -> #REF! | K6: =+D6+E6+G6+H6+I6 -> #REF! | L6: =VLOOKUP(C6,[2]ABC!$A$3:$B$88,2,0) -> 9000 | M6: =+L6/2 -> 4500 | O6: =VLOOKUP(C6,[1]CPD!$B$9:$I$35,8,0) -> 0 | P6: =+H6+I6 -> #REF! | Q6: =VLOOKUP(C6,[1]CPD!$B$9:$R$35,17,0) -> 0 | R6: =VLOOKUP(C6,[1]CPD!$B$9:$Q$35,16,0) -> 0 | S6: =VLOOKUP(C6,[2]CPD!$B$9:$S$35,18,0) -> 0 | T6: =VLOOKUP(C6,[1]CPD!$B$9:$T$35,19,0) -> 0 | W6: =VLOOKUP(C6,[1]CPD!$B$9:$V$35,21,0) -> 0 | Y6: =+K6-O6-P6+Q6+R6+S6+T6+U6+V6+W6 -> #REF! | Z6: =+M6-Y6 -> #REF! | AB6: =VLOOKUP(C6,[2]SINDICATO!$C$7:$Q$141,15,0) -> #N/A
A7: SEI0040 | B7: SEITON - (CONSULTORIA II) | C7: Mora Ramirez Acal Aldo Isidro | D7: =VLOOKUP(C7,[1]CPD!$B$9:$Y$35,24,0) -> 4036 | G7: =VLOOKUP(C7,#REF!,4,0) -> #REF! | H7: =VLOOKUP(C7,#REF!,5,0) -> #REF! | I7: =VLOOKUP(C7,#REF!,6,0) -> #REF! | K7: =+D7+E7+G7+H7+I7 -> #REF! | L7: 13000 | M7: =+L7/2 -> 6500 | O7: =VLOOKUP(C7,[1]CPD!$B$9:$I$35,8,0) -> 0 | P7: =+H7+I7 -> #REF! | Q7: =VLOOKUP(C7,[1]CPD!$B$9:$R$35,17,0) -> 0 | R7: =VLOOKUP(C7,[1]CPD!$B$9:$Q$35,16,0) -> 0 | S7: =VLOOKUP(C7,[2]CPD!$B$9:$S$35,18,0) -> 0 | T7: =VLOOKUP(C7,[1]CPD!$B$9:$T$35,19,0) -> 0 | W7: =VLOOKUP(C7,[1]CPD!$B$9:$V$35,21,0) -> 0 | Y7: =+K7-O7-P7+Q7+R7+S7+T7+U7+V7+W7 -> #REF! | Z7: =+M7-Y7 -> #REF! | AB7: =VLOOKUP(C7,[2]SINDICATO!$C$7:$Q$141,15,0) -> #N/A
A8: SEI0041 | B8: SEITON - (CONSULTORIA II) | C8: Vazquez Perez Miguel Angel | D8: =VLOOKUP(C8,[1]CPD!$B$9:$Y$35,24,0) -> 5074 | G8: =VLOOKUP(C8,#REF!,4,0) -> #REF! | H8: =VLOOKUP(C8,#REF!,5,0) -> #REF! | I8: =VLOOKUP(C8,#REF!,6,0) -> #REF! | K8: =+D8+E8+G8+H8+I8 -> #REF! | L8: =VLOOKUP(C8,[2]ABC!$A$3:$B$88,2,0) -> 18500 | M8: =+L8/2 -> 9250 | O8: =VLOOKUP(C8,[1]CPD!$B$9:$I$35,8,0) -> 0 | P8: =+H8+I8 -> #REF! | Q8: =VLOOKUP(C8,[1]CPD!$B$9:$R$35,17,0) -> 0 | R8: =VLOOKUP(C8,[1]CPD!$B$9:$Q$35,16,0) -> 0 | S8: =VLOOKUP(C8,[2]CPD!$B$9:$S$35,18,0) -> 0 | T8: =VLOOKUP(C8,[1]CPD!$B$9:$T$35,19,0) -> 0 | W8: =VLOOKUP(C8,[1]CPD!$B$9:$V$35,21,0) -> 0 | Y8: =+K8-O8-P8+Q8+R8+S8+T8+U8+V8+W8 -> #REF! | Z8: =+M8-Y8 -> #REF! | AB8: =VLOOKUP(C8,[2]SINDICATO!$C$7:$Q$141,15,0) -> #N/A
A9: SEI0088 | B9: SEITON - (CONSULTORIA II) | C9: Morgado Fernandez Martin | D9: =VLOOKUP(C9,[1]CPD!$B$9:$Y$35,24,0) -> 4899.6 | G9: =VLOOKUP(C9,#REF!,4,0) -> #REF! | H9: =VLOOKUP(C9,#REF!,5,0) -> #REF! | I9: =VLOOKUP(C9,#REF!,6,0) -> #REF! | K9: =+D9+E9+G9+H9+I9 -> #REF! | L9: =VLOOKUP(C9,[2]ABC!$A$3:$B$88,2,0) -> 15000 | M9: =+L9/2 -> 7500 | O9: =VLOOKUP(C9,[1]CPD!$B$9:$I$35,8,0) -> 0 | P9: =+H9+I9 -> #REF! | Q9: =VLOOKUP(C9,[1]CPD!$B$9:$R$35,17,0) -> 0 | R9: =VLOOKUP(C9,[1]CPD!$B$9:$Q$35,16,0) -> 0 | S9: =VLOOKUP(C9,[2]CPD!$B$9:$S$35,18,0) -> 0 | T9: =VLOOKUP(C9,[1]CPD!$B$9:$T$35,19,0) -> 0 | W9: =VLOOKUP(C9,[1]CPD!$B$9:$V$35,21,0) -> 0 | Y9: =+K9-O9-P9+Q9+R9+S9+T9+U9+V9+W9 -> #REF! | Z9: =+M9-Y9 -> #REF! | AB9: =VLOOKUP(C9,[2]SINDICATO!$C$7:$Q$141,15,0) -> #N/A
A10: SEI0097 | B10: SEITON - (CONSULTORIA II) | C10: Arreola Jimenez Jose Nieves | D10: =VLOOKUP(C10,[1]CPD!$B$9:$Y$35,24,0) -> 1927.6 | G10: =VLOOKUP(C10,#REF!,4,0) -> #REF! | H10: =VLOOKUP(C10,#REF!,5,0) -> #REF! | I10: =VLOOKUP(C10,#REF!,6,0) -> #REF! | K10: =+D10+E10+G10+H10+I10 -> #REF! | L10: =VLOOKUP(C10,[2]ABC!$A$3:$B$88,2,0) -> 10150 | M10: =+L10/2 -> 5075 | O10: =VLOOKUP(C10,[1]CPD!$B$9:$I$35,8,0) -> 0 | P10: =+H10+I10 -> #REF! | Q10: =VLOOKUP(C10,[1]CPD!$B$9:$R$35,17,0) -> 1574.29 | R10: =VLOOKUP(C10,[1]CPD!$B$9:$Q$35,16,0) -> 0 | S10: =VLOOKUP(C10,[2]CPD!$B$9:$S$35,18,0) -> 0 | T10: =VLOOKUP(C10,[1]CPD!$B$9:$T$35,19,0) -> 15 | W10: =VLOOKUP(C10,[1]CPD!$B$9:$V$35,21,0) -> 0 | Y10: =+K10-O10-P10+Q10+R10+S10+T10+U10+V10+W10 -> #REF! | Z10: =+M10-Y10 -> #REF! | AB10: =VLOOKUP(C10,[2]SINDICATO!$C$7:$Q$141,15,0) -> #N/A
A11: SEI0099 | B11: SEITON - (CONSULTORIA II) | C11: Garcia Villicaña Ricardo Pascual | D11: =VLOOKUP(C11,[1]CPD!$B$9:$Y$35,24,0) -> 4899.8 | G11: =VLOOKUP(C11,#REF!,4,0) -> #REF! | H11: =VLOOKUP(C11,#REF!,5,0) -> #REF! | I11: =VLOOKUP(C11,#REF!,6,0) -> #REF! | K11: =+D11+E11+G11+H11+I11 -> #REF! | L11: =VLOOKUP(C11,[2]ABC!$A$3:$B$88,2,0) -> 15000 | M11: =+L11/2 -> 7500 | O11: =VLOOKUP(C11,[1]CPD!$B$9:$I$35,8,0) -> 0 | P11: =+H11+I11 -> #REF! | Q11: =VLOOKUP(C11,[1]CPD!$B$9:$R$35,17,0) -> 0 | R11: =VLOOKUP(C11,[1]CPD!$B$9:$Q$35,16,0) -> 0 | S11: =VLOOKUP(C11,[2]CPD!$B$9:$S$35,18,0) -> 0 | T11: =VLOOKUP(C11,[1]CPD!$B$9:$T$35,19,0) -> 0 | W11: =VLOOKUP(C11,[1]CPD!$B$9:$V$35,21,0) -> 0 | Y11: =+K11-O11-P11+Q11+R11+S11+T11+U11+V11+W11 -> #REF! | Z11: =+M11-Y11 -> #REF! | AB11: =VLOOKUP(C11,[2]SINDICATO!$C$7:$Q$141,15,0) -> #N/A
A12: SEI0108 | B12: SEITON - (CONSULTORIA II) | C12: Caballero Diaz Francisco Javier | D12: =VLOOKUP(C12,[1]CPD!$B$9:$Y$35,24,0) -> 1675.4 | G12: =VLOOKUP(C12,#REF!,4,0) -> #REF! | H12: =VLOOKUP(C12,#REF!,5,0) -> #REF! | I12: =VLOOKUP(C12,#REF!,6,0) -> #REF! | K12: =+D12+E12+G12+H12+I12 -> #REF! | L12: =VLOOKUP(C12,[2]ABC!$A$3:$B$88,2,0) -> 10150 | M12: =+L12/2 -> 5075 | O12: =VLOOKUP(C12,[1]CPD!$B$9:$I$35,8,0) -> 0 | P12: =+H12+I12 -> #REF! | Q12: =VLOOKUP(C12,[1]CPD!$B$9:$R$35,17,0) -> 1826.51 | R12: =VLOOKUP(C12,[1]CPD!$B$9:$Q$35,16,0) -> 0 | S12: =VLOOKUP(C12,[2]CPD!$B$9:$S$35,18,0) -> 0 | T12: =VLOOKUP(C12,[1]CPD!$B$9:$T$35,19,0) -> 15 | W12: =VLOOKUP(C12,[1]CPD!$B$9:$V$35,21,0) -> 0 | Y12: =+K12-O12-P12+Q12+R12+S12+T12+U12+V12+W12 -> #REF! | Z12: =+M12-Y12 -> #REF! | AB12: =VLOOKUP(C12,[2]SINDICATO!$C$7:$Q$141,15,0) -> #N/A
A13: SEI0116 | B13: SEITON - (CONSULTORIA II) | C13: Casillas Cardona Cesar Alejandro | D13: =VLOOKUP(C13,[1]CPD!$B$9:$Y$35,24,0) -> 3336.6 | G13: =VLOOKUP(C13,#REF!,4,0) -> #REF! | H13: =VLOOKUP(C13,#REF!,5,0) -> #REF! | I13: =VLOOKUP(C13,#REF!,6,0) -> #REF! | K13: =+D13+E13+G13+H13+I13 -> #REF! | L13: =VLOOKUP(C13,[2]ABC!$A$3:$B$88,2,0) -> 12000 | M13: =+L13/2 -> 6000 | O13: =VLOOKUP(C13,[1]CPD!$B$9:$I$35,8,0) -> 0 | P13: =+H13+I13 -> #REF! | Q13: =VLOOKUP(C13,[1]CPD!$B$9:$R$35,17,0) -> 757.32 | R13: =VLOOKUP(C13,[1]CPD!$B$9:$Q$35,16,0) -> 0 | S13: =VLOOKUP(C13,[2]CPD!$B$9:$S$35,18,0) -> 0 | T13: =VLOOKUP(C13,[1]CPD!$B$9:$T$35,19,0) -> 15 | W13: =VLOOKUP(C13,[1]CPD!$B$9:$V$35,21,0) -> 0 | Y13: =+K13-O13-P13+Q13+R13+S13+T13+U13+V13+W13 -> #REF! | Z13: =+M13-Y13 -> #REF! | AB13: =VLOOKUP(C13,[2]SINDICATO!$C$7:$Q$141,15,0) -> #N/A
A14: SEI0117 | B14: SEITON - (CONSULTORIA II) | C14: Mariscal Romero Luis Adrian | D14: =VLOOKUP(C14,[1]CPD!$B$9:$Y$35,24,0) -> 3060 | G14: =VLOOKUP(C14,#REF!,4,0) -> #REF! | H14: =VLOOKUP(C14,#REF!,5,0) -> #REF! | I14: =VLOOKUP(C14,#REF!,6,0) -> #REF! | K14: =+D14+E14+G14+H14+I14 -> #REF! | L14: 15000 | M14: =+L14/2 -> 7500 | O14: =VLOOKUP(C14,[1]CPD!$B$9:$I$35,8,0) -> 0 | P14: =+H14+I14 -> #REF! | Q14: =VLOOKUP(C14,[1]CPD!$B$9:$R$35,17,0) -> 1674 | R14: =VLOOKUP(C14,[1]CPD!$B$9:$Q$35,16,0) -> 0 | S14: =VLOOKUP(C14,[2]CPD!$B$9:$S$35,18,0) -> 0 | T14: =VLOOKUP(C14,[1]CPD!$B$9:$T$35,19,0) -> 15 | W14: =VLOOKUP(C14,[1]CPD!$B$9:$V$35,21,0) -> 0 | Y14: =+K14-O14-P14+Q14+R14+S14+T14+U14+V14+W14 -> #REF! | Z14: =+M14-Y14 -> #REF! | AB14: =VLOOKUP(C14,[2]SINDICATO!$C$7:$Q$141,15,0) -> #N/A
A15: SEI0118 | B15: SEITON - (CONSULTORIA II) | C15: Arroyo Ramirez Hector Hugo | D15: =VLOOKUP(C15,[1]CPD!$B$9:$Y$35,24,0) -> 2967.4 | G15: =VLOOKUP(C15,#REF!,4,0) -> #REF! | H15: =VLOOKUP(C15,#REF!,5,0) -> #REF! | I15: =VLOOKUP(C15,#REF!,6,0) -> #REF! | K15: =+D15+E15+G15+H15+I15 -> #REF! | L15: =VLOOKUP(C15,[2]ABC!$A$3:$B$88,2,0) -> 13000 | M15: =+L15/2 -> 6500 | O15: =VLOOKUP(C15,[1]CPD!$B$9:$I$35,8,0) -> 285.99 | P15: =+H15+I15 -> #REF! | Q15: =VLOOKUP(C15,[1]CPD!$B$9:$R$35,17,0) -> 1432.4 | R15: =VLOOKUP(C15,[1]CPD!$B$9:$Q$35,16,0) -> 0 | S15: =VLOOKUP(C15,[2]CPD!$B$9:$S$35,18,0) -> 0 | T15: =VLOOKUP(C15,[1]CPD!$B$9:$T$35,19,0) -> 15 | W15: =VLOOKUP(C15,[1]CPD!$B$9:$V$35,21,0) -> 268.35 | Y15: =+K15-O15-P15+Q15+R15+S15+T15+U15+V15+W15 -> #REF! | Z15: =+M15-Y15 -> #REF! | AB15: =VLOOKUP(C15,[2]SINDICATO!$C$7:$Q$141,15,0) -> #N/A
A16: SEI0119 | B16: SEITON - (CONSULTORIA II) | C16: Dominguez Lopez Maria De Jesus | D16: =VLOOKUP(C16,[1]CPD!$B$9:$Y$35,24,0) -> 4635.4 | G16: =VLOOKUP(C16,#REF!,4,0) -> #REF! | H16: =VLOOKUP(C16,#REF!,5,0) -> #REF! | I16: =VLOOKUP(C16,#REF!,6,0) -> #REF! | J16: 0 | K16: =+D16+E16+G16+H16+I16 -> #REF! | L16: 13000 | M16: =+L16/2 -> 6500 | O16: =VLOOKUP(C16,[1]CPD!$B$9:$I$35,8,0) -> 786.49 | P16: =+H16+I16 -> #REF! | Q16: =VLOOKUP(C16,[1]CPD!$B$9:$R$35,17,0) -> 0 | R16: =VLOOKUP(C16,[1]CPD!$B$9:$Q$35,16,0) -> 533.16 | S16: =VLOOKUP(C16,[2]CPD!$B$9:$S$35,18,0) -> 0 | T16: =VLOOKUP(C16,[1]CPD!$B$9:$T$35,19,0) -> 15 | W16: =VLOOKUP(C16,[1]CPD!$B$9:$V$35,21,0) -> 0 | X16: 0 | Y16: =+K16-O16-P16+Q16+R16+S16+T16+U16+V16+W16 -> #REF! | Z16: =+M16-Y16 -> #REF! | AB16: =VLOOKUP(C16,[2]SINDICATO!$C$7:$Q$141,15,0) -> 0
A17: SEI0127 | B17: SEITON - (CONSULTORIA II) | C17: Hernandez Ochoa Eduardo | D17: =VLOOKUP(C17,[1]CPD!$B$9:$Y$35,24,0) -> 4899.8 | G17: =VLOOKUP(C17,#REF!,4,0) -> #REF! | H17: =VLOOKUP(C17,#REF!,5,0) -> #REF! | I17: =VLOOKUP(C17,#REF!,6,0) -> #REF! | K17: =+D17+E17+G17+H17+I17 -> #REF! | L17: =VLOOKUP(C17,[2]ABC!$A$3:$B$88,2,0) -> 15000 | M17: =+L17/2 -> 7500 | O17: =VLOOKUP(C17,[1]CPD!$B$9:$I$35,8,0) -> 0 | P17: =+H17+I17 -> #REF! | Q17: =VLOOKUP(C17,[1]CPD!$B$9:$R$35,17,0) -> 0 | R17: =VLOOKUP(C17,[1]CPD!$B$9:$Q$35,16,0) -> 0 | S17: =VLOOKUP(C17,[2]CPD!$B$9:$S$35,18,0) -> 0 | T17: =VLOOKUP(C17,[1]CPD!$B$9:$T$35,19,0) -> 0 | W17: =VLOOKUP(C17,[1]CPD!$B$9:$V$35,21,0) -> 0 | Y17: =+K17-O17-P17+Q17+R17+S17+T17+U17+V17+W17 -> #REF! | Z17: =+M17-Y17 -> #REF! | AB17: =VLOOKUP(C17,[2]SINDICATO!$C$7:$Q$141,15,0) -> #N/A
A18: SEI0147 | B18: SEITON - (CONSULTORIA II) | C18: Diaz Munguia Martha Liliana | D18: =VLOOKUP(C18,[1]CPD!$B$9:$Y$35,24,0) -> 5056.2 | G18: =VLOOKUP(C18,#REF!,4,0) -> #REF! | H18: =VLOOKUP(C18,#REF!,5,0) -> #REF! | I18: =VLOOKUP(C18,#REF!,6,0) -> #REF! | K18: =+D18+E18+G18+H18+I18 -> #REF! | L18: 25000 | M18: =+L18/2 -> 12500 | O18: =VLOOKUP(C18,[1]CPD!$B$9:$I$35,8,0) -> 0 | P18: =+H18+I18 -> #REF! | Q18: =VLOOKUP(C18,[1]CPD!$B$9:$R$35,17,0) -> 419.76 | R18: =VLOOKUP(C18,[1]CPD!$B$9:$Q$35,16,0) -> 0 | S18: =VLOOKUP(C18,[2]CPD!$B$9:$S$35,18,0) -> 0 | T18: =VLOOKUP(C18,[1]CPD!$B$9:$T$35,19,0) -> 15 | W18: =VLOOKUP(C18,[1]CPD!$B$9:$V$35,21,0) -> 0 | Y18: =+K18-O18-P18+Q18+R18+S18+T18+U18+V18+W18 -> #REF! | Z18: =+M18-Y18 -> #REF! | AB18: =VLOOKUP(C18,[2]SINDICATO!$C$7:$Q$141,15,0) -> 0
A19: SEI0173 | B19: SEITON - (CONSULTORIA II) | C19: Nieto Ortiz Jose Luis | D19: =VLOOKUP(C19,[1]CPD!$B$9:$Y$35,24,0) -> 1332.2 | G19: =VLOOKUP(C19,#REF!,4,0) -> #REF! | H19: =VLOOKUP(C19,#REF!,5,0) -> #REF! | I19: =VLOOKUP(C19,#REF!,6,0) -> #REF! | K19: =+D19+E19+G19+H19+I19 -> #REF! | L19: =VLOOKUP(C19,[2]ABC!$A$3:$B$88,2,0) -> 10000 | M19: =+L19/2 -> 5000 | O19: =VLOOKUP(C19,[1]CPD!$B$9:$I$35,8,0) -> 0 | P19: =+H19+I19 -> #REF! | Q19: =VLOOKUP(C19,[1]CPD!$B$9:$R$35,17,0) -> 2169.67 | R19: =VLOOKUP(C19,[1]CPD!$B$9:$Q$35,16,0) -> 0 | S19: =VLOOKUP(C19,[2]CPD!$B$9:$S$35,18,0) -> 0 | T19: =VLOOKUP(C19,[1]CPD!$B$9:$T$35,19,0) -> 15 | W19: =VLOOKUP(C19,[1]CPD!$B$9:$V$35,21,0) -> 0 | Y19: =+K19-O19-P19+Q19+R19+S19+T19+U19+V19+W19 -> #REF! | Z19: =+M19-Y19 -> #REF! | AB19: =VLOOKUP(C19,[2]SINDICATO!$C$7:$Q$141,15,0) -> #N/A
A20: SEI0221 | B20: SEITON - (CONSULTORIA II) | C20: Rogel Teran Marco Antonio | D20: =VLOOKUP(C20,[1]CPD!$B$9:$Y$35,24,0) -> 16969.2 | G20: =VLOOKUP(C20,#REF!,4,0) -> #REF! | H20: =VLOOKUP(C20,#REF!,5,0) -> #REF! | I20: =VLOOKUP(C20,#REF!,6,0) -> #REF! | K20: =+D20+E20+G20+H20+I20 -> #REF! | L20: 60000 | M20: =+L20/2 -> 30000 | O20: =VLOOKUP(C20,[1]CPD!$B$9:$I$35,8,0) -> 0 | P20: =+H20+I20 -> #REF! | Q20: =VLOOKUP(C20,[1]CPD!$B$9:$R$35,17,0) -> 0 | R20: =VLOOKUP(C20,[1]CPD!$B$9:$Q$35,16,0) -> 0 | S20: =VLOOKUP(C20,[2]CPD!$B$9:$S$35,18,0) -> 0 | T20: =VLOOKUP(C20,[1]CPD!$B$9:$T$35,19,0) -> 0 | W20: =VLOOKUP(C20,[1]CPD!$B$9:$V$35,21,0) -> 417.6 | Y20: =+K20-O20-P20+Q20+R20+S20+T20+U20+V20+W20 -> #REF! | Z20: =+M20-Y20 -> #REF! | AB20: =VLOOKUP(C20,[2]SINDICATO!$C$7:$Q$141,15,0) -> #N/A
A21: SEI0222 | B21: SEITON - (CONSULTORIA II) | C21: Saucedo Duran Jesus Alfredo | D21: =VLOOKUP(C21,[1]CPD!$B$9:$Y$35,24,0) -> 4241.4 | G21: =VLOOKUP(C21,#REF!,4,0) -> #REF! | H21: =VLOOKUP(C21,#REF!,5,0) -> #REF! | I21: =VLOOKUP(C21,#REF!,6,0) -> #REF! | K21: =+D21+E21+G21+H21+I21 -> #REF! | L21: 12000 | M21: =+L21/2 -> 6000 | O21: =VLOOKUP(C21,[1]CPD!$B$9:$I$35,8,0) -> 132.5 | P21: =+H21+I21 -> #REF! | Q21: =VLOOKUP(C21,[1]CPD!$B$9:$R$35,17,0) -> 0 | R21: =VLOOKUP(C21,[1]CPD!$B$9:$Q$35,16,0) -> 0 | S21: =VLOOKUP(C21,[2]CPD!$B$9:$S$35,18,0) -> 0 | T21: =VLOOKUP(C21,[1]CPD!$B$9:$T$35,19,0) -> 0 | W21: =VLOOKUP(C21,[1]CPD!$B$9:$V$35,21,0) -> 0 | Y21: =+K21-O21-P21+Q21+R21+S21+T21+U21+V21+W21 -> #REF! | Z21: =+M21-Y21 -> #REF! | AB21: =VLOOKUP(C21,[2]SINDICATO!$C$7:$Q$141,15,0) -> 0
A22: SEI032 | B22: SEITON - (CONSULTORIA II) | C22: Camarena Quiroz Erick Frank | D22: =VLOOKUP(C22,[1]CPD!$B$9:$Y$35,24,0) -> 2911.8 | G22: =VLOOKUP(C22,#REF!,4,0) -> #REF! | H22: =VLOOKUP(C22,#REF!,5,0) -> #REF! | I22: =VLOOKUP(C22,#REF!,6,0) -> #REF! | K22: =+D22+E22+G22+H22+I22 -> #REF! | L22: =VLOOKUP(C22,[2]ABC!$A$3:$B$88,2,0) -> 9000 | M22: =+L22/2 -> 4500 | O22: =VLOOKUP(C22,[1]CPD!$B$9:$I$35,8,0) -> 0 | P22: =+H22+I22 -> #REF! | Q22: =VLOOKUP(C22,[1]CPD!$B$9:$R$35,17,0) -> 0 | R22: =VLOOKUP(C22,[1]CPD!$B$9:$Q$35,16,0) -> 0 | S22: =VLOOKUP(C22,[2]CPD!$B$9:$S$35,18,0) -> 0 | T22: =VLOOKUP(C22,[1]CPD!$B$9:$T$35,19,0) -> 0 | W22: =VLOOKUP(C22,[1]CPD!$B$9:$V$35,21,0) -> 0 | Y22: =+K22-O22-P22+Q22+R22+S22+T22+U22+V22+W22 -> #REF! | Z22: =+M22-Y22 -> #REF! | AB22: =VLOOKUP(C22,[2]SINDICATO!$C$7:$Q$141,15,0) -> 0
A23: SEI0401 | B23: SEITON - (CONSULTORIA II) | C23: De La Torre Zambara Francisco Ernesto | D23: =VLOOKUP(C23,[1]CPD!$B$9:$Y$35,24,0) -> 3203.8 | G23: =VLOOKUP(C23,#REF!,4,0) -> #REF! | H23: =VLOOKUP(C23,#REF!,5,0) -> #REF! | I23: =VLOOKUP(C23,#REF!,6,0) -> #REF! | K23: =+D23+E23+G23+H23+I23 -> #REF! | L23: =VLOOKUP(C23,[2]ABC!$A$3:$B$88,2,0) -> 10150 | M23: =+L23/2 -> 5075 | O23: =VLOOKUP(C23,[1]CPD!$B$9:$I$35,8,0) -> 0 | P23: =+H23+I23 -> #REF! | Q23: =VLOOKUP(C23,[1]CPD!$B$9:$R$35,17,0) -> 0 | R23: =VLOOKUP(C23,[1]CPD!$B$9:$Q$35,16,0) -> 0 | S23: =VLOOKUP(C23,[2]CPD!$B$9:$S$35,18,0) -> 0 | T23: =VLOOKUP(C23,[1]CPD!$B$9:$T$35,19,0) -> 0 | W23: =VLOOKUP(C23,[1]CPD!$B$9:$V$35,21,0) -> 313.2 | Y23: =+K23-O23-P23+Q23+R23+S23+T23+U23+V23+W23 -> #REF! | Z23: =+M23-Y23 -> #REF! | AB23: =VLOOKUP(C23,[2]SINDICATO!$C$7:$Q$141,15,0) -> #N/A
A24: SEI0425 | B24: SEITON - (CONSULTORIA II) | C24: Carbajal Cabuto Jose Luis | D24: =VLOOKUP(C24,[1]CPD!$B$9:$Y$35,24,0) -> 1995.4 | G24: =VLOOKUP(C24,#REF!,4,0) -> #REF! | H24: =VLOOKUP(C24,#REF!,5,0) -> #REF! | I24: =VLOOKUP(C24,#REF!,6,0) -> #REF! | K24: =+D24+E24+G24+H24+I24 -> #REF! | L24: =VLOOKUP(C24,[2]ABC!$A$3:$B$88,2,0) -> 10250 | M24: =+L24/2 -> 5125 | O24: =VLOOKUP(C24,[1]CPD!$B$9:$I$35,8,0) -> 0 | P24: =+H24+I24 -> #REF! | Q24: =VLOOKUP(C24,[1]CPD!$B$9:$R$35,17,0) -> 1506.5 | R24: =VLOOKUP(C24,[1]CPD!$B$9:$Q$35,16,0) -> 0 | S24: =VLOOKUP(C24,[2]CPD!$B$9:$S$35,18,0) -> 0 | T24: =VLOOKUP(C24,[1]CPD!$B$9:$T$35,19,0) -> 15 | W24: =VLOOKUP(C24,[1]CPD!$B$9:$V$35,21,0) -> 0 | Y24: =+K24-O24-P24+Q24+R24+S24+T24+U24+V24+W24 -> #REF! | Z24: =+M24-Y24 -> #REF! | AB24: =VLOOKUP(C24,[2]SINDICATO!$C$7:$Q$141,15,0) -> #N/A
A25: SEI0435 | B25: SEITON - (CONSULTORIA II) | C25: Benavides Herrera Alejandra | D25: =VLOOKUP(C25,[1]CPD!$B$9:$Y$35,24,0) -> 3196.8 | G25: =VLOOKUP(C25,#REF!,4,0) -> #REF! | H25: =VLOOKUP(C25,#REF!,5,0) -> #REF! | I25: =VLOOKUP(C25,#REF!,6,0) -> #REF! | K25: =+D25+E25+G25+H25+I25 -> #REF! | L25: 40000 | M25: =+L25/2 -> 20000 | O25: =VLOOKUP(C25,[1]CPD!$B$9:$I$35,8,0) -> 0 | P25: =+H25+I25 -> #REF! | Q25: =VLOOKUP(C25,[1]CPD!$B$9:$R$35,17,0) -> 0 | R25: =VLOOKUP(C25,[1]CPD!$B$9:$Q$35,16,0) -> 0 | S25: =VLOOKUP(C25,[2]CPD!$B$9:$S$35,18,0) -> 0 | T25: =VLOOKUP(C25,[1]CPD!$B$9:$T$35,19,0) -> 0 | W25: =VLOOKUP(C25,[1]CPD!$B$9:$V$35,21,0) -> 0 | Y25: =+K25-O25-P25+Q25+R25+S25+T25+U25+V25+W25 -> #REF! | Z25: =+M25-Y25 -> #REF! | AB25: =VLOOKUP(C25,[2]SINDICATO!$C$7:$Q$141,15,0) -> #N/A
A26: SEI0437 | B26: SEITON - (CONSULTORIA II) | C26: Leal Montaño Diego | D26: =VLOOKUP(C26,[1]CPD!$B$9:$Y$35,24,0) -> 2782.8 | G26: =VLOOKUP(C26,#REF!,4,0) -> #REF! | H26: =VLOOKUP(C26,#REF!,5,0) -> #REF! | I26: =VLOOKUP(C26,#REF!,6,0) -> #REF! | K26: =+D26+E26+G26+H26+I26 -> #REF! | L26: 10000 | M26: =+L26/2 -> 5000 | O26: =VLOOKUP(C26,[1]CPD!$B$9:$I$35,8,0) -> 0 | P26: =+H26+I26 -> #REF! | Q26: =VLOOKUP(C26,[1]CPD!$B$9:$R$35,17,0) -> 398.98 | R26: =VLOOKUP(C26,[1]CPD!$B$9:$Q$35,16,0) -> 0 | S26: =VLOOKUP(C26,[2]CPD!$B$9:$S$35,18,0) -> 0 | T26: =VLOOKUP(C26,[1]CPD!$B$9:$T$35,19,0) -> 15 | W26: =VLOOKUP(C26,[1]CPD!$B$9:$V$35,21,0) -> 0 | Y26: =+K26-O26-P26+Q26+R26+S26+T26+U26+V26+W26 -> #REF! | Z26: =+M26-Y26 -> #REF! | AB26: =VLOOKUP(C26,[2]SINDICATO!$C$7:$Q$141,15,0) -> 0
A27: SEI0440 | B27: SEITON - (CONSULTORIA II) | C27: Leija Arevalo Guadalupe | D27: =VLOOKUP(C27,[1]CPD!$B$9:$Y$35,24,0) -> 1003 | G27: =VLOOKUP(C27,#REF!,4,0) -> #REF! | H27: =VLOOKUP(C27,#REF!,5,0) -> #REF! | I27: =VLOOKUP(C27,#REF!,6,0) -> #REF! | K27: =+D27+E27+G27+H27+I27 -> #REF! | L27: 4000 | M27: =+L27/2 -> 2000 | O27: =VLOOKUP(C27,[1]CPD!$B$9:$I$35,8,0) -> 0 | P27: =+H27+I27 -> #REF! | Q27: =VLOOKUP(C27,[1]CPD!$B$9:$R$35,17,0) -> 1005.81 | R27: =VLOOKUP(C27,[1]CPD!$B$9:$Q$35,16,0) -> 0 | S27: =VLOOKUP(C27,[2]CPD!$B$9:$S$35,18,0) -> 0 | T27: =VLOOKUP(C27,[1]CPD!$B$9:$T$35,19,0) -> 15 | W27: =VLOOKUP(C27,[1]CPD!$B$9:$V$35,21,0) -> 0 | Y27: =+K27-O27-P27+Q27+R27+S27+T27+U27+V27+W27 -> #REF! | Z27: =+M27-Y27 -> #REF! | AA27: subsidio | AB27: =VLOOKUP(C27,[2]SINDICATO!$C$7:$Q$141,15,0) -> 0
A28: SEI0442 | B28: SEITON - (CONSULTORIA II) | C28: Sierra Escamilla Daniela | D28: =VLOOKUP(C28,[1]CPD!$B$9:$Y$35,24,0) -> 4036 | G28: =VLOOKUP(C28,#REF!,4,0) -> #REF! | H28: =VLOOKUP(C28,#REF!,5,0) -> #REF! | I28: =VLOOKUP(C28,#REF!,6,0) -> #REF! | K28: =+D28+E28+G28+H28+I28 -> #REF! | L28: 13000 | M28: =+L28/2 -> 6500 | O28: =VLOOKUP(C28,[1]CPD!$B$9:$I$35,8,0) -> 0 | P28: =+H28+I28 -> #REF! | Q28: =VLOOKUP(C28,[1]CPD!$B$9:$R$35,17,0) -> 0 | R28: =VLOOKUP(C28,[1]CPD!$B$9:$Q$35,16,0) -> 0 | S28: =VLOOKUP(C28,[2]CPD!$B$9:$S$35,18,0) -> 0 | T28: =VLOOKUP(C28,[1]CPD!$B$9:$T$35,19,0) -> 0 | W28: =VLOOKUP(C28,[1]CPD!$B$9:$V$35,21,0) -> 0 | Y28: =+K28-O28-P28+Q28+R28+S28+T28+U28+V28+W28 -> #REF! | Z28: =+M28-Y28 -> #REF! | AB28: =VLOOKUP(C28,[2]SINDICATO!$C$7:$Q$141,15,0) -> #N/A
A29: SEI0445 | B29: SEITON - (CONSULTORIA II) | C29: Muñoz Melgoza Gabriel | D29: =VLOOKUP(C29,[1]CPD!$B$9:$Y$35,24,0) -> 4609.4 | G29: =VLOOKUP(C29,#REF!,4,0) -> #REF! | H29: =VLOOKUP(C29,#REF!,5,0) -> #REF! | I29: =VLOOKUP(C29,#REF!,6,0) -> #REF! | K29: =+D29+E29+G29+H29+I29 -> #REF! | L29: 15400 | M29: =+L29/2 -> 7700 | O29: =VLOOKUP(C29,[1]CPD!$B$9:$I$35,8,0) -> 0 | P29: =+H29+I29 -> #REF! | Q29: =VLOOKUP(C29,[1]CPD!$B$9:$R$35,17,0) -> 0 | R29: =VLOOKUP(C29,[1]CPD!$B$9:$Q$35,16,0) -> 0 | S29: =VLOOKUP(C29,[2]CPD!$B$9:$S$35,18,0) -> 0 | T29: =VLOOKUP(C29,[1]CPD!$B$9:$T$35,19,0) -> 0 | W29: =VLOOKUP(C29,[1]CPD!$B$9:$V$35,21,0) -> 0 | Y29: =+K29-O29-P29+Q29+R29+S29+T29+U29+V29+W29 -> #REF! | Z29: =+M29-Y29 -> #REF! | AB29: =VLOOKUP(C29,[2]SINDICATO!$C$7:$Q$141,15,0) -> #N/A
A30: SEI0448 | B30: SEITON - (CONSULTORIA II) | C30: Rodriguez Chavez Oswaldo Emmanuel | D30: =VLOOKUP(C30,[1]CPD!$B$9:$Y$35,24,0) -> 4327.4 | G30: =VLOOKUP(C30,#REF!,4,0) -> #REF! | H30: =VLOOKUP(C30,#REF!,5,0) -> #REF! | I30: =VLOOKUP(C30,#REF!,6,0) -> #REF! | K30: =+D30+E30+G30+H30+I30 -> #REF! | L30: 14000 | M30: =+L30/2 -> 7000 | O30: =VLOOKUP(C30,[1]CPD!$B$9:$I$35,8,0) -> 0 | P30: =+H30+I30 -> #REF! | Q30: =VLOOKUP(C30,[1]CPD!$B$9:$R$35,17,0) -> 0 | R30: =VLOOKUP(C30,[1]CPD!$B$9:$Q$35,16,0) -> 0 | S30: =VLOOKUP(C30,[2]CPD!$B$9:$S$35,18,0) -> 0 | T30: =VLOOKUP(C30,[1]CPD!$B$9:$T$35,19,0) -> 0 | W30: =VLOOKUP(C30,[1]CPD!$B$9:$V$35,21,0) -> 0 | Y30: =+K30-O30-P30+Q30+R30+S30+T30+U30+V30+W30 -> #REF! | Z30: =+M30-Y30 -> #REF! | AB30: =VLOOKUP(C30,[2]SINDICATO!$C$7:$Q$141,15,0) -> 0
A31: SEI0010 | B31: SEITON (IP INNOVA II) | C31: Torres Ricardez Alfredo | E31: =VLOOKUP(C31,[1]IP!$B$9:$V$116,21,0) -> 3585.4 | G31: =VLOOKUP(C31,#REF!,4,0) -> #REF! | H31: =VLOOKUP(C31,#REF!,5,0) -> #REF! | I31: =VLOOKUP(C31,#REF!,6,0) -> #REF! | K31: =+D31+E31+G31+H31+I31 -> #REF! | L31: =VLOOKUP(C31,[2]ABC!$A$3:$B$88,2,0) -> 8000 | M31: =+L31/2 -> 4000 | O31: =VLOOKUP(C31,[1]IP!$B$9:$I$116,8,0) -> 0 | P31: =+H31+I31 -> #REF! | Q31: =VLOOKUP(C31,[1]IP!$B$9:$N$116,13,0) -> 0 | R31: =VLOOKUP(C31,[1]IP!$B$9:$O$116,14,0) -> 0 | T31: =VLOOKUP(C31,[1]IP!$B$9:$P$116,15,0) -> 0 | U31: =VLOOKUP(C31,[1]IP!$B$9:$Q$116,16,0) -> 0 | V31: =VLOOKUP(C31,[1]IP!$B$9:$S$116,18,0) -> 0 | W31: =VLOOKUP(C31,[1]IP!$B$9:$R$116,17,0) -> 0 | Y31: =+K31-O31-P31+Q31+R31+S31+T31+U31+V31+W31 -> #REF! | Z31: =+M31-Y31 -> #REF! | AB31: =VLOOKUP(C31,[2]SINDICATO!$C$7:$Q$141,15,0) -> #N/A
A32: SEI0014 | B32: SEITON (IP INNOVA II) | C32: Montoya Portillo Carlos Alberto | E32: =VLOOKUP(C32,[1]IP!$B$9:$V$116,21,0) -> 3585.2 | G32: =VLOOKUP(C32,#REF!,4,0) -> #REF! | H32: =VLOOKUP(C32,#REF!,5,0) -> #REF! | I32: =VLOOKUP(C32,#REF!,6,0) -> #REF! | K32: =+D32+E32+G32+H32+I32 -> #REF! | L32: 8000 | M32: =+L32/2 -> 4000 | O32: =VLOOKUP(C32,[1]IP!$B$9:$I$116,8,0) -> 0 | P32: =+H32+I32 -> #REF! | Q32: =VLOOKUP(C32,[1]IP!$B$9:$N$116,13,0) -> 0 | R32: =VLOOKUP(C32,[1]IP!$B$9:$O$116,14,0) -> 0 | T32: =VLOOKUP(C32,[1]IP!$B$9:$P$116,15,0) -> 0 | U32: =VLOOKUP(C32,[1]IP!$B$9:$Q$116,16,0) -> 0 | V32: =VLOOKUP(C32,[1]IP!$B$9:$S$116,18,0) -> 0 | W32: =VLOOKUP(C32,[1]IP!$B$9:$R$116,17,0) -> 0 | Y32: =+K32-O32-P32+Q32+R32+S32+T32+U32+V32+W32 -> #REF! | Z32: =+M32-Y32 -> #REF! | AB32: =VLOOKUP(C32,[2]SINDICATO!$C$7:$Q$141,15,0) -> #N/A
A33: SEI0016 | B33: SEITON (IP INNOVA II) | C33: Negrete Bejar Aide Sarai | E33: =VLOOKUP(C33,[1]IP!$B$9:$V$116,21,0) -> 1278 | G33: =VLOOKUP(C33,#REF!,4,0) -> #REF! | H33: =VLOOKUP(C33,#REF!,5,0) -> #REF! | I33: =VLOOKUP(C33,#REF!,6,0) -> #REF! | K33: =+D33+E33+G33+H33+I33 -> #REF! | L33: =VLOOKUP(C33,[2]ABC!$A$3:$B$88,2,0) -> 4620 | M33: =+L33/2 -> 2310 | O33: =VLOOKUP(C33,[1]IP!$B$9:$I$116,8,0) -> 0 | P33: =+H33+I33 -> #REF! | Q33: =VLOOKUP(C33,[1]IP!$B$9:$N$116,13,0) -> 999.51 | R33: =VLOOKUP(C33,[1]IP!$B$9:$O$116,14,0) -> 0 | T33: =VLOOKUP(C33,[1]IP!$B$9:$P$116,15,0) -> 15 | U33: =VLOOKUP(C33,[1]IP!$B$9:$Q$116,16,0) -> 0 | V33: =VLOOKUP(C33,[1]IP!$B$9:$S$116,18,0) -> 0 | W33: =VLOOKUP(C33,[1]IP!$B$9:$R$116,17,0) -> 0 | Y33: =+K33-O33-P33+Q33+R33+S33+T33+U33+V33+W33 -> #REF! | Z33: =+M33-Y33 -> #REF! | AB33: =VLOOKUP(C33,[2]SINDICATO!$C$7:$Q$141,15,0) -> 0
