Workbook

Sheet CPD PITSS
B2: CONSULTORIA EN PROYECTOS DINAMICOS S DE RL DE CV
B3: Lista de Raya (forma tabular)
B4: Periodo 9 al 9 QNA SEITON del 01/05/2019 al 15/05/2019
B5: Reg Pat IMSS: Z2940859106
B6: RFC: CPD -150911-FA3
B7: 1 | C7: =+B7+1 -> 2 | D7: =+C7+1 -> 3 | E7: =+D7+1 -> 4 | F7: =+E7+1 -> 5 | G7: =+F7+1 -> 6 | H7: =+G7+1 -> 7 | I7: =+H7+1 -> 8 | J7: =+I7+1 -> 9 | ... V7: =+U7+1 -> 21
A8: Código | B8: Empleado | C8: Dias Laborados | D8: Dias Vacaciones | E8: Salario Diario | F8: Salario Diario Integrado | G8: Sueldo | H8: Vacaciones a tiempo | I8: Prima de vacaciones a tiempo | J8: Ayuda de Transporte | K8: Ayuda Alimentaria | L8: Ayuda de Renta | M8: *TOTAL* *PERCEPCIONES* | N8: Seguro de vivienda Infonavit | O8: Préstamo Infonavit (vsm) | P8: Subsidio al Empleo (sp) | Q8: I.S.R. (sp) | R8: I.M.S.S. | S8: Deduccion General | T8: Ajuste al neto | U8: *TOTAL* *DEDUCCIONES* | V8: *NETO* | W8: Invalidez y Vida | X8: Cesantia y Vejez | Y8: Enf. y Mat. Patron | Z8: 2% Fondo retiro SAR (8) | AA8: 2% Impuesto estatal | AB8: Riesgo de trabajo (9) | AC8: I.M.S.S. empresa | AD8: Infonavit empresa | AE8: Guarderia I.M.S.S. (7) | AF8: Banco | AG8: Aguinaldo | AH8: infonavit | AI8: subtotal 1 | AJ8: comision | AK8: subtotal 2 | AL8: costo patrimonial | AM8: 2% sobre nomina | AN8: importe de factura | AO8: iva
A9: SEI0009 | B9: Gutierrez Gutierrez Luis Arturo | C9: 15 | D9: 0 | E9: 141.67 | F9: 150.25 | G9: 2125.05 | H9: 0 | I9: 0 | J9: 212.51 | K9: 212.51 | L9: 212.51 | M9: 2762.58 | N9: 0 | O9: 0 | P9: -65.5 | Q9: 0 | R9: 53.52 | S9: 0 | T9: -0.04 | U9: -12.02 | V9: 2774.6 | W9: 39.44 | X9: 70.99 | Y9: 297.98 | Z9: 372.78 | AA9: 55.25 | AB9: 11.27 | AC9: 408.41 | AD9: 112.69 | AE9: 350.24 | AF9: 110 | AG9: =((20/365.24)*15)*($E9*1.3) -> 151.27396 | AH9: =N9+O9 -> 0 | AI9: =V9+S9+AH9 -> 2774.6 | AJ9: =AI9*2% -> 55.492 | AK9: =AI9+AJ9 -> 2830.092 | AL9: =R9+W9+X9+Y9+AB9+Z9+AD9+AE9 -> 1308.91 | AM9: =AL9*2% -> 26.1782 | AN9: =AK9+AL9+AM9 -> 4165.1802 | AO9: =AN9*0.16 -> 666.42883
A10: SEI0026 | B10: Patricio Aguilar Jhonattan Cristian | C10: 15 | D10: 0 | E10: 150 | F10: 159.07 | G10: 2250 | H10: 0 | I10: 0 | J10: 225 | K10: 225 | L10: 225 | M10: 2925 | N10: 0 | O10: 0 | P10: -43.57 | Q10: 0 | R10: 56.67 | S10: 0 | T10: -0.1 | U10: 13 | V10: 2912 | W10: 41.76 | X10: 75.16 | Y10: 300.29 | Z10: 375.42 | AA10: 58.5 | AB10: 11.93 | AC10: 417.21 | AD10: 119.31 | AE10: 351.56 | AF10: 110 | AG10: =((20/365.24)*15)*($E10*1.3) -> 160.16866 | AH10: =N10+O10 -> 0 | AI10: =V10+S10+AH10 -> 2912 | AJ10: =AI10*2% -> 58.24 | AK10: =AI10+AJ10 -> 2970.24 | AL10: =R10+W10+X10+Y10+AB10+Z10+AD10+AE10 -> 1332.1 | AM10: =AL10*2% -> 26.642 | AN10: =AK10+AL10+AM10 -> 4328.982 | AO10: =AN10*0.16 -> 692.63712
A11: SEI0040 | B11: Mora Ramirez Acal Aldo Isidro | C11: 15 | D11: 0 | E11: 216.67 | F11: 229.79 | G11: 3250.05 | H11: 0 | I11: 0 | J11: 325.01 | K11: 325.01 | L11: 325.01 | M11: 4225.08 | N11: 0 | O11: 0 | P11: 0 | Q11: 107.17 | R11: 81.87 | S11: 0 | T11: 0.04 | U11: 189.08 | V11: 4036 | W11: 60.32 | X11: 108.58 | Y11: 318.86 | Z11: 396.64 | AA11: 84.5 | AB11: 17.23 | AC11: 487.76 | AD11: 172.34 | AE11: 362.17 | AF11: 110 | AG11: =((20/365.24)*15)*($E11*1.3) -> 231.35828 | AH11: =N11+O11 -> 0 | AI11: =V11+S11+AH11 -> 4036 | AJ11: =AI11*2% -> 80.72 | AK11: =AI11+AJ11 -> 4116.72 | AL11: =R11+W11+X11+Y11+AB11+Z11+AD11+AE11 -> 1518.01 | AM11: =AL11*2% -> 30.3602 | AN11: =AK11+AL11+AM11 -> 5665.0902 | AO11: =AN11*0.16 -> 906.41443
A12: SEI0041 | B12: Vazquez Perez Miguel Angel | C12: 15 | D12: 0 | E12: 283.33 | F12: 300.49 | G12: 4249.95 | H12: 0 | I12: 0 | J12: 425 | K12: 425 | L12: 425 | M12: 5524.95 | N12: 0 | O12: 0 | P12: 0 | Q12: 341.06 | R12: 109.87 | S12: 0 | T12: 0.02 | U12: 450.95 | V12: 5074 | W12: 78.88 | X12: 141.98 | Y12: 345.18 | Z12: 417.85 | AA12: 110.5 | AB12: 22.54 | AC12: 566.04 | AD12: 225.37 | AE12: 372.77 | AF12: 110 | AG12: =((20/365.24)*15)*($E12*1.3) -> 302.53724 | AH12: =N12+O12 -> 0 | AI12: =V12+S12+AH12 -> 5074 | AJ12: =AI12*2% -> 101.48 | AK12: =AI12+AJ12 -> 5175.48 | AL12: =R12+W12+X12+Y12+AB12+Z12+AD12+AE12 -> 1714.44 | AM12: =AL12*2% -> 34.2888 | AN12: =AK12+AL12+AM12 -> 6924.2088 | AO12: =AN12*0.16 -> 1107.8734
A13: SEI0088 | B13: Morgado Fernandez Martin | C13: 15 | D13: 0 | E13: 273.33 | F13: 289.87 | G13: 4099.95 | H13: 0 | I13: 0 | J13: 410 | K13: 410 | L13: 410 | M13: 5329.95 | N13: 0 | O13: 0 | P13: 0 | Q13: 324.74 | R13: 105.46 | S13: 0 | T13: -0.05 | U13: 430.15 | V13: 4899.8 | W13: 76.09 | X13: 136.96 | Y13: 340.64 | Z13: 414.66 | AA13: 106.6 | AB13: 21.74 | AC13: 553.69 | AD13: 217.4 | AE13: 371.18 | AF13: 110 | AG13: =((20/365.24)*15)*($E13*1.3) -> 291.85933 | AH13: =N13+O13 -> 0 | AI13: =V13+S13+AH13 -> 4899.8 | AJ13: =AI13*2% -> 97.996 | AK13: =AI13+AJ13 -> 4997.796 | AL13: =R13+W13+X13+Y13+AB13+Z13+AD13+AE13 -> 1684.13 | AM13: =AL13*2% -> 33.6826 | AN13: =AK13+AL13+AM13 -> 6715.6086 | AO13: =AN13*0.16 -> 1074.4974
A14: SEI0097 | B14: Arreola Jimenez Jose Nieves | C14: 13 | D14: 2 | E14: 185.83 | F14: 197.07 | G14: 2415.79 | H14: 371.66 | I14: 111.5 | J14: 278.75 | K14: 278.75 | L14: 278.75 | M14: 3735.2 | N14: 15 | O14: 1508.27 | P14: 0 | Q14: 36.57 | R14: 70.22 | S14: 0 | T14: -0.06 | U14: 1630 | V14: 2105.2 | W14: 51.73 | X14: 93.12 | Y14: 310.27 | Z14: 386.82 | AA14: 74.7 | AB14: 14.78 | AC14: 455.12 | AD14: 147.8 | AE14: 357.26 | AF14: 110 | AG14: =((20/365.24)*15)*($E14*1.3) -> 198.42761 | AH14: =N14+O14 -> 1523.27 | AI14: =V14+S14+AH14 -> 3628.47 | AJ14: =AI14*2% -> 72.5694 | AK14: =AI14+AJ14 -> 3701.0394 | AL14: =R14+W14+X14+Y14+AB14+Z14+AD14+AE14 -> 1432 | AM14: =AL14*2% -> 28.64 | AN14: =AK14+AL14+AM14 -> 5161.6794 | AO14: =AN14*0.16 -> 825.8687
A15: SEI0099 | B15: Garcia Villicaña Ricardo Pascual | C15: 15 | D15: 0 | E15: 273.33 | F15: 289.87 | G15: 4099.95 | H15: 0 | I15: 0 | J15: 410 | K15: 410 | L15: 410 | M15: 5329.95 | N15: 0 | O15: 0 | P15: 0 | Q15: 324.74 | R15: 105.46 | S15: 175.43 | T15: 0.12 | U15: 605.75 | V15: =+M15-U15 -> 4724.2 | W15: 76.09 | X15: 136.96 | Y15: 340.64 | Z15: 414.66 | AA15: 106.6 | AB15: 21.74 | AC15: 553.69 | AD15: 217.4 | AE15: 371.18 | AF15: 110 | AG15: =((20/365.24)*15)*($E15*1.3) -> 291.85933 | AH15: =N15+O15 -> 0 | AI15: =V15+S15+AH15 -> 4899.63 | AJ15: =AI15*2% -> 97.9926 | AK15: =AI15+AJ15 -> 4997.6226 | AL15: =R15+W15+X15+Y15+AB15+Z15+AD15+AE15 -> 1684.13 | AM15: =AL15*2% -> 33.6826 | AN15: =AK15+AL15+AM15 -> 6715.4352 | AO15: =AN15*0.16 -> 1074.4696
A16: SEI0108 | B16: Caballero Diaz Francisco Javier | C16: 15 | D16: 0 | E16: 185.83 | F16: 197.07 | G16: 2787.45 | H16: 0 | I16: 0 | J16: 278.75 | K16: 278.75 | L16: 278.75 | M16: 3623.7 | N16: 15 | O16: 1750.48 | P16: 0 | Q16: 36.57 | R16: 70.22 | S16: 0 | T16: 0.03 | U16: 1872.3 | V16: 1751.4 | W16: 51.73 | X16: 93.12 | Y16: 310.27 | Z16: 386.82 | AA16: 72.47 | AB16: 14.78 | AC16: 455.12 | AD16: 147.8 | AE16: 357.26 | AF16: 110 | AG16: =((20/365.24)*15)*($E16*1.3) -> 198.42761 | AH16: =N16+O16 -> 1765.48 | AI16: =V16+S16+AH16 -> 3516.88 | AJ16: =AI16*2% -> 70.3376 | AK16: =AI16+AJ16 -> 3587.2176 | AL16: =R16+W16+X16+Y16+AB16+Z16+AD16+AE16 -> 1432 | AM16: =AL16*2% -> 28.64 | AN16: =AK16+AL16+AM16 -> 5047.8576 | AO16: =AN16*0.16 -> 807.65722
A17: SEI0116 | B17: Casillas Cardona Cesar Alejandro | C17: 15 | D17: 0 | E17: 220.83 | F17: 234.19 | G17: 3312.45 | H17: 0 | I17: 0 | J17: 331.25 | K17: 331.25 | L17: 331.25 | M17: 4306.2 | N17: 15 | O17: 1010.9 | P17: 0 | Q17: 113.96 | R17: 83.43 | S17: 0 | T17: -0.09 | U17: 1223.2 | V17: 3083 | W17: 61.47 | X17: 110.65 | Y17: 320.01 | Z17: 397.96 | AA17: 86.12 | AB17: 17.56 | AC17: 492.13 | AD17: 175.64 | AE17: 362.83 | AF17: 110 | AG17: =((20/365.24)*15)*($E17*1.3) -> 235.8003 | AH17: =N17+O17 -> 1025.9 | AI17: =V17+S17+AH17 -> 4108.9 | AJ17: =AI17*2% -> 82.178 | AK17: =AI17+AJ17 -> 4191.078 | AL17: =R17+W17+X17+Y17+AB17+Z17+AD17+AE17 -> 1529.55 | AM17: =AL17*2% -> 30.591 | AN17: =AK17+AL17+AM17 -> 5751.219 | AO17: =AN17*0.16 -> 920.19504
A18: SEI0117 | B18: Mariscal Romero Luis Adrian | C18: 15 | D18: 0 | E18: 264.58 | F18: 276.54 | G18: 3968.7 | H18: 0 | I18: 0 | J18: 396.87 | K18: 396.87 | L18: 396.87 | M18: 5159.31 | N18: 15 | O18: 1604.18 | P18: 0 | Q18: 310.46 | R18: 99.91 | S18: 0 | T18: -0.04 | U18: 2029.51 | V18: 3129.8 | W18: 72.59 | X18: 130.66 | Y18: 334.94 | Z18: 410.66 | AA18: 103.19 | AB18: 20.74 | AC18: 538.19 | AD18: 207.4 | AE18: 369.18 | AF18: 110 | AG18: =((20/365.24)*15)*($E18*1.3) -> 282.51615 | AH18: =N18+O18 -> 1619.18 | AI18: =V18+S18+AH18 -> 4748.98 | AJ18: =AI18*2% -> 94.9796 | AK18: =AI18+AJ18 -> 4843.9596 | AL18: =R18+W18+X18+Y18+AB18+Z18+AD18+AE18 -> 1646.08 | AM18: =AL18*2% -> 32.9216 | AN18: =AK18+AL18+AM18 -> 6522.9612 | AO18: =AN18*0.16 -> 1043.6738
A19: SEI0118 | B19: Arroyo Ramirez Hector Hugo | C19: 15 | D19: 0 | E19: 238.33 | F19: 252.75 | G19: 3574.95 | H19: 0 | I19: 238.33 | J19: 357.5 | K19: 357.5 | L19: 357.5 | M19: 4885.78 | N19: 15 | O19: 1372 | P19: 0 | Q19: 160.25 | R19: 90.05 | S19: 255.4 | T19: 0.08 | U19: 1892.78 | V19: =+M19-U19 -> 2993 | W19: 66.35 | X19: 119.42 | Y19: 324.89 | Z19: 403.52 | AA19: 97.72 | AB19: 18.96 | AC19: 510.66 | AD19: 189.56 | AE19: 365.61 | AF19: 110 | AG19: =((20/365.24)*15)*($E19*1.3) -> 254.48664 | AH19: =N19+O19 -> 1387 | AI19: =V19+S19+AH19 -> 4635.4 | AJ19: =AI19*2% -> 92.708 | AK19: =AI19+AJ19 -> 4728.108 | AL19: =R19+W19+X19+Y19+AB19+Z19+AD19+AE19 -> 1578.36 | AM19: =AL19*2% -> 31.5672 | AN19: =AK19+AL19+AM19 -> 6338.0352 | AO19: =AN19*0.16 -> 1014.0856
A20: SEI0127 | B20: Hernandez Ochoa Eduardo | C20: 15 | D20: 0 | E20: 273.33 | F20: 289.87 | G20: 4099.95 | H20: 0 | I20: 0 | J20: 410 | K20: 410 | L20: 410 | M20: 5329.95 | N20: 0 | O20: 0 | P20: 0 | Q20: 324.74 | R20: 105.46 | S20: 0 | T20: 0.15 | U20: 430.35 | V20: 4899.6 | W20: 76.09 | X20: 136.96 | Y20: 340.64 | Z20: 414.66 | AA20: 106.6 | AB20: 21.74 | AC20: 553.69 | AD20: 217.4 | AE20: 371.18 | AF20: 110 | AG20: =((20/365.24)*15)*($E20*1.3) -> 291.85933 | AH20: =N20+O20 -> 0 | AI20: =V20+S20+AH20 -> 4899.6 | AJ20: =AI20*2% -> 97.992 | AK20: =AI20+AJ20 -> 4997.592 | AL20: =R20+W20+X20+Y20+AB20+Z20+AD20+AE20 -> 1684.13 | AM20: =AL20*2% -> 33.6826 | AN20: =AK20+AL20+AM20 -> 6715.4046 | AO20: =AN20*0.16 -> 1074.4647
A21: SEI0173 | B21: Nieto Ortiz Jose Luis | C21: 15 | D21: 0 | E21: 185.83 | F21: 197.07 | G21: 2787.45 | H21: 0 | I21: 0 | J21: 278.75 | K21: 278.75 | L21: 278.75 | M21: 3623.7 | N21: 15 | O21: 2080.03 | P21: 0 | Q21: 36.57 | R21: 70.22 | S21: 0 | T21: 0.08 | U21: 2201.9 | V21: 1421.8 | W21: 51.73 | X21: 93.12 | Y21: 310.27 | Z21: 386.82 | AA21: 72.47 | AB21: 14.78 | AC21: 455.12 | AD21: 147.8 | AE21: 357.26 | AF21: 110 | AG21: =((20/365.24)*15)*($E21*1.3) -> 198.42761 | AH21: =N21+O21 -> 2095.03 | AI21: =V21+S21+AH21 -> 3516.83 | AJ21: =AI21*2% -> 70.3366 | AK21: =AI21+AJ21 -> 3587.1666 | AL21: =R21+W21+X21+Y21+AB21+Z21+AD21+AE21 -> 1432 | AM21: =AL21*2% -> 28.64 | AN21: =AK21+AL21+AM21 -> 5047.8066 | AO21: =AN21*0.16 -> 807.64906
A22: SEI0221 | B22: Rogel Teran Marco Antonio | C22: 14 | D22: 1 | E22: 1060.83 | F22: 1125.06 | G22: 14851.62 | H22: 1060.83 | I22: 318.25 | J22: 1591.25 | K22: 1591.25 | L22: 1591.25 | M22: 21004.45 | N22: 0 | O22: 0 | P22: 0 | Q22: 2846.24 | R22: 453.09 | S22: 0 | T22: 0.12 | U22: 3299.45 | V22: 17705 | W22: 295.33 | X22: 531.59 | Y22: 697.68 | Z22: 665.22 | AA22: 420.09 | AB22: 84.38 | AC22: 1524.6 | AD22: 843.79 | AE22: 496.46 | AF22: 110 | AG22: =((20/365.24)*15)*($E22*1.3) -> 1132.7448 | AH22: =N22+O22 -> 0 | AI22: =V22+S22+AH22 -> 17705 | AJ22: =AI22*2% -> 354.1 | AK22: =AI22+AJ22 -> 18059.1 | AL22: =R22+W22+X22+Y22+AB22+Z22+AD22+AE22 -> 4067.54 | AM22: =AL22*2% -> 81.3508 | AN22: =AK22+AL22+AM22 -> 22207.991 | AO22: =AN22*0.16 -> 3553.2785
A23: SEI0401 | B23: De La Torre Zambara Francisco Ernesto | C23: 13 | D23: 2 | E23: 185.83 | F23: 197.07 | G23: 2415.79 | H23: 371.66 | I23: 111.5 | J23: 278.75 | K23: 278.75 | L23: 278.75 | M23: 3735.2 | N23: 0 | O23: 0 | P23: 0 | Q23: 36.57 | R23: 70.22 | S23: 0 | T23: 0.01 | U23: 106.8 | V23: 3628.4 | W23: 51.73 | X23: 93.12 | Y23: 310.27 | Z23: 386.82 | AA23: 74.7 | AB23: 14.78 | AC23: 455.12 | AD23: 147.8 | AE23: 357.26 | AF23: 110 | AG23: =((20/365.24)*15)*($E23*1.3) -> 198.42761 | AH23: =N23+O23 -> 0 | AI23: =V23+S23+AH23 -> 3628.4 | AJ23: =AI23*2% -> 72.568 | AK23: =AI23+AJ23 -> 3700.968 | AL23: =R23+W23+X23+Y23+AB23+Z23+AD23+AE23 -> 1432 | AM23: =AL23*2% -> 28.64 | AN23: =AK23+AL23+AM23 -> 5161.608 | AO23: =AN23*0.16 -> 825.85728
A24: SEI0425 | B24: Carbajal Cabuto Jose Luis | C24: 15 | D24: 0 | E24: 185.83 | F24: 197.07 | G24: 2787.45 | H24: 0 | I24: 0 | J24: 278.75 | K24: 278.75 | L24: 278.75 | M24: 3623.7 | N24: 15 | O24: 1443.16 | P24: 0 | Q24: 36.57 | R24: 70.22 | S24: 0 | T24: -0.05 | U24: 1564.9 | V24: 2058.8 | W24: 51.73 | X24: 93.12 | Y24: 310.27 | Z24: 386.82 | AA24: 72.47 | AB24: 14.78 | AC24: 455.12 | AD24: 147.8 | AE24: 357.26 | AF24: 110 | AG24: =((20/365.24)*15)*($E24*1.3) -> 198.42761 | AH24: =N24+O24 -> 1458.16 | AI24: =V24+S24+AH24 -> 3516.96 | AJ24: =AI24*2% -> 70.3392 | AK24: =AI24+AJ24 -> 3587.2992 | AL24: =R24+W24+X24+Y24+AB24+Z24+AD24+AE24 -> 1432 | AM24: =AL24*2% -> 28.64 | AN24: =AK24+AL24+AM24 -> 5047.9392 | AO24: =AN24*0.16 -> 807.67027
A25: SEI0435 | B25: Benavides Herrera Alejandra | C25: 15 | D25: 0 | E25: 166.67 | F25: 176.76 | G25: 2500.05 | H25: 0 | I25: 0 | J25: 250.01 | K25: 250.01 | L25: 250.01 | M25: 3250.08 | N25: 0 | O25: 0 | P25: -9.62 | Q25: 0 | R25: 62.97 | S25: 0 | T25: -0.07 | U25: 53.28 | V25: 3196.8 | W25: 46.4 | X25: 83.52 | Y25: 304.94 | Z25: 380.73 | AA25: 65 | AB25: 13.26 | AC25: 434.86 | AD25: 132.57 | AE25: 354.21 | AF25: 110 | AG25: =((20/365.24)*15)*($E25*1.3) -> 177.96873 | AH25: =N25+O25 -> 0 | AI25: =V25+S25+AH25 -> 3196.8 | AJ25: =AI25*2% -> 63.936 | AK25: =AI25+AJ25 -> 3260.736 | AL25: =R25+W25+X25+Y25+AB25+Z25+AD25+AE25 -> 1378.6 | AM25: =AL25*2% -> 27.572 | AN25: =AK25+AL25+AM25 -> 4666.908 | AO25: =AN25*0.16 -> 746.70528
A26: SEI0442 | B26: Sierra Escamilla Daniela | C26: 15 | D26: 0 | E26: 216.67 | F26: 229.79 | G26: 3250.05 | H26: 0 | I26: 0 | J26: 325.01 | K26: 325.01 | L26: 325.01 | M26: 4225.08 | N26: 0 | O26: 0 | P26: 0 | Q26: 107.17 | R26: 81.87 | S26: 0 | T26: 0.04 | U26: 189.08 | V26: 4036 | W26: 60.32 | X26: 108.58 | Y26: 318.86 | Z26: 396.64 | AA26: 84.5 | AB26: 17.23 | AC26: 487.76 | AD26: 172.34 | AE26: 362.17 | AF26: 110 | AG26: =((20/365.24)*15)*($E26*1.3) -> 231.35828 | AH26: =N26+O26 -> 0 | AI26: =V26+S26+AH26 -> 4036 | AJ26: =AI26*2% -> 80.72 | AK26: =AI26+AJ26 -> 4116.72 | AL26: =R26+W26+X26+Y26+AB26+Z26+AD26+AE26 -> 1518.01 | AM26: =AL26*2% -> 30.3602 | AN26: =AK26+AL26+AM26 -> 5665.0902 | AO26: =AN26*0.16 -> 906.41443
C27: ============= | D27: ============= | E27: ============= | F27: ============= | G27: ============= | H27: ============= | I27: ============= | J27: ============= | K27: ============= | L27: ============= | M27: ============= | N27: ============= | O27: ============= | P27: ============= | Q27: ============= | R27: ============= | S27: ============= | T27: ============= | U27: ============= | V27: ============= | W27: ============= | X27: ============= | Y27: ============= | Z27: ============= | AA27: ============= | AB27: ============= | AC27: ============= | AD27: ============= | AE27: ============= | AF27: ============= | AG27: =============
A28: Total Gral. | C28: =SUM(C9:C26) -> 265 | D28: =SUM(D9:D26) -> 5 | E28: =SUM(E9:E26) -> 4708.72 | F28: =SUM(F9:F26) -> 4989.65 | G28: =SUM(G9:G26) -> 68826.65 | H28: =SUM(H9:H26) -> 1804.15 | I28: =SUM(I9:I26) -> 779.58 | J28: =SUM(J9:J26) -> 7063.16 | ... AG28: =SUM(AG9:AG26) -> 5027.929
L31: FACTURACION PITS
L32: Devengado Salario | M32: =+V28 -> 74429.4
L33: RETORNOS | M33: =+S28 -> 430.83
L34: Infonavit | M34: =+N28+O28+S28 -> 11304.85
L35: Prestamo Prospera | M35: 0
L36: Subtotal 1 | M36: =SUM(M32:M35) -> 86165.08
L37: Comision | M37: =+M36*2% -> 1723.3016
L38: Subtotal 2 | M38: =+M36+M37 -> 87888.382
L39: Costo Patronal Imss | M39: =+R28+W28+X28+Y28+AB28+Z28+AD28+AE28 -> 29803.99
L40: 2% Sobre Nomina | M40: =+M28*2% -> 1851.9972
L41: Importe de Factura | M41: =+M38+M39+M40 -> 119544.37
L42: IVA | M42: =+M41*16% -> 19127.099
L43: TOTAL | M43: =+M41+M42 -> 138671.47
...

Sheet IP PITSS
B2: IP INNOVACION EN PROYECTOS S DE RL DE CV
B3: Lista de Raya (forma tabular)
B4: Periodo 9 al 9 QNA SEITON del 01/05/2019 al 15/05/2019
B5: Reg Pat IMSS: R1363592103
B6: RFC: IIP -150923-DT7
A8: Código | B8: Empleado | C8: Dias Laborados | D8: Dias Vacaciones | E8: Salario Diario | F8: Salario Diario Integrado | G8: Sueldo | H8: Vacaciones a tiempo | I8: Prima de vacaciones a tiempo | J8: *TOTAL* *PERCEPCIONES* | K8: Seguro de vivienda Infonavit | L8: Préstamo Infonavit (vsm) | M8: Préstamo Infonavit (cf) | N8: Subsidio al Empleo (sp) | O8: I.S.R. (sp) | P8: I.M.S.S. | Q8: Préstamo FONACOT | R8: Deduccion general | S8: Ajuste al neto | T8: *TOTAL* *DEDUCCIONES* | U8: *NETO* | V8: Invalidez y Vida | W8: Cesantia y Vejez | X8: Enf. y Mat. Patron | Y8: 2% Fondo retiro SAR (8) | Z8: 2% Impuesto estatal | AA8: Riesgo de trabajo (9) | AB8: I.M.S.S. empresa | AC8: Infonavit empresa | AD8: Guarderia I.M.S.S. (7) | AE8: Banco | AF8: Aguinaldo | AG8: subtotal 1 | AH8: comision | AI8: subtotal 2 | AJ8: costo patronal imss | AK8: 2% sobre nomina | AL8: importe de factura | AM8: iva | AN8: total
A9: SEI0010 | B9: Torres Ricardez Alfredo | C9: 15 | D9: 0 | E9: 266.67 | F9: 278.72 | G9: 4000.05 | H9: 0 | I9: 0 | J9: 4000.05 | K9: 0 | L9: 0 | M9: 0 | N9: 0 | O9: 313.87 | P9: 100.81 | Q9: 0 | R9: 0 | S9: -0.03 | T9: 414.65 | U9: =+J9-T9 -> 3585.4 | V9: 73.16 | W9: 131.7 | X9: 335.88 | Y9: 273.62 | Z9: 80 | AA9: 33.3 | AB9: 540.74 | AC9: 209.04 | AD9: 231.81 | AE9: 110 | AF9: =((20/365.24)*15)*E9 -> 219.0368 | AG9: =U9+R9+K9+L9+M9+Q9 -> 3585.4 | AH9: =AG9*2% -> 71.708 | AI9: =AG9+AH9 -> 3657.108 | AJ9: =P9+V9+W9+X9+Y9+AA9+AC9+AD9 -> 1389.32 | AK9: =J9*2% -> 80.001 | AL9: =AI9+AJ9+AK9 -> 5126.429 | AM9: =AL9*16% -> 820.22864 | AN9: =AL9+AM9 -> 5946.6576
A10: SEI0014 | B10: Montoya Portillo Carlos Alberto | C10: 15 | D10: 0 | E10: 266.67 | F10: 278.72 | G10: 4000.05 | H10: 0 | I10: 0 | J10: 4000.05 | K10: 0 | L10: 0 | M10: 0 | N10: 0 | O10: 313.87 | P10: 100.81 | Q10: 0 | R10: 0 | S10: -0.03 | T10: 414.65 | U10: =+J10-T10 -> 3585.4 | V10: 73.16 | W10: 131.7 | X10: 335.88 | Y10: 273.62 | Z10: 80 | AA10: 33.3 | AB10: 540.74 | AC10: 209.04 | AD10: 231.81 | AE10: 110 | AF10: =((20/365.24)*15)*E10 -> 219.0368 | AG10: =U10+R10+K10+L10+M10+Q10 -> 3585.4 | AH10: =AG10*2% -> 71.708 | AI10: =AG10+AH10 -> 3657.108 | AJ10: =P10+V10+W10+X10+Y10+AA10+AC10+AD10 -> 1389.32 | AK10: =J10*2% -> 80.001 | AL10: =AI10+AJ10+AK10 -> 5126.429 | AM10: =AL10*16% -> 820.22864 | AN10: =AL10+AM10 -> 5946.6576
A11: SEI0015 | B11: Cota Jaramillo Miguel Angel | C11: 15 | D11: 0 | E11: 200 | F11: 209.04 | G11: 3000 | H11: 0 | I11: 0 | J11: 3000 | K11: 0 | L11: 0 | M11: 0 | N11: 0 | O11: 59.69 | P11: 74.48 | Q11: 0 | R11: 0 | S11: 0.03 | T11: 134.2 | U11: =+J11-T11 -> 2865.8 | V11: 54.87 | W11: 98.77 | X11: 313.41 | Y11: 252.71 | Z11: 60 | AA11: 24.98 | AB11: 467.05 | AC11: 156.78 | AD11: 221.36 | AE11: 110 | AF11: =((20/365.24)*15)*E11 -> 164.27554 | AG11: =U11+R11+K11+L11+M11+Q11 -> 2865.8 | AH11: =AG11*2% -> 57.316 | AI11: =AG11+AH11 -> 2923.116 | AJ11: =P11+V11+W11+X11+Y11+AA11+AC11+AD11 -> 1197.36 | AK11: =J11*2% -> 60 | AL11: =AI11+AJ11+AK11 -> 4180.476 | AM11: =AL11*16% -> 668.87616 | AN11: =AL11+AM11 -> 4849.3522
A12: SEI0016 | B12: Negrete Bejar Aide Sarai | C12: 15 | D12: 0 | E12: 154 | F12: 160.96 | G12: 2310 | H12: 0 | I12: 0 | J12: 2310 | K12: 15 | L12: 956.31 | M12: 0 | N12: -39.73 | O12: 0 | P12: 57.34 | Q12: 0 | R12: 0 | S12: -0.12 | T12: 988.8 | U12: =+J12-T12 -> 1321.2 | V12: 42.25 | W12: 76.05 | X12: 300.79 | Y12: 238.29 | Z12: 46.2 | AA12: 19.23 | AB12: 419.09 | AC12: 120.72 | AD12: 214.14 | AE12: 110 | AF12: =((20/365.24)*15)*E12 -> 126.49217 | AG12: =U12+R12+K12+L12+M12+Q12 -> 2292.51 | AH12: =AG12*2% -> 45.8502 | AI12: =AG12+AH12 -> 2338.3602 | AJ12: =P12+V12+W12+X12+Y12+AA12+AC12+AD12 -> 1068.81 | AK12: =J12*2% -> 46.2 | AL12: =AI12+AJ12+AK12 -> 3453.3702 | AM12: =AL12*16% -> 552.53923 | AN12: =AL12+AM12 -> 4005.9094
A13: SEI0017 | B13: Muñoz Reyes Luis Eduardo | C13: 15 | D13: 0 | E13: 266.67 | F13: 278.72 | G13: 4000.05 | H13: 0 | I13: 0 | J13: 4000.05 | K13: 15 | L13: 849.56 | M13: 0 | N13: 0 | O13: 313.87 | P13: 100.81 | Q13: 0 | R13: 0 | S13: 0.01 | T13: 1279.25 | U13: =+J13-T13 -> 2720.8 | V13: 73.16 | W13: 131.7 | X13: 335.88 | Y13: 273.62 | Z13: 80 | AA13: 33.3 | AB13: 540.74 | AC13: 209.04 | AD13: 231.81 | AE13: 110 | AF13: =((20/365.24)*15)*E13 -> 219.0368 | AG13: =U13+R13+K13+L13+M13+Q13 -> 3585.36 | AH13: =AG13*2% -> 71.7072 | AI13: =AG13+AH13 -> 3657.0672 | AJ13: =P13+V13+W13+X13+Y13+AA13+AC13+AD13 -> 1389.32 | AK13: =J13*2% -> 80.001 | AL13: =AI13+AJ13+AK13 -> 5126.3882 | AM13: =AL13*16% -> 820.22211 | AN13: =AL13+AM13 -> 5946.6103
A14: SEI0019 | B14: Gonzalez Rasgado Miguel Isaias | C14: 15 | D14: 0 | E14: 400 | F14: 424.2 | G14: 6000 | H14: 0 | I14: 0 | J14: 6000 | K14: 0 | L14: 0 | M14: 0 | N14: 0 | O14: 643.38 | P14: 161.36 | Q14: 0 | R14: 0 | S14: 0.06 | T14: 804.8 | U14: =+J14-T14 -> 5195.2 | V14: 111.35 | W14: 200.43 | X14: 398.06 | Y14: 317.26 | Z14: 120 | AA14: 50.69 | AB14: 709.84 | AC14: 318.15 | AD14: 253.63 | AE14: 110 | AF14: =((20/365.24)*15)*E14 -> 328.55109 | AG14: =U14+R14+K14+L14+M14+Q14 -> 5195.2 | AH14: =AG14*2% -> 103.904 | AI14: =AG14+AH14 -> 5299.104 | AJ14: =P14+V14+W14+X14+Y14+AA14+AC14+AD14 -> 1810.93 | AK14: =J14*2% -> 120 | AL14: =AI14+AJ14+AK14 -> 7230.034 | AM14: =AL14*16% -> 1156.8054 | AN14: =AL14+AM14 -> 8386.8394
A15: SEI0020 | B15: Mar Marquez Cesar Eduardo | C15: 15 | D15: 0 | E15: 266.67 | F15: 278.72 | G15: 4000.05 | H15: 0 | I15: 0 | J15: 4000.05 | K15: 0 | L15: 0 | M15: 0 | N15: 0 | O15: 313.87 | P15: 100.81 | Q15: 0 | R15: 0 | S15: -0.03 | T15: 414.65 | U15: =+J15-T15 -> 3585.4 | V15: 73.16 | W15: 131.7 | X15: 335.88 | Y15: 273.62 | Z15: 80 | AA15: 33.3 | AB15: 540.74 | AC15: 209.04 | AD15: 231.81 | AE15: 110 | AF15: =((20/365.24)*15)*E15 -> 219.0368 | AG15: =U15+R15+K15+L15+M15+Q15 -> 3585.4 | AH15: =AG15*2% -> 71.708 | AI15: =AG15+AH15 -> 3657.108 | AJ15: =P15+V15+W15+X15+Y15+AA15+AC15+AD15 -> 1389.32 | AK15: =J15*2% -> 80.001 | AL15: =AI15+AJ15+AK15 -> 5126.429 | AM15: =AL15*16% -> 820.22864 | AN15: =AL15+AM15 -> 5946.6576
A16: SEI0021 | B16: Velez Rodriguez Jaime | C16: 15 | D16: 0 | E16: 200 | F16: 212.1 | G16: 3000 | H16: 0 | I16: 0 | J16: 3000 | K16: 15 | L16: 1317.81 | M16: 0 | N16: 0 | O16: 59.69 | P16: 75.55 | Q16: 0 | R16: 0 | S16: -0.05 | T16: 1468 | U16: =+J16-T16 -> 1532 | V16: 55.68 | W16: 100.22 | X16: 314.22 | Y16: 253.63 | Z16: 60 | AA16: 25.34 | AB16: 470.12 | AC16: 159.08 | AD16: 221.82 | AE16: 110 | AF16: =((20/365.24)*15)*E16 -> 164.27554 | AG16: =U16+R16+K16+L16+M16+Q16 -> 2864.81 | AH16: =AG16*2% -> 57.2962 | AI16: =AG16+AH16 -> 2922.1062 | AJ16: =P16+V16+W16+X16+Y16+AA16+AC16+AD16 -> 1205.54 | AK16: =J16*2% -> 60 | AL16: =AI16+AJ16+AK16 -> 4187.6462 | AM16: =AL16*16% -> 670.02339 | AN16: =AL16+AM16 -> 4857.6696
A17: SEI0022 | B17: Najera Lopez Raul | C17: 15 | D17: 0 | E17: 333.33 | F17: 353.5 | G17: 4999.95 | H17: 0 | I17: 0 | J17: 4999.95 | K17: 0 | L17: 0 | M17: 0 | N17: 0 | O17: 461.63 | P17: 131.93 | Q17: 0 | R17: 0 | S17: -0.01 | T17: 593.55 | U17: =+J17-T17 -> 4406.4 | V17: 92.79 | W17: 167.03 | X17: 367.84 | Y17: 296.05 | Z17: 100 | AA17: 42.24 | AB17: 627.66 | AC17: 265.12 | AD17: 243.02 | AE17: 110 | AF17: =((20/365.24)*15)*E17 -> 273.78984 | AG17: =U17+R17+K17+L17+M17+Q17 -> 4406.4 | AH17: =AG17*2% -> 88.128 | AI17: =AG17+AH17 -> 4494.528 | AJ17: =P17+V17+W17+X17+Y17+AA17+AC17+AD17 -> 1606.02 | AK17: =J17*2% -> 99.999 | AL17: =AI17+AJ17+AK17 -> 6200.547 | AM17: =AL17*16% -> 992.08752 | AN17: =AL17+AM17 -> 7192.6345
A18: SEI0023 | B18: Puente Murguia Luis Felipe | C18: 15 | D18: 0 | E18: 233.33 | F18: 247.45 | G18: 3499.95 | H18: 0 | I18: 0 | J18: 3499.95 | K18: 0 | L18: 0 | M18: 0 | N18: 0 | O18: 134.36 | P18: 88.16 | Q18: 0 | R18: 0 | S18: 0.03 | T18: 222.55 | U18: =+J18-T18 -> 3277.4 | V18: 64.95 | W18: 116.92 | X18: 323.49 | Y18: 264.23 | Z18: 70 | AA18: 29.57 | AB18: 505.36 | AC18: 185.58 | AD18: 227.12 | AE18: 110 | AF18: =((20/365.24)*15)*E18 -> 191.65206 | AG18: =U18+R18+K18+L18+M18+Q18 -> 3277.4 | AH18: =AG18*2% -> 65.548 | AI18: =AG18+AH18 -> 3342.948 | AJ18: =P18+V18+W18+X18+Y18+AA18+AC18+AD18 -> 1300.02 | AK18: =J18*2% -> 69.999 | AL18: =AI18+AJ18+AK18 -> 4712.967 | AM18: =AL18*16% -> 754.07472 | AN18: =AL18+AM18 -> 5467.0417
A19: SEI0029 | B19: Arceo Garcia Manuel Federico | C19: 14 | D19: 1 | E19: 200 | F19: 212.1 | G19: 2800 | H19: 200 | I19: 60 | J19: 3060 | K19: 0 | L19: 0 | M19: 0 | N19: 0 | O19: 59.69 | P19: 75.55 | Q19: 600 | R19: 0 | S19: -0.04 | T19: 735.2 | U19: =+J19-T19 -> 2324.8 | V19: 55.68 | W19: 100.22 | X19: 314.22 | Y19: 253.63 | Z19: 61.2 | AA19: 25.34 | AB19: 470.12 | AC19: 159.08 | AD19: 221.82 | AE19: 110 | AF19: =((20/365.24)*15)*E19 -> 164.27554 | AG19: =U19+R19+K19+L19+M19+Q19 -> 2924.8 | AH19: =AG19*2% -> 58.496 | AI19: =AG19+AH19 -> 2983.296 | AJ19: =P19+V19+W19+X19+Y19+AA19+AC19+AD19 -> 1205.54 | AK19: =J19*2% -> 61.2 | AL19: =AI19+AJ19+AK19 -> 4250.036 | AM19: =AL19*16% -> 680.00576 | AN19: =AL19+AM19 -> 4930.0418
A20: SEI0364 | B20: Dominguez Lopez Mayeli Del Pilar | C20: 15 | D20: 0 | E20: 266.67 | F20: 282.81 | G20: 4000.05 | H20: 0 | I20: 0 | J20: 4000.05 | K20: 0 | L20: 0 | M20: 0 | N20: 0 | O20: 313.87 | P20: 102.51 | Q20: 0 | R20: 0 | S20: -0.13 | T20: 416.25 | U20: =+J20-T20 -> 3583.8 | V20: 74.24 | W20: 133.63 | X20: 337.62 | Y20: 274.84 | Z20: 80 | AA20: 33.79 | AB20: 545.49 | AC20: 212.11 | AD20: 232.42 | AE20: 110 | AF20: =((20/365.24)*15)*E20 -> 219.0368 | AG20: =U20+R20+K20+L20+M20+Q20 -> 3583.8 | AH20: =AG20*2% -> 71.676 | AI20: =AG20+AH20 -> 3655.476 | AJ20: =P20+V20+W20+X20+Y20+AA20+AC20+AD20 -> 1401.16 | AK20: =J20*2% -> 80.001 | AL20: =AI20+AJ20+AK20 -> 5136.637 | AM20: =AL20*16% -> 821.86192 | AN20: =AL20+AM20 -> 5958.4989
... A64: SEI0506 | B64: Mejia Duarte Jose Luis | C64: 15 | D64: 0 | E64: 166.67 | F64: 176.76 | G64: 2500.05 | H64: 0 | I64: 0 | J64: 2500.05 | K64: 0 | L64: 0 | M64: 0 | N64: -9.62 | O64: 0 | P64: 62.97 | Q64: 0 | R64: 0 | S64: 0.1 | T64: 53.45 | U64: =+J64-T64 -> 2446.6 | V64: 46.4 | W64: 83.52 | X64: 304.94 | Y64: 243.03 | Z64: 50 | AA64: 21.12 | AB64: 434.86 | AC64: 132.57 | AD64: 216.51 | AE64: 110 | AF64: =((20/365.24)*15)*E64 -> 136.89903 | AG64: =U64+R64+K64+L64+M64+Q64 -> 2446.6 | AH64: =AG64*2% -> 48.932 | AI64: =AG64+AH64 -> 2495.532 | AJ64: =P64+V64+W64+X64+Y64+AA64+AC64+AD64 -> 1111.06 | AK64: =J64*2% -> 50.001 | AL64: =AI64+AJ64+AK64 -> 3656.593 | AM64: =AL64*16% -> 585.05488 | AN64: =AL64+AM64 -> 4241.6479
A65: SEI0508 | B65: Cerro Garcia Elvis | C65: 15 | D65: 0 | E65: 166.67 | F65: 177.03 | G65: 2500.05 | H65: 0 | I65: 0 | J65: 2500.05 | K65: 0 | L65: 0 | M65: 0 | N65: -9.62 | O65: 0 | P65: 63.07 | Q65: 0 | R65: 0 | S65: - | T65: 53.45 | U65: =+J65-T65 -> 2446.6 | V65: 46.47 | W65: 83.65 | X65: 305.01 | Y65: 243.11 | Z65: 50 | AA65: 21.15 | AB65: 435.13 | AC65: 132.77 | AD65: 216.55 | AE65: 110 | AF65: =((20/365.24)*15)*E65 -> 136.89903 | AG65: =U65+R65+K65+L65+M65+Q65 -> 2446.6 | AH65: =AG65*2% -> 48.932 | AI65: =AG65+AH65 -> 2495.532 | AJ65: =P65+V65+W65+X65+Y65+AA65+AC65+AD65 -> 1111.78 | AK65: =J65*2% -> 50.001 | AL65: =AI65+AJ65+AK65 -> 3657.313 | AM65: =AL65*16% -> 585.17008 | AN65: =AL65+AM65 -> 4242.4831
A66: SEI0509 | B66: Gutierrez Castillo Jose De Jesus | C66: 15 | D66: 0 | E66: 200 | F66: 209.04 | G66: 3000 | H66: 0 | I66: 0 | J66: 3000 | K66: 0 | L66: 0 | M66: 0 | N66: 0 | O66: 59.69 | P66: 74.48 | Q66: 0 | R66: 0 | S66: 0.03 | T66: 134.2 | U66: =+J66-T66 -> 2865.8 | V66: 54.87 | W66: 98.77 | X66: 313.41 | Y66: 252.71 | Z66: 60 | AA66: 24.98 | AB66: 467.05 | AC66: 156.78 | AD66: 221.36 | AE66: 110 | AF66: =((20/365.24)*15)*E66 -> 164.27554 | AG66: =U66+R66+K66+L66+M66+Q66 -> 2865.8 | AH66: =AG66*2% -> 57.316 | AI66: =AG66+AH66 -> 2923.116 | AJ66: =P66+V66+W66+X66+Y66+AA66+AC66+AD66 -> 1197.36 | AK66: =J66*2% -> 60 | AL66: =AI66+AJ66+AK66 -> 4180.476 | AM66: =AL66*16% -> 668.87616 | AN66: =AL66+AM66 -> 4849.3522
A67: SEI0511 | B67: Lizaran Maceda Jose Guadalupe | C67: 15 | D67: 0 | E67: 166.67 | F67: 175.8 | G67: 2500.05 | H67: 0 | I67: 0 | J67: 2500.05 | K67: 0 | L67: 0 | M67: 0 | N67: -9.62 | O67: 0 | P67: 62.63 | Q67: 0 | R67: 0 | S67: -0.16 | T67: 52.85 | U67: =+J67-T67 -> 2447.2 | V67: 46.15 | W67: 83.07 | X67: 304.69 | Y67: 242.74 | Z67: 50 | AA67: 21.01 | AB67: 433.91 | AC67: 131.85 | AD67: 216.37 | AE67: 110 | AF67: =((20/365.24)*15)*E67 -> 136.89903 | AG67: =U67+R67+K67+L67+M67+Q67 -> 2447.2 | AH67: =AG67*2% -> 48.944 | AI67: =AG67+AH67 -> 2496.144 | AJ67: =P67+V67+W67+X67+Y67+AA67+AC67+AD67 -> 1108.51 | AK67: =J67*2% -> 50.001 | AL67: =AI67+AJ67+AK67 -> 3654.655 | AM67: =AL67*16% -> 584.7448 | AN67: =AL67+AM67 -> 4239.3998
A68: SEI0513 | B68: Mendez Rivera Ivan Israel | C68: 15 | D68: 0 | E68: 166.66 | F68: 174.19 | G68: 2499.9 | H68: 0 | I68: 0 | J68: 2499.9 | K68: 15 | L68: 398.9 | M68: 0 | N68: -9.64 | O68: 0 | P68: 62.06 | Q68: 0 | R68: 0 | S68: -0.02 | T68: 466.3 | U68: =+J68-T68 -> 2033.6 | V68: 45.73 | W68: 82.31 | X68: 304.27 | Y68: 242.26 | Z68: 50 | AA68: 20.81 | AB68: 432.31 | AC68: 130.65 | AD68: 216.13 | AE68: 110 | AF68: =((20/365.24)*15)*E68 -> 136.89081 | AG68: =U68+R68+K68+L68+M68+Q68 -> 2447.5 | AH68: =AG68*2% -> 48.95 | AI68: =AG68+AH68 -> 2496.45 | AJ68: =P68+V68+W68+X68+Y68+AA68+AC68+AD68 -> 1104.22 | AK68: =J68*2% -> 49.998 | AL68: =AI68+AJ68+AK68 -> 3650.668 | AM68: =AL68*16% -> 584.10688 | AN68: =AL68+AM68 -> 4234.7749
A69: SEI0517 | B69: Macias Torres Enrique | C69: 15 | D69: 0 | E69: 256.67 | F69: 272.21 | G69: 3850.05 | H69: 0 | I69: 0 | J69: 3850.05 | K69: 0 | L69: 0 | M69: 0 | N69: 0 | O69: 297.55 | P69: 98.1 | Q69: 0 | R69: 0 | S69: - | T69: 395.65 | U69: =+J69-T69 -> 3454.4 | V69: 71.46 | W69: 128.62 | X69: 333.08 | Y69: 271.66 | Z69: 77 | AA69: 32.53 | AB69: 533.16 | AC69: 204.16 | AD69: 230.83 | AE69: 110 | AF69: =((20/365.24)*15)*E69 -> 210.82302 | AG69: =U69+R69+K69+L69+M69+Q69 -> 3454.4 | AH69: =AG69*2% -> 69.088 | AI69: =AG69+AH69 -> 3523.488 | AJ69: =P69+V69+W69+X69+Y69+AA69+AC69+AD69 -> 1370.44 | AK69: =J69*2% -> 77.001 | AL69: =AI69+AJ69+AK69 -> 4970.929 | AM69: =AL69*16% -> 795.34864 | AN69: =AL69+AM69 -> 5766.2776
A70: SEI0519 | B70: Palacios Vega Luis Rosendo | C70: 15 | D70: 0 | E70: 166.67 | F70: 174.2 | G70: 2500.05 | H70: 0 | I70: 0 | J70: 2500.05 | K70: 0 | L70: 0 | M70: 0 | N70: -9.62 | O70: 0 | P70: 62.06 | Q70: 0 | R70: 0 | S70: 0.01 | T70: 52.45 | U70: =+J70-T70 -> 2447.6 | V70: 45.73 | W70: 82.31 | X70: 304.27 | Y70: 242.26 | Z70: 50 | AA70: 20.82 | AB70: 432.31 | AC70: 130.65 | AD70: 216.13 | AE70: 110 | AF70: =((20/365.24)*15)*E70 -> 136.89903 | AG70: =U70+R70+K70+L70+M70+Q70 -> 2447.6 | AH70: =AG70*2% -> 48.952 | AI70: =AG70+AH70 -> 2496.552 | AJ70: =P70+V70+W70+X70+Y70+AA70+AC70+AD70 -> 1104.23 | AK70: =J70*2% -> 50.001 | AL70: =AI70+AJ70+AK70 -> 3650.783 | AM70: =AL70*16% -> 584.12528 | AN70: =AL70+AM70 -> 4234.9083
A71: SEI0521 | B71: Rondero Savin Jacinto | C71: 15 | D71: 0 | E71: 233.33 | F71: 243.88 | G71: 3499.95 | H71: 0 | I71: 0 | J71: 3499.95 | K71: 0 | L71: 0 | M71: 0 | N71: 0 | O71: 134.36 | P71: 86.88 | Q71: 0 | R71: 0 | S71: -0.09 | T71: 221.15 | U71: =+J71-T71 -> 3278.8 | V71: 64.02 | W71: 115.23 | X71: 322.56 | Y71: 263.16 | Z71: 70 | AA71: 29.14 | AB71: 501.81 | AC71: 182.91 | AD71: 226.58 | AE71: 110 | AF71: =((20/365.24)*15)*E71 -> 191.65206 | AG71: =U71+R71+K71+L71+M71+Q71 -> 3278.8 | AH71: =AG71*2% -> 65.576 | AI71: =AG71+AH71 -> 3344.376 | AJ71: =P71+V71+W71+X71+Y71+AA71+AC71+AD71 -> 1290.48 | AK71: =J71*2% -> 69.999 | AL71: =AI71+AJ71+AK71 -> 4704.855 | AM71: =AL71*16% -> 752.7768 | AN71: =AL71+AM71 -> 5457.6318
A72: SEI0523 | B72: Hernandez Rodriguez Jorge | C72: 15 | D72: 0 | E72: 233.33 | F72: 247.46 | G72: 3499.95 | H72: 0 | I72: 0 | J72: 3499.95 | K72: 15 | L72: 1401.51 | M72: 0 | N72: 0 | O72: 134.36 | P72: 88.16 | Q72: 0 | R72: 0 | S72: 0.12 | T72: 1639.15 | U72: =+J72-T72 -> 1860.8 | V72: 64.96 | W72: 116.92 | X72: 323.5 | Y72: 264.24 | Z72: 70 | AA72: 29.57 | AB72: 505.38 | AC72: 185.6 | AD72: 227.12 | AE72: 110 | AF72: =((20/365.24)*15)*E72 -> 191.65206 | AG72: =U72+R72+K72+L72+M72+Q72 -> 3277.31 | AH72: =AG72*2% -> 65.5462 | AI72: =AG72+AH72 -> 3342.8562 | AJ72: =P72+V72+W72+X72+Y72+AA72+AC72+AD72 -> 1300.07 | AK72: =J72*2% -> 69.999 | AL72: =AI72+AJ72+AK72 -> 4712.9252 | AM72: =AL72*16% -> 754.06803 | AN72: =AL72+AM72 -> 5466.9932
A73: SEI0524 | B73: Orea Gonzalez Concepcion Esteban | C73: 15 | D73: 0 | E73: 210 | F73: 222.72 | G73: 3150 | H73: 0 | I73: 0 | J73: 3150 | K73: 0 | L73: 0 | M73: 0 | N73: 0 | O73: 96.29 | P73: 79.34 | Q73: 0 | R73: 0 | S73: 0.17 | T73: 175.8 | U73: =+J73-T73 -> 2974.2 | V73: 58.46 | W73: 105.24 | X73: 317.01 | Y73: 256.82 | Z73: 63 | AA73: 26.61 | AB73: 480.71 | AC73: 167.04 | AD73: 223.41 | AE73: 110 | AF73: =((20/365.24)*15)*E73 -> 172.48932 | AG73: =U73+R73+K73+L73+M73+Q73 -> 2974.2 | AH73: =AG73*2% -> 59.484 | AI73: =AG73+AH73 -> 3033.684 | AJ73: =P73+V73+W73+X73+Y73+AA73+AC73+AD73 -> 1233.93 | AK73: =J73*2% -> 63 | AL73: =AI73+AJ73+AK73 -> 4330.614 | AM73: =AL73*16% -> 692.89824 | AN73: =AL73+AM73 -> 5023.5122
A74: SEI0525 | B74: Lizaran Maceda Jesus | C74: 15 | D74: 0 | E74: 210 | F74: 222.72 | G74: 3150 | H74: 0 | I74: 0 | J74: 3150 | K74: 15 | L74: 0 | M74: 303.54 | N74: 0 | O74: 96.29 | P74: 79.34 | Q74: 0 | R74: 0 | S74: 0.03 | T74: 494.2 | U74: =+J74-T74 -> 2655.8 | V74: 58.46 | W74: 105.24 | X74: 317.01 | Y74: 256.82 | Z74: 63 | AA74: 26.61 | AB74: 480.71 | AC74: 167.04 | AD74: 223.41 | AE74: 110 | AF74: =((20/365.24)*15)*E74 -> 172.48932 | AG74: =U74+R74+K74+L74+M74+Q74 -> 2974.34 | AH74: =AG74*2% -> 59.4868 | AI74: =AG74+AH74 -> 3033.8268 | AJ74: =P74+V74+W74+X74+Y74+AA74+AC74+AD74 -> 1233.93 | AK74: =J74*2% -> 63 | AL74: =AI74+AJ74+AK74 -> 4330.7568 | AM74: =AL74*16% -> 692.92109 | AN74: =AL74+AM74 -> 5023.6779
A75: SEI0527 | B75: Alejandro Peña Deivi | C75: 15 | D75: 0 | E75: 210 | F75: 222.72 | G75: 3150 | H75: 0 | I75: 0 | J75: 3150 | K75: 0 | L75: 0 | M75: 0 | N75: 0 | O75: 96.29 | P75: 79.34 | Q75: 0 | R75: 0 | S75: -0.03 | T75: 175.6 | U75: =+J75-T75 -> 2974.4 | V75: 58.46 | W75: 105.24 | X75: 317.01 | Y75: 256.82 | Z75: 63 | AA75: 26.61 | AB75: 480.71 | AC75: 167.04 | AD75: 223.41 | AE75: 110 | AF75: =((20/365.24)*15)*E75 -> 172.48932 | AG75: =U75+R75+K75+L75+M75+Q75 -> 2974.4 | AH75: =AG75*2% -> 59.488 | AI75: =AG75+AH75 -> 3033.888 | AJ75: =P75+V75+W75+X75+Y75+AA75+AC75+AD75 -> 1233.93 | AK75: =J75*2% -> 63 | AL75: =AI75+AJ75+AK75 -> 4330.818 | AM75: =AL75*16% -> 692.93088 | AN75: =AL75+AM75 -> 5023.7489
A76: SEI0528 | B76: Casas Chavarria Rafael | C76: 15 | D76: 0 | E76: 210 | F76: 222.72 | G76: 3150 | H76: 0 | I76: 0 | J76: 3150 | K76: 15 | L76: 0 | M76: 942.33 | N76: 0 | O76: 96.29 | P76: 79.34 | Q76: 0 | R76: 0 | S76: 0.04 | T76: 1133 | U76: =+J76-T76 -> 2017 | V76: 58.46 | W76: 105.24 | X76: 317.01 | Y76: 256.82 | Z76: 63 | AA76: 26.61 | AB76: 480.71 | AC76: 167.04 | AD76: 223.41 | AE76: 110 | AF76: =((20/365.24)*15)*E76 -> 172.48932 | AG76: =U76+R76+K76+L76+M76+Q76 -> 2974.33 | AH76: =AG76*2% -> 59.4866 | AI76: =AG76+AH76 -> 3033.8166 | AJ76: =P76+V76+W76+X76+Y76+AA76+AC76+AD76 -> 1233.93 | AK76: =J76*2% -> 63 | AL76: =AI76+AJ76+AK76 -> 4330.7466 | AM76: =AL76*16% -> 692.91946 | AN76: =AL76+AM76 -> 5023.6661
A77: SEI0530 | B77: Del Pilar Mendez Lucio | C77: 15 | D77: 0 | E77: 200 | F77: 209.04 | G77: 3000 | H77: 0 | I77: 0 | J77: 3000 | K77: 15 | L77: 0 | M77: 1575.59 | N77: 0 | O77: 59.69 | P77: 74.48 | Q77: 0 | R77: 0 | S77: 0.04 | T77: 1724.8 | U77: =+J77-T77 -> 1275.2 | V77: 54.87 | W77: 98.77 | X77: 313.41 | Y77: 252.71 | Z77: 60 | AA77: 24.98 | AB77: 467.05 | AC77: 156.78 | AD77: 221.36 | AE77: 110 | AF77: =((20/365.24)*15)*E77 -> 164.27554 | AG77: =U77+R77+K77+L77+M77+Q77 -> 2865.79 | AH77: =AG77*2% -> 57.3158 | AI77: =AG77+AH77 -> 2923.1058 | AJ77: =P77+V77+W77+X77+Y77+AA77+AC77+AD77 -> 1197.36 | AK77: =J77*2% -> 60 | AL77: =AI77+AJ77+AK77 -> 4180.4658 | AM77: =AL77*16% -> 668.87453 | AN77: =AL77+AM77 -> 4849.3403
A78: SEI0534 | B78: Gonzalez Ramirez Paul | C78: 15 | D78: 0 | E78: 200 | F78: 209.04 | G78: 3000 | H78: 0 | I78: 0 | J78: 3000 | K78: 0 | L78: 0 | M78: 0 | N78: 0 | O78: 59.69 | P78: 74.48 | Q78: 0 | R78: 0 | S78: 0.03 | T78: 134.2 | U78: =+J78-T78 -> 2865.8 | V78: 54.87 | W78: 98.77 | X78: 313.41 | Y78: 252.71 | Z78: 60 | AA78: 24.98 | AB78: 467.05 | AC78: 156.78 | AD78: 221.36 | AE78: 110 | AF78: =((20/365.24)*15)*E78 -> 164.27554 | AG78: =U78+R78+K78+L78+M78+Q78 -> 2865.8 | AH78: =AG78*2% -> 57.316 | AI78: =AG78+AH78 -> 2923.116 | AJ78: =P78+V78+W78+X78+Y78+AA78+AC78+AD78 -> 1197.36 | AK78: =J78*2% -> 60 | AL78: =AI78+AJ78+AK78 -> 4180.476 | AM78: =AL78*16% -> 668.87616 | AN78: =AL78+AM78 -> 4849.3522
A79: SEI0535 | B79: Alejandro Vazquez Erasmo Miguel | C79: 15 | D79: 0 | E79: 200 | F79: 212.11 | G79: 3000 | H79: 0 | I79: 0 | J79: 3000 | K79: 15 | L79: 0 | M79: 466.28 | N79: 0 | O79: 59.69 | P79: 75.56 | Q79: 0 | R79: 0 | S79: 0.07 | T79: 616.6 | U79: =+J79-T79 -> 2383.4 | V79: 55.68 | W79: 100.22 | X79: 314.22 | Y79: 253.63 | Z79: 60 | AA79: 25.34 | AB79: 470.12 | AC79: 159.08 | AD79: 221.82 | AE79: 110 | AF79: =((20/365.24)*15)*E79 -> 164.27554 | AG79: =U79+R79+K79+L79+M79+Q79 -> 2864.68 | AH79: =AG79*2% -> 57.2936 | AI79: =AG79+AH79 -> 2921.9736 | AJ79: =P79+V79+W79+X79+Y79+AA79+AC79+AD79 -> 1205.55 | AK79: =J79*2% -> 60 | AL79: =AI79+AJ79+AK79 -> 4187.5236 | AM79: =AL79*16% -> 670.00378 | AN79: =AL79+AM79 -> 4857.5274
A80: SEI0536 | B80: Hernandez Ojeda Julio Cesar | C80: 15 | D80: 0 | E80: 116.67 | F80: 123.73 | G80: 1750.05 | H80: 0 | I80: 0 | J80: 1750.05 | K80: 15 | L80: 0 | M80: 836.5 | N80: -89.5 | O80: 0 | P80: 44.08 | Q80: 0 | R80: 0 | S80: -0.03 | T80: 806.05 | U80: =+J80-T80 -> 944 | V80: 32.48 | W80: 58.46 | X80: 291.02 | Y80: 227.12 | Z80: 35 | AA80: 14.78 | AB80: 381.96 | AC80: 92.8 | AD80: 208.56 | AE80: 110 | AF80: =((20/365.24)*15)*E80 -> 95.830139 | AG80: =U80+R80+K80+L80+M80+Q80 -> 1795.5 | AH80: =AG80*2% -> 35.91 | AI80: =AG80+AH80 -> 1831.41 | AJ80: =P80+V80+W80+X80+Y80+AA80+AC80+AD80 -> 969.3 | AK80: =J80*2% -> 35.001 | AL80: =AI80+AJ80+AK80 -> 2835.711 | AM80: =AL80*16% -> 453.71376 | AN80: =AL80+AM80 -> 3289.4248
A81: SEI0537 | B81: Serrano Esquivel Armando | C81: 15 | D81: 0 | E81: 116.67 | F81: 123.73 | G81: 1750.05 | H81: 0 | I81: 0 | J81: 1750.05 | K81: 15 | L81: 721.52 | M81: 0 | N81: -89.5 | O81: 0 | P81: 44.08 | Q81: 0 | R81: 0 | S81: -0.05 | T81: 691.05 | U81: =+J81-T81 -> 1059 | V81: 32.48 | W81: 58.46 | X81: 291.02 | Y81: 227.12 | Z81: 35 | AA81: 14.78 | AB81: 381.96 | AC81: 92.8 | AD81: 208.56 | AE81: 110 | AF81: =((20/365.24)*15)*E81 -> 95.830139 | AG81: =U81+R81+K81+L81+M81+Q81 -> 1795.52 | AH81: =AG81*2% -> 35.9104 | AI81: =AG81+AH81 -> 1831.4304 | AJ81: =P81+V81+W81+X81+Y81+AA81+AC81+AD81 -> 969.3 | AK81: =J81*2% -> 35.001 | AL81: =AI81+AJ81+AK81 -> 2835.7314 | AM81: =AL81*16% -> 453.71702 | AN81: =AL81+AM81 -> 3289.4484
... A87: SEI0547 | B87: Aguilar Garcia Rosa Paola | C87: 15 | D87: 0 | E87: 166.67 | F87: 176.76 | G87: 2500.05 | H87: 0 | I87: 0 | J87: 2500.05 | K87: 0 | L87: 0 | M87: 0 | N87: -9.62 | O87: 0 | P87: 62.97 | Q87: 0 | R87: 0 | S87: 0.1 | T87: 53.45 | U87: =+J87-T87 -> 2446.6 | V87: 46.4 | W87: 83.52 | X87: 304.94 | Y87: 243.03 | Z87: 50 | AA87: 21.12 | AB87: 434.86 | AC87: 132.57 | AD87: 216.51 | AE87: 110 | AF87: =((20/365.24)*15)*E87 -> 136.89903 | AG87: =U87+R87+K87+L87+M87+Q87 -> 2446.6 | AH87: =AG87*2% -> 48.932 | AI87: =AG87+AH87 -> 2495.532 | AJ87: =P87+V87+W87+X87+Y87+AA87+AC87+AD87 -> 1111.06 | AK87: =J87*2% -> 50.001 | AL87: =AI87+AJ87+AK87 -> 3656.593 | AM87: =AL87*16% -> 585.05488 | AN87: =AL87+AM87 -> 4241.6479
A88: SEI0548 | B88: Jauregui Madera Jorge Silvestre | C88: 14 | D88: 0 | E88: 200 | F88: 209.04 | G88: 2800 | H88: 0 | I88: 0 | J88: =+G88 -> 2800 | K88: 0 | L88: 0 | M88: 0 | N88: 0 | O88: 37.93 | P88: 70.81 | Q88: 0 | R88: 0 | S88: 0.06 | T88: 108.8 | U88: =+J88-T88 -> 2691.2 | V88: 54.87 | W88: 98.77 | X88: 313.41 | Y88: 252.71 | Z88: 60 | AA88: 24.98 | AB88: 467.05 | AC88: 156.78 | AD88: 221.36 | AE88: 110 | AF88: =((20/365.24)*15)*E88 -> 164.27554 | AG88: =U88+R88+K88+L88+M88+Q88 -> 2691.2 | AH88: =AG88*2% -> 53.824 | AI88: =AG88+AH88 -> 2745.024 | AJ88: =P88+V88+W88+X88+Y88+AA88+AC88+AD88 -> 1193.69 | AK88: =J88*2% -> 56 | AL88: =AI88+AJ88+AK88 -> 3994.714 | AM88: =AL88*16% -> 639.15424 | AN88: =AL88+AM88 -> 4633.8682
A89: SEI0549 | B89: Hinojosa Guerrero Alejandro | C89: 3 | D89: 0 | E89: 210 | F89: 219.83 | G89: 630 | H89: 0 | I89: 0 | J89: 630 | K89: 0 | L89: 0 | M89: 0 | N89: -173.3 | O89: 0 | P89: 15.66 | Q89: 0 | R89: 0 | S89: 0.04 | T89: -157.6 | U89: =+J89-T89 -> 787.6 | V89: 11.54 | W89: 20.77 | X89: 63.25 | Y89: 203.19 | Z89: 12.6 | AA89: 5.25 | AB89: 95.56 | AC89: 32.97 | AD89: 196.59 | AE89: 0 | AF89: =((20/365.24)*15)*E89 -> 172.48932 | AG89: =U89+R89+K89+L89+M89+Q89 -> 787.6 | AH89: =AG89*2% -> 15.752 | AI89: =AG89+AH89 -> 803.352 | AJ89: =P89+V89+W89+X89+Y89+AA89+AC89+AD89 -> 549.22 | AK89: =J89*2% -> 12.6 | AL89: =AI89+AJ89+AK89 -> 1365.172 | AM89: =AL89*16% -> 218.42752 | AN89: =AL89+AM89 -> 1583.5995
A90: SEI479 | B90: Cruz Perez Alejandro Nezahualcoyotl | C90: 15 | D90: 0 | E90: 266.67 | F90: 282.81 | G90: 4000.05 | H90: 0 | I90: 0 | J90: 4000.05 | K90: 0 | L90: 0 | M90: 0 | N90: 0 | O90: 313.87 | P90: 102.51 | Q90: 0 | R90: 0 | S90: -0.13 | T90: 416.25 | U90: =+J90-T90 -> 3583.8 | V90: 74.24 | W90: 133.63 | X90: 337.62 | Y90: 274.84 | Z90: 80 | AA90: 33.79 | AB90: 545.49 | AC90: 212.11 | AD90: 232.42 | AE90: 110 | AF90: =((20/365.24)*15)*E90 -> 219.0368 | AG90: =U90+R90+K90+L90+M90+Q90 -> 3583.8 | AH90: =AG90*2% -> 71.676 | AI90: =AG90+AH90 -> 3655.476 | AJ90: =P90+V90+W90+X90+Y90+AA90+AC90+AD90 -> 1401.16 | AK90: =J90*2% -> 80.001 | AL90: =AI90+AJ90+AK90 -> 5136.637 | AM90: =AL90*16% -> 821.86192 | AN90: =AL90+AM90 -> 5958.4989
...

Sheet SIND PITS
D1: SINDICATO | J1: PRIMA VACACIONAL
A2: CLAVE | B2: EMPRESA | C2: NOMBRE | D2: SUELDO SINDICATO | E2: BONO | F2: COMISION | G2: prima vacaciones | H2: TOTAL | J2: DIAS DE VACACIONES | K2: SUELDO NETO MENSUAL | L2: MONTO PRIMA TOTAL | M2: MENOS PRIMA IMSS | N2: PRIMA A PAGAR SINDICATO | P2: comision | Q2: subtotal | R2: iva
A3: SEI0097 | B3: CONSULTORIA | C3: Arreola Jimenez Jose Nieves | D3: 1557.96 | E3: 420 | F3: 320 | G3: =+N3 -> 91.5 | H3: =SUM(D3:G3) -> 2389.46 | J3: =VLOOKUP($C3,'CPD PITSS'!$B$9:$V$26,3,0) -> 2 | K3: 10150 | L3: =(((+K3/30)*J3)*30%) -> 203 | M3: =VLOOKUP($C3,'CPD PITSS'!$B$9:$V$26,8,0) -> 111.5 | N3: =+L3-M3 -> 91.5 | O3: SEI0097 | P3: =H3*2% -> 47.7892 | Q3: =H3+P3 -> 2437.2492 | R3: =Q3*16% -> 389.95987
A4: SEI0118 | B4: CONSULTORIA | C4: Arroyo Ramirez Hector Hugo | D4: 2104.9 | G4: =+N4 -> 281.67 | H4: =SUM(D4:G4) -> 2386.57 | J4: 4 | K4: 13000 | L4: =(((+K4/30)*J4)*30%) -> 520 | M4: =VLOOKUP($C4,'CPD PITSS'!$B$9:$V$26,8,0) -> 238.33 | N4: =+L4-M4 -> 281.67 | O4: SEI0118 | P4: =H4*2% -> 47.7314 | Q4: =H4+P4 -> 2434.3014 | R4: =Q4*16% -> 389.48822
A5: SEI0377 | B5: CONSULTORIA | C5: Benavides Herrera Alejandra | D5: 16803.4 | G5: =+N5 -> 0 | H5: =SUM(D5:G5) -> 16803.4 | J5: =VLOOKUP(C5,'CPD PITSS'!$B$9:$V$26,3,0) -> 0 | K5: 40000 | L5: =(((+K5/30)*J5)*30%) -> 0 | M5: =VLOOKUP($C5,'CPD PITSS'!$B$9:$V$26,8,0) -> 0 | N5: =+L5-M5 -> 0 | O5: SEI0377 | P5: =H5*2% -> 336.068 | Q5: =H5+P5 -> 17139.468 | R5: =Q5*16% -> 2742.3149
A6: SEI0108 | B6: CONSULTORIA | C6: Caballero Diaz Francisco Javier | D6: 1558.09 | E6: 330 | F6: 320 | G6: =+N6 -> 0 | H6: =SUM(D6:G6) -> 2208.09 | J6: =VLOOKUP(C6,'CPD PITSS'!$B$9:$V$26,3,0) -> 0 | K6: 10150 | L6: =(((+K6/30)*J6)*30%) -> 0 | M6: =VLOOKUP($C6,'CPD PITSS'!$B$9:$V$26,8,0) -> 0 | N6: =+L6-M6 -> 0 | O6: SEI0108 | P6: =H6*2% -> 44.1618 | Q6: =H6+P6 -> 2252.2518 | R6: =Q6*16% -> 360.36029
A7: SEI0425 | B7: CONSULTORIA | C7: Carbajal Cabuto Jose Luis | D7: 1608.1 | E7: 270 | G7: =+N7 -> 0 | H7: =SUM(D7:G7) -> 1878.1 | J7: =VLOOKUP(C7,'CPD PITSS'!$B$9:$V$26,3,0) -> 0 | K7: 10250 | L7: =(((+K7/30)*J7)*30%) -> 0 | M7: =VLOOKUP($C7,'CPD PITSS'!$B$9:$V$26,8,0) -> 0 | N7: =+L7-M7 -> 0 | O7: SEI0453 | P7: =H7*2% -> 37.562 | Q7: =H7+P7 -> 1915.662 | R7: =Q7*16% -> 306.50592
A8: SEI0116 | B8: CONSULTORIA | C8: Casillas Cardona Cesar Alejandro | D8: 1891.2 | G8: =+N8 -> 0 | H8: =SUM(D8:G8) -> 1891.2 | J8: =VLOOKUP(C8,'CPD PITSS'!$B$9:$V$26,3,0) -> 0 | K8: 12000 | L8: =(((+K8/30)*J8)*30%) -> 0 | M8: =VLOOKUP($C8,'CPD PITSS'!$B$9:$V$26,8,0) -> 0 | N8: =+L8-M8 -> 0 | O8: SEI0116 | P8: =H8*2% -> 37.824 | Q8: =H8+P8 -> 1929.024 | R8: =Q8*16% -> 308.64384
A9: SEI0401 | B9: CONSULTORIA | C9: De La Torre Zambara Francisco Ernesto | D9: 1558 | E9: 270 | F9: 320 | G9: =+N9 -> 91.5 | H9: =SUM(D9:G9) -> 2239.5 | J9: =VLOOKUP(C9,'CPD PITSS'!$B$9:$V$26,3,0) -> 2 | K9: 10150 | L9: =(((+K9/30)*J9)*30%) -> 203 | M9: =VLOOKUP($C9,'CPD PITSS'!$B$9:$V$26,8,0) -> 111.5 | N9: =+L9-M9 -> 91.5 | O9: SEI0401 | P9: =H9*2% -> 44.79 | Q9: =H9+P9 -> 2284.29 | R9: =Q9*16% -> 365.4864
A10: SEI0099 | B10: CONSULTORIA | C10: Garcia Villicaña Ricardo Pascual | D10: 2600.37 | E10: 150 | G10: =+N10 -> 0 | H10: =SUM(D10:G10) -> 2750.37 | J10: =VLOOKUP(C10,'CPD PITSS'!$B$9:$V$26,3,0) -> 0 | K10: 15000 | L10: =(((+K10/30)*J10)*30%) -> 0 | M10: =VLOOKUP($C10,'CPD PITSS'!$B$9:$V$26,8,0) -> 0 | N10: =+L10-M10 -> 0 | O10: SEI0099 | P10: =H10*2% -> 55.0074 | Q10: =H10+P10 -> 2805.3774 | R10: =Q10*16% -> 448.86038
A11: SEI0009 | B11: CONSULTORIA | C11: Gutierrez Gutierrez Luis Arturo | D11: 1475.4 | E11: 100 | G11: =+N11 -> 0 | H11: =SUM(D11:G11) -> 1575.4 | J11: =VLOOKUP(C11,'CPD PITSS'!$B$9:$V$26,3,0) -> 0 | K11: 8500 | L11: =(((+K11/30)*J11)*30%) -> 0 | M11: =VLOOKUP($C11,'CPD PITSS'!$B$9:$V$26,8,0) -> 0 | N11: =+L11-M11 -> 0 | O11: SEI0009 | P11: =H11*2% -> 31.508 | Q11: =H11+P11 -> 1606.908 | R11: =Q11*16% -> 257.10528
A12: SEI0127 | B12: CONSULTORIA | C12: Hernandez Ochoa Eduardo | D12: 2600.2 | E12: 337.5 | G12: =+N12 -> 0 | H12: =SUM(D12:G12) -> 2937.7 | J12: =VLOOKUP(C12,'CPD PITSS'!$B$9:$V$26,3,0) -> 0 | K12: 15000 | L12: =(((+K12/30)*J12)*30%) -> 0 | M12: =VLOOKUP($C12,'CPD PITSS'!$B$9:$V$26,8,0) -> 0 | N12: =+L12-M12 -> 0 | O12: SEI0127 | P12: =H12*2% -> 58.754 | Q12: =H12+P12 -> 2996.454 | R12: =Q12*16% -> 479.43264
A13: SEI0117 | B13: CONSULTORIA | C13: Mariscal Romero Luis Adrian | D13: 2751 | E13: 165 | G13: =+N13 -> 0 | H13: =SUM(D13:G13) -> 2916 | J13: =VLOOKUP(C13,'CPD PITSS'!$B$9:$V$26,3,0) -> 0 | K13: 15000 | L13: =(((+K13/30)*J13)*30%) -> 0 | M13: =VLOOKUP($C13,'CPD PITSS'!$B$9:$V$26,8,0) -> 0 | N13: =+L13-M13 -> 0 | O13: SEI0117 | P13: =H13*2% -> 58.32 | Q13: =H13+P13 -> 2974.32 | R13: =Q13*16% -> 475.8912
A14: SEI0040 | B14: CONSULTORIA | C14: Mora Ramirez Acal Aldo Isidro | D14: 2464 | E14: 1000 | G14: =+N14 -> 0 | H14: =SUM(D14:G14) -> 3464 | J14: =VLOOKUP(C14,'CPD PITSS'!$B$9:$V$26,3,0) -> 0 | K14: 13000 | L14: =(((+K14/30)*J14)*30%) -> 0 | M14: =VLOOKUP($C14,'CPD PITSS'!$B$9:$V$26,8,0) -> 0 | N14: =+L14-M14 -> 0 | O14: SEI0040 | P14: =H14*2% -> 69.28 | Q14: =H14+P14 -> 3533.28 | R14: =Q14*16% -> 565.3248
A15: SEI0088 | B15: CONSULTORIA | C15: Morgado Fernandez Martin | D15: 2600.4 | E15: 337.5 | G15: =+N15 -> 0 | H15: =SUM(D15:G15) -> 2937.9 | J15: =VLOOKUP(C15,'CPD PITSS'!$B$9:$V$26,3,0) -> 0 | K15: 15000 | L15: =(((+K15/30)*J15)*30%) -> 0 | M15: =VLOOKUP($C15,'CPD PITSS'!$B$9:$V$26,8,0) -> 0 | N15: =+L15-M15 -> 0 | O15: SEI0088 | P15: =H15*2% -> 58.758 | Q15: =H15+P15 -> 2996.658 | R15: =Q15*16% -> 479.46528
A16: SEI0173 | B16: CONSULTORIA | C16: Nieto Ortiz Jose Luis | D16: 1483.13 | E16: 20 | G16: =+N16 -> 0 | H16: =SUM(D16:G16) -> 1503.13 | J16: =VLOOKUP(C16,'CPD PITSS'!$B$9:$V$26,3,0) -> 0 | K16: 10000 | L16: =(((+K16/30)*J16)*30%) -> 0 | M16: =VLOOKUP($C16,'CPD PITSS'!$B$9:$V$26,8,0) -> 0 | N16: =+L16-M16 -> 0 | O16: SEI0173 | P16: =H16*2% -> 30.0626 | Q16: =H16+P16 -> 1533.1926 | R16: =Q16*16% -> 245.31082
A17: SEI0026 | B17: CONSULTORIA | C17: Patricio Aguilar Jhonattan Cristian | D17: 1588 | E17: 400 | G17: =+N17 -> 0 | H17: =SUM(D17:G17) -> 1988 | J17: =VLOOKUP(C17,'CPD PITSS'!$B$9:$V$26,3,0) -> 0 | K17: 9000 | L17: =(((+K17/30)*J17)*30%) -> 0 | M17: =VLOOKUP($C17,'CPD PITSS'!$B$9:$V$26,8,0) -> 0 | N17: =+L17-M17 -> 0 | O17: SEI0026 | P17: =H17*2% -> 39.76 | Q17: =H17+P17 -> 2027.76 | R17: =Q17*16% -> 324.4416
A18: SEI0221 | B18: CONSULTORIA | C18: Rogel Teran Marco Antonio | D18: 12613.2 | G18: =+N18 -> 281.75 | H18: =SUM(D18:G18) -> 12894.95 | J18: =VLOOKUP(C18,'CPD PITSS'!$B$9:$V$26,3,0) -> 1 | K18: 60000 | L18: =(((+K18/30)*J18)*30%) -> 600 | M18: =VLOOKUP($C18,'CPD PITSS'!$B$9:$V$26,8,0) -> 318.25 | N18: =+L18-M18 -> 281.75 | O18: SEI0221 | P18: =H18*2% -> 257.899 | Q18: =H18+P18 -> 13152.849 | R18: =Q18*16% -> 2104.4558
A19: SEI0442 | B19: CONSULTORIA | C19: Sierra Escamilla Daniela | D19: 2464 | E19: 1000 | G19: =+N19 -> 0 | H19: =SUM(D19:G19) -> 3464 | J19: =VLOOKUP(C19,'CPD PITSS'!$B$9:$V$26,3,0) -> 0 | K19: 13000 | L19: =(((+K19/30)*J19)*30%) -> 0 | M19: =VLOOKUP($C19,'CPD PITSS'!$B$9:$V$26,8,0) -> 0 | N19: =+L19-M19 -> 0 | O19: SEI0618 | P19: =H19*2% -> 69.28 | Q19: =H19+P19 -> 3533.28 | R19: =Q19*16% -> 565.3248
A20: SEI0041 | B20: CONSULTORIA | C20: Vazquez Perez Miguel Angel | D20: 4176 | E20: 750 | G20: =+N20 -> 0 | H20: =SUM(D20:G20) -> 4926 | J20: =VLOOKUP(C20,'CPD PITSS'!$B$9:$V$26,3,0) -> 0 | K20: 18500 | L20: =(((+K20/30)*J20)*30%) -> 0 | M20: =VLOOKUP($C20,'CPD PITSS'!$B$9:$V$26,8,0) -> 0 | N20: =+L20-M20 -> 0 | O20: SEI0041 | P20: =H20*2% -> 98.52 | Q20: =H20+P20 -> 5024.52 | R20: =Q20*16% -> 803.9232
A21: SEI0544 | B21: IP INNOVACION | C21: Aguilar Aguirre Alfonso | D21: 135.2 | H21: =SUM(D21:G21) -> 135.2 | J21: =VLOOKUP(C21,'IP PITSS'!$B$9:$U$90,3,0) -> 0 | K21: 6000 | L21: =(((+K21/30)*J21)*30%) -> 0 | M21: =VLOOKUP(C21,'IP PITSS'!$B$9:$I$90,8,0) -> 0 | N21: =+L21-M21 -> 0 | O21: SEI0652 | P21: =H21*2% -> 2.704 | Q21: =H21+P21 -> 137.904 | R21: =Q21*16% -> 22.06464
A22: SEI0431 | B22: IP INNOVACION | C22: Alcaraz Conde Zabdi Guadalupe | D22: 135.14 | E22: 455 | G22: =+N22 -> 0 | H22: =SUM(D22:G22) -> 590.14 | J22: =VLOOKUP(C22,'IP PITSS'!$B$9:$U$90,3,0) -> 0 | K22: 6000 | L22: =(((+K22/30)*J22)*30%) -> 0 | M22: =VLOOKUP(C22,'IP PITSS'!$B$9:$I$90,8,0) -> 0 | N22: =+L22-M22 -> 0 | O22: SEI0456 | P22: =H22*2% -> 11.8028 | Q22: =H22+P22 -> 601.9428 | R22: =Q22*16% -> 96.310848
A23: SEI0527 | B23: IP INNOVACION | C23: Alejandro Peña Deivi | D23: 175.6 | E23: 1068.75 | G23: =+N23 -> 0 | H23: =SUM(D23:G23) -> 1244.35 | J23: =VLOOKUP(C23,'IP PITSS'!$B$9:$U$90,3,0) -> 0 | K23: 6300 | L23: =(((+K23/30)*J23)*30%) -> 0 | M23: =VLOOKUP(C23,'IP PITSS'!$B$9:$I$90,8,0) -> 0 | N23: =+L23-M23 -> 0 | O23: SEI0628 | P23: =H23*2% -> 24.887 | Q23: =H23+P23 -> 1269.237 | R23: =Q23*16% -> 203.07792
A24: SEI0535 | B24: IP INNOVACION | C24: Alejandro Vazquez Erasmo Miguel | D24: 3135.32 | E24: 750 | G24: =+N24 -> 0 | H24: =SUM(D24:G24) -> 3885.32 | J24: =VLOOKUP(C24,'IP PITSS'!$B$9:$U$90,3,0) -> 0 | K24: 12000 | L24: =(((+K24/30)*J24)*30%) -> 0 | M24: =VLOOKUP(C24,'IP PITSS'!$B$9:$I$90,8,0) -> 0 | N24: =+L24-M24 -> 0 | O24: SEI0638 | P24: =H24*2% -> 77.7064 | Q24: =H24+P24 -> 3963.0264 | R24: =Q24*16% -> 634.08422
A25: SEI0029 | B25: IP INNOVACION | C25: Arceo Garcia Manuel Federico | D25: 255.2 | E25: 455 | G25: =+N25 -> 0 | H25: =SUM(D25:G25) -> 710.2 | J25: =VLOOKUP(C25,'IP PITSS'!$B$9:$U$90,3,0) -> 1 | K25: 6000 | L25: =(((+K25/30)*J25)*30%) -> 60 | M25: =VLOOKUP(C25,'IP PITSS'!$B$9:$I$90,8,0) -> 60 | N25: =+L25-M25 -> 0 | O25: SEI0029 | P25: =H25*2% -> 14.204 | Q25: =H25+P25 -> 724.404 | R25: =Q25*16% -> 115.90464
A26: SEI0472 | B26: IP INNOVACION | C26: Arzate Gil Juan Sebastian | D26: 416.5 | E26: 480 | G26: =+N26 -> 0 | H26: =SUM(D26:G26) -> 896.5 | J26: =VLOOKUP(C26,'IP PITSS'!$B$9:$U$90,3,0) -> 0 | K26: 8000 | L26: =(((+K26/30)*J26)*30%) -> 0 | M26: =VLOOKUP(C26,'IP PITSS'!$B$9:$I$90,8,0) -> 0 | N26: =+L26-M26 -> 0 | O26: SEI0550 | P26: =H26*2% -> 17.93 | Q26: =H26+P26 -> 914.43 | R26: =Q26*16% -> 146.3088
A27: SEI0528 | B27: IP INNOVACION | C27: Casas Chavarria Rafael | D27: 175.67 | E27: 675 | G27: =+N27 -> 0 | H27: =SUM(D27:G27) -> 850.67 | J27: =VLOOKUP(C27,'IP PITSS'!$B$9:$U$90,3,0) -> 0 | K27: 6300 | L27: =(((+K27/30)*J27)*30%) -> 0 | M27: =VLOOKUP(C27,'IP PITSS'!$B$9:$I$90,8,0) -> 0 | N27: =+L27-M27 -> 0 | O27: SEI0629 | P27: =H27*2% -> 17.0134 | Q27: =H27+P27 -> 867.6834 | R27: =Q27*16% -> 138.82934
A28: SEI0460 | B28: IP INNOVACION | C28: Castellon Ramos Rene | D28: 384.855 | E28: 135 | G28: =+N28 -> 0 | H28: =SUM(D28:G28) -> 519.855 | J28: =VLOOKUP(C28,'IP PITSS'!$B$9:$U$90,3,0) -> 0 | K28: 7505.99 | L28: =(((+K28/30)*J28)*30%) -> 0 | M28: =VLOOKUP(C28,'IP PITSS'!$B$9:$I$90,8,0) -> 0 | N28: =+L28-M28 -> 0 | O28: SEI0499 | P28: =H28*2% -> 10.3971 | Q28: =H28+P28 -> 530.2521 | R28: =Q28*16% -> 84.840336
A29: SEI0443 | B29: IP INNOVACION | C29: Castillo Nungaray Nestor Roman | D29: 135.2 | E29: 450 | G29: =+N29 -> 0 | H29: =SUM(D29:G29) -> 585.2 | J29: =VLOOKUP(C29,'IP PITSS'!$B$9:$U$90,3,0) -> 0 | K29: 6000 | L29: =(((+K29/30)*J29)*30%) -> 0 | M29: =VLOOKUP(C29,'IP PITSS'!$B$9:$I$90,8,0) -> 0 | N29: =+L29-M29 -> 0 | O29: SEI0468 | P29: =H29*2% -> 11.704 | Q29: =H29+P29 -> 596.904 | R29: =Q29*16% -> 95.50464
A30: SEI0490 | B30: IP INNOVACION | C30: Castillo Ramirez Hector Ivan | D30: 4001.2 | E30: 437.5 | F30: 840 | G30: =+N30 -> 0 | H30: =SUM(D30:G30) -> 5278.7 | J30: =VLOOKUP(C30,'IP PITSS'!$B$9:$U$90,3,0) -> 0 | K30: 14000 | L30: =(((+K30/30)*J30)*30%) -> 0 | M30: =VLOOKUP(C30,'IP PITSS'!$B$9:$I$90,8,0) -> 0 | N30: =+L30-M30 -> 0 | O30: SEI0448 | P30: =H30*2% -> 105.574 | Q30: =H30+P30 -> 5384.274 | R30: =Q30*16% -> 861.48384
A31: SEI0508 | B31: IP INNOVACION | C31: Cerro Garcia Elvis | D31: 2553.4 | E31: 400 | G31: =+N31 -> 0 | H31: =SUM(D31:G31) -> 2953.4 | J31: =VLOOKUP(C31,'IP PITSS'!$B$9:$U$90,3,0) -> 0 | K31: 10000 | L31: =(((+K31/30)*J31)*30%) -> 0 | M31: =VLOOKUP(C31,'IP PITSS'!$B$9:$I$90,8,0) -> 0 | N31: =+L31-M31 -> 0 | O31: SEI0513 | P31: =H31*2% -> 59.068 | Q31: =H31+P31 -> 3012.468 | R31: =Q31*16% -> 481.99488
A32: SEI0499 | B32: IP INNOVACION | C32: Chavez Dominguez Salvador | D32: 2667.4 | E32: 750 | F32: 400 | G32: =+N32 -> 0 | H32: =SUM(D32:G32) -> 3817.4 | J32: =VLOOKUP(C32,'IP PITSS'!$B$9:$U$90,3,0) -> 0 | K32: 12000 | L32: =(((+K32/30)*J32)*30%) -> 0 | M32: =VLOOKUP(C32,'IP PITSS'!$B$9:$I$90,8,0) -> 0 | N32: =+L32-M32 -> 0 | O32: SEI0483 | P32: =H32*2% -> 76.348 | Q32: =H32+P32 -> 3893.748 | R32: =Q32*16% -> 622.99968
A33: SEI0541 | B33: IP INNOVACION | C33: Chavez Govea Edgar Aram | D33: 222.6 | E33: 250 | G33: =+N33 -> 0 | H33: =SUM(D33:G33) -> 472.6 | J33: =VLOOKUP(C33,'IP PITSS'!$B$9:$U$90,3,0) -> 0 | K33: 7000 | L33: =(((+K33/30)*J33)*30%) -> 0 | M33: =VLOOKUP(C33,'IP PITSS'!$B$9:$I$90,8,0) -> 0 | N33: =+L33-M33 -> 0 | O33: SEI0644 | P33: =H33*2% -> 9.452 | Q33: =H33+P33 -> 482.052 | R33: =Q33*16% -> 77.12832
A34: SEI0442 | B34: IP INNOVACION | C34: Chavez Pedraza Samuel | D34: 1047.8 | E34: 687.5 | G34: =+N34 -> 0 | H34: =SUM(D34:G34) -> 1735.3 | J34: =VLOOKUP(C34,'IP PITSS'!$B$9:$U$90,3,0) -> 0 | K34: 14000 | L34: =(((+K34/30)*J34)*30%) -> 0 | M34: =VLOOKUP(C34,'IP PITSS'!$B$9:$I$90,8,0) -> 0 | N34: =+L34-M34 -> 0 | O34: SEI0467 | P34: =H34*2% -> 34.706 | Q34: =H34+P34 -> 1770.006 | R34: =Q34*16% -> 283.20096
A35: SEI0462 | B35: IP INNOVACION | C35: Chavez Saucedo Jorge Arturo | D35: 334.6 | E35: 450 | G35: =+N35 -> 0 | H35: =SUM(D35:G35) -> 784.6 | J35: =VLOOKUP(C35,'IP PITSS'!$B$9:$U$90,3,0) -> 1 | K35: 8000 | L35: =(((+K35/30)*J35)*30%) -> 80 | M35: =VLOOKUP(C35,'IP PITSS'!$B$9:$I$90,8,0) -> 80 | N35: =+L35-M35 -> 0 | O35: SEI0516 | P35: =H35*2% -> 15.692 | Q35: =H35+P35 -> 800.292 | R35: =Q35*16% -> 128.04672
A36: SEI0456 | B36: IP INNOVACION | C36: Chavira Garcia David Fernando | D36: 593.6 | E36: 110 | G36: =+N36 -> 0 | H36: =SUM(D36:G36) -> 703.6 | J36: =VLOOKUP(C36,'IP PITSS'!$B$9:$U$90,3,0) -> 0 | K36: 10000 | L36: =(((+K36/30)*J36)*30%) -> 0 | M36: =VLOOKUP(C36,'IP PITSS'!$B$9:$I$90,8,0) -> 0 | N36: =+L36-M36 -> 0 | O36: SEI0495 | P36: =H36*2% -> 14.072 | Q36: =H36+P36 -> 717.672 | R36: =Q36*16% -> 114.82752
A37: SEI0538 | B37: IP INNOVACION | C37: Coronado Vega Carlos Eduardo | D37: 0 | G37: =+N37 -> 0 | H37: =SUM(D37:G37) -> 0 | J37: 0 | K37: 6300 | L37: =(((+K37/30)*J37)*30%) -> 0 | M37: 0 | N37: =+L37-M37 -> 0 | O37: SEI0642 | P37: =H37*2% -> 0 | Q37: =H37+P37 -> 0 | R37: =Q37*16% -> 0
A38: SEI0015 | B38: IP INNOVACION | C38: Cota Jaramillo Miguel Angel | D38: 554.2 | E38: 225 | G38: =+N38 -> 0 | H38: =SUM(D38:G38) -> 779.2 | J38: =VLOOKUP(C38,'IP PITSS'!$B$9:$U$90,3,0) -> 0 | K38: 6000 | L38: =(((+K38/30)*J38)*30%) -> 0 | M38: =VLOOKUP(C38,'IP PITSS'!$B$9:$I$90,8,0) -> 0 | N38: =+L38-M38 -> 0 | O38: SEI0015 | P38: =H38*2% -> 15.584 | Q38: =H38+P38 -> 794.784 | R38: =Q38*16% -> 127.16544
A39: SEI0413 | B39: IP INNOVACION | C39: Courtenay Gutierrez Barry Vladimir | D39: 52.35 | E39: 250 | G39: =+N39 -> 0 | H39: =SUM(D39:G39) -> 302.35 | J39: =VLOOKUP(C39,'IP PITSS'!$B$9:$U$90,3,0) -> 0 | K39: 5000 | L39: =(((+K39/30)*J39)*30%) -> 0 | M39: =VLOOKUP(C39,'IP PITSS'!$B$9:$I$90,8,0) -> 0 | N39: =+L39-M39 -> 0 | O39: SEI0436 | P39: =H39*2% -> 6.047 | Q39: =H39+P39 -> 308.397 | R39: =Q39*16% -> 49.34352
A40: SEI0501 | B40: IP INNOVACION | C40: Cruz Herrera Roberto | D40: 1667.37 | E40: 465 | G40: =+N40 -> 0 | H40: =SUM(D40:G40) -> 2132.37 | J40: =VLOOKUP(C40,'IP PITSS'!$B$9:$U$90,3,0) -> 0 | K40: 10000 | L40: =(((+K40/30)*J40)*30%) -> 0 | M40: =VLOOKUP(C40,'IP PITSS'!$B$9:$I$90,8,0) -> 0 | N40: =+L40-M40 -> 0 | O40: SEI0485 | P40: =H40*2% -> 42.6474 | Q40: =H40+P40 -> 2175.0174 | R40: =Q40*16% -> 348.00278
...

Sheet RESUMEN PITS
F1: SINDICATO
A2: CLAVE | B2: EMPRESA | C2: NOMBRE | D2: NETO CPD | F2: SUELDO SINDICATO | G2: BONO | H2: COMISION | I2: PRIMA VACACIONAL SINDICATO | J2: B | K2: NETO A PAGAR | L2: NETO MENSUAL | M2: NETO QUINCENAL SEITON | N2: C | O2: prima vacacional | P2: COMISION Y PRIMA VACACIONAL | Q2: INFONAVIT | R2: FONACOT | S2: DESCUENTOS | T2: D | U2: TOTAL GENERAL | V2: DIFERENCIAS | W2: OBSERVACIONES | Y2: total
A3: SEI0009 | B3: CONSULTORIA | C3: Gutierrez Gutierrez Luis Arturo | D3: =VLOOKUP(C3,'CPD PITSS'!B9:V26,21,0) -> 2774.6 | F3: =VLOOKUP($C3,'SIND PITS'!$C$3:$G$20,2,0) -> 1475.4 | G3: =VLOOKUP($C3,'SIND PITS'!$C$3:$G$20,3,0) -> 100 | H3: =VLOOKUP($C3,'SIND PITS'!$C$3:$G$20,4,0) -> 0 | I3: =VLOOKUP($C3,'SIND PITS'!$C$3:$G$20,5,0) -> 0 | K3: =SUM(D3:I3) -> 4350 | L3: 8500 | M3: =+L3/2 -> 4250 | O3: =VLOOKUP($C3,'CPD PITSS'!$B$9:$V$26,8,0) -> 0 | P3: =+G3+H3+I3 -> 100 | Q3: =(VLOOKUP($C3,'CPD PITSS'!$B$9:$V$26,13,0))+(VLOOKUP($C3,'CPD PITSS'!$B$9:$V$26,14,0)) -> 0 | S3: 0 | U3: =+K3-O3-P3+Q3+R3+S3 -> 4250 | V3: =+M3-U3 -> 0 | X3: SEI0009 | Y3: =IFERROR(OFFSET('CPD PITSS'!$AN$8,MATCH('RESUMEN PITS'!C3,'CPD PITSS'!$B$9:$B$26,0),0),0)+IFERROR(OFFSET('IP PITSS'!$AL$8,MATCH('RESUMEN PITS'!C3,'IP PITSS'!$B$9:$B$90,0),0),0)+IFERROR(OFFSET('SIND PITS'!$Q$2,MATCH('RESUMEN PITS'!C3,'SIND PITS'!$C$3:$C$103,0),0),0) -> 5772.0882
