Workbook

Sheet CPD PITSS
B2: CONSULTORIA EN PROYECTOS DINAMICOS S DE RL DE CV
B3: Lista de Raya (forma tabular)
B5: Reg Pat IMSS: Z2940859106
B6: RFC: CPD -150911-FA3
B7: 1 | C7: =+B7+1 -> 2 | D7: =+C7+1 -> 3 | E7: =+D7+1 -> 4 | F7: =+E7+1 -> 5 | G7: =+F7+1 -> 6 | H7: =+G7+1 -> 7 | I7: =+H7+1 -> 8 | J7: =+I7+1 -> 9 | ... V7: =+U7+1 -> 21
A8: Código | B8: Empleado | C8: Dias Laborados | D8: Dias Vacaciones | E8: Salario Diario | F8: Salario Diario Integrado | G8: Sueldo | H8: Vacaciones a tiempo | I8: Prima de vacaciones a tiempo | J8: Ayuda de Transporte | K8: Ayuda Alimentaria | L8: Ayuda de Renta | M8: *TOTAL* *PERCEPCIONES* | N8: Seguro de vivienda Infonavit | O8: Préstamo Infonavit (vsm) | P8: Subsidio al Empleo (sp) | Q8: I.S.R. (sp) | R8: I.M.S.S. | S8: Deduccion General | T8: Ajuste al neto | U8: *TOTAL* *DEDUCCIONES* | V8: *NETO* | W8: Invalidez y Vida | X8: Cesantia y Vejez | Y8: Enf. y Mat. Patron | Z8: 2% Fondo retiro SAR (8) | AA8: 2% Impuesto estatal | AB8: Riesgo de trabajo (9) | AC8: I.M.S.S. empresa | AD8: Infonavit empresa | AE8: Guarderia I.M.S.S. (7) | AF8: Banco | AG8: Aguinaldo
A10: SEI0009 | B10: Gutierrez Gutierrez Luis Arturo | C10: 15 | D10: 0 | E10: 141.67 | F10: 150.25 | G10: 2125.05 | H10: 0 | I10: 0 | J10: 212.51 | K10: 212.51 | L10: 212.51 | M10: 2762.58 | O10: 0 | P10: -65.5 | Q10: 0 | R10: 53.52 | S10: 0 | T10: 0.16 | U10: -11.82 | V10: 2774.4 | W10: 39.44 | X10: 70.99 | Y10: 297.98 | Z10: 183.93 | AA10: 55.25 | AB10: 11.27 | AC10: 408.41 | AD10: 112.69 | AE10: 161.39 | AF10: 110 | AG10: =((20/365.24)*15)*($E10*1.3) -> 151.27396
A11: SEI0026 | B11: Patricio Aguilar Jhonattan Cristian | C11: 15 | D11: 0 | E11: 150 | F11: 159.07 | G11: 2250 | H11: 0 | I11: 0 | J11: 225 | K11: 225 | L11: 225 | M11: 2925 | O11: 0 | P11: -43.57 | Q11: 0 | R11: 56.67 | S11: 0 | T11: 0.1 | U11: 13.2 | V11: 2911.8 | W11: 41.76 | X11: 75.16 | Y11: 300.29 | Z11: 186.57 | AA11: 58.5 | AB11: 11.93 | AC11: 417.21 | AD11: 119.31 | AE11: 162.71 | AF11: 110 | AG11: =((20/365.24)*15)*($E11*1.3) -> 160.16866
A12: SEI0040 | B12: Mora Ramirez Acal Aldo Isidro | C12: 12 | D12: 3 | E12: 216.67 | F12: 229.79 | G12: 2600.04 | H12: 650.01 | I12: 195 | J12: 325.01 | K12: 325.01 | L12: 325.01 | M12: 4420.08 | O12: 0 | P12: 0 | Q12: 107.17 | R12: 81.87 | S12: 0 | T12: 0.04 | U12: 189.08 | V12: 4231 | W12: 60.32 | X12: 108.58 | Y12: 318.86 | Z12: 207.79 | AA12: 88.4 | AB12: 17.23 | AC12: 487.76 | AD12: 172.34 | AE12: 173.32 | AF12: 110 | AG12: =((20/365.24)*15)*($E12*1.3) -> 231.35828
A13: SEI0041 | B13: Vazquez Perez Miguel Angel | C13: 15 | D13: 0 | E13: 283.33 | F13: 300.49 | G13: 4249.95 | H13: 0 | I13: 0 | J13: 425 | K13: 425 | L13: 425 | M13: 5524.95 | O13: 0 | P13: 0 | Q13: 341.06 | R13: 109.87 | S13: 0 | T13: 0.02 | U13: 450.95 | V13: 5074 | W13: 78.88 | X13: 141.98 | Y13: 345.18 | Z13: 229 | AA13: 110.5 | AB13: 22.54 | AC13: 566.04 | AD13: 225.37 | AE13: 183.92 | AF13: 110 | AG13: =((20/365.24)*15)*($E13*1.3) -> 302.53724
A14: SEI0088 | B14: Morgado Fernandez Martin | C14: 15 | D14: 0 | E14: 273.33 | F14: 289.87 | G14: 4099.95 | H14: 0 | I14: 0 | J14: 410 | K14: 410 | L14: 410 | M14: 5329.95 | O14: 0 | P14: 0 | Q14: 324.74 | R14: 105.46 | S14: 275.95 | T14: 0 | U14: 706.15 | V14: 4623.8 | W14: 76.09 | X14: 136.96 | Y14: 340.64 | Z14: 225.81 | AA14: 106.6 | AB14: 21.74 | AC14: 553.69 | AD14: 217.4 | AE14: 182.33 | AF14: 110 | AG14: =((20/365.24)*15)*($E14*1.3) -> 291.85933
A15: SEI0097 | B15: Arreola Jimenez Jose Nieves | C15: 15 | D15: 0 | E15: 185.83 | F15: 197.07 | G15: 2787.45 | H15: 0 | I15: 0 | J15: 278.75 | K15: 278.75 | L15: 278.75 | M15: 3623.7 | O15: 1541.78 | P15: 0 | Q15: 36.57 | R15: 70.22 | S15: 0 | T15: -0.07 | U15: 1648.5 | V15: 1975.2 | W15: 51.73 | X15: 93.12 | Y15: 310.27 | Z15: 197.97 | AA15: 72.47 | AB15: 14.78 | AC15: 455.12 | AD15: 147.8 | AE15: 168.41 | AF15: 110 | AG15: =((20/365.24)*15)*($E15*1.3) -> 198.42761
A16: SEI0099 | B16: Garcia Villicaña Ricardo Pascual | C16: 15 | D16: 0 | E16: 273.33 | F16: 289.87 | G16: 4099.95 | H16: 0 | I16: 0 | J16: 410 | K16: 410 | L16: 410 | M16: 5329.95 | O16: 0 | P16: 0 | Q16: 324.74 | R16: 105.46 | S16: 0 | T16: -0.05 | U16: 430.15 | V16: 4899.8 | W16: 76.09 | X16: 136.96 | Y16: 340.64 | Z16: 225.81 | AA16: 106.6 | AB16: 21.74 | AC16: 553.69 | AD16: 217.4 | AE16: 182.33 | AF16: 110 | AG16: =((20/365.24)*15)*($E16*1.3) -> 291.85933
A17: SEI0108 | B17: Caballero Diaz Francisco Javier | C17: 9 | D17: 6 | E17: 185.83 | F17: 197.07 | G17: 1672.47 | H17: 1114.98 | I17: 334.49 | J17: 278.75 | K17: 278.75 | L17: 278.75 | M17: 3958.19 | O17: 1789.38 | P17: 0 | Q17: 36.57 | R17: 70.22 | S17: 238.8 | T17: 0.02 | U17: 2134.99 | V17: 1823.2 | W17: 51.73 | X17: 93.12 | Y17: 310.27 | Z17: 197.97 | AA17: 79.16 | AB17: 14.78 | AC17: 455.12 | AD17: 147.8 | AE17: 168.41 | AF17: 110 | AG17: =((20/365.24)*15)*($E17*1.3) -> 198.42761
A18: SEI0116 | B18: Casillas Cardona Cesar Alejandro | C18: 13 | D18: 2 | E18: 220.83 | F18: 234.19 | G18: 2870.79 | H18: 441.66 | I18: 132.5 | J18: 331.25 | K18: 331.25 | L18: 331.25 | M18: 4438.7 | O18: 894.93 | P18: 0 | Q18: 113.96 | R18: 83.43 | S18: 0 | T18: -0.02 | U18: 1092.3 | V18: 3346.4 | W18: 61.47 | X18: 110.65 | Y18: 320.01 | Z18: 209.11 | AA18: 88.77 | AB18: 17.56 | AC18: 492.13 | AD18: 175.64 | AE18: 173.98 | AF18: 110 | AG18: =((20/365.24)*15)*($E18*1.3) -> 235.8003
A19: SEI0117 | B19: Mariscal Romero Luis Adrian | C19: 15 | D19: 0 | E19: 264.58 | F19: 276.54 | G19: 3968.7 | H19: 0 | I19: 0 | J19: 396.87 | K19: 396.87 | L19: 396.87 | M19: 5159.31 | O19: 1639.72 | P19: 0 | Q19: 310.46 | R19: 99.91 | S19: 0 | T19: 0.02 | U19: 2050.11 | V19: 3109.2 | W19: 72.59 | X19: 130.66 | Y19: 334.94 | Z19: 221.81 | AA19: 103.19 | AB19: 20.74 | AC19: 538.19 | AD19: 207.4 | AE19: 180.33 | AF19: 110 | AG19: =((20/365.24)*15)*($E19*1.3) -> 282.51615
A20: SEI0118 | B20: Arroyo Ramirez Hector Hugo | C20: 15 | D20: 0 | E20: 238.33 | F20: 252.75 | G20: 3574.95 | H20: 0 | I20: 0 | J20: 357.5 | K20: 357.5 | L20: 357.5 | M20: 4647.45 | O20: 1402.48 | P20: 0 | Q20: 160.25 | R20: 90.05 | S20: 255.4 | T20: -0.13 | U20: 1908.05 | V20: 2739.4 | W20: 66.35 | X20: 119.42 | Y20: 324.89 | Z20: 214.67 | AA20: 92.95 | AB20: 18.96 | AC20: 510.66 | AD20: 189.56 | AE20: 176.76 | AF20: 110 | AG20: =((20/365.24)*15)*($E20*1.3) -> 254.48664
A21: SEI0127 | B21: Hernandez Ochoa Eduardo | C21: 15 | D21: 0 | E21: 273.33 | F21: 289.87 | G21: 4099.95 | H21: 0 | I21: 0 | J21: 410 | K21: 410 | L21: 410 | M21: 5329.95 | O21: 0 | P21: 0 | Q21: 324.74 | R21: 105.46 | S21: 0 | T21: -0.05 | U21: 430.15 | V21: 4899.8 | W21: 76.09 | X21: 136.96 | Y21: 340.64 | Z21: 225.81 | AA21: 106.6 | AB21: 21.74 | AC21: 553.69 | AD21: 217.4 | AE21: 182.33 | AF21: 110 | AG21: =((20/365.24)*15)*($E21*1.3) -> 291.85933
... A27: SEI0442 | B27: Sierra Escamilla Daniela | C27: 15 | D27: 0 | E27: 216.67 | F27: 229.79 | G27: 3250.05 | H27: 0 | I27: 0 | J27: 325.01 | K27: 325.01 | L27: 325.01 | M27: 4225.08 | O27: 0 | P27: 0 | Q27: 107.17 | R27: 81.87 | S27: 0 | T27: -0.16 | U27: 188.88 | V27: 4036.2 | W27: 60.32 | X27: 108.58 | Y27: 318.86 | Z27: 207.79 | AA27: 84.5 | AB27: 17.23 | AC27: 487.76 | AD27: 172.34 | AE27: 173.32 | AF27: 110 | AG27: =((20/365.24)*15)*($E27*1.3) -> 231.35828
C28: ============= | D28: ============= | E28: ============= | F28: ============= | G28: ============= | H28: ============= | I28: ============= | J28: ============= | K28: ============= | L28: ============= | M28: ============= | N28: ============= | O28: ============= | P28: ============= | Q28: ============= | R28: ============= | S28: ============= | T28: ============= | U28: ============= | V28: ============= | W28: ============= | X28: ============= | Y28: ============= | Z28: ============= | AA28: ============= | AB28: ============= | AC28: ============= | AD28: ============= | AE28: ============= | AF28: ============= | AG28: =============
A29: Total Gral. | C29: =SUM(C10:C27) -> 252 | D29: =SUM(D10:D27) -> 18 | E29: =SUM(E10:E27) -> 4708.72 | F29: =SUM(F10:F27) -> 4989.65 | G29: =SUM(G10:G27) -> 67123.34 | H29: =SUM(H10:H27) -> 3507.46 | I29: =SUM(I10:I27) -> 1052.23 | J29: =SUM(J10:J27) -> 7063.16 | ... AG29: =SUM(AG10:AG27) -> 5027.929
A31: 18 | B31: Nomina
B32: Altas | L32: FACTURACION PITS | N32: VENTAS | O32: ADMINISTRACION | P32: SERVICIO
B33: Bajas | L33: Devengado Salario | M33: =+V29 -> 74070.2 | N33: =V23 -> 17386.8 | O33: =V27+V13+V12 -> 13341.2 | P33: =M33-O33-N33 -> 43342.2
A34: =+A31+A32-A33 -> 18 | B34: Total Nomina | L34: RETORNOS | M34: =+S29 -> 1067.15 | P34: =M34 -> 1067.15
L35: Infonavit | M35: =+N29+O29 -> 10869.77 | N35: 0 | O35: 0 | P35: =M35 -> 10869.77
L36: Prestamo Prospera | M36: 0
L37: Subtotal 1 | M37: =SUM(M33:M36) -> 86007.12 | N37: =SUM(N33:N36) -> 17386.8 | O37: =SUM(O33:O36) -> 13341.2 | P37: =SUM(P33:P36) -> 55279.12
L38: Comision | M38: =+M37*2% -> 1720.1424 | N38: =N37*2% -> 347.736 | O38: =O37*2% -> 266.824 | P38: =P37*2% -> 1105.5824
L39: Subtotal 2 | M39: =+M37+M38 -> 87727.262 | N39: =N38+N37 -> 17734.536 | O39: =O38+O37 -> 13608.024 | P39: =P38+P37 -> 56384.702
L40: Costo Patronal Imss | M40: =+R29+W29+X29+Y29+AB29+Z29+AD29+AE29 -> 23005.39 | N40: =R23+W23+X23+Y23+Z23+AB23+AD23+AE23 -> 3689.84 | O40: =R27+R13+R12+W12+W13+X12+X13+Y12+Y13+Z12+Z13+Z27+Y27+X27+W27+AB27+AD27+AE27+AB13+AB12+AD12+AD13+AE12+AE13 -> 3617.36 | P40: =M40-N40-O40 -> 15698.19
L41: 2% Sobre Nomina | M41: =+M29*2% -> 1857.4502 | N41: =M23*2% -> 413.724 | O41: =14170.11*2% -> 283.4022 | P41: =M41-O41-N41 -> 1160.324
L42: Importe de Factura | M42: =+M39+M40+M41 -> 112590.1 | N42: =N41+N40+N39 -> 21838.1 | O42: =O41+O40+O39 -> 17508.786 | P42: =P41+P40+P39 -> 73243.216
L43: IVA | M43: =+M42*16% -> 18014.416 | N43: =N42*0.16 -> 3494.096 | O43: =O42*0.16 -> 2801.4058 | P43: =P42*0.16 -> 11718.915
L44: TOTAL | M44: =+M42+M43 -> 130604.52 | N44: =N43+N42 -> 25332.196 | O44: =O43+O42 -> 20310.192 | P44: =P43+P42 -> 84962.131
N45: =N42-N38 -> 21490.364 | O45: =O42-O38 -> 17241.962 | P45: =P42-P38 -> 72137.634
L46: PROVISION AGUINALDO | P46: 0.73 | Q46: 0.11 | R46: 0.12 | S46: 0.04
L47: FACTURACION PITS | P47: ITA | Q47: IP | R47: CPD | S47: EM
L48: Subtotal 1 | M48: =+AG29 -> 5027.929 | O48: SERVICIO | P48: =P45*$P$46 -> 52660.473 | Q48: =P45*$Q$46 -> 7935.1397 | R48: =P45*$R$46 -> 8656.5161 | S48: =P45*$S$46 -> 2885.5054
L49: Comision | M49: =+M48*2% -> 100.55858 | O49: ADMINISTRACION | P49: =O45*$P$46 -> 12586.632 | Q49: =O45*$Q$46 -> 1896.6158 | R49: =O45*$R$46 -> 2069.0355 | S49: =O45*$S$46 -> 689.67849
...

Sheet IP PITSS
B2: IP INNOVACION EN PROYECTOS S DE RL DE CV
B3: Lista de Raya (forma tabular)
B5: Reg Pat IMSS: R1363592103
B6: RFC: IIP -150923-DT7
A8: Código | B8: Empleado | C8: Dias Laborados | D8: Dias Vacaciones | E8: Salario Diario | F8: Salario Diario Integrado | G8: Sueldo | H8: Vacaciones a tiempo | I8: Prima de vacaciones a tiempo | J8: *TOTAL* *PERCEPCIONES* | K8: Seguro de vivienda Infonavit | L8: Préstamo Infonavit (vsm) | M8: Préstamo Infonavit (cf) | N8: Subsidio al Empleo (sp) | O8: I.S.R. (sp) | P8: I.M.S.S. | Q8: Préstamo FONACOT | R8: Deduccion general | S8: Ajuste al neto | T8: *TOTAL* *DEDUCCIONES* | U8: *NETO* | V8: Invalidez y Vida | W8: Cesantia y Vejez | X8: Enf. y Mat. Patron | Y8: 2% Fondo retiro SAR (8) | Z8: 2% Impuesto estatal | AA8: Riesgo de trabajo (9) | AB8: I.M.S.S. empresa | AC8: Infonavit empresa | AD8: Guarderia I.M.S.S. (7) | AE8: Banco | AF8: Aguinaldo
A10: SEI0010 | B10: Torres Ricardez Alfredo | C10: 15 | D10: 0 | E10: 266.67 | F10: 278.72 | G10: 4000.05 | H10: 0 | I10: 0 | J10: 4000.05 | L10: 0 | M10: 0 | N10: 0 | O10: 313.87 | P10: 100.81 | Q10: 0 | R10: 0 | S10: -0.03 | T10: 414.65 | U10: 3585.4 | V10: 73.16 | W10: 131.7 | X10: 335.88 | Y10: 273.62 | Z10: 80 | AA10: 33.3 | AB10: 540.74 | AC10: 209.04 | AD10: 231.81 | AE10: 110 | AF10: =((20/365.24)*15)*E10 -> 219.0368
A11: SEI0014 | B11: Montoya Portillo Carlos Alberto | C11: 15 | D11: 0 | E11: 266.67 | F11: 278.72 | G11: 4000.05 | H11: 0 | I11: 0 | J11: 4000.05 | L11: 0 | M11: 0 | N11: 0 | O11: 313.87 | P11: 100.81 | Q11: 0 | R11: 0 | S11: 0.17 | T11: 414.85 | U11: 3585.2 | V11: 73.16 | W11: 131.7 | X11: 335.88 | Y11: 273.62 | Z11: 80 | AA11: 33.3 | AB11: 540.74 | AC11: 209.04 | AD11: 231.81 | AE11: 110 | AF11: =((20/365.24)*15)*E11 -> 219.0368
A12: SEI0015 | B12: Cota Jaramillo Miguel Angel | C12: 15 | D12: 0 | E12: 200 | F12: 209.04 | G12: 3000 | H12: 0 | I12: 0 | J12: 3000 | L12: 0 | M12: 0 | N12: 0 | O12: 59.69 | P12: 74.48 | Q12: 0 | R12: 0 | S12: -0.17 | T12: 134 | U12: 2866 | V12: 54.87 | W12: 98.77 | X12: 313.41 | Y12: 252.71 | Z12: 60 | AA12: 24.98 | AB12: 467.05 | AC12: 156.78 | AD12: 221.36 | AE12: 110 | AF12: =((20/365.24)*15)*E12 -> 164.27554
A13: SEI0016 | B13: Negrete Bejar Aide Sarai | C13: 15 | D13: 0 | E13: 154 | F13: 160.96 | G13: 2310 | H13: 0 | I13: 0 | J13: 2310 | L13: 977.57 | M13: 0 | N13: -39.73 | O13: 0 | P13: 57.34 | Q13: 0 | R13: 0 | S13: 0.02 | T13: 995.2 | U13: 1314.8 | V13: 42.25 | W13: 76.05 | X13: 300.79 | Y13: 238.29 | Z13: 46.2 | AA13: 19.23 | AB13: 419.09 | AC13: 120.72 | AD13: 214.14 | AE13: 110 | AF13: =((20/365.24)*15)*E13 -> 126.49217
A14: SEI0017 | B14: Muñoz Reyes Luis Eduardo | C14: 15 | D14: 0 | E14: 266.67 | F14: 278.72 | G14: 4000.05 | H14: 0 | I14: 0 | J14: 4000.05 | L14: 868.44 | M14: 0 | N14: 0 | O14: 313.87 | P14: 100.81 | Q14: 0 | R14: 0 | S14: 0.13 | T14: 1283.25 | U14: 2716.8 | V14: 73.16 | W14: 131.7 | X14: 335.88 | Y14: 273.62 | Z14: 80 | AA14: 33.3 | AB14: 540.74 | AC14: 209.04 | AD14: 231.81 | AE14: 110 | AF14: =((20/365.24)*15)*E14 -> 219.0368
A15: SEI0019 | B15: Gonzalez Rasgado Miguel Isaias | C15: 15 | D15: 0 | E15: 521.68 | F15: 553.24 | G15: 7825.2 | H15: 0 | I15: 0 | J15: 7825.2 | L15: 0 | M15: 0 | N15: 0 | O15: 1033.24 | P15: 215.09 | Q15: 0 | R15: 0 | S15: 0.07 | T15: 1248.4 | U15: 6576.8 | V15: 145.23 | W15: 261.41 | X15: 453.23 | Y15: 355.97 | Z15: 156.5 | AA15: 66.11 | AB15: 859.87 | AC15: 414.93 | AD15: 272.99 | AE15: 110 | AF15: =((20/365.24)*15)*E15 -> 428.49633
A16: SEI0020 | B16: Mar Marquez Cesar Eduardo | C16: 15 | D16: 0 | E16: 266.67 | F16: 278.72 | G16: 4000.05 | H16: 0 | I16: 0 | J16: 4000.05 | L16: 0 | M16: 0 | N16: 0 | O16: 313.87 | P16: 100.81 | Q16: 0 | R16: 0 | S16: -0.03 | T16: 414.65 | U16: 3585.4 | V16: 73.16 | W16: 131.7 | X16: 335.88 | Y16: 273.62 | Z16: 80 | AA16: 33.3 | AB16: 540.74 | AC16: 209.04 | AD16: 231.81 | AE16: 110 | AF16: =((20/365.24)*15)*E16 -> 219.0368
A17: SEI0021 | B17: Velez Rodriguez Jaime | C17: 15 | D17: 0 | E17: 200 | F17: 212.1 | G17: 3000 | H17: 0 | I17: 0 | J17: 3000 | L17: 1347.1 | M17: 0 | N17: 0 | O17: 59.69 | P17: 75.55 | Q17: 0 | R17: 0 | S17: 0.06 | T17: 1482.4 | U17: 1517.6 | V17: 55.68 | W17: 100.22 | X17: 314.22 | Y17: 253.63 | Z17: 60 | AA17: 25.34 | AB17: 470.12 | AC17: 159.08 | AD17: 221.82 | AE17: 110 | AF17: =((20/365.24)*15)*E17 -> 164.27554
A18: SEI0022 | B18: Najera Lopez Raul | C18: 15 | D18: 0 | E18: 333.33 | F18: 353.5 | G18: 4999.95 | H18: 0 | I18: 0 | J18: 4999.95 | L18: 0 | M18: 0 | N18: 0 | O18: 461.63 | P18: 131.93 | Q18: 0 | R18: 0 | S18: -0.01 | T18: 593.55 | U18: 4406.4 | V18: 92.79 | W18: 167.03 | X18: 367.84 | Y18: 296.05 | Z18: 100 | AA18: 42.24 | AB18: 627.66 | AC18: 265.12 | AD18: 243.02 | AE18: 110 | AF18: =((20/365.24)*15)*E18 -> 273.78984
A19: SEI0023 | B19: Puente Murguia Luis Felipe | C19: 15 | D19: 0 | E19: 233.33 | F19: 247.45 | G19: 3499.95 | H19: 0 | I19: 0 | J19: 3499.95 | L19: 0 | M19: 0 | N19: 0 | O19: 134.36 | P19: 88.16 | Q19: 0 | R19: 0 | S19: 0.03 | T19: 222.55 | U19: 3277.4 | V19: 64.95 | W19: 116.92 | X19: 323.49 | Y19: 264.23 | Z19: 70 | AA19: 29.57 | AB19: 505.36 | AC19: 185.58 | AD19: 227.12 | AE19: 110 | AF19: =((20/365.24)*15)*E19 -> 191.65206
A20: SEI0029 | B20: Arceo Garcia Manuel Federico | C20: 13 | D20: 1 | E20: 200 | F20: 212.1 | G20: 2600 | H20: 200 | I20: 60 | J20: 2860 | L20: 0 | M20: 0 | N20: 0 | O20: 37.93 | P20: 71.85 | Q20: 600 | R20: 0 | S20: 0.02 | T20: 709.8 | U20: 2150.2 | V20: 55.68 | W20: 100.22 | X20: 314.22 | Y20: 253.63 | Z20: 57.2 | AA20: 25.34 | AB20: 470.12 | AC20: 159.08 | AD20: 221.82 | AE20: 110 | AF20: =((20/365.24)*15)*E20 -> 164.27554
A21: SEI0364 | B21: Dominguez Lopez Mayeli Del Pilar | C21: 15 | D21: 0 | E21: 266.67 | F21: 282.81 | G21: 4000.05 | H21: 0 | I21: 0 | J21: 4000.05 | L21: 0 | M21: 0 | N21: 0 | O21: 313.87 | P21: 102.51 | Q21: 0 | R21: 1666.67 | S21: 0 | T21: 2083.05 | U21: 1917 | V21: 74.24 | W21: 133.63 | X21: 337.62 | Y21: 274.84 | Z21: 80 | AA21: 33.79 | AB21: 545.49 | AC21: 212.11 | AD21: 232.42 | AE21: 110 | AF21: =((20/365.24)*15)*E21 -> 219.0368
... A91: SEI479 | B91: Cruz Perez Alejandro Nezahualcoyotl | C91: 15 | D91: 0 | E91: 266.67 | F91: 282.81 | G91: 4000.05 | H91: 0 | I91: 0 | J91: 4000.05 | L91: 0 | M91: 0 | N91: 0 | O91: 313.87 | P91: 102.51 | Q91: 0 | R91: 0 | S91: 0.07 | T91: 416.45 | U91: 3583.6 | V91: 74.24 | W91: 133.63 | X91: 337.62 | Y91: 274.84 | Z91: 80 | AA91: 33.79 | AB91: 545.49 | AC91: 212.11 | AD91: 232.42 | AE91: 110 | AF91: =((20/365.24)*15)*E91 -> 219.0368
C92: ============= | D92: ============= | E92: ============= | F92: ============= | G92: ============= | H92: ============= | I92: ============= | J92: ============= | K92: ============= | L92: ============= | M92: ============= | N92: ============= | O92: ============= | P92: ============= | Q92: ============= | R92: ============= | S92: ============= | T92: ============= | U92: ============= | V92: ============= | W92: ============= | X92: ============= | Y92: ============= | Z92: ============= | AA92: ============= | AB92: ============= | AC92: ============= | AD92: ============= | AE92: ============= | AF92: =============
A93: Total Gral. | C93: =SUM(C10:C91) -> 1222 | D93: =SUM(D10:D91) -> 7 | E93: =SUM(E10:E91) -> 19720.61 | F93: =SUM(F10:F91) -> 20791.33 | G93: =SUM(G10:G91) -> 293892.73 | H93: =SUM(H10:H91) -> 1716.52 | I93: =SUM(I10:I91) -> 514.96 | J93: =SUM(J10:J91) -> 296124.21 | ... AF93: =SUM(AF10:AF91) -> 16198.07
A95: 83 | B95: Nomina
A96: 0 | B96: Altas | I96: FACTURACION PITS | K96: VENTAS | L96: ADMINISTRACION | M96: SERVICIO
A97: 1 | B97: Bajas | I97: Devengado Salario | J97: =+U93 -> 232670.6 | K97: =U13 -> 1314.8 | L97: 0 | M97: =J97-L97-K97 -> 231355.8
A98: =+A95+A96-A97 -> 82 | B98: Total Nomina | I98: RETORNOS | J98: =+R93-R77 -> 4900.61 | M98: =J98 -> 4900.61
I99: Infonavit | J99: =+K93+L93+M93 -> 32692.87 | K99: =L13 -> 977.57 | L99: 0 | M99: =J99-K99 -> 31715.3
I100: Prestamo Prospera | J100: =+Q93 -> 1236.6 | M100: =J100 -> 1236.6
I101: Subtotal 1 | J101: =SUM(J97:J100) -> 271500.68 | K101: =SUM(K97:K100) -> 2292.37 | L101: =SUM(L97:L100) -> 0 | M101: =SUM(M97:M100) -> 269208.31
I102: Comision | J102: =+J101*2% -> 5430.0136 | K102: =K101*2% -> 45.8474 | L102: =L101*2% -> 0 | M102: =M101*2% -> 5384.1662
I103: Subtotal 2 | J103: =+J101+J102 -> 276930.69 | K103: =K102+K101 -> 2338.2174 | L103: =L102+L101 -> 0 | M103: =M102+M101 -> 274592.48
I104: Costo Patronal Imss | J104: =+P93+V93+W93+X93+Y93+AA93+AC93+AD93 -> 108425.64 | K104: =P13+V13+W13+X13+Y13+AA13+AC13+AD13 -> 1068.81 | L104: 0 | M104: =J104-K104-L104 -> 107356.83
I105: 2% Sobre Nomina | J105: =+J93*2% -> 5922.4842 | K105: =J13*2% -> 46.2 | L105: 0 | M105: =J105-L105-K105 -> 5876.2842
I106: Importe de Factura | J106: =+J103+J104+J105 -> 391278.82 | K106: =K105+K104+K103 -> 3453.2274 | L106: 0 | M106: =M105+M104+M103 -> 387825.59
I107: IVA | J107: =+J106*16% -> 62604.611 | K107: =K106*0.16 -> 552.51638 | L107: =L106*0.16 -> 0 | M107: =M106*0.16 -> 62052.094
I108: TOTAL | J108: =+J106+J107 -> 453883.43 | K108: =K107+K106 -> 4005.7438 | L108: =L107+L106 -> 0 | M108: =M107+M106 -> 449877.68
K109: =K106-K102 -> 3407.38 | L109: =L106-L102 -> 0 | M109: =M106-M102 -> 382441.42
I110: PROVISION AGUINALDO
I111: FACTURACION PITS
I112: Subtotal 1 | J112: =+AF93 -> 16198.07 | L112: 0.73 | M112: 0.11 | N112: 0.12 | O112: 0.04
I113: Comision | J113: =+J112*2% -> 323.9614 | L113: ITA | M113: IP | N113: CPD | O113: EM
I114: Subtotal 2 | J114: =+J112+J113 -> 16522.031 | K114: SERVICIO | L114: =M109*$L$112 -> 279182.24 | M114: =M109*$M$112 -> 42068.557 | N114: =M109*$N$112 -> 45892.971 | O114: =M109*$O$112 -> 15297.657
...

Sheet SIND PITS
D1: SINDICATO | J1: PRIMA VACACIONAL
A2: CLAVE | B2: EMPRESA | C2: NOMBRE | D2: SUELDO SINDICATO | E2: BONO | F2: COMISION | G2: prima vacaciones | H2: TOTAL | J2: DIAS DE VACACIONES | K2: SUELDO NETO MENSUAL | L2: MONTO PRIMA TOTAL | M2: MENOS PRIMA IMSS | N2: PRIMA A PAGAR SINDICATO
A3: SEI0097 | B3: CONSULTORIA | C3: Arreola Jimenez Jose Nieves | D3: 1558.02 | E3: 420 | F3: 0 | G3: =+N3 -> 0 | H3: =SUM(D3:G3) -> 1978.02 | J3: =VLOOKUP($C3,'CPD PITSS'!$B$10:$V$27,3,0) -> 0 | K3: 10150 | L3: =(((+K3/30)*J3)*30%) -> 0 | M3: =VLOOKUP($C3,'CPD PITSS'!$B$10:$V$27,8,0) -> 0 | N3: =+L3-M3 -> 0 | O3: SEI0097 | P3: =VLOOKUP(C3,'RESUMEN PITS'!$C$3:$V$102,20,0) -> -56.562642 | Q3: =+D3+P3 -> 1501.4574
A4: SEI0118 | B4: CONSULTORIA | C4: Arroyo Ramirez Hector Hugo | D4: 2102.72 | F4: 0 | G4: =+N4 -> 0 | H4: =SUM(D4:G4) -> 2102.72 | J4: =VLOOKUP($C4,'CPD PITSS'!$B$10:$V$27,3,0) -> 0 | K4: 13000 | L4: =(((+K4/30)*J4)*30%) -> 0 | M4: =VLOOKUP($C4,'CPD PITSS'!$B$10:$V$27,8,0) -> 0 | N4: =+L4-M4 -> 0 | O4: SEI0118 | P4: =VLOOKUP(C4,'RESUMEN PITS'!$C$3:$V$102,20,0) -> -56.562642 | Q4: =+D4+P4 -> 2046.1574
A5: SEI0377 | B5: CONSULTORIA | C5: Benavides Herrera Alejandra | D5: 16803.4 | F5: 0 | G5: =+N5 -> 0 | H5: =SUM(D5:G5) -> 16803.4 | J5: =VLOOKUP($C5,'CPD PITSS'!$B$10:$V$27,3,0) -> 0 | K5: 40000 | L5: =(((+K5/30)*J5)*30%) -> 0 | M5: =VLOOKUP($C5,'CPD PITSS'!$B$10:$V$27,8,0) -> 0 | N5: =+L5-M5 -> 0 | O5: SEI0377 | P5: =VLOOKUP(C5,'RESUMEN PITS'!$C$3:$V$102,20,0) -> -56.562642 | Q5: =+D5+P5 -> 16746.837
A6: SEI0108 | B6: CONSULTORIA | C6: Caballero Diaz Francisco Javier | D6: 1558.11 | E6: 210 | F6: 0 | G6: =+N6 -> 274.51 | H6: =SUM(D6:G6) -> 2042.62 | J6: =VLOOKUP($C6,'CPD PITSS'!$B$10:$V$27,3,0) -> 6 | K6: 10150 | L6: =(((+K6/30)*J6)*30%) -> 609 | M6: =VLOOKUP($C6,'CPD PITSS'!$B$10:$V$27,8,0) -> 334.49 | N6: =+L6-M6 -> 274.51 | O6: SEI0108 | P6: =VLOOKUP(C6,'RESUMEN PITS'!$C$3:$V$102,20,0) -> -56.562642 | Q6: =+D6+P6 -> 1501.5474
A7: SEI0425 | B7: CONSULTORIA | C7: Carbajal Cabuto Jose Luis | D7: 1608.06 | E7: 210 | F7: 0 | G7: =+N7 -> 280.51 | H7: =SUM(D7:G7) -> 2098.57 | J7: =VLOOKUP($C7,'CPD PITSS'!$B$10:$V$27,3,0) -> 6 | K7: 10250 | L7: =(((+K7/30)*J7)*30%) -> 615 | M7: =VLOOKUP($C7,'CPD PITSS'!$B$10:$V$27,8,0) -> 334.49 | N7: =+L7-M7 -> 280.51 | O7: SEI0453 | P7: =VLOOKUP(C7,'RESUMEN PITS'!$C$3:$V$102,20,0) -> -56.562642 | Q7: =+D7+P7 -> 1551.4974
A8: SEI0116 | B8: CONSULTORIA | C8: Casillas Cardona Cesar Alejandro | D8: 1891.17 | F8: 0 | G8: =+N8 -> 107.5 | H8: =SUM(D8:G8) -> 1998.67 | J8: =VLOOKUP($C8,'CPD PITSS'!$B$10:$V$27,3,0) -> 2 | K8: 12000 | L8: =(((+K8/30)*J8)*30%) -> 240 | M8: =VLOOKUP($C8,'CPD PITSS'!$B$10:$V$27,8,0) -> 132.5 | N8: =+L8-M8 -> 107.5 | O8: SEI0116 | P8: =VLOOKUP(C8,'RESUMEN PITS'!$C$3:$V$102,20,0) -> -56.562642 | Q8: =+D8+P8 -> 1834.6074
A9: SEI0401 | B9: CONSULTORIA | C9: De La Torre Zambara Francisco Ernesto | D9: 1557.95 | E9: 60 | F9: 0 | G9: =+N9 -> 45.75 | H9: =SUM(D9:G9) -> 1663.7 | J9: =VLOOKUP($C9,'CPD PITSS'!$B$10:$V$27,3,0) -> 1 | K9: 10150 | L9: =(((+K9/30)*J9)*30%) -> 101.5 | M9: =VLOOKUP($C9,'CPD PITSS'!$B$10:$V$27,8,0) -> 55.75 | N9: =+L9-M9 -> 45.75 | O9: SEI0401 | P9: =VLOOKUP(C9,'RESUMEN PITS'!$C$3:$V$102,20,0) -> -56.562642 | Q9: =+D9+P9 -> 1501.3874
A10: SEI0099 | B10: CONSULTORIA | C10: Garcia Villicaña Ricardo Pascual | D10: 2600.2 | F10: 0 | G10: =+N10 -> 0 | H10: =SUM(D10:G10) -> 2600.2 | J10: =VLOOKUP($C10,'CPD PITSS'!$B$10:$V$27,3,0) -> 0 | K10: 15000 | L10: =(((+K10/30)*J10)*30%) -> 0 | M10: =VLOOKUP($C10,'CPD PITSS'!$B$10:$V$27,8,0) -> 0 | N10: =+L10-M10 -> 0 | O10: SEI0099 | P10: =VLOOKUP(C10,'RESUMEN PITS'!$C$3:$V$102,20,0) -> -1417.0416 | Q10: =+D10+P10 -> 1183.1584
A11: SEI0009 | B11: CONSULTORIA | C11: Gutierrez Gutierrez Luis Arturo | D11: 1475.6 | F11: 0 | G11: =+N11 -> 0 | H11: =SUM(D11:G11) -> 1475.6 | J11: =VLOOKUP($C11,'CPD PITSS'!$B$10:$V$27,3,0) -> 0 | K11: 8500 | L11: =(((+K11/30)*J11)*30%) -> 0 | M11: =VLOOKUP($C11,'CPD PITSS'!$B$10:$V$27,8,0) -> 0 | N11: =+L11-M11 -> 0 | O11: SEI0009 | P11: =VLOOKUP(C11,'RESUMEN PITS'!$C$3:$V$102,20,0) -> -1417.0416 | Q11: =+D11+P11 -> 58.558358
A12: SEI0127 | B12: CONSULTORIA | C12: Hernandez Ochoa Eduardo | D12: 2600.2 | E12: 337.5 | F12: 0 | G12: =+N12 -> 0 | H12: =SUM(D12:G12) -> 2937.7 | J12: =VLOOKUP($C12,'CPD PITSS'!$B$10:$V$27,3,0) -> 0 | K12: 15000 | L12: =(((+K12/30)*J12)*30%) -> 0 | M12: =VLOOKUP($C12,'CPD PITSS'!$B$10:$V$27,8,0) -> 0 | N12: =+L12-M12 -> 0 | O12: SEI0127 | P12: =VLOOKUP(C12,'RESUMEN PITS'!$C$3:$V$102,20,0) -> -1417.0416 | Q12: =+D12+P12 -> 1183.1584
A13: SEI0117 | B13: CONSULTORIA | C13: Mariscal Romero Luis Adrian | D13: 2751.08 | F13: 0 | G13: =+N13 -> 0 | H13: =SUM(D13:G13) -> 2751.08 | J13: =VLOOKUP($C13,'CPD PITSS'!$B$10:$V$27,3,0) -> 0 | K13: 15000 | L13: =(((+K13/30)*J13)*30%) -> 0 | M13: =VLOOKUP($C13,'CPD PITSS'!$B$10:$V$27,8,0) -> 0 | N13: =+L13-M13 -> 0 | O13: SEI0117 | P13: =VLOOKUP(C13,'RESUMEN PITS'!$C$3:$V$102,20,0) -> -1915.9536 | Q13: =+D13+P13 -> 835.12636
A14: SEI0040 | B14: CONSULTORIA | C14: Mora Ramirez Acal Aldo Isidro | D14: 2464 | E14: 1000 | F14: 0 | G14: =+N14 -> 195 | H14: =SUM(D14:G14) -> 3659 | J14: =VLOOKUP($C14,'CPD PITSS'!$B$10:$V$27,3,0) -> 3 | K14: 13000 | L14: =(((+K14/30)*J14)*30%) -> 390 | M14: =VLOOKUP($C14,'CPD PITSS'!$B$10:$V$27,8,0) -> 195 | N14: =+L14-M14 -> 195 | O14: SEI0040 | P14: =VLOOKUP(C14,'RESUMEN PITS'!$C$3:$V$102,20,0) -> -1915.9536 | Q14: =+D14+P14 -> 548.04636
A15: SEI0088 | B15: CONSULTORIA | C15: Morgado Fernandez Martin | D15: 2600.25 | E15: 75 | F15: 0 | G15: =+N15 -> 0 | H15: =SUM(D15:G15) -> 2675.25 | J15: =VLOOKUP($C15,'CPD PITSS'!$B$10:$V$27,3,0) -> 0 | K15: 15000 | L15: =(((+K15/30)*J15)*30%) -> 0 | M15: =VLOOKUP($C15,'CPD PITSS'!$B$10:$V$27,8,0) -> 0 | N15: =+L15-M15 -> 0 | O15: SEI0088 | P15: =VLOOKUP(C15,'RESUMEN PITS'!$C$3:$V$102,20,0) -> -1344.8726 | Q15: =+D15+P15 -> 1255.3774
A16: SEI0173 | B16: CONSULTORIA | C16: Nieto Ortiz Jose Luis | D16: 1483.15 | E16: 30 | F16: 0 | G16: =+N16 -> 0 | H16: =SUM(D16:G16) -> 1513.15 | J16: =VLOOKUP($C16,'CPD PITSS'!$B$10:$V$27,3,0) -> 0 | K16: 10000 | L16: =(((+K16/30)*J16)*30%) -> 0 | M16: =VLOOKUP($C16,'CPD PITSS'!$B$10:$V$27,8,0) -> 0 | N16: =+L16-M16 -> 0 | O16: SEI0173 | P16: =VLOOKUP(C16,'RESUMEN PITS'!$C$3:$V$102,20,0) -> -1344.8726 | Q16: =+D16+P16 -> 138.27736
A17: SEI0026 | B17: CONSULTORIA | C17: Patricio Aguilar Jhonattan Cristian | D17: 1588.2 | E17: 400 | F17: 0 | G17: =+N17 -> 0 | H17: =SUM(D17:G17) -> 1988.2 | J17: =VLOOKUP($C17,'CPD PITSS'!$B$10:$V$27,3,0) -> 0 | K17: 9000 | L17: =(((+K17/30)*J17)*30%) -> 0 | M17: =VLOOKUP($C17,'CPD PITSS'!$B$10:$V$27,8,0) -> 0 | N17: =+L17-M17 -> 0 | O17: SEI0026 | P17: =VLOOKUP(C17,'RESUMEN PITS'!$C$3:$V$102,20,0) -> -1344.8726 | Q17: =+D17+P17 -> 243.32736
A18: SEI0221 | B18: CONSULTORIA | C18: Rogel Teran Marco Antonio | D18: 12613.2 | F18: 0 | G18: =+N18 -> 0 | H18: =SUM(D18:G18) -> 12613.2 | J18: =VLOOKUP($C18,'CPD PITSS'!$B$10:$V$27,3,0) -> 0 | K18: 60000 | L18: =(((+K18/30)*J18)*30%) -> 0 | M18: =VLOOKUP($C18,'CPD PITSS'!$B$10:$V$27,8,0) -> 0 | N18: =+L18-M18 -> 0 | O18: SEI0221 | P18: =VLOOKUP(C18,'RESUMEN PITS'!$C$3:$V$102,20,0) -> -1344.8726 | Q18: =+D18+P18 -> 11268.327
A19: SEI0442 | B19: CONSULTORIA | C19: Sierra Escamilla Daniela | D19: 2463.8 | E19: 1000 | F19: 0 | G19: =+N19 -> 0 | H19: =SUM(D19:G19) -> 3463.8 | J19: =VLOOKUP($C19,'CPD PITSS'!$B$10:$V$27,3,0) -> 0 | K19: 13000 | L19: =(((+K19/30)*J19)*30%) -> 0 | M19: =VLOOKUP($C19,'CPD PITSS'!$B$10:$V$27,8,0) -> 0 | N19: =+L19-M19 -> 0 | O19: SEI0618 | P19: =VLOOKUP(C19,'RESUMEN PITS'!$C$3:$V$102,20,0) -> -1344.8726 | Q19: =+D19+P19 -> 1118.9274
A20: SEI0041 | B20: CONSULTORIA | C20: Vazquez Perez Miguel Angel | D20: 4176 | E20: 750 | F20: 0 | G20: =+N20 -> 0 | H20: =SUM(D20:G20) -> 4926 | J20: =VLOOKUP($C20,'CPD PITSS'!$B$10:$V$27,3,0) -> 0 | K20: 18500 | L20: =(((+K20/30)*J20)*30%) -> 0 | M20: =VLOOKUP($C20,'CPD PITSS'!$B$10:$V$27,8,0) -> 0 | N20: =+L20-M20 -> 0 | O20: SEI0041 | P20: =VLOOKUP(C20,'RESUMEN PITS'!$C$3:$V$102,20,0) -> -1537.7236 | Q20: =+D20+P20 -> 2638.2764
A21: SEI0544 | B21: IP INNOVACION | C21: Aguilar Aguirre Alfonso | D21: 135.2 | F21: 0 | H21: =SUM(D21:G21) -> 135.2 | J21: =VLOOKUP(C21,'IP PITSS'!$B$10:$U$91,3,0) -> 0 | K21: 6000 | L21: =(((+K21/30)*J21)*30%) -> 0 | M21: =VLOOKUP(C21,'IP PITSS'!$B$10:$I$91,8,0) -> 0 | N21: =+L21-M21 -> 0 | O21: SEI0652 | P21: =VLOOKUP(C21,'RESUMEN PITS'!$C$3:$V$102,20,0) -> -56.562642 | Q21: =+D21+P21 -> 78.637358
A22: SEI0527 | B22: IP INNOVACION | C22: Alejandro Peña Deivi | D22: 175.6 | E22: 900 | F22: 0 | G22: =+N22 -> 0 | H22: =SUM(D22:G22) -> 1075.6 | J22: =VLOOKUP(C22,'IP PITSS'!$B$10:$U$91,3,0) -> 0 | K22: 6300 | L22: =(((+K22/30)*J22)*30%) -> 0 | M22: =VLOOKUP(C22,'IP PITSS'!$B$10:$I$91,8,0) -> 0 | N22: =+L22-M22 -> 0 | O22: SEI0628 | P22: =VLOOKUP(C22,'RESUMEN PITS'!$C$3:$V$102,20,0) -> -56.562642 | Q22: =+D22+P22 -> 119.03736
A23: SEI0535 | B23: IP INNOVACION | C23: Alejandro Vazquez Erasmo Miguel | D23: 3135.15 | E23: 750 | F23: 0 | G23: =+N23 -> 0 | H23: =SUM(D23:G23) -> 3885.15 | J23: =VLOOKUP(C23,'IP PITSS'!$B$10:$U$91,3,0) -> 0 | K23: 12000 | L23: =(((+K23/30)*J23)*30%) -> 0 | M23: =VLOOKUP(C23,'IP PITSS'!$B$10:$I$91,8,0) -> 0 | N23: =+L23-M23 -> 0 | O23: SEI0638 | P23: =VLOOKUP(C23,'RESUMEN PITS'!$C$3:$V$102,20,0) -> -56.562642 | Q23: =+D23+P23 -> 3078.5874
A24: SEI0029 | B24: IP INNOVACION | C24: Arceo Garcia Manuel Federico | D24: =309.8-210+150 -> 249.8 | E24: 1000 | F24: 0 | G24: =+N24 -> 3 | H24: =SUM(D24:G24) -> 1252.8 | J24: =VLOOKUP(C24,'IP PITSS'!$B$10:$U$91,3,0) -> 1 | K24: 6300 | L24: =(((+K24/30)*J24)*30%) -> 63 | M24: =VLOOKUP(C24,'IP PITSS'!$B$10:$I$91,8,0) -> 60 | N24: =+L24-M24 -> 3 | O24: SEI0029 | P24: =VLOOKUP(C24,'RESUMEN PITS'!$C$3:$V$102,20,0) -> 153.43736 | Q24: =+D24+P24 -> 403.23736
A25: SEI0472 | B25: IP INNOVACION | C25: Arzate Gil Juan Sebastian | D25: 416.4 | E25: 510 | F25: 0 | G25: =+N25 -> 0 | H25: =SUM(D25:G25) -> 926.4 | J25: =VLOOKUP(C25,'IP PITSS'!$B$10:$U$91,3,0) -> 0 | K25: 8000 | L25: =(((+K25/30)*J25)*30%) -> 0 | M25: =VLOOKUP(C25,'IP PITSS'!$B$10:$I$91,8,0) -> 0 | N25: =+L25-M25 -> 0 | O25: SEI0550 | P25: =VLOOKUP(C25,'RESUMEN PITS'!$C$3:$V$102,20,0) -> -56.562642 | Q25: =+D25+P25 -> 359.83736
A26: SEI0528 | B26: IP INNOVACION | C26: Casas Chavarria Rafael | D26: 175.72 | E26: 1350 | F26: 0 | G26: =+N26 -> 0 | H26: =SUM(D26:G26) -> 1525.72 | J26: =VLOOKUP(C26,'IP PITSS'!$B$10:$U$91,3,0) -> 0 | K26: 6300 | L26: =(((+K26/30)*J26)*30%) -> 0 | M26: =VLOOKUP(C26,'IP PITSS'!$B$10:$I$91,8,0) -> 0 | N26: =+L26-M26 -> 0 | O26: SEI0629 | P26: =VLOOKUP(C26,'RESUMEN PITS'!$C$3:$V$102,20,0) -> -56.562642 | Q26: =+D26+P26 -> 119.15736
A27: SEI0460 | B27: IP INNOVACION | C27: Castellon Ramos Rene | D27: 384.785 | E27: 70 | F27: 0 | G27: =+N27 -> 0 | H27: =SUM(D27:G27) -> 454.785 | J27: =VLOOKUP(C27,'IP PITSS'!$B$10:$U$91,3,0) -> 0 | K27: 7505.99 | L27: =(((+K27/30)*J27)*30%) -> 0 | M27: =VLOOKUP(C27,'IP PITSS'!$B$10:$I$91,8,0) -> 0 | N27: =+L27-M27 -> 0 | O27: SEI0499 | P27: =VLOOKUP(C27,'RESUMEN PITS'!$C$3:$V$102,20,0) -> -56.562642 | Q27: =+D27+P27 -> 328.22236
A28: SEI0443 | B28: IP INNOVACION | C28: Castillo Nungaray Nestor Roman | D28: =135.2+150 -> 285.2 | E28: 800 | F28: 0 | G28: =+N28 -> 0 | H28: =SUM(D28:G28) -> 1085.2 | J28: =VLOOKUP(C28,'IP PITSS'!$B$10:$U$91,3,0) -> 0 | K28: 6300 | L28: =(((+K28/30)*J28)*30%) -> 0 | M28: =VLOOKUP(C28,'IP PITSS'!$B$10:$I$91,8,0) -> 0 | N28: =+L28-M28 -> 0 | O28: SEI0468 | P28: =VLOOKUP(C28,'RESUMEN PITS'!$C$3:$V$102,20,0) -> -56.562642 | Q28: =+D28+P28 -> 228.63736
A29: SEI0490 | B29: IP INNOVACION | C29: Castillo Ramirez Hector Ivan | D29: 3721.2 | E29: 281.25 | F29: 0 | G29: =+N29 -> 0 | H29: =SUM(D29:G29) -> 4002.45 | J29: =VLOOKUP(C29,'IP PITSS'!$B$10:$U$91,3,0) -> 0 | K29: 14000 | L29: =(((+K29/30)*J29)*30%) -> 0 | M29: =VLOOKUP(C29,'IP PITSS'!$B$10:$I$91,8,0) -> 0 | N29: =+L29-M29 -> 0 | O29: SEI0448 | P29: =VLOOKUP(C29,'RESUMEN PITS'!$C$3:$V$102,20,0) -> -56.562642 | Q29: =+D29+P29 -> 3664.6374
A30: SEI0508 | B30: IP INNOVACION | C30: Cerro Garcia Elvis | D30: 2553.4 | E30: 400 | F30: 0 | G30: =+N30 -> 0 | H30: =SUM(D30:G30) -> 2953.4 | J30: =VLOOKUP(C30,'IP PITSS'!$B$10:$U$91,3,0) -> 0 | K30: 10000 | L30: =(((+K30/30)*J30)*30%) -> 0 | M30: =VLOOKUP(C30,'IP PITSS'!$B$10:$I$91,8,0) -> 0 | N30: =+L30-M30 -> 0 | O30: SEI0513 | P30: =VLOOKUP(C30,'RESUMEN PITS'!$C$3:$V$102,20,0) -> -56.562642 | Q30: =+D30+P30 -> 2496.8374
A31: SEI0499 | B31: IP INNOVACION | C31: Chavez Dominguez Salvador | D31: 2667.4 | E31: 500 | F31: 0 | G31: =+N31 -> 0 | H31: =SUM(D31:G31) -> 3167.4 | J31: =VLOOKUP(C31,'IP PITSS'!$B$10:$U$91,3,0) -> 0 | K31: 12000 | L31: =(((+K31/30)*J31)*30%) -> 0 | M31: =VLOOKUP(C31,'IP PITSS'!$B$10:$I$91,8,0) -> 0 | N31: =+L31-M31 -> 0 | O31: SEI0483 | P31: =VLOOKUP(C31,'RESUMEN PITS'!$C$3:$V$102,20,0) -> -56.562642 | Q31: =+D31+P31 -> 2610.8374
A32: SEI0541 | B32: IP INNOVACION | C32: Chavez Govea Edgar Aram | D32: 222.6 | E32: 187.5 | F32: 0 | G32: =+N32 -> 0 | H32: =SUM(D32:G32) -> 410.1 | J32: =VLOOKUP(C32,'IP PITSS'!$B$10:$U$91,3,0) -> 0 | K32: 7000 | L32: =(((+K32/30)*J32)*30%) -> 0 | M32: =VLOOKUP(C32,'IP PITSS'!$B$10:$I$91,8,0) -> 0 | N32: =+L32-M32 -> 0 | O32: SEI0644 | P32: =VLOOKUP(C32,'RESUMEN PITS'!$C$3:$V$102,20,0) -> -56.562642 | Q32: =+D32+P32 -> 166.03736
A33: SEI0442 | B33: IP INNOVACION | C33: Chavez Pedraza Samuel | D33: 1047.8 | E33: 312.5 | F33: 0 | G33: =+N33 -> 0 | H33: =SUM(D33:G33) -> 1360.3 | J33: =VLOOKUP(C33,'IP PITSS'!$B$10:$U$91,3,0) -> 0 | K33: 14000 | L33: =(((+K33/30)*J33)*30%) -> 0 | M33: =VLOOKUP(C33,'IP PITSS'!$B$10:$I$91,8,0) -> 0 | N33: =+L33-M33 -> 0 | O33: SEI0467 | P33: =VLOOKUP(C33,'RESUMEN PITS'!$C$3:$V$102,20,0) -> -56.562642 | Q33: =+D33+P33 -> 991.23736
A34: SEI0462 | B34: IP INNOVACION | C34: Chavez Saucedo Jorge Arturo | D34: 414.6 | E34: 600 | F34: 0 | G34: =+N34 -> 0 | H34: =SUM(D34:G34) -> 1014.6 | J34: =VLOOKUP(C34,'IP PITSS'!$B$10:$U$91,3,0) -> 0 | K34: 8000 | L34: =(((+K34/30)*J34)*30%) -> 0 | M34: =VLOOKUP(C34,'IP PITSS'!$B$10:$I$91,8,0) -> 0 | N34: =+L34-M34 -> 0 | O34: SEI0516 | P34: =VLOOKUP(C34,'RESUMEN PITS'!$C$3:$V$102,20,0) -> -56.562642 | Q34: =+D34+P34 -> 358.03736
A35: SEI0456 | B35: IP INNOVACION | C35: Chavira Garcia David Fernando | D35: 593.6 | E35: 60 | F35: 0 | G35: =+N35 -> 0 | H35: =SUM(D35:G35) -> 653.6 | J35: =VLOOKUP(C35,'IP PITSS'!$B$10:$U$91,3,0) -> 0 | K35: 10000 | L35: =(((+K35/30)*J35)*30%) -> 0 | M35: =VLOOKUP(C35,'IP PITSS'!$B$10:$I$91,8,0) -> 0 | N35: =+L35-M35 -> 0 | O35: SEI0495 | P35: =VLOOKUP(C35,'RESUMEN PITS'!$C$3:$V$102,20,0) -> -56.562642 | Q35: =+D35+P35 -> 537.03736
A36: SEI0015 | B36: IP INNOVACION | C36: Cota Jaramillo Miguel Angel | D36: 134 | E36: 337.5 | F36: 0 | G36: =+N36 -> 0 | H36: =SUM(D36:G36) -> 471.5 | J36: =VLOOKUP(C36,'IP PITSS'!$B$10:$U$91,3,0) -> 0 | K36: 6000 | L36: =(((+K36/30)*J36)*30%) -> 0 | M36: =VLOOKUP(C36,'IP PITSS'!$B$10:$I$91,8,0) -> 0 | N36: =+L36-M36 -> 0 | O36: SEI0015 | P36: =VLOOKUP(C36,'RESUMEN PITS'!$C$3:$V$102,20,0) -> -56.562642 | Q36: =+D36+P36 -> 77.437358
A37: SEI0413 | B37: IP INNOVACION | C37: Courtenay Gutierrez Barry Vladimir | D37: 52.4 | E37: 250 | F37: 2800 | G37: =+N37 -> 0 | H37: =SUM(D37:G37) -> 3102.4 | J37: =VLOOKUP(C37,'IP PITSS'!$B$10:$U$91,3,0) -> 0 | K37: 5000 | L37: =(((+K37/30)*J37)*30%) -> 0 | M37: =VLOOKUP(C37,'IP PITSS'!$B$10:$I$91,8,0) -> 0 | N37: =+L37-M37 -> 0 | O37: SEI0436 | P37: =VLOOKUP(C37,'RESUMEN PITS'!$C$3:$V$102,20,0) -> -56.562642 | Q37: =+D37+P37 -> -4.1626417
A38: SEI0501 | B38: IP INNOVACION | C38: Cruz Herrera Roberto | D38: 1667.29 | E38: 90 | F38: 0 | G38: =+N38 -> 0 | H38: =SUM(D38:G38) -> 1757.29 | J38: =VLOOKUP(C38,'IP PITSS'!$B$10:$U$91,3,0) -> 0 | K38: 10000 | L38: =(((+K38/30)*J38)*30%) -> 0 | M38: =VLOOKUP(C38,'IP PITSS'!$B$10:$I$91,8,0) -> 0 | N38: =+L38-M38 -> 0 | O38: SEI0485 | P38: =VLOOKUP(C38,'RESUMEN PITS'!$C$3:$V$102,20,0) -> -56.562642 | Q38: =+D38+P38 -> 1610.7274
A39: SEI479 | B39: IP INNOVACION | C39: Cruz Perez Alejandro Nezahualcoyotl | D39: 416.4 | E39: 570 | F39: 0 | G39: =+N39 -> 0 | H39: =SUM(D39:G39) -> 986.4 | J39: =VLOOKUP(C39,'IP PITSS'!$B$10:$U$91,3,0) -> 0 | K39: 8000 | L39: =(((+K39/30)*J39)*30%) -> 0 | M39: =VLOOKUP(C39,'IP PITSS'!$B$10:$I$91,8,0) -> 0 | N39: =+L39-M39 -> 0 | O39: SEI0606 | P39: =VLOOKUP(C39,'RESUMEN PITS'!$C$3:$V$102,20,0) -> -56.562642 | Q39: =+D39+P39 -> 359.83736
A40: SEI0530 | B40: IP INNOVACION | C40: Del Pilar Mendez Lucio | D40: 134 | E40: 363.75 | F40: 0 | G40: =+N40 -> 0 | H40: =SUM(D40:G40) -> 497.75 | J40: =VLOOKUP(C40,'IP PITSS'!$B$10:$U$91,3,0) -> 0 | K40: 6000 | L40: =(((+K40/30)*J40)*30%) -> 0 | M40: =VLOOKUP(C40,'IP PITSS'!$B$10:$I$91,8,0) -> 0 | N40: =+L40-M40 -> 0 | O40: SEI0630 | P40: =VLOOKUP(C40,'RESUMEN PITS'!$C$3:$V$102,20,0) -> -56.562642 | Q40: =+D40+P40 -> 77.437358
...

Sheet RESUMEN PITS
F1: SINDICATO
A2: CLAVE | B2: EMPRESA | C2: NOMBRE | D2: NETO IMSS | F2: SUELDO SINDICATO | G2: BONO | H2: COMISION | I2: PRIMA VACACIONAL SINDICATO | J2: B | K2: NETO A PAGAR | L2: NETO MENSUAL | M2: NETO QUINCENAL SEITON | N2: C | O2: prima vacacional | P2: COMISION Y PRIMA VACACIONAL | Q2: INFONAVIT | R2: FONACOT | S2: DESCUENTOS | T2: D | U2: TOTAL GENERAL | V2: DIFERENCIAS | W2: OBSERVACIONES
A3: SEI0009 | B3: CONSULTORIA | C3: Gutierrez Gutierrez Luis Arturo | D3: =VLOOKUP(C3,'CPD PITSS'!B10:V27,21,0) -> 2774.4 | F3: =VLOOKUP(C3,'SIND PITS'!$C$3:$H$104,2,0) -> 1475.6 | G3: =VLOOKUP(C3,'SIND PITS'!$C$3:$E$104,3,0) -> 0 | H3: =VLOOKUP(C3,'SIND PITS'!$C$3:$F$104,4,0) -> 0 | I3: =VLOOKUP(C3,'SIND PITS'!$C$3:$G$104,5,0) -> 0 | K3: =SUM(D3:I3) -> 4250 | L3: 8500 | M3: =+L3/2 -> 4250 | O3: =VLOOKUP($C3,'CPD PITSS'!$B$10:$V$27,8,0) -> 0 | P3: =+G3+H3+I3 -> 0 | Q3: =(VLOOKUP($C3,'CPD PITSS'!$B$10:$V$27,13,0))+(VLOOKUP($C3,'CPD PITSS'!$B$10:$V$27,14,0)) -> 0 | S3: =VLOOKUP(C3,'CPD PITSS'!$B$10:$S$27,18,0) -> 0 | U3: =+K3-O3-P3+Q3+R3+S3+IFERROR(VLOOKUP('RESUMEN PITS'!C3,'IP PITSS'!$B$10:$M$91,10),0)+IFERROR(VLOOKUP('RESUMEN PITS'!C3,'IP PITSS'!$B$10:$M$91,11),0)+IFERROR(VLOOKUP('RESUMEN PITS'!C3,'IP PITSS'!$B$10:$M$91,12),0)+VLOOKUP("Comision",'IP PITSS'!$I$97:$J$108,2)/COUNT($F$9:$F$111)+IFERROR(VLOOKUP('RESUMEN PITS'!C3,'IP PITSS'!$B$10:$AD$91,15),0)+IFERROR(VLOOKUP('RESUMEN PITS'!C3,'IP PITSS'!$B$10:$AD$91,21),0)+IFERROR(VLOOKUP('RESUMEN PITS'!C3,'IP PITSS'!$B$10:$AD$91,22),0)+IFERROR(VLOOKUP('RESUMEN PITS'!C3,'IP PITSS'!$B$10:$AD$91,23),0)+IFERROR(VLOOKUP('RESUMEN PITS'!C3,'IP PITSS'!$B$10:$AD$91,24),0)+IFERROR(VLOOKUP('RESUMEN PITS'!C3,'IP PITSS'!$B$10:$AD$91,26),0)+IFERROR(VLOOKUP('RESUMEN PITS'!C3,'IP PITSS'!$B$10:$AD$91,28),0)+IFERROR(VLOOKUP('RESUMEN PITS'!C3,'IP PITSS'!$B$10:$AD$91,29),0)+IFERROR(VLOOKUP('RESUMEN PITS'!C3,'IP PITSS'!$B$10:$AD$91,9),0)*2% -> 5667.0416 | V3: =+M3-U3 -> -1417.0416 | X3: SEI0009
A4: SEI0026 | B4: CONSULTORIA | C4: Patricio Aguilar Jhonattan Cristian | D4: =VLOOKUP(C4,'CPD PITSS'!B11:V28,21,0) -> 2911.8 | F4: =VLOOKUP(C4,'SIND PITS'!$C$3:$H$104,2,0) -> 1588.2 | G4: =VLOOKUP(C4,'SIND PITS'!$C$3:$E$104,3,0) -> 400 | H4: =VLOOKUP(C4,'SIND PITS'!$C$3:$F$104,4,0) -> 0 | I4: =VLOOKUP(C4,'SIND PITS'!$C$3:$G$104,5,0) -> 0 | K4: =SUM(D4:I4) -> 4900 | L4: 9000 | M4: =+L4/2 -> 4500 | O4: =VLOOKUP($C4,'CPD PITSS'!$B$10:$V$27,8,0) -> 0 | P4: =+G4+H4+I4 -> 400 | Q4: =(VLOOKUP($C4,'CPD PITSS'!$B$10:$V$27,13,0))+(VLOOKUP($C4,'CPD PITSS'!$B$10:$V$27,14,0)) -> 0 | S4: =VLOOKUP(C4,'CPD PITSS'!$B$10:$S$27,18,0) -> 0 | U4: =+K4-O4-P4+Q4+R4+S4+IFERROR(VLOOKUP('RESUMEN PITS'!C4,'IP PITSS'!$B$10:$M$91,10),0)+IFERROR(VLOOKUP('RESUMEN PITS'!C4,'IP PITSS'!$B$10:$M$91,11),0)+IFERROR(VLOOKUP('RESUMEN PITS'!C4,'IP PITSS'!$B$10:$M$91,12),0)+VLOOKUP("Comision",'IP PITSS'!$I$97:$J$108,2)/COUNT($F$9:$F$111)+IFERROR(VLOOKUP('RESUMEN PITS'!C4,'IP PITSS'!$B$10:$AD$91,15),0)+IFERROR(VLOOKUP('RESUMEN PITS'!C4,'IP PITSS'!$B$10:$AD$91,21),0)+IFERROR(VLOOKUP('RESUMEN PITS'!C4,'IP PITSS'!$B$10:$AD$91,22),0)+IFERROR(VLOOKUP('RESUMEN PITS'!C4,'IP PITSS'!$B$10:$AD$91,23),0)+IFERROR(VLOOKUP('RESUMEN PITS'!C4,'IP PITSS'!$B$10:$AD$91,24),0)+IFERROR(VLOOKUP('RESUMEN PITS'!C4,'IP PITSS'!$B$10:$AD$91,26),0)+IFERROR(VLOOKUP('RESUMEN PITS'!C4,'IP PITSS'!$B$10:$AD$91,28),0)+IFERROR(VLOOKUP('RESUMEN PITS'!C4,'IP PITSS'!$B$10:$AD$91,29),0)+IFERROR(VLOOKUP('RESUMEN PITS'!C4,'IP PITSS'!$B$10:$AD$91,9),0)*2% -> 5844.8726 | V4: =+M4-U4 -> -1344.8726 | X4: SEI0026
A5: SEI0040 | B5: CONSULTORIA | C5: Mora Ramirez Acal Aldo Isidro | D5: =VLOOKUP(C5,'CPD PITSS'!B12:V29,21,0) -> 4231 | F5: =VLOOKUP(C5,'SIND PITS'!$C$3:$H$104,2,0) -> 2464 | G5: =VLOOKUP(C5,'SIND PITS'!$C$3:$E$104,3,0) -> 1000 | H5: =VLOOKUP(C5,'SIND PITS'!$C$3:$F$104,4,0) -> 0 | I5: =VLOOKUP(C5,'SIND PITS'!$C$3:$G$104,5,0) -> 195 | K5: =SUM(D5:I5) -> 7890 | L5: 13000 | M5: =+L5/2 -> 6500 | O5: =VLOOKUP($C5,'CPD PITSS'!$B$10:$V$27,8,0) -> 195 | P5: =+G5+H5+I5 -> 1195 | Q5: =(VLOOKUP($C5,'CPD PITSS'!$B$10:$V$27,13,0))+(VLOOKUP($C5,'CPD PITSS'!$B$10:$V$27,14,0)) -> 0 | S5: =VLOOKUP(C5,'CPD PITSS'!$B$10:$S$27,18,0) -> 0 | U5: =+K5-O5-P5+Q5+R5+S5+IFERROR(VLOOKUP('RESUMEN PITS'!C5,'IP PITSS'!$B$10:$M$91,10),0)+IFERROR(VLOOKUP('RESUMEN PITS'!C5,'IP PITSS'!$B$10:$M$91,11),0)+IFERROR(VLOOKUP('RESUMEN PITS'!C5,'IP PITSS'!$B$10:$M$91,12),0)+VLOOKUP("Comision",'IP PITSS'!$I$97:$J$108,2)/COUNT($F$9:$F$111)+IFERROR(VLOOKUP('RESUMEN PITS'!C5,'IP PITSS'!$B$10:$AD$91,15),0)+IFERROR(VLOOKUP('RESUMEN PITS'!C5,'IP PITSS'!$B$10:$AD$91,21),0)+IFERROR(VLOOKUP('RESUMEN PITS'!C5,'IP PITSS'!$B$10:$AD$91,22),0)+IFERROR(VLOOKUP('RESUMEN PITS'!C5,'IP PITSS'!$B$10:$AD$91,23),0)+IFERROR(VLOOKUP('RESUMEN PITS'!C5,'IP PITSS'!$B$10:$AD$91,24),0)+IFERROR(VLOOKUP('RESUMEN PITS'!C5,'IP PITSS'!$B$10:$AD$91,26),0)+IFERROR(VLOOKUP('RESUMEN PITS'!C5,'IP PITSS'!$B$10:$AD$91,28),0)+IFERROR(VLOOKUP('RESUMEN PITS'!C5,'IP PITSS'!$B$10:$AD$91,29),0)+IFERROR(VLOOKUP('RESUMEN PITS'!C5,'IP PITSS'!$B$10:$AD$91,9),0)*2% -> 8415.9536 | V5: =+M5-U5 -> -1915.9536 | X5: SEI0040
A6: SEI0041 | B6: CONSULTORIA | C6: Vazquez Perez Miguel Angel | D6: =VLOOKUP(C6,'CPD PITSS'!B13:V30,21,0) -> 5074 | F6: =VLOOKUP(C6,'SIND PITS'!$C$3:$H$104,2,0) -> 4176 | G6: =VLOOKUP(C6,'SIND PITS'!$C$3:$E$104,3,0) -> 750 | H6: =VLOOKUP(C6,'SIND PITS'!$C$3:$F$104,4,0) -> 0 | I6: =VLOOKUP(C6,'SIND PITS'!$C$3:$G$104,5,0) -> 0 | K6: =SUM(D6:I6) -> 10000 | L6: 18500 | M6: =+L6/2 -> 9250 | O6: =VLOOKUP($C6,'CPD PITSS'!$B$10:$V$27,8,0) -> 0 | P6: =+G6+H6+I6 -> 750 | Q6: =(VLOOKUP($C6,'CPD PITSS'!$B$10:$V$27,13,0))+(VLOOKUP($C6,'CPD PITSS'!$B$10:$V$27,14,0)) -> 0 | S6: =VLOOKUP(C6,'CPD PITSS'!$B$10:$S$27,18,0) -> 0 | U6: =+K6-O6-P6+Q6+R6+S6+IFERROR(VLOOKUP('RESUMEN PITS'!C6,'IP PITSS'!$B$10:$M$91,10),0)+IFERROR(VLOOKUP('RESUMEN PITS'!C6,'IP PITSS'!$B$10:$M$91,11),0)+IFERROR(VLOOKUP('RESUMEN PITS'!C6,'IP PITSS'!$B$10:$M$91,12),0)+VLOOKUP("Comision",'IP PITSS'!$I$97:$J$108,2)/COUNT($F$9:$F$111)+IFERROR(VLOOKUP('RESUMEN PITS'!C6,'IP PITSS'!$B$10:$AD$91,15),0)+IFERROR(VLOOKUP('RESUMEN PITS'!C6,'IP PITSS'!$B$10:$AD$91,21),0)+IFERROR(VLOOKUP('RESUMEN PITS'!C6,'IP PITSS'!$B$10:$AD$91,22),0)+IFERROR(VLOOKUP('RESUMEN PITS'!C6,'IP PITSS'!$B$10:$AD$91,23),0)+IFERROR(VLOOKUP('RESUMEN PITS'!C6,'IP PITSS'!$B$10:$AD$91,24),0)+IFERROR(VLOOKUP('RESUMEN PITS'!C6,'IP PITSS'!$B$10:$AD$91,26),0)+IFERROR(VLOOKUP('RESUMEN PITS'!C6,'IP PITSS'!$B$10:$AD$91,28),0)+IFERROR(VLOOKUP('RESUMEN PITS'!C6,'IP PITSS'!$B$10:$AD$91,29),0)+IFERROR(VLOOKUP('RESUMEN PITS'!C6,'IP PITSS'!$B$10:$AD$91,9),0)*2% -> 10787.724 | V6: =+M6-U6 -> -1537.7236 | X6: SEI0041
A7: SEI0088 | B7: CONSULTORIA | C7: Morgado Fernandez Martin | D7: =VLOOKUP(C7,'CPD PITSS'!B14:V31,21,0) -> 4623.8 | F7: =VLOOKUP(C7,'SIND PITS'!$C$3:$H$104,2,0) -> 2600.25 | G7: =VLOOKUP(C7,'SIND PITS'!$C$3:$E$104,3,0) -> 75 | H7: =VLOOKUP(C7,'SIND PITS'!$C$3:$F$104,4,0) -> 0 | I7: =VLOOKUP(C7,'SIND PITS'!$C$3:$G$104,5,0) -> 0 | K7: =SUM(D7:I7) -> 7299.05 | L7: 15000 | M7: =+L7/2 -> 7500 | O7: =VLOOKUP($C7,'CPD PITSS'!$B$10:$V$27,8,0) -> 0 | P7: =+G7+H7+I7 -> 75 | Q7: =(VLOOKUP($C7,'CPD PITSS'!$B$10:$V$27,13,0))+(VLOOKUP($C7,'CPD PITSS'!$B$10:$V$27,14,0)) -> 0 | S7: =VLOOKUP(C7,'CPD PITSS'!$B$10:$S$27,18,0) -> 275.95 | U7: =+K7-O7-P7+Q7+R7+S7+IFERROR(VLOOKUP('RESUMEN PITS'!C7,'IP PITSS'!$B$10:$M$91,10),0)+IFERROR(VLOOKUP('RESUMEN PITS'!C7,'IP PITSS'!$B$10:$M$91,11),0)+IFERROR(VLOOKUP('RESUMEN PITS'!C7,'IP PITSS'!$B$10:$M$91,12),0)+VLOOKUP("Comision",'IP PITSS'!$I$97:$J$108,2)/COUNT($F$9:$F$111)+IFERROR(VLOOKUP('RESUMEN PITS'!C7,'IP PITSS'!$B$10:$AD$91,15),0)+IFERROR(VLOOKUP('RESUMEN PITS'!C7,'IP PITSS'!$B$10:$AD$91,21),0)+IFERROR(VLOOKUP('RESUMEN PITS'!C7,'IP PITSS'!$B$10:$AD$91,22),0)+IFERROR(VLOOKUP('RESUMEN PITS'!C7,'IP PITSS'!$B$10:$AD$91,23),0)+IFERROR(VLOOKUP('RESUMEN PITS'!C7,'IP PITSS'!$B$10:$AD$91,24),0)+IFERROR(VLOOKUP('RESUMEN PITS'!C7,'IP PITSS'!$B$10:$AD$91,26),0)+IFERROR(VLOOKUP('RESUMEN PITS'!C7,'IP PITSS'!$B$10:$AD$91,28),0)+IFERROR(VLOOKUP('RESUMEN PITS'!C7,'IP PITSS'!$B$10:$AD$91,29),0)+IFERROR(VLOOKUP('RESUMEN PITS'!C7,'IP PITSS'!$B$10:$AD$91,9),0)*2% -> 8844.8726 | V7: =+M7-U7 -> -1344.8726 | X7: SEI0088
A8: SEI0097 | B8: CONSULTORIA | C8: Arreola Jimenez Jose Nieves | D8: =VLOOKUP(C8,'CPD PITSS'!B15:V32,21,0) -> 1975.2 | F8: =VLOOKUP(C8,'SIND PITS'!$C$3:$H$104,2,0) -> 1558.02 | G8: =VLOOKUP(C8,'SIND PITS'!$C$3:$E$104,3,0) -> 420 | H8: =VLOOKUP(C8,'SIND PITS'!$C$3:$F$104,4,0) -> 0 | I8: =VLOOKUP(C8,'SIND PITS'!$C$3:$G$104,5,0) -> 0 | K8: =SUM(D8:I8) -> 3953.22 | L8: 10150 | M8: =+L8/2 -> 5075 | O8: =VLOOKUP($C8,'CPD PITSS'!$B$10:$V$27,8,0) -> 0 | P8: =+G8+H8+I8 -> 420 | Q8: =(VLOOKUP($C8,'CPD PITSS'!$B$10:$V$27,13,0))+(VLOOKUP($C8,'CPD PITSS'!$B$10:$V$27,14,0)) -> 1541.78 | S8: =VLOOKUP(C8,'CPD PITSS'!$B$10:$S$27,18,0) -> 0 | U8: =+K8-O8-P8+Q8+R8+S8+IFERROR(VLOOKUP('RESUMEN PITS'!C8,'IP PITSS'!$B$10:$M$91,10),0)+IFERROR(VLOOKUP('RESUMEN PITS'!C8,'IP PITSS'!$B$10:$M$91,11),0)+IFERROR(VLOOKUP('RESUMEN PITS'!C8,'IP PITSS'!$B$10:$M$91,12),0)+VLOOKUP("Comision",'IP PITSS'!$I$97:$J$108,2)/COUNT($F$9:$F$111)+IFERROR(VLOOKUP('RESUMEN PITS'!C8,'IP PITSS'!$B$10:$AD$91,15),0)+IFERROR(VLOOKUP('RESUMEN PITS'!C8,'IP PITSS'!$B$10:$AD$91,21),0)+IFERROR(VLOOKUP('RESUMEN PITS'!C8,'IP PITSS'!$B$10:$AD$91,22),0)+IFERROR(VLOOKUP('RESUMEN PITS'!C8,'IP PITSS'!$B$10:$AD$91,23),0)+IFERROR(VLOOKUP('RESUMEN PITS'!C8,'IP PITSS'!$B$10:$AD$91,24),0)+IFERROR(VLOOKUP('RESUMEN PITS'!C8,'IP PITSS'!$B$10:$AD$91,26),0)+IFERROR(VLOOKUP('RESUMEN PITS'!C8,'IP PITSS'!$B$10:$AD$91,28),0)+IFERROR(VLOOKUP('RESUMEN PITS'!C8,'IP PITSS'!$B$10:$AD$91,29),0)+IFERROR(VLOOKUP('RESUMEN PITS'!C8,'IP PITSS'!$B$10:$AD$91,9),0)*2% -> 5131.5626 | V8: =+M8-U8 -> -56.562642 | X8: SEI0097
A9: SEI0099 | B9: CONSULTORIA | C9: Garcia Villicaña Ricardo Pascual | D9: =VLOOKUP(C9,'CPD PITSS'!B16:V33,21,0) -> 4899.8 | F9: =VLOOKUP(C9,'SIND PITS'!$C$3:$H$104,2,0) -> 2600.2 | G9: =VLOOKUP(C9,'SIND PITS'!$C$3:$E$104,3,0) -> 0 | H9: =VLOOKUP(C9,'SIND PITS'!$C$3:$F$104,4,0) -> 0 | I9: =VLOOKUP(C9,'SIND PITS'!$C$3:$G$104,5,0) -> 0 | K9: =SUM(D9:I9) -> 7500 | L9: 15000 | M9: =+L9/2 -> 7500 | O9: =VLOOKUP($C9,'CPD PITSS'!$B$10:$V$27,8,0) -> 0 | P9: =+G9+H9+I9 -> 0 | Q9: =(VLOOKUP($C9,'CPD PITSS'!$B$10:$V$27,13,0))+(VLOOKUP($C9,'CPD PITSS'!$B$10:$V$27,14,0)) -> 0 | S9: =VLOOKUP(C9,'CPD PITSS'!$B$10:$S$27,18,0) -> 0 | U9: =+K9-O9-P9+Q9+R9+S9+IFERROR(VLOOKUP('RESUMEN PITS'!C9,'IP PITSS'!$B$10:$M$91,10),0)+IFERROR(VLOOKUP('RESUMEN PITS'!C9,'IP PITSS'!$B$10:$M$91,11),0)+IFERROR(VLOOKUP('RESUMEN PITS'!C9,'IP PITSS'!$B$10:$M$91,12),0)+VLOOKUP("Comision",'IP PITSS'!$I$97:$J$108,2)/COUNT($F$9:$F$111)+IFERROR(VLOOKUP('RESUMEN PITS'!C9,'IP PITSS'!$B$10:$AD$91,15),0)+IFERROR(VLOOKUP('RESUMEN PITS'!C9,'IP PITSS'!$B$10:$AD$91,21),0)+IFERROR(VLOOKUP('RESUMEN PITS'!C9,'IP PITSS'!$B$10:$AD$91,22),0)+IFERROR(VLOOKUP('RESUMEN PITS'!C9,'IP PITSS'!$B$10:$AD$91,23),0)+IFERROR(VLOOKUP('RESUMEN PITS'!C9,'IP PITSS'!$B$10:$AD$91,24),0)+IFERROR(VLOOKUP('RESUMEN PITS'!C9,'IP PITSS'!$B$10:$AD$91,26),0)+IFERROR(VLOOKUP('RESUMEN PITS'!C9,'IP PITSS'!$B$10:$AD$91,28),0)+IFERROR(VLOOKUP('RESUMEN PITS'!C9,'IP PITSS'!$B$10:$AD$91,29),0)+IFERROR(VLOOKUP('RESUMEN PITS'!C9,'IP PITSS'!$B$10:$AD$91,9),0)*2% -> 8917.0416 | V9: =+M9-U9 -> -1417.0416 | X9: SEI0099
A10: SEI0108 | B10: CONSULTORIA | C10: Caballero Diaz Francisco Javier | D10: =VLOOKUP(C10,'CPD PITSS'!B17:V34,21,0) -> 1823.2 | F10: =VLOOKUP(C10,'SIND PITS'!$C$3:$H$104,2,0) -> 1558.11 | G10: =VLOOKUP(C10,'SIND PITS'!$C$3:$E$104,3,0) -> 210 | H10: =VLOOKUP(C10,'SIND PITS'!$C$3:$F$104,4,0) -> 0 | I10: =VLOOKUP(C10,'SIND PITS'!$C$3:$G$104,5,0) -> 274.51 | K10: =SUM(D10:I10) -> 3865.82 | L10: 10150 | M10: =+L10/2 -> 5075 | O10: =VLOOKUP($C10,'CPD PITSS'!$B$10:$V$27,8,0) -> 334.49 | P10: =+G10+H10+I10 -> 484.51 | Q10: =(VLOOKUP($C10,'CPD PITSS'!$B$10:$V$27,13,0))+(VLOOKUP($C10,'CPD PITSS'!$B$10:$V$27,14,0)) -> 1789.38 | S10: =VLOOKUP(C10,'CPD PITSS'!$B$10:$S$27,18,0) -> 238.8 | U10: =+K10-O10-P10+Q10+R10+S10+IFERROR(VLOOKUP('RESUMEN PITS'!C10,'IP PITSS'!$B$10:$M$91,10),0)+IFERROR(VLOOKUP('RESUMEN PITS'!C10,'IP PITSS'!$B$10:$M$91,11),0)+IFERROR(VLOOKUP('RESUMEN PITS'!C10,'IP PITSS'!$B$10:$M$91,12),0)+VLOOKUP("Comision",'IP PITSS'!$I$97:$J$108,2)/COUNT($F$9:$F$111)+IFERROR(VLOOKUP('RESUMEN PITS'!C10,'IP PITSS'!$B$10:$AD$91,15),0)+IFERROR(VLOOKUP('RESUMEN PITS'!C10,'IP PITSS'!$B$10:$AD$91,21),0)+IFERROR(VLOOKUP('RESUMEN PITS'!C10,'IP PITSS'!$B$10:$AD$91,22),0)+IFERROR(VLOOKUP('RESUMEN PITS'!C10,'IP PITSS'!$B$10:$AD$91,23),0)+IFERROR(VLOOKUP('RESUMEN PITS'!C10,'IP PITSS'!$B$10:$AD$91,24),0)+IFERROR(VLOOKUP('RESUMEN PITS'!C10,'IP PITSS'!$B$10:$AD$91,26),0)+IFERROR(VLOOKUP('RESUMEN PITS'!C10,'IP PITSS'!$B$10:$AD$91,28),0)+IFERROR(VLOOKUP('RESUMEN PITS'!C10,'IP PITSS'!$B$10:$AD$91,29),0)+IFERROR(VLOOKUP('RESUMEN PITS'!C10,'IP PITSS'!$B$10:$AD$91,9),0)*2% -> 5131.5626 | V10: =+M10-U10 -> -56.562642 | X10: SEI0108
A11: SEI0116 | B11: CONSULTORIA | C11: Casillas Cardona Cesar Alejandro | D11: =VLOOKUP(C11,'CPD PITSS'!B18:V35,21,0) -> 3346.4 | F11: =VLOOKUP(C11,'SIND PITS'!$C$3:$H$104,2,0) -> 1891.17 | G11: =VLOOKUP(C11,'SIND PITS'!$C$3:$E$104,3,0) -> 0 | H11: =VLOOKUP(C11,'SIND PITS'!$C$3:$F$104,4,0) -> 0 | I11: =VLOOKUP(C11,'SIND PITS'!$C$3:$G$104,5,0) -> 107.5 | K11: =SUM(D11:I11) -> 5345.07 | L11: 12000 | M11: =+L11/2 -> 6000 | O11: =VLOOKUP($C11,'CPD PITSS'!$B$10:$V$27,8,0) -> 132.5 | P11: =+G11+H11+I11 -> 107.5 | Q11: =(VLOOKUP($C11,'CPD PITSS'!$B$10:$V$27,13,0))+(VLOOKUP($C11,'CPD PITSS'!$B$10:$V$27,14,0)) -> 894.93 | S11: =VLOOKUP(C11,'CPD PITSS'!$B$10:$S$27,18,0) -> 0 | U11: =+K11-O11-P11+Q11+R11+S11+IFERROR(VLOOKUP('RESUMEN PITS'!C11,'IP PITSS'!$B$10:$M$91,10),0)+IFERROR(VLOOKUP('RESUMEN PITS'!C11,'IP PITSS'!$B$10:$M$91,11),0)+IFERROR(VLOOKUP('RESUMEN PITS'!C11,'IP PITSS'!$B$10:$M$91,12),0)+VLOOKUP("Comision",'IP PITSS'!$I$97:$J$108,2)/COUNT($F$9:$F$111)+IFERROR(VLOOKUP('RESUMEN PITS'!C11,'IP PITSS'!$B$10:$AD$91,15),0)+IFERROR(VLOOKUP('RESUMEN PITS'!C11,'IP PITSS'!$B$10:$AD$91,21),0)+IFERROR(VLOOKUP('RESUMEN PITS'!C11,'IP PITSS'!$B$10:$AD$91,22),0)+IFERROR(VLOOKUP('RESUMEN PITS'!C11,'IP PITSS'!$B$10:$AD$91,23),0)+IFERROR(VLOOKUP('RESUMEN PITS'!C11,'IP PITSS'!$B$10:$AD$91,24),0)+IFERROR(VLOOKUP('RESUMEN PITS'!C11,'IP PITSS'!$B$10:$AD$91,26),0)+IFERROR(VLOOKUP('RESUMEN PITS'!C11,'IP PITSS'!$B$10:$AD$91,28),0)+IFERROR(VLOOKUP('RESUMEN PITS'!C11,'IP PITSS'!$B$10:$AD$91,29),0)+IFERROR(VLOOKUP('RESUMEN PITS'!C11,'IP PITSS'!$B$10:$AD$91,9),0)*2% -> 6056.5626 | V11: =+M11-U11 -> -56.562642 | X11: SEI0116
A12: SEI0117 | B12: CONSULTORIA | C12: Mariscal Romero Luis Adrian | D12: =VLOOKUP(C12,'CPD PITSS'!B19:V36,21,0) -> 3109.2 | F12: =VLOOKUP(C12,'SIND PITS'!$C$3:$H$104,2,0) -> 2751.08 | G12: =VLOOKUP(C12,'SIND PITS'!$C$3:$E$104,3,0) -> 0 | H12: =VLOOKUP(C12,'SIND PITS'!$C$3:$F$104,4,0) -> 0 | I12: =VLOOKUP(C12,'SIND PITS'!$C$3:$G$104,5,0) -> 0 | K12: =SUM(D12:I12) -> 5860.28 | L12: 15000 | M12: =+L12/2 -> 7500 | O12: =VLOOKUP($C12,'CPD PITSS'!$B$10:$V$27,8,0) -> 0 | P12: =+G12+H12+I12 -> 0 | Q12: =(VLOOKUP($C12,'CPD PITSS'!$B$10:$V$27,13,0))+(VLOOKUP($C12,'CPD PITSS'!$B$10:$V$27,14,0)) -> 1639.72 | S12: =VLOOKUP(C12,'CPD PITSS'!$B$10:$S$27,18,0) -> 0 | U12: =+K12-O12-P12+Q12+R12+S12+IFERROR(VLOOKUP('RESUMEN PITS'!C12,'IP PITSS'!$B$10:$M$91,10),0)+IFERROR(VLOOKUP('RESUMEN PITS'!C12,'IP PITSS'!$B$10:$M$91,11),0)+IFERROR(VLOOKUP('RESUMEN PITS'!C12,'IP PITSS'!$B$10:$M$91,12),0)+VLOOKUP("Comision",'IP PITSS'!$I$97:$J$108,2)/COUNT($F$9:$F$111)+IFERROR(VLOOKUP('RESUMEN PITS'!C12,'IP PITSS'!$B$10:$AD$91,15),0)+IFERROR(VLOOKUP('RESUMEN PITS'!C12,'IP PITSS'!$B$10:$AD$91,21),0)+IFERROR(VLOOKUP('RESUMEN PITS'!C12,'IP PITSS'!$B$10:$AD$91,22),0)+IFERROR(VLOOKUP('RESUMEN PITS'!C12,'IP PITSS'!$B$10:$AD$91,23),0)+IFERROR(VLOOKUP('RESUMEN PITS'!C12,'IP PITSS'!$B$10:$AD$91,24),0)+IFERROR(VLOOKUP('RESUMEN PITS'!C12,'IP PITSS'!$B$10:$AD$91,26),0)+IFERROR(VLOOKUP('RESUMEN PITS'!C12,'IP PITSS'!$B$10:$AD$91,28),0)+IFERROR(VLOOKUP('RESUMEN PITS'!C12,'IP PITSS'!$B$10:$AD$91,29),0)+IFERROR(VLOOKUP('RESUMEN PITS'!C12,'IP PITSS'!$B$10:$AD$91,9),0)*2% -> 9415.9536 | V12: =+M12-U12 -> -1915.9536 | X12: SEI0117
A13: SEI0118 | B13: CONSULTORIA | C13: Arroyo Ramirez Hector Hugo | D13: =VLOOKUP(C13,'CPD PITSS'!B20:V37,21,0) -> 2739.4 | F13: =VLOOKUP(C13,'SIND PITS'!$C$3:$H$104,2,0) -> 2102.72 | G13: =VLOOKUP(C13,'SIND PITS'!$C$3:$E$104,3,0) -> 0 | H13: =VLOOKUP(C13,'SIND PITS'!$C$3:$F$104,4,0) -> 0 | I13: =VLOOKUP(C13,'SIND PITS'!$C$3:$G$104,5,0) -> 0 | K13: =SUM(D13:I13) -> 4842.12 | L13: 13000 | M13: =+L13/2 -> 6500 | O13: =VLOOKUP($C13,'CPD PITSS'!$B$10:$V$27,8,0) -> 0 | P13: =+G13+H13+I13 -> 0 | Q13: =(VLOOKUP($C13,'CPD PITSS'!$B$10:$V$27,13,0))+(VLOOKUP($C13,'CPD PITSS'!$B$10:$V$27,14,0)) -> 1402.48 | S13: =VLOOKUP(C13,'CPD PITSS'!$B$10:$S$27,18,0) -> 255.4 | U13: =+K13-O13-P13+Q13+R13+S13+IFERROR(VLOOKUP('RESUMEN PITS'!C13,'IP PITSS'!$B$10:$M$91,10),0)+IFERROR(VLOOKUP('RESUMEN PITS'!C13,'IP PITSS'!$B$10:$M$91,11),0)+IFERROR(VLOOKUP('RESUMEN PITS'!C13,'IP PITSS'!$B$10:$M$91,12),0)+VLOOKUP("Comision",'IP PITSS'!$I$97:$J$108,2)/COUNT($F$9:$F$111)+IFERROR(VLOOKUP('RESUMEN PITS'!C13,'IP PITSS'!$B$10:$AD$91,15),0)+IFERROR(VLOOKUP('RESUMEN PITS'!C13,'IP PITSS'!$B$10:$AD$91,21),0)+IFERROR(VLOOKUP('RESUMEN PITS'!C13,'IP PITSS'!$B$10:$AD$91,22),0)+IFERROR(VLOOKUP('RESUMEN PITS'!C13,'IP PITSS'!$B$10:$AD$91,23),0)+IFERROR(VLOOKUP('RESUMEN PITS'!C13,'IP PITSS'!$B$10:$AD$91,24),0)+IFERROR(VLOOKUP('RESUMEN PITS'!C13,'IP PITSS'!$B$10:$AD$91,26),0)+IFERROR(VLOOKUP('RESUMEN PITS'!C13,'IP PITSS'!$B$10:$AD$91,28),0)+IFERROR(VLOOKUP('RESUMEN PITS'!C13,'IP PITSS'!$B$10:$AD$91,29),0)+IFERROR(VLOOKUP('RESUMEN PITS'!C13,'IP PITSS'!$B$10:$AD$91,9),0)*2% -> 6556.5626 | V13: =+M13-U13 -> -56.562642 | X13: SEI0118
A14: SEI0127 | B14: CONSULTORIA | C14: Hernandez Ochoa Eduardo | D14: =VLOOKUP(C14,'CPD PITSS'!B21:V38,21,0) -> 4899.8 | F14: =VLOOKUP(C14,'SIND PITS'!$C$3:$H$104,2,0) -> 2600.2 | G14: =VLOOKUP(C14,'SIND PITS'!$C$3:$E$104,3,0) -> 337.5 | H14: =VLOOKUP(C14,'SIND PITS'!$C$3:$F$104,4,0) -> 0 | I14: =VLOOKUP(C14,'SIND PITS'!$C$3:$G$104,5,0) -> 0 | K14: =SUM(D14:I14) -> 7837.5 | L14: 15000 | M14: =+L14/2 -> 7500 | O14: =VLOOKUP($C14,'CPD PITSS'!$B$10:$V$27,8,0) -> 0 | P14: =+G14+H14+I14 -> 337.5 | Q14: =(VLOOKUP($C14,'CPD PITSS'!$B$10:$V$27,13,0))+(VLOOKUP($C14,'CPD PITSS'!$B$10:$V$27,14,0)) -> 0 | S14: =VLOOKUP(C14,'CPD PITSS'!$B$10:$S$27,18,0) -> 0 | U14: =+K14-O14-P14+Q14+R14+S14+IFERROR(VLOOKUP('RESUMEN PITS'!C14,'IP PITSS'!$B$10:$M$91,10),0)+IFERROR(VLOOKUP('RESUMEN PITS'!C14,'IP PITSS'!$B$10:$M$91,11),0)+IFERROR(VLOOKUP('RESUMEN PITS'!C14,'IP PITSS'!$B$10:$M$91,12),0)+VLOOKUP("Comision",'IP PITSS'!$I$97:$J$108,2)/COUNT($F$9:$F$111)+IFERROR(VLOOKUP('RESUMEN PITS'!C14,'IP PITSS'!$B$10:$AD$91,15),0)+IFERROR(VLOOKUP('RESUMEN PITS'!C14,'IP PITSS'!$B$10:$AD$91,21),0)+IFERROR(VLOOKUP('RESUMEN PITS'!C14,'IP PITSS'!$B$10:$AD$91,22),0)+IFERROR(VLOOKUP('RESUMEN PITS'!C14,'IP PITSS'!$B$10:$AD$91,23),0)+IFERROR(VLOOKUP('RESUMEN PITS'!C14,'IP PITSS'!$B$10:$AD$91,24),0)+IFERROR(VLOOKUP('RESUMEN PITS'!C14,'IP PITSS'!$B$10:$AD$91,26),0)+IFERROR(VLOOKUP('RESUMEN PITS'!C14,'IP PITSS'!$B$10:$AD$91,28),0)+IFERROR(VLOOKUP('RESUMEN PITS'!C14,'IP PITSS'!$B$10:$AD$91,29),0)+IFERROR(VLOOKUP('RESUMEN PITS'!C14,'IP PITSS'!$B$10:$AD$91,9),0)*2% -> 8917.0416 | V14: =+M14-U14 -> -1417.0416 | X14: SEI0127
... A20: SEI0442 | B20: CONSULTORIA | C20: Sierra Escamilla Daniela | D20: =VLOOKUP(C20,'CPD PITSS'!B27:V44,21,0) -> 4036.2 | F20: =VLOOKUP(C20,'SIND PITS'!$C$3:$H$104,2,0) -> 2463.8 | G20: =VLOOKUP(C20,'SIND PITS'!$C$3:$E$104,3,0) -> 1000 | H20: =VLOOKUP(C20,'SIND PITS'!$C$3:$F$104,4,0) -> 0 | I20: =VLOOKUP(C20,'SIND PITS'!$C$3:$G$104,5,0) -> 0 | K20: =SUM(D20:I20) -> 7500 | L20: 13000 | M20: =+L20/2 -> 6500 | O20: =VLOOKUP($C20,'CPD PITSS'!$B$10:$V$27,8,0) -> 0 | P20: =+G20+H20+I20 -> 1000 | Q20: =(VLOOKUP($C20,'CPD PITSS'!$B$10:$V$27,13,0))+(VLOOKUP($C20,'CPD PITSS'!$B$10:$V$27,14,0)) -> 0 | S20: =VLOOKUP(C20,'CPD PITSS'!$B$10:$S$27,18,0) -> 0 | U20: =+K20-O20-P20+Q20+R20+S20+IFERROR(VLOOKUP('RESUMEN PITS'!C20,'IP PITSS'!$B$10:$M$91,10),0)+IFERROR(VLOOKUP('RESUMEN PITS'!C20,'IP PITSS'!$B$10:$M$91,11),0)+IFERROR(VLOOKUP('RESUMEN PITS'!C20,'IP PITSS'!$B$10:$M$91,12),0)+VLOOKUP("Comision",'IP PITSS'!$I$97:$J$108,2)/COUNT($F$9:$F$111)+IFERROR(VLOOKUP('RESUMEN PITS'!C20,'IP PITSS'!$B$10:$AD$91,15),0)+IFERROR(VLOOKUP('RESUMEN PITS'!C20,'IP PITSS'!$B$10:$AD$91,21),0)+IFERROR(VLOOKUP('RESUMEN PITS'!C20,'IP PITSS'!$B$10:$AD$91,22),0)+IFERROR(VLOOKUP('RESUMEN PITS'!C20,'IP PITSS'!$B$10:$AD$91,23),0)+IFERROR(VLOOKUP('RESUMEN PITS'!C20,'IP PITSS'!$B$10:$AD$91,24),0)+IFERROR(VLOOKUP('RESUMEN PITS'!C20,'IP PITSS'!$B$10:$AD$91,26),0)+IFERROR(VLOOKUP('RESUMEN PITS'!C20,'IP PITSS'!$B$10:$AD$91,28),0)+IFERROR(VLOOKUP('RESUMEN PITS'!C20,'IP PITSS'!$B$10:$AD$91,29),0)+IFERROR(VLOOKUP('RESUMEN PITS'!C20,'IP PITSS'!$B$10:$AD$91,9),0)*2% -> 7844.8726 | V20: =+M20-U20 -> -1344.8726 | X20: SEI0618
A21: SEI0010 | B21: IP INNOVACION | C21: Torres Ricardez Alfredo | D21: =VLOOKUP(C21,'IP PITSS'!$B$10:$U$91,20,0) -> 3585.4 | F21: =VLOOKUP(C21,'SIND PITS'!$C$3:$H$104,2,0) -> 414.6 | G21: =VLOOKUP(C21,'SIND PITS'!$C$3:$E$104,3,0) -> 175 | H21: =VLOOKUP(C21,'SIND PITS'!$C$3:$F$104,4,0) -> 0 | I21: =VLOOKUP(C21,'SIND PITS'!$C$3:$G$104,5,0) -> 0 | K21: =SUM(D21:I21) -> 4175 | L21: 8000 | M21: =+L21/2 -> 4000 | O21: =VLOOKUP(C21,'IP PITSS'!$B$10:$I$91,8,0) -> 0 | P21: =+G21+H21+I21 -> 175 | Q21: =VLOOKUP(C21,'IP PITSS'!$B$10:$K$91,10,0)+VLOOKUP('RESUMEN PITS'!C21,'IP PITSS'!$B$10:$L$91,11,0)+VLOOKUP('RESUMEN PITS'!C21,'IP PITSS'!$B$10:$M$91,12,0) -> 0 | R21: =VLOOKUP(C21,'IP PITSS'!$B$10:$Q$91,16,0) -> 0 | S21: =VLOOKUP(C21,'IP PITSS'!$B$10:$R$91,17,0) -> 0 | U21: =+K21-O21-P21+Q21+R21+S21+IFERROR(VLOOKUP('RESUMEN PITS'!C21,'IP PITSS'!$B$10:$M$91,10),0)+IFERROR(VLOOKUP('RESUMEN PITS'!C21,'IP PITSS'!$B$10:$M$91,11),0)+IFERROR(VLOOKUP('RESUMEN PITS'!C21,'IP PITSS'!$B$10:$M$91,12),0)+VLOOKUP("Comision",'IP PITSS'!$I$97:$J$108,2)/COUNT($F$9:$F$111)+IFERROR(VLOOKUP('RESUMEN PITS'!C21,'IP PITSS'!$B$10:$AD$91,15),0)+IFERROR(VLOOKUP('RESUMEN PITS'!C21,'IP PITSS'!$B$10:$AD$91,21),0)+IFERROR(VLOOKUP('RESUMEN PITS'!C21,'IP PITSS'!$B$10:$AD$91,22),0)+IFERROR(VLOOKUP('RESUMEN PITS'!C21,'IP PITSS'!$B$10:$AD$91,23),0)+IFERROR(VLOOKUP('RESUMEN PITS'!C21,'IP PITSS'!$B$10:$AD$91,24),0)+IFERROR(VLOOKUP('RESUMEN PITS'!C21,'IP PITSS'!$B$10:$AD$91,26),0)+IFERROR(VLOOKUP('RESUMEN PITS'!C21,'IP PITSS'!$B$10:$AD$91,28),0)+IFERROR(VLOOKUP('RESUMEN PITS'!C21,'IP PITSS'!$B$10:$AD$91,29),0)+IFERROR(VLOOKUP('RESUMEN PITS'!C21,'IP PITSS'!$B$10:$AD$91,9),0)*2% -> 5344.8726 | V21: =+M21-U21 -> -1344.8726 | X21: SEI0010
