Workbook

Sheet CPD PITSS
B2: CONSULTORIA EN PROYECTOS DINAMICOS S DE RL DE CV
B3: Lista de Raya (forma tabular)
B5: Reg Pat IMSS: Z2940859106
B6: RFC: CPD -150911-FA3
B7: 1 | C7: =+B7+1 -> 2 | D7: =+C7+1 -> 3 | E7: =+D7+1 -> 4 | F7: =+E7+1 -> 5 | G7: =+F7+1 -> 6 | H7: =+G7+1 -> 7 | I7: =+H7+1 -> 8 | J7: =+I7+1 -> 9 | ... V7: =+U7+1 -> 21
A8: Código | B8: Empleado | C8: Dias Laborados | D8: Dias Vacaciones | E8: Salario Diario | F8: Salario Diario Integrado | G8: Sueldo | H8: Vacaciones a tiempo | I8: Prima de vacaciones a tiempo | J8: Ayuda de Transporte | K8: Ayuda Alimentaria | L8: Ayuda de Renta | M8: *TOTAL* *PERCEPCIONES* | N8: Seguro de vivienda Infonavit | O8: Préstamo Infonavit (vsm) | P8: Subsidio al Empleo (sp) | Q8: I.S.R. (sp) | R8: I.M.S.S. | S8: Deduccion General | T8: Ajuste al neto | U8: *TOTAL* *DEDUCCIONES* | V8: *NETO* | W8: Invalidez y Vida | X8: Cesantia y Vejez | Y8: Enf. y Mat. Patron | Z8: 2% Fondo retiro SAR (8) | AA8: 2% Impuesto estatal | AB8: Riesgo de trabajo (9) | AC8: I.M.S.S. empresa | AD8: Infonavit empresa | AE8: Guarderia I.M.S.S. (7) | AF8: Banco | AG8: Aguinaldo | AH8: infonavit | AI8: subtotal 1 | AJ8: comision | AK8: subtotal 2 | AL8: costo patrimonial | AM8: 2% sobre nomina | AN8: importe de factura | AO8: iva
A9: SEI0009 | B9: Gutierrez Gutierrez Luis Arturo | C9: 15 | D9: 0 | E9: 141.67 | F9: 150.25 | G9: 2125.05 | H9: 0 | I9: 255 | J9: 212.51 | K9: 212.51 | L9: 212.51 | M9: 3017.58 | O9: 0 | P9: -65.5 | Q9: 0 | R9: 57.11 | S9: 0 | T9: -0.03 | U9: -8.42 | V9: 3026 | W9: 42.07 | X9: 75.73 | Y9: 317.85 | Z9: 186.93 | AA9: 60.35 | AB9: 12.02 | AC9: 435.65 | AD9: 120.2 | AE9: 162.89 | AF9: 110 | AG9: =((20/365.24)*15)*($E9*1.3) -> 151.27396 | AH9: =N9+O9 -> 0 | AI9: =V9+S9+AH9 -> 3026 | AJ9: =AI9*2% -> 60.52 | AK9: =AI9+AJ9 -> 3086.52 | AL9: =R9+W9+X9+Y9+AB9+Z9+AD9+AE9 -> 974.8 | AM9: =AL9*2% -> 19.496 | AN9: =AK9+AL9+AM9 -> 4080.816 | AO9: =AN9*0.16 -> 652.93056
A10: SEI0026 | B10: Patricio Aguilar Jhonattan Cristian | C10: 15 | D10: 0 | E10: 150 | F10: 159.07 | G10: 2250 | H10: 0 | I10: 0 | J10: 225 | K10: 225 | L10: 225 | M10: 2925 | O10: 0 | P10: -43.57 | Q10: 0 | R10: 60.44 | S10: 0 | T10: -0.07 | U10: 16.8 | V10: 2908.2 | W10: 44.54 | X10: 80.17 | Y10: 320.32 | Z10: 189.75 | AA10: 58.5 | AB10: 12.73 | AC10: 445.03 | AD10: 127.26 | AE10: 164.3 | AF10: 110 | AG10: =((20/365.24)*15)*($E10*1.3) -> 160.16866 | AH10: =N10+O10 -> 0 | AI10: =V10+S10+AH10 -> 2908.2 | AJ10: =AI10*2% -> 58.164 | AK10: =AI10+AJ10 -> 2966.364 | AL10: =R10+W10+X10+Y10+AB10+Z10+AD10+AE10 -> 999.51 | AM10: =AL10*2% -> 19.9902 | AN10: =AK10+AL10+AM10 -> 3985.8642 | AO10: =AN10*0.16 -> 637.73827
A11: SEI0040 | B11: Mora Ramirez Acal Aldo Isidro | C11: 15 | D11: 0 | E11: 216.67 | F11: 229.79 | G11: 3250.05 | H11: 0 | I11: 0 | J11: 325.01 | K11: 325.01 | L11: 325.01 | M11: 4225.08 | O11: 0 | P11: 0 | Q11: 107.17 | R11: 87.32 | S11: 0 | T11: -0.01 | U11: 194.48 | V11: 4030.6 | W11: 64.34 | X11: 115.81 | Y11: 340.12 | Z11: 212.38 | AA11: 84.5 | AB11: 18.38 | AC11: 520.27 | AD11: 183.83 | AE11: 175.62 | AF11: 110 | AG11: =((20/365.24)*15)*($E11*1.3) -> 231.35828 | AH11: =N11+O11 -> 0 | AI11: =V11+S11+AH11 -> 4030.6 | AJ11: =AI11*2% -> 80.612 | AK11: =AI11+AJ11 -> 4111.212 | AL11: =R11+W11+X11+Y11+AB11+Z11+AD11+AE11 -> 1197.8 | AM11: =AL11*2% -> 23.956 | AN11: =AK11+AL11+AM11 -> 5332.968 | AO11: =AN11*0.16 -> 853.27488
A12: SEI0041 | B12: Vazquez Perez Miguel Angel | C12: 15 | D12: 0 | E12: 283.33 | F12: 300.49 | G12: 4249.95 | H12: 0 | I12: 0 | J12: 425 | K12: 425 | L12: 425 | M12: 5524.95 | O12: 0 | P12: 0 | Q12: 341.06 | R12: 117.2 | S12: 0 | T12: -0.11 | U12: 458.15 | V12: 5066.8 | W12: 84.14 | X12: 151.45 | Y12: 368.19 | Z12: 235.01 | AA12: 110.5 | AB12: 24.04 | AC12: 603.78 | AD12: 240.39 | AE12: 186.93 | AF12: 110 | AG12: =((20/365.24)*15)*($E12*1.3) -> 302.53724 | AH12: =N12+O12 -> 0 | AI12: =V12+S12+AH12 -> 5066.8 | AJ12: =AI12*2% -> 101.336 | AK12: =AI12+AJ12 -> 5168.136 | AL12: =R12+W12+X12+Y12+AB12+Z12+AD12+AE12 -> 1407.35 | AM12: =AL12*2% -> 28.147 | AN12: =AK12+AL12+AM12 -> 6603.633 | AO12: =AN12*0.16 -> 1056.5813
A13: SEI0088 | B13: Morgado Fernandez Martin | C13: 12 | D13: 3 | E13: 273.33 | F13: 289.87 | G13: 3279.96 | H13: 819.99 | I13: 246 | J13: 410 | K13: 410 | L13: 410 | M13: 5575.95 | O13: 0 | P13: 0 | Q13: 324.74 | R13: 112.48 | S13: 275.95 | T13: -0.02 | U13: 713.15 | V13: 4862.8 | W13: 81.16 | X13: 146.09 | Y13: 363.36 | Z13: 231.61 | AA13: 111.52 | AB13: 23.19 | AC13: 590.61 | AD13: 231.89 | AE13: 185.23 | AF13: 110 | AG13: =((20/365.24)*15)*($E13*1.3) -> 291.85933 | AH13: =N13+O13 -> 0 | AI13: =V13+S13+AH13 -> 5138.75 | AJ13: =AI13*2% -> 102.775 | AK13: =AI13+AJ13 -> 5241.525 | AL13: =R13+W13+X13+Y13+AB13+Z13+AD13+AE13 -> 1375.01 | AM13: =AL13*2% -> 27.5002 | AN13: =AK13+AL13+AM13 -> 6644.0352 | AO13: =AN13*0.16 -> 1063.0456
A14: SEI0097 | B14: Arreola Jimenez Jose Nieves | C14: 15 | D14: 0 | E14: 185.83 | F14: 197.07 | G14: 2787.45 | H14: 0 | I14: 0 | J14: 278.75 | K14: 278.75 | L14: 278.75 | M14: 3623.7 | O14: 1541.78 | P14: 0 | Q14: 36.57 | R14: 74.88 | S14: 0 | T14: 0.07 | U14: 1653.3 | V14: 1970.4 | W14: 55.18 | X14: 99.32 | Y14: 330.96 | Z14: 201.91 | AA14: 72.47 | AB14: 15.77 | AC14: 485.46 | AD14: 157.66 | AE14: 170.38 | AF14: 110 | AG14: =((20/365.24)*15)*($E14*1.3) -> 198.42761 | AH14: =N14+O14 -> 1541.78 | AI14: =V14+S14+AH14 -> 3512.18 | AJ14: =AI14*2% -> 70.2436 | AK14: =AI14+AJ14 -> 3582.4236 | AL14: =R14+W14+X14+Y14+AB14+Z14+AD14+AE14 -> 1106.06 | AM14: =AL14*2% -> 22.1212 | AN14: =AK14+AL14+AM14 -> 4710.6048 | AO14: =AN14*0.16 -> 753.69677
A15: SEI0099 | B15: Garcia Villicaña Ricardo Pascual | C15: 11 | D15: 4 | E15: 273.33 | F15: 289.87 | G15: 3006.63 | H15: 1093.32 | I15: 328 | J15: 410 | K15: 410 | L15: 410 | M15: 5657.95 | O15: 0 | P15: 0 | Q15: 324.74 | R15: 112.48 | S15: 0 | T15: -0.07 | U15: 437.15 | V15: 5220.8 | W15: 81.16 | X15: 146.09 | Y15: 363.36 | Z15: 231.61 | AA15: 113.16 | AB15: 23.19 | AC15: 590.61 | AD15: 231.89 | AE15: 185.23 | AF15: 110 | AG15: =((20/365.24)*15)*($E15*1.3) -> 291.85933 | AH15: =N15+O15 -> 0 | AI15: =V15+S15+AH15 -> 5220.8 | AJ15: =AI15*2% -> 104.416 | AK15: =AI15+AJ15 -> 5325.216 | AL15: =R15+W15+X15+Y15+AB15+Z15+AD15+AE15 -> 1375.01 | AM15: =AL15*2% -> 27.5002 | AN15: =AK15+AL15+AM15 -> 6727.7262 | AO15: =AN15*0.16 -> 1076.4362
A16: SEI0108 | B16: Caballero Diaz Francisco Javier | C16: 15 | D16: 0 | E16: 185.83 | F16: 197.07 | G16: 2787.45 | H16: 0 | I16: 0 | J16: 278.75 | K16: 278.75 | L16: 278.75 | M16: 3623.7 | O16: 1789.38 | P16: 0 | Q16: 36.57 | R16: 74.88 | S16: 238.8 | T16: 0.07 | U16: 2139.7 | V16: 1484 | W16: 55.18 | X16: 99.32 | Y16: 330.96 | Z16: 201.91 | AA16: 72.47 | AB16: 15.77 | AC16: 485.46 | AD16: 157.66 | AE16: 170.38 | AF16: 110 | AG16: =((20/365.24)*15)*($E16*1.3) -> 198.42761 | AH16: =N16+O16 -> 1789.38 | AI16: =V16+S16+AH16 -> 3512.18 | AJ16: =AI16*2% -> 70.2436 | AK16: =AI16+AJ16 -> 3582.4236 | AL16: =R16+W16+X16+Y16+AB16+Z16+AD16+AE16 -> 1106.06 | AM16: =AL16*2% -> 22.1212 | AN16: =AK16+AL16+AM16 -> 4710.6048 | AO16: =AN16*0.16 -> 753.69677
A17: SEI0116 | B17: Casillas Cardona Cesar Alejandro | C17: 15 | D17: 0 | E17: 220.83 | F17: 234.19 | G17: 3312.45 | H17: 0 | I17: 0 | J17: 331.25 | K17: 331.25 | L17: 331.25 | M17: 4306.2 | O17: 894.93 | P17: 0 | Q17: 113.96 | R17: 88.99 | S17: 0 | T17: 0.12 | U17: 1098 | V17: 3208.2 | W17: 65.57 | X17: 118.03 | Y17: 341.35 | Z17: 213.79 | AA17: 86.12 | AB17: 18.74 | AC17: 524.95 | AD17: 187.35 | AE17: 176.32 | AF17: 110 | AG17: =((20/365.24)*15)*($E17*1.3) -> 235.8003 | AH17: =N17+O17 -> 894.93 | AI17: =V17+S17+AH17 -> 4103.13 | AJ17: =AI17*2% -> 82.0626 | AK17: =AI17+AJ17 -> 4185.1926 | AL17: =R17+W17+X17+Y17+AB17+Z17+AD17+AE17 -> 1210.14 | AM17: =AL17*2% -> 24.2028 | AN17: =AK17+AL17+AM17 -> 5419.5354 | AO17: =AN17*0.16 -> 867.12566
A18: SEI0117 | B18: Mariscal Romero Luis Adrian | C18: 15 | D18: 0 | E18: 264.58 | F18: 276.54 | G18: 3968.7 | H18: 0 | I18: 0 | J18: 396.87 | K18: 396.87 | L18: 396.87 | M18: 5159.31 | O18: 1639.72 | P18: 0 | Q18: 310.46 | R18: 106.56 | S18: 0 | T18: -0.03 | U18: 2056.71 | V18: 3102.6 | W18: 77.43 | X18: 139.38 | Y18: 357.27 | Z18: 227.34 | AA18: 103.19 | AB18: 22.12 | AC18: 574.08 | AD18: 221.23 | AE18: 183.1 | AF18: 110 | AG18: =((20/365.24)*15)*($E18*1.3) -> 282.51615 | AH18: =N18+O18 -> 1639.72 | AI18: =V18+S18+AH18 -> 4742.32 | AJ18: =AI18*2% -> 94.8464 | AK18: =AI18+AJ18 -> 4837.1664 | AL18: =R18+W18+X18+Y18+AB18+Z18+AD18+AE18 -> 1334.43 | AM18: =AL18*2% -> 26.6886 | AN18: =AK18+AL18+AM18 -> 6198.285 | AO18: =AN18*0.16 -> 991.7256
A19: SEI0118 | B19: Arroyo Ramirez Hector Hugo | C19: 15 | D19: 0 | E19: 238.33 | F19: 252.75 | G19: 3574.95 | H19: 0 | I19: 0 | J19: 357.5 | K19: 357.5 | L19: 357.5 | M19: 4647.45 | O19: 1402.48 | P19: 0 | Q19: 160.25 | R19: 96.03 | S19: 255.4 | T19: 0.09 | U19: 1914.25 | V19: 2733.2 | W19: 70.77 | X19: 127.39 | Y19: 346.55 | Z19: 219.73 | AA19: 92.95 | AB19: 20.22 | AC19: 544.71 | AD19: 202.2 | AE19: 179.29 | AF19: 110 | AG19: =((20/365.24)*15)*($E19*1.3) -> 254.48664 | AH19: =N19+O19 -> 1402.48 | AI19: =V19+S19+AH19 -> 4391.08 | AJ19: =AI19*2% -> 87.8216 | AK19: =AI19+AJ19 -> 4478.9016 | AL19: =R19+W19+X19+Y19+AB19+Z19+AD19+AE19 -> 1262.18 | AM19: =AL19*2% -> 25.2436 | AN19: =AK19+AL19+AM19 -> 5766.3252 | AO19: =AN19*0.16 -> 922.61203
A20: SEI0127 | B20: Hernandez Ochoa Eduardo | C20: 15 | D20: 0 | E20: 273.33 | F20: 289.87 | G20: 4099.95 | H20: 0 | I20: 0 | J20: 410 | K20: 410 | L20: 410 | M20: 5329.95 | O20: 0 | P20: 0 | Q20: 324.74 | R20: 112.48 | S20: 0 | T20: -0.07 | U20: 437.15 | V20: 4892.8 | W20: 81.16 | X20: 146.09 | Y20: 363.36 | Z20: 231.61 | AA20: 106.6 | AB20: 23.19 | AC20: 590.61 | AD20: 231.89 | AE20: 185.23 | AF20: 110 | AG20: =((20/365.24)*15)*($E20*1.3) -> 291.85933 | AH20: =N20+O20 -> 0 | AI20: =V20+S20+AH20 -> 4892.8 | AJ20: =AI20*2% -> 97.856 | AK20: =AI20+AJ20 -> 4990.656 | AL20: =R20+W20+X20+Y20+AB20+Z20+AD20+AE20 -> 1375.01 | AM20: =AL20*2% -> 27.5002 | AN20: =AK20+AL20+AM20 -> 6393.1662 | AO20: =AN20*0.16 -> 1022.9066
... A26: SEI0442 | B26: Sierra Escamilla Daniela | C26: 15 | D26: 0 | E26: 216.67 | F26: 229.79 | G26: 3250.05 | H26: 0 | I26: 0 | J26: 325.01 | K26: 325.01 | L26: 325.01 | M26: 4225.08 | O26: 0 | P26: 0 | Q26: 107.17 | R26: 87.32 | S26: 0 | T26: -0.01 | U26: 194.48 | V26: 4030.6 | W26: 64.34 | X26: 115.81 | Y26: 340.12 | Z26: 212.38 | AA26: 84.5 | AB26: 18.38 | AC26: 520.27 | AD26: 183.83 | AE26: 175.62 | AF26: 110 | AG26: =((20/365.24)*15)*($E26*1.3) -> 231.35828 | AH26: =N26+O26 -> 0 | AI26: =V26+S26+AH26 -> 4030.6 | AJ26: =AI26*2% -> 80.612 | AK26: =AI26+AJ26 -> 4111.212 | AL26: =R26+W26+X26+Y26+AB26+Z26+AD26+AE26 -> 1197.8 | AM26: =AL26*2% -> 23.956 | AN26: =AK26+AL26+AM26 -> 5332.968 | AO26: =AN26*0.16 -> 853.27488
C27: ============= | D27: ============= | E27: ============= | F27: ============= | G27: ============= | H27: ============= | I27: ============= | J27: ============= | K27: ============= | L27: ============= | M27: ============= | N27: ============= | O27: ============= | P27: ============= | Q27: ============= | R27: ============= | S27: ============= | T27: ============= | U27: ============= | V27: ============= | W27: ============= | X27: ============= | Y27: ============= | Z27: ============= | AA27: ============= | AB27: ============= | AC27: ============= | AD27: ============= | AE27: ============= | AF27: ============= | AG27: =============
A28: Total Gral. | C28: =SUM(C9:C26) -> 263 | D28: =SUM(D9:D26) -> 7 | E28: =SUM(E9:E26) -> 4708.72 | F28: =SUM(F9:F26) -> 4989.65 | G28: =SUM(G9:G26) -> 68717.49 | H28: =SUM(H9:H26) -> 1913.31 | I28: =SUM(I9:I26) -> 829 | J28: =SUM(J9:J26) -> 7063.16 | ... AG28: =SUM(AG9:AG26) -> 5027.929
A30: 18 | B30: Nomina
B31: Altas | L31: FACTURACION PITS
B32: Bajas | L32: Devengado Salario | M32: =+V28 -> 73724.6
A33: =+A30+A31-A32 -> 18 | B33: Total Nomina | L33: RETORNOS | M33: =+S28 -> 1067.15
L34: Infonavit | M34: =+N28+O28 -> 10869.77
L35: Prestamo Prospera | M35: 0
L36: Subtotal 1 | M36: =SUM(M32:M35) -> 85661.52
L37: Comision | M37: =+M36*2% -> 1713.2304
L38: Subtotal 2 | M38: =+M36+M37 -> 87374.75
L39: Costo Patronal Imss | M39: =+R28+W28+X28+Y28+AB28+Z28+AD28+AE28 -> 24205.8
L40: 2% Sobre Nomina | M40: =+M28*2% -> 1852.9856
L41: Importe de Factura | M41: =+M38+M39+M40 -> 113433.54
L42: IVA | M42: =+M41*16% -> 18149.366
L43: TOTAL | M43: =+M41+M42 -> 131582.9
L45: PROVISION AGUINALDO
L46: FACTURACION PITS
L47: Subtotal 1 | M47: =+AG28 -> 5027.929
L48: Comision | M48: =+M47*2% -> 100.55858
L49: Subtotal 2 | M49: =+M47+M48 -> 5128.4876
...

Sheet IP PITSS
B2: IP INNOVACION EN PROYECTOS S DE RL DE CV
B3: Lista de Raya (forma tabular)
B5: Reg Pat IMSS: R1363592103
B6: RFC: IIP -150923-DT7
A8: Código | B8: Empleado | C8: Dias Laborados | D8: Dias Vacaciones | E8: Salario Diario | F8: Salario Diario Integrado | G8: Sueldo | H8: Vacaciones a tiempo | I8: Prima de vacaciones a tiempo | J8: *TOTAL* *PERCEPCIONES* | K8: Seguro de vivienda Infonavit | L8: Préstamo Infonavit (vsm) | M8: Préstamo Infonavit (cf) | N8: Subsidio al Empleo (sp) | O8: I.S.R. (sp) | P8: I.M.S.S. | Q8: Préstamo FONACOT | R8: Deduccion general | S8: Ajuste al neto | T8: *TOTAL* *DEDUCCIONES* | U8: *NETO* | V8: Invalidez y Vida | W8: Cesantia y Vejez | X8: Enf. y Mat. Patron | Y8: 2% Fondo retiro SAR (8) | Z8: 2% Impuesto estatal | AA8: Riesgo de trabajo (9) | AB8: I.M.S.S. empresa | AC8: Infonavit empresa | AD8: Guarderia I.M.S.S. (7) | AE8: Banco | AF8: Aguinaldo | AG8: subtotal 1 | AH8: comision | AI8: subtotal 2 | AJ8: costo patronal imss | AK8: 2% sobre nomina | AL8: importe de factura | AM8: iva | AN8: total
A9: SEI0010 | B9: Torres Ricardez Alfredo | C9: 15 | D9: 0 | E9: 266.67 | F9: 278.72 | G9: 4000.05 | H9: 0 | I9: 0 | J9: 4000.05 | K9: 0 | L9: 0 | M9: 0 | N9: 0 | O9: 313.87 | P9: 107.53 | Q9: 0 | R9: 0 | S9: 0.05 | T9: 421.45 | U9: 3578.6 | V9: 78.04 | W9: 140.48 | X9: 358.27 | Y9: 277.46 | Z9: 80 | AA9: 35.52 | AB9: 576.79 | AC9: 222.98 | AD9: 232.87 | AE9: 110 | AF9: =((20/365.24)*15)*E9 -> 219.0368 | AG9: =U9+R9+K9+L9+M9+Q9 -> 3578.6 | AH9: =AG9*2% -> 71.572 | AI9: =AG9+AH9 -> 3650.172 | AJ9: =P9+V9+W9+X9+Y9+AA9+AC9+AD9 -> 1453.15 | AK9: =J9*2% -> 80.001 | AL9: =AI9+AJ9+AK9 -> 5183.323 | AM9: =AL9*16% -> 829.33168 | AN9: =AL9+AM9 -> 6012.6547
A10: SEI0014 | B10: Montoya Portillo Carlos Alberto | C10: 14 | D10: 1 | E10: 266.67 | F10: 278.72 | G10: 3733.38 | H10: 266.67 | I10: 80 | J10: 4080.05 | K10: 0 | L10: 0 | M10: 0 | N10: 0 | O10: 313.87 | P10: 107.53 | Q10: 0 | R10: 0 | S10: -0.15 | T10: 421.25 | U10: 3658.8 | V10: 78.04 | W10: 140.48 | X10: 358.27 | Y10: 277.46 | Z10: 81.6 | AA10: 35.52 | AB10: 576.79 | AC10: 222.98 | AD10: 232.87 | AE10: 110 | AF10: =((20/365.24)*15)*E10 -> 219.0368 | AG10: =U10+R10+K10+L10+M10+Q10 -> 3658.8 | AH10: =AG10*2% -> 73.176 | AI10: =AG10+AH10 -> 3731.976 | AJ10: =P10+V10+W10+X10+Y10+AA10+AC10+AD10 -> 1453.15 | AK10: =J10*2% -> 81.601 | AL10: =AI10+AJ10+AK10 -> 5266.727 | AM10: =AL10*16% -> 842.67632 | AN10: =AL10+AM10 -> 6109.4033
A11: SEI0015 | B11: Cota Jaramillo Miguel Angel | C11: 15 | D11: 0 | E11: 200 | F11: 209.04 | G11: 3000 | H11: 0 | I11: 0 | J11: 3000 | K11: 0 | L11: 0 | M11: 0 | N11: 0 | O11: 59.69 | P11: 79.43 | Q11: 0 | R11: 0 | S11: 0.08 | T11: 139.2 | U11: 2860.8 | V11: 58.53 | W11: 105.36 | X11: 334.31 | Y11: 255.16 | Z11: 60 | AA11: 26.64 | AB11: 498.2 | AC11: 167.23 | AD11: 221.72 | AE11: 110 | AF11: =((20/365.24)*15)*E11 -> 164.27554 | AG11: =U11+R11+K11+L11+M11+Q11 -> 2860.8 | AH11: =AG11*2% -> 57.216 | AI11: =AG11+AH11 -> 2918.016 | AJ11: =P11+V11+W11+X11+Y11+AA11+AC11+AD11 -> 1248.38 | AK11: =J11*2% -> 60 | AL11: =AI11+AJ11+AK11 -> 4226.396 | AM11: =AL11*16% -> 676.22336 | AN11: =AL11+AM11 -> 4902.6194
A12: SEI0016 | B12: Negrete Bejar Aide Sarai | C12: 15 | D12: 0 | E12: 154 | F12: 160.96 | G12: 2310 | H12: 0 | I12: 0 | J12: 2310 | K12: 0 | L12: 977.57 | M12: 0 | N12: -39.73 | O12: 0 | P12: 61.17 | Q12: 0 | R12: 0 | S12: -0.01 | T12: 999 | U12: 1311 | V12: 45.07 | W12: 81.12 | X12: 320.85 | Y12: 239.78 | Z12: 46.2 | AA12: 20.52 | AB12: 447.04 | AC12: 128.77 | AD12: 214.02 | AE12: 110 | AF12: =((20/365.24)*15)*E12 -> 126.49217 | AG12: =U12+R12+K12+L12+M12+Q12 -> 2288.57 | AH12: =AG12*2% -> 45.7714 | AI12: =AG12+AH12 -> 2334.3414 | AJ12: =P12+V12+W12+X12+Y12+AA12+AC12+AD12 -> 1111.3 | AK12: =J12*2% -> 46.2 | AL12: =AI12+AJ12+AK12 -> 3491.8414 | AM12: =AL12*16% -> 558.69462 | AN12: =AL12+AM12 -> 4050.536
A13: SEI0017 | B13: Muñoz Reyes Luis Eduardo | C13: 15 | D13: 0 | E13: 266.67 | F13: 278.72 | G13: 4000.05 | H13: 0 | I13: 480 | J13: 4480.05 | K13: 0 | L13: 868.44 | M13: 0 | N13: 0 | O13: 313.87 | P13: 107.53 | Q13: 0 | R13: 0 | S13: 0.01 | T13: 1289.85 | U13: 3190.2 | V13: 78.04 | W13: 140.48 | X13: 358.27 | Y13: 277.46 | Z13: 89.6 | AA13: 35.52 | AB13: 576.79 | AC13: 222.98 | AD13: 232.87 | AE13: 110 | AF13: =((20/365.24)*15)*E13 -> 219.0368 | AG13: =U13+R13+K13+L13+M13+Q13 -> 4058.64 | AH13: =AG13*2% -> 81.1728 | AI13: =AG13+AH13 -> 4139.8128 | AJ13: =P13+V13+W13+X13+Y13+AA13+AC13+AD13 -> 1453.15 | AK13: =J13*2% -> 89.601 | AL13: =AI13+AJ13+AK13 -> 5682.5638 | AM13: =AL13*16% -> 909.21021 | AN13: =AL13+AM13 -> 6591.774
A14: SEI0019 | B14: Gonzalez Rasgado Miguel Isaias | C14: 15 | E14: 521.68 | F14: 553.24 | G14: 7825.2 | J14: 7825.2 | O14: 1033.24 | P14: 229.41 | S14: -0.05 | T14: 1262.6 | U14: 6562.6 | V14: 154.91 | W14: 278.83 | X14: 483.44 | Y14: 365.31 | Z14: 156.5 | AA14: 70.51 | AB14: 917.18 | AC14: 442.59 | AD14: 276.79 | AE14: 110 | AF14: =((20/365.24)*15)*E14 -> 428.49633 | AG14: =U14+R14+K14+L14+M14+Q14 -> 6562.6 | AH14: =AG14*2% -> 131.252 | AI14: =AG14+AH14 -> 6693.852 | AJ14: =P14+V14+W14+X14+Y14+AA14+AC14+AD14 -> 2301.79 | AK14: =J14*2% -> 156.504 | AL14: =AI14+AJ14+AK14 -> 9152.146 | AM14: =AL14*16% -> 1464.3434 | AN14: =AL14+AM14 -> 10616.489
A15: SEI0020 | B15: Mar Marquez Cesar Eduardo | C15: 15 | D15: 0 | E15: 266.67 | F15: 278.72 | G15: 4000.05 | H15: 0 | I15: 400 | J15: 4400.05 | K15: 0 | L15: 0 | M15: 0 | N15: 0 | O15: 313.87 | P15: 107.53 | Q15: 0 | R15: 0 | S15: 0.05 | T15: 421.45 | U15: 3978.6 | V15: 78.04 | W15: 140.48 | X15: 358.27 | Y15: 277.46 | Z15: 88 | AA15: 35.52 | AB15: 576.79 | AC15: 222.98 | AD15: 232.87 | AE15: 110 | AF15: =((20/365.24)*15)*E15 -> 219.0368 | AG15: =U15+R15+K15+L15+M15+Q15 -> 3978.6 | AH15: =AG15*2% -> 79.572 | AI15: =AG15+AH15 -> 4058.172 | AJ15: =P15+V15+W15+X15+Y15+AA15+AC15+AD15 -> 1453.15 | AK15: =J15*2% -> 88.001 | AL15: =AI15+AJ15+AK15 -> 5599.323 | AM15: =AL15*16% -> 895.89168 | AN15: =AL15+AM15 -> 6495.2147
A16: SEI0021 | B16: Velez Rodriguez Jaime | C16: 15 | D16: 0 | E16: 200 | F16: 212.1 | G16: 3000 | H16: 0 | I16: 0 | J16: 3000 | K16: 0 | L16: 1347.1 | M16: 0 | N16: 0 | O16: 59.69 | P16: 80.6 | Q16: 0 | R16: 0 | S16: 0.01 | T16: 1487.4 | U16: 1512.6 | V16: 59.39 | W16: 106.9 | X16: 335.17 | Y16: 256.14 | Z16: 60 | AA16: 27.03 | AB16: 501.46 | AC16: 169.68 | AD16: 222.21 | AE16: 110 | AF16: =((20/365.24)*15)*E16 -> 164.27554 | AG16: =U16+R16+K16+L16+M16+Q16 -> 2859.7 | AH16: =AG16*2% -> 57.194 | AI16: =AG16+AH16 -> 2916.894 | AJ16: =P16+V16+W16+X16+Y16+AA16+AC16+AD16 -> 1257.12 | AK16: =J16*2% -> 60 | AL16: =AI16+AJ16+AK16 -> 4234.014 | AM16: =AL16*16% -> 677.44224 | AN16: =AL16+AM16 -> 4911.4562
A17: SEI0022 | B17: Najera Lopez Raul | C17: 15 | D17: 0 | E17: 333.33 | F17: 353.5 | G17: 4999.95 | H17: 0 | I17: 0 | J17: 4999.95 | K17: 0 | L17: 0 | M17: 0 | N17: 0 | O17: 461.63 | P17: 140.73 | Q17: 0 | R17: 0 | S17: -0.01 | T17: 602.35 | U17: 4397.6 | V17: 98.98 | W17: 178.16 | X17: 392.36 | Y17: 301.39 | Z17: 100 | AA17: 45.05 | AB17: 669.5 | AC17: 282.8 | AD17: 244.83 | AE17: 110 | AF17: =((20/365.24)*15)*E17 -> 273.78984 | AG17: =U17+R17+K17+L17+M17+Q17 -> 4397.6 | AH17: =AG17*2% -> 87.952 | AI17: =AG17+AH17 -> 4485.552 | AJ17: =P17+V17+W17+X17+Y17+AA17+AC17+AD17 -> 1684.3 | AK17: =J17*2% -> 99.999 | AL17: =AI17+AJ17+AK17 -> 6269.851 | AM17: =AL17*16% -> 1003.1762 | AN17: =AL17+AM17 -> 7273.0272
A18: SEI0023 | B18: Puente Murguia Luis Felipe | C18: 15 | D18: 0 | E18: 233.33 | F18: 247.45 | G18: 3499.95 | H18: 0 | I18: 0 | J18: 3499.95 | K18: 0 | L18: 0 | M18: 0 | N18: 0 | O18: 134.36 | P18: 94.03 | Q18: 0 | R18: 0 | S18: -0.04 | T18: 228.35 | U18: 3271.6 | V18: 69.28 | W18: 124.71 | X18: 345.06 | Y18: 267.45 | Z18: 70 | AA18: 31.54 | AB18: 539.05 | AC18: 197.96 | AD18: 227.86 | AE18: 110 | AF18: =((20/365.24)*15)*E18 -> 191.65206 | AG18: =U18+R18+K18+L18+M18+Q18 -> 3271.6 | AH18: =AG18*2% -> 65.432 | AI18: =AG18+AH18 -> 3337.032 | AJ18: =P18+V18+W18+X18+Y18+AA18+AC18+AD18 -> 1357.89 | AK18: =J18*2% -> 69.999 | AL18: =AI18+AJ18+AK18 -> 4764.921 | AM18: =AL18*16% -> 762.38736 | AN18: =AL18+AM18 -> 5527.3084
A19: SEI0029 | B19: Arceo Garcia Manuel Federico | C19: 15 | D19: 0 | E19: 200 | F19: 212.1 | G19: 3000 | H19: 0 | I19: 0 | J19: 3000 | K19: 0 | L19: 0 | M19: 0 | N19: 0 | O19: 59.69 | P19: 80.6 | Q19: 600 | R19: 0 | S19: -0.09 | T19: 740.2 | U19: 2259.8 | V19: 59.39 | W19: 106.9 | X19: 335.17 | Y19: 256.14 | Z19: 60 | AA19: 27.03 | AB19: 501.46 | AC19: 169.68 | AD19: 222.21 | AE19: 110 | AF19: =((20/365.24)*15)*E19 -> 164.27554 | AG19: =U19+R19+K19+L19+M19+Q19 -> 2859.8 | AH19: =AG19*2% -> 57.196 | AI19: =AG19+AH19 -> 2916.996 | AJ19: =P19+V19+W19+X19+Y19+AA19+AC19+AD19 -> 1257.12 | AK19: =J19*2% -> 60 | AL19: =AI19+AJ19+AK19 -> 4234.116 | AM19: =AL19*16% -> 677.45856 | AN19: =AL19+AM19 -> 4911.5746
A20: SEI0364 | B20: Dominguez Lopez Mayeli Del Pilar | C20: 15 | D20: 0 | E20: 266.67 | F20: 282.81 | G20: 4000.05 | H20: 0 | I20: 0 | J20: 4000.05 | K20: 0 | L20: 0 | M20: 0 | N20: 0 | O20: 313.87 | P20: 109.35 | Q20: 0 | R20: 1666.67 | S20: -0.04 | T20: 2089.85 | U20: 1910.2 | V20: 79.19 | W20: 142.54 | X20: 360.12 | Y20: 278.77 | Z20: 80 | AA20: 36.05 | AB20: 581.85 | AC20: 226.25 | AD20: 233.52 | AE20: 110 | AF20: =((20/365.24)*15)*E20 -> 219.0368 | AG20: =U20+R20+K20+L20+M20+Q20 -> 3576.87 | AH20: =AG20*2% -> 71.5374 | AI20: =AG20+AH20 -> 3648.4074 | AJ20: =P20+V20+W20+X20+Y20+AA20+AC20+AD20 -> 1465.79 | AK20: =J20*2% -> 80.001 | AL20: =AI20+AJ20+AK20 -> 5194.1984 | AM20: =AL20*16% -> 831.07174 | AN20: =AL20+AM20 -> 6025.2701
A21: SEI0413 | B21: Courtenay Gutierrez Barry Vladimir | C21: 12 | D21: 3 | E21: 166.67 | F21: 174.2 | G21: 2000.04 | H21: 500.01 | I21: 150 | J21: 2650.05 | K21: 0 | L21: 0 | M21: 0 | N21: -9.62 | O21: 0 | P21: 66.2 | Q21: 0 | R21: 337.56 | S21: 0.11 | T21: 394.25 | U21: 2255.8 | V21: 48.78 | W21: 87.8 | X21: 324.56 | Y21: 244.02 | Z21: 53 | AA21: 22.2 | AB21: 461.14 | AC21: 139.36 | AD21: 216.14 | AE21: 110 | AF21: =((20/365.24)*15)*E21 -> 136.89903 | AG21: =U21+R21+K21+L21+M21+Q21 -> 2593.36 | AH21: =AG21*2% -> 51.8672 | AI21: =AG21+AH21 -> 2645.2272 | AJ21: =P21+V21+W21+X21+Y21+AA21+AC21+AD21 -> 1149.06 | AK21: =J21*2% -> 53.001 | AL21: =AI21+AJ21+AK21 -> 3847.2882 | AM21: =AL21*16% -> 615.56611 | AN21: =AL21+AM21 -> 4462.8543
A22: SEI0421 | B22: Marin Avila Hector | C22: 15 | D22: 0 | E22: 275 | F22: 287.43 | G22: 4125 | H22: 0 | I22: 0 | J22: 4125 | K22: 0 | L22: 0 | M22: 0 | N22: 0 | O22: 327.47 | P22: 111.4 | Q22: 0 | R22: 0 | S22: -0.07 | T22: 438.8 | U22: 3686.2 | V22: 80.48 | W22: 144.87 | X22: 362.24 | Y22: 280.25 | Z22: 82.5 | AA22: 36.63 | AB22: 587.59 | AC22: 229.95 | AD22: 234.26 | AE22: 110 | AF22: =((20/365.24)*15)*E22 -> 225.87887 | AG22: =U22+R22+K22+L22+M22+Q22 -> 3686.2 | AH22: =AG22*2% -> 73.724 | AI22: =AG22+AH22 -> 3759.924 | AJ22: =P22+V22+W22+X22+Y22+AA22+AC22+AD22 -> 1480.08 | AK22: =J22*2% -> 82.5 | AL22: =AI22+AJ22+AK22 -> 5322.504 | AM22: =AL22*16% -> 851.60064 | AN22: =AL22+AM22 -> 6174.1046
A23: SEI0424 | B23: Palacios Ramos Jesus | C23: 15 | D23: 0 | E23: 266.67 | F23: 282.81 | G23: 4000.05 | H23: 0 | I23: 0 | J23: 4000.05 | K23: 0 | L23: 0 | M23: 0 | N23: 0 | O23: 313.87 | P23: 109.35 | Q23: 0 | R23: 0 | S23: -0.17 | T23: 423.05 | U23: 3577 | V23: 79.19 | W23: 142.54 | X23: 360.12 | Y23: 278.77 | Z23: 80 | AA23: 36.05 | AB23: 581.85 | AC23: 226.25 | AD23: 233.52 | AE23: 110 | AF23: =((20/365.24)*15)*E23 -> 219.0368 | AG23: =U23+R23+K23+L23+M23+Q23 -> 3577 | AH23: =AG23*2% -> 71.54 | AI23: =AG23+AH23 -> 3648.54 | AJ23: =P23+V23+W23+X23+Y23+AA23+AC23+AD23 -> 1465.79 | AK23: =J23*2% -> 80.001 | AL23: =AI23+AJ23+AK23 -> 5194.331 | AM23: =AL23*16% -> 831.09296 | AN23: =AL23+AM23 -> 6025.424
A24: SEI0428 | B24: Martinez Hernandez J. Antonio | C24: 15 | D24: 0 | E24: 266.67 | F24: 282.81 | G24: 4000.05 | H24: 0 | I24: 0 | J24: 4000.05 | K24: 0 | L24: 0 | M24: 0 | N24: 0 | O24: 313.87 | P24: 109.35 | Q24: 0 | R24: 0 | S24: 0.03 | T24: 423.25 | U24: 3576.8 | V24: 79.19 | W24: 142.54 | X24: 360.12 | Y24: 278.77 | Z24: 80 | AA24: 36.05 | AB24: 581.85 | AC24: 226.25 | AD24: 233.52 | AE24: 110 | AF24: =((20/365.24)*15)*E24 -> 219.0368 | AG24: =U24+R24+K24+L24+M24+Q24 -> 3576.8 | AH24: =AG24*2% -> 71.536 | AI24: =AG24+AH24 -> 3648.336 | AJ24: =P24+V24+W24+X24+Y24+AA24+AC24+AD24 -> 1465.79 | AK24: =J24*2% -> 80.001 | AL24: =AI24+AJ24+AK24 -> 5194.127 | AM24: =AL24*16% -> 831.06032 | AN24: =AL24+AM24 -> 6025.1873
A25: SEI0438 | B25: Lopez Terron Roberto Porfirio | C25: 15 | D25: 0 | E25: 466.67 | F25: 494.92 | G25: 7000.05 | H25: 0 | I25: 0 | J25: 7000.05 | K25: 0 | L25: 0 | M25: 0 | N25: 0 | O25: 856.99 | P25: 203.53 | Q25: 0 | R25: 0 | S25: -0.07 | T25: 1060.45 | U25: 5939.6 | V25: 138.58 | W25: 249.44 | X25: 456.86 | Y25: 346.64 | Z25: 140 | AA25: 63.08 | AB25: 844.88 | AC25: 395.94 | AD25: 267.46 | AE25: 110 | AF25: =((20/365.24)*15)*E25 -> 383.31234 | AG25: =U25+R25+K25+L25+M25+Q25 -> 5939.6 | AH25: =AG25*2% -> 118.792 | AI25: =AG25+AH25 -> 6058.392 | AJ25: =P25+V25+W25+X25+Y25+AA25+AC25+AD25 -> 2121.53 | AK25: =J25*2% -> 140.001 | AL25: =AI25+AJ25+AK25 -> 8319.923 | AM25: =AL25*16% -> 1331.1877 | AN25: =AL25+AM25 -> 9651.1107
A26: SEI0442 | B26: Chavez Pedraza Samuel | C26: 15 | D26: 0 | E26: 466.67 | F26: 494.92 | G26: 7000.05 | H26: 0 | I26: 0 | J26: 7000.05 | K26: 0 | L26: 0 | M26: 0 | N26: 0 | O26: 856.99 | P26: 203.53 | Q26: 0 | R26: 0 | S26: -0.07 | T26: 1060.45 | U26: 5939.6 | V26: 138.58 | W26: 249.44 | X26: 456.86 | Y26: 346.64 | Z26: 140 | AA26: 63.08 | AB26: 844.88 | AC26: 395.94 | AD26: 267.46 | AE26: 110 | AF26: =((20/365.24)*15)*E26 -> 383.31234 | AG26: =U26+R26+K26+L26+M26+Q26 -> 5939.6 | AH26: =AG26*2% -> 118.792 | AI26: =AG26+AH26 -> 6058.392 | AJ26: =P26+V26+W26+X26+Y26+AA26+AC26+AD26 -> 2121.53 | AK26: =J26*2% -> 140.001 | AL26: =AI26+AJ26+AK26 -> 8319.923 | AM26: =AL26*16% -> 1331.1877 | AN26: =AL26+AM26 -> 9651.1107
... A91: SEI479 | B91: Cruz Perez Alejandro Nezahualcoyotl | C91: 15 | D91: 0 | E91: 266.67 | F91: 282.81 | G91: 4000.05 | H91: 0 | I91: 0 | J91: 4000.05 | K91: 0 | L91: 0 | M91: 0 | N91: 0 | O91: 313.87 | P91: 109.35 | Q91: 0 | R91: 0 | S91: 0.03 | T91: 423.25 | U91: 3576.8 | V91: 79.19 | W91: 142.54 | X91: 360.12 | Y91: 278.77 | Z91: 80 | AA91: 36.05 | AB91: 581.85 | AC91: 226.25 | AD91: 233.52 | AE91: 110 | AF91: =((20/365.24)*15)*E91 -> 219.0368 | AG91: =U91+R91+K91+L91+M91+Q91 -> 3576.8 | AH91: =AG91*2% -> 71.536 | AI91: =AG91+AH91 -> 3648.336 | AJ91: =P91+V91+W91+X91+Y91+AA91+AC91+AD91 -> 1465.79 | AK91: =J91*2% -> 80.001 | AL91: =AI91+AJ91+AK91 -> 5194.127 | AM91: =AL91*16% -> 831.06032 | AN91: =AL91+AM91 -> 6025.1873
C92: ============= | D92: ============= | E92: ============= | F92: ============= | G92: ============= | H92: ============= | I92: ============= | J92: ============= | K92: ============= | L92: ============= | M92: ============= | N92: ============= | O92: ============= | P92: ============= | Q92: ============= | R92: ============= | S92: ============= | T92: ============= | U92: ============= | V92: ============= | W92: ============= | X92: ============= | Y92: ============= | Z92: ============= | AA92: ============= | AB92: ============= | AC92: ============= | AD92: ============= | AE92: ============= | AF92: =============
A93: Total Gral. | C93: =SUM(C9:C91) -> 1198 | D93: =SUM(D9:D91) -> 28 | E93: =SUM(E9:E91) -> 19920.61 | F93: =SUM(F9:F91) -> 21003.44 | G93: =SUM(G9:G91) -> 288699.96 | H93: =SUM(H9:H91) -> 6199.29 | I93: =SUM(I9:I91) -> 4094.87 | J93: =SUM(J9:J91) -> 298994.12 | ... AF93: =SUM(AF9:AF91) -> 16362.345
A95: 82 | B95: Nomina
A96: 2 | B96: Altas | I96: FACTURACION PITS
A97: 1 | B97: Bajas | I97: Devengado Salario | J97: =+U93 -> 233719.4
A98: =+A95+A96-A97 -> 83 | B98: Total Nomina | I98: RETORNOS | J98: =+R93-R77 -> 6577.77 | K98: =+J98-R86 -> 5494.17 | L98: solo retornar este monto
I99: Infonavit | J99: =+K93+L93+M93 -> 32707.87
I100: Prestamo Prospera | J100: 0
I101: Subtotal 1 | J101: =SUM(J97:J100) -> 273005.04
I102: Comision | J102: =+J101*2% -> 5460.1008
I103: Subtotal 2 | J103: =+J101+J102 -> 278465.14
I104: Costo Patronal Imss | J104: =+P93+V93+W93+X93+Y93+AA93+AC93+AD93 -> 113600.25
I105: 2% Sobre Nomina | J105: =+J93*2% -> 5979.8824
I106: Importe de Factura | J106: =+J103+J104+J105 -> 398045.27
I107: IVA | J107: =+J106*16% -> 63687.244
I108: TOTAL | J108: =+J106+J107 -> 461732.52
...

Sheet SIND PITS
D1: SINDICATO | J1: PRIMA VACACIONAL
A2: CLAVE | B2: EMPRESA | C2: NOMBRE | D2: SUELDO SINDICATO | E2: BONO | F2: COMISION | G2: prima vacaciones | H2: TOTAL | J2: DIAS DE VACACIONES | K2: SUELDO NETO MENSUAL | L2: MONTO PRIMA TOTAL | M2: MENOS PRIMA IMSS | N2: PRIMA A PAGAR SINDICATO | R2: comision | S2: subtotal | T2: iva
A3: SEI0097 | B3: CONSULTORIA | C3: Arreola Jimenez Jose Nieves | D3: 1562.82 | E3: 480 | G3: =+N3 -> 0 | H3: =SUM(D3:G3) -> 2042.82 | J3: =VLOOKUP($C3,'CPD PITSS'!$B$9:$V$26,3,0) -> 0 | K3: 10150 | L3: =(((+K3/30)*J3)*30%) -> 0 | M3: =VLOOKUP($C3,'CPD PITSS'!$B$9:$V$26,8,0) -> 0 | N3: =+L3-M3 -> 0 | O3: SEI0097 | P3: =VLOOKUP(C3,'RESUMEN PITS'!$C$3:$V$103,20,0) -> 0 | Q3: =+D3+P3 -> 1562.82 | R3: =H3*2% -> 40.8564 | S3: =H3+R3 -> 2083.6764 | T3: =S3*16% -> 333.38822
A4: SEI0118 | B4: CONSULTORIA | C4: Arroyo Ramirez Hector Hugo | D4: 2108.92 | G4: =+N4 -> 0 | H4: =SUM(D4:G4) -> 2108.92 | J4: 0 | K4: 13000 | L4: =(((+K4/30)*J4)*30%) -> 0 | M4: =VLOOKUP($C4,'CPD PITSS'!$B$9:$V$26,8,0) -> 0 | N4: =+L4-M4 -> 0 | O4: SEI0118 | P4: =VLOOKUP(C4,'RESUMEN PITS'!$C$3:$V$103,20,0) -> 0 | Q4: =+D4+P4 -> 2108.92 | R4: =H4*2% -> 42.1784 | S4: =H4+R4 -> 2151.0984 | T4: =S4*16% -> 344.17574
A5: SEI0377 | B5: CONSULTORIA | C5: Benavides Herrera Alejandra | D5: 16807.4 | G5: =+N5 -> 0 | H5: =SUM(D5:G5) -> 16807.4 | J5: =VLOOKUP(C5,'CPD PITSS'!$B$9:$V$26,3,0) -> 0 | K5: 40000 | L5: =(((+K5/30)*J5)*30%) -> 0 | M5: =VLOOKUP($C5,'CPD PITSS'!$B$9:$V$26,8,0) -> 0 | N5: =+L5-M5 -> 0 | O5: SEI0377 | P5: =VLOOKUP(C5,'RESUMEN PITS'!$C$3:$V$103,20,0) -> 0 | Q5: =+D5+P5 -> 16807.4 | R5: =H5*2% -> 336.148 | S5: =H5+R5 -> 17143.548 | T5: =S5*16% -> 2742.9677
A6: SEI0108 | B6: CONSULTORIA | C6: Caballero Diaz Francisco Javier | D6: =1801.62-238.8 -> 1562.82 | E6: 330 | G6: =+N6 -> 0 | H6: =SUM(D6:G6) -> 1892.82 | J6: =VLOOKUP(C6,'CPD PITSS'!$B$9:$V$26,3,0) -> 0 | K6: 10150 | L6: =(((+K6/30)*J6)*30%) -> 0 | M6: =VLOOKUP($C6,'CPD PITSS'!$B$9:$V$26,8,0) -> 0 | N6: =+L6-M6 -> 0 | O6: SEI0108 | P6: =VLOOKUP(C6,'RESUMEN PITS'!$C$3:$V$103,20,0) -> 0 | Q6: =+D6+P6 -> 1562.82 | R6: =H6*2% -> 37.8564 | S6: =H6+R6 -> 1930.6764 | T6: =S6*16% -> 308.90822
A7: SEI0425 | B7: CONSULTORIA | C7: Carbajal Cabuto Jose Luis | D7: 1612.77 | E7: 270 | G7: =+N7 -> 0 | H7: =SUM(D7:G7) -> 1882.77 | J7: =VLOOKUP(C7,'CPD PITSS'!$B$9:$V$26,3,0) -> 0 | K7: 10250 | L7: =(((+K7/30)*J7)*30%) -> 0 | M7: =VLOOKUP($C7,'CPD PITSS'!$B$9:$V$26,8,0) -> 0 | N7: =+L7-M7 -> 0 | O7: SEI0453 | P7: =VLOOKUP(C7,'RESUMEN PITS'!$C$3:$V$103,20,0) -> 0 | Q7: =+D7+P7 -> 1612.77 | R7: =H7*2% -> 37.6554 | S7: =H7+R7 -> 1920.4254 | T7: =S7*16% -> 307.26806
A8: SEI0116 | B8: CONSULTORIA | C8: Casillas Cardona Cesar Alejandro | D8: 1896.87 | G8: =+N8 -> 0 | H8: =SUM(D8:G8) -> 1896.87 | J8: =VLOOKUP(C8,'CPD PITSS'!$B$9:$V$26,3,0) -> 0 | K8: 12000 | L8: =(((+K8/30)*J8)*30%) -> 0 | M8: =VLOOKUP($C8,'CPD PITSS'!$B$9:$V$26,8,0) -> 0 | N8: =+L8-M8 -> 0 | O8: SEI0116 | P8: =VLOOKUP(C8,'RESUMEN PITS'!$C$3:$V$103,20,0) -> 0 | Q8: =+D8+P8 -> 1896.87 | R8: =H8*2% -> 37.9374 | S8: =H8+R8 -> 1934.8074 | T8: =S8*16% -> 309.56918
A9: SEI0401 | B9: CONSULTORIA | C9: De La Torre Zambara Francisco Ernesto | D9: 1562.8 | E9: 270 | G9: =+N9 -> 0 | H9: =SUM(D9:G9) -> 1832.8 | J9: =VLOOKUP(C9,'CPD PITSS'!$B$9:$V$26,3,0) -> 0 | K9: 10150 | L9: =(((+K9/30)*J9)*30%) -> 0 | M9: =VLOOKUP($C9,'CPD PITSS'!$B$9:$V$26,8,0) -> 0 | N9: =+L9-M9 -> 0 | O9: SEI0401 | P9: =VLOOKUP(C9,'RESUMEN PITS'!$C$3:$V$103,20,0) -> 0 | Q9: =+D9+P9 -> 1562.8 | R9: =H9*2% -> 36.656 | S9: =H9+R9 -> 1869.456 | T9: =S9*16% -> 299.11296
A10: SEI0099 | B10: CONSULTORIA | C10: Garcia Villicaña Ricardo Pascual | D10: 2607.2 | E10: 150 | F10: 2160 | G10: =+N10 -> 272 | H10: =SUM(D10:G10) -> 5189.2 | J10: =VLOOKUP(C10,'CPD PITSS'!$B$9:$V$26,3,0) -> 4 | K10: 15000 | L10: =(((+K10/30)*J10)*30%) -> 600 | M10: =VLOOKUP($C10,'CPD PITSS'!$B$9:$V$26,8,0) -> 328 | N10: =+L10-M10 -> 272 | O10: SEI0099 | P10: =VLOOKUP(C10,'RESUMEN PITS'!$C$3:$V$103,20,0) -> 0 | Q10: =+D10+P10 -> 2607.2 | R10: =H10*2% -> 103.784 | S10: =H10+R10 -> 5292.984 | T10: =S10*16% -> 846.87744
A11: SEI0009 | B11: CONSULTORIA | C11: Gutierrez Gutierrez Luis Arturo | D11: 1479 | E11: 100 | G11: =+N11 -> 255 | H11: =SUM(D11:G11) -> 1834 | J11: 6 | K11: 8500 | L11: =(((+K11/30)*J11)*30%) -> 510 | M11: =VLOOKUP($C11,'CPD PITSS'!$B$9:$V$26,8,0) -> 255 | N11: =+L11-M11 -> 255 | O11: SEI0009 | P11: =VLOOKUP(C11,'RESUMEN PITS'!$C$3:$V$103,20,0) -> 0 | Q11: =+D11+P11 -> 1479 | R11: =H11*2% -> 36.68 | S11: =H11+R11 -> 1870.68 | T11: =S11*16% -> 299.3088
A12: SEI0127 | B12: CONSULTORIA | C12: Hernandez Ochoa Eduardo | D12: 2607.2 | E12: 337.5 | G12: =+N12 -> 0 | H12: =SUM(D12:G12) -> 2944.7 | J12: =VLOOKUP(C12,'CPD PITSS'!$B$9:$V$26,3,0) -> 0 | K12: 15000 | L12: =(((+K12/30)*J12)*30%) -> 0 | M12: =VLOOKUP($C12,'CPD PITSS'!$B$9:$V$26,8,0) -> 0 | N12: =+L12-M12 -> 0 | O12: SEI0127 | P12: =VLOOKUP(C12,'RESUMEN PITS'!$C$3:$V$103,20,0) -> 0 | Q12: =+D12+P12 -> 2607.2 | R12: =H12*2% -> 58.894 | S12: =H12+R12 -> 3003.594 | T12: =S12*16% -> 480.57504
A13: SEI0117 | B13: CONSULTORIA | C13: Mariscal Romero Luis Adrian | D13: 2757.68 | E13: 165 | G13: =+N13 -> 0 | H13: =SUM(D13:G13) -> 2922.68 | J13: =VLOOKUP(C13,'CPD PITSS'!$B$9:$V$26,3,0) -> 0 | K13: 15000 | L13: =(((+K13/30)*J13)*30%) -> 0 | M13: =VLOOKUP($C13,'CPD PITSS'!$B$9:$V$26,8,0) -> 0 | N13: =+L13-M13 -> 0 | O13: SEI0117 | P13: =VLOOKUP(C13,'RESUMEN PITS'!$C$3:$V$103,20,0) -> 0 | Q13: =+D13+P13 -> 2757.68 | R13: =H13*2% -> 58.4536 | S13: =H13+R13 -> 2981.1336 | T13: =S13*16% -> 476.98138
A14: SEI0040 | B14: CONSULTORIA | C14: Mora Ramirez Acal Aldo Isidro | D14: 2469.4 | E14: 1000 | G14: =+N14 -> 0 | H14: =SUM(D14:G14) -> 3469.4 | J14: =VLOOKUP(C14,'CPD PITSS'!$B$9:$V$26,3,0) -> 0 | K14: 13000 | L14: =(((+K14/30)*J14)*30%) -> 0 | M14: =VLOOKUP($C14,'CPD PITSS'!$B$9:$V$26,8,0) -> 0 | N14: =+L14-M14 -> 0 | O14: SEI0040 | P14: =VLOOKUP(C14,'RESUMEN PITS'!$C$3:$V$103,20,0) -> 0 | Q14: =+D14+P14 -> 2469.4 | R14: =H14*2% -> 69.388 | S14: =H14+R14 -> 3538.788 | T14: =S14*16% -> 566.20608
A15: SEI0088 | B15: CONSULTORIA | C15: Morgado Fernandez Martin | D15: =2883.2-275.95 -> 2607.25 | E15: 337.5 | G15: =+N15 -> 204 | H15: =SUM(D15:G15) -> 3148.75 | J15: =VLOOKUP(C15,'CPD PITSS'!$B$9:$V$26,3,0) -> 3 | K15: 15000 | L15: =(((+K15/30)*J15)*30%) -> 450 | M15: =VLOOKUP($C15,'CPD PITSS'!$B$9:$V$26,8,0) -> 246 | N15: =+L15-M15 -> 204 | O15: SEI0088 | P15: =VLOOKUP(C15,'RESUMEN PITS'!$C$3:$V$103,20,0) -> 0 | Q15: =+D15+P15 -> 2607.25 | R15: =H15*2% -> 62.975 | S15: =H15+R15 -> 3211.725 | T15: =S15*16% -> 513.876
A16: SEI0173 | B16: CONSULTORIA | C16: Nieto Ortiz Jose Luis | D16: =1784.75-297 -> 1487.75 | E16: 20 | G16: =+N16 -> 0 | H16: =SUM(D16:G16) -> 1507.75 | J16: =VLOOKUP(C16,'CPD PITSS'!$B$9:$V$26,3,0) -> 0 | K16: 10000 | L16: =(((+K16/30)*J16)*30%) -> 0 | M16: =VLOOKUP($C16,'CPD PITSS'!$B$9:$V$26,8,0) -> 0 | N16: =+L16-M16 -> 0 | O16: SEI0173 | P16: =VLOOKUP(C16,'RESUMEN PITS'!$C$3:$V$103,20,0) -> 0 | Q16: =+D16+P16 -> 1487.75 | R16: =H16*2% -> 30.155 | S16: =H16+R16 -> 1537.905 | T16: =S16*16% -> 246.0648
A17: SEI0026 | B17: CONSULTORIA | C17: Patricio Aguilar Jhonattan Cristian | D17: 1591.8 | E17: 400 | G17: =+N17 -> 0 | H17: =SUM(D17:G17) -> 1991.8 | J17: =VLOOKUP(C17,'CPD PITSS'!$B$9:$V$26,3,0) -> 0 | K17: 9000 | L17: =(((+K17/30)*J17)*30%) -> 0 | M17: =VLOOKUP($C17,'CPD PITSS'!$B$9:$V$26,8,0) -> 0 | N17: =+L17-M17 -> 0 | O17: SEI0026 | P17: =VLOOKUP(C17,'RESUMEN PITS'!$C$3:$V$103,20,0) -> 0 | Q17: =+D17+P17 -> 1591.8 | R17: =H17*2% -> 39.836 | S17: =H17+R17 -> 2031.636 | T17: =S17*16% -> 325.06176
A18: SEI0221 | B18: CONSULTORIA | C18: Rogel Teran Marco Antonio | D18: 12643.2 | G18: =+N18 -> 0 | H18: =SUM(D18:G18) -> 12643.2 | J18: =VLOOKUP(C18,'CPD PITSS'!$B$9:$V$26,3,0) -> 0 | K18: 60000 | L18: =(((+K18/30)*J18)*30%) -> 0 | M18: =VLOOKUP($C18,'CPD PITSS'!$B$9:$V$26,8,0) -> 0 | N18: =+L18-M18 -> 0 | O18: SEI0221 | P18: =VLOOKUP(C18,'RESUMEN PITS'!$C$3:$V$103,20,0) -> 0 | Q18: =+D18+P18 -> 12643.2 | R18: =H18*2% -> 252.864 | S18: =H18+R18 -> 12896.064 | T18: =S18*16% -> 2063.3702
A19: SEI0442 | B19: CONSULTORIA | C19: Sierra Escamilla Daniela | D19: 2469.4 | E19: 1000 | G19: =+N19 -> 0 | H19: =SUM(D19:G19) -> 3469.4 | J19: =VLOOKUP(C19,'CPD PITSS'!$B$9:$V$26,3,0) -> 0 | K19: 13000 | L19: =(((+K19/30)*J19)*30%) -> 0 | M19: =VLOOKUP($C19,'CPD PITSS'!$B$9:$V$26,8,0) -> 0 | N19: =+L19-M19 -> 0 | O19: SEI0618 | P19: =VLOOKUP(C19,'RESUMEN PITS'!$C$3:$V$103,20,0) -> 0 | Q19: =+D19+P19 -> 2469.4 | R19: =H19*2% -> 69.388 | S19: =H19+R19 -> 3538.788 | T19: =S19*16% -> 566.20608
A20: SEI0041 | B20: CONSULTORIA | C20: Vazquez Perez Miguel Angel | D20: 4183.2 | E20: 750 | G20: =+N20 -> 0 | H20: =SUM(D20:G20) -> 4933.2 | J20: =VLOOKUP(C20,'CPD PITSS'!$B$9:$V$26,3,0) -> 0 | K20: 18500 | L20: =(((+K20/30)*J20)*30%) -> 0 | M20: =VLOOKUP($C20,'CPD PITSS'!$B$9:$V$26,8,0) -> 0 | N20: =+L20-M20 -> 0 | O20: SEI0041 | P20: =VLOOKUP(C20,'RESUMEN PITS'!$C$3:$V$103,20,0) -> 0 | Q20: =+D20+P20 -> 4183.2 | R20: =H20*2% -> 98.664 | S20: =H20+R20 -> 5031.864 | T20: =S20*16% -> 805.09824
A21: SEI0544 | B21: IP INNOVACION | C21: Aguilar Aguirre Alfonso | D21: 140.4 | H21: =SUM(D21:G21) -> 140.4 | J21: =VLOOKUP(C21,'IP PITSS'!$B$9:$U$91,3,0) -> 0 | K21: 6000 | L21: =(((+K21/30)*J21)*30%) -> 0 | M21: =VLOOKUP(C21,'IP PITSS'!$B$9:$I$91,8,0) -> 0 | N21: =+L21-M21 -> 0 | O21: SEI0652 | P21: =VLOOKUP(C21,'RESUMEN PITS'!$C$3:$V$103,20,0) -> 0 | Q21: =+D21+P21 -> 140.4 | R21: =H21*2% -> 2.808 | S21: =H21+R21 -> 143.208 | T21: =S21*16% -> 22.91328
A22: SEI0527 | B22: IP INNOVACION | C22: Alejandro Peña Deivi | D22: 180.8 | E22: 1068.75 | G22: =+N22 -> 0 | H22: =SUM(D22:G22) -> 1249.55 | J22: =VLOOKUP(C22,'IP PITSS'!$B$9:$U$91,3,0) -> 0 | K22: 6300 | L22: =(((+K22/30)*J22)*30%) -> 0 | M22: =VLOOKUP(C22,'IP PITSS'!$B$9:$I$91,8,0) -> 0 | N22: =+L22-M22 -> 0 | O22: SEI0628 | P22: =VLOOKUP(C22,'RESUMEN PITS'!$C$3:$V$103,20,0) -> 0 | Q22: =+D22+P22 -> 180.8 | R22: =H22*2% -> 24.991 | S22: =H22+R22 -> 1274.541 | T22: =S22*16% -> 203.92656
A23: SEI0535 | B23: IP INNOVACION | C23: Alejandro Vazquez Erasmo Miguel | D23: 3140.35 | E23: 750 | G23: =+N23 -> 0 | H23: =SUM(D23:G23) -> 3890.35 | J23: =VLOOKUP(C23,'IP PITSS'!$B$9:$U$91,3,0) -> 0 | K23: 12000 | L23: =(((+K23/30)*J23)*30%) -> 0 | M23: =VLOOKUP(C23,'IP PITSS'!$B$9:$I$91,8,0) -> 0 | N23: =+L23-M23 -> 0 | O23: SEI0638 | P23: =VLOOKUP(C23,'RESUMEN PITS'!$C$3:$V$103,20,0) -> 0 | Q23: =+D23+P23 -> 3140.35 | R23: =H23*2% -> 77.807 | S23: =H23+R23 -> 3968.157 | T23: =S23*16% -> 634.90512
A24: SEI0029 | B24: IP INNOVACION | C24: Arceo Garcia Manuel Federico | D24: 140.2 | E24: 1545 | G24: =+N24 -> 0 | H24: =SUM(D24:G24) -> 1685.2 | J24: =VLOOKUP(C24,'IP PITSS'!$B$9:$U$91,3,0) -> 0 | K24: 6000 | L24: =(((+K24/30)*J24)*30%) -> 0 | M24: =VLOOKUP(C24,'IP PITSS'!$B$9:$I$91,8,0) -> 0 | N24: =+L24-M24 -> 0 | O24: SEI0029 | P24: =VLOOKUP(C24,'RESUMEN PITS'!$C$3:$V$103,20,0) -> 0 | Q24: =+D24+P24 -> 140.2 | R24: =H24*2% -> 33.704 | S24: =H24+R24 -> 1718.904 | T24: =S24*16% -> 275.02464
A25: SEI0472 | B25: IP INNOVACION | C25: Arzate Gil Juan Sebastian | D25: 423 | E25: 480 | G25: =+N25 -> 0 | H25: =SUM(D25:G25) -> 903 | J25: =VLOOKUP(C25,'IP PITSS'!$B$9:$U$91,3,0) -> 0 | K25: 8000 | L25: =(((+K25/30)*J25)*30%) -> 0 | M25: =VLOOKUP(C25,'IP PITSS'!$B$9:$I$91,8,0) -> 0 | N25: =+L25-M25 -> 0 | O25: SEI0550 | P25: =VLOOKUP(C25,'RESUMEN PITS'!$C$3:$V$103,20,0) -> 0 | Q25: =+D25+P25 -> 423 | R25: =H25*2% -> 18.06 | S25: =H25+R25 -> 921.06 | T25: =S25*16% -> 147.3696
A26: SEI0528 | B26: IP INNOVACION | C26: Casas Chavarria Rafael | D26: 180.92 | E26: 675 | G26: =+N26 -> 0 | H26: =SUM(D26:G26) -> 855.92 | J26: =VLOOKUP(C26,'IP PITSS'!$B$9:$U$91,3,0) -> 0 | K26: 6300 | L26: =(((+K26/30)*J26)*30%) -> 0 | M26: =VLOOKUP(C26,'IP PITSS'!$B$9:$I$91,8,0) -> 0 | N26: =+L26-M26 -> 0 | O26: SEI0629 | P26: =VLOOKUP(C26,'RESUMEN PITS'!$C$3:$V$103,20,0) -> 0 | Q26: =+D26+P26 -> 180.92 | R26: =H26*2% -> 17.1184 | S26: =H26+R26 -> 873.0384 | T26: =S26*16% -> 139.68614
A27: SEI0460 | B27: IP INNOVACION | C27: Castellon Ramos Rene | D27: 391.185 | E27: 135 | G27: =+N27 -> 0.0599 | H27: =SUM(D27:G27) -> 526.2449 | J27: =VLOOKUP(C27,'IP PITSS'!$B$9:$U$91,3,0) -> 1 | K27: 7505.99 | L27: =(((+K27/30)*J27)*30%) -> 75.0599 | M27: =VLOOKUP(C27,'IP PITSS'!$B$9:$I$91,8,0) -> 75 | N27: =+L27-M27 -> 0.0599 | O27: SEI0499 | P27: =VLOOKUP(C27,'RESUMEN PITS'!$C$3:$V$103,20,0) -> 0 | Q27: =+D27+P27 -> 391.185 | R27: =H27*2% -> 10.524898 | S27: =H27+R27 -> 536.7698 | T27: =S27*16% -> 85.883168
A28: SEI0443 | B28: IP INNOVACION | C28: Castillo Nungaray Nestor Roman | D28: 140.4 | E28: 2250 | G28: =+N28 -> 0 | H28: =SUM(D28:G28) -> 2390.4 | J28: =VLOOKUP(C28,'IP PITSS'!$B$9:$U$91,3,0) -> 0 | K28: 6000 | L28: =(((+K28/30)*J28)*30%) -> 0 | M28: =VLOOKUP(C28,'IP PITSS'!$B$9:$I$91,8,0) -> 0 | N28: =+L28-M28 -> 0 | O28: SEI0468 | P28: =VLOOKUP(C28,'RESUMEN PITS'!$C$3:$V$103,20,0) -> 0 | Q28: =+D28+P28 -> 140.4 | R28: =H28*2% -> 47.808 | S28: =H28+R28 -> 2438.208 | T28: =S28*16% -> 390.11328
A29: SEI0490 | B29: IP INNOVACION | C29: Castillo Ramirez Hector Ivan | D29: 3727.2 | E29: 437.5 | G29: =+N29 -> 0 | H29: =SUM(D29:G29) -> 4164.7 | J29: =VLOOKUP(C29,'IP PITSS'!$B$9:$U$91,3,0) -> 0 | K29: 14000 | L29: =(((+K29/30)*J29)*30%) -> 0 | M29: =VLOOKUP(C29,'IP PITSS'!$B$9:$I$91,8,0) -> 0 | N29: =+L29-M29 -> 0 | O29: SEI0448 | P29: =VLOOKUP(C29,'RESUMEN PITS'!$C$3:$V$103,20,0) -> 0 | Q29: =+D29+P29 -> 3727.2 | R29: =H29*2% -> 83.294 | S29: =H29+R29 -> 4247.994 | T29: =S29*16% -> 679.67904
A30: SEI0508 | B30: IP INNOVACION | C30: Cerro Garcia Elvis | D30: 2557.6 | E30: 400 | G30: =+N30 -> 0 | H30: =SUM(D30:G30) -> 2957.6 | J30: =VLOOKUP(C30,'IP PITSS'!$B$9:$U$91,3,0) -> 0 | K30: 10000 | L30: =(((+K30/30)*J30)*30%) -> 0 | M30: =VLOOKUP(C30,'IP PITSS'!$B$9:$I$91,8,0) -> 0 | N30: =+L30-M30 -> 0 | O30: SEI0513 | P30: =VLOOKUP(C30,'RESUMEN PITS'!$C$3:$V$103,20,0) -> 0 | Q30: =+D30+P30 -> 2557.6 | R30: =H30*2% -> 59.152 | S30: =H30+R30 -> 3016.752 | T30: =S30*16% -> 482.68032
A31: SEI0499 | B31: IP INNOVACION | C31: Chavez Dominguez Salvador | D31: 2673.38 | E31: 750 | G31: =+N31 -> 725.22 | H31: =SUM(D31:G31) -> 4148.6 | J31: =VLOOKUP(C31,'IP PITSS'!$B$9:$U$91,3,0) -> 15 | K31: 12000 | L31: =(((+K31/30)*J31)*30%) -> 1800 | M31: =VLOOKUP(C31,'IP PITSS'!$B$9:$I$91,8,0) -> 1074.78 | N31: =+L31-M31 -> 725.22 | O31: SEI0483 | P31: =VLOOKUP(C31,'RESUMEN PITS'!$C$3:$V$103,20,0) -> 0 | Q31: =+D31+P31 -> 2673.38 | R31: =H31*2% -> 82.972 | S31: =H31+R31 -> 4231.572 | T31: =S31*16% -> 677.05152
A32: SEI0541 | B32: IP INNOVACION | C32: Chavez Govea Edgar Aram | D32: 228.4 | E32: 250 | G32: =+N32 -> 0 | H32: =SUM(D32:G32) -> 478.4 | J32: =VLOOKUP(C32,'IP PITSS'!$B$9:$U$91,3,0) -> 0 | K32: 7000 | L32: =(((+K32/30)*J32)*30%) -> 0 | M32: =VLOOKUP(C32,'IP PITSS'!$B$9:$I$91,8,0) -> 0 | N32: =+L32-M32 -> 0 | O32: SEI0644 | P32: =VLOOKUP(C32,'RESUMEN PITS'!$C$3:$V$103,20,0) -> 0 | Q32: =+D32+P32 -> 228.4 | R32: =H32*2% -> 9.568 | S32: =H32+R32 -> 487.968 | T32: =S32*16% -> 78.07488
A33: SEI0442 | B33: IP INNOVACION | C33: Chavez Pedraza Samuel | D33: 1060.4 | E33: 687.5 | G33: =+N33 -> 0 | H33: =SUM(D33:G33) -> 1747.9 | J33: =VLOOKUP(C33,'IP PITSS'!$B$9:$U$91,3,0) -> 0 | K33: 14000 | L33: =(((+K33/30)*J33)*30%) -> 0 | M33: =VLOOKUP(C33,'IP PITSS'!$B$9:$I$91,8,0) -> 0 | N33: =+L33-M33 -> 0 | O33: SEI0467 | P33: =VLOOKUP(C33,'RESUMEN PITS'!$C$3:$V$103,20,0) -> 0 | Q33: =+D33+P33 -> 1060.4 | R33: =H33*2% -> 34.958 | S33: =H33+R33 -> 1782.858 | T33: =S33*16% -> 285.25728
... A42: SEI0364 | B42: IP INNOVACION | C42: Dominguez Lopez Mayeli Del Pilar | D42: 1423.2 | E42: 718.75 | G42: =+N42 -> 0 | H42: =SUM(D42:G42) -> 2141.95 | J42: =VLOOKUP(C42,'IP PITSS'!$B$9:$U$91,3,0) -> 0 | K42: 10000 | L42: =(((+K42/30)*J42)*30%) -> 0 | M42: =VLOOKUP(C42,'IP PITSS'!$B$9:$I$91,8,0) -> 0 | N42: =+L42-M42 -> 0 | O42: SEI0364 | P42: =VLOOKUP(C42,'RESUMEN PITS'!$C$3:$V$103,20,0) -> -0.07 | Q42: =+D42+P42 -> 1423.13 | R42: =H42*2% -> 42.839 | S42: =H42+R42 -> 2184.789 | T42: =S42*16% -> 349.56624
A43: SEI0474 | B43: IP INNOVACION | C43: Enriquez Zamora Jessica Del Rocio | D43: =314.8-200 -> 114.8 | E43: 455 | G43: =+N43 -> 0 | H43: =SUM(D43:G43) -> 569.8 | J43: =VLOOKUP(C43,'IP PITSS'!$B$9:$U$91,3,0) -> 0 | K43: 6000 | L43: =(((+K43/30)*J43)*30%) -> 0 | M43: =VLOOKUP(C43,'IP PITSS'!$B$9:$I$91,8,0) -> 0 | N43: =+L43-M43 -> 0 | O43: SEI0600 | P43: =VLOOKUP(C43,'RESUMEN PITS'!$C$3:$V$103,20,0) -> 200 | Q43: =+D43+P43 -> 314.8 | R43: =H43*2% -> 11.396 | S43: =H43+R43 -> 581.196 | T43: =S43*16% -> 92.99136
A44: SEI0489 | B44: IP INNOVACION | C44: Escobedo Olivares Juan Guadalupe | D44: 3727 | E44: 375 | G44: =+N44 -> 0 | H44: =SUM(D44:G44) -> 4102 | J44: =VLOOKUP(C44,'IP PITSS'!$B$9:$U$91,3,0) -> 0 | K44: 14000 | L44: =(((+K44/30)*J44)*30%) -> 0 | M44: =VLOOKUP(C44,'IP PITSS'!$B$9:$I$91,8,0) -> 0 | N44: =+L44-M44 -> 0 | O44: SEI0447 | P44: =VLOOKUP(C44,'RESUMEN PITS'!$C$3:$V$103,20,0) -> 0 | Q44: =+D44+P44 -> 3727 | R44: =H44*2% -> 82.04 | S44: =H44+R44 -> 4184.04 | T44: =S44*16% -> 669.4464
A45: SEI0449 | B45: IP INNOVACION | C45: Flores Cerrillos Jorge Humberto | D45: 423.2 | E45: 130 | G45: =+N45 -> 0 | H45: =SUM(D45:G45) -> 553.2 | J45: =VLOOKUP(C45,'IP PITSS'!$B$9:$U$91,3,0) -> 0 | K45: 8000 | L45: =(((+K45/30)*J45)*30%) -> 0 | M45: =VLOOKUP(C45,'IP PITSS'!$B$9:$I$91,8,0) -> 0 | N45: =+L45-M45 -> 0 | O45: SEI0474 | P45: =VLOOKUP(C45,'RESUMEN PITS'!$C$3:$V$103,20,0) -> 0 | Q45: =+D45+P45 -> 423.2 | R45: =H45*2% -> 11.064 | S45: =H45+R45 -> 564.264 | T45: =S45*16% -> 90.28224
A46: SEI0461 | B46: IP INNOVACION | C46: Flores Franco Marco | D46: 458.205 | E46: 412.5 | G46: =+N46 -> 0 | H46: =SUM(D46:G46) -> 870.705 | J46: =VLOOKUP(C46,'IP PITSS'!$B$9:$U$91,3,0) -> 0 | K46: 8500.01 | L46: =(((+K46/30)*J46)*30%) -> 0 | M46: =VLOOKUP(C46,'IP PITSS'!$B$9:$I$91,8,0) -> 0 | N46: =+L46-M46 -> 0 | O46: SEI0500 | P46: =VLOOKUP(C46,'RESUMEN PITS'!$C$3:$V$103,20,0) -> 0 | Q46: =+D46+P46 -> 458.205 | R46: =H46*2% -> 17.4141 | S46: =H46+R46 -> 888.1191 | T46: =S46*16% -> 142.09906
A47: SEI0500 | B47: IP INNOVACION | C47: Garcia Gutierrez Jose Juan | D47: 3140.2 | E47: 225 | G47: =+N47 -> 0 | H47: =SUM(D47:G47) -> 3365.2 | J47: =VLOOKUP(C47,'IP PITSS'!$B$9:$U$91,3,0) -> 0 | K47: 12000 | L47: =(((+K47/30)*J47)*30%) -> 0 | M47: =VLOOKUP(C47,'IP PITSS'!$B$9:$I$91,8,0) -> 0 | N47: =+L47-M47 -> 0 | O47: SEI0484 | P47: =VLOOKUP(C47,'RESUMEN PITS'!$C$3:$V$103,20,0) -> 0 | Q47: =+D47+P47 -> 3140.2 | R47: =H47*2% -> 67.304 | S47: =H47+R47 -> 3432.504 | T47: =S47*16% -> 549.20064
A48: SEI0534 | B48: IP INNOVACION | C48: Gonzalez Ramirez Paul | D48: 139.1 | E48: 130 | G48: =+N48 -> 0 | H48: =SUM(D48:G48) -> 269.1 | J48: =VLOOKUP(C48,'IP PITSS'!$B$9:$U$91,3,0) -> 0 | K48: 6000 | L48: =(((+K48/30)*J48)*30%) -> 0 | M48: =VLOOKUP(C48,'IP PITSS'!$B$9:$I$91,8,0) -> 0 | N48: =+L48-M48 -> 0 | O48: 0SEI0635 | P48: =VLOOKUP(C48,'RESUMEN PITS'!$C$3:$V$103,20,0) -> 0 | Q48: =+D48+P48 -> 139.1 | R48: =H48*2% -> 5.382 | S48: =H48+R48 -> 274.482 | T48: =S48*16% -> 43.91712
...

Sheet RESUMEN PITS
F1: SINDICATO
A2: CLAVE | B2: EMPRESA | C2: NOMBRE | D2: NETO IMSS | F2: SUELDO SINDICATO | G2: BONO | H2: COMISION | I2: PRIMA VACACIONAL SINDICATO | J2: B | K2: NETO A PAGAR | L2: NETO MENSUAL | M2: NETO QUINCENAL SEITON | N2: C | O2: prima vacacional | P2: COMISION Y PRIMA VACACIONAL | Q2: INFONAVIT | R2: FONACOT | S2: DESCUENTOS | T2: D | U2: TOTAL GENERAL | V2: DIFERENCIAS | W2: OBSERVACIONES | Y2: total
A3: SEI0009 | B3: CONSULTORIA | C3: Gutierrez Gutierrez Luis Arturo | D3: =VLOOKUP(C3,'CPD PITSS'!B9:V26,21,0) -> 3026 | F3: =VLOOKUP(C3,'SIND PITS'!$C$3:$H$104,2,0) -> 1479 | G3: =VLOOKUP(C3,'SIND PITS'!$C$3:$E$104,3,0) -> 100 | H3: =VLOOKUP(C3,'SIND PITS'!$C$3:$F$104,4,0) -> 0 | I3: =VLOOKUP(C3,'SIND PITS'!$C$3:$G$104,5,0) -> 255 | K3: =SUM(D3:I3) -> 4860 | L3: 8500 | M3: =+L3/2 -> 4250 | O3: =VLOOKUP($C3,'CPD PITSS'!$B$9:$V$26,8,0) -> 255 | P3: =+G3+H3+I3 -> 355 | Q3: =(VLOOKUP($C3,'CPD PITSS'!$B$9:$V$26,13,0))+(VLOOKUP($C3,'CPD PITSS'!$B$9:$V$26,14,0)) -> 0 | S3: =VLOOKUP(C3,'CPD PITSS'!$B$9:$S$26,18,0) -> 0 | U3: =+K3-O3-P3+Q3+R3+S3 -> 4250 | V3: =+M3-U3 -> 0 | X3: SEI0009 | Y3: =IFERROR(OFFSET('CPD PITSS'!$AN$8,MATCH('RESUMEN PITS'!C3,'CPD PITSS'!$B$9:$B$26,0),0),0)+IFERROR(OFFSET('IP PITSS'!$AL$8,MATCH('RESUMEN PITS'!C3,'IP PITSS'!$B$9:$B$91,0),0),0)+IFERROR(OFFSET('SIND PITS'!$S$2,MATCH('RESUMEN PITS'!C3,'SIND PITS'!$C$3:$C$103,0),0),0) -> 5951.496
A4: SEI0026 | B4: CONSULTORIA | C4: Patricio Aguilar Jhonattan Cristian | D4: =VLOOKUP(C4,'CPD PITSS'!B10:V27,21,0) -> 2908.2 | F4: =VLOOKUP(C4,'SIND PITS'!$C$3:$H$104,2,0) -> 1591.8 | G4: =VLOOKUP(C4,'SIND PITS'!$C$3:$E$104,3,0) -> 400 | H4: =VLOOKUP(C4,'SIND PITS'!$C$3:$F$104,4,0) -> 0 | I4: =VLOOKUP(C4,'SIND PITS'!$C$3:$G$104,5,0) -> 0 | K4: =SUM(D4:I4) -> 4900 | L4: 9000 | M4: =+L4/2 -> 4500 | O4: =VLOOKUP($C4,'CPD PITSS'!$B$9:$V$26,8,0) -> 0 | P4: =+G4+H4+I4 -> 400 | Q4: =(VLOOKUP($C4,'CPD PITSS'!$B$9:$V$26,13,0))+(VLOOKUP($C4,'CPD PITSS'!$B$9:$V$26,14,0)) -> 0 | S4: =VLOOKUP(C4,'CPD PITSS'!$B$9:$S$26,18,0) -> 0 | U4: =+K4-O4-P4+Q4+R4+S4 -> 4500 | V4: =+M4-U4 -> 0 | X4: SEI0026 | Y4: =IFERROR(OFFSET('CPD PITSS'!$AN$8,MATCH('RESUMEN PITS'!C4,'CPD PITSS'!$B$9:$B$26,0),0),0)+IFERROR(OFFSET('IP PITSS'!$AL$8,MATCH('RESUMEN PITS'!C4,'IP PITSS'!$B$9:$B$91,0),0),0)+IFERROR(OFFSET('SIND PITS'!$S$2,MATCH('RESUMEN PITS'!C4,'SIND PITS'!$C$3:$C$103,0),0),0) -> 6017.5002
A5: SEI0040 | B5: CONSULTORIA | C5: Mora Ramirez Acal Aldo Isidro | D5: =VLOOKUP(C5,'CPD PITSS'!B11:V28,21,0) -> 4030.6 | F5: =VLOOKUP(C5,'SIND PITS'!$C$3:$H$104,2,0) -> 2469.4 | G5: =VLOOKUP(C5,'SIND PITS'!$C$3:$E$104,3,0) -> 1000 | H5: =VLOOKUP(C5,'SIND PITS'!$C$3:$F$104,4,0) -> 0 | I5: =VLOOKUP(C5,'SIND PITS'!$C$3:$G$104,5,0) -> 0 | K5: =SUM(D5:I5) -> 7500 | L5: 13000 | M5: =+L5/2 -> 6500 | O5: =VLOOKUP($C5,'CPD PITSS'!$B$9:$V$26,8,0) -> 0 | P5: =+G5+H5+I5 -> 1000 | Q5: =(VLOOKUP($C5,'CPD PITSS'!$B$9:$V$26,13,0))+(VLOOKUP($C5,'CPD PITSS'!$B$9:$V$26,14,0)) -> 0 | S5: =VLOOKUP(C5,'CPD PITSS'!$B$9:$S$26,18,0) -> 0 | U5: =+K5-O5-P5+Q5+R5+S5 -> 6500 | V5: =+M5-U5 -> 0 | X5: SEI0040 | Y5: =IFERROR(OFFSET('CPD PITSS'!$AN$8,MATCH('RESUMEN PITS'!C5,'CPD PITSS'!$B$9:$B$26,0),0),0)+IFERROR(OFFSET('IP PITSS'!$AL$8,MATCH('RESUMEN PITS'!C5,'IP PITSS'!$B$9:$B$91,0),0),0)+IFERROR(OFFSET('SIND PITS'!$S$2,MATCH('RESUMEN PITS'!C5,'SIND PITS'!$C$3:$C$103,0),0),0) -> 8871.756
A6: SEI0041 | B6: CONSULTORIA | C6: Vazquez Perez Miguel Angel | D6: =VLOOKUP(C6,'CPD PITSS'!B12:V29,21,0) -> 5066.8 | F6: =VLOOKUP(C6,'SIND PITS'!$C$3:$H$104,2,0) -> 4183.2 | G6: =VLOOKUP(C6,'SIND PITS'!$C$3:$E$104,3,0) -> 750 | H6: =VLOOKUP(C6,'SIND PITS'!$C$3:$F$104,4,0) -> 0 | I6: =VLOOKUP(C6,'SIND PITS'!$C$3:$G$104,5,0) -> 0 | K6: =SUM(D6:I6) -> 10000 | L6: 18500 | M6: =+L6/2 -> 9250 | O6: =VLOOKUP($C6,'CPD PITSS'!$B$9:$V$26,8,0) -> 0 | P6: =+G6+H6+I6 -> 750 | Q6: =(VLOOKUP($C6,'CPD PITSS'!$B$9:$V$26,13,0))+(VLOOKUP($C6,'CPD PITSS'!$B$9:$V$26,14,0)) -> 0 | S6: =VLOOKUP(C6,'CPD PITSS'!$B$9:$S$26,18,0) -> 0 | U6: =+K6-O6-P6+Q6+R6+S6 -> 9250 | V6: =+M6-U6 -> 0 | X6: SEI0041 | Y6: =IFERROR(OFFSET('CPD PITSS'!$AN$8,MATCH('RESUMEN PITS'!C6,'CPD PITSS'!$B$9:$B$26,0),0),0)+IFERROR(OFFSET('IP PITSS'!$AL$8,MATCH('RESUMEN PITS'!C6,'IP PITSS'!$B$9:$B$91,0),0),0)+IFERROR(OFFSET('SIND PITS'!$S$2,MATCH('RESUMEN PITS'!C6,'SIND PITS'!$C$3:$C$103,0),0),0) -> 11635.497
A7: SEI0088 | B7: CONSULTORIA | C7: Morgado Fernandez Martin | D7: =VLOOKUP(C7,'CPD PITSS'!B13:V30,21,0) -> 4862.8 | F7: =VLOOKUP(C7,'SIND PITS'!$C$3:$H$104,2,0) -> 2607.25 | G7: =VLOOKUP(C7,'SIND PITS'!$C$3:$E$104,3,0) -> 337.5 | H7: =VLOOKUP(C7,'SIND PITS'!$C$3:$F$104,4,0) -> 0 | I7: =VLOOKUP(C7,'SIND PITS'!$C$3:$G$104,5,0) -> 204 | K7: =SUM(D7:I7) -> 8011.55 | L7: 15000 | M7: =+L7/2 -> 7500 | O7: =VLOOKUP($C7,'CPD PITSS'!$B$9:$V$26,8,0) -> 246 | P7: =+G7+H7+I7 -> 541.5 | Q7: =(VLOOKUP($C7,'CPD PITSS'!$B$9:$V$26,13,0))+(VLOOKUP($C7,'CPD PITSS'!$B$9:$V$26,14,0)) -> 0 | S7: =VLOOKUP(C7,'CPD PITSS'!$B$9:$S$26,18,0) -> 275.95 | U7: =+K7-O7-P7+Q7+R7+S7 -> 7500 | V7: =+M7-U7 -> 0 | X7: SEI0088 | Y7: =IFERROR(OFFSET('CPD PITSS'!$AN$8,MATCH('RESUMEN PITS'!C7,'CPD PITSS'!$B$9:$B$26,0),0),0)+IFERROR(OFFSET('IP PITSS'!$AL$8,MATCH('RESUMEN PITS'!C7,'IP PITSS'!$B$9:$B$91,0),0),0)+IFERROR(OFFSET('SIND PITS'!$S$2,MATCH('RESUMEN PITS'!C7,'SIND PITS'!$C$3:$C$103,0),0),0) -> 9855.7602
A8: SEI0097 | B8: CONSULTORIA | C8: Arreola Jimenez Jose Nieves | D8: =VLOOKUP(C8,'CPD PITSS'!B14:V31,21,0) -> 1970.4 | F8: =VLOOKUP(C8,'SIND PITS'!$C$3:$H$104,2,0) -> 1562.82 | G8: =VLOOKUP(C8,'SIND PITS'!$C$3:$E$104,3,0) -> 480 | H8: =VLOOKUP(C8,'SIND PITS'!$C$3:$F$104,4,0) -> 0 | I8: =VLOOKUP(C8,'SIND PITS'!$C$3:$G$104,5,0) -> 0 | K8: =SUM(D8:I8) -> 4013.22 | L8: 10150 | M8: =+L8/2 -> 5075 | O8: =VLOOKUP($C8,'CPD PITSS'!$B$9:$V$26,8,0) -> 0 | P8: =+G8+H8+I8 -> 480 | Q8: =(VLOOKUP($C8,'CPD PITSS'!$B$9:$V$26,13,0))+(VLOOKUP($C8,'CPD PITSS'!$B$9:$V$26,14,0)) -> 1541.78 | S8: =VLOOKUP(C8,'CPD PITSS'!$B$9:$S$26,18,0) -> 0 | U8: =+K8-O8-P8+Q8+R8+S8 -> 5075 | V8: =+M8-U8 -> 0 | X8: SEI0097 | Y8: =IFERROR(OFFSET('CPD PITSS'!$AN$8,MATCH('RESUMEN PITS'!C8,'CPD PITSS'!$B$9:$B$26,0),0),0)+IFERROR(OFFSET('IP PITSS'!$AL$8,MATCH('RESUMEN PITS'!C8,'IP PITSS'!$B$9:$B$91,0),0),0)+IFERROR(OFFSET('SIND PITS'!$S$2,MATCH('RESUMEN PITS'!C8,'SIND PITS'!$C$3:$C$103,0),0),0) -> 6794.2812
A9: SEI0099 | B9: CONSULTORIA | C9: Garcia Villicaña Ricardo Pascual | D9: =VLOOKUP(C9,'CPD PITSS'!B15:V32,21,0) -> 5220.8 | F9: =VLOOKUP(C9,'SIND PITS'!$C$3:$H$104,2,0) -> 2607.2 | G9: =VLOOKUP(C9,'SIND PITS'!$C$3:$E$104,3,0) -> 150 | H9: =VLOOKUP(C9,'SIND PITS'!$C$3:$F$104,4,0) -> 2160 | I9: =VLOOKUP(C9,'SIND PITS'!$C$3:$G$104,5,0) -> 272 | K9: =SUM(D9:I9) -> 10410 | L9: 15000 | M9: =+L9/2 -> 7500 | O9: =VLOOKUP($C9,'CPD PITSS'!$B$9:$V$26,8,0) -> 328 | P9: =+G9+H9+I9 -> 2582 | Q9: =(VLOOKUP($C9,'CPD PITSS'!$B$9:$V$26,13,0))+(VLOOKUP($C9,'CPD PITSS'!$B$9:$V$26,14,0)) -> 0 | S9: =VLOOKUP(C9,'CPD PITSS'!$B$9:$S$26,18,0) -> 0 | U9: =+K9-O9-P9+Q9+R9+S9 -> 7500 | V9: =+M9-U9 -> 0 | X9: SEI0099 | Y9: =IFERROR(OFFSET('CPD PITSS'!$AN$8,MATCH('RESUMEN PITS'!C9,'CPD PITSS'!$B$9:$B$26,0),0),0)+IFERROR(OFFSET('IP PITSS'!$AL$8,MATCH('RESUMEN PITS'!C9,'IP PITSS'!$B$9:$B$91,0),0),0)+IFERROR(OFFSET('SIND PITS'!$S$2,MATCH('RESUMEN PITS'!C9,'SIND PITS'!$C$3:$C$103,0),0),0) -> 12020.71
A10: SEI0108 | B10: CONSULTORIA | C10: Caballero Diaz Francisco Javier | D10: =VLOOKUP(C10,'CPD PITSS'!B16:V33,21,0) -> 1484 | F10: =VLOOKUP(C10,'SIND PITS'!$C$3:$H$104,2,0) -> 1562.82 | G10: =VLOOKUP(C10,'SIND PITS'!$C$3:$E$104,3,0) -> 330 | H10: =VLOOKUP(C10,'SIND PITS'!$C$3:$F$104,4,0) -> 0 | I10: =VLOOKUP(C10,'SIND PITS'!$C$3:$G$104,5,0) -> 0 | K10: =SUM(D10:I10) -> 3376.82 | L10: 10150 | M10: =+L10/2 -> 5075 | O10: =VLOOKUP($C10,'CPD PITSS'!$B$9:$V$26,8,0) -> 0 | P10: =+G10+H10+I10 -> 330 | Q10: =(VLOOKUP($C10,'CPD PITSS'!$B$9:$V$26,13,0))+(VLOOKUP($C10,'CPD PITSS'!$B$9:$V$26,14,0)) -> 1789.38 | S10: =VLOOKUP(C10,'CPD PITSS'!$B$9:$S$26,18,0) -> 238.8 | U10: =+K10-O10-P10+Q10+R10+S10 -> 5075 | V10: =+M10-U10 -> 0 | X10: SEI0108 | Y10: =IFERROR(OFFSET('CPD PITSS'!$AN$8,MATCH('RESUMEN PITS'!C10,'CPD PITSS'!$B$9:$B$26,0),0),0)+IFERROR(OFFSET('IP PITSS'!$AL$8,MATCH('RESUMEN PITS'!C10,'IP PITSS'!$B$9:$B$91,0),0),0)+IFERROR(OFFSET('SIND PITS'!$S$2,MATCH('RESUMEN PITS'!C10,'SIND PITS'!$C$3:$C$103,0),0),0) -> 6641.2812
A11: SEI0116 | B11: CONSULTORIA | C11: Casillas Cardona Cesar Alejandro | D11: =VLOOKUP(C11,'CPD PITSS'!B17:V34,21,0) -> 3208.2 | F11: =VLOOKUP(C11,'SIND PITS'!$C$3:$H$104,2,0) -> 1896.87 | G11: =VLOOKUP(C11,'SIND PITS'!$C$3:$E$104,3,0) -> 0 | H11: =VLOOKUP(C11,'SIND PITS'!$C$3:$F$104,4,0) -> 0 | I11: =VLOOKUP(C11,'SIND PITS'!$C$3:$G$104,5,0) -> 0 | K11: =SUM(D11:I11) -> 5105.07 | L11: 12000 | M11: =+L11/2 -> 6000 | O11: =VLOOKUP($C11,'CPD PITSS'!$B$9:$V$26,8,0) -> 0 | P11: =+G11+H11+I11 -> 0 | Q11: =(VLOOKUP($C11,'CPD PITSS'!$B$9:$V$26,13,0))+(VLOOKUP($C11,'CPD PITSS'!$B$9:$V$26,14,0)) -> 894.93 | S11: =VLOOKUP(C11,'CPD PITSS'!$B$9:$S$26,18,0) -> 0 | U11: =+K11-O11-P11+Q11+R11+S11 -> 6000 | V11: =+M11-U11 -> 0 | X11: SEI0116 | Y11: =IFERROR(OFFSET('CPD PITSS'!$AN$8,MATCH('RESUMEN PITS'!C11,'CPD PITSS'!$B$9:$B$26,0),0),0)+IFERROR(OFFSET('IP PITSS'!$AL$8,MATCH('RESUMEN PITS'!C11,'IP PITSS'!$B$9:$B$91,0),0),0)+IFERROR(OFFSET('SIND PITS'!$S$2,MATCH('RESUMEN PITS'!C11,'SIND PITS'!$C$3:$C$103,0),0),0) -> 7354.3428
A12: SEI0117 | B12: CONSULTORIA | C12: Mariscal Romero Luis Adrian | D12: =VLOOKUP(C12,'CPD PITSS'!B18:V35,21,0) -> 3102.6 | F12: =VLOOKUP(C12,'SIND PITS'!$C$3:$H$104,2,0) -> 2757.68 | G12: =VLOOKUP(C12,'SIND PITS'!$C$3:$E$104,3,0) -> 165 | H12: =VLOOKUP(C12,'SIND PITS'!$C$3:$F$104,4,0) -> 0 | I12: =VLOOKUP(C12,'SIND PITS'!$C$3:$G$104,5,0) -> 0 | K12: =SUM(D12:I12) -> 6025.28 | L12: 15000 | M12: =+L12/2 -> 7500 | O12: =VLOOKUP($C12,'CPD PITSS'!$B$9:$V$26,8,0) -> 0 | P12: =+G12+H12+I12 -> 165 | Q12: =(VLOOKUP($C12,'CPD PITSS'!$B$9:$V$26,13,0))+(VLOOKUP($C12,'CPD PITSS'!$B$9:$V$26,14,0)) -> 1639.72 | S12: =VLOOKUP(C12,'CPD PITSS'!$B$9:$S$26,18,0) -> 0 | U12: =+K12-O12-P12+Q12+R12+S12 -> 7500 | V12: =+M12-U12 -> 0 | X12: SEI0117 | Y12: =IFERROR(OFFSET('CPD PITSS'!$AN$8,MATCH('RESUMEN PITS'!C12,'CPD PITSS'!$B$9:$B$26,0),0),0)+IFERROR(OFFSET('IP PITSS'!$AL$8,MATCH('RESUMEN PITS'!C12,'IP PITSS'!$B$9:$B$91,0),0),0)+IFERROR(OFFSET('SIND PITS'!$S$2,MATCH('RESUMEN PITS'!C12,'SIND PITS'!$C$3:$C$103,0),0),0) -> 9179.4186
A13: SEI0118 | B13: CONSULTORIA | C13: Arroyo Ramirez Hector Hugo | D13: =VLOOKUP(C13,'CPD PITSS'!B19:V36,21,0) -> 2733.2 | F13: =VLOOKUP(C13,'SIND PITS'!$C$3:$H$104,2,0) -> 2108.92 | G13: =VLOOKUP(C13,'SIND PITS'!$C$3:$E$104,3,0) -> 0 | H13: =VLOOKUP(C13,'SIND PITS'!$C$3:$F$104,4,0) -> 0 | I13: =VLOOKUP(C13,'SIND PITS'!$C$3:$G$104,5,0) -> 0 | K13: =SUM(D13:I13) -> 4842.12 | L13: 13000 | M13: =+L13/2 -> 6500 | O13: =VLOOKUP($C13,'CPD PITSS'!$B$9:$V$26,8,0) -> 0 | P13: =+G13+H13+I13 -> 0 | Q13: =(VLOOKUP($C13,'CPD PITSS'!$B$9:$V$26,13,0))+(VLOOKUP($C13,'CPD PITSS'!$B$9:$V$26,14,0)) -> 1402.48 | S13: =VLOOKUP(C13,'CPD PITSS'!$B$9:$S$26,18,0) -> 255.4 | U13: =+K13-O13-P13+Q13+R13+S13 -> 6500 | V13: =+M13-U13 -> 0 | X13: SEI0118 | Y13: =IFERROR(OFFSET('CPD PITSS'!$AN$8,MATCH('RESUMEN PITS'!C13,'CPD PITSS'!$B$9:$B$26,0),0),0)+IFERROR(OFFSET('IP PITSS'!$AL$8,MATCH('RESUMEN PITS'!C13,'IP PITSS'!$B$9:$B$91,0),0),0)+IFERROR(OFFSET('SIND PITS'!$S$2,MATCH('RESUMEN PITS'!C13,'SIND PITS'!$C$3:$C$103,0),0),0) -> 7917.4236
